Workbook
Name _Hlk211416489: 'RELACION DE PAGOS EMITIDOS'!#REF!

Sheet RELACION DE PAGOS EMITIDOS
A5: DIRECCION DE FISCALIZACION Y CONTROL
A6: RELACION DE PAGOS EMITIDOS DURANTE EL MES DE NOVIEMBRE 2025
A7: ESTABLECIMIENTO: HOSPITAL MATERNO INFANTIL SAN LORENZO DE LOS MINA
A9: PAGOS CORRESPONDIENTES AL MES : NOVIEMBRE 2025
A10: FECHA | B10: LIBRAMIENTO | C10: TRANSFERENCIA | D10: CHEQUE | E10: BENEFICIARIO | F10: NO.FACTURAS | G10: VALOR DE FACTURA | H10: VALOR PAGADO
A11: 45964 | C11: 372 | E11: P&D RECYCLING SRL | F11: PAGO NCF B1500000320 SERVICIO DE RECOGIDA DE DESECHOS BIOMEDICOS SEGÚN O/C HSLM-2025-01044. | G11: 720000 | H11: 684000
A12: 45965 | C12: 373 | E12: CARLOS RAFAEL DE PAULA ROSSO | F12: PAGO NCF B1500000071 REPARACION DE CUARTO FRIO AREA DE COCINA DE 4 TONELADAS SEGÚN O/C HSLM-2025-01099 | G12: 361378.54 | H12: 346065.89
A13: 45967 | C13: 379 | E13: LUZ ESTHER BATISTA PEREZ | F13: PAGO NCF B1500001309, ADQUISICION DE FUNDAS PLASTICAS SEGÚN O/C HSLM-2025-01031. | G13: 158061 | H13: 151363.5
A14: 45974 | C14: 380 | E14: PLANETA AZUL S.A | F14: PAGO NCF E45000013058 ADQUISICION DE BOTELLAS DE AGUA SEGÚN O/C HSLM-2025-00322. | G14: 15000 | H14: 15000
A15: 45974 | C15: 381 | E15: PLANETA AZUL S.A | F15: PAGO NCF E450000012562 ADQUISICION DE BOTELLAS DE AGUA SEGÚN O/C HSLM-2025-01004 | G15: 14000 | H15: 14000
A16: 45974 | C16: 382 | E16: SUPER LAPTOP BROWSING SRL | F16: PAGO NCF B1500000184 ADQUISICION DE UPS SEGÚN O/C HSLM-2025-01090 | G16: 413000 | H16: 395500
A17: 45974 | C17: 383 | E17: BAAM & ASOCIADOS SRL | F17: PAGO NCF B1500000096 ADQUISICION E INSTALACION DE CONTROL DE SALIDA PUERTA PRINCIPAL SEGÚN O/C HSLM-2025-01038 | G17: 175173.19 | H17: 166414.53
A18: 45974 | C18: 384 | E18: BAAM & ASOCIADOS SRL | F18: PAGO NCF B1500000197 ADQUISICION BARRERAS DE CONTROL EN LAS ENTRADAS PRINCIPALES DE LOS PARQUEOS SEGÚN O/C HSLM-2025-01037 | G18: 244226.81 | H18: 233878.22
A19: 45974 | C19: 385 | E19: G&M GELMAT COMERCIAL SRL | F19: PAGO NCF B1500000199 ADQUISICION DE CAJAS PARA EQUIPO ELECTRICO SEGÚN O/C HSLM-2025-01071. | G19: 41819.2 | H19: 40047.2
A20: 45974 | C20: 386 | E20: NULO | F20: NULO | G20: 0 | H20: 0
A21: 45974 | C21: 387 | E21: IV BIODESINFECCION SRL | F21: PAGO NCF B1500000305 SERVICIO DE DESINFECION SEGÚN O/C HSLM-2025-01089 | G21: 185260 | H21: 177410
A22: 45974 | C22: 388 | E22: TROPIGAS DOMINICANA SRL | F22: PAGO NCF E45000000005518 POR ADQUISICION DE GAS LICUADO DE PETROLEO SEGÚN O/ C HSLM-2025-00730 | G22: 21952 | H22: 21952
... A35: 45989 | C35: 401 | E35: TONER DEPOT MULTISERVICIOS EORG SRL | F35: PAGO NCF E450000000424, POR SERVICIO DE IMPRESIÓN EN EL MES DE OCTUBRE 2025 SEGÚN O/C HSLM-2025-00725 | G35: 298561.92 | H35: 272247.99
A36: 45989 | C36: =+C35+1 -> 402 | E36: OFITOP, SRL | F36: PAGO DE FACT NCF NO. B1500000024, POR ADQUISICION DE MUEBLES DE OFICINA PARA SER UTILIZADO EN LA READECUACION DEL CONSULTORIO DE OFTALMOLOGIA, SEGÚN ORDEN DE COMPRA HSLM-2025-01042 | G36: 182234.7 | H36: 174512.67
A37: 45989 | C37: =+C36+1 -> 403 | E37: OFITOP, SRL | F37: PAGO DE FACT NCF NO. B1500000021, POR ELABORCION DE LETRERO TIPO SEÑALIZACION EN ACRILICO ROTULADO EN VINIL 30X30, SEGÚN ORDEN DE COMPRA HSLM-2025-01026 | G37: 221258.85 | H37: 211883.48
A38: 45989 | C38: =+C37+1 -> 404 | E38: OFITOP, SRL | F38: PAGO DE FACT NCF NO. B1500000019, POR ADQUISICION DE MOBILIARIOS, SEGÚN ORDEN DE COMPRA HSLM-2025-01041 | G38: 260210.02 | H38: 249184.17
A39: 45989 | C39: 405 | E39: FARMACO QUIMICA NACIONAL, | F39: ADQUISICION DE VALCULA HIDROCEFALICA, | G39: 30444 | H39: 30444
A40: 45989 | C40: 406 | E40: HOSPAL MEDICA SRL | F40: ADQUISICION DE VALCULA HIDROCEFALICA, ORDEN DE SEVICIO 2025-01222 | G40: 34220 | H40: 34220
A41: 45989 | C41: 407 | E41: Suplimed, SRL | F41: PAGO FACTURA NCF B1500000127 | G41: 195000 | H41: 195000
A42: 45989 | C42: 408 | E42: COMISION NACIONAL DE ENERGIA | F42: SERVICIO DE LICENCIA OPERACIONAL RADIODIAGNOSTICA PARA EL HOSPITAL | G42: 13260 | H42: 13260
A43: 45972 | D43: 37317 | E43: NULO | F43: NULO | G43: 0 | H43: 0
A44: 45981 | D44: 37318 | E44: DELMIRA GARCIA | F44: REPOSICION DEL FONDO DE CAJA CHICA DESDE RECIBO 40668 HASTA EL RECIBO 40702 | G44: 56945.15 | H44: 56945.15
A45: 45981 | D45: 37319 | E45: RUDDY SEGURA | F45: PAGO NCF B1100000080 SERVICIO DE LIMPIEZA Y CLORIFICACION DE CISTERNA DE ESTE HOSPITAL | G45: 21673.47 | H45: 18000
A46: 45981 | D46: 37320 | E46: ALEXANDER MENDEZ CONTRERAS | F46: PAGO NCF B1100000081 SERVICIO DE JARDINERIA PARA AREAS VERDES DE ESTE HOSPITAL. | G46: 18061.22 | H46: 15000
A47: 45981 | D47: 37321 | E47: NELSON YNFANTE VELAZQUEZ | F47: PAGO NCF B1100000082 SERVICIO DE PINTURA DE LAS AREAS DE EMERGENCIA Y PEDIATRIA DE ESTE HOSPITAL | G47: 18061.22 | H47: 15000
A48: 45981 | D48: 37322 | E48: FREDDY OSCAR RODRIGUEZ RIVAS | F48: COLABORACION DE CAVACION DE HOYO Y CERTIFICACION DE ACTAS EN EL MES DE NOVIEMBRE 2025 | G48: 3600 | H48: 3600
A49: 45982 | D49: 37323 | E49: OVIDIO DE JESUS DURAN CLEMENTE | F49: PAGO POR SERVICIO DE TRANSPORTE DE LA AMBULANCIA CORRESPONDIENTE AL MES DE NOVIEMBRE 2025 | G49: 20000 | H49: 20000
A50: 45991 | E50: COMISIONES BANCARIAS | F50: COMISIONES BANCARIAS | G50: 14087.24 | H50: 14087.24
A51: 03/11/2025 | B51: 4930 | E51: Grupo Xeron Medic SRL | F51: PAGO FACTURA NCF B1500000303 POR ADQUISICION DE UTIL MEDICO SEGUN O/C HSLM-2025-01062. | G51: 272108
A52: 03/11/2025 | B52: 4934 | E52: Grupo Xeron Medic SRL | F52: PAGO FACTURA NCF B1500000310 POR ADQUISICION DE UTIL MEDICO SEGUN O/C HSLM-2025-01082. | G52: 252331.2
A53: 03/11/2025 | B53: 4938 | E53: Grupo Xeron Medic SRL | F53: PAGO FACTURA NCF B1500000312 POR ADQUISICION DE UTIL MEDICO SEGUN O/C HSLM-2025-01095. | G53: 224294.4
A54: 03/11/2025 | B54: 4942 | E54: Bio Nuclear, SA | F54: PAGO DE FACT NCF NO. E450000008409 Y E450000008443, POR ADQUISICION DE CONTROLES EQAS, SEGUN ORDEN DE COMPRA HSLM-2025-01021 | G54: 17504.5
A55: 03/11/2025 | B55: 4953 | E55: PAPELERIA E IMPRESOS CRISHOAN, SRL | F55: PAGO DE FACT NCF NO B1500001792, POR ADQUISICION DE IMPRESOS, SEGUN ORDEN DE COMPRA HSLM-2025-01097 | G55: 271695
A56: 03/11/2025 | B56: 4960 | E56: Farmaco Internacional, SRL | F56: PAGO DE FACT NCF NO. E450000000118, POR ADQUISICION DE UTIL MEDICO, SEGUN ORDEN DE COMPRA HSLM-2025-00894 | G56: 138591
A57: 03/11/2025 | B57: 4961 | E57: Destreza Comercial, SRL | F57: PAGO DE FACT NCF B1500000079 POR ADQUISICION DE MEDICAMENTOS SEGUN O/C HSLM-2025-01083. | G57: 71400
...

Sheet RELACION ORDENES DE COMPRAS
A4: SERVICIO NACIONAL DE SALUD
A5: DIRECCION DE FISCALIZACION
A6: RELACIÓN DE ORDENES DE COMPRAS DE BIENES Y SERVICIOS EFECTUADAS.
A7: ESTABLECIMIENTO: HOSPITAL MATERNO INFANTIL SAN LORENZO DE LOS MINA REGION OZAMA
A8: 45962 | J8: EN PROCESO POR EL AREA DE COMPRAS
A9: Fecha | B9: # Orden de Compra o Servicios | C9: # DE EXPEDIENTE(PROCESO CELEBRADO) | D9: No. De Factura Fiscal NCF | E9: Fuente. Financ (FR-VS) | F9: Beneficiario | G9: Rubro | H9: No. Cta. Objetal del Gasto | I9: Valor | J9: Status del proceso | K9: solo observar cuando se presentas esos procesos

Sheet CONS. FUENTES FINAN
A1: Form. No.6 SRS
A3: Servicio Nacional de Salud
A4: Dirección de Fizcalización
A5: Consolidado de Ingresos y Gastos por Fuente de Financiamiento
A6: HOSPITAL MATERNO INFANTIL SAN LORENZO DE LOS MINA
A7: OCTUBRE 2025
C8: Ingresos Generales:
E9: 1.- Balance Inicial / Fuente:
E10: Anticipo Financiero | H10: Otros Aportes | L10: Contraseña: 0001
E11: Transferencias Corrientes
E12: Venta de Servicios | G12: 5363379
E13: 2.- Ingresos por Fuente / Cuenta
E14: Anticipo Financiero | H14: Otros Aportes | L14: OBJETAL | M14: FR | N14: VS
E15: Transferencias Corrientes | G15: =+'INGR SEGUN ORIGEN'!E12 -> 1.5626822e+08 | H15: Aportes Nomina SNS | L15: 2.1 | M15: =G26 -> 1.3374081e+08 | N15: =H26 -> 0
E16: Venta de Servicios | G16: =+'INGR SEGUN ORIGEN'!E35+'INGR SEGUN ORIGEN'!E42 -> 9309369.1 | L16: 2.2 | M16: =G87 -> 1896797.1 | N16: =H87 -> 2083820.5
H17: TOTAL INGRESOS RDS | I17: =+G10+G11+G12+I10+G14+G15+G16+I14+I15 -> 1.7094097e+08 | L17: 2.3 | M17: ='CONS. FUENTES FINAN'!G212 -> 13779851 | N17: ='CONS. FUENTES FINAN'!H212 -> 2184325.9
L18: 2.4 | M18: =G330 -> 0 | N18: =H330 -> 3600
L19: 2.6 | M19: =G336 -> 8010447.3 | N19: =H336 -> 2755244.7
L20: 2.7 | M20: ='CONS. FUENTES FINAN'!G463 -> 0 | N20: ='CONS. FUENTES FINAN'!H463 -> 0
A21: 1 | F21: 2 | G21: 3 | I21: 4 | J21: 5
A22: Código Presupuestario | F22: Descripción Gasto por Cuenta | G22: Distribución del Gasto por Fuente de Financiamiento | I22: TOTAL | J22: %
A23: Tipo | B23: Objeto | C23: Cuenta | D23: Sub-Cuenta | E23: Auxiliar | G23: Fondo 100 | H23: Venta de Servicios/ Otros Aportes
A25: 2 | F25: Gastos | G25: =+G26+G87+G212+G330+G336+G463 -> 157427908 | H25: =+H26+H87+H212+H330+H336+H463 -> 7026991.1 | I25: =SUM(G25:H25) -> 1.644549e+08 | J25: =+J26+J87+J212+J330+J336+J463 -> 1
A26: 2 | B26: 1 | F26: Servicios Personales | G26: =+G27+G51+G64+G71+G78 -> 1.3374081e+08 | H26: =+H27+H51+H64+H71+H78 -> 0 | I26: =SUM(G26:H26) -> 1.3374081e+08 | J26: =I26/$I$25 -> 0.81323702
A27: 2 | B27: 1 | C27: 1 | F27: Remuneraciones | G27: =+G28+G35+G42+G44+G46 -> 1.2113301e+08 | H27: =+H28+H35+H42+H44+H46 -> 0 | I27: =SUM(G27:H27) -> 1.2113301e+08
A28: 2 | B28: 1 | C28: 1 | D28: 1 | F28: Remuneraciones al personal fijo | G28: =SUM(G29:G34) -> 59046800 | H28: =SUM(H29:H34) -> 0 | I28: =SUM(G28:H28) -> 59046800
A29: 2 | B29: 1 | C29: 1 | D29: 1 | E29: 01 | F29: Sueldos a empleados fijos | G29: ='CUENTA T FONDO 100'!A97 -> 59046800 | H29: ='CUENTA T VS'!A75 -> 0 | I29: =SUM(G29:H29) -> 59046800 | J29: =I29/$I$25 -> 0.35904555
A30: 2 | B30: 1 | C30: 1 | D30: 1 | E30: 02 | F30: Sueldos a médicos | G30: ='CUENTA T FONDO 100'!B97 -> 0 | H30: ='CUENTA T VS'!B75 -> 0 | I30: =SUM(G30:H30) -> 0 | J30: =I30/$I$25 -> 0
A31: 2 | B31: 1 | C31: 1 | D31: 1 | E31: 03 | F31: Ascensos a militares | G31: ='CUENTA T FONDO 100'!C97 -> 0 | H31: ='CUENTA T VS'!C75 -> 0 | I31: =SUM(G31:H31) -> 0 | J31: =I31/$I$25 -> 0
A32: 2 | B32: 1 | C32: 1 | D32: 1 | E32: 04 | F32: Nuevas plazas maestros | G32: ='CUENTA T FONDO 100'!D97 -> 0 | H32: ='CUENTA T VS'!D75 -> 0 | I32: =SUM(G32:H32) -> 0 | J32: =I32/$I$25 -> 0
A33: 2 | B33: 1 | C33: 1 | D33: 1 | E33: 05 | F33: Incentivos y escalafón | G33: ='CUENTA T FONDO 100'!E97 -> 0 | H33: ='CUENTA T VS'!E75 -> 0 | I33: =SUM(G33:H33) -> 0 | J33: =I33/$I$25 -> 0
A34: 2 | B34: 1 | C34: 1 | D34: 1 | E34: 06 | F34: Nuevas plazas a médicos | G34: ='CUENTA T FONDO 100'!F97 -> 0 | H34: ='CUENTA T VS'!F75 -> 0 | I34: =SUM(G34:H34) -> 0 | J34: =I34/$I$25 -> 0
A35: 2 | B35: 1 | C35: 1 | D35: 2 | F35: Remuneraciones al personal con carácter transitorio | G35: =SUM(G36:G41) -> 1342531 | H35: =SUM(H36:H41) -> 0 | I35: =SUM(G35:H35) -> 1342531
A36: 2 | B36: 1 | C36: 1 | D36: 2 | E36: 03 | F36: Suplencias | G36: ='CUENTA T FONDO 100'!G97 -> 0 | H36: ='CUENTA T VS'!G75 -> 0 | I36: =SUM(G36:H36) -> 0 | J36: =I36/$I$25 -> 0
A37: 2 | B37: 1 | C37: 1 | D37: 2 | E37: 05 | F37: Sueldo al personal nominal en período probatorio | G37: ='CUENTA T FONDO 100'!H97 -> 0 | H37: ='CUENTA T VS'!H75 -> 0 | I37: =SUM(G37:H37) -> 0 | J37: =I37/$I$25 -> 0
A38: 2 | B38: 1 | C38: 1 | D38: 2 | E38: 06 | F38: Jornales | G38: ='CUENTA T FONDO 100'!I97 -> 0 | H38: ='CUENTA T VS'!I75 -> 0 | I38: =SUM(G38:H38) -> 0 | J38: =I38/$I$25 -> 0
A39: 2 | B39: 1 | C39: 1 | D39: 2 | E39: 08 | F39: Empleados temporales | G39: ='CUENTA T FONDO 100'!J97 -> 1342531 | H39: ='CUENTA T VS'!J75 -> 0 | I39: =SUM(G39:H39) -> 1342531 | J39: =I39/$I$25 -> 0.008163521
A40: 2 | B40: 1 | C40: 1 | D40: 2 | E40: 09 | F40: Personal de carácter eventual | G40: ='CUENTA T FONDO 100'!K97 -> 0 | H40: ='CUENTA T VS'!K75 -> 0 | I40: =SUM(G40:H40) -> 0 | J40: =I40/$I$25 -> 0
A41: 2 | B41: 1 | C41: 1 | D41: 2 | E41: 11 | F41: Interinato | G41: ='CUENTA T FONDO 100'!L97 -> 0 | H41: ='CUENTA T VS'!L75 -> 0 | I41: =SUM(G41:H41) -> 0 | J41: =I41/$I$25 -> 0
A42: 2 | B42: 1 | C42: 1 | D42: 3 | F42: Sueldos al personal fijo en trámite de pensiones | G42: =SUM(G43) -> 0 | H42: =SUM(H43) -> 0 | I42: =SUM(G42:H42) -> 0
...

Sheet CUENTA T FONDO 100
A1: D E S G L O S E D E L A S C U E N T A S
A2: 211101 | B2: 211102 | C2: 211103 | D2: 211104 | E2: 211105 | F2: 211106 | G2: 211203 | H2: 211205 | I2: 211206 | J2: 211208 | K2: 211209 | L2: 211211 | M2: 211301 | N2: 211401 | O2: 211501 | P2: 211502 | Q2: 211503 | R2: 211504 | S2: 212101 | T2: 212201 | U2: 212203 | V2: 212204 | W2: 212205 | X2: 212206 | Y2: 212207 | Z2: 212208 | AA2: 212209 | AB2: 212210 | AC2: 213101 | AD2: 213102 | AE2: 213201 | AF2: 213202 | AG2: 214101 | AH2: 214201 | AI2: 214202 | AJ2: 214203 | AK2: 215101 | AL2: 215201 | AM2: 215301 | AN2: 215401 | AO2: 221101 | AP2: 221201 | AQ2: 221301 | AR2: 221401 | AS2: 221501 | AT2: 221601 | AU2: 221602 | AV2: 221701 | AW2: 221801 | AX2: 222101 | AY2: 222201 | AZ2: 223101 | BA2: 223201 | BB2: 224101 | BC2: 224201 | BD2: 224301 | BE2: 224401 | BF2: 225101 | BG2: 225201 | BH2: 225301 | BI2: 225302 | BJ2: 225303 | BK2: 225304 | BL2: 225305 | BM2: 225401 | BN2: 225501 | BO2: 225601 | BP2: 225701 | BQ2: 225801 | BR2: 225901 | BS2: 226101 | BT2: 226201 | BU2: 226301 | BV2: 226401 | BW2: 227101 | BX2: 227102 | BY2: 227103 | BZ2: 227104 | CA2: 227105 | CB2: 227106 | CC2: 227107 | CD2: 227199 | CE2: 227201 | CF2: 227202 | CG2: 227203 | CH2: 227204 | CI2: 227205 | CJ2: 227206 | CK2: 227207 | CL2: 227208 | CM2: 227299 | CN2: 227301 | CO2: 228101 | CP2: 228201 | CQ2: 228301 | CR2: 228401 | CS2: 228501 | CT2: 228502 | CU2: 228503 | CV2: 228601 | CW2: 228602 | CX2: 228603 | CY2: 228604 | CZ2: 228701 | DA2: 228702 | DB2: 228703 | DC2: 228704 | DD2: 228705 | DE2: 228706 | DF2: 228801 | DG2: 228802 | DH2: 228803 | DI2: 229201 | DJ2: 229203 | DK2: 231101 | DL2: 231102 | DM2: 231201 | DN2: 231301 | DO2: 231302 | DP2: 231303 | DQ2: 231401 | DR2: 232101 | DS2: 232201 | DT2: 232301 | DU2: 233101 | DV2: 233201 | DW2: 233301 | DX2: 233401 | DY2: 233501 | DZ2: 233601 | EA2: 234101 | EB2: 234201 | EC2: 235101 | ED2: 235201 | EE2: 235301 | EF2: 235401 | EG2: 235501 | EH2: 236101 | EI2: 236102 | EJ2: 236103 | EK2: 236104 | EL2: 236105 | EM2: 236201 | EN2: 236202 | EO2: 236203 | EP2: 236304 | EQ2: 236305 | ER2: 236306 | ES2: 236401 | ET2: 236402 | EU2: 236403 | EV2: 236404 | EW2: 236405 | EX2: 236406 | EY2: 236407 | EZ2: 236901 | FA2: 237101 | FB2: 237102 | FC2: 237103 | FD2: 237104 | FE2: 237105 | FF2: 237106 | FG2: 237107 | FH2: 237201 | FI2: 237202 | FJ2: 237203 | FK2: 237204 | FL2: 237205 | FM2: 237206 | FN2: 237299 | FO2: 238101 | FP2: 238201 | FQ2: 239101 | FR2: 239102 | FS2: 239201 | FT2: 239301 | FU2: 239401 | FV2: 239501 | FW2: 239601 | FX2: 239701 | FY2: 239801 | FZ2: 239802 | GA2: 239901 | GB2: 239904 | GC2: 241201 | GD2: 241202 | GE2: 241203 | GF2: 241204 | GG2: 241205 | GH2: 261101 | GI2: 261201 | GJ2: 261301 | GK2: 261401 | GL2: 261901 | GM2: 262101 | GN2: 262201 | GO2: 262301 | GP2: 262401 | GQ2: 263101 | GR2: 263201 | GS2: 263301 | GT2: 263401 | GU2: 264101 | GV2: 264201 | GW2: 264301 | GX2: 264401 | GY2: 264501 | GZ2: 264601 | HA2: 264701 | HB2: 264801 | HC2: 265101 | HD2: 265201 | HE2: 265301 | HF2: 265401 | HG2: 265501 | HH2: 265601 | HI2: 265701 | HJ2: 265801 | HK2: 266101 | HL2: 266201 | HM2: 267101 | HN2: 267201 | HO2: 267301 | HP2: 267401 | HQ2: 267501 | HR2: 267601 | HS2: 267701 | HT2: 267801 | HU2: 267901 | HV2: 268101 | HW2: 268201 | HX2: 268301 | HY2: 268302 | HZ2: 268401 | IA2: 268501 | IB2: 268601 | IC2: 268701 | ID2: 268802 | IE2: 268803 | IF2: 268804 | IG2: 268901 | IH2: 269101 | II2: 269102 | IJ2: 269201 | IK2: 269202 | IL2: 269301 | IM2: 269401 | IN2: 269501 | IO2: 269502 | IP2: 269503 | IQ2: 2269901 | IR2: 271101 | IS2: 271201 | IT2: 271301 | IU2: 271401 | IV2: 272101 | IW2: 272201 | IX2: 272301 | IY2: 272401 | IZ2: 272501 | JA2: 272601 | JB2: 272701 | JC2: 272801 | JD2: 272901 | JE2: 273101 | JF2: 273201 | JG2: 274101 | JH2: 274201 | JI2: Totales | JJ2: TRANSF NO. | JK2: VALOR | JL2: RETENCION | JM2: AÑOS ANTERIORES | JN2: 2022 | JO2: Total | JP2: Proveedor Informal
FT3: 272108 | JI3: =SUM(A3:JH3) -> 272108 | JJ3: 4930 | JO3: =+JM3+JN3 -> 0
FT4: 252331.2 | JI4: =SUM(A4:JH4) -> 252331.2 | JJ4: 4934
FT5: 224294.4 | JI5: =SUM(A5:JH5) -> 224294.4 | JJ5: 4938
FJ6: 17504.5 | JI6: =SUM(A6:JH6) -> 17504.5 | JJ6: 4942
DW7: 271695 | JI7: =SUM(A7:JH7) -> 271695 | JJ7: 4953
FT8: 138591 | JI8: =SUM(A8:JH8) -> 138591 | JJ8: 4960
EA9: 71400 | JI9: =SUM(A9:JH9) -> 71400 | JJ9: 4961
FT10: 255284.8 | JI10: =SUM(A10:JH10) -> 255284.8 | JJ10: 4965
EA11: 87500 | JI11: =SUM(A11:JH11) -> 87500 | JJ11: 4969
FT12: 247800 | JI12: =SUM(A12:JH12) -> 247800 | JJ12: 4974
FT13: 101786 | JI13: =SUM(A13:JH13) -> 101786 | JJ13: 4977
FT14: 138591 | JI14: =SUM(A14:JH14) -> 138591 | JJ14: 4981
EA15: 97435 | JI15: =SUM(A15:JH15) -> 97435 | JJ15: 4988
FT16: 1513350 | JI16: =SUM(A16:JH16) -> 1513350 | JJ16: 4989
FT17: 96946.88 | JI17: =SUM(A17:JH17) -> 96946.88 | JJ17: 4993
FJ18: 80000 | JI18: =SUM(A18:JH18) -> 80000 | JJ18: 4997
FJ19: 249166 | FT19: 23128 | JI19: =SUM(A19:JH19) -> 272294 | JJ19: 5001
BX20: 30861.53 | EG20: 18154.65 | JI20: =SUM(A20:JH20) -> 49016.18 | JJ20: 5014
EA21: 260000 | JI21: =SUM(A21:JH21) -> 260000 | JJ21: 5016
GH22: 31507.02 | JI22: =SUM(A22:JH22) -> 31507.02 | JJ22: 5021
GQ23: 1791000 | JI23: =SUM(A23:JH23) -> 1791000 | JJ23: 5026
HF24: 42057.86 | JI24: =SUM(A24:JH24) -> 42057.86 | JJ24: 5031
FT25: 247800 | JI25: =SUM(A25:JH25) -> 247800 | JJ25: 5032
HI26: 22585.2 | JI26: =SUM(A26:JH26) -> 22585.2 | JJ26: 5040
GR27: 59000 | JI27: =SUM(A27:JH27) -> 59000 | JJ27: 5041
FS28: 225498 | JI28: =SUM(A28:JH28) -> 225498 | JJ28: 5045
EA29: 192000 | JI29: =SUM(A29:JH29) -> 192000 | JJ29: 5049
FT30: 54000 | JI30: =SUM(A30:JH30) -> 54000 | JJ30: 5054
EA31: 33000 | FT31: 15599.6 | JI31: =SUM(A31:JH31) -> 48599.6 | JJ31: 5058
GH32: 58174 | GK32: 38940 | JI32: =SUM(A32:JH32) -> 97114 | JJ32: 5072
Q33: 51000 | JI33: =SUM(A33:JH33) -> 51000 | JJ33: 5074
R34: 479819.29 | JI34: =SUM(A34:JH34) -> 479819.29 | JJ34: 5076
FT35: 102987.84 | JI35: =SUM(A35:JH35) -> 102987.84 | JJ35: 5082
FQ36: 1207966 | JI36: =SUM(A36:JH36) -> 1207966 | JJ36: 5086
DK37: 292565.2 | JI37: =SUM(A37:JH37) -> 292565.2 | JJ37: 5090
GQ38: 1500000.7 | JI38: =SUM(A38:JH38) -> 1500000.7 | JJ38: 5101
DR39: 557734.03 | JI39: =SUM(A39:JH39) -> 557734.03 | JJ39: 5105
CH40: 5691.23 | JI40: =SUM(A40:JH40) -> 5691.23 | JJ40: 5125
...

Sheet CUENTA T VS
A1: D E S G L O S E D E L A S C U E N T A S
A2: 211101 | B2: 211102 | C2: 211103 | D2: 211104 | E2: 211105 | F2: 211106 | G2: 211203 | H2: 211205 | I2: 211206 | J2: 211208 | K2: 211209 | L2: 211211 | M2: 211301 | N2: 211401 | O2: 211501 | P2: 211502 | Q2: 211503 | R2: 211504 | S2: 212101 | T2: 212201 | U2: 212203 | V2: 212204 | W2: 212205 | X2: 212206 | Y2: 212207 | Z2: 212208 | AA2: 212209 | AB2: 212210 | AC2: 213101 | AD2: 213102 | AE2: 213201 | AF2: 213202 | AG2: 214101 | AH2: 214201 | AI2: 214202 | AJ2: 214203 | AK2: 215101 | AL2: 215201 | AM2: 215301 | AN2: 215401 | AO2: 221101 | AP2: 221201 | AQ2: 221301 | AR2: 221401 | AS2: 221501 | AT2: 221601 | AU2: 221602 | AV2: 221701 | AW2: 221801 | AX2: 222101 | AY2: 222201 | AZ2: 223101 | BA2: 223201 | BB2: 224101 | BC2: 224201 | BD2: 224301 | BE2: 224401 | BF2: 225101 | BG2: 225201 | BH2: 225301 | BI2: 225302 | BJ2: 225303 | BK2: 225304 | BL2: 225305 | BM2: 225401 | BN2: 225501 | BO2: 225601 | BP2: 225701 | BQ2: 225801 | BR2: 225901 | BS2: 226101 | BT2: 226201 | BU2: 226301 | BV2: 226401 | BW2: 227101 | BX2: 227102 | BY2: 227103 | BZ2: 227104 | CA2: 227105 | CB2: 227106 | CC2: 227107 | CD2: 227199 | CE2: 227201 | CF2: 227202 | CG2: 227203 | CH2: 227204 | CI2: 227205 | CJ2: 227206 | CK2: 227207 | CL2: 227208 | CM2: 227299 | CN2: 227301 | CO2: 228101 | CP2: 228201 | CQ2: 228301 | CR2: 228401 | CS2: 228501 | CT2: 228502 | CU2: 228503 | CV2: 228601 | CW2: 228602 | CX2: 228603 | CY2: 228604 | CZ2: 228701 | DA2: 228702 | DB2: 228703 | DC2: 228704 | DD2: 228705 | DE2: 228706 | DF2: 228801 | DG2: 228802 | DH2: 228803 | DI2: 229201 | DJ2: 229203 | DK2: 231101 | DL2: 231102 | DM2: 231201 | DN2: 231301 | DO2: 231302 | DP2: 231303 | DQ2: 231401 | DR2: 232101 | DS2: 232201 | DT2: 232301 | DU2: 233101 | DV2: 233201 | DW2: 233301 | DX2: 233401 | DY2: 233501 | DZ2: 233601 | EA2: 234101 | EB2: 234201 | EC2: 235101 | ED2: 235201 | EE2: 235301 | EF2: 235401 | EG2: 235501 | EH2: 236101 | EI2: 236102 | EJ2: 236103 | EK2: 236104 | EL2: 236105 | EM2: 236201 | EN2: 236202 | EO2: 236203 | EP2: 236304 | EQ2: 236305 | ER2: 236306 | ES2: 236401 | ET2: 236402 | EU2: 236403 | EV2: 236404 | EW2: 236405 | EX2: 236406 | EY2: 236407 | EZ2: 236901 | FA2: 237101 | FB2: 237102 | FC2: 237103 | FD2: 237104 | FE2: 237105 | FF2: 237106 | FG2: 237107 | FH2: 237201 | FI2: 237202 | FJ2: 237203 | FK2: 237204 | FL2: 237205 | FM2: 237206 | FN2: 237299 | FO2: 238101 | FP2: 238201 | FQ2: 239101 | FR2: 239102 | FS2: 239201 | FT2: 239301 | FU2: 239401 | FV2: 239501 | FW2: 239601 | FX2: 239701 | FY2: 239801 | FZ2: 239802 | GA2: 239901 | GB2: 239904 | GC2: 241201 | GD2: 241202 | GE2: 241203 | GF2: 241204 | GG2: 241205 | GH2: 261101 | GI2: 261201 | GJ2: 261301 | GK2: 261401 | GL2: 261901 | GM2: 262101 | GN2: 262201 | GO2: 262301 | GP2: 262401 | GQ2: 263101 | GR2: 263201 | GS2: 263301 | GT2: 263401 | GU2: 264101 | GV2: 264201 | GW2: 264301 | GX2: 264401 | GY2: 264501 | GZ2: 264601 | HA2: 264701 | HB2: 264801 | HC2: 265101 | HD2: 265201 | HE2: 265301 | HF2: 265401 | HG2: 265501 | HH2: 265601 | HI2: 265701 | HJ2: 265801 | HK2: 266101 | HL2: 266201 | HM2: 267101 | HN2: 267201 | HO2: 267301 | HP2: 267401 | HQ2: 267501 | HR2: 267601 | HS2: 267701 | HT2: 267801 | HU2: 267901 | HV2: 268101 | HW2: 268201 | HX2: 268301 | HY2: 268302 | HZ2: 268401 | IA2: 268501 | IB2: 268601 | IC2: 268701 | ID2: 268802 | IE2: 268803 | IF2: 268804 | IG2: 268901 | IH2: 269101 | II2: 269102 | IJ2: 269201 | IK2: 269202 | IL2: 269301 | IM2: 269401 | IN2: 269501 | IO2: 269502 | IP2: 269503 | IQ2: 2269901 | IR2: 271101 | IS2: 271201 | IT2: 271301 | IU2: 271401 | IV2: 272101 | IW2: 272201 | IX2: 272301 | IY2: 272401 | IZ2: 272501 | JA2: 272601 | JB2: 272701 | JC2: 272801 | JD2: 272901 | JE2: 273101 | JF2: 273201 | JG2: 274101 | JH2: 274201 | JI2: Totales | JJ2: TRANSF NO. | JK2: VALOR | JL2: RETENCION | JM2: AÑOS ANTERIORES | JN2: 2022 | JO2: Total | JP2: Proveedor Informal
AW3: 720000 | JI3: =SUM(A3:JH3) -> 720000 | JJ3: 372 | JK3: 684000 | JL3: =+JI3-JK3 -> 36000
CL4: 361378.54 | JI4: =SUM(A4:JH4) -> 361378.54 | JJ4: 373 | JK4: 346065.89 | JL4: =+JI4-JK4 -> 15312.65
FQ5: 158061 | JI5: =SUM(A5:JH5) -> 158061 | JJ5: 379 | JK5: 151363.5 | JL5: =+JI5-JK5 -> 6697.5
DK6: 15000 | JI6: =SUM(A6:JH6) -> 15000 | JJ6: 380 | JK6: 15000 | JL6: =+JI6-JK6 -> 0
DK7: 14000 | JI7: =SUM(A7:JH7) -> 14000 | JJ7: 381 | JK7: 14000 | JL7: =+JI7-JK7 -> 0
HH8: 413000 | JI8: =SUM(A8:JH8) -> 413000 | JJ8: 382 | JK8: 395500 | JL8: =+JI8-JK8 -> 17500
GB9: 175173.19 | JI9: =SUM(A9:JH9) -> 175173.19 | JJ9: 383 | JK9: 166414.53 | JL9: =+JI9-JK9 -> 8758.66
GB10: 244226.81 | JI10: =SUM(A10:JH10) -> 244226.81 | JJ10: 384 | JK10: 233878.22 | JL10: =+JI10-JK10 -> 10348.59
FW11: 41819.2 | JI11: =SUM(A11:JH11) -> 41819.2 | JJ11: 385 | JK11: 40047.2 | JL11: =+JI11-JK11 -> 1772
JI12: =SUM(A12:JH12) -> 0 | JJ12: 386 | JK12: 0 | JL12: =+JI12-JK12 -> 0
CU13: 185260 | JI13: =SUM(A13:JH13) -> 185260 | JJ13: 387 | JK13: 177410 | JL13: =+JI13-JK13 -> 7850
FD14: 21952 | JI14: =SUM(A14:JH14) -> 21952 | JJ14: 388 | JK14: 21952 | JL14: =+JI14-JK14 -> 0
AW15: 25000 | JI15: =SUM(A15:JH15) -> 25000 | JJ15: 389 | JK15: 25000 | JL15: =+JI15-JK15 -> 0
DD16: 244260 | JI16: =SUM(A16:JH16) -> 244260 | JJ16: 390 | JK16: 233910 | JL16: =+JI16-JK16 -> 10350
FN17: 140797.6 | JI17: =SUM(A17:JH17) -> 140797.6 | JJ17: 391 | JK17: 134831.6 | JL17: =+JI17-JK17 -> 5966
GR18: 1899800 | JI18: =SUM(A18:JH18) -> 1899800 | JJ18: 392 | JK18: 1819300 | JL18: =+JI18-JK18 -> 80500
DE19: 16520 | JI19: =SUM(A19:JH19) -> 16520 | JJ19: 393 | JK19: 16520 | JL19: =+JI19-JK19 -> 0
DK20: 41400 | JI20: =SUM(A20:JH20) -> 41400 | JJ20: 394 | JK20: 41400 | JL20: =+JI20-JK20 -> 0
EA21: 270000 | JI21: =SUM(A21:JH21) -> 270000 | JJ21: 395 | JK21: 256500 | JL21: =+JI21-JK21 -> 13500
FQ22: 262500 | JI22: =SUM(A22:JH22) -> 262500 | JJ22: 396 | JK22: 249375 | JL22: =+JI22-JK22 -> 13125
FA23: 172000 | JI23: =SUM(A23:JH23) -> 172000 | JJ23: 397 | JK23: 170573.26 | JL23: =+JI23-JK23 -> 1426.74
DK24: 92925 | JI24: =SUM(A24:JH24) -> 92925 | JJ24: 398 | JK24: 88278.75 | JL24: =+JI24-JK24 -> 4646.25
DE25: 10000 | JI25: =SUM(A25:JH25) -> 10000 | JJ25: 399 | JK25: 10000 | JL25: =+JI25-JK25 -> 0
EA26: 114300 | JI26: =SUM(A26:JH26) -> 114300 | JJ26: 400 | JK26: 108585 | JL26: =+JI26-JK26 -> 5715
EE27: 298561.92 | JI27: =SUM(A27:JH27) -> 298561.92 | JJ27: 401 | JK27: 272247.99 | JL27: =+JI27-JK27 -> 26313.93
GH28: 182234.7 | JI28: =SUM(A28:JH28) -> 182234.7 | JJ28: 402 | JK28: 174512.67 | JL28: =+JI28-JK28 -> 7722.03
AX29: 221258.85 | JI29: =SUM(A29:JH29) -> 221258.85 | JJ29: 403 | JK29: 211883.48 | JL29: =+JI29-JK29 -> 9375.37
GH30: 260210.02 | JI30: =SUM(A30:JH30) -> 260210.02 | JJ30: 404 | JK30: 249184.17 | JL30: =+JI30-JK30 -> 11025.85
FT31: 30444 | JI31: =SUM(A31:JH31) -> 30444 | JJ31: 405 | JK31: 30444 | JL31: =+JI31-JK31 -> 0
FT32: 34220 | JI32: =SUM(A32:JH32) -> 34220 | JJ32: 406 | JK32: 34220 | JL32: =+JI32-JK32 -> 0
DE33: 195000 | JI33: =SUM(A33:JH33) -> 195000 | JJ33: 407 | JK33: 195000 | JL33: =+JI33-JK33 -> 0
DE34: 13260 | JI34: =SUM(A34:JH34) -> 13260 | JJ34: 408 | JK34: 13260 | JL34: =+JI34-JK34 -> 0
JI35: =SUM(A35:JH35) -> 0 | JJ35: 37317 | JK35: 0 | JL35: =+JI35-JK35 -> 0
GA36: 56945.15 | JI36: =SUM(A36:JH36) -> 56945.15 | JJ36: 37318 | JK36: 56945.15 | JL36: =+JI36-JK36 -> 0
BW37: 21673.47 | JI37: =SUM(A37:JH37) -> 21673.47 | JJ37: 37319 | JK37: 18000 | JL37: =+JI37-JK37 -> 3673.47
BW38: 18061.22 | JI38: =SUM(A38:JH38) -> 18061.22 | JJ38: 37320 | JK38: 15000 | JL38: =+JI38-JK38 -> 3061.22
BW39: 18061.22 | JI39: =SUM(A39:JH39) -> 18061.22 | JJ39: 37321 | JK39: 15000 | JL39: =+JI39-JK39 -> 3061.22
GC40: 3600 | JI40: =SUM(A40:JH40) -> 3600 | JJ40: 37322 | JK40: 3600 | JL40: =+JI40-JK40 -> 0
...

Sheet GASTOS X ATENCION
A1: SERVICIO NACIONAL DE SALUD
A2: ='CONS. FUENTES FINAN'!A6 -> HOSPITAL MATERNO INFANTIL SAN LORENZO DE LOS MINA
A3: RESUMEN COMPARATIVO DE GASTOS ESPECIFICOS FONDO 100 Y VENTA DE SERVICIOS
A6: DETALLE | B6: FONDO 100 | C6: VENTA SERVICIOS | D6: TOTAL | E6: %
A8: Atención Directa
A9: Medicamentos e Insumos Médicos | B9: ='CONS. FUENTES FINAN'!G245+'CONS. FUENTES FINAN'!G315 -> 7603116.1 | C9: ='CONS. FUENTES FINAN'!H245+'CONS. FUENTES FINAN'!H315 -> 448964 | D9: =SUM(B9:C9) -> 8052080.1 | E9: =+D9/D12 -> 0.79216828
A10: Oxigeno | B10: ='CONS. FUENTES FINAN'!G302 -> 0 | C10: ='CONS. FUENTES FINAN'!H302 -> 140797.6 | D10: =SUM(B10:C10) -> 140797.6 | E10: =+D10/D12 -> 0.013851749
A11: Reactivos e Insumos de Laboratorio | B11: ='CONS. FUENTES FINAN'!G296+'CONS. FUENTES FINAN'!G297+'CONS. FUENTES FINAN'!G298 -> 1971730.4 | C11: ='CONS. FUENTES FINAN'!H296+'CONS. FUENTES FINAN'!H297+'CONS. FUENTES FINAN'!H298 -> 0 | D11: =SUM(B11:C11) -> 1971730.4 | E11: =+D11/D12 -> 0.19397997
A12: Total | B12: =SUM(B9:B11) -> 9574846.5 | C12: =SUM(C9:C11) -> 589761.6 | D12: =SUM(D9:D11) -> 10164608 | E12: =+D12/D39 -> 0.061807876
A13: Mantenimiento de Equipos
A14: Reparación y Mantenimiento Maquinaria y Eq. | B14: ='CONS. FUENTES FINAN'!G157+'CONS. FUENTES FINAN'!G188+'CONS. FUENTES FINAN'!G223+'CONS. FUENTES FINAN'!G252+'CONS. FUENTES FINAN'!G254+'CONS. FUENTES FINAN'!G256+'CONS. FUENTES FINAN'!G258+'CONS. FUENTES FINAN'!G261+'CONS. FUENTES FINAN'!G292+'CONS. FUENTES FINAN'!G293+'CONS. FUENTES FINAN'!G299+'CONS. FUENTES FINAN'!G300+'CONS. FUENTES FINAN'!G301+'CONS. FUENTES FINAN'!G324 -> 1627102.1 | C14: ='CONS. FUENTES FINAN'!H157+'CONS. FUENTES FINAN'!H188+'CONS. FUENTES FINAN'!H223+'CONS. FUENTES FINAN'!H252+'CONS. FUENTES FINAN'!H254+'CONS. FUENTES FINAN'!H256+'CONS. FUENTES FINAN'!H258+'CONS. FUENTES FINAN'!H261+'CONS. FUENTES FINAN'!H292+'CONS. FUENTES FINAN'!H293+'CONS. FUENTES FINAN'!H299+'CONS. FUENTES FINAN'!H300+'CONS. FUENTES FINAN'!H301+'CONS. FUENTES FINAN'!H324 -> 902996.37 | D14: =SUM(B14:C14) -> 2530098.5 | E14: =+D14/D16 -> 0.98374007
A15: Productos Eléctricos y Afines | B15: ='CONS. FUENTES FINAN'!G320 -> 0 | C15: ='CONS. FUENTES FINAN'!H320 -> 41819.2 | D15: =SUM(B15:C15) -> 41819.2 | E15: =+D15/D16 -> 0.016259929
A16: Total | B16: =SUM(B14:B15) -> 1627102.1 | C16: =SUM(C14:C15) -> 944815.57 | D16: =SUM(D14:D15) -> 2571917.7 | E16: =+D16/D39 -> 0.015639046
A17: Gastos Administrativos
A18: Servicios Personales | B18: ='CONS. FUENTES FINAN'!G26 -> 1.3374081e+08 | C18: ='CONS. FUENTES FINAN'!H26 -> 0 | D18: =SUM(B18:C18) -> 1.3374081e+08 | E18: =+D18/D34 -> 0.94883482
A19: Servicio Telefónico | B19: ='CONS. FUENTES FINAN'!G91+'CONS. FUENTES FINAN'!G93+'CONS. FUENTES FINAN'!G95+'CONS. FUENTES FINAN'!G97 -> 0 | C19: ='CONS. FUENTES FINAN'!H91+'CONS. FUENTES FINAN'!H93+'CONS. FUENTES FINAN'!H95+'CONS. FUENTES FINAN'!H97 -> 0 | D19: =SUM(B19:C19) -> 0 | E19: =+D19/D34 -> 0
A20: Servicios Basicos (electricidad, agua y residuos solidos) | B20: ='CONS. FUENTES FINAN'!G99+'CONS. FUENTES FINAN'!G102+'CONS. FUENTES FINAN'!G104 -> 60535 | C20: ='CONS. FUENTES FINAN'!H99+'CONS. FUENTES FINAN'!H102+'CONS. FUENTES FINAN'!H104 -> 745000 | D20: =SUM(B20:C20) -> 805535 | E20: =+D20/D34 -> 0.0057149321
A21: Viáticos | B21: ='CONS. FUENTES FINAN'!G111 -> 0 | C21: ='CONS. FUENTES FINAN'!H111 -> 0 | D21: =SUM(B21:C21) -> 0 | E21: =+D21/D34 -> 0
A22: Transporte y almacenaje | B22: ='CONS. FUENTES FINAN'!G116 -> 0 | C22: ='CONS. FUENTES FINAN'!H116 -> 20000 | D22: =SUM(B22:C22) -> 20000 | E22: =+D22/D34 -> 0.00014189159
A23: Alquileres | B23: ='CONS. FUENTES FINAN'!G125 -> 0 | C23: ='CONS. FUENTES FINAN'!H125 -> 0 | D23: =SUM(B23:C23) -> 0 | E23: =+D23/D34 -> 0
A24: Comisiones y Gastos Bancarios | B24: ='CONS. FUENTES FINAN'!G182 -> 0 | C24: ='CONS. FUENTES FINAN'!H182 -> 0 | D24: =SUM(B24:C24) -> 0 | E24: =+D24/D34 -> 0
A25: Materiales de Oficina, Impresión y Encuadernación | B25: ='CONS. FUENTES FINAN'!G109+'CONS. FUENTES FINAN'!G312 -> 225498 | C25: ='CONS. FUENTES FINAN'!H109+'CONS. FUENTES FINAN'!H312 -> 0 | D25: =SUM(B25:C25) -> 225498 | E25: =+D25/D34 -> 0.0015998135
A26: Alimentos y Bebidas para Personas | B26: ='CONS. FUENTES FINAN'!G208+'CONS. FUENTES FINAN'!G214+'CONS. FUENTES FINAN'!G217+'CONS. FUENTES FINAN'!G219 -> 292565.2 | C26: ='CONS. FUENTES FINAN'!H208+'CONS. FUENTES FINAN'!H214+'CONS. FUENTES FINAN'!H217+'CONS. FUENTES FINAN'!H219 -> 163325 | D26: =SUM(B26:C26) -> 455890.2 | E26: =+D26/D34 -> 0.0032343493
A27: Productos de papel, carton e impesos | B27: ='CONS. FUENTES FINAN'!G232 -> 1655540 | C27: ='CONS. FUENTES FINAN'!H232 -> 0 | D27: =SUM(B27:C27) -> 1655540 | E27: =+D27/D34 -> 0.01174536
A28: Articulos de Plasticos | B28: ='CONS. FUENTES FINAN'!G259 -> 18154.65 | C28: ='CONS. FUENTES FINAN'!H259 -> 0 | D28: =SUM(B28:C28) -> 18154.65 | E28: =+D28/D34 -> 0.00012879961
A29: Gasolina | B29: ='CONS. FUENTES FINAN'!G288 -> 0 | C29: ='CONS. FUENTES FINAN'!H288 -> 172000 | D29: =SUM(B29:C29) -> 172000 | E29: =+D29/D34 -> 0.0012202677
A30: Gasoil | B30: ='CONS. FUENTES FINAN'!G289+'CONS. FUENTES FINAN'!G290 -> 0 | C30: ='CONS. FUENTES FINAN'!H289+'CONS. FUENTES FINAN'!H290 -> 0 | D30: =SUM(B30:C30) -> 0 | E30: =+D30/D34 -> 0
A31: GLP | B31: ='CONS. FUENTES FINAN'!G291+'CONS. FUENTES FINAN'!G294 -> 0 | C31: ='CONS. FUENTES FINAN'!H291+'CONS. FUENTES FINAN'!H294 -> 21952 | D31: =SUM(B31:C31) -> 21952 | E31: =+D31/D34 -> 0.00015574021
A32: Materiales de Limpieza e Higiene | B32: ='CONS. FUENTES FINAN'!G309 -> 1373621 | C32: ='CONS. FUENTES FINAN'!H309 -> 420561 | D32: =SUM(B32:C32) -> 1794182 | E32: =+D32/D34 -> 0.012728967
A33: Otros Egresos y Gastos | B33: ='CONS. FUENTES FINAN'!G89+'CONS. FUENTES FINAN'!G107+'CONS. FUENTES FINAN'!G148+'CONS. FUENTES FINAN'!G180+'CONS. FUENTES FINAN'!G184+'CONS. FUENTES FINAN'!G186+'CONS. FUENTES FINAN'!G192+'CONS. FUENTES FINAN'!G197+'CONS. FUENTES FINAN'!G204+'CONS. FUENTES FINAN'!G225+'CONS. FUENTES FINAN'!G303+'CONS. FUENTES FINAN'!G316+'CONS. FUENTES FINAN'!G318+'CONS. FUENTES FINAN'!G322+'CONS. FUENTES FINAN'!G327+'CONS. FUENTES FINAN'!G330 -> 848786.03 | C33: ='CONS. FUENTES FINAN'!H89+'CONS. FUENTES FINAN'!H107+'CONS. FUENTES FINAN'!H148+'CONS. FUENTES FINAN'!H180+'CONS. FUENTES FINAN'!H184+'CONS. FUENTES FINAN'!H186+'CONS. FUENTES FINAN'!H192+'CONS. FUENTES FINAN'!H197+'CONS. FUENTES FINAN'!H204+'CONS. FUENTES FINAN'!H225+'CONS. FUENTES FINAN'!H303+'CONS. FUENTES FINAN'!H316+'CONS. FUENTES FINAN'!H318+'CONS. FUENTES FINAN'!H322+'CONS. FUENTES FINAN'!H327+'CONS. FUENTES FINAN'!H330 -> 1194331.2 | D33: =SUM(B33:C33) -> 2043117.3 | E33: =+D33/D34 -> 0.014495058
A34: Total | B34: =SUM(B17:B33) -> 1.3821551e+08 | C34: =SUM(C17:C33) -> 2737169.2 | D34: =SUM(D17:D33) -> 1.4095268e+08 | E34: =+D34/D39 -> 0.85709019
A35: Gastos Inversion y Capital
A36: Bienes Muebles, Inmuebles e Intangibles | B36: ='CONS. FUENTES FINAN'!G336 -> 8010447.3 | C36: ='CONS. FUENTES FINAN'!H336 -> 2755244.7 | D36: =SUM(B36:C36) -> 10765692 | E36: =+D36/D38 -> 1
A37: Obras | B37: ='CONS. FUENTES FINAN'!G463 -> 0 | C37: ='CONS. FUENTES FINAN'!H463 -> 0 | D37: =SUM(B37:C37) -> 0 | E37: =+D37/D38 -> 0
A38: Total | B38: =SUM(B36:B37) -> 8010447.3 | C38: =SUM(C36:C37) -> 2755244.7 | D38: =SUM(D36:D37) -> 10765692 | E38: =+D38/D39 -> 0.065462884
A39: Total General | B39: =+B12+B16+B34+B38 -> 157427908 | C39: =+C12+C16+C34+C38 -> 7026991.1 | D39: =+D12+D16+D34+D38 -> 1.644549e+08 | E39: =+E12+E16+E34+E38 -> 1
A40: Porciento | B40: =+B39/D39 -> 0.95727101 | C40: =+C39/D39 -> 0.042728986 | D40: =+B40+C40 -> 1

Sheet PLANTILLA PRESUPUESTO
A1: SERVICIO NACIONAL DE SALUD
A2: NOMBRE DEL ESTABLECIMIENTO
A3: CONSOLIDADO GASTOS EJECUCION FINANCIERA 2025
A4: En RD$
A6: Detalle | B6: FONDO REPONIBLE | G6: VENTA SEVICIOS/OTROS APORTES | L6: TOTAL
A7: 2 - GASTOS | B7: 1ro | C7: 2do | D7: 3ro | E7: 4to | G7: 1ro | H7: 2do | I7: 3ro | J7: 4to | L7: 1ro | M7: 2do | N7: 3ro | O7: 4to
A8: 2.1 - REMUNERACIONES Y CONTRIBUCIONES | B8: =SUM(B9:B13) -> 1.9856074e+08 | C8: =SUM(C9:C13) -> 1.9977032e+08 | D8: =SUM(D9:D13) -> 2.1475844e+08 | E8: =SUM(E9:E13) -> 2.0672766e+08 | G8: =SUM(G9:G13) -> 5231553.6 | H8: =SUM(H9:H13) -> 0 | I8: =SUM(I9:I13) -> 4413127.6 | J8: =SUM(J9:J13) -> 0 | L8: =SUM(B8+G8) -> 2.0379229e+08 | M8: =SUM(C8+H8) -> 1.9977032e+08 | N8: =SUM(D8+I8) -> 2.1917157e+08 | O8: =SUM(E8+J8) -> 2.0672766e+08
A9: 2.1.1 - REMUNERACIONES | B9: =SUM('TRANSFERENCIA CORRIENTE'!C10:E10) -> 1.639452e+08 | C9: =SUM('TRANSFERENCIA CORRIENTE'!F10:H10) -> 1.6408478e+08 | D9: =SUM('TRANSFERENCIA CORRIENTE'!I10:K10) -> 1.775012e+08 | E9: =SUM('TRANSFERENCIA CORRIENTE'!L10:N10) -> 1.8153111e+08 | G9: =SUM(VS!C10:E10) -> 0 | H9: =SUM(VS!F10:H10) -> 0 | I9: =SUM(VS!I10:K10) -> 0 | J9: =SUM(VS!L10:N10) -> 0 | L9: =SUM(B9+G9) -> 1.639452e+08 | M9: =SUM(C9+H9) -> 1.6408478e+08 | N9: =SUM(D9+I9) -> 1.775012e+08 | O9: =SUM(E9+J9) -> 1.8153111e+08
A10: 2.1.2 - SOBRESUELDOS | B10: =SUM('TRANSFERENCIA CORRIENTE'!C11:E11) -> 9594398.8 | C10: =SUM('TRANSFERENCIA CORRIENTE'!F11:H11) -> 10535799 | D10: =SUM('TRANSFERENCIA CORRIENTE'!I11:K11) -> 10034891 | E10: =SUM('TRANSFERENCIA CORRIENTE'!L11:N11) -> 6610497.3 | G10: =SUM(VS!C11:E11) -> 5231553.6 | H10: =SUM(VS!F11:H11) -> 0 | I10: =SUM(VS!I11:K11) -> 4413127.6 | J10: =SUM(VS!L11:N11) -> 0 | L10: =SUM(B10+G10) -> 14825952 | M10: =SUM(C10+H10) -> 10535799 | N10: =SUM(D10+I10) -> 14448019 | O10: =SUM(E10+J10) -> 6610497.3
A11: 2.1.3 - DIETAS Y GASTOS DE REPRESENTACIÓN | B11: =SUM('TRANSFERENCIA CORRIENTE'!C12:E12) -> 0 | C11: =SUM('TRANSFERENCIA CORRIENTE'!F12:H12) -> 0 | D11: =SUM('TRANSFERENCIA CORRIENTE'!I12:K12) -> 0 | E11: =SUM('TRANSFERENCIA CORRIENTE'!L12:N12) -> 0 | G11: =SUM(VS!C12:E12) -> 0 | H11: =SUM(VS!F12:H12) -> 0 | I11: =SUM(VS!I12:K12) -> 0 | J11: =SUM(VS!L12:N12) -> 0 | L11: =SUM(B11+G11) -> 0 | M11: =SUM(C11+H11) -> 0 | N11: =SUM(D11+I11) -> 0 | O11: =SUM(E11+J11) -> 0
A12: 2.1.4 - GRATIFICACIONES Y BONIFICACIONES | B12: =SUM('TRANSFERENCIA CORRIENTE'!C13:E13) -> 0 | C12: =SUM('TRANSFERENCIA CORRIENTE'!F13:H13) -> 0 | D12: =SUM('TRANSFERENCIA CORRIENTE'!I13:K13) -> 0 | E12: =SUM('TRANSFERENCIA CORRIENTE'!L13:N13) -> 0 | G12: =SUM(VS!C13:E13) -> 0 | H12: =SUM(VS!F13:H13) -> 0 | I12: =SUM(VS!I13:K13) -> 0 | J12: =SUM(VS!L13:N13) -> 0 | L12: =SUM(B12+G12) -> 0 | M12: =SUM(C12+H12) -> 0 | N12: =SUM(D12+I12) -> 0 | O12: =SUM(E12+J12) -> 0
A13: 2.1.5 - CONTRIBUCIONES A LA SEGURIDAD SOCIAL | B13: =SUM('TRANSFERENCIA CORRIENTE'!C14:E14) -> 25021132 | C13: =SUM('TRANSFERENCIA CORRIENTE'!F14:H14) -> 25149742 | D13: =SUM('TRANSFERENCIA CORRIENTE'!I14:K14) -> 27222347 | E13: =SUM('TRANSFERENCIA CORRIENTE'!L14:N14) -> 18586055 | G13: =SUM(VS!C14:E14) -> 0 | H13: =SUM(VS!F14:H14) -> 0 | I13: =SUM(VS!I14:K14) -> 0 | J13: =SUM(VS!L14:N14) -> 0 | L13: =SUM(B13+G13) -> 25021132 | M13: =SUM(C13+H13) -> 25149742 | N13: =SUM(D13+I13) -> 27222347 | O13: =SUM(E13+J13) -> 18586055
A14: 2.2 - CONTRATACIÓN DE SERVICIOS | B14: =SUM(B15:B23) -> 9308364.9 | C14: =SUM(C15:C23) -> 10131818 | D14: =SUM(D15:D23) -> 11703690 | E14: =SUM(E15:E23) -> 2689695.2 | G14: =SUM(G15:G23) -> 8306683.8 | H14: =SUM(H15:H23) -> 7239413.8 | I14: =SUM(I15:I23) -> 10378416 | J14: =SUM(J15:J23) -> 4048661.9 | L14: =SUM(B14+G14) -> 17615049 | M14: =SUM(C14+H14) -> 17371232 | N14: =SUM(D14+I14) -> 22082105 | O14: =SUM(E14+J14) -> 6738357.1
A15: 2.2.1 - SERVICIOS BÁSICOS | B15: =SUM('TRANSFERENCIA CORRIENTE'!C16:E16) -> 2020024.3 | C15: =SUM('TRANSFERENCIA CORRIENTE'!F16:H16) -> 181605 | D15: =SUM('TRANSFERENCIA CORRIENTE'!J16:L16) -> 181605 | E15: =SUM('TRANSFERENCIA CORRIENTE'!L16:N16) -> 121070 | G15: =SUM(VS!C16:E16) -> 2341561.9 | H15: =SUM(VS!F16:H16) -> 2348580.7 | I15: =SUM(VS!I16:K16) -> 2876937.6 | J15: =SUM(VS!L16:N16) -> 1913099.9 | L15: =SUM(B15+G15) -> 4361586.2 | M15: =SUM(C15+H15) -> 2530185.7 | N15: =SUM(D15+I15) -> 3058542.6 | O15: =SUM(E15+J15) -> 2034169.9
A16: 2.2.2 - PUBLICIDAD, IMPRESIÓN Y ENCUADERNACIÓN | B16: =SUM('TRANSFERENCIA CORRIENTE'!C17:E17) -> 324206.83 | C16: =SUM('TRANSFERENCIA CORRIENTE'!F17:H17) -> 351993.83 | D16: =SUM('TRANSFERENCIA CORRIENTE'!J17:L17) -> 190472.3 | E16: =SUM('TRANSFERENCIA CORRIENTE'!L17:N17) -> 54044 | G16: =SUM(VS!C17:E17) -> 0 | H16: =SUM(VS!F17:H17) -> 310139.4 | I16: =SUM(VS!I17:K17) -> 1187725.2 | J16: =SUM(VS!L17:N17) -> 221258.85 | L16: =SUM(B16+G16) -> 324206.83 | M16: =SUM(C16+H16) -> 662133.23 | N16: =SUM(D16+I16) -> 1378197.5 | O16: =SUM(E16+J16) -> 275302.85
A17: 2.2.3 - VIÁTICOS | B17: =SUM('TRANSFERENCIA CORRIENTE'!C18:E18) -> 0 | C17: =SUM('TRANSFERENCIA CORRIENTE'!F18:H18) -> 0 | D17: =SUM('TRANSFERENCIA CORRIENTE'!J18:L18) -> 0 | E17: =SUM('TRANSFERENCIA CORRIENTE'!L18:N18) -> 0 | G17: =SUM(VS!C18:E18) -> 0 | H17: =SUM(VS!F18:H18) -> 0 | I17: =SUM(VS!I18:K18) -> 0 | J17: =SUM(VS!L18:N18) -> 40000 | L17: =SUM(B17+G17) -> 0 | M17: =SUM(C17+H17) -> 0 | N17: =SUM(D17+I17) -> 0 | O17: =SUM(E17+J17) -> 40000
A18: 2.2.4 - TRANSPORTE Y ALMACENAJE | B18: =SUM('TRANSFERENCIA CORRIENTE'!C19:E19) -> 0 | C18: =SUM('TRANSFERENCIA CORRIENTE'!F19:H19) -> 0 | D18: =SUM('TRANSFERENCIA CORRIENTE'!J19:L19) -> 0 | E18: =SUM('TRANSFERENCIA CORRIENTE'!L19:N19) -> 0 | G18: =SUM(VS!C19:E19) -> 56000 | H18: =SUM(VS!F19:H19) -> 96000 | I18: =SUM(VS!I19:K19) -> 76000 | J18: =SUM(VS!L19:N19) -> 20000 | L18: =SUM(B18+G18) -> 56000 | M18: =SUM(C18+H18) -> 96000 | N18: =SUM(D18+I18) -> 76000 | O18: =SUM(E18+J18) -> 20000
A19: 2.2.5 - ALQUILERES Y RENTAS | B19: =SUM('TRANSFERENCIA CORRIENTE'!C20:E20) -> 0 | C19: =SUM('TRANSFERENCIA CORRIENTE'!F20:H20) -> 150000 | D19: =SUM('TRANSFERENCIA CORRIENTE'!J20:L20) -> 448561.92 | E19: =SUM('TRANSFERENCIA CORRIENTE'!L20:N20) -> 298561.92 | G19: =SUM(VS!C20:E20) -> 519625.15 | H19: =SUM(VS!F20:H20) -> 759170.42 | I19: =SUM(VS!I20:K20) -> 927025.64 | J19: =SUM(VS!L20:N20) -> 298143.38 | L19: =SUM(B19+G19) -> 519625.15 | M19: =SUM(C19+H19) -> 909170.42 | N19: =SUM(D19+I19) -> 1375587.6 | O19: =SUM(E19+J19) -> 596705.3
A20: 2.2.6 - SEGUROS | B20: =SUM('TRANSFERENCIA CORRIENTE'!C21:E21) -> 0 | C20: =SUM('TRANSFERENCIA CORRIENTE'!F21:H21) -> 0 | D20: =SUM('TRANSFERENCIA CORRIENTE'!J21:L21) -> 0 | E20: =SUM('TRANSFERENCIA CORRIENTE'!L21:N21) -> 0 | G20: =SUM(VS!C21:E21) -> 0 | H20: =SUM(VS!F21:H21) -> 0 | I20: =SUM(VS!I21:K21) -> 0 | J20: =SUM(VS!L21:N21) -> 3449.08 | L20: =SUM(B20+G20) -> 0 | M20: =SUM(C20+H20) -> 0 | N20: =SUM(D20+I20) -> 0 | O20: =SUM(E20+J20) -> 3449.08
A21: 2.2.7 - SERVICIOS DE CONSERVACIÓN, REPARACIONES MENORES E INSTALACIONES TEMPORALES | B21: =SUM('TRANSFERENCIA CORRIENTE'!C22:E22) -> 6474433.8 | C21: =SUM('TRANSFERENCIA CORRIENTE'!F22:H22) -> 5611474.3 | D21: =SUM('TRANSFERENCIA CORRIENTE'!J22:L22) -> 4467039.5 | E21: =SUM('TRANSFERENCIA CORRIENTE'!L22:N22) -> 1669019.3 | G21: =SUM(VS!C22:E22) -> 4556850.1 | H21: =SUM(VS!F22:H22) -> 1040817.6 | I21: =SUM(VS!I22:K22) -> 3360268.8 | J21: =SUM(VS!L22:N22) -> 425674.45 | L21: =SUM(B21+G21) -> 11031284 | M21: =SUM(C21+H21) -> 6652291.9 | N21: =SUM(D21+I21) -> 7827308.2 | O21: =SUM(E21+J21) -> 2094693.7
A22: 2.2.8 - OTROS SERVICIOS NO INCLUIDOS EN CONCEPTOS ANTERIORES | B22: =SUM('TRANSFERENCIA CORRIENTE'!C23:E23) -> 489700 | C22: =SUM('TRANSFERENCIA CORRIENTE'!F23:H23) -> 413000 | D22: =SUM('TRANSFERENCIA CORRIENTE'!J23:L23) -> 4101500 | E22: =SUM('TRANSFERENCIA CORRIENTE'!L23:N23) -> 547000 | G22: =SUM(VS!C23:E23) -> 832646.66 | H22: =SUM(VS!F23:H23) -> 1774418.3 | I22: =SUM(VS!I23:K23) -> 1400729.1 | J22: =SUM(VS!L23:N23) -> 1127036.2 | L22: =SUM(B22+G22) -> 1322346.7 | M22: =SUM(C22+H22) -> 2187418.3 | N22: =SUM(D22+I22) -> 5502229.1 | O22: =SUM(E22+J22) -> 1674036.2
A23: 2.2.9 - OTRAS CONTRATACIONES DE SERVICIOS | B23: =SUM('TRANSFERENCIA CORRIENTE'!C24:E24) -> 0 | C23: =SUM('TRANSFERENCIA CORRIENTE'!F24:H24) -> 3423745 | D23: =SUM('TRANSFERENCIA CORRIENTE'!J24:L24) -> 2314511 | E23: =SUM('TRANSFERENCIA CORRIENTE'!L24:N24) -> 0 | G23: =SUM(VS!C24:E24) -> 0 | H23: =SUM(VS!F24:H24) -> 910287.4 | I23: =SUM(VS!I24:K24) -> 549729.55 | J23: =SUM(VS!L24:N24) -> 0 | L23: =SUM(B23+G23) -> 0 | M23: =SUM(C23+H23) -> 4334032.4 | N23: =SUM(D23+I23) -> 2864240.5 | O23: =SUM(E23+J23) -> 0
A24: 2.3 - MATERIALES Y SUMINISTROS | B24: =SUM(B25:B33) -> 46153283 | C24: =SUM(C25:C33) -> 52385651 | D24: =SUM(D25:D33) -> 1.0378694e+08 | E24: =SUM(E25:E33) -> 45676288 | G24: =SUM(G25:G33) -> 7292547.3 | H24: =SUM(H25:H33) -> 6552680.6 | I24: =SUM(I25:I33) -> 9091857.1 | J24: =SUM(J25:J33) -> 8069838.1 | L24: =SUM(B24+G24) -> 53445831 | M24: =SUM(C24+H24) -> 58938331 | N24: =SUM(D24+I24) -> 1.128788e+08 | O24: =SUM(E24+J24) -> 53746126
A25: 2.3.1 - ALIMENTOS Y PRODUCTOS AGROFORESTALES | B25: =SUM('TRANSFERENCIA CORRIENTE'!C26:E26) -> 3713897.2 | C25: =SUM('TRANSFERENCIA CORRIENTE'!F26:H26) -> 4866999.2 | D25: =SUM('TRANSFERENCIA CORRIENTE'!I23:K23) -> 3779000 | E25: =SUM('TRANSFERENCIA CORRIENTE'!L26:N26) -> 1904370.2 | G25: =SUM(VS!C26:E26) -> 1500755.8 | H25: =SUM(VS!F26:H26) -> 663230 | I25: =SUM(VS!I26:K26) -> 1574425.7 | J25: =SUM(VS!L26:N26) -> 448552 | L25: =SUM(B25+G25) -> 5214653 | M25: =SUM(C25+H25) -> 5530229.2 | N25: =SUM(D25+I25) -> 5353425.7 | O25: =SUM(E25+J25) -> 2352922.2
A26: 2.3.2 - TEXTILES Y VESTUARIOS | B26: =SUM('TRANSFERENCIA CORRIENTE'!C27:E27) -> 61630.73 | C26: =SUM('TRANSFERENCIA CORRIENTE'!F27:H27) -> 2375399.4 | D26: =SUM('TRANSFERENCIA CORRIENTE'!I24:K24) -> 2314511 | E26: =SUM('TRANSFERENCIA CORRIENTE'!L27:N27) -> 624994.03 | G26: =SUM(VS!C27:E27) -> 0 | H26: =SUM(VS!F27:H27) -> 346306.4 | I26: =SUM(VS!I27:K27) -> 0 | J26: =SUM(VS!L27:N27) -> 0 | L26: =SUM(B26+G26) -> 61630.73 | M26: =SUM(C26+H26) -> 2721705.8 | N26: =SUM(D26+I26) -> 2314511 | O26: =SUM(E26+J26) -> 624994.03
A27: 2.3.3 - PRODUCTOS DE PAPEL, CARTÓN E IMPRESOS | B27: =SUM('TRANSFERENCIA CORRIENTE'!C28:E28) -> 1826911.8 | C27: =SUM('TRANSFERENCIA CORRIENTE'!F28:H28) -> 2991695.7 | D27: =SUM('TRANSFERENCIA CORRIENTE'!I25:K25) -> 65609607 | E27: =SUM('TRANSFERENCIA CORRIENTE'!L28:N28) -> 2540026 | G27: =SUM(VS!C28:E28) -> 251163 | H27: =SUM(VS!F28:H28) -> 803989 | I27: =SUM(VS!I28:K28) -> 734332.03 | J27: =SUM(VS!L28:N28) -> 0 | L27: =SUM(B27+G27) -> 2078074.8 | M27: =SUM(C27+H27) -> 3795684.7 | N27: =SUM(D27+I27) -> 66343939 | O27: =SUM(E27+J27) -> 2540026
A28: 2.3.4 - PRODUCTOS FARMACÉUTICOS | B28: =SUM('TRANSFERENCIA CORRIENTE'!C29:E29) -> 10797336 | C28: =SUM('TRANSFERENCIA CORRIENTE'!F29:H29) -> 12009357 | D28: =SUM('TRANSFERENCIA CORRIENTE'!I26:K26) -> 6044845.1 | E28: =SUM('TRANSFERENCIA CORRIENTE'!L29:N29) -> 6533049.3 | G28: =SUM(VS!C29:E29) -> 558000 | H28: =SUM(VS!F29:H29) -> 402220.76 | I28: =SUM(VS!I29:K29) -> 496000 | J28: =SUM(VS!L29:N29) -> 2567560 | L28: =SUM(B28+G28) -> 11355336 | M28: =SUM(C28+H28) -> 12411577 | N28: =SUM(D28+I28) -> 6540845.1 | O28: =SUM(E28+J28) -> 9100609.3
A29: 2.3.5 - PRODUCTOS DE CUERO, CAUCHO Y PLÁSTICO | B29: =SUM('TRANSFERENCIA CORRIENTE'!C30:E30) -> 334708.95 | C29: =SUM('TRANSFERENCIA CORRIENTE'!F30:H30) -> 1024240.4 | D29: =SUM('TRANSFERENCIA CORRIENTE'!I27:K27) -> 3015806.8 | E29: =SUM('TRANSFERENCIA CORRIENTE'!L30:N30) -> 641356.08 | G29: =SUM(VS!C30:E30) -> 567494.87 | H29: =SUM(VS!F30:H30) -> 0 | I29: =SUM(VS!I30:K30) -> 140314.78 | J29: =SUM(VS!L30:N30) -> 298561.92 | L29: =SUM(B29+G29) -> 902203.82 | M29: =SUM(C29+H29) -> 1024240.4 | N29: =SUM(D29+I29) -> 3156121.5 | O29: =SUM(E29+J29) -> 939918
A30: 2.3.6 - PRODUCTOS DE MINERALES, METÁLICOS Y NO METÁLICOS | B30: =SUM('TRANSFERENCIA CORRIENTE'!C31:E31) -> 11630.98 | C30: =SUM('TRANSFERENCIA CORRIENTE'!F31:H31) -> 667620.59 | D30: =SUM('TRANSFERENCIA CORRIENTE'!I28:K28) -> 2859834.4 | E30: =SUM('TRANSFERENCIA CORRIENTE'!L31:N31) -> 236465.7 | G30: =SUM(VS!C31:E31) -> 293957.3 | H30: =SUM(VS!F31:H31) -> 0 | I30: =SUM(VS!I31:K31) -> 211552.06 | J30: =SUM(VS!L31:N31) -> 875.01 | L30: =SUM(B30+G30) -> 305588.28 | M30: =SUM(C30+H30) -> 667620.59 | N30: =SUM(D30+I30) -> 3071386.4 | O30: =SUM(E30+J30) -> 237340.71
A31: 2.3.7 - COMBUSTIBLES, LUBRICANTES, PRODUCTOS QUÍMICOS Y CONEXOS | B31: =SUM('TRANSFERENCIA CORRIENTE'!C32:E32) -> 8910102 | C31: =SUM('TRANSFERENCIA CORRIENTE'!F32:H32) -> 10068979 | D31: =SUM('TRANSFERENCIA CORRIENTE'!I29:K29) -> 19203378 | E31: =SUM('TRANSFERENCIA CORRIENTE'!L32:N32) -> 21413947 | G31: =SUM(VS!C32:E32) -> 1660334.6 | H31: =SUM(VS!F32:H32) -> 1500202 | I31: =SUM(VS!I32:K32) -> 2324461 | J31: =SUM(VS!L32:N32) -> 1113655 | L31: =SUM(B31+G31) -> 10570437 | M31: =SUM(C31+H31) -> 11569181 | N31: =SUM(D31+I31) -> 21527839 | O31: =SUM(E31+J31) -> 22527602
A32: 2.3.8 - GASTOS QUE SE ASIGNARÁN DURANTE EL EJERCICIO (ART. 32 Y 33 LEY 423-06) | B32: =SUM('TRANSFERENCIA CORRIENTE'!C33:E33) -> 0 | C32: =SUM('TRANSFERENCIA CORRIENTE'!F33:H33) -> 0 | D32: =SUM('TRANSFERENCIA CORRIENTE'!I30:K30) -> 673453.82 | E32: =SUM('TRANSFERENCIA CORRIENTE'!L33:N33) -> 0 | G32: =SUM(VS!C33:E33) -> 0 | H32: =SUM(VS!F33:H33) -> 0 | I32: =SUM(VS!I33:K33) -> 0 | J32: =SUM(VS!L33:N33) -> 0 | L32: =SUM(B32+G32) -> 0 | M32: =SUM(C32+H32) -> 0 | N32: =SUM(D32+I32) -> 673453.82 | O32: =SUM(E32+J32) -> 0
A33: 2.3.9 - PRODUCTOS Y ÚTILES VARIOS | B33: =SUM('TRANSFERENCIA CORRIENTE'!C34:E34) -> 20497066 | C33: =SUM('TRANSFERENCIA CORRIENTE'!F34:H34) -> 18381359 | D33: =SUM('TRANSFERENCIA CORRIENTE'!I31:K31) -> 286504 | E33: =SUM('TRANSFERENCIA CORRIENTE'!L34:N34) -> 11782079 | G33: =SUM(VS!C34:E34) -> 2460841.8 | H33: =SUM(VS!F34:H34) -> 2836732.4 | I33: =SUM(VS!I34:K34) -> 3610771.5 | J33: =SUM(VS!L34:N34) -> 3640634.2 | L33: =SUM(B33+G33) -> 22957908 | M33: =SUM(C33+H33) -> 21218092 | N33: =SUM(D33+I33) -> 3897275.5 | O33: =SUM(E33+J33) -> 15422714
A34: 2.4 - TRANSFERENCIAS CORRIENTES | B34: =SUM(B35:B41) -> 0 | C34: =SUM(C35:C41) -> 0 | D34: =SUM(D35:D41) -> 0 | E34: =SUM(E35:E41) -> 0 | G34: =SUM(G35:G41) -> 287786.7 | H34: =SUM(H35:H41) -> 1223981 | I34: =SUM(I35:I41) -> 122771 | J34: =SUM(J35:J41) -> 3600 | L34: =SUM(B34+G34) -> 287786.7 | M34: =SUM(C34+H34) -> 1223981 | N34: =SUM(D34+I34) -> 122771 | O34: =SUM(E34+J34) -> 3600
A35: 2.4.1 - TRANSFERENCIAS CORRIENTES AL SECTOR PRIVADO | B35: =SUM('TRANSFERENCIA CORRIENTE'!C36:E36) -> 0 | C35: =SUM('TRANSFERENCIA CORRIENTE'!F36:H36) -> 0 | D35: =SUM('TRANSFERENCIA CORRIENTE'!I36:K36) -> 0 | E35: =SUM('TRANSFERENCIA CORRIENTE'!L36:N36) -> 0 | G35: =SUM(VS!C36:E36) -> 287786.7 | H35: =SUM(VS!F36:H36) -> 1223981 | I35: =SUM(VS!I36:K36) -> 122771 | J35: =SUM(VS!L36:N36) -> 3600 | L35: =SUM(B35+G35) -> 287786.7 | M35: =SUM(C35+H35) -> 1223981 | N35: =SUM(D35+I35) -> 122771 | O35: =SUM(E35+J35) -> 3600
A36: 2.4.2 - TRANSFERENCIAS CORRIENTES AL GOBIERNO GENERAL NACIONAL | B36: =SUM('TRANSFERENCIA CORRIENTE'!C37:E37) -> 0 | C36: =SUM('TRANSFERENCIA CORRIENTE'!F37:H37) -> 0 | D36: =SUM('TRANSFERENCIA CORRIENTE'!I37:K37) -> 0 | E36: =SUM('TRANSFERENCIA CORRIENTE'!L37:N37) -> 0 | G36: =SUM(VS!C37:E37) -> 0 | H36: =SUM(VS!F37:H37) -> 0 | I36: =SUM(VS!I37:K37) -> 0 | J36: =SUM(VS!L37:N37) -> 0 | L36: =SUM(B36+G36) -> 0 | M36: =SUM(C36+H36) -> 0 | N36: =SUM(D36+I36) -> 0 | O36: =SUM(E36+J36) -> 0
A37: 2.4.3 - TRANSFERENCIAS CORRIENTES A GOBIERNOS GENERALES LOCALES | B37: =SUM('TRANSFERENCIA CORRIENTE'!C38:E38) -> 0 | C37: =SUM('TRANSFERENCIA CORRIENTE'!F38:H38) -> 0 | D37: =SUM('TRANSFERENCIA CORRIENTE'!I38:K38) -> 0 | E37: =SUM('TRANSFERENCIA CORRIENTE'!L38:N38) -> 0 | G37: =SUM(VS!C38:E38) -> 0 | H37: =SUM(VS!F38:H38) -> 0 | I37: =SUM(VS!I38:K38) -> 0 | J37: =SUM(VS!L38:N38) -> 0 | L37: =SUM(B37+G37) -> 0 | M37: =SUM(C37+H37) -> 0 | N37: =SUM(D37+I37) -> 0 | O37: =SUM(E37+J37) -> 0
A38: 2.4.4 - TRANSFERENCIAS CORRIENTES A EMPRESAS PÚBLICAS NO FINANCIERAS | B38: =SUM('TRANSFERENCIA CORRIENTE'!C39:E39) -> 0 | C38: =SUM('TRANSFERENCIA CORRIENTE'!F39:H39) -> 0 | D38: =SUM('TRANSFERENCIA CORRIENTE'!I39:K39) -> 0 | E38: =SUM('TRANSFERENCIA CORRIENTE'!L39:N39) -> 0 | G38: =SUM(VS!C39:E39) -> 0 | H38: =SUM(VS!F39:H39) -> 0 | I38: =SUM(VS!I39:K39) -> 0 | J38: =SUM(VS!L39:N39) -> 0 | L38: =SUM(B38+G38) -> 0 | M38: =SUM(C38+H38) -> 0 | N38: =SUM(D38+I38) -> 0 | O38: =SUM(E38+J38) -> 0
A39: 2.4.5 - TRANSFERENCIAS CORRIENTES A INSTITUCIONES PÚBLICAS FINANCIERAS | B39: =SUM('TRANSFERENCIA CORRIENTE'!C40:E40) -> 0 | C39: =SUM('TRANSFERENCIA CORRIENTE'!F40:H40) -> 0 | D39: =SUM('TRANSFERENCIA CORRIENTE'!I40:K40) -> 0 | E39: =SUM('TRANSFERENCIA CORRIENTE'!L40:N40) -> 0 | G39: =SUM(VS!C40:E40) -> 0 | H39: =SUM(VS!F40:H40) -> 0 | I39: =SUM(VS!I40:K40) -> 0 | J39: =SUM(VS!L40:N40) -> 0 | L39: =SUM(B39+G39) -> 0 | M39: =SUM(C39+H39) -> 0 | N39: =SUM(D39+I39) -> 0 | O39: =SUM(E39+J39) -> 0
A40: 2.4.7 - TRANSFERENCIAS CORRIENTES AL SECTOR EXTERNO | B40: =SUM('TRANSFERENCIA CORRIENTE'!C41:E41) -> 0 | C40: =SUM('TRANSFERENCIA CORRIENTE'!F41:H41) -> 0 | D40: =SUM('TRANSFERENCIA CORRIENTE'!I41:K41) -> 0 | E40: =SUM('TRANSFERENCIA CORRIENTE'!L41:N41) -> 0 | G40: =SUM(VS!C41:E41) -> 0 | H40: =SUM(VS!F41:H41) -> 0 | I40: =SUM(VS!I41:K41) -> 0 | J40: =SUM(VS!L41:N41) -> 0 | L40: =SUM(B40+G40) -> 0 | M40: =SUM(C40+H40) -> 0 | N40: =SUM(D40+I40) -> 0 | O40: =SUM(E40+J40) -> 0
A41: 2.4.9 - TRANSFERENCIAS CORRIENTES A OTRAS INSTITUCIONES PÚBLICAS | B41: =SUM('TRANSFERENCIA CORRIENTE'!C42:E42) -> 0 | C41: =SUM('TRANSFERENCIA CORRIENTE'!F42:H42) -> 0 | D41: =SUM('TRANSFERENCIA CORRIENTE'!I42:K42) -> 0 | E41: =SUM('TRANSFERENCIA CORRIENTE'!L42:N42) -> 0 | G41: =SUM(VS!C42:E42) -> 0 | H41: =SUM(VS!F42:H42) -> 0 | I41: =SUM(VS!I42:K42) -> 0 | J41: =SUM(VS!L42:N42) -> 0 | L41: =SUM(B41+G41) -> 0 | M41: =SUM(C41+H41) -> 0 | N41: =SUM(D41+I41) -> 0 | O41: =SUM(E41+J41) -> 0
...

Sheet Sheet2

Sheet TRANSFERENCIA CORRIENTE
A1: SERVICIO NACIONAL DE SALUD
A2: HOSPITAL MATERNO INFANTIL SAN LORENZO DE LOS MINA
A3: REGION
A4: Ejecución de Gastos Fondo (100) 2025
A5: En RD$
A7: Detalle | B7: Total | C7: Enero | D7: Febrero | E7: Marzo | F7: Abril | G7: Mayo | H7: Junio | I7: Julio | J7: Agosto | K7: Septiembre | L7: Octubre | M7: Noviembre | N7: Diciembre
A8: 2 - GASTOS
A9: 2.1 - REMUNERACIONES Y CONTRIBUCIONES | B9: =SUM(B10:B14) -> 8.1981716e+08 | C9: 65091180 | D9: 67131936 | E9: 66337620 | F9: 66556156 | G9: 66630551 | H9: 66583615 | I9: 71335676 | J9: 71831261 | K9: =SUM(K10:K14) -> 71591504 | L9: =SUM(L10:L14) -> 72986847 | M9: =SUM(M10:M14) -> 1.3374081e+08 | N9: 0
A10: 2.1.1 - REMUNERACIONES | B10: =SUM(C10:N10) -> 6.870623e+08 | C10: 53640339 | D10: 55586129 | E10: 54718737 | F10: 54771097 | G10: 54445140 | H10: 54868543 | I10: 58925421 | J10: 59410356 | K10: 59165425 | L10: 60398098 | M10: 1.2113301e+08
A11: 2.1.2 - SOBRESUELDOS | B11: =SUM(C11:N11) -> 36775586 | C11: 3196999.6 | D11: 3197999.6 | E11: 3199399.6 | F11: 3384964.5 | G11: 3807608.3 | H11: 3343226.2 | I11: 3344880.2 | J11: 3368105.6 | K11: 3321905.6 | L11: 3295047.1 | M11: 3315450.2
A12: 2.1.3 - DIETAS Y GASTOS DE REPRESENTACIÓN | B12: =SUM(C12:N12) -> 0
A13: 2.1.4 - GRATIFICACIONES Y BONIFICACIONES | B13: =SUM(C13:N13) -> 0
A14: 2.1.5 - CONTRIBUCIONES A LA SEGURIDAD SOCIAL | B14: =SUM(C14:N14) -> 95979276 | C14: 8253841.6 | D14: 8347807.5 | E14: 8419483.2 | F14: 8400093.9 | G14: 8377802.1 | H14: 8371846.2 | I14: 9065374.6 | J14: 9052799.4 | K14: 9104173.4 | L14: 9293701.9 | M14: 9292352.7
A15: 2.2 - CONTRATACIÓN DE SERVICIOS | B15: =SUM(C15:N15) -> 36550236 | C15: 0 | D15: 1336968.6 | E15: 7971396.2 | F15: 210535 | G15: 1680824.8 | H15: 8240458.4 | I15: 3509565.8 | J15: 3128332.8 | K15: =SUM(K16:K24) -> 7782458.8 | L15: =SUM(L16:L24) -> 792898.06 | M15: =SUM(M16:M24) -> 1896797.1 | N15: 0
A16: 2.2.1 - SERVICIOS BÁSICOS | B16: =SUM(C16:N16) -> 2504304.3 | E16: 2020024.3 | F16: 60535 | G16: 60535 | H16: 60535 | I16: 60535 | J16: 60535 | K16: 60535 | L16: 60535 | M16: 60535
A17: 2.2.2 - PUBLICIDAD, IMPRESIÓN Y ENCUADERNACIÓN | B17: =SUM(C17:N17) -> 866672.96 | D17: 324206.83 | G17: 32889.84 | H17: 319103.99 | J17: 88795 | K17: 47633.3 | L17: 54044
A18: 2.2.3 - VIÁTICOS | B18: =SUM(C18:N18) -> 0
A19: 2.2.4 - TRANSPORTE Y ALMACENAJE | B19: =SUM(C19:N19) -> 0
A20: 2.2.5 - ALQUILERES Y RENTAS | B20: =SUM(C20:N20) -> 598561.92 | F20: 150000 | J20: 150000 | L20: 298561.92
A21: 2.2.6 - SEGUROS | B21: =SUM(C21:N21) -> 0
A22: 2.2.7 - SERVICIOS DE CONSERVACIÓN, REPARACIONES MENORES E INSTALACIONES TEMPORALES | B22: =SUM(C22:N22) -> 21613740 | D22: 523061.81 | E22: 5951371.9 | G22: 1174400 | H22: 4437074.3 | I22: 3449030.8 | J22: 2829002.8 | K22: 1580779.5 | L22: 57257.14 | M22: 1611762.1
A23: 2.2.8 - OTROS SERVICIOS NO INCLUIDOS EN CONCEPTOS ANTERIORES | B23: =SUM(C23:N23) -> 5228700 | D23: 489700 | G23: 413000 | K23: 3779000 | L23: 322500 | M23: 224500
A24: 2.2.9 - OTRAS CONTRATACIONES DE SERVICIOS | B24: =SUM(C24:N24) -> 5738256 | H24: 3423745 | K24: 2314511
A25: 2.3 - MATERIALES Y SUMINISTROS | B25: =SUM(B26:B34) -> 2.0982483e+08 | C25: =SUM(C26:C34) -> 4970600.4 | D25: =SUM(D26:D34) -> 14433131 | E25: =SUM(E26:E34) -> 26749552 | F25: =SUM(F26:F34) -> 20368607 | G25: =SUM(G26:G34) -> 16608513 | H25: =SUM(H26:H34) -> 15408530 | I25: =SUM(I26:I34) -> 26146220 | ... N25: =SUM(N26:N34) -> 0
A26: 2.3.1 - ALIMENTOS Y PRODUCTOS AGROFORESTALES | B26: =SUM(C26:N26) -> 16530112 | D26: 591460.4 | E26: 3122436.8 | F26: 812515 | G26: 1657538 | H26: 2396946.2 | I26: 1787251.8 | J26: 2077230.7 | K26: 2180362.6 | L26: 1611805 | M26: 292565.2
A27: 2.3.2 - TEXTILES Y VESTUARIOS | B27: =SUM(C27:N27) -> 6077830.9 | D27: 61630.73 | F27: 1562980.5 | H27: 812418.96 | I27: 1577150.7 | J27: 180540 | K27: 1258116.1 | L27: 67260 | M27: 557734.03
A28: 2.3.3 - PRODUCTOS DE PAPEL, CARTÓN E IMPRESOS | B28: =SUM(C28:N28) -> 10218468 | D28: 352366.67 | E28: 1474545.2 | F28: 1510942.2 | G28: 765138.96 | H28: 715614.54 | I28: 1579886.7 | J28: 912967.7 | K28: 366980 | L28: 884486 | M28: 1655540
A29: 2.3.4 - PRODUCTOS FARMACÉUTICOS | B29: =SUM(C29:N29) -> 48543120 | C29: 1862880 | D29: 2014526.8 | E29: 6919929 | F29: 6349109 | G29: 2637285.6 | H29: 3022962 | I29: 6806505 | J29: 2962573 | K29: 9434300 | L29: 2958714.3 | M29: 3574335
A30: 2.3.5 - PRODUCTOS DE CUERO, CAUCHO Y PLÁSTICO | B30: =SUM(C30:N30) -> 2673759.3 | E30: 334708.95 | F30: 506546.35 | G30: 384413.08 | H30: 133281 | I30: 655140.22 | J30: 18313.6 | L30: 623201.43 | M30: 18154.65
A31: 2.3.6 - PRODUCTOS DE MINERALES, METÁLICOS Y NO METÁLICOS | B31: =SUM(C31:N31) -> 1202221.3 | D31: 11630.98 | F31: 351015.88 | G31: 215177.81 | H31: 101426.9 | J31: 286504 | L31: 236465.7
A32: 2.3.7 - COMBUSTIBLES, LUBRICANTES, PRODUCTOS QUÍMICOS Y CONEXOS | B32: =SUM(C32:N32) -> 51823570 | C32: 1844663.4 | D32: 3902915.5 | E32: 3162523 | F32: 2759191.9 | G32: 4409677.5 | H32: 2900109.8 | I32: 4028536.8 | J32: 2398944 | K32: 5003060.2 | L32: 19442217 | M32: 1971730.4
A33: 2.3.8 - GASTOS QUE SE ASIGNARÁN DURANTE EL EJERCICIO (ART. 32 Y 33 LEY 423-06) | B33: =SUM(C33:N33) -> 0
A34: 2.3.9 - PRODUCTOS Y ÚTILES VARIOS | B34: =SUM(C34:N34) -> 72755749 | C34: 1263057 | D34: 7498600.4 | E34: 11735409 | F34: 6516306.6 | G34: 6539281.9 | H34: 5325771 | I34: 9711748.4 | J34: 5484666.6 | K34: 6898829.2 | L34: 6072287.3 | M34: 5709792.1
A35: 2.4 - TRANSFERENCIAS CORRIENTES | B35: 0 | C35: 0 | D35: 0 | E35: 0 | F35: 0 | G35: 0 | H35: 0 | I35: 0 | J35: 0 | K35: =SUM(K36:K42) -> 0 | L35: 0 | M35: 0 | N35: 0
A36: 2.4.1 - TRANSFERENCIAS CORRIENTES AL SECTOR PRIVADO | B36: 0
A37: 2.4.2 - TRANSFERENCIAS CORRIENTES AL GOBIERNO GENERAL NACIONAL | B37: 0
A38: 2.4.3 - TRANSFERENCIAS CORRIENTES A GOBIERNOS GENERALES LOCALES | B38: 0
A39: 2.4.4 - TRANSFERENCIAS CORRIENTES A EMPRESAS PÚBLICAS NO FINANCIERAS | B39: 0
A40: 2.4.5 - TRANSFERENCIAS CORRIENTES A INSTITUCIONES PÚBLICAS FINANCIERAS | B40: 0
A41: 2.4.7 - TRANSFERENCIAS CORRIENTES AL SECTOR EXTERNO | B41: 0
...

Sheet VS
A1: SERVICIO NACIONAL DE SALUD
A2: HOSPITAL MATERNO INFANTIL SAN LORENZO DE LOS MINA
A3: REGION
A4: Ejecución de Gastos VENTA SERVICIOS 2025
A5: En RD$
A7: Detalle | B7: Total | C7: Enero | D7: Febrero | E7: Marzo | F7: Abril | G7: Mayo | H7: Junio | I7: Julio | J7: Agosto | K7: Septiembre | L7: Octubre | M7: Noviembre | N7: Diciembre
A8: 2 - GASTOS
A9: 2.1 - REMUNERACIONES Y CONTRIBUCIONES | B9: =SUM(C9:N9) -> 9644681.1 | C9: 0 | D9: 0 | E9: 5231553.6 | F9: 0 | G9: 0 | H9: 0 | I9: 0 | J9: 0 | K9: =SUM(K10:K14) -> 4413127.6 | L9: 0 | M9: =SUM(M10:M14) -> 0 | N9: 0
A10: 2.1.1 - REMUNERACIONES | B10: =SUM(C10:N10) -> 0
A11: 2.1.2 - SOBRESUELDOS | B11: =SUM(C11:N11) -> 9644681.1 | E11: 5231553.6 | K11: 4413127.6
A12: 2.1.3 - DIETAS Y GASTOS DE REPRESENTACIÓN | B12: =SUM(C12:N12) -> 0
A13: 2.1.4 - GRATIFICACIONES Y BONIFICACIONES | B13: =SUM(C13:N13) -> 0
A14: 2.1.5 - CONTRIBUCIONES A LA SEGURIDAD SOCIAL | B14: =SUM(C14:N14) -> 0
A15: 2.2 - CONTRATACIÓN DE SERVICIOS | B15: =SUM(C15:N15) -> 29973175 | C15: 2733844.3 | D15: 1213383.4 | E15: 4359456.2 | F15: 1256712.1 | G15: 2044062.6 | H15: 3938639.1 | I15: 5012155.8 | J15: 3808523.8 | K15: =SUM(K16:K24) -> 1557736.2 | L15: =SUM(L16:L24) -> 1964841.4 | M15: =SUM(M16:M24) -> 2083820.5 | N15: 0
A16: 2.2.1 - SERVICIOS BÁSICOS | B16: =SUM(C16:N16) -> 9480180.1 | C16: 351316.33 | D16: 259054.4 | E16: 1731191.2 | F16: 285608.3 | G16: 1098463.4 | H16: 964509 | I16: 1781904.1 | J16: 933611.83 | K16: 161421.68 | L16: 1168099.9 | M16: 745000
A17: 2.2.2 - PUBLICIDAD, IMPRESIÓN Y ENCUADERNACIÓN | B17: =SUM(C17:N17) -> 1719123.4 | H17: 310139.4 | I17: 581445 | J17: 336559.6 | K17: 269720.57 | M17: 221258.85
A18: 2.2.3 - VIÁTICOS | B18: =SUM(C18:N18) -> 40000 | L18: 40000
A19: 2.2.4 - TRANSPORTE Y ALMACENAJE | B19: =SUM(C19:N19) -> 248000 | D19: 24000 | E19: 32000 | G19: 76000 | H19: 20000 | I19: 8000 | K19: 68000 | M19: 20000
A20: 2.2.5 - ALQUILERES Y RENTAS | B20: =SUM(C20:N20) -> 2503964.6 | C20: 266664.25 | D20: 252960.9 | F20: 229519.78 | G20: 529650.64 | I20: 298861.54 | J20: 628164.1 | L20: 298143.38
A21: 2.2.6 - SEGUROS | B21: =SUM(C21:N21) -> 3449.08 | L21: 3449.08
