Workbook

Sheet RELACION DE PAGOS EMITIDOS
A5: DIRECCION DE FISCALIZACION Y CONTROL
A6: RELACION DE PAGOS EMITIDOS DURANTE EL MES
A7: ESTABLECIMIENTO:HOSPITAL MATERNO INFANTIL SAN LORENZO DE LOS MINA
A9: PAGOS CORRESPONDIENTES AL MES : ABRIL 2025
A10: FECHA | B10: LIBRAMIENTO | C10: TRANSFERENCIA | D10: CHEQUE | E10: BENEFICIARIO | F10: NO.FACTURAS | G10: VALOR DE FACTURA | H10: VALOR PAGADO
A11: 45778 | C11: 130 | E11: TONER DEPOT MULTISERVICIOS EORG, SRL | F11: PAGO NCF B1500008503 SERVCIO DE IMPRESIÓN EN EL MES DE ABRIL 2025 SEGÚN O/C HSLM-2025-00147. | G11: 247030.86 | H11: 236563.45
A12: 45778 | C12: =+C11+1 -> 131 | E12: P&D RECYCLING, SRL | F12: PAGO DE FACT NCF NO. B1500000308, POR SERVICIO DE RECOGIDA DE DESECHOS SOLIDOS, SEGÚN ORDEN DE COMPRA HSLM-2025-00344 | G12: 760000 | H12: 722000
A13: 45779 | C13: =+C12+1 -> 132 | E13: ALTICE DOMINICANA, SA | F13: PAGO DE FACT NCF NO. E4500000014550 | G13: 104532.2 | H13: 104532.2
A14: 45779 | C14: =+C13+1 -> 133 | E14: COLEGIO DOMINICANO DE PROFESIONALES DE ENFERMERIA | F14: APORTE ECONOMICO PARA PERSONAL DE ENFERMERIA PARA EL XVIII CONGRESO NACIONAL Y X INTERNACIONAL DE ENFERMERIA QUE SERA CELEBRADO DEL 08 AL 11 DE MARZO 2025 | G14: 200000 | H14: 200000
A15: 45779 | C15: =+C14+1 -> 134 | E15: ALTICE DOMINICANA, SA | F15: PAGO DE FACT E4500000014347, POR SERVICIO DE COMUNICACIÓN PERIODO FACTURADO 23/03/2025 AL 22/04/2025, CUENTA 2666630 | G15: 104427.01 | H15: 104427.01
C16: =+C15+1 -> 135 | E16: UTILIZADA EN ABRIL 2025 | F16: UTILIZADA EN ABRIL 2025 | G16: 0 | H16: 0
C17: =+C16+1 -> 136 | E17: UTILIZADA EN ABRIL 2026 | F17: UTILIZADA EN ABRIL 2026 | G17: 0 | H17: 0
C18: =+C17+1 -> 137 | E18: FARMACO QUIMICA NACIONAL S.A | G18: 26821.4 | H18: 25684
C19: =+C18+1 -> 138 | E19: FARMACO QUIMICA NACIONAL S.A | G19: 26821.4 | H19: 25684
A20: 45784 | C20: =+C19+1 -> 139 | E20: DELIA JOSEFINA TATIS PERDOMO | F20: PAGO DE FACT NCF NO. B1500000524, POR ALQUILER DE CARPA 6*6 EJECUTIVA POR 15 DIAS CALENDARIO, PARA SER UTILIZADA EN EL AREA DE PARQUEO, SEGÚN ORDEN DE COMPRA HSLM-2024-00706 | G20: 53100 | H20: 50850
C21: =+C20+1 -> 140 | E21: WEPA TOURS, SRL | F21: COLABORACION PARA LA JORNADA EDUCATIVA DEDICADA AL DIA DE LAS ENFERMERAS, A REALIZARSE DESDE EL 14 AL 16 DE MAYO 2025 | G21: 70800 | H21: 70800
A22: 45784 | C22: =+C21+1 -> 141 | E22: LILIAN YOMAYRA ENCARNACION DE MATOS | F22: PAGO DE REGENCIA EN PERMISO DE DROGAS Y FARMACIA, PERTENECIENTE AL MES DE ABRIL 2025 | G22: 10000 | H22: 10000
C23: =+C22+1 -> 142 | E23: TURINTER | G23: 50958 | H23: 50958
A24: 45789 | C24: =+C23+1 -> 143 | E24: HOSPITRONICA, SRL | F24: PAGO DE FACT NCF B1500000145, POR ADQUISICION DE CARRO DE TRANSPORTE PARA AUTOCLAVE DE VAPOR, SEGÚN ORDEN DE COMPRA HSLM-2025-00308 | G24: 621205.1 | H24: 594882.85
C25: =+C24+1 -> 144 | E25: INVERSIONES FH SRL | F25: PAGO NCF B15000001495 ADQUISICION DE TICKETS DE COMBUSTIBLE SEGÚN O/C HSLM-2025-00423 | G25: 172000 | H25: 170573.26
A26: 45790 | C26: =+C25+1 -> 145 | E26: CEM CARIBBEAN EQUIPMENT MEDICAL, SRL | F26: PAGO DE FACT NCF NO. B1500001345, POR ADQUISICION DE KIT DE CONTROL DE GASES ARTERIALES, SEGÚN ORDEN DE COMPRA HSLM-2025-00167 | G26: 846850 | H26: 804507.5
A27: 45790 | C27: =+C26+1 -> 146 | E27: ADLER AMICIS VALDEZ MARMOLEJOS | F27: PAGO DE FACT NCF NO. B1500000029, ADQUISICION DE MATERIALES IMPRESOS, SEGÚN ORDEN DE COMPRA HSLM-2025-00320 | G27: 108265 | H27: 103677.5
A28: 45790 | C28: =+C27+1 -> 147 | E28: TROPIGAS DOMINICANA, SRL | F28: PAGO DE FACT E450000005419, POR ADQUISICION DE GAS LICUADO DE PETROLEO, SEGÚN ORDEN DE COMPRA HSLM-2025-00066 | G28: 23868 | H28: 23868
A29: 45790 | C29: =+C28+1 -> 148 | E29: JESUS FERMIN MARTINEZ LOPEZ | F29: PAGO DE FACT NCF NO. B1500000432, POR SERVICIO DE TRANSPORTE SEGÚN ORDEN DE COMPRA HSLM-2025-000068 | G29: 32000 | H29: 30400
A30: 45790 | C30: =+C29+1 -> 149 | E30: LEHAIM SUMINISTROS | F30: PAGO DE FACT NCF NO. B1500000014, POR ADQUISICION DE SERVILLETA, SEGÚN ORDEN DE COMPRA HSLM-2025-00143 | G30: 227500 | H30: 216125
A31: 45790 | C31: =+C30+1 -> 150 | E31: LEHAIM SUMINISTROS | F31: PAGO DE FACT NO. B1500000013, POR ADQUISICION DE PAPEL HIGIENICO | G31: 271400 | H31: 259900
A32: 45790 | C32: =+C31+1 -> 151 | E32: CEM CARIBBEAN EQUIPMENT MEDICAL, SRL | F32: PAGO DE FACT NCF NO. B1500001356, POR ADQUISICION DE VENTILADOR PEDIATRICO NEONATAL, SEGÚN ORDEN DE COMPRA HSLM-2025-0271 | G32: 1590510.2 | H32: 1523115.7
A33: 45791 | C33: =+C32+1 -> 152 | E33: GESTIONES SANITARIAS & AMBIENTALES, SRL | F33: PAGO DE FACT NCF NO B1500000447, POR SERVICIO DDE ANALISIS MICROBIOLOGICO, DE AGUA POTABLE, HSLM-CD-2024-0007 | G33: 39530 | H33: 37855
A34: 45791 | C34: =+C33+1 -> 153 | E34: PRODUCTOS CANO | F34: PAGO DE FACT NCF NO, B1500001319 POR ADQUISICION DE PAN MES DE ABRIL 2025 | G34: 91875 | H34: 87281.25
A35: 45791 | C35: =+C34+1 -> 154 | E35: CABOD, EIRL | F35: PAGO DE FACT NCF NO B1500001758, POR ADQUISICION DE MATERIALES DE LIMPIEZA SEGÚN ORDEN DE COMPRA HSLM-2025-00318 | G35: 98506.4 | H35: 94332.4
A36: 45791 | C36: =+C35+1 -> 155 | E36: JF2H SUPLIDORES DIVERSOS | F36: PAGO NCF B150000104 ADQUISICION DE TELA PARA FABRICAR COLCHAS, SEGÚN ORDEN DE COMPRA HSLM-2025-00412 | G36: 141128 | H36: 135148
C37: =+C36+1 -> 156 | E37: SANDRY GOMEZ RODRIGUEZ | F37: PAGO DE FACT NCF NO. B1500000560, POR ADQUISICION DE ALIMENTOS, SEGÚN ORDEN DE COMPRA HSLM-2025-00310 | G37: 263200 | H37: 250040
C38: =+C37+1 -> 157 | E38: SINDICATO NACIONAL DE TRABAJADORES DE ENFERMERIA | F38: SALDO COLABORACION PARA ACTIVIDAD DEL DIA DEL ENFERMERO | G38: 70000 | H38: 70000
C39: =+C38+1 -> 158 | E39: DESTREZA COMERCIAL SRL | F39: PAGO NCF B1500000060 ADQUISCION DE MEDICAMENTOS SEGÚN O/C HSLM-2025-00414. | G39: 42000 | H39: 39900
C40: =+C39+1 -> 159 | E40: IV BIODESINFECCION SRL | F40: PAGO NCF B1500000285 SERVICIO DE DESINFECCION AREA DE QUIROFANO DE INFECTOLOGIA, UCI DE ADULTOS 3ERA PLANTA Y AREA DE HOSPITALIZACION SEGÚN O/C HSLM-2025-00407. | G40: 37996 | H40: 36386
C41: =+C40+1 -> 160 | E41: IV BIODESINFECCION SRL | F41: PAGO NCF B1500000286 SERVICIO DE DESINFECCION AREA DE UCIN 1 SEGÚN O/C HSLM-2025-00418 | G41: 9912 | H41: 9492
C42: =+C41+1 -> 161 | E42: ANTARES PHARMA SRL | F42: PAGO NCF B1500000001 UTILES MEDICOS E INSPIROMETRO SEGÚN O/C HSLM-2025-00379. | G42: 65468.29 | H42: 62694.21
C43: =+C42+1 -> 162 | E43: FARMACIA RUTH SRL | F43: PAGO NCF B1500000278 ADQUISICION DE MEDICAMENTOS SEGÚN O/C 1896 | G43: 88100 | H43: 83695
C44: =+C43+1 -> 163 | E44: NULO | F44: NULO | G44: 0 | H44: 0
C45: =+C44+1 -> 164 | E45: NULO | F45: NULO | G45: 0 | H45: 0
...

Sheet RELACION ORDENES DE COMPRAS
A4: SERVICIO NACIONAL DE SALUD
A5: DIRECCION DE FISCALIZACION
A6: RELACIÓN DE ORDENES DE COMPRAS DE BIENES Y SERVICIOS EFECTUADAS.
A7: ESTABLECIMIENTO: HOSPITAL MATERNO INFANTIL SAN LORENZO DE LOS MINA REGION_0 MES DE MAYO 2025
A8: Fecha | B8: # Orden de Compra o Servicios | C8: # DE EXPEDIENTE(PROCESO CELEBRADO) | D8: No. De Factura Fiscal NCF | E8: Fuente. Financ (FR-VS) | F8: Beneficiario | G8: Rubro | H8: No. Cta. Objetal del Gasto | I8: Valor | J8: Status del proceso | K8: solo observar cuando se presentas esos procesos
A9: 45778.502 | B9: HSML-2025-00421 | C9: HSLM-DAF-CD-2025-0339 | E9: VS/FG | F9: Diucam Group SRL | G9: 44120000 | H9: 2.2.7.1.01 | I9: 272005.91 | J9: Adjudicado
A10: 45778.502 | B10: Analisis de oferta | C10: HSLM-DAF-CM-2025-0108 | E10: VS/FG | G10: 42290000 | J10: Evaluación
A11: 45778.502 | B11: Analisis de oferta | C11: HSLM-DAF-CM-2025-0109 | E11: VS/FG | G11: 42290000 | H11: 2.2.7.1.01 | J11: Evaluación
A12: 45779.459 | B12: HSML-2025-00422 | C12: HSLM-DAF-CD-2025-0340 | E12: VS/FG | F12: Baucomer, SRL | G12: 51160000 | H12: 2.6.3.2.01 | I12: 199620 | J12: Adjudicado
A13: 45779.479 | B13: HSML-2025-00447 | C13: HSLM-DAF-CM-2025-0110 | E13: VS/FG | F13: BAAM & Asociados, SRL | G13: 30170000 | H13: 2.2.7.1.01 | I13: 883372.39 | J13: Adjudicado
A14: 45779.576 | B14: HSML-2025-00423 | C14: HSLM-DAF-CD-2025-0341 | E14: VS/FG | F14: INVERSIONES FH, SRL | G14: 15100000 | H14: 2.2.7.1.01 | I14: 172000 | J14: Adjudicado
A15: 45783.521 | B15: HSML-2025-00425 | C15: HSLM-DAF-CD-2025-0342 | E15: VS/FG | F15: Dumas Pharmaceuticals, SRL | G15: 51100000 | H15: 2.6.1.1.01 | I15: 77000 | J15: Adjudicado
A16: 45783.569 | B16: HSML-2025-00452 | C16: HSLM-DAF-CM-2025-0111 | E16: VS/FG | F16: P&D Recycling, SRL | G16: 76120000 | H16: 2.6.3.1.01 | I16: 760000 | J16: Adjudicado
A17: 45784.465 | B17: HSML-2025-00429 | C17: HSLM-DAF-CD-2025-0343 | E17: VS/FG | F17: Baucomer, SRL | G17: 42140000 | H17: 2.3.1.1.01 | I17: 242945 | J17: Adjudicado
A18: 45784.502 | B18: HSML-2025-00430 | C18: HSLM-DAF-CD-2025-0344 | E18: VS/FG | F18: Diucam Group SRL | G18: 90100000 | H18: 2.3.7.1.01 | I18: 57938 | J18: Adjudicado
A19: 45784.584 | B19: HSML-2025-00431 | C19: HSLM-DAF-CD-2025-0346 | E19: VS/FG | F19: Grupo Xeron Medic SRL | G19: 51140000 | H19: 2.3.1.1.01 | I19: 251945 | J19: Adjudicado
A20: 45784.626 | B20: HSML-2025-00469 | C20: HSLM-DAF-CD-2025-0345 | E20: VS/FG | F20: osorio integraciones | G20: 46170000 | H20: 2.3.1.1.01 | I20: 58764 | J20: Adjudicado
A21: 45784.709 | B21: HSML-2025-00433 | C21: HSLM-DAF-CD-2025-0348 | E21: VS/FG | F21: Farmaco Internacional, SRL | G21: 42180000 | H21: 2.3.9.3.01 | I21: 26821.4 | J21: Adjudicado
A22: 45784.709 | B22: HSML-2025-00432 | C22: HSLM-DAF-CD-2025-0347 | E22: VS/FG | F22: Grupo Xeron Medic SRL | G22: 42170000 | H22: 2.2.1.8.01 | I22: 160159.96 | J22: Adjudicado
A23: 45785.465 | B23: HSML-2025-00435 | C23: HSLM-DAF-CD-2025-0349 | E23: VS/FG | F23: Farmaco Internacional, SRL | G23: 42180000 | H23: 2.6.1.3.01 | I23: 26821.4 | J23: Adjudicado
... A61: 45792.502 | B61: HSML-2025-00494 | C61: HSLM-DAF-CM-2025-0122 | E61: VS/FG | F61: Ciencia Tecnología y Consultas, SRL | G61: 41100000 | H61: 2.3.4.1.01 | I61: 778983.4 | J61: Adjudicado
A62: 45792.502 | B62: HSML-2025-00501 | C62: HSLM-DAF-CD-2025-0378 | E62: VS/FG | F62: Farmaceutica Dalmasi (FARMADAL), SRL | G62: 41110000 | I62: 34021.44 | J62: Adjudicado
A63: 45792.542 | B63: HSML-2025-00497 | C63: HSLM-DAF-CM-2025-0125 | E63: VS/FG | F63: Bello-Lab, SRL | G63: 41100000 | H63: 2.3.9.3.01 | I63: 329391 | J63: Adjudicado
A64: 45792.542 | B64: HSML-2025-00481 | C64: HSLM-DAF-CD-2025-0379 | E64: VS/FG | F64: CEM Caribbean Equipment Medical, SRL | G64: 41110000 | H64: 2.3.9.3.01 | I64: 174238 | J64: Adjudicado
A65: 45792.573 | B65: HSML-2025-00470 | C65: HSLM-DAF-CD-2025-0382 | E65: VS/FG | F65: Farmaco Internacional, SRL | G65: 41100000 | H65: 2.3.4.1.01 | I65: 6289.04 | J65: Adjudicado
A66: 45792.584 | B66: HSML-2025-00473 | C66: HSLM-DAF-CD-2025-0381 | E66: VS/FG | F66: Papelería E. Impresos Crishoan, SRL | G66: 82120000 | H66: 2.2.7.2.08 | I66: 266326 | J66: Adjudicado
A67: 45792.584 | B67: HSML-2025-00498 | C67: HSLM-DAF-CM-2025-0123 | E67: VS/FG | F67: Sued & Fargesa, SRL | G67: 41110000 | H67: 2.3.9.1.01 | I67: 573395 | J67: Adjudicado
A68: 45792.585 | B68: HSML-2025-00471 | C68: HSLM-DAF-CD-2025-0380 | E68: VS/FG | F68: Q&Q Medical RD, SRL | G68: 41100000 | H68: 2.3.4.1.01 | I68: 226240.22 | J68: Adjudicado
A69: 45792.611 | B69: HSML-2025-00499 | C69: HSLM-DAF-CM-2025-0124 | E69: VS/FG | F69: CEM Caribbean Equipment Medical, SRL | G69: 41110000 | H69: 2.3.9.3.01 | I69: 668000 | J69: Adjudicado
A70: 45793.438 | B70: HSML-2025-00480 | C70: HSLM-DAF-CD-2025-0383 | E70: VS/FG | F70: Global Multi-Pharma Dominicana THM, SRL | G70: 42310000 | H70: 2.3.4.1.01 | I70: 264000 | J70: Adjudicado
A71: 45793.46 | B71: HSML-2025-00479 | C71: HSLM-DAF-CD-2025-0384 | E71: VS/FG | F71: Global Multi-Pharma Dominicana THM, SRL | G71: 42180000 | H71: 2.3.7.2.03 | I71: 57820 | J71: Adjudicado
A72: 45793.502 | B72: HSML-2025-00495 | C72: HSLM-DAF-CM-2025-0126 | E72: VS/FG | F72: G & M Gelmat Comercial, SRL | G72: 42180000 | H72: 2.3.9.3.01 | I72: 674774 | J72: Adjudicado
A73: 45793.503 | B73: cancelado | C73: HSLM-DAF-CD-2025-0385 | E73: VS/FG | G73: 52150000 | H73: 2.3.4.1.01 | J73: Cancelado
A74: 45793.542 | B74: HSML-2025-00475 | C74: HSLM-DAF-CD-2025-0388 | E74: VS/FG | F74: Gestoria Administrativa Ynuñez S.R.L | G74: 41100000 | H74: 2.3.7.2.03 | I74: 270007.6 | J74: Adjudicado
A75: 45793.542 | B75: HSML-2025-00474 | C75: HSLM-DAF-CD-2025-0387 | E75: VS/FG | F75: Dumas Pharmaceuticals, SRL | G75: 51120000 | H75: 2.6.1.1.01 | I75: 45000 | J75: Adjudicado
A76: 45793.542 | B76: Analisis de oferta | C76: HSLM-DAF-CM-2025-0127 | E76: VS/FG | G76: 42200000 | H76: 2.6.3.4.01 | J76: Evaluación
A77: 45793.542 | B77: HSML-2025-00478 | C77: HSLM-DAF-CD-2025-0386 | E77: VS/FG | F77: Bello-Lab, SRL | G77: 41110000 | H77: 2.3.4.1.01 | I77: 247123.9 | J77: Adjudicado
A78: 45793.542 | B78: HSML-2025-00477 | C78: HSLM-DAF-CD-2025-0389 | E78: VS/FG | F78: JM Distribución, SRL | G78: 52150000 | H78: 2.3.9.3.01 | I78: 72900.01 | J78: Adjudicado
A79: 45793.584 | B79: HSML-2025-00476 | C79: HSLM-DAF-CD-2025-0390 | E79: VS/FG | F79: Grupo Xeron Medic SRL | G79: 42270000 | H79: 2.2.9.1.01 | I79: 163902 | J79: Adjudicado
A80: 45796.479 | B80: HSML-2025-00482 | C80: HSLM-DAF-CD-2025-0391 | E80: VS/FG | F80: Xavier Vargas, Ingeniería Electromecánica, EIRL | G80: 40100000 | H80: 2.6.5.4.02 | I80: 232932 | J80: Adjudicado
...

Sheet CUENTA T VS
A1: D E S G L O S E D E L A S C U E N T A S
A2: 211101 | B2: 211102 | C2: 211103 | D2: 211104 | E2: 211105 | F2: 211106 | G2: 211203 | H2: 211205 | I2: 211206 | J2: 211208 | K2: 211209 | L2: 211211 | M2: 211301 | N2: 211401 | O2: 211501 | P2: 211502 | Q2: 211503 | R2: 211504 | S2: 212101 | T2: 212201 | U2: 212203 | V2: 212204 | W2: 212205 | X2: 212206 | Y2: 212207 | Z2: 212208 | AA2: 212209 | AB2: 212210 | AC2: 213101 | AD2: 213102 | AE2: 213201 | AF2: 213202 | AG2: 214101 | AH2: 214201 | AI2: 214202 | AJ2: 214203 | AK2: 215101 | AL2: 215201 | AM2: 215301 | AN2: 215401 | AO2: 221101 | AP2: 221201 | AQ2: 221301 | AR2: 221401 | AS2: 221501 | AT2: 221601 | AU2: 221602 | AV2: 221701 | AW2: 221801 | AX2: 222101 | AY2: 222201 | AZ2: 223101 | BA2: 223201 | BB2: 224101 | BC2: 224201 | BD2: 224301 | BE2: 224401 | BF2: 225101 | BG2: 225201 | BH2: 225301 | BI2: 225302 | BJ2: 225303 | BK2: 225304 | BL2: 225305 | BM2: 225401 | BN2: 225501 | BO2: 225601 | BP2: 225701 | BQ2: 225801 | BR2: 225901 | BS2: 226101 | BT2: 226201 | BU2: 226301 | BV2: 226401 | BW2: 227101 | BX2: 227102 | BY2: 227103 | BZ2: 227104 | CA2: 227105 | CB2: 227106 | CC2: 227107 | CD2: 227199 | CE2: 227201 | CF2: 227202 | CG2: 227203 | CH2: 227204 | CI2: 227205 | CJ2: 227206 | CK2: 227207 | CL2: 227208 | CM2: 227299 | CN2: 227301 | CO2: 228101 | CP2: 228201 | CQ2: 228301 | CR2: 228401 | CS2: 228501 | CT2: 228502 | CU2: 228503 | CV2: 228601 | CW2: 228602 | CX2: 228603 | CY2: 228604 | CZ2: 228701 | DA2: 228702 | DB2: 228703 | DC2: 228704 | DD2: 228705 | DE2: 228706 | DF2: 228801 | DG2: 228802 | DH2: 228803 | DI2: 229201 | DJ2: 229203 | DK2: 231101 | DL2: 231102 | DM2: 231201 | DN2: 231301 | DO2: 231302 | DP2: 231303 | DQ2: 231401 | DR2: 232101 | DS2: 232201 | DT2: 232301 | DU2: 233101 | DV2: 233201 | DW2: 233301 | DX2: 233401 | DY2: 233501 | DZ2: 233601 | EA2: 234101 | EB2: 234201 | EC2: 235101 | ED2: 235201 | EE2: 235301 | EF2: 235401 | EG2: 235501 | EH2: 236101 | EI2: 236102 | EJ2: 236103 | EK2: 236104 | EL2: 236105 | EM2: 236201 | EN2: 236202 | EO2: 236203 | EP2: 236304 | EQ2: 236305 | ER2: 236306 | ES2: 236401 | ET2: 236402 | EU2: 236403 | EV2: 236404 | EW2: 236405 | EX2: 236406 | EY2: 236407 | EZ2: 236901 | FA2: 237101 | FB2: 237102 | FC2: 237103 | FD2: 237104 | FE2: 237105 | FF2: 237106 | FG2: 237107 | FH2: 237201 | FI2: 237202 | FJ2: 237203 | FK2: 237204 | FL2: 237205 | FM2: 237206 | FN2: 237299 | FO2: 238101 | FP2: 238201 | FQ2: 239101 | FR2: 239102 | FS2: 239201 | FT2: 239301 | FU2: 239401 | FV2: 239501 | FW2: 239601 | FX2: 239701 | FY2: 239801 | FZ2: 239802 | GA2: 239901 | GB2: 239904 | GC2: 241201 | GD2: 241202 | GE2: 241203 | GF2: 241204 | GG2: 241205 | GH2: 261101 | GI2: 261201 | GJ2: 261301 | GK2: 261401 | GL2: 261901 | GM2: 262101 | GN2: 262201 | GO2: 262301 | GP2: 262401 | GQ2: 263101 | GR2: 263201 | GS2: 263301 | GT2: 263401 | GU2: 264101 | GV2: 264201 | GW2: 264301 | GX2: 264401 | GY2: 264501 | GZ2: 264601 | HA2: 264701 | HB2: 264801 | HC2: 265101 | HD2: 265201 | HE2: 265301 | HF2: 265401 | HG2: 265501 | HH2: 265601 | HI2: 265701 | HJ2: 265801 | HK2: 266101 | HL2: 266201 | HM2: 267101 | HN2: 267201 | HO2: 267301 | HP2: 267401 | HQ2: 267501 | HR2: 267601 | HS2: 267701 | HT2: 267801 | HU2: 267901 | HV2: 268101 | HW2: 268201 | HX2: 268301 | HY2: 268302 | HZ2: 268401 | IA2: 268501 | IB2: 268601 | IC2: 268701 | ID2: 268802 | IE2: 268803 | IF2: 268804 | IG2: 268901 | IH2: 269101 | II2: 269102 | IJ2: 269201 | IK2: 269202 | IL2: 269301 | IM2: 269401 | IN2: 269501 | IO2: 269502 | IP2: 269503 | IQ2: 2269901 | IR2: 271101 | IS2: 271201 | IT2: 271301 | IU2: 271401 | IV2: 272101 | IW2: 272201 | IX2: 272301 | IY2: 272401 | IZ2: 272501 | JA2: 272601 | JB2: 272701 | JC2: 272801 | JD2: 272901 | JE2: 273101 | JF2: 273201 | JG2: 274101 | JH2: 274201 | JI2: Totales | JJ2: TRANSF NO. | JK2: VALOR | JL2: RETENCION | JM2: AÑOS ANTERIORES | JN2: 2022 | JO2: Total | JP2: Proveedor Informal
BI3: 247030.86 | JI3: =SUM(A3:JH3) -> 247030.86 | JJ3: 130
AW4: 760000 | JI4: =SUM(A4:JH4) -> 760000 | JJ4: 131
AQ5: 104532.2 | JI5: =SUM(A5:JH5) -> 104532.2 | JJ5: 132
GD6: 200000 | JI6: =SUM(A6:JH6) -> 200000 | JJ6: 133
AS7: 104427.01 | JI7: =SUM(A7:JH7) -> 104427.01 | JJ7: 134
JI8: =SUM(A8:JH8) -> 0 | JJ8: 135
JI9: =SUM(A9:JH9) -> 0 | JJ9: 136
FT10: 26821.4 | JI10: =SUM(A10:JH10) -> 26821.4 | JJ10: 137
FT11: 26821.4 | JI11: =SUM(A11:JH11) -> 26821.4 | JJ11: 138
BQ12: 53100 | JI12: =SUM(A12:JH12) -> 53100 | JJ12: 139
GD13: 70800 | JI13: =SUM(A13:JH13) -> 70800 | JJ13: 140
DE14: 10000 | JI14: =SUM(A14:JH14) -> 10000 | JJ14: 141
GD15: 50958 | JI15: =SUM(A15:JH15) -> 50958 | JJ15: 142
GR16: 621205.1 | JI16: =SUM(A16:JH16) -> 621205.1 | JJ16: 143
FA17: 172000 | JI17: =SUM(A17:JH17) -> 172000 | JJ17: 144
FJ18: 846850 | JI18: =SUM(A18:JH18) -> 846850 | JJ18: 145
DW19: 108265 | JI19: =SUM(A19:JH19) -> 108265 | JJ19: 146
FD20: 23868 | JI20: =SUM(A20:JH20) -> 23868 | JJ20: 147
BC21: 32000 | JI21: =SUM(A21:JH21) -> 32000 | JJ21: 148
DV22: 227500 | JI22: =SUM(A22:JH22) -> 227500 | JJ22: 149
DV23: 271400 | JI23: =SUM(A23:JH23) -> 271400 | JJ23: 150
GR24: 1590510.2 | JI24: =SUM(A24:JH24) -> 1590510.2 | JJ24: 151
CU25: 39530 | JI25: =SUM(A25:JH25) -> 39530 | JJ25: 152
DK26: 91875 | JI26: =SUM(A26:JH26) -> 91875 | JJ26: 153
FQ27: 98506.4 | JI27: =SUM(A27:JH27) -> 98506.4 | JJ27: 154
DR28: 141128 | JI28: =SUM(A28:JH28) -> 141128 | JJ28: 155
DK29: 263200 | JI29: =SUM(A29:JH29) -> 263200 | JJ29: 156
GD30: 70000 | JI30: =SUM(A30:JH30) -> 70000 | JJ30: =+JJ29+1 -> 157
EA31: 42000 | JI31: =SUM(A31:JH31) -> 42000 | JJ31: =+JJ30+1 -> 158
CU32: 37996 | JI32: =SUM(A32:JH32) -> 37996 | JJ32: =+JJ31+1 -> 159
CU33: 9912 | JI33: =SUM(A33:JH33) -> 9912 | JJ33: =+JJ32+1 -> 160
FT34: 55241.4 | GR34: 10226.89 | JI34: =SUM(A34:JH34) -> 65468.29 | JJ34: =+JJ33+1 -> 161
EA35: 88100 | JI35: =SUM(A35:JH35) -> 88100 | JJ35: =+JJ34+1 -> 162
JI36: =SUM(A36:JH36) -> 0 | JJ36: =+JJ35+1 -> 163
JI37: =SUM(A37:JH37) -> 0 | JJ37: =+JJ36+1 -> 164
AQ38: 104504.21 | JI38: =SUM(A38:JH38) -> 104504.21 | JJ38: =+JJ37+1 -> 165
DE39: 17033 | JI39: =SUM(A39:JH39) -> 17033 | JJ39: =+JJ38+1 -> 166
AW40: 25000 | JI40: =SUM(A40:JH40) -> 25000 | JJ40: =+JJ39+1 -> 167
...

Sheet CUENTA T FONDO 100
A1: D E S G L O S E D E L A S C U E N T A S
A2: 211101 | B2: 211102 | C2: 211103 | D2: 211104 | E2: 211105 | F2: 211106 | G2: 211203 | H2: 211205 | I2: 211206 | J2: 211208 | K2: 211209 | L2: 211211 | M2: 211301 | N2: 211401 | O2: 211501 | P2: 211502 | Q2: 211503 | R2: 211504 | S2: 212101 | T2: 212201 | U2: 212203 | V2: 212204 | W2: 212205 | X2: 212206 | Y2: 212207 | Z2: 212208 | AA2: 212209 | AB2: 212210 | AC2: 213101 | AD2: 213102 | AE2: 213201 | AF2: 213202 | AG2: 214101 | AH2: 214201 | AI2: 214202 | AJ2: 214203 | AK2: 215101 | AL2: 215201 | AM2: 215301 | AN2: 215401 | AO2: 221101 | AP2: 221201 | AQ2: 221301 | AR2: 221401 | AS2: 221501 | AT2: 221601 | AU2: 221602 | AV2: 221701 | AW2: 221801 | AX2: 222101 | AY2: 222201 | AZ2: 223101 | BA2: 223201 | BB2: 224101 | BC2: 224201 | BD2: 224301 | BE2: 224401 | BF2: 225101 | BG2: 225201 | BH2: 225301 | BI2: 225302 | BJ2: 225303 | BK2: 225304 | BL2: 225305 | BM2: 225401 | BN2: 225501 | BO2: 225601 | BP2: 225701 | BQ2: 225801 | BR2: 225901 | BS2: 226101 | BT2: 226201 | BU2: 226301 | BV2: 226401 | BW2: 227101 | BX2: 227102 | BY2: 227103 | BZ2: 227104 | CA2: 227105 | CB2: 227106 | CC2: 227107 | CD2: 227199 | CE2: 227201 | CF2: 227202 | CG2: 227203 | CH2: 227204 | CI2: 227205 | CJ2: 227206 | CK2: 227207 | CL2: 227208 | CM2: 227299 | CN2: 227301 | CO2: 228101 | CP2: 228201 | CQ2: 228301 | CR2: 228401 | CS2: 228501 | CT2: 228502 | CU2: 228503 | CV2: 228601 | CW2: 228602 | CX2: 228603 | CY2: 228604 | CZ2: 228701 | DA2: 228702 | DB2: 228703 | DC2: 228704 | DD2: 228705 | DE2: 228706 | DF2: 228801 | DG2: 228802 | DH2: 228803 | DI2: 229201 | DJ2: 229203 | DK2: 231101 | DL2: 231102 | DM2: 231201 | DN2: 231301 | DO2: 231302 | DP2: 231303 | DQ2: 231401 | DR2: 232101 | DS2: 232201 | DT2: 232301 | DU2: 233101 | DV2: 233201 | DW2: 233301 | DX2: 233401 | DY2: 233501 | DZ2: 233601 | EA2: 234101 | EB2: 234201 | EC2: 235101 | ED2: 235201 | EE2: 235301 | EF2: 235401 | EG2: 235501 | EH2: 236101 | EI2: 236102 | EJ2: 236103 | EK2: 236104 | EL2: 236105 | EM2: 236201 | EN2: 236202 | EO2: 236203 | EP2: 236304 | EQ2: 236305 | ER2: 236306 | ES2: 236401 | ET2: 236402 | EU2: 236403 | EV2: 236404 | EW2: 236405 | EX2: 236406 | EY2: 236407 | EZ2: 236901 | FA2: 237101 | FB2: 237102 | FC2: 237103 | FD2: 237104 | FE2: 237105 | FF2: 237106 | FG2: 237107 | FH2: 237201 | FI2: 237202 | FJ2: 237203 | FK2: 237204 | FL2: 237205 | FM2: 237206 | FN2: 237299 | FO2: 238101 | FP2: 238201 | FQ2: 239101 | FR2: 239102 | FS2: 239201 | FT2: 239301 | FU2: 239401 | FV2: 239501 | FW2: 239601 | FX2: 239701 | FY2: 239801 | FZ2: 239802 | GA2: 239901 | GB2: 239904 | GC2: 241201 | GD2: 241202 | GE2: 241203 | GF2: 241204 | GG2: 241205 | GH2: 261101 | GI2: 261201 | GJ2: 261301 | GK2: 261401 | GL2: 261901 | GM2: 262101 | GN2: 262201 | GO2: 262301 | GP2: 262401 | GQ2: 263101 | GR2: 263201 | GS2: 263301 | GT2: 263401 | GU2: 264101 | GV2: 264201 | GW2: 264301 | GX2: 264401 | GY2: 264501 | GZ2: 264601 | HA2: 264701 | HB2: 264801 | HC2: 265101 | HD2: 265201 | HE2: 265301 | HF2: 265401 | HG2: 265501 | HH2: 265601 | HI2: 265701 | HJ2: 265801 | HK2: 266101 | HL2: 266201 | HM2: 267101 | HN2: 267201 | HO2: 267301 | HP2: 267401 | HQ2: 267501 | HR2: 267601 | HS2: 267701 | HT2: 267801 | HU2: 267901 | HV2: 268101 | HW2: 268201 | HX2: 268301 | HY2: 268302 | HZ2: 268401 | IA2: 268501 | IB2: 268601 | IC2: 268701 | ID2: 268802 | IE2: 268803 | IF2: 268804 | IG2: 268901 | IH2: 269101 | II2: 269102 | IJ2: 269201 | IK2: 269202 | IL2: 269301 | IM2: 269401 | IN2: 269501 | IO2: 269502 | IP2: 269503 | IQ2: 2269901 | IR2: 271101 | IS2: 271201 | IT2: 271301 | IU2: 271401 | IV2: 272101 | IW2: 272201 | IX2: 272301 | IY2: 272401 | IZ2: 272501 | JA2: 272601 | JB2: 272701 | JC2: 272801 | JD2: 272901 | JE2: 273101 | JF2: 273201 | JG2: 274101 | JH2: 274201 | JI2: Totales | JJ2: LIBRAMIENTO | JK2: VALOR | JL2: RETENCION | JM2: AÑOS ANTERIORES | JN2: 2024 | JO2: Total | JP2: Proveedor Informal
FJ3: 622991.58 | FQ3: 52756.9 | JI3: =SUM(A3:JH3) -> 675748.48 | JJ3: 1778 | JL3: =+JI3-JK3 -> 675748.48 | JO3: =+JM3+JN3 -> 0
FA4: 1649337.3 | JI4: =SUM(A4:JH4) -> 1649337.3 | JJ4: 1781 | JL4: =+JI4-JK4 -> 1649337.3
FJ5: 645614.72 | FN5: 9976 | FQ5: 161732.4 | JI5: =SUM(A5:JH5) -> 817323.12 | JJ5: 1785 | JL5: =+JI5-JK5 -> 817323.12
FQ6: 247068.4 | JI6: =SUM(A6:JH6) -> 247068.4 | JJ6: 1790 | JL6: =+JI6-JK6 -> 247068.4
FT7: 270102 | JI7: =SUM(A7:JH7) -> 270102 | JJ7: 1801 | JL7: =+JI7-JK7 -> 270102
GR8: 939471.75 | JI8: =SUM(A8:JH8) -> 939471.75 | JJ8: 1805 | JL8: =+JI8-JK8 -> 939471.75
EA9: 210000 | JI9: =SUM(A9:JH9) -> 210000 | JJ9: 1809 | JL9: =+JI9-JK9 -> 210000
FT10: 270102 | JI10: =SUM(A10:JH10) -> 270102 | JJ10: 1813 | JL10: =+JI10-JK10 -> 270102
HF11: 91569.9 | JI11: =SUM(A11:JH11) -> 91569.9 | JJ11: 1820 | JL11: =+JI11-JK11 -> 91569.9
FT12: 1937560 | JI12: =SUM(A12:JH12) -> 1937560 | JJ12: 1835 | JL12: =+JI12-JK12 -> 1937560
FT13: 276519 | JI13: =SUM(A13:JH13) -> 276519 | JJ13: 1839 | JL13: =+JI13-JK13 -> 276519
AA14: 443970.11 | JI14: =SUM(A14:JH14) -> 443970.11 | JJ14: 1841 | JL14: =+JI14-JK14 -> 443970.11
EA15: 17133.6 | FT15: 36875 | JI15: =SUM(A15:JH15) -> 54008.6 | JJ15: 1845 | JL15: =+JI15-JK15 -> 54008.6
EA16: 152500 | JI16: =SUM(A16:JH16) -> 152500 | JJ16: 1849 | JL16: =+JI16-JK16 -> 152500
DK17: 698555.7 | JI17: =SUM(A17:JH17) -> 698555.7 | JJ17: 1853 | JL17: =+JI17-JK17 -> 698555.7
FT18: 271400 | JI18: =SUM(A18:JH18) -> 271400 | JJ18: 1857 | JL18: =+JI18-JK18 -> 271400
GQ19: 508060.8 | JI19: =SUM(A19:JH19) -> 508060.8 | JJ19: 1861 | JL19: =+JI19-JK19 -> 508060.8
FT20: 177000 | JI20: =SUM(A20:JH20) -> 177000 | JJ20: 1865 | JL20: =+JI20-JK20 -> 177000
EG21: 57151.44 | JI21: =SUM(A21:JH21) -> 57151.44 | JJ21: 1873 | JL21: =+JI21-JK21 -> 57151.44
FT22: 129520 | JI22: =SUM(A22:JH22) -> 129520 | JJ22: 1875 | JL22: =+JI22-JK22 -> 129520
FT23: 179360 | JI23: =SUM(A23:JH23) -> 179360 | JJ23: 1879 | JL23: =+JI23-JK23 -> 179360
EA24: 199620 | JI24: =SUM(A24:JH24) -> 199620 | JJ24: 1890 | JL24: =+JI24-JK24 -> 199620
FT25: 242945 | JI25: =SUM(A25:JH25) -> 242945 | JJ25: 1897 | JL25: =+JI25-JK25 -> 242945
FT26: 270000 | JI26: =SUM(A26:JH26) -> 270000 | JJ26: 1900 | JL26: =+JI26-JK26 -> 270000
EA27: 44000 | JI27: =SUM(A27:JH27) -> 44000 | JJ27: 1902 | JL27: =+JI27-JK27 -> 44000
DV28: 209745 | JI28: =SUM(A28:JH28) -> 209745 | JJ28: 1910 | JL28: =+JI28-JK28 -> 209745
DW29: 271990 | JI29: =SUM(A29:JH29) -> 271990 | JJ29: 1917 | JL29: =+JI29-JK29 -> 271990
FJ30: 64960 | FT30: 47500 | JI30: =SUM(A30:JH30) -> 112460 | JJ30: 1920 | JL30: =+JI30-JK30 -> 112460
EA31: 205342 | JI31: =SUM(A31:JH31) -> 205342 | JJ31: 1923 | JL31: =+JI31-JK31 -> 205342
DK32: 269657.5 | JI32: =SUM(A32:JH32) -> 269657.5 | JJ32: 1927 | JL32: =+JI32-JK32 -> 269657.5
EA33: 190315 | JI33: =SUM(A33:JH33) -> 190315 | JJ33: 1931 | JL33: =+JI33-JK33 -> 190315
EA34: 250000 | JI34: =SUM(A34:JH34) -> 250000 | JJ34: 1936 | JL34: =+JI34-JK34 -> 250000
DK35: 436930 | JI35: =SUM(A35:JH35) -> 436930 | JJ35: 1940 | JL35: =+JI35-JK35 -> 436930
EA36: 263750 | JI36: =SUM(A36:JH36) -> 263750 | JJ36: 1944 | JL36: =+JI36-JK36 -> 263750
EP37: 160008 | FN37: 5616.8 | JI37: =SUM(A37:JH37) -> 165624.8 | JJ37: 1956 | JL37: =+JI37-JK37 -> 165624.8
FT38: 115050 | JI38: =SUM(A38:JH38) -> 115050 | JJ38: 1961 | JL38: =+JI38-JK38 -> 115050
HJ39: 97704 | JI39: =SUM(A39:JH39) -> 97704 | JJ39: 1968 | JL39: =+JI39-JK39 -> 97704
EA40: 251945 | JI40: =SUM(A40:JH40) -> 251945 | JJ40: 1969 | JL40: =+JI40-JK40 -> 251945
...

Sheet CONS. FUENTES FINAN
A1: Form. No.6 SRS
A3: Servicio Nacional de Salud
A4: Dirección de Fizcalización
A5: Consolidado de Ingresos y Gastos por Fuente de Financiamiento
A6: HOSPITAL MATERNO INFANTIL SAN LORENZO DE LOS MINA
A7: MAYO 2025
C8: Ingresos Generales:
E9: 1.- Balance Inicial / Fuente:
E10: Anticipo Financiero | H10: Otros Aportes | L10: Contraseña: 0001
E11: Transferencias Corrientes
E12: Venta de Servicios | G12: 1731116.6
E13: 2.- Ingresos por Fuente / Cuenta
E14: Anticipo Financiero | G14: 0 | H14: Otros Aportes | I14: =+'INGR SEGUN ORIGEN'!E37 -> 574300 | L14: OBJETAL | M14: FR | N14: VS
E15: Transferencias Corrientes | G15: =+'INGR SEGUN ORIGEN'!E12 -> 1.003168e+08 | H15: Aportes Nomina SNS | I15: 0 | L15: 2.1 | M15: =G26 -> 66630551 | N15: =H26 -> 0
E16: Venta de Servicios | G16: =+'INGR SEGUN ORIGEN'!E29 -> 7518709.1 | L16: 2.2 | M16: =G87 -> 1680824.8 | N16: =H87 -> 2044062.6
H17: TOTAL INGRESOS RDS | I17: =+G10+G11+G12+I10+G14+G15+G16+I14+I15 -> 1.1014092e+08 | L17: 2.3 | M17: ='CONS. FUENTES FINAN'!G212 -> 16608514 | N17: ='CONS. FUENTES FINAN'!H212 -> 2557401.6
L18: 2.4 | M18: =G330 -> 0 | N18: =H330 -> 480808
L19: 2.6 | M19: =G336 -> 6580673.1 | N19: =H336 -> 3927042.2
L20: 2.7 | M20: ='CONS. FUENTES FINAN'!G463 -> 0 | N20: ='CONS. FUENTES FINAN'!H463 -> 0
A21: 1 | F21: 2 | G21: 3 | I21: 4 | J21: 5
A22: Código Presupuestario | F22: Descripción Gasto por Cuenta | G22: Distribución del Gasto por Fuente de Financiamiento | I22: TOTAL | J22: %
A23: Tipo | B23: Objeto | C23: Cuenta | D23: Sub-Cuenta | E23: Auxiliar | G23: Fondo 100 | H23: Venta de Servicios/ Otros Aportes
A25: 2 | F25: Gastos | G25: =+G26+G87+G212+G330+G336+G463 -> 91500562 | H25: =+H26+H87+H212+H330+H336+H463 -> 9009314.4 | I25: =SUM(G25:H25) -> 1.0050988e+08 | J25: =+J26+J87+J212+J330+J336+J463 -> 1
A26: 2 | B26: 1 | F26: Servicios Personales | G26: =+G27+G51+G64+G71+G78 -> 66630551 | H26: =+H27+H51+H64+H71+H78 -> 0 | I26: =SUM(G26:H26) -> 66630551 | J26: =I26/$I$25 -> 0.66292541
A27: 2 | B27: 1 | C27: 1 | F27: Remuneraciones | G27: =+G28+G35+G42+G44+G46 -> 54445140 | H27: =+H28+H35+H42+H44+H46 -> 0 | I27: =SUM(G27:H27) -> 54445140 | J27: =I27/$I$25 -> 0.54168946
A28: 2 | B28: 1 | C28: 1 | D28: 1 | F28: Remuneraciones al personal fijo | G28: =SUM(G29:G34) -> 53314609 | H28: =SUM(H29:H34) -> 0 | I28: =SUM(G28:H28) -> 53314609 | J28: =I28/$I$25 -> 0.5304415
A29: 2 | B29: 1 | C29: 1 | D29: 1 | E29: 01 | F29: Sueldos a empleados fijos | G29: ='CUENTA T FONDO 100'!A126 -> 53314609 | H29: ='CUENTA T VS'!A106 -> 0 | I29: =SUM(G29:H29) -> 53314609 | J29: =I29/$I$25 -> 0.5304415
A30: 2 | B30: 1 | C30: 1 | D30: 1 | E30: 02 | F30: Sueldos a médicos | G30: ='CUENTA T FONDO 100'!B126 -> 0 | H30: ='CUENTA T VS'!B106 -> 0 | I30: =SUM(G30:H30) -> 0 | J30: =I30/$I$25 -> 0
A31: 2 | B31: 1 | C31: 1 | D31: 1 | E31: 03 | F31: Ascensos a militares | G31: ='CUENTA T FONDO 100'!C126 -> 0 | H31: ='CUENTA T VS'!C106 -> 0 | I31: =SUM(G31:H31) -> 0 | J31: =I31/$I$25 -> 0
A32: 2 | B32: 1 | C32: 1 | D32: 1 | E32: 04 | F32: Nuevas plazas maestros | G32: ='CUENTA T FONDO 100'!D126 -> 0 | H32: ='CUENTA T VS'!D106 -> 0 | I32: =SUM(G32:H32) -> 0 | J32: =I32/$I$25 -> 0
A33: 2 | B33: 1 | C33: 1 | D33: 1 | E33: 05 | F33: Incentivos y escalafón | G33: ='CUENTA T FONDO 100'!E126 -> 0 | H33: ='CUENTA T VS'!E106 -> 0 | I33: =SUM(G33:H33) -> 0 | J33: =I33/$I$25 -> 0
A34: 2 | B34: 1 | C34: 1 | D34: 1 | E34: 06 | F34: Nuevas plazas a médicos | G34: ='CUENTA T FONDO 100'!F126 -> 0 | H34: ='CUENTA T VS'!F106 -> 0 | I34: =SUM(G34:H34) -> 0 | J34: =I34/$I$25 -> 0
A35: 2 | B35: 1 | C35: 1 | D35: 2 | F35: Remuneraciones al personal con carácter transitorio | G35: =SUM(G36:G41) -> 1130531 | H35: =SUM(H36:H41) -> 0 | I35: =SUM(G35:H35) -> 1130531
A36: 2 | B36: 1 | C36: 1 | D36: 2 | E36: 03 | F36: Suplencias | G36: ='CUENTA T FONDO 100'!G126 -> 0 | H36: ='CUENTA T VS'!G106 -> 0 | I36: =SUM(G36:H36) -> 0 | J36: =I36/$I$25 -> 0
A37: 2 | B37: 1 | C37: 1 | D37: 2 | E37: 05 | F37: Sueldo al personal nominal en período probatorio | G37: ='CUENTA T FONDO 100'!H126 -> 0 | H37: ='CUENTA T VS'!H106 -> 0 | I37: =SUM(G37:H37) -> 0 | J37: =I37/$I$25 -> 0
A38: 2 | B38: 1 | C38: 1 | D38: 2 | E38: 06 | F38: Jornales | G38: ='CUENTA T FONDO 100'!I126 -> 0 | H38: ='CUENTA T VS'!I106 -> 0 | I38: =SUM(G38:H38) -> 0 | J38: =I38/$I$25 -> 0
A39: 2 | B39: 1 | C39: 1 | D39: 2 | E39: 08 | F39: Empleados temporales | G39: ='CUENTA T FONDO 100'!J126 -> 1130531 | H39: ='CUENTA T VS'!J106 -> 0 | I39: =SUM(G39:H39) -> 1130531 | J39: =I39/$I$25 -> 0.01124796
A40: 2 | B40: 1 | C40: 1 | D40: 2 | E40: 09 | F40: Personal de carácter eventual | G40: ='CUENTA T FONDO 100'!K126 -> 0 | H40: ='CUENTA T VS'!K106 -> 0 | I40: =SUM(G40:H40) -> 0 | J40: =I40/$I$25 -> 0
A41: 2 | B41: 1 | C41: 1 | D41: 2 | E41: 11 | F41: Interinato | G41: ='CUENTA T FONDO 100'!L126 -> 0 | H41: ='CUENTA T VS'!L106 -> 0 | I41: =SUM(G41:H41) -> 0 | J41: =I41/$I$25 -> 0
A42: 2 | B42: 1 | C42: 1 | D42: 3 | F42: Sueldos al personal fijo en trámite de pensiones | G42: =SUM(G43) -> 0 | H42: =SUM(H43) -> 0 | I42: =SUM(G42:H42) -> 0
...

Sheet GASTOS X ATENCION
A1: SERVICIO NACIONAL DE SALUD
A2: ='CONS. FUENTES FINAN'!A6 -> HOSPITAL MATERNO INFANTIL SAN LORENZO DE LOS MINA
A3: RESUMEN COMPARATIVO DE GASTOS ESPECIFICOS FONDO 100 Y VENTA DE SERVICIOS
A6: DETALLE | B6: FONDO 100 | C6: VENTA SERVICIOS | D6: TOTAL | E6: %
A8: Atención Directa
A9: Medicamentos e Insumos Médicos | B9: ='CONS. FUENTES FINAN'!G245+'CONS. FUENTES FINAN'!G315 -> 8317198.8 | C9: ='CONS. FUENTES FINAN'!H245+'CONS. FUENTES FINAN'!H315 -> 238984.2 | D9: =SUM(B9:C9) -> 8556183 | E9: =+D9/D12 -> 0.76593676
A10: Oxigeno | B10: ='CONS. FUENTES FINAN'!G302 -> 113956.7 | C10: ='CONS. FUENTES FINAN'!H302 -> 0 | D10: =SUM(B10:C10) -> 113956.7 | E10: =+D10/D12 -> 0.010201234
A11: Reactivos e Insumos de Laboratorio | B11: ='CONS. FUENTES FINAN'!G296+'CONS. FUENTES FINAN'!G297+'CONS. FUENTES FINAN'!G298 -> 1653884.3 | C11: ='CONS. FUENTES FINAN'!H296+'CONS. FUENTES FINAN'!H297+'CONS. FUENTES FINAN'!H298 -> 846850 | D11: =SUM(B11:C11) -> 2500734.3 | E11: =+D11/D12 -> 0.22386201
A12: Total | B12: =SUM(B9:B11) -> 10085040 | C12: =SUM(C9:C11) -> 1085834.2 | D12: =SUM(D9:D11) -> 11170874 | E12: =+D12/D39 -> 0.11114205
A13: Mantenimiento de Equipos
A14: Reparación y Mantenimiento Maquinaria y Eq. | B14: ='CONS. FUENTES FINAN'!G157+'CONS. FUENTES FINAN'!G188+'CONS. FUENTES FINAN'!G223+'CONS. FUENTES FINAN'!G252+'CONS. FUENTES FINAN'!G254+'CONS. FUENTES FINAN'!G256+'CONS. FUENTES FINAN'!G258+'CONS. FUENTES FINAN'!G261+'CONS. FUENTES FINAN'!G292+'CONS. FUENTES FINAN'!G293+'CONS. FUENTES FINAN'!G299+'CONS. FUENTES FINAN'!G300+'CONS. FUENTES FINAN'!G301+'CONS. FUENTES FINAN'!G324 -> 1717277 | C14: ='CONS. FUENTES FINAN'!H157+'CONS. FUENTES FINAN'!H188+'CONS. FUENTES FINAN'!H223+'CONS. FUENTES FINAN'!H252+'CONS. FUENTES FINAN'!H254+'CONS. FUENTES FINAN'!H256+'CONS. FUENTES FINAN'!H258+'CONS. FUENTES FINAN'!H261+'CONS. FUENTES FINAN'!H292+'CONS. FUENTES FINAN'!H293+'CONS. FUENTES FINAN'!H299+'CONS. FUENTES FINAN'!H300+'CONS. FUENTES FINAN'!H301+'CONS. FUENTES FINAN'!H324 -> 297915.54 | D14: =SUM(B14:C14) -> 2015192.5 | E14: =+D14/D16 -> 0.93123777
A15: Productos Eléctricos y Afines | B15: ='CONS. FUENTES FINAN'!G320 -> 148801.03 | C15: ='CONS. FUENTES FINAN'!H320 -> 0 | D15: =SUM(B15:C15) -> 148801.03 | E15: =+D15/D16 -> 0.068762235
A16: Total | B16: =SUM(B14:B15) -> 1866078 | C16: =SUM(C14:C15) -> 297915.54 | D16: =SUM(D14:D15) -> 2163993.5 | E16: =+D16/D39 -> 0.021530158
A17: Gastos Administrativos
A18: Servicios Personales | B18: ='CONS. FUENTES FINAN'!G26 -> 66630551 | C18: ='CONS. FUENTES FINAN'!H26 -> 0 | D18: =SUM(B18:C18) -> 66630551 | E18: =+D18/D34 -> 0.86908703
A19: Servicio Telefónico | B19: ='CONS. FUENTES FINAN'!G91+'CONS. FUENTES FINAN'!G93+'CONS. FUENTES FINAN'!G95+'CONS. FUENTES FINAN'!G97 -> 0 | C19: ='CONS. FUENTES FINAN'!H91+'CONS. FUENTES FINAN'!H93+'CONS. FUENTES FINAN'!H95+'CONS. FUENTES FINAN'!H97 -> 313463.42 | D19: =SUM(B19:C19) -> 313463.42 | E19: =+D19/D34 -> 0.0040886199
A20: Servicios Basicos (electricidad, agua y residuos solidos) | B20: ='CONS. FUENTES FINAN'!G99+'CONS. FUENTES FINAN'!G102+'CONS. FUENTES FINAN'!G104 -> 60535 | C20: ='CONS. FUENTES FINAN'!H99+'CONS. FUENTES FINAN'!H102+'CONS. FUENTES FINAN'!H104 -> 785000 | D20: =SUM(B20:C20) -> 845535 | E20: =+D20/D34 -> 0.011028627
A21: Viáticos | B21: ='CONS. FUENTES FINAN'!G111 -> 0 | C21: ='CONS. FUENTES FINAN'!H111 -> 0 | D21: =SUM(B21:C21) -> 0 | E21: =+D21/D34 -> 0
A22: Transporte y almacenaje | B22: ='CONS. FUENTES FINAN'!G116 -> 0 | C22: ='CONS. FUENTES FINAN'!H116 -> 76000 | D22: =SUM(B22:C22) -> 76000 | E22: =+D22/D34 -> 0.00099129624
A23: Alquileres | B23: ='CONS. FUENTES FINAN'!G125 -> 0 | C23: ='CONS. FUENTES FINAN'!H125 -> 529650.64 | D23: =SUM(B23:C23) -> 529650.64 | E23: =+D23/D34 -> 0.0069084301
A24: Comisiones y Gastos Bancarios | B24: ='CONS. FUENTES FINAN'!G182 -> 0 | C24: ='CONS. FUENTES FINAN'!H182 -> 0 | D24: =SUM(B24:C24) -> 0 | E24: =+D24/D34 -> 0
A25: Materiales de Oficina, Impresión y Encuadernación | B25: ='CONS. FUENTES FINAN'!G109+'CONS. FUENTES FINAN'!G312 -> 40253.04 | C25: ='CONS. FUENTES FINAN'!H109+'CONS. FUENTES FINAN'!H312 -> 0 | D25: =SUM(B25:C25) -> 40253.04 | E25: =+D25/D34 -> 0.00052503536
A26: Alimentos y Bebidas para Personas | B26: ='CONS. FUENTES FINAN'!G208+'CONS. FUENTES FINAN'!G214+'CONS. FUENTES FINAN'!G217+'CONS. FUENTES FINAN'!G219 -> 1657538.8 | C26: ='CONS. FUENTES FINAN'!H208+'CONS. FUENTES FINAN'!H214+'CONS. FUENTES FINAN'!H217+'CONS. FUENTES FINAN'!H219 -> 355075 | D26: =SUM(B26:C26) -> 2012613.8 | E26: =+D26/D34 -> 0.02625127
A27: Productos de papel, carton e impesos | B27: ='CONS. FUENTES FINAN'!G232 -> 765138.96 | C27: ='CONS. FUENTES FINAN'!H232 -> 607165 | D27: =SUM(B27:C27) -> 1372304 | E27: =+D27/D34 -> 0.01789947
A28: Articulos de Plasticos | B28: ='CONS. FUENTES FINAN'!G259 -> 384413.08 | C28: ='CONS. FUENTES FINAN'!H259 -> 0 | D28: =SUM(B28:C28) -> 384413.08 | E28: =+D28/D34 -> 0.0050140426
A29: Gasolina | B29: ='CONS. FUENTES FINAN'!G288 -> 1649337.3 | C29: ='CONS. FUENTES FINAN'!H288 -> 172000 | D29: =SUM(B29:C29) -> 1821337.3 | E29: =+D29/D34 -> 0.023756379
A30: Gasoil | B30: ='CONS. FUENTES FINAN'!G289+'CONS. FUENTES FINAN'!G290 -> 664800 | C30: ='CONS. FUENTES FINAN'!H289+'CONS. FUENTES FINAN'!H290 -> 0 | D30: =SUM(B30:C30) -> 664800 | E30: =+D30/D34 -> 0.0086712334
A31: GLP | B31: ='CONS. FUENTES FINAN'!G291+'CONS. FUENTES FINAN'!G294 -> 0 | C31: ='CONS. FUENTES FINAN'!H291+'CONS. FUENTES FINAN'!H294 -> 47073 | D31: =SUM(B31:C31) -> 47073 | E31: =+D31/D34 -> 0.00061399063
A32: Materiales de Limpieza e Higiene | B32: ='CONS. FUENTES FINAN'!G309 -> 662238.29 | C32: ='CONS. FUENTES FINAN'!H309 -> 98506.4 | D32: =SUM(B32:C32) -> 760744.69 | E32: =+D32/D34 -> 0.0099226756
A33: Otros Egresos y Gastos | B33: ='CONS. FUENTES FINAN'!G89+'CONS. FUENTES FINAN'!G107+'CONS. FUENTES FINAN'!G148+'CONS. FUENTES FINAN'!G180+'CONS. FUENTES FINAN'!G184+'CONS. FUENTES FINAN'!G186+'CONS. FUENTES FINAN'!G192+'CONS. FUENTES FINAN'!G197+'CONS. FUENTES FINAN'!G204+'CONS. FUENTES FINAN'!G225+'CONS. FUENTES FINAN'!G303+'CONS. FUENTES FINAN'!G316+'CONS. FUENTES FINAN'!G318+'CONS. FUENTES FINAN'!G322+'CONS. FUENTES FINAN'!G327+'CONS. FUENTES FINAN'!G330 -> 453966.13 | C33: ='CONS. FUENTES FINAN'!H89+'CONS. FUENTES FINAN'!H107+'CONS. FUENTES FINAN'!H148+'CONS. FUENTES FINAN'!H180+'CONS. FUENTES FINAN'!H184+'CONS. FUENTES FINAN'!H186+'CONS. FUENTES FINAN'!H192+'CONS. FUENTES FINAN'!H197+'CONS. FUENTES FINAN'!H204+'CONS. FUENTES FINAN'!H225+'CONS. FUENTES FINAN'!H303+'CONS. FUENTES FINAN'!H316+'CONS. FUENTES FINAN'!H318+'CONS. FUENTES FINAN'!H322+'CONS. FUENTES FINAN'!H327+'CONS. FUENTES FINAN'!H330 -> 714589 | D33: =SUM(B33:C33) -> 1168555.1 | E33: =+D33/D34 -> 0.015241899
A34: Total | B34: =SUM(B17:B33) -> 72968771 | C34: =SUM(C17:C33) -> 3698522.5 | D34: =SUM(D17:D33) -> 76667294 | E34: =+D34/D39 -> 0.76278368
A35: Gastos Inversion y Capital
A36: Bienes Muebles, Inmuebles e Intangibles | B36: ='CONS. FUENTES FINAN'!G336 -> 6580673.1 | C36: ='CONS. FUENTES FINAN'!H336 -> 3927042.2 | D36: =SUM(B36:C36) -> 10507715 | E36: =+D36/D38 -> 1
A37: Obras | B37: ='CONS. FUENTES FINAN'!G463 -> 0 | C37: ='CONS. FUENTES FINAN'!H463 -> 0 | D37: =SUM(B37:C37) -> 0 | E37: =+D37/D38 -> 0
A38: Total | B38: =SUM(B36:B37) -> 6580673.1 | C38: =SUM(C36:C37) -> 3927042.2 | D38: =SUM(D36:D37) -> 10507715 | E38: =+D38/D39 -> 0.10454411
A39: Total General | B39: =+B12+B16+B34+B38 -> 91500562 | C39: =+C12+C16+C34+C38 -> 9009314.4 | D39: =+D12+D16+D34+D38 -> 1.0050988e+08 | E39: =+E12+E16+E34+E38 -> 1
A40: Porciento | B40: =+B39/D39 -> 0.91036389 | C40: =+C39/D39 -> 0.08963611 | D40: =+B40+C40 -> 1

Sheet PLANTILLA PRESUPUESTO
A1: SERVICIO NACIONAL DE SALUD
A2: HOSPITAL MATERNO INFANTIL SAN LORENZO DE LOS MINA
A3: CONSOLIDADO GASTOS EJECUCION FINANCIERA 2025
A4: En RD$
A6: Detalle | B6: FONDO REPONIBLE | G6: VENTA SEVICIOS/OTROS APORTES | L6: TOTAL
A7: 2 - GASTOS | B7: 1ro | C7: 2do | D7: 3ro | E7: 4to | G7: 1ro | H7: 2do | I7: 3ro | J7: 4to | L7: 1ro | M7: 2do | N7: 3ro | O7: 4to
A8: 2.1 - REMUNERACIONES Y CONTRIBUCIONES | B8: =SUM(B9:B13) -> 1.9856074e+08 | C8: =SUM(C9:C13) -> 1.3318671e+08 | D8: =SUM(D9:D13) -> 0 | E8: =SUM(E9:E13) -> 0 | G8: =SUM(G9:G13) -> 5231553.6 | H8: =SUM(H9:H13) -> 0 | I8: =SUM(I9:I13) -> 0 | J8: =SUM(J9:J13) -> 0 | L8: =SUM(B8+G8) -> 2.0379229e+08 | M8: =SUM(C8+H8) -> 1.3318671e+08 | N8: =SUM(D8+I8) -> 0 | O8: =SUM(E8+J8) -> 0
A9: 2.1.1 - REMUNERACIONES | B9: =SUM('TRANSFERENCIA CORRIENTE'!C10:E10) -> 1.639452e+08 | C9: =SUM('TRANSFERENCIA CORRIENTE'!F10:H10) -> 1.0921624e+08 | D9: =SUM('TRANSFERENCIA CORRIENTE'!I10:K10) -> 0 | E9: =SUM('TRANSFERENCIA CORRIENTE'!L10:N10) -> 0 | G9: =SUM(VS!C10:E10) -> 0 | H9: =SUM(VS!F10:H10) -> 0 | I9: =SUM(VS!I10:K10) -> 0 | J9: =SUM(VS!L10:N10) -> 0 | L9: =SUM(B9+G9) -> 1.639452e+08 | M9: =SUM(C9+H9) -> 1.0921624e+08 | N9: =SUM(D9+I9) -> 0 | O9: =SUM(E9+J9) -> 0
A10: 2.1.2 - SOBRESUELDOS | B10: =SUM('TRANSFERENCIA CORRIENTE'!C11:E11) -> 9594398.8 | C10: =SUM('TRANSFERENCIA CORRIENTE'!F11:H11) -> 7192572.8 | D10: =SUM('TRANSFERENCIA CORRIENTE'!I11:K11) -> 0 | E10: =SUM('TRANSFERENCIA CORRIENTE'!L11:N11) -> 0 | G10: =SUM(VS!C11:E11) -> 5231553.6 | H10: =SUM(VS!F11:H11) -> 0 | I10: =SUM(VS!I11:K11) -> 0 | J10: =SUM(VS!L11:N11) -> 0 | L10: =SUM(B10+G10) -> 14825952 | M10: =SUM(C10+H10) -> 7192572.8 | N10: =SUM(D10+I10) -> 0 | O10: =SUM(E10+J10) -> 0
A11: 2.1.3 - DIETAS Y GASTOS DE REPRESENTACIÓN | B11: =SUM('TRANSFERENCIA CORRIENTE'!C12:E12) -> 0 | C11: =SUM('TRANSFERENCIA CORRIENTE'!F12:H12) -> 0 | D11: =SUM('TRANSFERENCIA CORRIENTE'!I12:K12) -> 0 | E11: =SUM('TRANSFERENCIA CORRIENTE'!L12:N12) -> 0 | G11: =SUM(VS!C12:E12) -> 0 | H11: =SUM(VS!F12:H12) -> 0 | I11: =SUM(VS!I12:K12) -> 0 | J11: =SUM(VS!L12:N12) -> 0 | L11: =SUM(B11+G11) -> 0 | M11: =SUM(C11+H11) -> 0 | N11: =SUM(D11+I11) -> 0 | O11: =SUM(E11+J11) -> 0
A12: 2.1.4 - GRATIFICACIONES Y BONIFICACIONES | B12: =SUM('TRANSFERENCIA CORRIENTE'!C13:E13) -> 0 | C12: =SUM('TRANSFERENCIA CORRIENTE'!F13:H13) -> 0 | D12: =SUM('TRANSFERENCIA CORRIENTE'!I13:K13) -> 0 | E12: =SUM('TRANSFERENCIA CORRIENTE'!L13:N13) -> 0 | G12: =SUM(VS!C13:E13) -> 0 | H12: =SUM(VS!F13:H13) -> 0 | I12: =SUM(VS!I13:K13) -> 0 | J12: =SUM(VS!L13:N13) -> 0 | L12: =SUM(B12+G12) -> 0 | M12: =SUM(C12+H12) -> 0 | N12: =SUM(D12+I12) -> 0 | O12: =SUM(E12+J12) -> 0
A13: 2.1.5 - CONTRIBUCIONES A LA SEGURIDAD SOCIAL | B13: =SUM('TRANSFERENCIA CORRIENTE'!C14:E14) -> 25021132 | C13: =SUM('TRANSFERENCIA CORRIENTE'!F14:H14) -> 16777896 | D13: =SUM('TRANSFERENCIA CORRIENTE'!I14:K14) -> 0 | E13: =SUM('TRANSFERENCIA CORRIENTE'!L14:N14) -> 0 | G13: =SUM(VS!C14:E14) -> 0 | H13: =SUM(VS!F14:H14) -> 0 | I13: =SUM(VS!I14:K14) -> 0 | J13: =SUM(VS!L14:N14) -> 0 | L13: =SUM(B13+G13) -> 25021132 | M13: =SUM(C13+H13) -> 16777896 | N13: =SUM(D13+I13) -> 0 | O13: =SUM(E13+J13) -> 0
A14: 2.2 - CONTRATACIÓN DE SERVICIOS | B14: =SUM(B15:B23) -> 9308364.9 | C14: =SUM(C15:C23) -> 1891359.8 | D14: =SUM(D15:D23) -> 0 | E14: =SUM(E15:E23) -> 0 | G14: =SUM(G15:G23) -> 8306683.8 | H14: =SUM(H15:H23) -> 3300774.7 | I14: =SUM(I15:I23) -> 0 | J14: =SUM(J15:J23) -> 0 | L14: =SUM(B14+G14) -> 17615049 | M14: =SUM(C14+H14) -> 5192134.5 | N14: =SUM(D14+I14) -> 0 | O14: =SUM(E14+J14) -> 0
A15: 2.2.1 - SERVICIOS BÁSICOS | B15: =SUM('TRANSFERENCIA CORRIENTE'!C16:E16) -> 2020024.3 | C15: =SUM('TRANSFERENCIA CORRIENTE'!F16:H16) -> 121070 | D15: =SUM('TRANSFERENCIA CORRIENTE'!J16:L16) -> 0 | E15: =SUM('TRANSFERENCIA CORRIENTE'!L16:N16) -> 0 | G15: =SUM(VS!C16:E16) -> 2341561.9 | H15: =SUM(VS!F16:H16) -> 1384071.7 | I15: =SUM(VS!I16:K16) -> 0 | J15: =SUM(VS!L16:N16) -> 0 | L15: =SUM(B15+G15) -> 4361586.2 | M15: =SUM(C15+H15) -> 1505141.7 | N15: =SUM(D15+I15) -> 0 | O15: =SUM(E15+J15) -> 0
A16: 2.2.2 - PUBLICIDAD, IMPRESIÓN Y ENCUADERNACIÓN | B16: =SUM('TRANSFERENCIA CORRIENTE'!C17:E17) -> 324206.83 | C16: =SUM('TRANSFERENCIA CORRIENTE'!F17:H17) -> 32889.84 | D16: =SUM('TRANSFERENCIA CORRIENTE'!J17:L17) -> 0 | E16: =SUM('TRANSFERENCIA CORRIENTE'!L17:N17) -> 0 | G16: =SUM(VS!C17:E17) -> 0 | H16: =SUM(VS!F17:H17) -> 0 | I16: =SUM(VS!I17:K17) -> 0 | J16: =SUM(VS!L17:N17) -> 0 | L16: =SUM(B16+G16) -> 324206.83 | M16: =SUM(C16+H16) -> 32889.84 | N16: =SUM(D16+I16) -> 0 | O16: =SUM(E16+J16) -> 0
A17: 2.2.3 - VIÁTICOS | B17: =SUM('TRANSFERENCIA CORRIENTE'!C18:E18) -> 0 | C17: =SUM('TRANSFERENCIA CORRIENTE'!F18:H18) -> 0 | D17: =SUM('TRANSFERENCIA CORRIENTE'!J18:L18) -> 0 | E17: =SUM('TRANSFERENCIA CORRIENTE'!L18:N18) -> 0 | G17: =SUM(VS!C18:E18) -> 0 | H17: =SUM(VS!F18:H18) -> 0 | I17: =SUM(VS!I18:K18) -> 0 | J17: =SUM(VS!L18:N18) -> 0 | L17: =SUM(B17+G17) -> 0 | M17: =SUM(C17+H17) -> 0 | N17: =SUM(D17+I17) -> 0 | O17: =SUM(E17+J17) -> 0
A18: 2.2.4 - TRANSPORTE Y ALMACENAJE | B18: =SUM('TRANSFERENCIA CORRIENTE'!C19:E19) -> 0 | C18: =SUM('TRANSFERENCIA CORRIENTE'!F19:H19) -> 0 | D18: =SUM('TRANSFERENCIA CORRIENTE'!J19:L19) -> 0 | E18: =SUM('TRANSFERENCIA CORRIENTE'!L19:N19) -> 0 | G18: =SUM(VS!C19:E19) -> 56000 | H18: =SUM(VS!F19:H19) -> 76000 | I18: =SUM(VS!I19:K19) -> 0 | J18: =SUM(VS!L19:N19) -> 0 | L18: =SUM(B18+G18) -> 56000 | M18: =SUM(C18+H18) -> 76000 | N18: =SUM(D18+I18) -> 0 | O18: =SUM(E18+J18) -> 0
A19: 2.2.5 - ALQUILERES Y RENTAS | B19: =SUM('TRANSFERENCIA CORRIENTE'!C20:E20) -> 0 | C19: =SUM('TRANSFERENCIA CORRIENTE'!F20:H20) -> 150000 | D19: =SUM('TRANSFERENCIA CORRIENTE'!J20:L20) -> 0 | E19: =SUM('TRANSFERENCIA CORRIENTE'!L20:N20) -> 0 | G19: =SUM(VS!C20:E20) -> 519625.15 | H19: =SUM(VS!F20:H20) -> 759170.42 | I19: =SUM(VS!I20:K20) -> 0 | J19: =SUM(VS!L20:N20) -> 0 | L19: =SUM(B19+G19) -> 519625.15 | M19: =SUM(C19+H19) -> 909170.42 | N19: =SUM(D19+I19) -> 0 | O19: =SUM(E19+J19) -> 0
A20: 2.2.6 - SEGUROS | B20: =SUM('TRANSFERENCIA CORRIENTE'!C21:E21) -> 0 | C20: =SUM('TRANSFERENCIA CORRIENTE'!F21:H21) -> 0 | D20: =SUM('TRANSFERENCIA CORRIENTE'!J21:L21) -> 0 | E20: =SUM('TRANSFERENCIA CORRIENTE'!L21:N21) -> 0 | G20: =SUM(VS!C21:E21) -> 0 | H20: =SUM(VS!F21:H21) -> 0 | I20: =SUM(VS!I21:K21) -> 0 | J20: =SUM(VS!L21:N21) -> 0 | L20: =SUM(B20+G20) -> 0 | M20: =SUM(C20+H20) -> 0 | N20: =SUM(D20+I20) -> 0 | O20: =SUM(E20+J20) -> 0
A21: 2.2.7 - SERVICIOS DE CONSERVACIÓN, REPARACIONES MENORES E INSTALACIONES TEMPORALES | B21: =SUM('TRANSFERENCIA CORRIENTE'!C22:E22) -> 6474433.8 | C21: =SUM('TRANSFERENCIA CORRIENTE'!F22:H22) -> 1174400 | D21: =SUM('TRANSFERENCIA CORRIENTE'!J22:L22) -> 0 | E21: =SUM('TRANSFERENCIA CORRIENTE'!L22:N22) -> 0 | G21: =SUM(VS!C22:E22) -> 4556850.1 | H21: =SUM(VS!F22:H22) -> 405776.67 | I21: =SUM(VS!I22:K22) -> 0 | J21: =SUM(VS!L22:N22) -> 0 | L21: =SUM(B21+G21) -> 11031284 | M21: =SUM(C21+H21) -> 1580176.6 | N21: =SUM(D21+I21) -> 0 | O21: =SUM(E21+J21) -> 0
A22: 2.2.8 - OTROS SERVICIOS NO INCLUIDOS EN CONCEPTOS ANTERIORES | B22: =SUM('TRANSFERENCIA CORRIENTE'!C23:E23) -> 489700 | C22: =SUM('TRANSFERENCIA CORRIENTE'!F23:H23) -> 413000 | D22: =SUM('TRANSFERENCIA CORRIENTE'!J23:L23) -> 0 | E22: =SUM('TRANSFERENCIA CORRIENTE'!L23:N23) -> 0 | G22: =SUM(VS!C23:E23) -> 832646.66 | H22: =SUM(VS!F23:H23) -> 675755.88 | I22: =SUM(VS!I23:K23) -> 0 | J22: =SUM(VS!L23:N23) -> 0 | L22: =SUM(B22+G22) -> 1322346.7 | M22: =SUM(C22+H22) -> 1088755.9 | N22: =SUM(D22+I22) -> 0 | O22: =SUM(E22+J22) -> 0
A23: 2.2.9 - OTRAS CONTRATACIONES DE SERVICIOS | B23: =SUM('TRANSFERENCIA CORRIENTE'!C24:E24) -> 0 | C23: =SUM('TRANSFERENCIA CORRIENTE'!F24:H24) -> 0 | D23: =SUM('TRANSFERENCIA CORRIENTE'!J24:L24) -> 0 | E23: =SUM('TRANSFERENCIA CORRIENTE'!L24:N24) -> 0 | G23: =SUM(VS!C24:E24) -> 0 | H23: =SUM(VS!F24:H24) -> 0 | I23: =SUM(VS!I24:K24) -> 0 | J23: =SUM(VS!L24:N24) -> 0 | L23: =SUM(B23+G23) -> 0 | M23: =SUM(C23+H23) -> 0 | N23: =SUM(D23+I23) -> 0 | O23: =SUM(E23+J23) -> 0
A24: 2.3 - MATERIALES Y SUMINISTROS | B24: =SUM(B25:B33) -> 46153283 | C24: =SUM(C25:C33) -> 36977120 | D24: =SUM(D25:D33) -> 0 | E24: =SUM(E25:E33) -> 0 | G24: =SUM(G25:G33) -> 7292547.3 | H24: =SUM(H25:H33) -> 5553166.8 | I24: =SUM(I25:I33) -> 0 | J24: =SUM(J25:J33) -> 0 | L24: =SUM(B24+G24) -> 53445831 | M24: =SUM(C24+H24) -> 42530287 | N24: =SUM(D24+I24) -> 0 | O24: =SUM(E24+J24) -> 0
A25: 2.3.1 - ALIMENTOS Y PRODUCTOS AGROFORESTALES | B25: =SUM('TRANSFERENCIA CORRIENTE'!C26:E26) -> 3713897.2 | C25: =SUM('TRANSFERENCIA CORRIENTE'!F26:H26) -> 2470053 | D25: =SUM('TRANSFERENCIA CORRIENTE'!I23:K23) -> 0 | E25: =SUM('TRANSFERENCIA CORRIENTE'!L26:N26) -> 0 | G25: =SUM(VS!C26:E26) -> 1500755.8 | H25: =SUM(VS!F26:H26) -> 449925 | I25: =SUM(VS!I26:K26) -> 0 | J25: =SUM(VS!L26:N26) -> 0 | L25: =SUM(B25+G25) -> 5214653 | M25: =SUM(C25+H25) -> 2919978 | N25: =SUM(D25+I25) -> 0 | O25: =SUM(E25+J25) -> 0
A26: 2.3.2 - TEXTILES Y VESTUARIOS | B26: =SUM('TRANSFERENCIA CORRIENTE'!C27:E27) -> 61630.73 | C26: =SUM('TRANSFERENCIA CORRIENTE'!F27:H27) -> 1562980.5 | D26: =SUM('TRANSFERENCIA CORRIENTE'!I24:K24) -> 0 | E26: =SUM('TRANSFERENCIA CORRIENTE'!L27:N27) -> 0 | G26: =SUM(VS!C27:E27) -> 0 | H26: =SUM(VS!F27:H27) -> 141128 | I26: =SUM(VS!I27:K27) -> 0 | J26: =SUM(VS!L27:N27) -> 0 | L26: =SUM(B26+G26) -> 61630.73 | M26: =SUM(C26+H26) -> 1704108.5 | N26: =SUM(D26+I26) -> 0 | O26: =SUM(E26+J26) -> 0
A27: 2.3.3 - PRODUCTOS DE PAPEL, CARTÓN E IMPRESOS | B27: =SUM('TRANSFERENCIA CORRIENTE'!C28:E28) -> 1826911.8 | C27: =SUM('TRANSFERENCIA CORRIENTE'!F28:H28) -> 2276081.2 | D27: =SUM('TRANSFERENCIA CORRIENTE'!I25:K25) -> 0 | E27: =SUM('TRANSFERENCIA CORRIENTE'!L28:N28) -> 0 | G27: =SUM(VS!C28:E28) -> 251163 | H27: =SUM(VS!F28:H28) -> 803989 | I27: =SUM(VS!I28:K28) -> 0 | J27: =SUM(VS!L28:N28) -> 0 | L27: =SUM(B27+G27) -> 2078074.8 | M27: =SUM(C27+H27) -> 3080070.2 | N27: =SUM(D27+I27) -> 0 | O27: =SUM(E27+J27) -> 0
A28: 2.3.4 - PRODUCTOS FARMACÉUTICOS | B28: =SUM('TRANSFERENCIA CORRIENTE'!C29:E29) -> 10797336 | C28: =SUM('TRANSFERENCIA CORRIENTE'!F29:H29) -> 8986394.6 | D28: =SUM('TRANSFERENCIA CORRIENTE'!I26:K26) -> 0 | E28: =SUM('TRANSFERENCIA CORRIENTE'!L29:N29) -> 0 | G28: =SUM(VS!C29:E29) -> 558000 | H28: =SUM(VS!F29:H29) -> 222100 | I28: =SUM(VS!I29:K29) -> 0 | J28: =SUM(VS!L29:N29) -> 0 | L28: =SUM(B28+G28) -> 11355336 | M28: =SUM(C28+H28) -> 9208494.6 | N28: =SUM(D28+I28) -> 0 | O28: =SUM(E28+J28) -> 0
A29: 2.3.5 - PRODUCTOS DE CUERO, CAUCHO Y PLÁSTICO | B29: =SUM('TRANSFERENCIA CORRIENTE'!C30:E30) -> 334708.95 | C29: =SUM('TRANSFERENCIA CORRIENTE'!F30:H30) -> 890959.43 | D29: =SUM('TRANSFERENCIA CORRIENTE'!I27:K27) -> 0 | E29: =SUM('TRANSFERENCIA CORRIENTE'!L30:N30) -> 0 | G29: =SUM(VS!C30:E30) -> 567494.87 | H29: =SUM(VS!F30:H30) -> 0 | I29: =SUM(VS!I30:K30) -> 0 | J29: =SUM(VS!L30:N30) -> 0 | L29: =SUM(B29+G29) -> 902203.82 | M29: =SUM(C29+H29) -> 890959.43 | N29: =SUM(D29+I29) -> 0 | O29: =SUM(E29+J29) -> 0
A30: 2.3.6 - PRODUCTOS DE MINERALES, METÁLICOS Y NO METÁLICOS | B30: =SUM('TRANSFERENCIA CORRIENTE'!C31:E31) -> 11630.98 | C30: =SUM('TRANSFERENCIA CORRIENTE'!F31:H31) -> 566193.69 | D30: =SUM('TRANSFERENCIA CORRIENTE'!I28:K28) -> 0 | E30: =SUM('TRANSFERENCIA CORRIENTE'!L31:N31) -> 0 | G30: =SUM(VS!C31:E31) -> 293957.3 | H30: =SUM(VS!F31:H31) -> 0 | I30: =SUM(VS!I31:K31) -> 0 | J30: =SUM(VS!L31:N31) -> 0 | L30: =SUM(B30+G30) -> 305588.28 | M30: =SUM(C30+H30) -> 566193.69 | N30: =SUM(D30+I30) -> 0 | O30: =SUM(E30+J30) -> 0
A31: 2.3.7 - COMBUSTIBLES, LUBRICANTES, PRODUCTOS QUÍMICOS Y CONEXOS | B31: =SUM('TRANSFERENCIA CORRIENTE'!C32:E32) -> 8910102 | C31: =SUM('TRANSFERENCIA CORRIENTE'!F32:H32) -> 7168869.4 | D31: =SUM('TRANSFERENCIA CORRIENTE'!I29:K29) -> 0 | E31: =SUM('TRANSFERENCIA CORRIENTE'!L32:N32) -> 0 | G31: =SUM(VS!C32:E32) -> 1660334.6 | H31: =SUM(VS!F32:H32) -> 1292460 | I31: =SUM(VS!I32:K32) -> 0 | J31: =SUM(VS!L32:N32) -> 0 | L31: =SUM(B31+G31) -> 10570437 | M31: =SUM(C31+H31) -> 8461329.4 | N31: =SUM(D31+I31) -> 0 | O31: =SUM(E31+J31) -> 0
A32: 2.3.8 - GASTOS QUE SE ASIGNARÁN DURANTE EL EJERCICIO (ART. 32 Y 33 LEY 423-06) | B32: =SUM('TRANSFERENCIA CORRIENTE'!C33:E33) -> 0 | C32: =SUM('TRANSFERENCIA CORRIENTE'!F33:H33) -> 0 | D32: =SUM('TRANSFERENCIA CORRIENTE'!I30:K30) -> 0 | E32: =SUM('TRANSFERENCIA CORRIENTE'!L33:N33) -> 0 | G32: =SUM(VS!C33:E33) -> 0 | H32: =SUM(VS!F33:H33) -> 0 | I32: =SUM(VS!I33:K33) -> 0 | J32: =SUM(VS!L33:N33) -> 0 | L32: =SUM(B32+G32) -> 0 | M32: =SUM(C32+H32) -> 0 | N32: =SUM(D32+I32) -> 0 | O32: =SUM(E32+J32) -> 0
A33: 2.3.9 - PRODUCTOS Y ÚTILES VARIOS | B33: =SUM('TRANSFERENCIA CORRIENTE'!C34:E34) -> 20497066 | C33: =SUM('TRANSFERENCIA CORRIENTE'!F34:H34) -> 13055589 | D33: =SUM('TRANSFERENCIA CORRIENTE'!I31:K31) -> 0 | E33: =SUM('TRANSFERENCIA CORRIENTE'!L34:N34) -> 0 | G33: =SUM(VS!C34:E34) -> 2460841.8 | H33: =SUM(VS!F34:H34) -> 2643564.8 | I33: =SUM(VS!I34:K34) -> 0 | J33: =SUM(VS!L34:N34) -> 0 | L33: =SUM(B33+G33) -> 22957908 | M33: =SUM(C33+H33) -> 15699153 | N33: =SUM(D33+I33) -> 0 | O33: =SUM(E33+J33) -> 0
A34: 2.4 - TRANSFERENCIAS CORRIENTES | B34: =SUM(B35:B41) -> 0 | C34: =SUM(C35:C41) -> 0 | D34: =SUM(D35:D41) -> 0 | E34: =SUM(E35:E41) -> 0 | G34: =SUM(G35:G41) -> 287786.7 | H34: =SUM(H35:H41) -> 1105381 | I34: =SUM(I35:I41) -> 0 | J34: =SUM(J35:J41) -> 0 | L34: =SUM(B34+G34) -> 287786.7 | M34: =SUM(C34+H34) -> 1105381 | N34: =SUM(D34+I34) -> 0 | O34: =SUM(E34+J34) -> 0
A35: 2.4.1 - TRANSFERENCIAS CORRIENTES AL SECTOR PRIVADO | B35: =SUM('TRANSFERENCIA CORRIENTE'!C36:E36) -> 0 | C35: =SUM('TRANSFERENCIA CORRIENTE'!F36:H36) -> 0 | D35: =SUM('TRANSFERENCIA CORRIENTE'!I36:K36) -> 0 | E35: =SUM('TRANSFERENCIA CORRIENTE'!L36:N36) -> 0 | G35: =SUM(VS!C36:E36) -> 287786.7 | H35: =SUM(VS!F36:H36) -> 1105381 | I35: =SUM(VS!I36:K36) -> 0 | J35: =SUM(VS!L36:N36) -> 0 | L35: =SUM(B35+G35) -> 287786.7 | M35: =SUM(C35+H35) -> 1105381 | N35: =SUM(D35+I35) -> 0 | O35: =SUM(E35+J35) -> 0
A36: 2.4.2 - TRANSFERENCIAS CORRIENTES AL GOBIERNO GENERAL NACIONAL | B36: =SUM('TRANSFERENCIA CORRIENTE'!C37:E37) -> 0 | C36: =SUM('TRANSFERENCIA CORRIENTE'!F37:H37) -> 0 | D36: =SUM('TRANSFERENCIA CORRIENTE'!I37:K37) -> 0 | E36: =SUM('TRANSFERENCIA CORRIENTE'!L37:N37) -> 0 | G36: =SUM(VS!C37:E37) -> 0 | H36: =SUM(VS!F37:H37) -> 0 | I36: =SUM(VS!I37:K37) -> 0 | J36: =SUM(VS!L37:N37) -> 0 | L36: =SUM(B36+G36) -> 0 | M36: =SUM(C36+H36) -> 0 | N36: =SUM(D36+I36) -> 0 | O36: =SUM(E36+J36) -> 0
A37: 2.4.3 - TRANSFERENCIAS CORRIENTES A GOBIERNOS GENERALES LOCALES | B37: =SUM('TRANSFERENCIA CORRIENTE'!C38:E38) -> 0 | C37: =SUM('TRANSFERENCIA CORRIENTE'!F38:H38) -> 0 | D37: =SUM('TRANSFERENCIA CORRIENTE'!I38:K38) -> 0 | E37: =SUM('TRANSFERENCIA CORRIENTE'!L38:N38) -> 0 | G37: =SUM(VS!C38:E38) -> 0 | H37: =SUM(VS!F38:H38) -> 0 | I37: =SUM(VS!I38:K38) -> 0 | J37: =SUM(VS!L38:N38) -> 0 | L37: =SUM(B37+G37) -> 0 | M37: =SUM(C37+H37) -> 0 | N37: =SUM(D37+I37) -> 0 | O37: =SUM(E37+J37) -> 0
A38: 2.4.4 - TRANSFERENCIAS CORRIENTES A EMPRESAS PÚBLICAS NO FINANCIERAS | B38: =SUM('TRANSFERENCIA CORRIENTE'!C39:E39) -> 0 | C38: =SUM('TRANSFERENCIA CORRIENTE'!F39:H39) -> 0 | D38: =SUM('TRANSFERENCIA CORRIENTE'!I39:K39) -> 0 | E38: =SUM('TRANSFERENCIA CORRIENTE'!L39:N39) -> 0 | G38: =SUM(VS!C39:E39) -> 0 | H38: =SUM(VS!F39:H39) -> 0 | I38: =SUM(VS!I39:K39) -> 0 | J38: =SUM(VS!L39:N39) -> 0 | L38: =SUM(B38+G38) -> 0 | M38: =SUM(C38+H38) -> 0 | N38: =SUM(D38+I38) -> 0 | O38: =SUM(E38+J38) -> 0
A39: 2.4.5 - TRANSFERENCIAS CORRIENTES A INSTITUCIONES PÚBLICAS FINANCIERAS | B39: =SUM('TRANSFERENCIA CORRIENTE'!C40:E40) -> 0 | C39: =SUM('TRANSFERENCIA CORRIENTE'!F40:H40) -> 0 | D39: =SUM('TRANSFERENCIA CORRIENTE'!I40:K40) -> 0 | E39: =SUM('TRANSFERENCIA CORRIENTE'!L40:N40) -> 0 | G39: =SUM(VS!C40:E40) -> 0 | H39: =SUM(VS!F40:H40) -> 0 | I39: =SUM(VS!I40:K40) -> 0 | J39: =SUM(VS!L40:N40) -> 0 | L39: =SUM(B39+G39) -> 0 | M39: =SUM(C39+H39) -> 0 | N39: =SUM(D39+I39) -> 0 | O39: =SUM(E39+J39) -> 0
A40: 2.4.7 - TRANSFERENCIAS CORRIENTES AL SECTOR EXTERNO | B40: =SUM('TRANSFERENCIA CORRIENTE'!C41:E41) -> 0 | C40: =SUM('TRANSFERENCIA CORRIENTE'!F41:H41) -> 0 | D40: =SUM('TRANSFERENCIA CORRIENTE'!I41:K41) -> 0 | E40: =SUM('TRANSFERENCIA CORRIENTE'!L41:N41) -> 0 | G40: =SUM(VS!C41:E41) -> 0 | H40: =SUM(VS!F41:H41) -> 0 | I40: =SUM(VS!I41:K41) -> 0 | J40: =SUM(VS!L41:N41) -> 0 | L40: =SUM(B40+G40) -> 0 | M40: =SUM(C40+H40) -> 0 | N40: =SUM(D40+I40) -> 0 | O40: =SUM(E40+J40) -> 0
A41: 2.4.9 - TRANSFERENCIAS CORRIENTES A OTRAS INSTITUCIONES PÚBLICAS | B41: =SUM('TRANSFERENCIA CORRIENTE'!C42:E42) -> 0 | C41: =SUM('TRANSFERENCIA CORRIENTE'!F42:H42) -> 0 | D41: =SUM('TRANSFERENCIA CORRIENTE'!I42:K42) -> 0 | E41: =SUM('TRANSFERENCIA CORRIENTE'!L42:N42) -> 0 | G41: =SUM(VS!C42:E42) -> 0 | H41: =SUM(VS!F42:H42) -> 0 | I41: =SUM(VS!I42:K42) -> 0 | J41: =SUM(VS!L42:N42) -> 0 | L41: =SUM(B41+G41) -> 0 | M41: =SUM(C41+H41) -> 0 | N41: =SUM(D41+I41) -> 0 | O41: =SUM(E41+J41) -> 0
...

Sheet TRANSFERENCIA CORRIENTE
A1: SERVICIO NACIONAL DE SALUD
A2: HOSPITAL MATERNO INFANTIL SAN LORENZO DE LOS MINA
A3: REGION
A4: Ejecución de Gastos Fondo (100) 2025
A5: En RD$
A7: Detalle | B7: Total | C7: Enero | D7: Febrero | E7: Marzo | F7: Abril | G7: Mayo | H7: Junio | I7: Julio | J7: Agosto | K7: Septiembre | L7: Octubre | M7: Noviembre | N7: Diciembre
A8: 2 - GASTOS
A9: 2.1 - REMUNERACIONES Y CONTRIBUCIONES | B9: =SUM(C9:N9) -> 3.3174744e+08 | C9: =SUM(C10:C14) -> 65091180 | D9: =SUM(D10:D14) -> 67131936 | E9: =SUM(E10:E14) -> 66337620 | F9: =SUM(F10:F14) -> 66556156 | G9: =SUM(G10:G14) -> 66630551 | H9: =SUM(H10:H14) -> 0 | I9: =SUM(I10:I14) -> 0 | J9: =SUM(J10:J14) -> 0 | ... N9: =SUM(N10:N14) -> 0
A10: 2.1.1 - REMUNERACIONES | B10: =SUM(C10:N10) -> 2.7316144e+08 | C10: 53640339 | D10: 55586129 | E10: 54718737 | F10: 54771097 | G10: 54445140
A11: 2.1.2 - SOBRESUELDOS | B11: =SUM(C11:N11) -> 16786972 | C11: 3196999.6 | D11: 3197999.6 | E11: 3199399.6 | F11: 3384964.5 | G11: 3807608.3
A12: 2.1.3 - DIETAS Y GASTOS DE REPRESENTACIÓN | B12: =SUM(C12:N12) -> 0
A13: 2.1.4 - GRATIFICACIONES Y BONIFICACIONES | B13: =SUM(C13:N13) -> 0
A14: 2.1.5 - CONTRIBUCIONES A LA SEGURIDAD SOCIAL | B14: =SUM(C14:N14) -> 41799028 | C14: 8253841.6 | D14: 8347807.5 | E14: 8419483.2 | F14: 8400093.9 | G14: 8377802.1
A15: 2.2 - CONTRATACIÓN DE SERVICIOS | B15: =SUM(C15:N15) -> 11199725 | C15: =SUM(C16:C24) -> 0 | D15: =SUM(D16:D24) -> 1336968.6 | E15: =SUM(E16:E24) -> 7971396.2 | F15: =SUM(F16:F24) -> 210535 | G15: =SUM(G16:G24) -> 1680824.8 | H15: =SUM(H16:H24) -> 0 | I15: =SUM(I16:I24) -> 0 | J15: =SUM(J16:J24) -> 0 | ... N15: =SUM(N16:N24) -> 0
A16: 2.2.1 - SERVICIOS BÁSICOS | B16: =SUM(C16:N16) -> 2141094.3 | E16: 2020024.3 | F16: 60535 | G16: 60535
A17: 2.2.2 - PUBLICIDAD, IMPRESIÓN Y ENCUADERNACIÓN | B17: =SUM(C17:N17) -> 357096.67 | D17: 324206.83 | G17: 32889.84
A18: 2.2.3 - VIÁTICOS | B18: =SUM(C18:N18) -> 0
A19: 2.2.4 - TRANSPORTE Y ALMACENAJE | B19: =SUM(C19:N19) -> 0
A20: 2.2.5 - ALQUILERES Y RENTAS | B20: =SUM(C20:N20) -> 150000 | F20: 150000
A21: 2.2.6 - SEGUROS | B21: =SUM(C21:N21) -> 0
A22: 2.2.7 - SERVICIOS DE CONSERVACIÓN, REPARACIONES MENORES E INSTALACIONES TEMPORALES | B22: =SUM(C22:N22) -> 7648833.7 | D22: 523061.81 | E22: 5951371.9 | G22: 1174400
A23: 2.2.8 - OTROS SERVICIOS NO INCLUIDOS EN CONCEPTOS ANTERIORES | B23: =SUM(C23:N23) -> 902700 | D23: 489700 | G23: 413000
A24: 2.2.9 - OTRAS CONTRATACIONES DE SERVICIOS | B24: =SUM(C24:N24) -> 0
A25: 2.3 - MATERIALES Y SUMINISTROS | B25: =SUM(C25:N25) -> 83130404 | C25: =SUM(C26:C34) -> 4970600.4 | D25: =SUM(D26:D34) -> 14433131 | E25: =SUM(E26:E34) -> 26749552 | F25: =SUM(F26:F34) -> 20368607 | G25: =SUM(G26:G34) -> 16608513 | H25: =SUM(H26:H34) -> 0 | I25: =SUM(I26:I34) -> 0 | J25: =SUM(J26:J34) -> 0 | ... N25: =SUM(N26:N34) -> 0
A26: 2.3.1 - ALIMENTOS Y PRODUCTOS AGROFORESTALES | D26: 591460.4 | E26: 3122436.8 | F26: 812515 | G26: 1657538
A27: 2.3.2 - TEXTILES Y VESTUARIOS | D27: 61630.73 | F27: 1562980.5
A28: 2.3.3 - PRODUCTOS DE PAPEL, CARTÓN E IMPRESOS | D28: 352366.67 | E28: 1474545.2 | F28: 1510942.2 | G28: 765138.96
A29: 2.3.4 - PRODUCTOS FARMACÉUTICOS | C29: 1862880 | D29: 2014526.8 | E29: 6919929 | F29: 6349109 | G29: 2637285.6
A30: 2.3.5 - PRODUCTOS DE CUERO, CAUCHO Y PLÁSTICO | E30: 334708.95 | F30: 506546.35 | G30: 384413.08
A31: 2.3.6 - PRODUCTOS DE MINERALES, METÁLICOS Y NO METÁLICOS | D31: 11630.98 | F31: 351015.88 | G31: 215177.81
