Workbook

Sheet RELACION DE PAGOS EMITIDOS
A5: DIRECCION DE FISCALIZACION Y CONTROL
A6: RELACION DE PAGOS EMITIDOS DURANTE EL MES
A7: ESTABLECIMIENTO: HOSPITAL MATERNO INFANTIL SAN LORENZO DE LOS MINA
A9: PAGOS CORRESPONDIENTES AL MES : SEPTIEMBRE 2025
A10: FECHA | B10: LIBRAMIENTO | C10: TRANSFERENCIA | D10: CHEQUE | E10: BENEFICIARIO | F10: NO.FACTURAS | G10: VALOR DE FACTURA | H10: VALOR PAGADO
A11: 45697 | C11: 290 | E11: LORA & ALMONTE REPARACIONES, SRL | F11: PAGO DE FACT NCF NO. B1500000209 POR ADQUISICION DE TANQUE DE AGUA DE 120 GL, PARA SER UTILIZADOS EN EL CUARTO DE BOMBA ESTE HOSPITAL, SEGÚN ORDEN DE COMPRA HSLM-2025-00862 | G11: 177799.99 | H11: 170266.1
A12: 45786 | C12: 291 | E12: CABOD, SRL | F12: PAGO DE FACTS NCFS NOS, B1500001833 y B1500001837, POR ADQUISICION DE DETERGENTE PARA LAVANDERIA, SEGÚN ORDEN DE COMPRA HSLM-2025-00615 (SALDO DE LA ORDEN) | G12: 155677.4 | H12: 149080.9
A13: 45786 | C13: 292 | E13: PRODUCTOS CANO SRL | F13: PAGO NCF B1500001400, POR ADQUISICION DE PAN SEGÚN O/C HSLM-2025-00118. | G13: 90600 | H13: 86070
A14: 45786 | C14: 293 | E14: BIO-WIN | F14: PAGO DE FACT NCF NO. B1500002583, B1500002591, POR ADQUISICION DE SANGRE DE CARNERO, SEGÚN ORDEN DE COMPRA HSLM-2025-00669 | G14: 4800 | H14: 4560
A15: 45786 | C15: 294 | E15: PLANETA AZUL | F15: PAGO DE FACT NCF E4500000014324, POR ADQUISICION DE BOTELLAS DE AGUA 16.9 ONZ,, SEGÚN ORDEN DE COMPRA 2025-00649 | G15: 14000 | H15: 14000
A16: 45786 | C16: 295 | E16: PLANETA AZUL, SA | F16: PAGO DE FACT NCF E4500000017083, E4500000017078 Y E4500000017088 POR ADQUISICION DE BOTELLONES DE AGUA, SEGÚN ORDEN DE COMPRA 2025-00587 | G16: 30060 | H16: 30060
A17: 45786 | C17: 296 | E17: PLANETA AZUL, SA | F17: PAGO DE FACT NCF E4500000009906, POR ADQUISICION DE BOTELLITAS DE AGUA DE 16.9 OZ, SEGÚN ORDEN DE COMPRA 2025-00323 | G17: 7000 | H17: 7000
A18: 45786 | C18: 297 | E18: AIR LIQUIDE DOMINICANA, SAS | F18: PAGO DE FACT NCF E4500000003124, POR ADQUISICION DE SERVICIOS DE INSTALACION Y MANTENIMIENTO DE LA RED DE OXIGENO DEL HOSPITAL, SEGÚN ORDEN DE COMPRA HSLM-2025-00860 | G18: 132966.46 | H18: 132966.46
A19: 45786 | C19: 298 | E19: JESUS FERMIN MARTINEZ | F19: PAGO DE FACT NCF NO B1500000459, POR SERVICIO DE TRANSPORTE, SEGÚN ORDEN DE COMPRA HSLM-2025-00709 | G19: 16000 | H19: 15200
A20: 45786 | C20: 299 | E20: AYUNTAMIENTO SANTO DOMINGO ESTE | F20: PAGO NCF NO B1500056270, POR SERVICIO DE RECOGIDA DE DESECHOS SOLIDOS EN EL MES DE AGOSTO 2025 | G20: 25000 | H20: 25000
A21: 45786 | C21: 300 | E21: ALTICE DOMINICANA S,A | F21: PAGO NCF E450000017823, POR SERVICIO DE COMUNICACIÓN PERIODO FACTURADO 01/09/2025 CUENTA 12843802 | G21: 111421.68 | H21: 111421.68
A22: 45786 | C22: 301 | E22: Lilian Yomayra Encarnación de Matos | F22: pago de regencia y renovación del permiso de drogas y farmacia del hospital, perteneciente al mes de agosto 2025 | G22: 25000 | H22: 25000
... A27: 46000 | C27: 306 | E27: INVERSIONES FH, SRL | F27: PAGO NCF B1500001543 ADQUISICION DE TICKETS DE COMBUSTIBLE SEGÚN O/C HSLM-2025-00912 | G27: 172000 | H27: 170573.26
A28: 17/09/2025 | C28: 307 | E28: FARMACO QUIMICA NACIONAL, SA | F28: ADQUISICION DE VALVULA HIDROCEFALICA, SEGÚN ORDEN DE COMPRA HSLM-2025-00943 | G28: 27704.04 | H28: 26530.14
A29: 18/09/2025 | C29: 308 | E29: TROPIGAS DOMINICANA, SRL | F29: PAGO DE FACT NCF NO. E450000005486, POR ADQUISICION DE GAS LICUADO DE PETROLEO SEGÚN ORDEN DE COMPRA HSLM-2025-00730 | G29: 22638 | H29: 22638
A30: 18/09/2025 | C30: 309 | E30: CENTRO DE LA SANGRE Y ESPECIALIDADES Y ESPECIALIDADES SRL | F30: PAGO NCF B1500000413, SERVICIO DE SANGRE PARA PACIENTES INTERNOS SEGÚN O/C HSLM-2025-00428. | G30: 74000 | H30: 70300
A31: 18/09/2025 | C31: 310 | E31: AYUNTAMIENTO SANTO DOMINGO ESTE | F31: PAGO NCF NO B1500056466, POR SERVICIO DE RECOGIDA DE DESECHOS SOLIDOS EN EL MES DE SEPTIEMBRE 2025 | G31: 25000 | H31: 25000
A32: 18/9/2025 | C32: 311 | E32: LABORATORIO CLINICO LCDA PATRIA M RIVAS SRL | F32: PAGO NCF NO E4500000000115 Y E4500000000098, POR SERVICIO DE ESTUDIOS ESPECIALIZADOS SEGÚN ORDEN DE COMPRA HSLM-2025-00312 | G32: 76045 | H32: 76045
A33: 18/09/2025 | C33: 312 | E33: CENTRO DE ESTUDIOS MEDICOS Y DIAGNOSTICOS POR IMÁGENES, SRL | F33: PAGO DE FACT NCF B1500000407, POR SERVICIOS DE ESTUDIOS ESPECIALIZADOS A PACIENTES INTERNOS SEGÚN O/C HSLM-2025-00311 | G33: 44300 | H33: 42085
A34: 18/09/2025 | C34: 313 | E34: WILSON HUMBERTO CIRINEO DE LA CRUZ | F34: PAGO DE FACT NCF B1500000002, POR INSTALACION DE CUBICULO Y DIVISION DE OFICINA, SEGÚN ORDEN DE COMPRA HSLM-2025-00839 | G34: 180568 | H34: 173003
A35: 18/09/2025 | C35: 314 | E35: OFITOP, SRL | F35: PAGO DE FACT NCF NO. B1500000013, POR ADQUISICION DE LETRERO TIPO SEÑALIZACION EN ACRILICO ROTULADO EN VINYL, SEGÚN ORDEN DE COMPRA HSLM-2025-00767 | G35: 136880 | H35: 131080
A36: 18/09/2025 | C36: 315 | E36: CARLOS RAFAEL DE PAULA ROSSO | F36: PAGO DE FACT NCF NO. B1500000070, POR ADQUISICION DE REPARACION DE AIRE ACONDICIONADO, SEGÚN ORDEN DE COMPRA HSLM-2025-00915 | G36: 396975.6 | H36: 380154.6
A37: 18/09/2025 | C37: 316 | E37: OFITOP, SRL | F37: PAGO DE FACT NCF NO. B1500000012, POR ADQUISICION DE NEVERA EJECUTIVA Y MOBILIARIO, SEGÚN ORDEN DE COMPRA HSLM-2025-00879 | G37: 248301.03 | H37: 237779.8
A38: 18/9/2025 | C38: 317 | E38: OFITOP, SRL | F38: PAGO DE FACT NCF NO. B1500000011, POR ADQUISICION DE LAMINADOS EN VINIL ADHESIVO, SEGÚN ORDEN DE COMPRA HSLM-2025-00816 | G38: 132840.57 | H38: 127211.73
A39: 22/09/2025 | C39: 318 | E39: PRODUCTOS TECNOLOGICOS E INDUSTRIALES JARDIN DEL EDEN, E.I.R.L | F39: PAGO DE FACT NCF NO. B1500000090, POR ADQUISICION DE DETERGENTE PARA LA LAVANDERIA, SEGÚN ORDEN DE COMPRA HSLM-2025-00918 | G39: 365139.2 | H39: 349667.2
... A43: 26/09/2025 | C43: 322 | E43: OSCAR A RENTA NEGRON, SA | F43: ADQUISICION DE MEDICAMENTOS, | G43: 34270.4 | H43: 34270.4
A44: 29/9/2025 | C44: 322-A | E44: NOMINA INCENTIVOS | F44: PAGO NOMINA INCENTIVO SENASA ENERO-JULIO 2025 | G44: 4413127.6 | H44: 4413127.6
A45: 03/09/2025 | B45: 3911 | E45: Insocorp, SRL | F45: PAGO DE FACT NCF B1500000231 POR ADQUISICION DE ASPIRADORES DE SECRECIONES ELECTRICAS SEGUN O/C HSLM- 2025-00724. | G45: 1945820
A46: 03/09/2025 | B46: 3915 | E46: Insocorp, SRL | F46: PAGO DE FACT NCF B1500000226 POR ADQUISICION DE LENTE DE LAPAROSCOPIA SEGUN O/C HSLM-2025-00857. | G46: 271000
A47: 03/09/2025 | B47: 3919 | E47: Corporacion Medica A.G., SRL | F47: PAGO DE FACT NCF B1500000128 POR ADQUISICION DE PAPEL GRADO MEDICO SEGUN O/C HSLM-2025-00858. | G47: 260780
A48: 03/09/2025 | B48: 3923 | E48: Tu Amigo, SRL | F48: PAGO DE FACT NCF B1500000312 POR ADQUISICION DE GASOIL REGULAR SEGUN O/C HSLM-2025-00842. | G48: 337200
A49: 03/09/2025 | B49: 3927 | E49: Ofitop, S.R.L | F49: PAGO DE FACT NCF B1500000007 POR ADQUISICION DE SILLA CAJERO, SILLON SEMI EJECUTIVO Y SILLA DE VISITA SEGUN O/C HSLM-2025-00795. | G49: 260443.67
A50: 03/09/2025 | B50: 3932 | E50: Ofitop, S.R.L | F50: PAGO DE FACT NCF B1500000008 POR ADQUISICION DE SILLA CAJERO SEGUN O/C HSLM-2025-00798. | G50: 45366.46
A51: 04/09/2025 | B51: 3936 | E51: Abrias Novo Group SRL | F51: PAGO DE FACT NCF B1500000157 POR ADQUISICION DE COCTEL SIN ALCOHOL PARA 500 PERSONAS SEGUN O/C HSLM-2025-00821. | G51: 242313
A52: 04/09/2025 | B52: 3940 | E52: Lambda Diagnósticos, SRL | F52: PAGO DE FACT NCF B1500002206 POR ADQUISICION DE REACTIVOS Y UTILES MEDICOS SEGUN O/C HSLM-2024-01177. | G52: 163477.94
...

Sheet RELACION ORDENES DE COMPRAS
A4: SERVICIO NACIONAL DE SALUD
A5: DIRECCION DE FISCALIZACION
A6: RELACIÓN DE ORDENES DE COMPRAS DE BIENES Y SERVICIOS EFECTUADAS MES DE SEPTIEMBRE 2025
A7: ESTABLECIMIENTO: HOSPITAL MATERNO INFANTIL SAN LORENZO DE LOS MINA REGION OZAMA
A8: Fecha | B8: # Orden de Compra o Servicios | C8: # DE EXPEDIENTE(PROCESO CELEBRADO) | D8: No. De Factura Fiscal NCF | E8: Fuente. Financ (FR-VS) | F8: Beneficiario | G8: Rubro | H8: No. Cta. Objetal del Gasto | I8: Valor | J8: Status del proceso | K8: solo observar cuando se presentas esos procesos
A9: 45901.419 | B9: HSML-2025-00698 | C9: HSLM-DAF-CD-2025-0698 | F9: Margayu, SRL | G9: 50110000 | H9: Productos de carne y aves de corral | I9: 227500 | J9: Adjudicado
A10: 45901.459 | B10: HSML-2025-00882 | C10: HSLM-DAF-CD-2025-0699 | F10: Farmacia Ruth, SRL | G10: 85120000 | H10: Práctica médica | I10: 270000 | J10: Adjudicado
A11: 45901.459 | B11: HSML-2025-00880 | C11: HSLM-DAF-CD-2025-0700 | F11: Corporacion Medica A.G., SRL | G11: 42280000 | H11: Productos para la esterilización médica | I11: 260780 | J11: Adjudicado
A12: 45901.626 | B12: HSML-2025-00885 | C12: HSLM-DAF-CD-2025-0701 | F12: Farmaco Internacional, SRL | G12: 42220000 | H12: Productos para administración intravenosa y arterial | I12: 216825 | J12: Adjudicado
A13: 45901.626 | B13: HSML-2025-00884 | C13: HSLM-DAF-CD-2025-0702 | F13: Empresa Rotricomercial, SRL | G13: 51190000 | H13: Agentes que afectan el agua y los electrolitos | I13: 240000 | J13: Adjudicado
A14: 45902.42 | B14: HSML-2025-00886 | C14: HSLM-DAF-CD-2025-0703 | F14: Dumas Pharmaceuticals, SRL | G14: 42200000 | H14: Productos de hacer imágenes diagnósticas médicas y de medicina nuclear | I14: 197768 | J14: Adjudicado
A15: 45902.46 | B15: HSML-2025-00910 | C15: HSLM-DAF-CM-2025-0220 | F15: INSOCORP, SRL | G15: 42290000 | H15: Productos quirúrgicos | I15: 708000 | J15: Adjudicado
A16: 45902.503 | B16: HSML-2025-00909 | C16: HSLM-DAF-CM-2025-0221 | F16: INSOCORP, SRL | G16: 42290000 | H16: Productos quirúrgicos | I16: 354815 | J16: Adjudicado
A17: 45902.507 | B17: HSML-2025-00808 | C17: HSLM-DAF-CD-2025-0704 | F17: INSOCORP, SRL | G17: 41100000 | H17: Equipo de laboratorio y científico | I17: 26550 | J17: Adjudicado
A18: 45902.542 | B18: HSML-2025-00902 | C18: HSLM-DAF-CD-2025-0705 | F18: Jhonathan Del Rosario Franco | G18: 80120000 | H18: Servicios legales | I18: 17700 | J18: Adjudicado
A19: 45902.585 | B19: HSML-2025-00901 | C19: HSLM-DAF-CD-2025-0706 | F19: Diucam Group SRL | G19: 47130000 | H19: Suministros de aseo y limpieza | I19: 212400 | J19: Adjudicado
A20: 45903.419 | B20: HSML-2025-00897 | C20: HSLM-DAF-CD-2025-0707 | F20: Sermetic, SRL | G20: 71120000 | H20: Servicios de construcción y perforación de pozos | I20: 90049 | J20: Adjudicado
... A66: 45915.418 | B66: HSML-2025-00937 | C66: HSLM-DAF-CD-2025-0739 | F66: Diucam Group SRL | G66: 47130000 | H66: Suministros de aseo y limpieza | I66: 264674 | J66: Adjudicado
A67: 45915.459 | B67: Analisis de oferta | C67: HSLM-DAF-CD-2025-0741 | G67: 50200000 | H67: Bebidas | J67: Evaluación
A68: 45915.459 | B68: HSML-2025-00938 | C68: HSLM-DAF-CD-2025-0740 | F68: Papelería E. Impresos Crishoan, SRL | G68: 44120000 | H68: Suministros de oficina | I68: 271072 | J68: Adjudicado
A69: 45915.503 | B69: HSML-2025-00940 | C69: HSLM-DAF-CD-2025-0742 | F69: Bello-Lab, SRL | G69: 42290000 | H69: Productos quirúrgicos | I69: 206175 | J69: Adjudicado
A70: 45916.419 | B70: HSML-2025-00941 | C70: HSLM-DAF-CD-2025-0743 | F70: Diucam Group SRL | G70: 47130000 | H70: Suministros de aseo y limpieza | I70: 256532 | J70: Adjudicado
A71: 45916.431 | B71: HSML-2025-00943 | C71: HSLM-DAF-CD-2025-0744 | F71: Farmaco Quimica Nacional, SA | G71: 42180000 | H71: Productos de examen y control del paciente | I71: 27704 | J71: Adjudicado
A72: 45916.502 | B72: HSML-2025-00975 | C72: HSLM-DAF-CM-2025-0237 | F72: Negocios Suheidy Rodriguez, SRL | G72: 24110000 | H72: Recipientes y almacenamiento | I72: 858450 | J72: Adjudicado
A73: 45916.543 | B73: HSML-2025-00946 | C73: HSLM-DAF-CD-2025-0745 | F73: Dumas Pharmaceuticals, SRL | G73: 51180000 | H73: Hormonas y antagonistas hormonales | I73: 26900 | J73: Adjudicado
A74: 45916.569 | B74: HSML-2025-00947 | C74: HSLM-DAF-CD-2025-0746 | F74: Oficclin Comercial, SRL | G74: 51120000 | H74: Medicamentos cardiovasculares | I74: 145220 | J74: Adjudicado
A75: 45917.334 | B75: HSML-2025-00992 | C75: HSLM-DAF-CM-2025-0238 | F75: Khris Aus Pharmacy, S.R.L | G75: 51100000 | H75: Medicamentos antiinfecciosos | I75: 1200000 | J75: Adjudicado
A76: 45917.424 | B76: HSML-2025-00951 | C76: HSLM-DAF-CD-2025-0747 | F76: CEM Caribbean Equipment Medical, SRL | G76: 14110000 | H76: Productos de papel | I76: 28462 | J76: Adjudicado
A77: 45917.469 | B77: HSML-2025-00953 | C77: HSLM-DAF-CD-2025-0748 | F77: Osiris & Co, SA | G77: 42240000 | H77: Productos medicinales de deportes y ortopédicos y prótesis | I77: 212738 | J77: Adjudicado
A78: 45917.507 | B78: HSML-2025-00950 | C78: HSLM-DAF-CD-2025-0749 | F78: Antares Pharma, SRL | G78: 51100000 | H78: Medicamentos antiinfecciosos | I78: 225000 | J78: Adjudicado
A79: 45917.585 | B79: HSML-2025-00952 | C79: HSLM-DAF-CD-2025-0750 | F79: G & M Gelmat Comercial, SRL | G79: 51150000 | H79: Medicamentos para el sistema nervioso autónomo | I79: 144000 | J79: Adjudicado
... A97: 45922.514 | B97: HSML-2025-00974 | C97: HSLM-DAF-CD-2025-0767 | F97: Medequip, SRL | G97: 47120000 | H97: Equipo de aseo | I97: 168003 | J97: Adjudicado
A98: 45922.626 | B98: Analisis de oferta | C98: HSLM-DAF-CM-2025-0240 | G98: 50100000 | H98: Frutos secos | J98: Evaluación
A99: 45922.708 | B99: HSML-2025-00979 | C99: HSLM-DAF-CD-2025-0768 | F99: Grupo Irmaceli Services, S.R.L. | G99: 46190000 | H99: Protección contra incendios | I99: 135936 | J99: Adjudicado
A100: 45923.419 | B100: Analisis de oferta | C100: HSLM-DAF-CM-2025-0241 | G100: 50110000 | H100: Productos de carne y aves de corral | J100: Evaluación
A101: 45923.461 | B101: HSML-2025-00978 | C101: HSLM-DAF-CD-2025-0769 | F101: Suplimed, SRL | G101: 42310000 | H101: Productos para el cuidado de heridas | I101: 172643 | J101: Adjudicado
A102: 45923.502 | B102: HSML-2025-00976 | C102: HSLM-DAF-CD-2025-0772 | F102: Hauspital, SRL | G102: 42270000 | H102: Productos de resucitación, anestesia y respiratorio | I102: 159300 | J102: Adjudicado
A103: 45923.503 | B103: Analisis de oferta | C103: HSLM-DAF-CM-2025-0242 | G103: 50110000 | H103: Productos de carne y aves de corral | J103: Evaluación
A104: 45923.503 | B104: HSML-2025-00977 | C104: HSLM-DAF-CD-2025-0771 | F104: Hauspital, SRL | G104: 51190000 | H104: Agentes que afectan el agua y los electrolitos | I104: 117000 | J104: Adjudicado
A105: 45923.503 | B105: HSML-2025-00980 | C105: HSLM-DAF-CD-2025-0770 | F105: Bello-Lab, SRL | G105: 41110000 | H105: Instrumentos de medida, observación y ensayo | I105: 272294 | J105: Adjudicado
...

Sheet CONS. FUENTES FINAN
A1: Form. No.6 SRS
A3: Servicio Nacional de Salud
A4: Dirección de Fizcalización
A5: Consolidado de Ingresos y Gastos por Fuente de Financiamiento
A6: HOSPITAL MATERNO INFANTIL SAN LORENZO DE LOS MINA
A7: SEPTIEMBRE 2025
C8: Ingresos Generales:
E9: 1.- Balance Inicial / Fuente:
E10: Anticipo Financiero | H10: Otros Aportes | L10: Contraseña: 0001
E11: Transferencias Corrientes
E12: Venta de Servicios | G12: 209079.81
E13: 2.- Ingresos por Fuente / Cuenta
E14: Anticipo Financiero | H14: Otros Aportes | I14: =+'INGR SEGUN ORIGEN'!E38 -> 489300 | L14: OBJETAL | M14: FR | N14: VS
E15: Transferencias Corrientes | G15: =+'INGR SEGUN ORIGEN'!E12 -> 1.0574137e+08 | H15: Aportes Nomina SNS | L15: 2.1 | M15: =G26 -> 71591504 | N15: =H26 -> 4413127.6
E16: Venta de Servicios | G16: =+'INGR SEGUN ORIGEN'!E30 -> 12277160 | L16: 2.2 | M16: =G87 -> 7782458.8 | N16: =H87 -> 1557736.2
H17: TOTAL INGRESOS RDS | I17: =+G10+G11+G12+I10+G14+G15+G16+I14+I15 -> 1.1871691e+08 | L17: 2.3 | M17: ='CONS. FUENTES FINAN'!G212 -> 25141648 | N17: ='CONS. FUENTES FINAN'!H212 -> 3168875.7
L18: 2.4 | M18: =G330 -> 0 | N18: =H330 -> 21600
L19: 2.6 | M19: =G336 -> 5819603.3 | N19: =H336 -> 2245366
L20: 2.7 | M20: ='CONS. FUENTES FINAN'!G463 -> 0 | N20: ='CONS. FUENTES FINAN'!H463 -> 0
A21: 1 | F21: 2 | G21: 3 | I21: 4 | J21: 5
A22: Código Presupuestario | F22: Descripción Gasto por Cuenta | G22: Distribución del Gasto por Fuente de Financiamiento | I22: TOTAL | J22: %
A23: Tipo | B23: Objeto | C23: Cuenta | D23: Sub-Cuenta | E23: Auxiliar | G23: Fondo 100 | H23: Venta de Servicios/ Otros Aportes
A25: 2 | F25: Gastos | G25: =+G26+G87+G212+G330+G336+G463 -> 1.1033521e+08 | H25: =+H26+H87+H212+H330+H336+H463 -> 11406705 | I25: =SUM(G25:H25) -> 1.2174192e+08 | J25: =+J26+J87+J212+J330+J336+J463 -> 1
A26: 2 | B26: 1 | F26: Servicios Personales | G26: =+G27+G51+G64+G71+G78 -> 71591504 | H26: =+H27+H51+H64+H71+H78 -> 4413127.6 | I26: =SUM(G26:H26) -> 76004631 | J26: =I26/$I$25 -> 0.62430945
A27: 2 | B27: 1 | C27: 1 | F27: Remuneraciones | G27: =+G28+G35+G42+G44+G46 -> 59165425 | H27: =+H28+H35+H42+H44+H46 -> 0 | I27: =SUM(G27:H27) -> 59165425
A28: 2 | B28: 1 | C28: 1 | D28: 1 | F28: Remuneraciones al personal fijo | G28: =SUM(G29:G34) -> 58052894 | H28: =SUM(H29:H34) -> 0 | I28: =SUM(G28:H28) -> 58052894
A29: 2 | B29: 1 | C29: 1 | D29: 1 | E29: 01 | F29: Sueldos a empleados fijos | G29: ='CUENTA T FONDO 100'!A126 -> 58052894 | H29: ='CUENTA T VS'!A75 -> 0 | I29: =SUM(G29:H29) -> 58052894 | J29: =I29/$I$25 -> 0.47685213
A30: 2 | B30: 1 | C30: 1 | D30: 1 | E30: 02 | F30: Sueldos a médicos | G30: ='CUENTA T FONDO 100'!B126 -> 0 | H30: ='CUENTA T VS'!B75 -> 0 | I30: =SUM(G30:H30) -> 0 | J30: =I30/$I$25 -> 0
A31: 2 | B31: 1 | C31: 1 | D31: 1 | E31: 03 | F31: Ascensos a militares | G31: ='CUENTA T FONDO 100'!C126 -> 0 | H31: ='CUENTA T VS'!C75 -> 0 | I31: =SUM(G31:H31) -> 0 | J31: =I31/$I$25 -> 0
A32: 2 | B32: 1 | C32: 1 | D32: 1 | E32: 04 | F32: Nuevas plazas maestros | G32: ='CUENTA T FONDO 100'!D126 -> 0 | H32: ='CUENTA T VS'!D75 -> 0 | I32: =SUM(G32:H32) -> 0 | J32: =I32/$I$25 -> 0
A33: 2 | B33: 1 | C33: 1 | D33: 1 | E33: 05 | F33: Incentivos y escalafón | G33: ='CUENTA T FONDO 100'!E126 -> 0 | H33: ='CUENTA T VS'!E75 -> 0 | I33: =SUM(G33:H33) -> 0 | J33: =I33/$I$25 -> 0
A34: 2 | B34: 1 | C34: 1 | D34: 1 | E34: 06 | F34: Nuevas plazas a médicos | G34: ='CUENTA T FONDO 100'!F126 -> 0 | H34: ='CUENTA T VS'!F75 -> 0 | I34: =SUM(G34:H34) -> 0 | J34: =I34/$I$25 -> 0
A35: 2 | B35: 1 | C35: 1 | D35: 2 | F35: Remuneraciones al personal con carácter transitorio | G35: =SUM(G36:G41) -> 1112531 | H35: =SUM(H36:H41) -> 0 | I35: =SUM(G35:H35) -> 1112531
A36: 2 | B36: 1 | C36: 1 | D36: 2 | E36: 03 | F36: Suplencias | G36: ='CUENTA T FONDO 100'!G126 -> 0 | H36: ='CUENTA T VS'!G75 -> 0 | I36: =SUM(G36:H36) -> 0 | J36: =I36/$I$25 -> 0
A37: 2 | B37: 1 | C37: 1 | D37: 2 | E37: 05 | F37: Sueldo al personal nominal en período probatorio | G37: ='CUENTA T FONDO 100'!H126 -> 0 | H37: ='CUENTA T VS'!H75 -> 0 | I37: =SUM(G37:H37) -> 0 | J37: =I37/$I$25 -> 0
A38: 2 | B38: 1 | C38: 1 | D38: 2 | E38: 06 | F38: Jornales | G38: ='CUENTA T FONDO 100'!I126 -> 0 | H38: ='CUENTA T VS'!I75 -> 0 | I38: =SUM(G38:H38) -> 0 | J38: =I38/$I$25 -> 0
A39: 2 | B39: 1 | C39: 1 | D39: 2 | E39: 08 | F39: Empleados temporales | G39: ='CUENTA T FONDO 100'!J126 -> 1112531 | H39: ='CUENTA T VS'!J75 -> 0 | I39: =SUM(G39:H39) -> 1112531 | J39: =I39/$I$25 -> 0.0091384384
A40: 2 | B40: 1 | C40: 1 | D40: 2 | E40: 09 | F40: Personal de carácter eventual | G40: ='CUENTA T FONDO 100'!K126 -> 0 | H40: ='CUENTA T VS'!K75 -> 0 | I40: =SUM(G40:H40) -> 0 | J40: =I40/$I$25 -> 0
A41: 2 | B41: 1 | C41: 1 | D41: 2 | E41: 11 | F41: Interinato | G41: ='CUENTA T FONDO 100'!L126 -> 0 | H41: ='CUENTA T VS'!L75 -> 0 | I41: =SUM(G41:H41) -> 0 | J41: =I41/$I$25 -> 0
A42: 2 | B42: 1 | C42: 1 | D42: 3 | F42: Sueldos al personal fijo en trámite de pensiones | G42: =SUM(G43) -> 0 | H42: =SUM(H43) -> 0 | I42: =SUM(G42:H42) -> 0
...

Sheet CUENTA T FONDO 100
A1: D E S G L O S E D E L A S C U E N T A S
A2: 211101 | B2: 211102 | C2: 211103 | D2: 211104 | E2: 211105 | F2: 211106 | G2: 211203 | H2: 211205 | I2: 211206 | J2: 211208 | K2: 211209 | L2: 211211 | M2: 211301 | N2: 211401 | O2: 211501 | P2: 211502 | Q2: 211503 | R2: 211504 | S2: 212101 | T2: 212201 | U2: 212203 | V2: 212204 | W2: 212205 | X2: 212206 | Y2: 212207 | Z2: 212208 | AA2: 212209 | AB2: 212210 | AC2: 213101 | AD2: 213102 | AE2: 213201 | AF2: 213202 | AG2: 214101 | AH2: 214201 | AI2: 214202 | AJ2: 214203 | AK2: 215101 | AL2: 215201 | AM2: 215301 | AN2: 215401 | AO2: 221101 | AP2: 221201 | AQ2: 221301 | AR2: 221401 | AS2: 221501 | AT2: 221601 | AU2: 221602 | AV2: 221701 | AW2: 221801 | AX2: 222101 | AY2: 222201 | AZ2: 223101 | BA2: 223201 | BB2: 224101 | BC2: 224201 | BD2: 224301 | BE2: 224401 | BF2: 225101 | BG2: 225201 | BH2: 225301 | BI2: 225302 | BJ2: 225303 | BK2: 225304 | BL2: 225305 | BM2: 225401 | BN2: 225501 | BO2: 225601 | BP2: 225701 | BQ2: 225801 | BR2: 225901 | BS2: 226101 | BT2: 226201 | BU2: 226301 | BV2: 226401 | BW2: 227101 | BX2: 227102 | BY2: 227103 | BZ2: 227104 | CA2: 227105 | CB2: 227106 | CC2: 227107 | CD2: 227199 | CE2: 227201 | CF2: 227202 | CG2: 227203 | CH2: 227204 | CI2: 227205 | CJ2: 227206 | CK2: 227207 | CL2: 227208 | CM2: 227299 | CN2: 227301 | CO2: 228101 | CP2: 228201 | CQ2: 228301 | CR2: 228401 | CS2: 228501 | CT2: 228502 | CU2: 228503 | CV2: 228601 | CW2: 228602 | CX2: 228603 | CY2: 228604 | CZ2: 228701 | DA2: 228702 | DB2: 228703 | DC2: 228704 | DD2: 228705 | DE2: 228706 | DF2: 228801 | DG2: 228802 | DH2: 228803 | DI2: 229201 | DJ2: 229203 | DK2: 231101 | DL2: 231102 | DM2: 231201 | DN2: 231301 | DO2: 231302 | DP2: 231303 | DQ2: 231401 | DR2: 232101 | DS2: 232201 | DT2: 232301 | DU2: 233101 | DV2: 233201 | DW2: 233301 | DX2: 233401 | DY2: 233501 | DZ2: 233601 | EA2: 234101 | EB2: 234201 | EC2: 235101 | ED2: 235201 | EE2: 235301 | EF2: 235401 | EG2: 235501 | EH2: 236101 | EI2: 236102 | EJ2: 236103 | EK2: 236104 | EL2: 236105 | EM2: 236201 | EN2: 236202 | EO2: 236203 | EP2: 236304 | EQ2: 236305 | ER2: 236306 | ES2: 236401 | ET2: 236402 | EU2: 236403 | EV2: 236404 | EW2: 236405 | EX2: 236406 | EY2: 236407 | EZ2: 236901 | FA2: 237101 | FB2: 237102 | FC2: 237103 | FD2: 237104 | FE2: 237105 | FF2: 237106 | FG2: 237107 | FH2: 237201 | FI2: 237202 | FJ2: 237203 | FK2: 237204 | FL2: 237205 | FM2: 237206 | FN2: 237299 | FO2: 238101 | FP2: 238201 | FQ2: 239101 | FR2: 239102 | FS2: 239201 | FT2: 239301 | FU2: 239401 | FV2: 239501 | FW2: 239601 | FX2: 239701 | FY2: 239801 | FZ2: 239802 | GA2: 239901 | GB2: 239904 | GC2: 241201 | GD2: 241202 | GE2: 241203 | GF2: 241204 | GG2: 241205 | GH2: 261101 | GI2: 261201 | GJ2: 261301 | GK2: 261401 | GL2: 261901 | GM2: 262101 | GN2: 262201 | GO2: 262301 | GP2: 262401 | GQ2: 263101 | GR2: 263201 | GS2: 263301 | GT2: 263401 | GU2: 264101 | GV2: 264201 | GW2: 264301 | GX2: 264401 | GY2: 264501 | GZ2: 264601 | HA2: 264701 | HB2: 264801 | HC2: 265101 | HD2: 265201 | HE2: 265301 | HF2: 265401 | HG2: 265501 | HH2: 265601 | HI2: 265701 | HJ2: 265801 | HK2: 266101 | HL2: 266201 | HM2: 267101 | HN2: 267201 | HO2: 267301 | HP2: 267401 | HQ2: 267501 | HR2: 267601 | HS2: 267701 | HT2: 267801 | HU2: 267901 | HV2: 268101 | HW2: 268201 | HX2: 268301 | HY2: 268302 | HZ2: 268401 | IA2: 268501 | IB2: 268601 | IC2: 268701 | ID2: 268802 | IE2: 268803 | IF2: 268804 | IG2: 268901 | IH2: 269101 | II2: 269102 | IJ2: 269201 | IK2: 269202 | IL2: 269301 | IM2: 269401 | IN2: 269501 | IO2: 269502 | IP2: 269503 | IQ2: 2269901 | IR2: 271101 | IS2: 271201 | IT2: 271301 | IU2: 271401 | IV2: 272101 | IW2: 272201 | IX2: 272301 | IY2: 272401 | IZ2: 272501 | JA2: 272601 | JB2: 272701 | JC2: 272801 | JD2: 272901 | JE2: 273101 | JF2: 273201 | JG2: 274101 | JH2: 274201 | JI2: Totales | JJ2: TRANSF NO. | JK2: VALOR | JL2: RETENCION | JM2: AÑOS ANTERIORES | JN2: 2022 | JO2: Total | JP2: Proveedor Informal
GQ3: 1945820 | JI3: =SUM(A3:JH3) -> 1945820 | JJ3: 3911 | JO3: =+JM3+JN3 -> 0
FT4: 271000 | JI4: =SUM(A4:JH4) -> 271000 | JJ4: 3915
FT5: 260780 | JI5: =SUM(A5:JH5) -> 260780 | JJ5: 3919
FB6: 337200 | JI6: =SUM(A6:JH6) -> 337200 | JJ6: 3923
GH7: 260443.67 | JI7: =SUM(A7:JH7) -> 260443.67 | JJ7: 3927
GH8: 45366.46 | JI8: =SUM(A8:JH8) -> 45366.46 | JJ8: 3932
DK9: 242313 | JI9: =SUM(A9:JH9) -> 242313 | JJ9: 3936
FJ10: 120000 | FT10: 43477.94 | JI10: =SUM(A10:JH10) -> 163477.94 | JJ10: 3940
EA11: 75000 | JI11: =SUM(A11:JH11) -> 75000 | JJ11: 3944
FT12: 259328 | JI12: =SUM(A12:JH12) -> 259328 | JJ12: 3948
EA13: 271700 | JI13: =SUM(A13:JH13) -> 271700 | JJ13: 3952
EA14: 180000 | JI14: =SUM(A14:JH14) -> 180000 | JJ14: 3963
FT15: 177000 | JI15: =SUM(A15:JH15) -> 177000 | JJ15: 4016
EA16: 78000 | JI16: =SUM(A16:JH16) -> 78000 | JJ16: 4020
DK17: 166220 | JI17: =SUM(A17:JH17) -> 166220 | JJ17: 4029
FT18: 144019 | JI18: =SUM(A18:JH18) -> 144019 | JJ18: 4033
FT19: 188800 | JI19: =SUM(A19:JH19) -> 188800 | JJ19: 4037
EA20: 230000 | JI20: =SUM(A20:JH20) -> 230000 | JJ20: 4044
EA21: 193640 | FT21: 39936 | JI21: =SUM(A21:JH21) -> 233576 | JJ21: 4045
FT22: 259234.2 | JI22: =SUM(A22:JH22) -> 259234.2 | JJ22: 4049
EA23: 92500 | JI23: =SUM(A23:JH23) -> 92500 | JJ23: 4056
AV24: 60535 | JI24: =SUM(A24:JH24) -> 60535 | JJ24: 4060
W25: 45000 | JI25: =SUM(A25:JH25) -> 45000 | JJ25: 4067
J26: 1112531 | AK26: 78878.45 | AL26: 78989.7 | AM26: 13250.76 | JI26: =SUM(A26:JH26) -> 1283649.9 | JJ26: 4069
FQ27: 112690 | JI27: =SUM(A27:JH27) -> 112690 | JJ27: 4074
FT28: 247800 | JI28: =SUM(A28:JH28) -> 247800 | JJ28: 4078
EA29: 79600 | JI29: =SUM(A29:JH29) -> 79600 | JJ29: 4083
CH30: 13039 | JI30: =SUM(A30:JH30) -> 13039 | JJ30: 4095
FT31: 368160 | JI31: =SUM(A31:JH31) -> 368160 | JJ31: 4099
EA32: 735000 | JI32: =SUM(A32:JH32) -> 735000 | JJ32: 4104
EA33: 1875000 | JI33: =SUM(A33:JH33) -> 1875000 | JJ33: 4108
DJ34: 1095158 | JI34: =SUM(A34:JH34) -> 1095158 | JJ34: 4115
DJ35: 1144423 | JI35: =SUM(A35:JH35) -> 1144423 | JJ35: 4119
GK36: 111510 | JI36: =SUM(A36:JH36) -> 111510 | JJ36: 4126
DV37: 97940 | JI37: =SUM(A37:JH37) -> 97940 | JJ37: 4132
GJ38: 99049.2 | JI38: =SUM(A38:JH38) -> 99049.2 | JJ38: 4133
A39: 58052894 | S39: 2702311.6 | Z39: 288000 | AB39: =101150.82+185443.17 -> 286593.99 | AK39: 4115950.9 | AL39: 4121757.1 | AM39: 695346.42 | JI39: =SUM(A39:JH39) -> 70262854 | JJ39: 4135
FY40: 80124.36 | JI40: =SUM(A40:JH40) -> 80124.36 | JJ40: 4139
...

Sheet CUENTA T VS
A1: D E S G L O S E D E L A S C U E N T A S
A2: 211101 | B2: 211102 | C2: 211103 | D2: 211104 | E2: 211105 | F2: 211106 | G2: 211203 | H2: 211205 | I2: 211206 | J2: 211208 | K2: 211209 | L2: 211211 | M2: 211301 | N2: 211401 | O2: 211501 | P2: 211502 | Q2: 211503 | R2: 211504 | S2: 212101 | T2: 212201 | U2: 212203 | V2: 212204 | W2: 212205 | X2: 212206 | Y2: 212207 | Z2: 212208 | AA2: 212209 | AB2: 212210 | AC2: 213101 | AD2: 213102 | AE2: 213201 | AF2: 213202 | AG2: 214101 | AH2: 214201 | AI2: 214202 | AJ2: 214203 | AK2: 215101 | AL2: 215201 | AM2: 215301 | AN2: 215401 | AO2: 221101 | AP2: 221201 | AQ2: 221301 | AR2: 221401 | AS2: 221501 | AT2: 221601 | AU2: 221602 | AV2: 221701 | AW2: 221801 | AX2: 222101 | AY2: 222201 | AZ2: 223101 | BA2: 223201 | BB2: 224101 | BC2: 224201 | BD2: 224301 | BE2: 224401 | BF2: 225101 | BG2: 225201 | BH2: 225301 | BI2: 225302 | BJ2: 225303 | BK2: 225304 | BL2: 225305 | BM2: 225401 | BN2: 225501 | BO2: 225601 | BP2: 225701 | BQ2: 225801 | BR2: 225901 | BS2: 226101 | BT2: 226201 | BU2: 226301 | BV2: 226401 | BW2: 227101 | BX2: 227102 | BY2: 227103 | BZ2: 227104 | CA2: 227105 | CB2: 227106 | CC2: 227107 | CD2: 227199 | CE2: 227201 | CF2: 227202 | CG2: 227203 | CH2: 227204 | CI2: 227205 | CJ2: 227206 | CK2: 227207 | CL2: 227208 | CM2: 227299 | CN2: 227301 | CO2: 228101 | CP2: 228201 | CQ2: 228301 | CR2: 228401 | CS2: 228501 | CT2: 228502 | CU2: 228503 | CV2: 228601 | CW2: 228602 | CX2: 228603 | CY2: 228604 | CZ2: 228701 | DA2: 228702 | DB2: 228703 | DC2: 228704 | DD2: 228705 | DE2: 228706 | DF2: 228801 | DG2: 228802 | DH2: 228803 | DI2: 229201 | DJ2: 229203 | DK2: 231101 | DL2: 231102 | DM2: 231201 | DN2: 231301 | DO2: 231302 | DP2: 231303 | DQ2: 231401 | DR2: 232101 | DS2: 232201 | DT2: 232301 | DU2: 233101 | DV2: 233201 | DW2: 233301 | DX2: 233401 | DY2: 233501 | DZ2: 233601 | EA2: 234101 | EB2: 234201 | EC2: 235101 | ED2: 235201 | EE2: 235301 | EF2: 235401 | EG2: 235501 | EH2: 236101 | EI2: 236102 | EJ2: 236103 | EK2: 236104 | EL2: 236105 | EM2: 236201 | EN2: 236202 | EO2: 236203 | EP2: 236304 | EQ2: 236305 | ER2: 236306 | ES2: 236401 | ET2: 236402 | EU2: 236403 | EV2: 236404 | EW2: 236405 | EX2: 236406 | EY2: 236407 | EZ2: 236901 | FA2: 237101 | FB2: 237102 | FC2: 237103 | FD2: 237104 | FE2: 237105 | FF2: 237106 | FG2: 237107 | FH2: 237201 | FI2: 237202 | FJ2: 237203 | FK2: 237204 | FL2: 237205 | FM2: 237206 | FN2: 237299 | FO2: 238101 | FP2: 238201 | FQ2: 239101 | FR2: 239102 | FS2: 239201 | FT2: 239301 | FU2: 239401 | FV2: 239501 | FW2: 239601 | FX2: 239701 | FY2: 239801 | FZ2: 239802 | GA2: 239901 | GB2: 239904 | GC2: 241201 | GD2: 241202 | GE2: 241203 | GF2: 241204 | GG2: 241205 | GH2: 261101 | GI2: 261201 | GJ2: 261301 | GK2: 261401 | GL2: 261901 | GM2: 262101 | GN2: 262201 | GO2: 262301 | GP2: 262401 | GQ2: 263101 | GR2: 263201 | GS2: 263301 | GT2: 263401 | GU2: 264101 | GV2: 264201 | GW2: 264301 | GX2: 264401 | GY2: 264501 | GZ2: 264601 | HA2: 264701 | HB2: 264801 | HC2: 265101 | HD2: 265201 | HE2: 265301 | HF2: 265401 | HG2: 265501 | HH2: 265601 | HI2: 265701 | HJ2: 265801 | HK2: 266101 | HL2: 266201 | HM2: 267101 | HN2: 267201 | HO2: 267301 | HP2: 267401 | HQ2: 267501 | HR2: 267601 | HS2: 267701 | HT2: 267801 | HU2: 267901 | HV2: 268101 | HW2: 268201 | HX2: 268301 | HY2: 268302 | HZ2: 268401 | IA2: 268501 | IB2: 268601 | IC2: 268701 | ID2: 268802 | IE2: 268803 | IF2: 268804 | IG2: 268901 | IH2: 269101 | II2: 269102 | IJ2: 269201 | IK2: 269202 | IL2: 269301 | IM2: 269401 | IN2: 269501 | IO2: 269502 | IP2: 269503 | IQ2: 2269901 | IR2: 271101 | IS2: 271201 | IT2: 271301 | IU2: 271401 | IV2: 272101 | IW2: 272201 | IX2: 272301 | IY2: 272401 | IZ2: 272501 | JA2: 272601 | JB2: 272701 | JC2: 272801 | JD2: 272901 | JE2: 273101 | JF2: 273201 | JG2: 274101 | JH2: 274201 | JI2: Totales | JJ2: TRANSF NO. | JK2: VALOR | JL2: RETENCION | JM2: AÑOS ANTERIORES | JN2: 2022 | JO2: Total | JP2: Proveedor Informal
GL4: 177799.99 | JI4: =SUM(A4:JH4) -> 177799.99 | JJ4: 290 | JK4: 177799.99 | JL4: =+JI4-JK4 -> 0
FN5: 155677.4 | JI5: =SUM(A5:JH5) -> 155677.4 | JJ5: 291 | JK5: 155677.4 | JL5: =+JI5-JK5 -> 0
DK6: 90600 | JI6: =SUM(A6:JH6) -> 90600 | JJ6: 292 | JK6: 90600 | JL6: =+JI6-JK6 -> 0
FJ7: 4800 | JI7: =SUM(A7:JH7) -> 4800 | JJ7: 293 | JK7: 4800 | JL7: =+JI7-JK7 -> 0
DK8: 14000 | JI8: =SUM(A8:JH8) -> 14000 | JJ8: 294 | JK8: 14000 | JL8: =+JI8-JK8 -> 0
DK9: 30060 | JI9: =SUM(A9:JH9) -> 30060 | JJ9: 295 | JK9: 30060 | JL9: =+JI9-JK9 -> 0
DK10: 7000 | JI10: =SUM(A10:JH10) -> 7000 | JJ10: 296 | JK10: 7000 | JL10: =+JI10-JK10 -> 0
CH11: 132966.46 | JI11: =SUM(A11:JH11) -> 132966.46 | JJ11: 297 | JK11: 132966.46 | JL11: =+JI11-JK11 -> 0
BC12: 16000 | JI12: =SUM(A12:JH12) -> 16000 | JJ12: 298 | JK12: 16000 | JL12: =+JI12-JK12 -> 0
AW13: 25000 | JI13: =SUM(A13:JH13) -> 25000 | JJ13: 299 | JK13: 25000 | JL13: =+JI13-JK13 -> 0
AQ14: 111421.68 | JI14: =SUM(A14:JH14) -> 111421.68 | JJ14: 300 | JK14: 111421.68 | JL14: =+JI14-JK14 -> 0
DE15: 25000 | JI15: =SUM(A15:JH15) -> 25000 | JJ15: 301 | JK15: 25000 | JL15: =+JI15-JK15 -> 0
GJ16: 1819265 | JI16: =SUM(A16:JH16) -> 1819265 | JJ16: 302 | JK16: 1819265 | JL16: =+JI16-JK16 -> 0
DK17: 633345.26 | DV17: 17600.03 | FV17: 2900 | JI17: =SUM(A17:JH17) -> 653845.29 | JJ17: 303 | JK17: 653845.29 | JL17: =+JI17-JK17 -> 0
DK18: 237670 | JI18: =SUM(A18:JH18) -> 237670 | JJ18: 304 | JK18: 237670 | JL18: =+JI18-JK18 -> 0
DI19: 90048.75 | JI19: =SUM(A19:JH19) -> 90048.75 | JJ19: 305 | JK19: 90048.75 | JL19: =+JI19-JK19 -> 0
FA20: 172000 | JI20: =SUM(A20:JH20) -> 172000 | JJ20: 306 | JK20: 172000 | JL20: =+JI20-JK20 -> 0
FT21: 27704.04 | JI21: =SUM(A21:JH21) -> 27704.04 | JJ21: 307 | JK21: 27704.04 | JL21: =+JI21-JK21 -> 0
FD22: 22638 | JI22: =SUM(A22:JH22) -> 22638 | JJ22: 308 | JK22: 22638 | JL22: =+JI22-JK22 -> 0
EA23: 74000 | JI23: =SUM(A23:JH23) -> 74000 | JJ23: 309 | JK23: 74000 | JL23: =+JI23-JK23 -> 0
AW24: 25000 | JI24: =SUM(A24:JH24) -> 25000 | JJ24: 310 | JK24: 25000 | JL24: =+JI24-JK24 -> 0
DE25: 76045 | JI25: =SUM(A25:JH25) -> 76045 | JJ25: 311 | JK25: 76045 | JL25: =+JI25-JK25 -> 0
DE26: 44300 | JI26: =SUM(A26:JH26) -> 44300 | JJ26: 312 | JK26: 44300 | JL26: =+JI26-JK26 -> 0
CL27: 180568 | JI27: =SUM(A27:JH27) -> 180568 | JJ27: 313 | JK27: 180568 | JL27: =+JI27-JK27 -> 0
AY28: 136880 | JI28: =SUM(A28:JH28) -> 136880 | JJ28: 314 | JK28: 136880 | JL28: =+JI28-JK28 -> 0
CL29: 396975.6 | JI29: =SUM(A29:JH29) -> 396975.6 | JJ29: 315 | JK29: 396975.6 | JL29: =+JI29-JK29 -> 0
GH30: 162142.87 | GK30: 26658.16 | GL30: 59500 | JI30: =SUM(A30:JH30) -> 248301.03 | JJ30: 316 | JK30: 248301.03 | JL30: =+JI30-JK30 -> 0
AY31: 132840.57 | JI31: =SUM(A31:JH31) -> 132840.57 | JJ31: 317 | JK31: 132840.57 | JL31: =+JI31-JK31 -> 0
FN32: 365139.2 | JI32: =SUM(A32:JH32) -> 365139.2 | JJ32: 318 | JK32: 365139.2 | JL32: =+JI32-JK32 -> 0
FN33: 308841.4 | JI33: =SUM(A33:JH33) -> 308841.4 | JJ33: 319 | JK33: 308841.4 | JL33: =+JI33-JK33 -> 0
BC34: 32000 | JI34: =SUM(A34:JH34) -> 32000 | JJ34: 320 | JK34: 32000 | JL34: =+JI34-JK34 -> 0
FV35: 858540 | JI35: =SUM(A35:JH35) -> 858540 | JJ35: 321 | JK35: 858540 | JL35: =+JI35-JK35 -> 0
DK36: 34270.4 | JI36: =SUM(A36:JH36) -> 34270.4 | JJ36: 322 | JK36: 34270.4 | JL36: =+JI36-JK36 -> 0
CJ37: 33714.29 | JI37: =SUM(A37:JH37) -> 33714.29 | JJ37: 37290 | JL37: =+JI37-JK37 -> 33714.29
GA38: 55617.91 | JI38: =SUM(A38:JH38) -> 55617.91 | JJ38: =+JJ37+1 -> 37291 | JL38: =+JI38-JK38 -> 55617.91
GC39: 3600 | JI39: =SUM(A39:JH39) -> 3600 | JJ39: =+JJ38+1 -> 37292 | JL39: =+JI39-JK39 -> 3600
JI40: =SUM(A40:JH40) -> 0 | JJ40: =+JJ39+1 -> 37293 | JL40: =+JI40-JK40 -> 0
JI41: =SUM(A41:JH41) -> 0 | JJ41: =+JJ40+1 -> 37294 | JL41: =+JI41-JK41 -> 0
...

Sheet GASTOS X ATENCION
A1: SERVICIO NACIONAL DE SALUD
A2: ='CONS. FUENTES FINAN'!A6 -> HOSPITAL MATERNO INFANTIL SAN LORENZO DE LOS MINA
A3: RESUMEN COMPARATIVO DE GASTOS ESPECIFICOS FONDO 100 Y VENTA DE SERVICIOS
A6: DETALLE | B6: FONDO 100 | C6: VENTA SERVICIOS | D6: TOTAL | E6: %
A8: Atención Directa
A9: Medicamentos e Insumos Médicos | B9: ='CONS. FUENTES FINAN'!G245+'CONS. FUENTES FINAN'!G315 -> 15355854 | C9: ='CONS. FUENTES FINAN'!H245+'CONS. FUENTES FINAN'!H315 -> 101704.04 | D9: =SUM(B9:C9) -> 15457558 | E9: =+D9/D12 -> 0.73755365
A10: Oxigeno | B10: ='CONS. FUENTES FINAN'!G302 -> 0 | C10: ='CONS. FUENTES FINAN'!H302 -> 829658 | D10: =SUM(B10:C10) -> 829658 | E10: =+D10/D12 -> 0.03958693
A11: Reactivos e Insumos de Laboratorio | B11: ='CONS. FUENTES FINAN'!G296+'CONS. FUENTES FINAN'!G297+'CONS. FUENTES FINAN'!G298 -> 4665860.2 | C11: ='CONS. FUENTES FINAN'!H296+'CONS. FUENTES FINAN'!H297+'CONS. FUENTES FINAN'!H298 -> 4800 | D11: =SUM(B11:C11) -> 4670660.2 | E11: =+D11/D12 -> 0.22285942
A12: Total | B12: =SUM(B9:B11) -> 20021714 | C12: =SUM(C9:C11) -> 936162.04 | D12: =SUM(D9:D11) -> 20957877 | E12: =+D12/D39 -> 0.17215004
A13: Mantenimiento de Equipos
A14: Reparación y Mantenimiento Maquinaria y Eq. | B14: ='CONS. FUENTES FINAN'!G157+'CONS. FUENTES FINAN'!G188+'CONS. FUENTES FINAN'!G223+'CONS. FUENTES FINAN'!G252+'CONS. FUENTES FINAN'!G254+'CONS. FUENTES FINAN'!G256+'CONS. FUENTES FINAN'!G258+'CONS. FUENTES FINAN'!G261+'CONS. FUENTES FINAN'!G292+'CONS. FUENTES FINAN'!G293+'CONS. FUENTES FINAN'!G299+'CONS. FUENTES FINAN'!G300+'CONS. FUENTES FINAN'!G301+'CONS. FUENTES FINAN'!G324 -> 1687453.9 | C14: ='CONS. FUENTES FINAN'!H157+'CONS. FUENTES FINAN'!H188+'CONS. FUENTES FINAN'!H223+'CONS. FUENTES FINAN'!H252+'CONS. FUENTES FINAN'!H254+'CONS. FUENTES FINAN'!H256+'CONS. FUENTES FINAN'!H258+'CONS. FUENTES FINAN'!H261+'CONS. FUENTES FINAN'!H292+'CONS. FUENTES FINAN'!H293+'CONS. FUENTES FINAN'!H299+'CONS. FUENTES FINAN'!H300+'CONS. FUENTES FINAN'!H301+'CONS. FUENTES FINAN'!H324 -> 802020.26 | D14: =SUM(B14:C14) -> 2489474.1 | E14: =+D14/D16 -> 1
A15: Productos Eléctricos y Afines | B15: ='CONS. FUENTES FINAN'!G320 -> 0 | C15: ='CONS. FUENTES FINAN'!H320 -> 0 | D15: =SUM(B15:C15) -> 0 | E15: =+D15/D16 -> 0
A16: Total | B16: =SUM(B14:B15) -> 1687453.9 | C16: =SUM(C14:C15) -> 802020.26 | D16: =SUM(D14:D15) -> 2489474.1 | E16: =+D16/D39 -> 0.020448783
A17: Gastos Administrativos
A18: Servicios Personales | B18: ='CONS. FUENTES FINAN'!G26 -> 71591504 | C18: ='CONS. FUENTES FINAN'!H26 -> 4413127.6 | D18: =SUM(B18:C18) -> 76004631 | E18: =+D18/D34 -> 0.84234699
A19: Servicio Telefónico | B19: ='CONS. FUENTES FINAN'!G91+'CONS. FUENTES FINAN'!G93+'CONS. FUENTES FINAN'!G95+'CONS. FUENTES FINAN'!G97 -> 0 | C19: ='CONS. FUENTES FINAN'!H91+'CONS. FUENTES FINAN'!H93+'CONS. FUENTES FINAN'!H95+'CONS. FUENTES FINAN'!H97 -> 111421.68 | D19: =SUM(B19:C19) -> 111421.68 | E19: =+D19/D34 -> 0.0012348684
A20: Servicios Basicos (electricidad, agua y residuos solidos) | B20: ='CONS. FUENTES FINAN'!G99+'CONS. FUENTES FINAN'!G102+'CONS. FUENTES FINAN'!G104 -> 60535 | C20: ='CONS. FUENTES FINAN'!H99+'CONS. FUENTES FINAN'!H102+'CONS. FUENTES FINAN'!H104 -> 50000 | D20: =SUM(B20:C20) -> 110535 | E20: =+D20/D34 -> 0.0012250415
A21: Viáticos | B21: ='CONS. FUENTES FINAN'!G111 -> 0 | C21: ='CONS. FUENTES FINAN'!H111 -> 0 | D21: =SUM(B21:C21) -> 0 | E21: =+D21/D34 -> 0
A22: Transporte y almacenaje | B22: ='CONS. FUENTES FINAN'!G116 -> 0 | C22: ='CONS. FUENTES FINAN'!H116 -> 68000 | D22: =SUM(B22:C22) -> 68000 | E22: =+D22/D34 -> 0.00075363296
A23: Alquileres | B23: ='CONS. FUENTES FINAN'!G125 -> 0 | C23: ='CONS. FUENTES FINAN'!H125 -> 0 | D23: =SUM(B23:C23) -> 0 | E23: =+D23/D34 -> 0
A24: Comisiones y Gastos Bancarios | B24: ='CONS. FUENTES FINAN'!G182 -> 0 | C24: ='CONS. FUENTES FINAN'!H182 -> 21179.93 | D24: =SUM(B24:C24) -> 21179.93 | E24: =+D24/D34 -> 0.00023473372
A25: Materiales de Oficina, Impresión y Encuadernación | B25: ='CONS. FUENTES FINAN'!G109+'CONS. FUENTES FINAN'!G312 -> 318704.8 | C25: ='CONS. FUENTES FINAN'!H109+'CONS. FUENTES FINAN'!H312 -> 269720.57 | D25: =SUM(B25:C25) -> 588425.37 | E25: =+D25/D34 -> 0.0065214228
A26: Alimentos y Bebidas para Personas | B26: ='CONS. FUENTES FINAN'!G208+'CONS. FUENTES FINAN'!G214+'CONS. FUENTES FINAN'!G217+'CONS. FUENTES FINAN'!G219 -> 4494873.6 | C26: ='CONS. FUENTES FINAN'!H208+'CONS. FUENTES FINAN'!H214+'CONS. FUENTES FINAN'!H217+'CONS. FUENTES FINAN'!H219 -> 1136994.4 | D26: =SUM(B26:C26) -> 5631868 | E26: =+D26/D34 -> 0.062417078
A27: Productos de papel, carton e impesos | B27: ='CONS. FUENTES FINAN'!G232 -> 366980 | C27: ='CONS. FUENTES FINAN'!H232 -> 17600.03 | D27: =SUM(B27:C27) -> 384580.03 | E27: =+D27/D34 -> 0.004262238
A28: Articulos de Plasticos | B28: ='CONS. FUENTES FINAN'!G259 -> 0 | C28: ='CONS. FUENTES FINAN'!H259 -> 0 | D28: =SUM(B28:C28) -> 0 | E28: =+D28/D34 -> 0
A29: Gasolina | B29: ='CONS. FUENTES FINAN'!G288 -> 0 | C29: ='CONS. FUENTES FINAN'!H288 -> 172000 | D29: =SUM(B29:C29) -> 172000 | E29: =+D29/D34 -> 0.0019062481
A30: Gasoil | B30: ='CONS. FUENTES FINAN'!G289+'CONS. FUENTES FINAN'!G290 -> 337200 | C30: ='CONS. FUENTES FINAN'!H289+'CONS. FUENTES FINAN'!H290 -> 0 | D30: =SUM(B30:C30) -> 337200 | E30: =+D30/D34 -> 0.0037371328
A31: GLP | B31: ='CONS. FUENTES FINAN'!G291+'CONS. FUENTES FINAN'!G294 -> 0 | C31: ='CONS. FUENTES FINAN'!H291+'CONS. FUENTES FINAN'!H294 -> 22638 | D31: =SUM(B31:C31) -> 22638 | E31: =+D31/D34 -> 0.00025089328
A32: Materiales de Limpieza e Higiene | B32: ='CONS. FUENTES FINAN'!G309 -> 599529.09 | C32: ='CONS. FUENTES FINAN'!H309 -> 0 | D32: =SUM(B32:C32) -> 599529.09 | E32: =+D32/D34 -> 0.0066444836
A33: Otros Egresos y Gastos | B33: ='CONS. FUENTES FINAN'!G89+'CONS. FUENTES FINAN'!G107+'CONS. FUENTES FINAN'!G148+'CONS. FUENTES FINAN'!G180+'CONS. FUENTES FINAN'!G184+'CONS. FUENTES FINAN'!G186+'CONS. FUENTES FINAN'!G192+'CONS. FUENTES FINAN'!G197+'CONS. FUENTES FINAN'!G204+'CONS. FUENTES FINAN'!G225+'CONS. FUENTES FINAN'!G303+'CONS. FUENTES FINAN'!G316+'CONS. FUENTES FINAN'!G318+'CONS. FUENTES FINAN'!G322+'CONS. FUENTES FINAN'!G327+'CONS. FUENTES FINAN'!G330 -> 5037116.1 | C33: ='CONS. FUENTES FINAN'!H89+'CONS. FUENTES FINAN'!H107+'CONS. FUENTES FINAN'!H148+'CONS. FUENTES FINAN'!H180+'CONS. FUENTES FINAN'!H184+'CONS. FUENTES FINAN'!H186+'CONS. FUENTES FINAN'!H192+'CONS. FUENTES FINAN'!H197+'CONS. FUENTES FINAN'!H204+'CONS. FUENTES FINAN'!H225+'CONS. FUENTES FINAN'!H303+'CONS. FUENTES FINAN'!H316+'CONS. FUENTES FINAN'!H318+'CONS. FUENTES FINAN'!H322+'CONS. FUENTES FINAN'!H327+'CONS. FUENTES FINAN'!H330 -> 1140474.9 | D33: =SUM(B33:C33) -> 6177591 | E33: =+D33/D34 -> 0.068465238
A34: Total | B34: =SUM(B17:B33) -> 82806442 | C34: =SUM(C17:C33) -> 7423157.1 | D34: =SUM(D17:D33) -> 90229600 | E34: =+D34/D39 -> 0.74115473
A35: Gastos Inversion y Capital
A36: Bienes Muebles, Inmuebles e Intangibles | B36: ='CONS. FUENTES FINAN'!G336 -> 5819603.3 | C36: ='CONS. FUENTES FINAN'!H336 -> 2245366 | D36: =SUM(B36:C36) -> 8064969.4 | E36: =+D36/D38 -> 1
A37: Obras | B37: ='CONS. FUENTES FINAN'!G463 -> 0 | C37: ='CONS. FUENTES FINAN'!H463 -> 0 | D37: =SUM(B37:C37) -> 0 | E37: =+D37/D38 -> 0
A38: Total | B38: =SUM(B36:B37) -> 5819603.3 | C38: =SUM(C36:C37) -> 2245366 | D38: =SUM(D36:D37) -> 8064969.4 | E38: =+D38/D39 -> 0.066246445
A39: Total General | B39: =+B12+B16+B34+B38 -> 1.1033521e+08 | C39: =+C12+C16+C34+C38 -> 11406705 | D39: =+D12+D16+D34+D38 -> 1.2174192e+08 | E39: =+E12+E16+E34+E38 -> 1
A40: Porciento | B40: =+B39/D39 -> 0.90630421 | C40: =+C39/D39 -> 0.093695791 | D40: =+B40+C40 -> 1

Sheet PLANTILLA PRESUPUESTO
A1: SERVICIO NACIONAL DE SALUD
A2: NOMBRE DEL ESTABLECIMIENTO
A3: CONSOLIDADO GASTOS EJECUCION FINANCIERA 2025
A4: En RD$
A6: Detalle | B6: FONDO REPONIBLE | G6: VENTA SEVICIOS/OTROS APORTES | L6: TOTAL
A7: 2 - GASTOS | B7: 1ro | C7: 2do | D7: 3ro | E7: 4to | G7: 1ro | H7: 2do | I7: 3ro | J7: 4to | L7: 1ro | M7: 2do | N7: 3ro | O7: 4to
A8: 2.1 - REMUNERACIONES Y CONTRIBUCIONES | B8: =SUM(B9:B13) -> 1.9856074e+08 | C8: =SUM(C9:C13) -> 1.9977032e+08 | D8: =SUM(D9:D13) -> 2.1475844e+08 | E8: =SUM(E9:E13) -> 0 | G8: =SUM(G9:G13) -> 5231553.6 | H8: =SUM(H9:H13) -> 0 | I8: =SUM(I9:I13) -> 4413127.6 | J8: =SUM(J9:J13) -> 0 | L8: =SUM(B8+G8) -> 2.0379229e+08 | M8: =SUM(C8+H8) -> 1.9977032e+08 | N8: =SUM(D8+I8) -> 2.1917157e+08 | O8: =SUM(E8+J8) -> 0
A9: 2.1.1 - REMUNERACIONES | B9: =SUM('TRANSFERENCIA CORRIENTE'!C10:E10) -> 1.639452e+08 | C9: =SUM('TRANSFERENCIA CORRIENTE'!F10:H10) -> 1.6408478e+08 | D9: =SUM('TRANSFERENCIA CORRIENTE'!I10:K10) -> 1.775012e+08 | E9: =SUM('TRANSFERENCIA CORRIENTE'!L10:N10) -> 0 | G9: =SUM(VS!C10:E10) -> 0 | H9: =SUM(VS!F10:H10) -> 0 | I9: =SUM(VS!I10:K10) -> 0 | J9: =SUM(VS!L10:N10) -> 0 | L9: =SUM(B9+G9) -> 1.639452e+08 | M9: =SUM(C9+H9) -> 1.6408478e+08 | N9: =SUM(D9+I9) -> 1.775012e+08 | O9: =SUM(E9+J9) -> 0
A10: 2.1.2 - SOBRESUELDOS | B10: =SUM('TRANSFERENCIA CORRIENTE'!C11:E11) -> 9594398.8 | C10: =SUM('TRANSFERENCIA CORRIENTE'!F11:H11) -> 10535799 | D10: =SUM('TRANSFERENCIA CORRIENTE'!I11:K11) -> 10034891 | E10: =SUM('TRANSFERENCIA CORRIENTE'!L11:N11) -> 0 | G10: =SUM(VS!C11:E11) -> 5231553.6 | H10: =SUM(VS!F11:H11) -> 0 | I10: =SUM(VS!I11:K11) -> 4413127.6 | J10: =SUM(VS!L11:N11) -> 0 | L10: =SUM(B10+G10) -> 14825952 | M10: =SUM(C10+H10) -> 10535799 | N10: =SUM(D10+I10) -> 14448019 | O10: =SUM(E10+J10) -> 0
A11: 2.1.3 - DIETAS Y GASTOS DE REPRESENTACIÓN | B11: =SUM('TRANSFERENCIA CORRIENTE'!C12:E12) -> 0 | C11: =SUM('TRANSFERENCIA CORRIENTE'!F12:H12) -> 0 | D11: =SUM('TRANSFERENCIA CORRIENTE'!I12:K12) -> 0 | E11: =SUM('TRANSFERENCIA CORRIENTE'!L12:N12) -> 0 | G11: =SUM(VS!C12:E12) -> 0 | H11: =SUM(VS!F12:H12) -> 0 | I11: =SUM(VS!I12:K12) -> 0 | J11: =SUM(VS!L12:N12) -> 0 | L11: =SUM(B11+G11) -> 0 | M11: =SUM(C11+H11) -> 0 | N11: =SUM(D11+I11) -> 0 | O11: =SUM(E11+J11) -> 0
A12: 2.1.4 - GRATIFICACIONES Y BONIFICACIONES | B12: =SUM('TRANSFERENCIA CORRIENTE'!C13:E13) -> 0 | C12: =SUM('TRANSFERENCIA CORRIENTE'!F13:H13) -> 0 | D12: =SUM('TRANSFERENCIA CORRIENTE'!I13:K13) -> 0 | E12: =SUM('TRANSFERENCIA CORRIENTE'!L13:N13) -> 0 | G12: =SUM(VS!C13:E13) -> 0 | H12: =SUM(VS!F13:H13) -> 0 | I12: =SUM(VS!I13:K13) -> 0 | J12: =SUM(VS!L13:N13) -> 0 | L12: =SUM(B12+G12) -> 0 | M12: =SUM(C12+H12) -> 0 | N12: =SUM(D12+I12) -> 0 | O12: =SUM(E12+J12) -> 0
A13: 2.1.5 - CONTRIBUCIONES A LA SEGURIDAD SOCIAL | B13: =SUM('TRANSFERENCIA CORRIENTE'!C14:E14) -> 25021132 | C13: =SUM('TRANSFERENCIA CORRIENTE'!F14:H14) -> 25149742 | D13: =SUM('TRANSFERENCIA CORRIENTE'!I14:K14) -> 27222347 | E13: =SUM('TRANSFERENCIA CORRIENTE'!L14:N14) -> 0 | G13: =SUM(VS!C14:E14) -> 0 | H13: =SUM(VS!F14:H14) -> 0 | I13: =SUM(VS!I14:K14) -> 0 | J13: =SUM(VS!L14:N14) -> 0 | L13: =SUM(B13+G13) -> 25021132 | M13: =SUM(C13+H13) -> 25149742 | N13: =SUM(D13+I13) -> 27222347 | O13: =SUM(E13+J13) -> 0
A14: 2.2 - CONTRATACIÓN DE SERVICIOS | B14: =SUM(B15:B23) -> 9308364.9 | C14: =SUM(C15:C23) -> 10131818 | D14: =SUM(D15:D23) -> 10910792 | E14: =SUM(E15:E23) -> 0 | G14: =SUM(G15:G23) -> 8306683.8 | H14: =SUM(H15:H23) -> 7239413.8 | I14: =SUM(I15:I23) -> 10378416 | J14: =SUM(J15:J23) -> 0 | L14: =SUM(B14+G14) -> 17615049 | M14: =SUM(C14+H14) -> 17371232 | N14: =SUM(D14+I14) -> 21289207 | O14: =SUM(E14+J14) -> 0
A15: 2.2.1 - SERVICIOS BÁSICOS | B15: =SUM('TRANSFERENCIA CORRIENTE'!C16:E16) -> 2020024.3 | C15: =SUM('TRANSFERENCIA CORRIENTE'!F16:H16) -> 181605 | D15: =SUM('TRANSFERENCIA CORRIENTE'!J16:L16) -> 121070 | E15: =SUM('TRANSFERENCIA CORRIENTE'!L16:N16) -> 0 | G15: =SUM(VS!C16:E16) -> 2341561.9 | H15: =SUM(VS!F16:H16) -> 2348580.7 | I15: =SUM(VS!I16:K16) -> 2876937.6 | J15: =SUM(VS!L16:N16) -> 0 | L15: =SUM(B15+G15) -> 4361586.2 | M15: =SUM(C15+H15) -> 2530185.7 | N15: =SUM(D15+I15) -> 2998007.6 | O15: =SUM(E15+J15) -> 0
A16: 2.2.2 - PUBLICIDAD, IMPRESIÓN Y ENCUADERNACIÓN | B16: =SUM('TRANSFERENCIA CORRIENTE'!C17:E17) -> 324206.83 | C16: =SUM('TRANSFERENCIA CORRIENTE'!F17:H17) -> 351993.83 | D16: =SUM('TRANSFERENCIA CORRIENTE'!J17:L17) -> 136428.3 | E16: =SUM('TRANSFERENCIA CORRIENTE'!L17:N17) -> 0 | G16: =SUM(VS!C17:E17) -> 0 | H16: =SUM(VS!F17:H17) -> 310139.4 | I16: =SUM(VS!I17:K17) -> 1187725.2 | J16: =SUM(VS!L17:N17) -> 0 | L16: =SUM(B16+G16) -> 324206.83 | M16: =SUM(C16+H16) -> 662133.23 | N16: =SUM(D16+I16) -> 1324153.5 | O16: =SUM(E16+J16) -> 0
A17: 2.2.3 - VIÁTICOS | B17: =SUM('TRANSFERENCIA CORRIENTE'!C18:E18) -> 0 | C17: =SUM('TRANSFERENCIA CORRIENTE'!F18:H18) -> 0 | D17: =SUM('TRANSFERENCIA CORRIENTE'!J18:L18) -> 0 | E17: =SUM('TRANSFERENCIA CORRIENTE'!L18:N18) -> 0 | G17: =SUM(VS!C18:E18) -> 0 | H17: =SUM(VS!F18:H18) -> 0 | I17: =SUM(VS!I18:K18) -> 0 | J17: =SUM(VS!L18:N18) -> 0 | L17: =SUM(B17+G17) -> 0 | M17: =SUM(C17+H17) -> 0 | N17: =SUM(D17+I17) -> 0 | O17: =SUM(E17+J17) -> 0
A18: 2.2.4 - TRANSPORTE Y ALMACENAJE | B18: =SUM('TRANSFERENCIA CORRIENTE'!C19:E19) -> 0 | C18: =SUM('TRANSFERENCIA CORRIENTE'!F19:H19) -> 0 | D18: =SUM('TRANSFERENCIA CORRIENTE'!J19:L19) -> 0 | E18: =SUM('TRANSFERENCIA CORRIENTE'!L19:N19) -> 0 | G18: =SUM(VS!C19:E19) -> 56000 | H18: =SUM(VS!F19:H19) -> 96000 | I18: =SUM(VS!I19:K19) -> 76000 | J18: =SUM(VS!L19:N19) -> 0 | L18: =SUM(B18+G18) -> 56000 | M18: =SUM(C18+H18) -> 96000 | N18: =SUM(D18+I18) -> 76000 | O18: =SUM(E18+J18) -> 0
A19: 2.2.5 - ALQUILERES Y RENTAS | B19: =SUM('TRANSFERENCIA CORRIENTE'!C20:E20) -> 0 | C19: =SUM('TRANSFERENCIA CORRIENTE'!F20:H20) -> 150000 | D19: =SUM('TRANSFERENCIA CORRIENTE'!J20:L20) -> 150000 | E19: =SUM('TRANSFERENCIA CORRIENTE'!L20:N20) -> 0 | G19: =SUM(VS!C20:E20) -> 519625.15 | H19: =SUM(VS!F20:H20) -> 759170.42 | I19: =SUM(VS!I20:K20) -> 927025.64 | J19: =SUM(VS!L20:N20) -> 0 | L19: =SUM(B19+G19) -> 519625.15 | M19: =SUM(C19+H19) -> 909170.42 | N19: =SUM(D19+I19) -> 1077025.6 | O19: =SUM(E19+J19) -> 0
A20: 2.2.6 - SEGUROS | B20: =SUM('TRANSFERENCIA CORRIENTE'!C21:E21) -> 0 | C20: =SUM('TRANSFERENCIA CORRIENTE'!F21:H21) -> 0 | D20: =SUM('TRANSFERENCIA CORRIENTE'!J21:L21) -> 0 | E20: =SUM('TRANSFERENCIA CORRIENTE'!L21:N21) -> 0 | G20: =SUM(VS!C21:E21) -> 0 | H20: =SUM(VS!F21:H21) -> 0 | I20: =SUM(VS!I21:K21) -> 0 | J20: =SUM(VS!L21:N21) -> 0 | L20: =SUM(B20+G20) -> 0 | M20: =SUM(C20+H20) -> 0 | N20: =SUM(D20+I20) -> 0 | O20: =SUM(E20+J20) -> 0
A21: 2.2.7 - SERVICIOS DE CONSERVACIÓN, REPARACIONES MENORES E INSTALACIONES TEMPORALES | B21: =SUM('TRANSFERENCIA CORRIENTE'!C22:E22) -> 6474433.8 | C21: =SUM('TRANSFERENCIA CORRIENTE'!F22:H22) -> 5611474.3 | D21: =SUM('TRANSFERENCIA CORRIENTE'!J22:L22) -> 4409782.3 | E21: =SUM('TRANSFERENCIA CORRIENTE'!L22:N22) -> 0 | G21: =SUM(VS!C22:E22) -> 4556850.1 | H21: =SUM(VS!F22:H22) -> 1040817.6 | I21: =SUM(VS!I22:K22) -> 3360268.8 | J21: =SUM(VS!L22:N22) -> 0 | L21: =SUM(B21+G21) -> 11031284 | M21: =SUM(C21+H21) -> 6652291.9 | N21: =SUM(D21+I21) -> 7770051.1 | O21: =SUM(E21+J21) -> 0
A22: 2.2.8 - OTROS SERVICIOS NO INCLUIDOS EN CONCEPTOS ANTERIORES | B22: =SUM('TRANSFERENCIA CORRIENTE'!C23:E23) -> 489700 | C22: =SUM('TRANSFERENCIA CORRIENTE'!F23:H23) -> 413000 | D22: =SUM('TRANSFERENCIA CORRIENTE'!J23:L23) -> 3779000 | E22: =SUM('TRANSFERENCIA CORRIENTE'!L23:N23) -> 0 | G22: =SUM(VS!C23:E23) -> 832646.66 | H22: =SUM(VS!F23:H23) -> 1774418.3 | I22: =SUM(VS!I23:K23) -> 1400729.1 | J22: =SUM(VS!L23:N23) -> 0 | L22: =SUM(B22+G22) -> 1322346.7 | M22: =SUM(C22+H22) -> 2187418.3 | N22: =SUM(D22+I22) -> 5179729.1 | O22: =SUM(E22+J22) -> 0
A23: 2.2.9 - OTRAS CONTRATACIONES DE SERVICIOS | B23: =SUM('TRANSFERENCIA CORRIENTE'!C24:E24) -> 0 | C23: =SUM('TRANSFERENCIA CORRIENTE'!F24:H24) -> 3423745 | D23: =SUM('TRANSFERENCIA CORRIENTE'!J24:L24) -> 2314511 | E23: =SUM('TRANSFERENCIA CORRIENTE'!L24:N24) -> 0 | G23: =SUM(VS!C24:E24) -> 0 | H23: =SUM(VS!F24:H24) -> 910287.4 | I23: =SUM(VS!I24:K24) -> 549729.55 | J23: =SUM(VS!L24:N24) -> 0 | L23: =SUM(B23+G23) -> 0 | M23: =SUM(C23+H23) -> 4334032.4 | N23: =SUM(D23+I23) -> 2864240.5 | O23: =SUM(E23+J23) -> 0
A24: 2.3 - MATERIALES Y SUMINISTROS | B24: =SUM(B25:B33) -> 46153283 | C24: =SUM(C25:C33) -> 52385651 | D24: =SUM(D25:D33) -> 1.0378694e+08 | E24: =SUM(E25:E33) -> 0 | G24: =SUM(G25:G33) -> 7292547.3 | H24: =SUM(H25:H33) -> 6552680.6 | I24: =SUM(I25:I33) -> 9091857.1 | J24: =SUM(J25:J33) -> 0 | L24: =SUM(B24+G24) -> 53445831 | M24: =SUM(C24+H24) -> 58938331 | N24: =SUM(D24+I24) -> 1.128788e+08 | O24: =SUM(E24+J24) -> 0
A25: 2.3.1 - ALIMENTOS Y PRODUCTOS AGROFORESTALES | B25: =SUM('TRANSFERENCIA CORRIENTE'!C26:E26) -> 3713897.2 | C25: =SUM('TRANSFERENCIA CORRIENTE'!F26:H26) -> 4866999.2 | D25: =SUM('TRANSFERENCIA CORRIENTE'!I23:K23) -> 3779000 | E25: =SUM('TRANSFERENCIA CORRIENTE'!L26:N26) -> 0 | G25: =SUM(VS!C26:E26) -> 1500755.8 | H25: =SUM(VS!F26:H26) -> 663230 | I25: =SUM(VS!I26:K26) -> 1574425.7 | J25: =SUM(VS!L26:N26) -> 0 | L25: =SUM(B25+G25) -> 5214653 | M25: =SUM(C25+H25) -> 5530229.2 | N25: =SUM(D25+I25) -> 5353425.7 | O25: =SUM(E25+J25) -> 0
A26: 2.3.2 - TEXTILES Y VESTUARIOS | B26: =SUM('TRANSFERENCIA CORRIENTE'!C27:E27) -> 61630.73 | C26: =SUM('TRANSFERENCIA CORRIENTE'!F27:H27) -> 2375399.4 | D26: =SUM('TRANSFERENCIA CORRIENTE'!I24:K24) -> 2314511 | E26: =SUM('TRANSFERENCIA CORRIENTE'!L27:N27) -> 0 | G26: =SUM(VS!C27:E27) -> 0 | H26: =SUM(VS!F27:H27) -> 346306.4 | I26: =SUM(VS!I27:K27) -> 0 | J26: =SUM(VS!L27:N27) -> 0 | L26: =SUM(B26+G26) -> 61630.73 | M26: =SUM(C26+H26) -> 2721705.8 | N26: =SUM(D26+I26) -> 2314511 | O26: =SUM(E26+J26) -> 0
A27: 2.3.3 - PRODUCTOS DE PAPEL, CARTÓN E IMPRESOS | B27: =SUM('TRANSFERENCIA CORRIENTE'!C28:E28) -> 1826911.8 | C27: =SUM('TRANSFERENCIA CORRIENTE'!F28:H28) -> 2991695.7 | D27: =SUM('TRANSFERENCIA CORRIENTE'!I25:K25) -> 65609607 | E27: =SUM('TRANSFERENCIA CORRIENTE'!L28:N28) -> 0 | G27: =SUM(VS!C28:E28) -> 251163 | H27: =SUM(VS!F28:H28) -> 803989 | I27: =SUM(VS!I28:K28) -> 734332.03 | J27: =SUM(VS!L28:N28) -> 0 | L27: =SUM(B27+G27) -> 2078074.8 | M27: =SUM(C27+H27) -> 3795684.7 | N27: =SUM(D27+I27) -> 66343939 | O27: =SUM(E27+J27) -> 0
A28: 2.3.4 - PRODUCTOS FARMACÉUTICOS | B28: =SUM('TRANSFERENCIA CORRIENTE'!C29:E29) -> 10797336 | C28: =SUM('TRANSFERENCIA CORRIENTE'!F29:H29) -> 12009357 | D28: =SUM('TRANSFERENCIA CORRIENTE'!I26:K26) -> 6044845.1 | E28: =SUM('TRANSFERENCIA CORRIENTE'!L29:N29) -> 0 | G28: =SUM(VS!C29:E29) -> 558000 | H28: =SUM(VS!F29:H29) -> 402220.76 | I28: =SUM(VS!I29:K29) -> 496000 | J28: =SUM(VS!L29:N29) -> 0 | L28: =SUM(B28+G28) -> 11355336 | M28: =SUM(C28+H28) -> 12411577 | N28: =SUM(D28+I28) -> 6540845.1 | O28: =SUM(E28+J28) -> 0
A29: 2.3.5 - PRODUCTOS DE CUERO, CAUCHO Y PLÁSTICO | B29: =SUM('TRANSFERENCIA CORRIENTE'!C30:E30) -> 334708.95 | C29: =SUM('TRANSFERENCIA CORRIENTE'!F30:H30) -> 1024240.4 | D29: =SUM('TRANSFERENCIA CORRIENTE'!I27:K27) -> 3015806.8 | E29: =SUM('TRANSFERENCIA CORRIENTE'!L30:N30) -> 0 | G29: =SUM(VS!C30:E30) -> 567494.87 | H29: =SUM(VS!F30:H30) -> 0 | I29: =SUM(VS!I30:K30) -> 140314.78 | J29: =SUM(VS!L30:N30) -> 0 | L29: =SUM(B29+G29) -> 902203.82 | M29: =SUM(C29+H29) -> 1024240.4 | N29: =SUM(D29+I29) -> 3156121.5 | O29: =SUM(E29+J29) -> 0
A30: 2.3.6 - PRODUCTOS DE MINERALES, METÁLICOS Y NO METÁLICOS | B30: =SUM('TRANSFERENCIA CORRIENTE'!C31:E31) -> 11630.98 | C30: =SUM('TRANSFERENCIA CORRIENTE'!F31:H31) -> 667620.59 | D30: =SUM('TRANSFERENCIA CORRIENTE'!I28:K28) -> 2859834.4 | E30: =SUM('TRANSFERENCIA CORRIENTE'!L31:N31) -> 0 | G30: =SUM(VS!C31:E31) -> 293957.3 | H30: =SUM(VS!F31:H31) -> 0 | I30: =SUM(VS!I31:K31) -> 211552.06 | J30: =SUM(VS!L31:N31) -> 0 | L30: =SUM(B30+G30) -> 305588.28 | M30: =SUM(C30+H30) -> 667620.59 | N30: =SUM(D30+I30) -> 3071386.4 | O30: =SUM(E30+J30) -> 0
A31: 2.3.7 - COMBUSTIBLES, LUBRICANTES, PRODUCTOS QUÍMICOS Y CONEXOS | B31: =SUM('TRANSFERENCIA CORRIENTE'!C32:E32) -> 8910102 | C31: =SUM('TRANSFERENCIA CORRIENTE'!F32:H32) -> 10068979 | D31: =SUM('TRANSFERENCIA CORRIENTE'!I29:K29) -> 19203378 | E31: =SUM('TRANSFERENCIA CORRIENTE'!L32:N32) -> 0 | G31: =SUM(VS!C32:E32) -> 1660334.6 | H31: =SUM(VS!F32:H32) -> 1500202 | I31: =SUM(VS!I32:K32) -> 2324461 | J31: =SUM(VS!L32:N32) -> 0 | L31: =SUM(B31+G31) -> 10570437 | M31: =SUM(C31+H31) -> 11569181 | N31: =SUM(D31+I31) -> 21527839 | O31: =SUM(E31+J31) -> 0
A32: 2.3.8 - GASTOS QUE SE ASIGNARÁN DURANTE EL EJERCICIO (ART. 32 Y 33 LEY 423-06) | B32: =SUM('TRANSFERENCIA CORRIENTE'!C33:E33) -> 0 | C32: =SUM('TRANSFERENCIA CORRIENTE'!F33:H33) -> 0 | D32: =SUM('TRANSFERENCIA CORRIENTE'!I30:K30) -> 673453.82 | E32: =SUM('TRANSFERENCIA CORRIENTE'!L33:N33) -> 0 | G32: =SUM(VS!C33:E33) -> 0 | H32: =SUM(VS!F33:H33) -> 0 | I32: =SUM(VS!I33:K33) -> 0 | J32: =SUM(VS!L33:N33) -> 0 | L32: =SUM(B32+G32) -> 0 | M32: =SUM(C32+H32) -> 0 | N32: =SUM(D32+I32) -> 673453.82 | O32: =SUM(E32+J32) -> 0
A33: 2.3.9 - PRODUCTOS Y ÚTILES VARIOS | B33: =SUM('TRANSFERENCIA CORRIENTE'!C34:E34) -> 20497066 | C33: =SUM('TRANSFERENCIA CORRIENTE'!F34:H34) -> 18381359 | D33: =SUM('TRANSFERENCIA CORRIENTE'!I31:K31) -> 286504 | E33: =SUM('TRANSFERENCIA CORRIENTE'!L34:N34) -> 0 | G33: =SUM(VS!C34:E34) -> 2460841.8 | H33: =SUM(VS!F34:H34) -> 2836732.4 | I33: =SUM(VS!I34:K34) -> 3610771.5 | J33: =SUM(VS!L34:N34) -> 0 | L33: =SUM(B33+G33) -> 22957908 | M33: =SUM(C33+H33) -> 21218092 | N33: =SUM(D33+I33) -> 3897275.5 | O33: =SUM(E33+J33) -> 0
A34: 2.4 - TRANSFERENCIAS CORRIENTES | B34: =SUM(B35:B41) -> 0 | C34: =SUM(C35:C41) -> 0 | D34: =SUM(D35:D41) -> 0 | E34: =SUM(E35:E41) -> 0 | G34: =SUM(G35:G41) -> 287786.7 | H34: =SUM(H35:H41) -> 1223981 | I34: =SUM(I35:I41) -> 122771 | J34: =SUM(J35:J41) -> 0 | L34: =SUM(B34+G34) -> 287786.7 | M34: =SUM(C34+H34) -> 1223981 | N34: =SUM(D34+I34) -> 122771 | O34: =SUM(E34+J34) -> 0
A35: 2.4.1 - TRANSFERENCIAS CORRIENTES AL SECTOR PRIVADO | B35: =SUM('TRANSFERENCIA CORRIENTE'!C36:E36) -> 0 | C35: =SUM('TRANSFERENCIA CORRIENTE'!F36:H36) -> 0 | D35: =SUM('TRANSFERENCIA CORRIENTE'!I36:K36) -> 0 | E35: =SUM('TRANSFERENCIA CORRIENTE'!L36:N36) -> 0 | G35: =SUM(VS!C36:E36) -> 287786.7 | H35: =SUM(VS!F36:H36) -> 1223981 | I35: =SUM(VS!I36:K36) -> 122771 | J35: =SUM(VS!L36:N36) -> 0 | L35: =SUM(B35+G35) -> 287786.7 | M35: =SUM(C35+H35) -> 1223981 | N35: =SUM(D35+I35) -> 122771 | O35: =SUM(E35+J35) -> 0
A36: 2.4.2 - TRANSFERENCIAS CORRIENTES AL GOBIERNO GENERAL NACIONAL | B36: =SUM('TRANSFERENCIA CORRIENTE'!C37:E37) -> 0 | C36: =SUM('TRANSFERENCIA CORRIENTE'!F37:H37) -> 0 | D36: =SUM('TRANSFERENCIA CORRIENTE'!I37:K37) -> 0 | E36: =SUM('TRANSFERENCIA CORRIENTE'!L37:N37) -> 0 | G36: =SUM(VS!C37:E37) -> 0 | H36: =SUM(VS!F37:H37) -> 0 | I36: =SUM(VS!I37:K37) -> 0 | J36: =SUM(VS!L37:N37) -> 0 | L36: =SUM(B36+G36) -> 0 | M36: =SUM(C36+H36) -> 0 | N36: =SUM(D36+I36) -> 0 | O36: =SUM(E36+J36) -> 0
A37: 2.4.3 - TRANSFERENCIAS CORRIENTES A GOBIERNOS GENERALES LOCALES | B37: =SUM('TRANSFERENCIA CORRIENTE'!C38:E38) -> 0 | C37: =SUM('TRANSFERENCIA CORRIENTE'!F38:H38) -> 0 | D37: =SUM('TRANSFERENCIA CORRIENTE'!I38:K38) -> 0 | E37: =SUM('TRANSFERENCIA CORRIENTE'!L38:N38) -> 0 | G37: =SUM(VS!C38:E38) -> 0 | H37: =SUM(VS!F38:H38) -> 0 | I37: =SUM(VS!I38:K38) -> 0 | J37: =SUM(VS!L38:N38) -> 0 | L37: =SUM(B37+G37) -> 0 | M37: =SUM(C37+H37) -> 0 | N37: =SUM(D37+I37) -> 0 | O37: =SUM(E37+J37) -> 0
A38: 2.4.4 - TRANSFERENCIAS CORRIENTES A EMPRESAS PÚBLICAS NO FINANCIERAS | B38: =SUM('TRANSFERENCIA CORRIENTE'!C39:E39) -> 0 | C38: =SUM('TRANSFERENCIA CORRIENTE'!F39:H39) -> 0 | D38: =SUM('TRANSFERENCIA CORRIENTE'!I39:K39) -> 0 | E38: =SUM('TRANSFERENCIA CORRIENTE'!L39:N39) -> 0 | G38: =SUM(VS!C39:E39) -> 0 | H38: =SUM(VS!F39:H39) -> 0 | I38: =SUM(VS!I39:K39) -> 0 | J38: =SUM(VS!L39:N39) -> 0 | L38: =SUM(B38+G38) -> 0 | M38: =SUM(C38+H38) -> 0 | N38: =SUM(D38+I38) -> 0 | O38: =SUM(E38+J38) -> 0
A39: 2.4.5 - TRANSFERENCIAS CORRIENTES A INSTITUCIONES PÚBLICAS FINANCIERAS | B39: =SUM('TRANSFERENCIA CORRIENTE'!C40:E40) -> 0 | C39: =SUM('TRANSFERENCIA CORRIENTE'!F40:H40) -> 0 | D39: =SUM('TRANSFERENCIA CORRIENTE'!I40:K40) -> 0 | E39: =SUM('TRANSFERENCIA CORRIENTE'!L40:N40) -> 0 | G39: =SUM(VS!C40:E40) -> 0 | H39: =SUM(VS!F40:H40) -> 0 | I39: =SUM(VS!I40:K40) -> 0 | J39: =SUM(VS!L40:N40) -> 0 | L39: =SUM(B39+G39) -> 0 | M39: =SUM(C39+H39) -> 0 | N39: =SUM(D39+I39) -> 0 | O39: =SUM(E39+J39) -> 0
A40: 2.4.7 - TRANSFERENCIAS CORRIENTES AL SECTOR EXTERNO | B40: =SUM('TRANSFERENCIA CORRIENTE'!C41:E41) -> 0 | C40: =SUM('TRANSFERENCIA CORRIENTE'!F41:H41) -> 0 | D40: =SUM('TRANSFERENCIA CORRIENTE'!I41:K41) -> 0 | E40: =SUM('TRANSFERENCIA CORRIENTE'!L41:N41) -> 0 | G40: =SUM(VS!C41:E41) -> 0 | H40: =SUM(VS!F41:H41) -> 0 | I40: =SUM(VS!I41:K41) -> 0 | J40: =SUM(VS!L41:N41) -> 0 | L40: =SUM(B40+G40) -> 0 | M40: =SUM(C40+H40) -> 0 | N40: =SUM(D40+I40) -> 0 | O40: =SUM(E40+J40) -> 0
A41: 2.4.9 - TRANSFERENCIAS CORRIENTES A OTRAS INSTITUCIONES PÚBLICAS | B41: =SUM('TRANSFERENCIA CORRIENTE'!C42:E42) -> 0 | C41: =SUM('TRANSFERENCIA CORRIENTE'!F42:H42) -> 0 | D41: =SUM('TRANSFERENCIA CORRIENTE'!I42:K42) -> 0 | E41: =SUM('TRANSFERENCIA CORRIENTE'!L42:N42) -> 0 | G41: =SUM(VS!C42:E42) -> 0 | H41: =SUM(VS!F42:H42) -> 0 | I41: =SUM(VS!I42:K42) -> 0 | J41: =SUM(VS!L42:N42) -> 0 | L41: =SUM(B41+G41) -> 0 | M41: =SUM(C41+H41) -> 0 | N41: =SUM(D41+I41) -> 0 | O41: =SUM(E41+J41) -> 0
...

Sheet Sheet2

Sheet TRANSFERENCIA CORRIENTE
A1: SERVICIO NACIONAL DE SALUD
A2: HOSPITAL MATERNO INFANTIL SAN LORENZO DE LOS MINA
A3: REGION
A4: Ejecución de Gastos Fondo (100) 2025
A5: En RD$
A7: Detalle | B7: Total | C7: Enero | D7: Febrero | E7: Marzo | F7: Abril | G7: Mayo | H7: Junio | I7: Julio | J7: Agosto | K7: Septiembre | L7: Octubre | M7: Noviembre | N7: Diciembre
A8: 2 - GASTOS
A9: 2.1 - REMUNERACIONES Y CONTRIBUCIONES | B9: 5.4149799e+08 | C9: 65091180 | D9: 67131936 | E9: 66337620 | F9: 66556156 | G9: 66630551 | H9: 66583615 | I9: 71335676 | J9: 71831261 | K9: =SUM(K10:K14) -> 71591504 | L9: 0 | M9: 0 | N9: 0
A10: 2.1.1 - REMUNERACIONES | B10: 4.4636576e+08 | C10: 53640339 | D10: 55586129 | E10: 54718737 | F10: 54771097 | G10: 54445140 | H10: 54868543 | I10: 58925421 | J10: 59410356 | K10: 59165425
A11: 2.1.2 - SOBRESUELDOS | B11: 26843184 | C11: 3196999.6 | D11: 3197999.6 | E11: 3199399.6 | F11: 3384964.5 | G11: 3807608.3 | H11: 3343226.2 | I11: 3344880.2 | J11: 3368105.6 | K11: 3321905.6
A12: 2.1.3 - DIETAS Y GASTOS DE REPRESENTACIÓN | B12: 0
A13: 2.1.4 - GRATIFICACIONES Y BONIFICACIONES | B13: 0
A14: 2.1.5 - CONTRIBUCIONES A LA SEGURIDAD SOCIAL | B14: 68289048 | C14: 8253841.6 | D14: 8347807.5 | E14: 8419483.2 | F14: 8400093.9 | G14: 8377802.1 | H14: 8371846.2 | I14: 9065374.6 | J14: 9052799.4 | K14: 9104173.4
