Workbook

Sheet RESUMEN
A1: Form. No.6 SRS
A3: Servicio Nacional de Salud
A4: Dirección de Fizcalización
A5: Consolidado de Ingresos y Gastos por Fuente de Financiamiento
A6: HOSPITAL MATERNO INFANTIL SAN LORENZO DE LOS MINA
A7: RESUMEN DE EJECUCION ENERO-
C8: Ingresos Generales:
E9: 1.- Balance Inicial / Fuente:
E10: Anticipo Financiero | H10: Otros Aportes | L10: Contraseña: 0001
E11: Transferencias Corrientes
E12: Venta de Servicios
E13: 2.- Ingresos por Fuente / Cuenta
E14: Anticipo Financiero | G14: 0 | H14: Otros Aportes | I14: =+SEPTIEMBRE!I14+'AGOSTO '!I14+JULIO!I14 -> 2105668.7 | L14: OBJETAL | M14: FR | N14: VS
E15: Transferencias Corrientes | G15: =+SEPTIEMBRE!G15+'AGOSTO '!G15+JULIO!G15 -> 3.0637496e+08 | H15: Aportes Nomina SNS | I15: 0 | L15: 2.1 | M15: =G26 -> 5.6592929e+08 | N15: =H26 -> 0
E16: Venta de Servicios | G16: =+SEPTIEMBRE!G16+'AGOSTO '!G16+JULIO!G16 -> 22795995 | L16: 2.2 | M16: =G87 -> 2443769.3 | N16: =H87 -> 8735180.1
H17: TOTAL INGRESOS RDS | I17: =+G10+G11+G12+I10+G14+G15+G16+I14+I15 -> 3.3127662e+08 | L17: 2.3 | M17: ='[1]CONS. FUENTES FINAN'!G212 -> 15408530 | N17: ='[1]CONS. FUENTES FINAN'!H212 -> 999513.81
L18: 2.4 | M18: =G330 -> 0 | N18: =H330 -> 350986
L19: 2.6 | M19: =G336 -> 11931242 | N19: =H336 -> 2945979.2
L20: 2.7 | M20: ='[1]CONS. FUENTES FINAN'!G463 -> 0 | N20: ='[1]CONS. FUENTES FINAN'!H463 -> 0
A21: Código Presupuestario | F21: Descripción Gasto por Cuenta | G21: Distribución del Gasto por Fuente de Financiamiento | I21: TOTAL | J21: %
A22: Tipo | B22: Objeto | C22: Cuenta | D22: Sub-Cuenta | E22: Auxiliar | G22: Fondo 100 | H22: Venta de Servicios/ Otros Aportes
A24: 2 | F24: Gastos | G24: =+SEPTIEMBRE!G25+'AGOSTO '!G25+JULIO!G24+'OCTUBRE '!G25+'ENERO-JUNIO 2025'!G25+'RESUMEN TRIMESTRE OCTUBRE-DIC'!G25 -> 1.4259055e+09 | H24: =+SEPTIEMBRE!H25+'AGOSTO '!H25+JULIO!H24+'OCTUBRE '!H25+'ENERO-JUNIO 2025'!H25 -> 84207144 | I24: =+G24+H24 -> 1.5101126e+09 | J24: 1
A25: 2 | B25: 1 | F25: Servicios Personales | G25: =+SEPTIEMBRE!G26+'AGOSTO '!G26+JULIO!G25+'OCTUBRE '!G26+'ENERO-JUNIO 2025'!G26 -> 6.8607635e+08 | H25: =+SEPTIEMBRE!H26+'AGOSTO '!H26+JULIO!H25+'OCTUBRE '!H26+'ENERO-JUNIO 2025'!H26 -> 9644681.1 | I25: =+G25+H25 -> 6.9572103e+08 | J25: 0.59671635
A26: 2 | B26: 1 | C26: 1 | F26: Remuneraciones | G26: =+SEPTIEMBRE!G27+'AGOSTO '!G27+JULIO!G26+'OCTUBRE '!G27+'ENERO-JUNIO 2025'!G27 -> 5.6592929e+08 | H26: =+SEPTIEMBRE!H27+'AGOSTO '!H27+JULIO!H26+'OCTUBRE '!H27+'ENERO-JUNIO 2025'!H27 -> 0 | I26: =+G26+H26 -> 5.6592929e+08 | J26: 0.49290571
A27: 2 | B27: 1 | C27: 1 | D27: 1 | F27: Remuneraciones al personal fijo | G27: =+SEPTIEMBRE!G28+'AGOSTO '!G28+JULIO!G27+'OCTUBRE '!G28+'ENERO-JUNIO 2025'!G28 -> 5.521678e+08 | H27: =+SEPTIEMBRE!H28+'AGOSTO '!H28+JULIO!H27+'OCTUBRE '!H28+'ENERO-JUNIO 2025'!H28 -> 0 | I27: =+G27+H27 -> 5.521678e+08 | J27: 0.48334771
A28: 2 | B28: 1 | C28: 1 | D28: 1 | E28: 01 | F28: Sueldos a empleados fijos | G28: =+SEPTIEMBRE!G29+'AGOSTO '!G29+JULIO!G28+'OCTUBRE '!G29+'ENERO-JUNIO 2025'!G29 -> 5.521678e+08 | H28: =+SEPTIEMBRE!H29+'AGOSTO '!H29+JULIO!H28+'OCTUBRE '!H29+'ENERO-JUNIO 2025'!H29 -> 0 | I28: =+G28+H28 -> 5.521678e+08 | J28: 0.48334771
A29: 2 | B29: 1 | C29: 1 | D29: 1 | E29: 02 | F29: Sueldos a médicos | G29: =+SEPTIEMBRE!G30+'AGOSTO '!G30+JULIO!G29+'OCTUBRE '!G30+'ENERO-JUNIO 2025'!G30 -> 0 | H29: =+SEPTIEMBRE!H30+'AGOSTO '!H30+JULIO!H29+'OCTUBRE '!H30+'ENERO-JUNIO 2025'!H30 -> 0 | I29: =+G29+H29 -> 0 | J29: 0
A30: 2 | B30: 1 | C30: 1 | D30: 1 | E30: 03 | F30: Ascensos a militares | G30: =+SEPTIEMBRE!G31+'AGOSTO '!G31+JULIO!G30+'OCTUBRE '!G31+'ENERO-JUNIO 2025'!G31 -> 0 | H30: =+SEPTIEMBRE!H31+'AGOSTO '!H31+JULIO!H30+'OCTUBRE '!H31+'ENERO-JUNIO 2025'!H31 -> 0 | I30: =+G30+H30 -> 0 | J30: 0
A31: 2 | B31: 1 | C31: 1 | D31: 1 | E31: 04 | F31: Nuevas plazas maestros | G31: =+SEPTIEMBRE!G32+'AGOSTO '!G32+JULIO!G31+'OCTUBRE '!G32+'ENERO-JUNIO 2025'!G32 -> 0 | H31: =+SEPTIEMBRE!H32+'AGOSTO '!H32+JULIO!H31+'OCTUBRE '!H32+'ENERO-JUNIO 2025'!H32 -> 0 | I31: =+G31+H31 -> 0 | J31: 0
A32: 2 | B32: 1 | C32: 1 | D32: 1 | E32: 05 | F32: Incentivos y escalafón | G32: =+SEPTIEMBRE!G33+'AGOSTO '!G33+JULIO!G32+'OCTUBRE '!G33+'ENERO-JUNIO 2025'!G33 -> 0 | H32: =+SEPTIEMBRE!H33+'AGOSTO '!H33+JULIO!H32+'OCTUBRE '!H33+'ENERO-JUNIO 2025'!H33 -> 0 | I32: =+G32+H32 -> 0 | J32: 0
A33: 2 | B33: 1 | C33: 1 | D33: 1 | E33: 06 | F33: Nuevas plazas a médicos | G33: =+SEPTIEMBRE!G34+'AGOSTO '!G34+JULIO!G33+'OCTUBRE '!G34+'ENERO-JUNIO 2025'!G34 -> 0 | H33: =+SEPTIEMBRE!H34+'AGOSTO '!H34+JULIO!H33+'OCTUBRE '!H34+'ENERO-JUNIO 2025'!H34 -> 0 | I33: =+G33+H33 -> 0 | J33: 0
A34: 2 | B34: 1 | C34: 1 | D34: 2 | F34: Remuneraciones al personal con carácter transitorio | G34: =+SEPTIEMBRE!G35+'AGOSTO '!G35+JULIO!G34+'OCTUBRE '!G35+'ENERO-JUNIO 2025'!G35 -> 11194310 | H34: =+SEPTIEMBRE!H35+'AGOSTO '!H35+JULIO!H34+'OCTUBRE '!H35+'ENERO-JUNIO 2025'!H35 -> 0 | I34: =+G34+H34 -> 11194310
A35: 2 | B35: 1 | C35: 1 | D35: 2 | E35: 03 | F35: Suplencias | G35: =+SEPTIEMBRE!G36+'AGOSTO '!G36+JULIO!G35+'OCTUBRE '!G36+'ENERO-JUNIO 2025'!G36 -> 0 | H35: =+SEPTIEMBRE!H36+'AGOSTO '!H36+JULIO!H35+'OCTUBRE '!H36+'ENERO-JUNIO 2025'!H36 -> 0 | I35: =+G35+H35 -> 0 | J35: 0
A36: 2 | B36: 1 | C36: 1 | D36: 2 | E36: 05 | F36: Sueldo al personal nominal en período probatorio | G36: =+SEPTIEMBRE!G37+'AGOSTO '!G37+JULIO!G36+'OCTUBRE '!G37+'ENERO-JUNIO 2025'!G37 -> 0 | H36: =+SEPTIEMBRE!H37+'AGOSTO '!H37+JULIO!H36+'OCTUBRE '!H37+'ENERO-JUNIO 2025'!H37 -> 0 | I36: =+G36+H36 -> 0 | J36: 0
A37: 2 | B37: 1 | C37: 1 | D37: 2 | E37: 06 | F37: Jornales | G37: =+SEPTIEMBRE!G38+'AGOSTO '!G38+JULIO!G37+'OCTUBRE '!G38+'ENERO-JUNIO 2025'!G38 -> 0 | H37: =+SEPTIEMBRE!H38+'AGOSTO '!H38+JULIO!H37+'OCTUBRE '!H38+'ENERO-JUNIO 2025'!H38 -> 0 | I37: =+G37+H37 -> 0 | J37: 0
A38: 2 | B38: 1 | C38: 1 | D38: 2 | E38: 08 | F38: Empleados temporales | G38: =+SEPTIEMBRE!G39+'AGOSTO '!G39+JULIO!G38+'OCTUBRE '!G39+'ENERO-JUNIO 2025'!G39 -> 11194310 | H38: =+SEPTIEMBRE!H39+'AGOSTO '!H39+JULIO!H38+'OCTUBRE '!H39+'ENERO-JUNIO 2025'!H39 -> 0 | I38: =+G38+H38 -> 11194310 | J38: 0.0094567878
A39: 2 | B39: 1 | C39: 1 | D39: 2 | E39: 09 | F39: Personal de carácter eventual | G39: =+SEPTIEMBRE!G40+'AGOSTO '!G40+JULIO!G39+'OCTUBRE '!G40+'ENERO-JUNIO 2025'!G40 -> 0 | H39: =+SEPTIEMBRE!H40+'AGOSTO '!H40+JULIO!H39+'OCTUBRE '!H40+'ENERO-JUNIO 2025'!H40 -> 0 | I39: =+G39+H39 -> 0 | J39: 0
A40: 2 | B40: 1 | C40: 1 | D40: 2 | E40: 11 | F40: Interinato | G40: =+SEPTIEMBRE!G41+'AGOSTO '!G41+JULIO!G40+'OCTUBRE '!G41+'ENERO-JUNIO 2025'!G41 -> 0 | H40: =+SEPTIEMBRE!H41+'AGOSTO '!H41+JULIO!H40+'OCTUBRE '!H41+'ENERO-JUNIO 2025'!H41 -> 0 | I40: =+G40+H40 -> 0 | J40: 0
A41: 2 | B41: 1 | C41: 1 | D41: 3 | F41: Sueldos al personal fijo en trámite de pensiones | G41: =+SEPTIEMBRE!G42+'AGOSTO '!G42+JULIO!G41+'OCTUBRE '!G42+'ENERO-JUNIO 2025'!G42 -> 0 | H41: =+SEPTIEMBRE!H42+'AGOSTO '!H42+JULIO!H41+'OCTUBRE '!H42+'ENERO-JUNIO 2025'!H42 -> 0 | I41: =+G41+H41 -> 0
A42: 2 | B42: 1 | C42: 1 | D42: 3 | E42: 01 | F42: Sueldos al personal fijo en trámite de pensiones | G42: =+SEPTIEMBRE!G43+'AGOSTO '!G43+JULIO!G42+'OCTUBRE '!G43+'ENERO-JUNIO 2025'!G43 -> 0 | H42: =+SEPTIEMBRE!H43+'AGOSTO '!H43+JULIO!H42+'OCTUBRE '!H43+'ENERO-JUNIO 2025'!H43 -> 0 | I42: =+G42+H42 -> 0 | J42: 0
...

Sheet SEPTIEMBRE
A1: Form. No.6 SRS
A3: Servicio Nacional de Salud
A4: Dirección de Fizcalización
A5: Consolidado de Ingresos y Gastos por Fuente de Financiamiento
A6: HOSPITAL MATERNO INFANTIL SAN LORENZO DE LOS MINA
A7: SEPTIEMBRE 2025
C8: Ingresos Generales:
E9: 1.- Balance Inicial / Fuente:
E10: Anticipo Financiero | H10: Otros Aportes | L10: Contraseña: 0001
E11: Transferencias Corrientes
E12: Venta de Servicios | G12: 209079.81
E13: 2.- Ingresos por Fuente / Cuenta
E14: Anticipo Financiero | H14: Otros Aportes | I14: =+'[2]INGR SEGUN ORIGEN'!E38 -> 489300 | L14: OBJETAL | M14: FR | N14: VS
E15: Transferencias Corrientes | G15: =+'[2]INGR SEGUN ORIGEN'!E12 -> 1.0574137e+08 | H15: Aportes Nomina SNS | L15: 2.1 | M15: =G26 -> 71591504 | N15: =H26 -> 4413127.6
E16: Venta de Servicios | G16: =+'[2]INGR SEGUN ORIGEN'!E30 -> 12277160 | L16: 2.2 | M16: =G87 -> 7782458.8 | N16: =H87 -> 1557736.2
H17: TOTAL INGRESOS RDS | I17: =+G10+G11+G12+I10+G14+G15+G16+I14+I15 -> 1.1871691e+08 | L17: 2.3 | M17: ='[2]CONS. FUENTES FINAN'!G212 -> 25141648 | N17: ='[2]CONS. FUENTES FINAN'!H212 -> 3168875.7
L18: 2.4 | M18: =G330 -> 0 | N18: =H330 -> 21600
L19: 2.6 | M19: =G336 -> 5819603.3 | N19: =H336 -> 2245366
L20: 2.7 | M20: ='[2]CONS. FUENTES FINAN'!G463 -> 0 | N20: ='[2]CONS. FUENTES FINAN'!H463 -> 0
A21: 1 | F21: 2 | G21: 3 | I21: 4 | J21: 5
A22: Código Presupuestario | F22: Descripción Gasto por Cuenta | G22: Distribución del Gasto por Fuente de Financiamiento | I22: TOTAL | J22: %
A23: Tipo | B23: Objeto | C23: Cuenta | D23: Sub-Cuenta | E23: Auxiliar | G23: Fondo 100 | H23: Venta de Servicios/ Otros Aportes
A25: 2 | F25: Gastos | G25: =+G26+G87+G212+G330+G336+G463 -> 1.1033521e+08 | H25: =+H26+H87+H212+H330+H336+H463 -> 11406705 | I25: =SUM(G25:H25) -> 1.2174192e+08 | J25: =+J26+J87+J212+J330+J336+J463 -> 1
A26: 2 | B26: 1 | F26: Servicios Personales | G26: =+G27+G51+G64+G71+G78 -> 71591504 | H26: =+H27+H51+H64+H71+H78 -> 4413127.6 | I26: =SUM(G26:H26) -> 76004631 | J26: =I26/$I$25 -> 0.62430945
A27: 2 | B27: 1 | C27: 1 | F27: Remuneraciones | G27: =+G28+G35+G42+G44+G46 -> 59165425 | H27: =+H28+H35+H42+H44+H46 -> 0 | I27: =SUM(G27:H27) -> 59165425
A28: 2 | B28: 1 | C28: 1 | D28: 1 | F28: Remuneraciones al personal fijo | G28: =SUM(G29:G34) -> 58052894 | H28: =SUM(H29:H34) -> 0 | I28: =SUM(G28:H28) -> 58052894
A29: 2 | B29: 1 | C29: 1 | D29: 1 | E29: 01 | F29: Sueldos a empleados fijos | G29: ='[2]CUENTA T FONDO 100'!A126 -> 58052894 | H29: ='[2]CUENTA T VS'!A75 -> 0 | I29: =SUM(G29:H29) -> 58052894 | J29: =I29/$I$25 -> 0.47685213
A30: 2 | B30: 1 | C30: 1 | D30: 1 | E30: 02 | F30: Sueldos a médicos | G30: ='[2]CUENTA T FONDO 100'!B126 -> 0 | H30: ='[2]CUENTA T VS'!B75 -> 0 | I30: =SUM(G30:H30) -> 0 | J30: =I30/$I$25 -> 0
A31: 2 | B31: 1 | C31: 1 | D31: 1 | E31: 03 | F31: Ascensos a militares | G31: ='[2]CUENTA T FONDO 100'!C126 -> 0 | H31: ='[2]CUENTA T VS'!C75 -> 0 | I31: =SUM(G31:H31) -> 0 | J31: =I31/$I$25 -> 0
A32: 2 | B32: 1 | C32: 1 | D32: 1 | E32: 04 | F32: Nuevas plazas maestros | G32: ='[2]CUENTA T FONDO 100'!D126 -> 0 | H32: ='[2]CUENTA T VS'!D75 -> 0 | I32: =SUM(G32:H32) -> 0 | J32: =I32/$I$25 -> 0
A33: 2 | B33: 1 | C33: 1 | D33: 1 | E33: 05 | F33: Incentivos y escalafón | G33: ='[2]CUENTA T FONDO 100'!E126 -> 0 | H33: ='[2]CUENTA T VS'!E75 -> 0 | I33: =SUM(G33:H33) -> 0 | J33: =I33/$I$25 -> 0
A34: 2 | B34: 1 | C34: 1 | D34: 1 | E34: 06 | F34: Nuevas plazas a médicos | G34: ='[2]CUENTA T FONDO 100'!F126 -> 0 | H34: ='[2]CUENTA T VS'!F75 -> 0 | I34: =SUM(G34:H34) -> 0 | J34: =I34/$I$25 -> 0
A35: 2 | B35: 1 | C35: 1 | D35: 2 | F35: Remuneraciones al personal con carácter transitorio | G35: =SUM(G36:G41) -> 1112531 | H35: =SUM(H36:H41) -> 0 | I35: =SUM(G35:H35) -> 1112531
A36: 2 | B36: 1 | C36: 1 | D36: 2 | E36: 03 | F36: Suplencias | G36: ='[2]CUENTA T FONDO 100'!G126 -> 0 | H36: ='[2]CUENTA T VS'!G75 -> 0 | I36: =SUM(G36:H36) -> 0 | J36: =I36/$I$25 -> 0
A37: 2 | B37: 1 | C37: 1 | D37: 2 | E37: 05 | F37: Sueldo al personal nominal en período probatorio | G37: ='[2]CUENTA T FONDO 100'!H126 -> 0 | H37: ='[2]CUENTA T VS'!H75 -> 0 | I37: =SUM(G37:H37) -> 0 | J37: =I37/$I$25 -> 0
A38: 2 | B38: 1 | C38: 1 | D38: 2 | E38: 06 | F38: Jornales | G38: ='[2]CUENTA T FONDO 100'!I126 -> 0 | H38: ='[2]CUENTA T VS'!I75 -> 0 | I38: =SUM(G38:H38) -> 0 | J38: =I38/$I$25 -> 0
A39: 2 | B39: 1 | C39: 1 | D39: 2 | E39: 08 | F39: Empleados temporales | G39: ='[2]CUENTA T FONDO 100'!J126 -> 1112531 | H39: ='[2]CUENTA T VS'!J75 -> 0 | I39: =SUM(G39:H39) -> 1112531 | J39: =I39/$I$25 -> 0.0091384384
A40: 2 | B40: 1 | C40: 1 | D40: 2 | E40: 09 | F40: Personal de carácter eventual | G40: ='[2]CUENTA T FONDO 100'!K126 -> 0 | H40: ='[2]CUENTA T VS'!K75 -> 0 | I40: =SUM(G40:H40) -> 0 | J40: =I40/$I$25 -> 0
A41: 2 | B41: 1 | C41: 1 | D41: 2 | E41: 11 | F41: Interinato | G41: ='[2]CUENTA T FONDO 100'!L126 -> 0 | H41: ='[2]CUENTA T VS'!L75 -> 0 | I41: =SUM(G41:H41) -> 0 | J41: =I41/$I$25 -> 0
A42: 2 | B42: 1 | C42: 1 | D42: 3 | F42: Sueldos al personal fijo en trámite de pensiones | G42: =SUM(G43) -> 0 | H42: =SUM(H43) -> 0 | I42: =SUM(G42:H42) -> 0
...

Sheet AGOSTO 
A1: Form. No.6 SRS
A3: Servicio Nacional de Salud
A4: Dirección de Fizcalización
A5: Consolidado de Ingresos y Gastos por Fuente de Financiamiento
A6: NOMBRE ESTABLECIMIENTO
A7: AGOSTO 2025
C8: Ingresos Generales:
E9: 1.- Balance Inicial / Fuente:
E10: Anticipo Financiero | H10: Otros Aportes | L10: Contraseña: 0001
E11: Transferencias Corrientes
E12: Venta de Servicios | G12: 1771845.5
E13: 2.- Ingresos por Fuente / Cuenta
E14: Anticipo Financiero | H14: Otros Aportes | I14: =+'[3]INGR SEGUN ORIGEN'!E37 -> 590200 | L14: OBJETAL | M14: FR | N14: VS
E15: Transferencias Corrientes | G15: =+'[3]INGR SEGUN ORIGEN'!E12 -> 1.003168e+08 | H15: Aportes Nomina SNS | L15: 2.1 | M15: =G26 -> 71831261 | N15: =H26 -> 0
E16: Venta de Servicios | G16: =+'[3]INGR SEGUN ORIGEN'!E29 -> 6887322.7 | L16: 2.2 | M16: =G87 -> 3128332.8 | N16: =H87 -> 3852523.8
H17: TOTAL INGRESOS RDS | I17: =+G10+G11+G12+I10+G14+G15+G16+I14+I15 -> 1.0956616e+08 | L17: 2.3 | M17: ='[3]CONS. FUENTES FINAN'!G212 -> 14321740 | N17: ='[3]CONS. FUENTES FINAN'!H212 -> 2478357.5
L18: 2.4 | M18: =G330 -> 0 | N18: =H330 -> 33600
L19: 2.6 | M19: =G336 -> 10590779 | N19: =H336 -> 2395076.4
L20: 2.7 | M20: ='[3]CONS. FUENTES FINAN'!G463 -> 0 | N20: ='[3]CONS. FUENTES FINAN'!H463 -> 0
A21: 1 | F21: 2 | G21: 3 | I21: 4 | J21: 5
A22: Código Presupuestario | F22: Descripción Gasto por Cuenta | G22: Distribución del Gasto por Fuente de Financiamiento | I22: TOTAL | J22: %
A23: Tipo | B23: Objeto | C23: Cuenta | D23: Sub-Cuenta | E23: Auxiliar | G23: Fondo 100 | H23: Venta de Servicios/ Otros Aportes
A25: 2 | F25: Gastos | G25: =+G26+G87+G212+G330+G336+G463 -> 99872112 | H25: =+H26+H87+H212+H330+H336+H463 -> 8759557.7 | I25: =SUM(G25:H25) -> 1.0863167e+08 | J25: =+J26+J87+J212+J330+J336+J463 -> 1
A26: 2 | B26: 1 | F26: Servicios Personales | G26: =+G27+G51+G64+G71+G78 -> 71831261 | H26: =+H27+H51+H64+H71+H78 -> 0 | I26: =SUM(G26:H26) -> 71831261 | J26: =I26/$I$25 -> 0.66123683
A27: 2 | B27: 1 | C27: 1 | F27: Remuneraciones | G27: =+G28+G35+G42+G44+G46 -> 59410356 | H27: =+H28+H35+H42+H44+H46 -> 0 | I27: =SUM(G27:H27) -> 59410356 | J27: 0
A28: 2 | B28: 1 | C28: 1 | D28: 1 | F28: Remuneraciones al personal fijo | G28: =SUM(G29:G34) -> 57719080 | H28: =SUM(H29:H34) -> 0 | I28: =SUM(G28:H28) -> 57719080 | J28: 0
A29: 2 | B29: 1 | C29: 1 | D29: 1 | E29: 01 | F29: Sueldos a empleados fijos | G29: ='[3]CUENTA T FONDO 100'!A461 -> 57719080 | H29: ='[3]CUENTA T VS'!A225 -> 0 | I29: =SUM(G29:H29) -> 57719080 | J29: =I29/$I$25 -> 0.5313283
A30: 2 | B30: 1 | C30: 1 | D30: 1 | E30: 02 | F30: Sueldos a médicos | G30: ='[3]CUENTA T FONDO 100'!B461 -> 0 | H30: ='[3]CUENTA T VS'!B225 -> 0 | I30: =SUM(G30:H30) -> 0 | J30: =I30/$I$25 -> 0
A31: 2 | B31: 1 | C31: 1 | D31: 1 | E31: 03 | F31: Ascensos a militares | G31: ='[3]CUENTA T FONDO 100'!C461 -> 0 | H31: ='[3]CUENTA T VS'!C225 -> 0 | I31: =SUM(G31:H31) -> 0 | J31: =I31/$I$25 -> 0
A32: 2 | B32: 1 | C32: 1 | D32: 1 | E32: 04 | F32: Nuevas plazas maestros | G32: ='[3]CUENTA T FONDO 100'!D461 -> 0 | H32: ='[3]CUENTA T VS'!D225 -> 0 | I32: =SUM(G32:H32) -> 0 | J32: =I32/$I$25 -> 0
A33: 2 | B33: 1 | C33: 1 | D33: 1 | E33: 05 | F33: Incentivos y escalafón | G33: ='[3]CUENTA T FONDO 100'!E461 -> 0 | H33: ='[3]CUENTA T VS'!E225 -> 0 | I33: =SUM(G33:H33) -> 0 | J33: =I33/$I$25 -> 0
A34: 2 | B34: 1 | C34: 1 | D34: 1 | E34: 06 | F34: Nuevas plazas a médicos | G34: ='[3]CUENTA T FONDO 100'!F461 -> 0 | H34: ='[3]CUENTA T VS'!F225 -> 0 | I34: =SUM(G34:H34) -> 0 | J34: =I34/$I$25 -> 0
A35: 2 | B35: 1 | C35: 1 | D35: 2 | F35: Remuneraciones al personal con carácter transitorio | G35: =SUM(G36:G41) -> 1112531 | H35: =SUM(H36:H41) -> 0 | I35: =SUM(G35:H35) -> 1112531
A36: 2 | B36: 1 | C36: 1 | D36: 2 | E36: 03 | F36: Suplencias | G36: ='[3]CUENTA T FONDO 100'!G461 -> 0 | H36: ='[3]CUENTA T VS'!G225 -> 0 | I36: =SUM(G36:H36) -> 0 | J36: =I36/$I$25 -> 0
A37: 2 | B37: 1 | C37: 1 | D37: 2 | E37: 05 | F37: Sueldo al personal nominal en período probatorio | G37: ='[3]CUENTA T FONDO 100'!H461 -> 0 | H37: ='[3]CUENTA T VS'!H225 -> 0 | I37: =SUM(G37:H37) -> 0 | J37: =I37/$I$25 -> 0
A38: 2 | B38: 1 | C38: 1 | D38: 2 | E38: 06 | F38: Jornales | G38: ='[3]CUENTA T FONDO 100'!I461 -> 0 | H38: ='[3]CUENTA T VS'!I225 -> 0 | I38: =SUM(G38:H38) -> 0 | J38: =I38/$I$25 -> 0
A39: 2 | B39: 1 | C39: 1 | D39: 2 | E39: 08 | F39: Empleados temporales | G39: ='[3]CUENTA T FONDO 100'!J461 -> 1112531 | H39: ='[3]CUENTA T VS'!J225 -> 0 | I39: =SUM(G39:H39) -> 1112531 | J39: =I39/$I$25 -> 0.010241314
A40: 2 | B40: 1 | C40: 1 | D40: 2 | E40: 09 | F40: Personal de carácter eventual | G40: ='[3]CUENTA T FONDO 100'!K461 -> 0 | H40: ='[3]CUENTA T VS'!K225 -> 0 | I40: =SUM(G40:H40) -> 0 | J40: =I40/$I$25 -> 0
A41: 2 | B41: 1 | C41: 1 | D41: 2 | E41: 11 | F41: Interinato | G41: ='[3]CUENTA T FONDO 100'!L461 -> 0 | H41: ='[3]CUENTA T VS'!L225 -> 0 | I41: =SUM(G41:H41) -> 0 | J41: =I41/$I$25 -> 0
A42: 2 | B42: 1 | C42: 1 | D42: 3 | F42: Sueldos al personal fijo en trámite de pensiones | G42: =SUM(G43) -> 0 | H42: =SUM(H43) -> 0 | I42: =SUM(G42:H42) -> 0
...

Sheet JULIO
A1: Form. No.6 SRS
A3: Servicio Nacional de Salud
A4: Dirección de Fizcalización
A5: Consolidado de Ingresos y Gastos por Fuente de Financiamiento
A6: HOSPITAL MATERNO INFANTIL SAN LORENZO DE LOS MINA
A7: JULIO 2025
C8: Ingresos Generales:
E9: 1.- Balance Inicial / Fuente:
E10: Anticipo Financiero | H10: Otros Aportes | L10: Contraseña: 0001
E11: Transferencias Corrientes
E12: Venta de Servicios | G12: 1377881.2
E13: 2.- Ingresos por Fuente / Cuenta
E14: Anticipo Financiero | G14: 0 | H14: Otros Aportes | I14: =+'[1]INGR SEGUN ORIGEN'!E31 -> 1026168.7 | L14: OBJETAL | M14: FR | N14: VS
E15: Transferencias Corrientes | G15: =+'[1]INGR SEGUN ORIGEN'!E12 -> 1.003168e+08 | H15: Aportes Nomina SNS | I15: 0 | L15: 2.1 | M15: =G26 -> 58925421 | N15: =H26 -> 0
E16: Venta de Servicios | G16: =+'[1]INGR SEGUN ORIGEN'!E23 -> 3631511.4 | L16: 2.2 | M16: =G87 -> 60535 | N16: =H87 -> 1781904.1
H17: TOTAL INGRESOS RDS | I17: =+G10+G11+G12+I10+G14+G15+G16+I14+I15 -> 1.0635236e+08 | L17: 2.3 | M17: ='[1]CONS. FUENTES FINAN'!G212 -> 15408530 | N17: ='[1]CONS. FUENTES FINAN'!H212 -> 999513.81
L18: 2.4 | M18: =G330 -> 0 | N18: =H330 -> 30371
L19: 2.6 | M19: =G336 -> 2268904.4 | N19: =H336 -> 0
L20: 2.7 | M20: ='[1]CONS. FUENTES FINAN'!G463 -> 0 | N20: ='[1]CONS. FUENTES FINAN'!H463 -> 0
A21: Código Presupuestario | F21: Descripción Gasto por Cuenta | G21: Distribución del Gasto por Fuente de Financiamiento | I21: TOTAL | J21: %
A22: Tipo | B22: Objeto | C22: Cuenta | D22: Sub-Cuenta | E22: Auxiliar | G22: Fondo 100 | H22: Venta de Servicios/ Otros Aportes
A24: 2 | F24: Gastos | G24: 1.1029218e+08 | H24: 9254860.6 | I24: 1.1954704e+08 | J24: 1
A25: 2 | B25: 1 | F25: Servicios Personales | G25: 71335676 | H25: 0 | I25: 71335676 | J25: 0.59671635
A26: 2 | B26: 1 | C26: 1 | F26: Remuneraciones | G26: 58925421 | H26: 0 | I26: 58925421 | J26: 0.49290571
A27: 2 | B27: 1 | C27: 1 | D27: 1 | F27: Remuneraciones al personal fijo | G27: 57782790 | H27: 0 | I27: 57782790 | J27: 0.48334771
A28: 2 | B28: 1 | C28: 1 | D28: 1 | E28: 01 | F28: Sueldos a empleados fijos | G28: 57782790 | H28: 0 | I28: 57782790 | J28: 0.48334771
A29: 2 | B29: 1 | C29: 1 | D29: 1 | E29: 02 | F29: Sueldos a médicos | G29: 0 | H29: 0 | I29: 0 | J29: 0
A30: 2 | B30: 1 | C30: 1 | D30: 1 | E30: 03 | F30: Ascensos a militares | G30: 0 | H30: 0 | I30: 0 | J30: 0
A31: 2 | B31: 1 | C31: 1 | D31: 1 | E31: 04 | F31: Nuevas plazas maestros | G31: 0 | H31: 0 | I31: 0 | J31: 0
A32: 2 | B32: 1 | C32: 1 | D32: 1 | E32: 05 | F32: Incentivos y escalafón | G32: 0 | H32: 0 | I32: 0 | J32: 0
A33: 2 | B33: 1 | C33: 1 | D33: 1 | E33: 06 | F33: Nuevas plazas a médicos | G33: 0 | H33: 0 | I33: 0 | J33: 0
A34: 2 | B34: 1 | C34: 1 | D34: 2 | F34: Remuneraciones al personal con carácter transitorio | G34: 1130531 | H34: 0 | I34: 1130531
A35: 2 | B35: 1 | C35: 1 | D35: 2 | E35: 03 | F35: Suplencias | G35: 0 | H35: 0 | I35: 0 | J35: 0
A36: 2 | B36: 1 | C36: 1 | D36: 2 | E36: 05 | F36: Sueldo al personal nominal en período probatorio | G36: 0 | H36: 0 | I36: 0 | J36: 0
A37: 2 | B37: 1 | C37: 1 | D37: 2 | E37: 06 | F37: Jornales | G37: 0 | H37: 0 | I37: 0 | J37: 0
A38: 2 | B38: 1 | C38: 1 | D38: 2 | E38: 08 | F38: Empleados temporales | G38: 1130531 | H38: 0 | I38: 1130531 | J38: 0.0094567878
A39: 2 | B39: 1 | C39: 1 | D39: 2 | E39: 09 | F39: Personal de carácter eventual | G39: 0 | H39: 0 | I39: 0 | J39: 0
A40: 2 | B40: 1 | C40: 1 | D40: 2 | E40: 11 | F40: Interinato | G40: 0 | H40: 0 | I40: 0 | J40: 0
A41: 2 | B41: 1 | C41: 1 | D41: 3 | F41: Sueldos al personal fijo en trámite de pensiones | G41: 0 | H41: 0 | I41: 0
A42: 2 | B42: 1 | C42: 1 | D42: 3 | E42: 01 | F42: Sueldos al personal fijo en trámite de pensiones | G42: 0 | H42: 0 | I42: 0 | J42: 0
...

Sheet OCTUBRE 
A1: Form. No.6 SRS
A3: Servicio Nacional de Salud
A4: Dirección de Fizcalización
A5: Consolidado de Ingresos y Gastos por Fuente de Financiamiento
A6: HOSPITAL MATERNO INFANTIL SAN LORENZO DE LOS MINA
A7: OCTUBRE 2025
C8: Ingresos Generales:
E9: 1.- Balance Inicial / Fuente:
E10: Anticipo Financiero | H10: Otros Aportes
E11: Transferencias Corrientes
E12: Venta de Servicios | G12: 209079.81
E13: 2.- Ingresos por Fuente / Cuenta
E14: Anticipo Financiero | H14: Otros Aportes
E15: Transferencias Corrientes | G15: =+'[4]INGR SEGUN ORIGEN'!E12 -> 1.0607056e+08 | H15: Aportes Nomina SNS
E16: Venta de Servicios | G16: =+'[4]INGR SEGUN ORIGEN'!E27+'[4]INGR SEGUN ORIGEN'!E34 -> 8172161.3
H17: TOTAL INGRESOS RDS | I17: =+G10+G11+G12+I10+G14+G15+G16+I14+I15 -> 1.144518e+08
A21: 1 | F21: 2 | G21: 3 | I21: 4 | J21: 5
A22: Código Presupuestario | F22: Descripción Gasto por Cuenta | G22: Distribución del Gasto por Fuente de Financiamiento | I22: TOTAL | J22: %
A23: Tipo | B23: Objeto | C23: Cuenta | D23: Sub-Cuenta | E23: Auxiliar | G23: Fondo 100 | H23: Venta de Servicios/ Otros Aportes
A25: 2 | F25: Gastos | G25: =+G26+G87+G212+G330+G336+G463 -> 1.0911345e+08 | H25: =+H26+H87+H212+H330+H336+H463 -> 8161061 | I25: =SUM(G25:H25) -> 1.1727451e+08 | J25: =+J26+J87+J212+J330+J336+J463 -> 1
A26: 2 | B26: 1 | F26: Servicios Personales | G26: =+G27+G51+G64+G71+G78 -> 72986847 | H26: =+H27+H51+H64+H71+H78 -> 0 | I26: =SUM(G26:H26) -> 72986847 | J26: =I26/$I$25 -> 0.62235902
A27: 2 | B27: 1 | C27: 1 | F27: Remuneraciones | G27: =+G28+G35+G42+G44+G46 -> 60398098 | H27: =+H28+H35+H42+H44+H46 -> 0 | I27: =SUM(G27:H27) -> 60398098
A28: 2 | B28: 1 | C28: 1 | D28: 1 | F28: Remuneraciones al personal fijo | G28: =SUM(G29:G34) -> 59105567 | H28: =SUM(H29:H34) -> 0 | I28: =SUM(G28:H28) -> 59105567
A29: 2 | B29: 1 | C29: 1 | D29: 1 | E29: 01 | F29: Sueldos a empleados fijos | G29: ='[4]CUENTA T FONDO 100'!A126 -> 59105567 | H29: ='[4]CUENTA T VS'!A75 -> 0 | I29: =SUM(G29:H29) -> 59105567 | J29: =I29/$I$25 -> 0.50399331
A30: 2 | B30: 1 | C30: 1 | D30: 1 | E30: 02 | F30: Sueldos a médicos | G30: ='[4]CUENTA T FONDO 100'!B126 -> 0 | H30: ='[4]CUENTA T VS'!B75 -> 0 | I30: =SUM(G30:H30) -> 0 | J30: =I30/$I$25 -> 0
A31: 2 | B31: 1 | C31: 1 | D31: 1 | E31: 03 | F31: Ascensos a militares | G31: ='[4]CUENTA T FONDO 100'!C126 -> 0 | H31: ='[4]CUENTA T VS'!C75 -> 0 | I31: =SUM(G31:H31) -> 0 | J31: =I31/$I$25 -> 0
A32: 2 | B32: 1 | C32: 1 | D32: 1 | E32: 04 | F32: Nuevas plazas maestros | G32: ='[4]CUENTA T FONDO 100'!D126 -> 0 | H32: ='[4]CUENTA T VS'!D75 -> 0 | I32: =SUM(G32:H32) -> 0 | J32: =I32/$I$25 -> 0
A33: 2 | B33: 1 | C33: 1 | D33: 1 | E33: 05 | F33: Incentivos y escalafón | G33: ='[4]CUENTA T FONDO 100'!E126 -> 0 | H33: ='[4]CUENTA T VS'!E75 -> 0 | I33: =SUM(G33:H33) -> 0 | J33: =I33/$I$25 -> 0
A34: 2 | B34: 1 | C34: 1 | D34: 1 | E34: 06 | F34: Nuevas plazas a médicos | G34: ='[4]CUENTA T FONDO 100'!F126 -> 0 | H34: ='[4]CUENTA T VS'!F75 -> 0 | I34: =SUM(G34:H34) -> 0 | J34: =I34/$I$25 -> 0
A35: 2 | B35: 1 | C35: 1 | D35: 2 | F35: Remuneraciones al personal con carácter transitorio | G35: =SUM(G36:G41) -> 1292531 | H35: =SUM(H36:H41) -> 0 | I35: =SUM(G35:H35) -> 1292531
A36: 2 | B36: 1 | C36: 1 | D36: 2 | E36: 03 | F36: Suplencias | G36: ='[4]CUENTA T FONDO 100'!G126 -> 0 | H36: ='[4]CUENTA T VS'!G75 -> 0 | I36: =SUM(G36:H36) -> 0 | J36: =I36/$I$25 -> 0
A37: 2 | B37: 1 | C37: 1 | D37: 2 | E37: 05 | F37: Sueldo al personal nominal en período probatorio | G37: ='[4]CUENTA T FONDO 100'!H126 -> 0 | H37: ='[4]CUENTA T VS'!H75 -> 0 | I37: =SUM(G37:H37) -> 0 | J37: =I37/$I$25 -> 0
A38: 2 | B38: 1 | C38: 1 | D38: 2 | E38: 06 | F38: Jornales | G38: ='[4]CUENTA T FONDO 100'!I126 -> 0 | H38: ='[4]CUENTA T VS'!I75 -> 0 | I38: =SUM(G38:H38) -> 0 | J38: =I38/$I$25 -> 0
A39: 2 | B39: 1 | C39: 1 | D39: 2 | E39: 08 | F39: Empleados temporales | G39: ='[4]CUENTA T FONDO 100'!J126 -> 1292531 | H39: ='[4]CUENTA T VS'!J75 -> 0 | I39: =SUM(G39:H39) -> 1292531 | J39: =I39/$I$25 -> 0.011021415
A40: 2 | B40: 1 | C40: 1 | D40: 2 | E40: 09 | F40: Personal de carácter eventual | G40: ='[4]CUENTA T FONDO 100'!K126 -> 0 | H40: ='[4]CUENTA T VS'!K75 -> 0 | I40: =SUM(G40:H40) -> 0 | J40: =I40/$I$25 -> 0
A41: 2 | B41: 1 | C41: 1 | D41: 2 | E41: 11 | F41: Interinato | G41: ='[4]CUENTA T FONDO 100'!L126 -> 0 | H41: ='[4]CUENTA T VS'!L75 -> 0 | I41: =SUM(G41:H41) -> 0 | J41: =I41/$I$25 -> 0
A42: 2 | B42: 1 | C42: 1 | D42: 3 | F42: Sueldos al personal fijo en trámite de pensiones | G42: =SUM(G43) -> 0 | H42: =SUM(H43) -> 0 | I42: =SUM(G42:H42) -> 0
A43: 2 | B43: 1 | C43: 1 | D43: 3 | E43: 01 | F43: Sueldos al personal fijo en trámite de pensiones | G43: ='[4]CUENTA T FONDO 100'!M126 -> 0 | H43: ='[4]CUENTA T VS'!M75 -> 0 | I43: =SUM(G43:H43) -> 0 | J43: =I43/$I$25 -> 0
A44: 2 | B44: 1 | C44: 1 | D44: 4 | F44: Sueldo anual no. 13 | G44: =SUM(G45) -> 0 | H44: =SUM(H45) -> 0 | I44: =SUM(G44:H44) -> 0
A45: 2 | B45: 1 | C45: 1 | D45: 4 | E45: 01 | F45: Sueldo anual no. 13 | G45: ='[4]CUENTA T FONDO 100'!N126 -> 0 | H45: ='[4]CUENTA T VS'!N75 -> 0 | I45: =SUM(G45:H45) -> 0 | J45: =I45/$I$25 -> 0
...

Sheet NOVIEMBRE
A1: Form. No.6 SRS
A3: Servicio Nacional de Salud
A4: Dirección de Fizcalización
A5: Consolidado de Ingresos y Gastos por Fuente de Financiamiento
A6: HOSPITAL MATERNO INFANTIL SAN LORENZO DE LOS MINA
A7: OCTUBRE 2025
C8: Ingresos Generales:
E9: 1.- Balance Inicial / Fuente:
E10: Anticipo Financiero | H10: Otros Aportes | L10: Contraseña: 0001
E11: Transferencias Corrientes
E12: Venta de Servicios | G12: 5363379
E13: 2.- Ingresos por Fuente / Cuenta
E14: Anticipo Financiero | H14: Otros Aportes | L14: OBJETAL | M14: FR | N14: VS
E15: Transferencias Corrientes | G15: =+'[7]INGR SEGUN ORIGEN'!E12 -> 1.5626822e+08 | H15: Aportes Nomina SNS | L15: 2.1 | M15: =G26 -> 1.3374081e+08 | N15: =H26 -> 0
E16: Venta de Servicios | G16: =+'[7]INGR SEGUN ORIGEN'!E35+'[7]INGR SEGUN ORIGEN'!E42 -> 9309369.1 | L16: 2.2 | M16: =G87 -> 1896797.1 | N16: =H87 -> 2083820.5
H17: TOTAL INGRESOS RDS | I17: =+G10+G11+G12+I10+G14+G15+G16+I14+I15 -> 1.7094097e+08 | L17: 2.3 | M17: ='[7]CONS. FUENTES FINAN'!G212 -> 13779851 | N17: ='[7]CONS. FUENTES FINAN'!H212 -> 2184325.9
L18: 2.4 | M18: =G330 -> 0 | N18: =H330 -> 3600
L19: 2.6 | M19: =G336 -> 8010447.3 | N19: =H336 -> 2755244.7
L20: 2.7 | M20: ='[7]CONS. FUENTES FINAN'!G463 -> 0 | N20: ='[7]CONS. FUENTES FINAN'!H463 -> 0
A21: 1 | F21: 2 | G21: 3 | I21: 4 | J21: 5
A22: Código Presupuestario | F22: Descripción Gasto por Cuenta | G22: Distribución del Gasto por Fuente de Financiamiento | I22: TOTAL | J22: %
A23: Tipo | B23: Objeto | C23: Cuenta | D23: Sub-Cuenta | E23: Auxiliar | G23: Fondo 100 | H23: Venta de Servicios/ Otros Aportes
A25: 2 | F25: Gastos | G25: =+G26+G87+G212+G330+G336+G463 -> 157427908 | H25: =+H26+H87+H212+H330+H336+H463 -> 7026991.1 | I25: =SUM(G25:H25) -> 1.644549e+08 | J25: =+J26+J87+J212+J330+J336+J463 -> 1
A26: 2 | B26: 1 | F26: Servicios Personales | G26: =+G27+G51+G64+G71+G78 -> 1.3374081e+08 | H26: =+H27+H51+H64+H71+H78 -> 0 | I26: =SUM(G26:H26) -> 1.3374081e+08 | J26: =I26/$I$25 -> 0.81323702
A27: 2 | B27: 1 | C27: 1 | F27: Remuneraciones | G27: =+G28+G35+G42+G44+G46 -> 1.2113301e+08 | H27: =+H28+H35+H42+H44+H46 -> 0 | I27: =SUM(G27:H27) -> 1.2113301e+08
A28: 2 | B28: 1 | C28: 1 | D28: 1 | F28: Remuneraciones al personal fijo | G28: =SUM(G29:G34) -> 59046800 | H28: =SUM(H29:H34) -> 0 | I28: =SUM(G28:H28) -> 59046800
A29: 2 | B29: 1 | C29: 1 | D29: 1 | E29: 01 | F29: Sueldos a empleados fijos | G29: ='[7]CUENTA T FONDO 100'!A97 -> 59046800 | H29: ='[7]CUENTA T VS'!A75 -> 0 | I29: =SUM(G29:H29) -> 59046800 | J29: =I29/$I$25 -> 0.35904555
A30: 2 | B30: 1 | C30: 1 | D30: 1 | E30: 02 | F30: Sueldos a médicos | G30: ='[7]CUENTA T FONDO 100'!B97 -> 0 | H30: ='[7]CUENTA T VS'!B75 -> 0 | I30: =SUM(G30:H30) -> 0 | J30: =I30/$I$25 -> 0
A31: 2 | B31: 1 | C31: 1 | D31: 1 | E31: 03 | F31: Ascensos a militares | G31: ='[7]CUENTA T FONDO 100'!C97 -> 0 | H31: ='[7]CUENTA T VS'!C75 -> 0 | I31: =SUM(G31:H31) -> 0 | J31: =I31/$I$25 -> 0
A32: 2 | B32: 1 | C32: 1 | D32: 1 | E32: 04 | F32: Nuevas plazas maestros | G32: ='[7]CUENTA T FONDO 100'!D97 -> 0 | H32: ='[7]CUENTA T VS'!D75 -> 0 | I32: =SUM(G32:H32) -> 0 | J32: =I32/$I$25 -> 0
A33: 2 | B33: 1 | C33: 1 | D33: 1 | E33: 05 | F33: Incentivos y escalafón | G33: ='[7]CUENTA T FONDO 100'!E97 -> 0 | H33: ='[7]CUENTA T VS'!E75 -> 0 | I33: =SUM(G33:H33) -> 0 | J33: =I33/$I$25 -> 0
A34: 2 | B34: 1 | C34: 1 | D34: 1 | E34: 06 | F34: Nuevas plazas a médicos | G34: ='[7]CUENTA T FONDO 100'!F97 -> 0 | H34: ='[7]CUENTA T VS'!F75 -> 0 | I34: =SUM(G34:H34) -> 0 | J34: =I34/$I$25 -> 0
A35: 2 | B35: 1 | C35: 1 | D35: 2 | F35: Remuneraciones al personal con carácter transitorio | G35: =SUM(G36:G41) -> 1342531 | H35: =SUM(H36:H41) -> 0 | I35: =SUM(G35:H35) -> 1342531
A36: 2 | B36: 1 | C36: 1 | D36: 2 | E36: 03 | F36: Suplencias | G36: ='[7]CUENTA T FONDO 100'!G97 -> 0 | H36: ='[7]CUENTA T VS'!G75 -> 0 | I36: =SUM(G36:H36) -> 0 | J36: =I36/$I$25 -> 0
A37: 2 | B37: 1 | C37: 1 | D37: 2 | E37: 05 | F37: Sueldo al personal nominal en período probatorio | G37: ='[7]CUENTA T FONDO 100'!H97 -> 0 | H37: ='[7]CUENTA T VS'!H75 -> 0 | I37: =SUM(G37:H37) -> 0 | J37: =I37/$I$25 -> 0
A38: 2 | B38: 1 | C38: 1 | D38: 2 | E38: 06 | F38: Jornales | G38: ='[7]CUENTA T FONDO 100'!I97 -> 0 | H38: ='[7]CUENTA T VS'!I75 -> 0 | I38: =SUM(G38:H38) -> 0 | J38: =I38/$I$25 -> 0
A39: 2 | B39: 1 | C39: 1 | D39: 2 | E39: 08 | F39: Empleados temporales | G39: ='[7]CUENTA T FONDO 100'!J97 -> 1342531 | H39: ='[7]CUENTA T VS'!J75 -> 0 | I39: =SUM(G39:H39) -> 1342531 | J39: =I39/$I$25 -> 0.008163521
A40: 2 | B40: 1 | C40: 1 | D40: 2 | E40: 09 | F40: Personal de carácter eventual | G40: ='[7]CUENTA T FONDO 100'!K97 -> 0 | H40: ='[7]CUENTA T VS'!K75 -> 0 | I40: =SUM(G40:H40) -> 0 | J40: =I40/$I$25 -> 0
A41: 2 | B41: 1 | C41: 1 | D41: 2 | E41: 11 | F41: Interinato | G41: ='[7]CUENTA T FONDO 100'!L97 -> 0 | H41: ='[7]CUENTA T VS'!L75 -> 0 | I41: =SUM(G41:H41) -> 0 | J41: =I41/$I$25 -> 0
A42: 2 | B42: 1 | C42: 1 | D42: 3 | F42: Sueldos al personal fijo en trámite de pensiones | G42: =SUM(G43) -> 0 | H42: =SUM(H43) -> 0 | I42: =SUM(G42:H42) -> 0
...

Sheet DICIEMBRE 2025
A1: Form. No.6 SRS
A3: Servicio Nacional de Salud
A4: Dirección de Fizcalización
A5: Consolidado de Ingresos y Gastos por Fuente de Financiamiento
A6: HOSPITAL MATERNO INFANTIL SAN LORENZO DE LOS MINA
A7: DICIEMBRE 2025
C8: Ingresos Generales:
E9: 1.- Balance Inicial / Fuente:
E10: Anticipo Financiero | H10: Otros Aportes | L10: Contraseña: 0001
E11: Transferencias Corrientes
E12: Venta de Servicios | G12: 2685939.8
E13: 2.- Ingresos por Fuente / Cuenta
E14: Anticipo Financiero | H14: Otros Aportes | L14: OBJETAL | M14: FR | N14: VS
E15: Transferencias Corrientes | G15: =+'[8]INGR SEGUN ORIGEN'!E12 -> 1.2257458e+08 | H15: Aportes Nomina SNS | L15: 2.1 | M15: =G26 -> 81717721 | N15: =H26 -> 0
E16: Venta de Servicios | G16: =+'[8]INGR SEGUN ORIGEN'!E26+'[8]INGR SEGUN ORIGEN'!E33 -> 16833212 | L16: 2.2 | M16: =G87 -> 13617256 | N16: =H87 -> 7601154.9
H17: TOTAL INGRESOS RDS | I17: =+G10+G11+G12+I10+G14+G15+G16+I14+I15 -> 1.4209373e+08 | L17: 2.3 | M17: ='[8]CONS. FUENTES FINAN'!G212 -> 71708916 | N17: ='[8]CONS. FUENTES FINAN'!H212 -> 11135613
L18: 2.4 | M18: =G330 -> 0 | N18: =H330 -> 16000
L19: 2.6 | M19: =G336 -> 17995006 | N19: =H336 -> 4350775.5
L20: 2.7 | M20: ='[8]CONS. FUENTES FINAN'!G463 -> 0 | N20: ='[8]CONS. FUENTES FINAN'!H463 -> 0
A21: 1 | F21: 2 | G21: 3 | I21: 4 | J21: 5
A22: Código Presupuestario | F22: Descripción Gasto por Cuenta | G22: Distribución del Gasto por Fuente de Financiamiento | I22: TOTAL | J22: %
A23: Tipo | B23: Objeto | C23: Cuenta | D23: Sub-Cuenta | E23: Auxiliar | G23: Fondo 100 | H23: Venta de Servicios/ Otros Aportes
A25: 2 | F25: Gastos | G25: =+G26+G87+G212+G330+G336+G463 -> 1.850389e+08 | H25: =+H26+H87+H212+H330+H336+H463 -> 23103544 | I25: =SUM(G25:H25) -> 2.0814244e+08 | J25: =+J26+J87+J212+J330+J336+J463 -> 1
A26: 2 | B26: 1 | F26: Servicios Personales | G26: =+G27+G51+G64+G71+G78 -> 81717721 | H26: =+H27+H51+H64+H71+H78 -> 0 | I26: =SUM(G26:H26) -> 81717721 | J26: =I26/$I$25 -> 0.39260479
A27: 2 | B27: 1 | C27: 1 | F27: Remuneraciones | G27: =+G28+G35+G42+G44+G46 -> 61417331 | H27: =+H28+H35+H42+H44+H46 -> 0 | I27: =SUM(G27:H27) -> 61417331
A28: 2 | B28: 1 | C28: 1 | D28: 1 | F28: Remuneraciones al personal fijo | G28: =SUM(G29:G34) -> 59174005 | H28: =SUM(H29:H34) -> 0 | I28: =SUM(G28:H28) -> 59174005
A29: 2 | B29: 1 | C29: 1 | D29: 1 | E29: 01 | F29: Sueldos a empleados fijos | G29: ='[8]CUENTA T FONDO 100'!A210 -> 59174005 | H29: ='[8]CUENTA T VS'!A498 -> 0 | I29: =SUM(G29:H29) -> 59174005 | J29: =I29/$I$25 -> 0.28429572
A30: 2 | B30: 1 | C30: 1 | D30: 1 | E30: 02 | F30: Sueldos a médicos | G30: ='[8]CUENTA T FONDO 100'!B210 -> 0 | H30: ='[8]CUENTA T VS'!B498 -> 0 | I30: =SUM(G30:H30) -> 0 | J30: =I30/$I$25 -> 0
A31: 2 | B31: 1 | C31: 1 | D31: 1 | E31: 03 | F31: Ascensos a militares | G31: ='[8]CUENTA T FONDO 100'!C210 -> 0 | H31: ='[8]CUENTA T VS'!C498 -> 0 | I31: =SUM(G31:H31) -> 0 | J31: =I31/$I$25 -> 0
A32: 2 | B32: 1 | C32: 1 | D32: 1 | E32: 04 | F32: Nuevas plazas maestros | G32: ='[8]CUENTA T FONDO 100'!D210 -> 0 | H32: ='[8]CUENTA T VS'!D498 -> 0 | I32: =SUM(G32:H32) -> 0 | J32: =I32/$I$25 -> 0
A33: 2 | B33: 1 | C33: 1 | D33: 1 | E33: 05 | F33: Incentivos y escalafón | G33: ='[8]CUENTA T FONDO 100'!E210 -> 0 | H33: ='[8]CUENTA T VS'!E498 -> 0 | I33: =SUM(G33:H33) -> 0 | J33: =I33/$I$25 -> 0
A34: 2 | B34: 1 | C34: 1 | D34: 1 | E34: 06 | F34: Nuevas plazas a médicos | G34: ='[8]CUENTA T FONDO 100'!F210 -> 0 | H34: ='[8]CUENTA T VS'!F498 -> 0 | I34: =SUM(G34:H34) -> 0 | J34: =I34/$I$25 -> 0
A35: 2 | B35: 1 | C35: 1 | D35: 2 | F35: Remuneraciones al personal con carácter transitorio | G35: =SUM(G36:G41) -> 1342531 | H35: =SUM(H36:H41) -> 0 | I35: =SUM(G35:H35) -> 1342531
A36: 2 | B36: 1 | C36: 1 | D36: 2 | E36: 03 | F36: Suplencias | G36: ='[8]CUENTA T FONDO 100'!G210 -> 0 | H36: ='[8]CUENTA T VS'!G498 -> 0 | I36: =SUM(G36:H36) -> 0 | J36: =I36/$I$25 -> 0
A37: 2 | B37: 1 | C37: 1 | D37: 2 | E37: 05 | F37: Sueldo al personal nominal en período probatorio | G37: ='[8]CUENTA T FONDO 100'!H210 -> 0 | H37: ='[8]CUENTA T VS'!H498 -> 0 | I37: =SUM(G37:H37) -> 0 | J37: =I37/$I$25 -> 0
A38: 2 | B38: 1 | C38: 1 | D38: 2 | E38: 06 | F38: Jornales | G38: ='[8]CUENTA T FONDO 100'!I210 -> 0 | H38: ='[8]CUENTA T VS'!I498 -> 0 | I38: =SUM(G38:H38) -> 0 | J38: =I38/$I$25 -> 0
A39: 2 | B39: 1 | C39: 1 | D39: 2 | E39: 08 | F39: Empleados temporales | G39: ='[8]CUENTA T FONDO 100'!J210 -> 1342531 | H39: ='[8]CUENTA T VS'!J498 -> 0 | I39: =SUM(G39:H39) -> 1342531 | J39: =I39/$I$25 -> 0.006450059
A40: 2 | B40: 1 | C40: 1 | D40: 2 | E40: 09 | F40: Personal de carácter eventual | G40: ='[8]CUENTA T FONDO 100'!K210 -> 0 | H40: ='[8]CUENTA T VS'!K498 -> 0 | I40: =SUM(G40:H40) -> 0 | J40: =I40/$I$25 -> 0
A41: 2 | B41: 1 | C41: 1 | D41: 2 | E41: 11 | F41: Interinato | G41: ='[8]CUENTA T FONDO 100'!L210 -> 0 | H41: ='[8]CUENTA T VS'!L498 -> 0 | I41: =SUM(G41:H41) -> 0 | J41: =I41/$I$25 -> 0
A42: 2 | B42: 1 | C42: 1 | D42: 3 | F42: Sueldos al personal fijo en trámite de pensiones | G42: =SUM(G43) -> 0 | H42: =SUM(H43) -> 0 | I42: =SUM(G42:H42) -> 0
...

Sheet RESUMEN TRIMESTRE OCTUBRE-DIC
A1: Form. No.6 SRS
A3: Servicio Nacional de Salud
A4: Dirección de Fizcalización
A5: Consolidado de Ingresos y Gastos por Fuente de Financiamiento
A6: HOSPITAL MATERNO INFANTIL SAN LORENZO DE LOS MINA
A7: OCTUBRE-DICIEMBRE 2025
C8: Ingresos Generales:
E9: 1.- Balance Inicial / Fuente:
E10: Anticipo Financiero | H10: Otros Aportes | L10: Contraseña: 0001
E11: Transferencias Corrientes
E12: Venta de Servicios | G12: 2685939.8
E13: 2.- Ingresos por Fuente / Cuenta
E14: Anticipo Financiero | H14: Otros Aportes | L14: OBJETAL | M14: FR | N14: VS
E15: Transferencias Corrientes | G15: =+'[8]INGR SEGUN ORIGEN'!E12 -> 1.2257458e+08 | H15: Aportes Nomina SNS | L15: 2.1 | M15: =G26 -> 2.8844538e+08 | N15: =H26 -> 0
E16: Venta de Servicios | G16: =+'[8]INGR SEGUN ORIGEN'!E26+'[8]INGR SEGUN ORIGEN'!E33 -> 16833212 | L16: 2.2 | M16: =G87 -> 16306952 | N16: =H87 -> 11649817
H17: TOTAL INGRESOS RDS | I17: =+G10+G11+G12+I10+G14+G15+G16+I14+I15 -> 1.4209373e+08 | L17: 2.3 | M17: ='[8]CONS. FUENTES FINAN'!G212 -> 71708916 | N17: ='[8]CONS. FUENTES FINAN'!H212 -> 11135613
L18: 2.4 | M18: =G330 -> 0 | N18: =H330 -> 19600
L19: 2.6 | M19: =G336 -> 29442717 | N19: =H336 -> 7416727.6
L20: 2.7 | M20: ='[8]CONS. FUENTES FINAN'!G463 -> 0 | N20: ='[8]CONS. FUENTES FINAN'!H463 -> 0
A21: 1 | F21: 2 | G21: 3 | I21: 4 | J21: 5
A22: Código Presupuestario | F22: Descripción Gasto por Cuenta | G22: Distribución del Gasto por Fuente de Financiamiento | I22: TOTAL | J22: %
A23: Tipo | B23: Objeto | C23: Cuenta | D23: Sub-Cuenta | E23: Auxiliar | G23: Fondo 100 | H23: Venta de Servicios/ Otros Aportes
A25: 2 | F25: Gastos | G25: =+'OCTUBRE '!G25+NOVIEMBRE!G25+'DICIEMBRE 2025'!G25 -> 4.5158025e+08 | H25: =+'OCTUBRE '!H25+NOVIEMBRE!H25+'DICIEMBRE 2025'!H25 -> 38291596 | I25: =SUM(G25:H25) -> 4.8987185e+08 | J25: =+J26+J87+J212+J330+J336+J463 -> 1
A26: 2 | B26: 1 | F26: Servicios Personales | G26: =+'OCTUBRE '!G26+NOVIEMBRE!G26+'DICIEMBRE 2025'!G26 -> 2.8844538e+08 | H26: =+'OCTUBRE '!H26+NOVIEMBRE!H26+'DICIEMBRE 2025'!H26 -> 0 | I26: =SUM(G26:H26) -> 2.8844538e+08 | J26: =I26/$I$25 -> 0.58881804
A27: 2 | B27: 1 | C27: 1 | F27: Remuneraciones | G27: =+'OCTUBRE '!G27+NOVIEMBRE!G27+'DICIEMBRE 2025'!G27 -> 2.4294844e+08 | H27: =+'OCTUBRE '!H27+NOVIEMBRE!H27+'DICIEMBRE 2025'!H27 -> 0 | I27: =SUM(G27:H27) -> 2.4294844e+08
A28: 2 | B28: 1 | C28: 1 | D28: 1 | F28: Remuneraciones al personal fijo | G28: =+'OCTUBRE '!G28+NOVIEMBRE!G28+'DICIEMBRE 2025'!G28 -> 1.7732637e+08 | H28: =+'OCTUBRE '!H28+NOVIEMBRE!H28+'DICIEMBRE 2025'!H28 -> 0 | I28: =SUM(G28:H28) -> 1.7732637e+08
A29: 2 | B29: 1 | C29: 1 | D29: 1 | E29: 01 | F29: Sueldos a empleados fijos | G29: =+'OCTUBRE '!G29+NOVIEMBRE!G29+'DICIEMBRE 2025'!G29 -> 1.7732637e+08 | H29: =+'OCTUBRE '!H29+NOVIEMBRE!H29+'DICIEMBRE 2025'!H29 -> 0 | I29: =SUM(G29:H29) -> 1.7732637e+08 | J29: =I29/$I$25 -> 0.36198523
A30: 2 | B30: 1 | C30: 1 | D30: 1 | E30: 02 | F30: Sueldos a médicos | G30: =+'OCTUBRE '!G30+NOVIEMBRE!G30+'DICIEMBRE 2025'!G30 -> 0 | H30: =+'OCTUBRE '!H30+NOVIEMBRE!H30+'DICIEMBRE 2025'!H30 -> 0 | I30: =SUM(G30:H30) -> 0 | J30: =I30/$I$25 -> 0
A31: 2 | B31: 1 | C31: 1 | D31: 1 | E31: 03 | F31: Ascensos a militares | G31: =+'OCTUBRE '!G31+NOVIEMBRE!G31+'DICIEMBRE 2025'!G31 -> 0 | H31: =+'OCTUBRE '!H31+NOVIEMBRE!H31+'DICIEMBRE 2025'!H31 -> 0 | I31: =SUM(G31:H31) -> 0 | J31: =I31/$I$25 -> 0
A32: 2 | B32: 1 | C32: 1 | D32: 1 | E32: 04 | F32: Nuevas plazas maestros | G32: =+'OCTUBRE '!G32+NOVIEMBRE!G32+'DICIEMBRE 2025'!G32 -> 0 | H32: =+'OCTUBRE '!H32+NOVIEMBRE!H32+'DICIEMBRE 2025'!H32 -> 0 | I32: =SUM(G32:H32) -> 0 | J32: =I32/$I$25 -> 0
A33: 2 | B33: 1 | C33: 1 | D33: 1 | E33: 05 | F33: Incentivos y escalafón | G33: =+'OCTUBRE '!G33+NOVIEMBRE!G33+'DICIEMBRE 2025'!G33 -> 0 | H33: =+'OCTUBRE '!H33+NOVIEMBRE!H33+'DICIEMBRE 2025'!H33 -> 0 | I33: =SUM(G33:H33) -> 0 | J33: =I33/$I$25 -> 0
A34: 2 | B34: 1 | C34: 1 | D34: 1 | E34: 06 | F34: Nuevas plazas a médicos | G34: =+'OCTUBRE '!G34+NOVIEMBRE!G34+'DICIEMBRE 2025'!G34 -> 0 | H34: =+'OCTUBRE '!H34+NOVIEMBRE!H34+'DICIEMBRE 2025'!H34 -> 0 | I34: =SUM(G34:H34) -> 0 | J34: =I34/$I$25 -> 0
A35: 2 | B35: 1 | C35: 1 | D35: 2 | F35: Remuneraciones al personal con carácter transitorio | G35: =+'OCTUBRE '!G35+NOVIEMBRE!G35+'DICIEMBRE 2025'!G35 -> 3977593.1 | H35: =+'OCTUBRE '!H35+NOVIEMBRE!H35+'DICIEMBRE 2025'!H35 -> 0 | I35: =SUM(G35:H35) -> 3977593.1
A36: 2 | B36: 1 | C36: 1 | D36: 2 | E36: 03 | F36: Suplencias | G36: =+'OCTUBRE '!G36+NOVIEMBRE!G36+'DICIEMBRE 2025'!G36 -> 0 | H36: =+'OCTUBRE '!H36+NOVIEMBRE!H36+'DICIEMBRE 2025'!H36 -> 0 | I36: =SUM(G36:H36) -> 0 | J36: =I36/$I$25 -> 0
A37: 2 | B37: 1 | C37: 1 | D37: 2 | E37: 05 | F37: Sueldo al personal nominal en período probatorio | G37: =+'OCTUBRE '!G37+NOVIEMBRE!G37+'DICIEMBRE 2025'!G37 -> 0 | H37: =+'OCTUBRE '!H37+NOVIEMBRE!H37+'DICIEMBRE 2025'!H37 -> 0 | I37: =SUM(G37:H37) -> 0 | J37: =I37/$I$25 -> 0
A38: 2 | B38: 1 | C38: 1 | D38: 2 | E38: 06 | F38: Jornales | G38: =+'OCTUBRE '!G38+NOVIEMBRE!G38+'DICIEMBRE 2025'!G38 -> 0 | H38: =+'OCTUBRE '!H38+NOVIEMBRE!H38+'DICIEMBRE 2025'!H38 -> 0 | I38: =SUM(G38:H38) -> 0 | J38: =I38/$I$25 -> 0
A39: 2 | B39: 1 | C39: 1 | D39: 2 | E39: 08 | F39: Empleados temporales | G39: =+'OCTUBRE '!G39+NOVIEMBRE!G39+'DICIEMBRE 2025'!G39 -> 3977593.1 | H39: =+'OCTUBRE '!H39+NOVIEMBRE!H39+'DICIEMBRE 2025'!H39 -> 0 | I39: =SUM(G39:H39) -> 3977593.1 | J39: =I39/$I$25 -> 0.0081196605
A40: 2 | B40: 1 | C40: 1 | D40: 2 | E40: 09 | F40: Personal de carácter eventual | G40: =+'OCTUBRE '!G40+NOVIEMBRE!G40+'DICIEMBRE 2025'!G40 -> 0 | H40: =+'OCTUBRE '!H40+NOVIEMBRE!H40+'DICIEMBRE 2025'!H40 -> 0 | I40: =SUM(G40:H40) -> 0 | J40: =I40/$I$25 -> 0
A41: 2 | B41: 1 | C41: 1 | D41: 2 | E41: 11 | F41: Interinato | G41: =+'OCTUBRE '!G41+NOVIEMBRE!G41+'DICIEMBRE 2025'!G41 -> 0 | H41: =+'OCTUBRE '!H41+NOVIEMBRE!H41+'DICIEMBRE 2025'!H41 -> 0 | I41: =SUM(G41:H41) -> 0 | J41: =I41/$I$25 -> 0
A42: 2 | B42: 1 | C42: 1 | D42: 3 | F42: Sueldos al personal fijo en trámite de pensiones | G42: =+'OCTUBRE '!G42+NOVIEMBRE!G42+'DICIEMBRE 2025'!G42 -> 0 | H42: =+'OCTUBRE '!H42+NOVIEMBRE!H42+'DICIEMBRE 2025'!H42 -> 0 | I42: =SUM(G42:H42) -> 0
...

Sheet ENERO-JUNIO 2025
A1: Form. No.6 SRS
A3: Servicio Nacional de Salud
A4: Dirección de Fizcalización
A5: Consolidado de Ingresos y Gastos por Fuente de Financiamiento
A6: HOSPITAL MATERNO INFANTIL SAN LORENZO DE LOS MINA
A7: ENERO-JUNIO 2025
C8: Ingresos Generales:
E9: 1.- Balance Inicial / Fuente:
E10: Anticipo Financiero | G10: 0 | H10: Otros Aportes
E11: Transferencias Corrientes | G11: 0
E12: Venta de Servicios
E13: 2.- Ingresos por Fuente / Cuenta
E14: Anticipo Financiero | H14: Otros Aportes
E15: Transferencias Corrientes | H15: Aportes Nomina SNS
E16: Venta de Servicios
H17: TOTAL INGRESOS RDS | J17: =+G10+G11+G12+J10+G14+G15+G16+J14+J15 -> 0
A21: 1 | F21: 2 | G21: 3 | J21: 4 | K21: 5
A22: Código Presupuestario | F22: Descripción Gasto por Cuenta | G22: Distribución del Gasto por Fuente de Financiamiento | J22: TOTAL | K22: %
A23: Tipo | B23: Objeto | C23: Cuenta | D23: Sub-Cuenta | E23: Auxiliar | G23: Fondo 100 | H23: Venta de Servicios/ Otros Aportes | I23: Aportes Nomina SNS
A25: 2 | F25: Gastos | G25: =+G26+G87+G212+G330+G336+G463 -> 5.4471224e+08 | H25: =+'[5]junio 2025'!H25+'[5]mayo 2025'!H25+[5]abril!H25+[5]marzo!H25+[5]febrero!H25+'[5]enero '!H25 -> 46624960 | I25: =+I26+I87+I212+I330+I336+I463 -> 0 | J25: =SUM(G25:I25) -> 5.913372e+08 | K25: =+K26+K87+K212+K330+K336+K463 -> 1
A26: 2 | B26: 1 | F26: Servicios Personales | G26: =+G27+G51+G64+G71+G78 -> 3.9833106e+08 | H26: =+'[5]junio 2025'!H26+'[5]mayo 2025'!H26+[5]abril!H26+[5]marzo!H26+[5]febrero!H26+'[5]enero '!H26 -> 5231553.6 | I26: =+I27+I51+I64+I71+I78 -> 0 | J26: =SUM(G26:I26) -> 4.0356261e+08 | K26: =J26/$J$25 -> 0.68245767
A27: 2 | B27: 1 | C27: 1 | F27: Remuneraciones | G27: =+G28+G35+G42+G44+G46 -> 3.2802999e+08 | H27: =+'[5]junio 2025'!H27+'[5]mayo 2025'!H27+[5]abril!H27+[5]marzo!H27+[5]febrero!H27+'[5]enero '!H27 -> 0 | I27: =+I28+I35+I42+I44+I46 -> 0 | J27: =SUM(G27:I27) -> 3.2802999e+08 | K27: =J27/$J$25 -> 0.55472577
A28: 2 | B28: 1 | C28: 1 | D28: 1 | F28: Remuneraciones al personal fijo | G28: =SUM(G29:G34) -> 3.1950747e+08 | H28: =+'[5]junio 2025'!H28+'[5]mayo 2025'!H28+[5]abril!H28+[5]marzo!H28+[5]febrero!H28+'[5]enero '!H28 -> 0 | I28: =SUM(I29:I34) -> 0 | J28: =SUM(G28:I28) -> 3.1950747e+08 | K28: =J28/$J$25 -> 0.54031349
A29: 2 | B29: 1 | C29: 1 | D29: 1 | E29: 01 | F29: Sueldos a empleados fijos | G29: 3.1950747e+08 | H29: =+'[5]junio 2025'!H29+'[5]mayo 2025'!H29+[5]abril!H29+[5]marzo!H29+[5]febrero!H29+'[5]enero '!H29 -> 0 | I29: ='[6]CUENTA T NOMINA SNS'!A58 -> 0 | J29: =SUM(G29:I29) -> 3.1950747e+08 | K29: =J29/$J$25 -> 0.54031349
A30: 2 | B30: 1 | C30: 1 | D30: 1 | E30: 02 | F30: Sueldos a médicos | G30: ='[6]CUENTA T FONDO 100'!B288 -> 0 | H30: =+'[5]junio 2025'!H30+'[5]mayo 2025'!H30+[5]abril!H30+[5]marzo!H30+[5]febrero!H30+'[5]enero '!H30 -> 0 | I30: ='[6]CUENTA T NOMINA SNS'!B58 -> 0 | J30: =SUM(G30:I30) -> 0 | K30: =J30/$J$25 -> 0
A31: 2 | B31: 1 | C31: 1 | D31: 1 | E31: 03 | F31: Ascensos a militares | G31: ='[6]CUENTA T FONDO 100'!C288 -> 0 | H31: =+'[5]junio 2025'!H31+'[5]mayo 2025'!H31+[5]abril!H31+[5]marzo!H31+[5]febrero!H31+'[5]enero '!H31 -> 0 | I31: ='[6]CUENTA T NOMINA SNS'!C58 -> 0 | J31: =SUM(G31:I31) -> 0 | K31: =J31/$J$25 -> 0
A32: 2 | B32: 1 | C32: 1 | D32: 1 | E32: 04 | F32: Nuevas plazas maestros | G32: ='[6]CUENTA T FONDO 100'!D288 -> 0 | H32: =+'[5]junio 2025'!H32+'[5]mayo 2025'!H32+[5]abril!H32+[5]marzo!H32+[5]febrero!H32+'[5]enero '!H32 -> 0 | I32: ='[6]CUENTA T NOMINA SNS'!D58 -> 0 | J32: =SUM(G32:I32) -> 0 | K32: =J32/$J$25 -> 0
A33: 2 | B33: 1 | C33: 1 | D33: 1 | E33: 05 | F33: Incentivos y escalafón | G33: ='[6]CUENTA T FONDO 100'!E288 -> 0 | H33: =+'[5]junio 2025'!H33+'[5]mayo 2025'!H33+[5]abril!H33+[5]marzo!H33+[5]febrero!H33+'[5]enero '!H33 -> 0 | I33: ='[6]CUENTA T NOMINA SNS'!E58 -> 0 | J33: =SUM(G33:I33) -> 0 | K33: =J33/$J$25 -> 0
A34: 2 | B34: 1 | C34: 1 | D34: 1 | E34: 06 | F34: Nuevas plazas a médicos | G34: ='[6]CUENTA T FONDO 100'!F288 -> 0 | H34: =+'[5]junio 2025'!H34+'[5]mayo 2025'!H34+[5]abril!H34+[5]marzo!H34+[5]febrero!H34+'[5]enero '!H34 -> 0 | I34: ='[6]CUENTA T NOMINA SNS'!F58 -> 0 | J34: =SUM(G34:I34) -> 0 | K34: =J34/$J$25 -> 0
A35: 2 | B35: 1 | C35: 1 | D35: 2 | F35: Remuneraciones al personal con carácter transitorio | G35: =SUM(G36:G41) -> 6546186.2 | H35: =+'[5]junio 2025'!H35+'[5]mayo 2025'!H35+[5]abril!H35+[5]marzo!H35+[5]febrero!H35+'[5]enero '!H35 -> 0 | I35: =SUM(I36:I41) -> 0 | J35: =SUM(G35:I35) -> 6546186.2
A36: 2 | B36: 1 | C36: 1 | D36: 2 | E36: 03 | F36: Suplencias | G36: ='[6]CUENTA T FONDO 100'!G288 -> 0 | H36: =+'[5]junio 2025'!H36+'[5]mayo 2025'!H36+[5]abril!H36+[5]marzo!H36+[5]febrero!H36+'[5]enero '!H36 -> 0 | I36: ='[6]CUENTA T NOMINA SNS'!G58 -> 0 | J36: =SUM(G36:I36) -> 0 | K36: =J36/$J$25 -> 0
A37: 2 | B37: 1 | C37: 1 | D37: 2 | E37: 05 | F37: Sueldo al personal nominal en período probatorio | G37: ='[6]CUENTA T FONDO 100'!H288 -> 0 | H37: =+'[5]junio 2025'!H37+'[5]mayo 2025'!H37+[5]abril!H37+[5]marzo!H37+[5]febrero!H37+'[5]enero '!H37 -> 0 | I37: ='[6]CUENTA T NOMINA SNS'!H58 -> 0 | J37: =SUM(G37:I37) -> 0 | K37: =J37/$J$25 -> 0
A38: 2 | B38: 1 | C38: 1 | D38: 2 | E38: 06 | F38: Jornales | G38: ='[6]CUENTA T FONDO 100'!I288 -> 0 | H38: =+'[5]junio 2025'!H38+'[5]mayo 2025'!H38+[5]abril!H38+[5]marzo!H38+[5]febrero!H38+'[5]enero '!H38 -> 0 | I38: ='[6]CUENTA T NOMINA SNS'!I58 -> 0 | J38: =SUM(G38:I38) -> 0 | K38: =J38/$J$25 -> 0
A39: 2 | B39: 1 | C39: 1 | D39: 2 | E39: 08 | F39: Empleados temporales | G39: 6546186.2 | H39: =+'[5]junio 2025'!H39+'[5]mayo 2025'!H39+[5]abril!H39+[5]marzo!H39+[5]febrero!H39+'[5]enero '!H39 -> 0 | I39: ='[6]CUENTA T NOMINA SNS'!J58 -> 0 | J39: =SUM(G39:I39) -> 6546186.2 | K39: =J39/$J$25 -> 0.011070141
A40: 2 | B40: 1 | C40: 1 | D40: 2 | E40: 09 | F40: Personal de carácter eventual | G40: ='[6]CUENTA T FONDO 100'!K288 -> 0 | H40: =+'[5]junio 2025'!H40+'[5]mayo 2025'!H40+[5]abril!H40+[5]marzo!H40+[5]febrero!H40+'[5]enero '!H40 -> 0 | I40: ='[6]CUENTA T NOMINA SNS'!K58 -> 0 | J40: =SUM(G40:I40) -> 0 | K40: =J40/$J$25 -> 0
A41: 2 | B41: 1 | C41: 1 | D41: 2 | E41: 11 | F41: Interinato | G41: ='[6]CUENTA T FONDO 100'!L288 -> 0 | H41: =+'[5]junio 2025'!H41+'[5]mayo 2025'!H41+[5]abril!H41+[5]marzo!H41+[5]febrero!H41+'[5]enero '!H41 -> 0 | I41: ='[6]CUENTA T NOMINA SNS'!L58 -> 0 | J41: =SUM(G41:I41) -> 0 | K41: =J41/$J$25 -> 0
A42: 2 | B42: 1 | C42: 1 | D42: 3 | F42: Sueldos al personal fijo en trámite de pensiones | G42: =SUM(G43) -> 0 | H42: =+'[5]junio 2025'!H42+'[5]mayo 2025'!H42+[5]abril!H42+[5]marzo!H42+[5]febrero!H42+'[5]enero '!H42 -> 0 | I42: =SUM(I43) -> 0 | J42: =SUM(G42:I42) -> 0
A43: 2 | B43: 1 | C43: 1 | D43: 3 | E43: 01 | F43: Sueldos al personal fijo en trámite de pensiones | G43: ='[6]CUENTA T FONDO 100'!M288 -> 0 | H43: =+'[5]junio 2025'!H43+'[5]mayo 2025'!H43+[5]abril!H43+[5]marzo!H43+[5]febrero!H43+'[5]enero '!H43 -> 0 | I43: ='[6]CUENTA T NOMINA SNS'!M58 -> 0 | J43: =SUM(G43:I43) -> 0 | K43: =J43/$J$25 -> 0
A44: 2 | B44: 1 | C44: 1 | D44: 4 | F44: Sueldo anual no. 13 | G44: =SUM(G45) -> 0 | H44: =+'[5]junio 2025'!H44+'[5]mayo 2025'!H44+[5]abril!H44+[5]marzo!H44+[5]febrero!H44+'[5]enero '!H44 -> 0 | I44: =SUM(I45) -> 0 | J44: =SUM(G44:I44) -> 0
A45: 2 | B45: 1 | C45: 1 | D45: 4 | E45: 01 | F45: Sueldo anual no. 13 | G45: ='[6]CUENTA T FONDO 100'!N288 -> 0 | H45: =+'[5]junio 2025'!H45+'[5]mayo 2025'!H45+[5]abril!H45+[5]marzo!H45+[5]febrero!H45+'[5]enero '!H45 -> 0 | I45: ='[6]CUENTA T NOMINA SNS'!N58 -> 0 | J45: =SUM(G45:I45) -> 0 | K45: =J45/$J$25 -> 0
...
