Workbook
Name OLE_LINK1: 'NOTAS 7 AL19'!$A$8
Name OLE_LINK3: 'NOTAS 7 AL19'!#REF!
Name OLE_LINK4: 'NOTAS 7 AL19'!$A$19

Sheet Estado de Situación
A1: Hospital Materno Infantil San Lorenzo de los Mina
A2: Estado de Situación Financiera
A3: Del ejercicio terminado al 30 de abril 2025
A4: (Valores en RD$)
B6: 2025 | D6: 2021
A7: Activos
A8: Activos corrientes
A9: Efectivo y equivalente de efectivo (Notas 7) | B9: =+'NOTAS 7 AL19'!C12 -> 3.0392686e+08 | D9: =+'NOTAS 7 AL19'!#REF! -> #REF!
A10: Cuenta por cobrar a corto plazo (Notas 8) | B10: =+'NOTAS 7 AL19'!C24 -> 82148815 | D10: =+'NOTAS 7 AL19'!#REF! -> #REF!
A11: Inventarios (Nota 9) | B11: =+'NOTAS 7 AL19'!C32 -> 92426425 | D11: =+'NOTAS 7 AL19'!#REF! -> #REF!
A12: Total activos corrientes | B12: =SUM(B9:B11) -> 4.785021e+08 | D12: =SUM(D9:D11) -> #REF!
A14: Activos no corrientes
A15: Propiedad, planta y equipo neto (Nota 10) | B15: =+'NOTA 10'!I13 -> 1.6507226e+08 | D15: =3988531.33-566295.13 -> 3422236.2
A16: Total activos no corrientes | B16: =SUM(B15:B15) -> 1.6507226e+08 | D16: =SUM(D15:D15) -> 3422236.2
A18: Total activos | B18: =+B12+B16 -> 6.4357436e+08 | D18: =+D12+D16 -> #REF!
A19: Pasivos corrientes
A21: Cuentas por pagar a corto plazo (Nota 11) | B21: =+'NOTAS 7 AL19'!C38 -> 21432969 | D21: =+'NOTAS 7 AL19'!#REF! -> #REF!
A22: Retenciones y acumulaciones por pagar (Nota 12) | B22: =+'NOTAS 7 AL19'!C46 -> 12190724 | D22: =+'NOTAS 7 AL19'!#REF! -> #REF!
A23: Beneficios a empleados a corto plazo (Nota 13) | B23: =+'NOTAS 7 AL19'!C52 -> 1251715.8 | D23: =+'NOTAS 7 AL19'!#REF! -> #REF!
A24: Total pasivos corrientes | B24: =SUM(B21:B23) -> 34875409 | D24: =SUM(D21:D23) -> #REF!
A26: Pasivos no corrientes
A27: Total pasivos no corrientes | B27: 0 | D27: 0
A29: Total pasivos | B29: =+B24+B27 -> 34875409 | D29: =+D24+D27 -> #REF!
A31: Activos Netos/Patrimonio (Nota 14)
A32: Capital | B32: 3.4196058e+08 | D32: 64803453
A33: Resultados positivos (ahorro)/negativo (desahorro) | B33: =+'Est. de Rendimiento Fin'!B24 -> 1.4970253e+08 | D33: =+'Est. de Rendimiento Fin'!#REF! -> #REF!
A34: Resultado acumulado | B34: =+'cambio en el patr.'!E13+'cambio en el patr.'!E8 -> 1.1703585e+08
A35: Patrimonio Neto | B35: =SUM(B32:B34) -> 6.0869896e+08 | D35: =SUM(D32:D34) -> #REF!
A36: Total Activos Netos/Patrimonio mas Pasivos | B36: =SUM(B29+B35) -> 6.4357436e+08 | D36: =SUM(D32:D34) -> #REF!
D37: =+D36-D18 -> #REF!
A48: ___________________________
A49: Licdo. Eugenio Rosario | B49: Licda. Milagros Martinez de la Rosa
A50: Encargado Administrativo y Financiero | B50: Contadora
A56: Dr. Armando Camejo
A57: Director General
A58: Dr. Leonardo Aquino
A59: Director General

Sheet Est. de Rendimiento Fin
A1: Hospital Materno Infantil San Lorenzo de los Mina
A2: Estado de Rendimiento Financiero
A3: Del ejercicio terminado al 30 de abril 2025
A4: (Valores en RD$)
B6: 2025
A7: Ingresos (Notas 15)
A8: Impuestos | B8: 0
A9: Ingresos por transacciones con contraprestación | B9: =+'NOTAS 7 AL19'!C67 -> 24062967
A10: Transferencias y donaciones | B10: =+'NOTAS 7 AL19'!C71 -> 5.0575311e+08
A11: Recargos, multas y otros ingresos | B11: =+'NOTAS 7 AL19'!C75 -> 1182489.4
A12: Total ingresos | B12: =SUM(B8:B11) -> 5.3099857e+08
A14: Gastos (Notas 16,17,18,19,20,21)
A15: Sueldos, salarios y beneficios a empleados | B15: =+'NOTAS 7 AL19'!C95 -> 2.7034844e+08
A16: Subvenciones y otros pagos por transferencias | B16: =+'NOTAS 7 AL19'!C99 -> 912359.7
A17: Suministros y material para consumo | B17: =+'NOTAS 7 AL19'!C112 -> 76810203
A18: Gasto de depreciación y amortización | B18: =+'NOTAS 7 AL19'!C120 -> 14142739
A19: Otros gastos | B19: =+'NOTAS 7 AL19'!C133 -> 19032242
A20: Gastos financieros | B20: =+'NOTAS 7 AL19'!C139 -> 50054.14
A21: Total gastos | B21: =SUM(B15:B20) -> 3.8129604e+08
A24: Resultado del período (ahorro / desahorro) | B24: =+B12-B21 -> 1.4970253e+08
A27: Las notas en las páginas 07 al 09 son parte integral de estos Estados Financieros.
A33: Licdo. Eugenio Rosario | B33: Licda. Milagros Martinez de la Rosa
A34: Encargado Administrativo y Financiero | B34: Contadora
A40: Dr. Armando Camejo
A41: Director General
A42: Dr. Leonardo Aquino
A43: Director General

Sheet Cambio del Patrimonio
A1: Hospital Materno Infantil San Lorenzo de los Mina
A2: Estado de Cambio de Activo Neto / Patrimonio | G2: corregir el encabezado del estado, valido para todos
A3: Del ejercicio terminado al 30 de junio 2024 y 2023
A4: (Valores en RD$)
B6: Capital Aportado | C6: Cambios en Políticas Contables | D6: Revaluación | E6: Resultados Acumulados | F6: Total Activos Netos / Patrimonio | H6: este estado esta mal elaborado, fvor revisar, según conversaciones
A8: Saldo al 31 de diciembre 2022 | B8: =+'Estado de Situación'!B32 -> 3.4196058e+08 | E8: =+'Estado de Situación'!B34 -> 1.1703585e+08 | F8: =+B8+C8+D8+E8 -> 4.5899643e+08
A9: Cambio en políticas contables | F9: =+B9+C9+D9+E9 -> 0
A10: Revaluación de Propiedad, planta y equipo | F10: =+B10+C10+D10+E10 -> 0
A11: Ajuste al patrimonio | F11: =+B11+C11+D11+E11 -> 0
A13: Resultado del período | F13: =+F8+E13 -> 4.5899643e+08
A14: Saldo al 31 de diciembre 2024 | C14: =SUM(C7:C13) -> 0 | D14: =SUM(D7:D13) -> 0 | F14: =+B14+C14+D14+E14+F13 -> 4.5899643e+08
A16: Cambio en políticas contables | F16: =+B16+C16+D16+E16 -> 0
A17: Revaluación de Propiedad, planta y equipo | F17: =+B17+C17+D17+E17 -> 0
A18: Efecto del gasto de depreciación de los activos revaluados | F18: =+B18+C18+D18+E18 -> 0
A19: Ajuste al patrimonio | F19: =+B19+C19+D19+E19 -> 0
A20: Resultado del período | E20: =+'Estado de Situación'!B33 -> 1.4970253e+08 | F20: =+B20+C20+D20+E20 -> 1.4970253e+08
F21: =+F18+F19+F20+F14 -> 6.0869896e+08
A25: Las notas en las páginas 07 al 09 son parte integral de estos Estados Financieros.
A34: ___________________________
A35: Licdo. Eugenio Rosario | B35: Licda. Milagros Martinez
A36: Encargado Administrativo y Financiero | B36: Contadora
A42: Dr. Armando Camejo
A43: Director General

Sheet cambio en el patr.
A1: Hospital Materno Infantil San Lorenzo de los Mina
A2: Estado de Cambio de Activo Neto / Patrimonio
A3: Del ejercicio al 30 de abril 2025
A4: (Valores en RD$)
B6: Capital Aportado | C6: Cambios en Políticas Contables | D6: Revaluación | E6: Resultados Acumulados | F6: Total Activos Netos / Patrimonio
A8: Saldo al 31 de diciembre 2022 | B8: =+'[1]Estado de Situación'!B32 -> 3.4196058e+08 | E8: -1.1119234e+08 | F8: =+B8+C8+D8+E8 -> 2.3076825e+08
A9: Ajuste al patrimonio | F9: =+B9+C9+D9+E9 -> 0
A10: Resultado del período | E10: 0 | F10: =SUM(B10:E10) -> 0
A11: Saldo al 31 de diciembre 2023 | B11: =SUM(B8:B10) -> 3.4196058e+08 | C11: =SUM(C7:C10) -> 0 | D11: =SUM(D7:D10) -> 0 | E11: =SUM(E7:E10) -> -1.1119234e+08 | F11: =SUM(F8:F10) -> 2.3076825e+08
A13: Ajuste al patrimonio | E13: 2.2822818e+08 | F13: =+E13 -> 2.2822818e+08
A14: Resultado del período | E14: =+'Est. de Rendimiento Fin'!B24 -> 1.4970253e+08 | F14: =+E14 -> 1.4970253e+08
A15: Saldo al 31 de diciembre 2024 | B15: =SUM(B11) -> 3.4196058e+08 | E15: =SUM(E11:E14) -> 2.6673837e+08 | F15: =SUM(F11:F14) -> 6.0869896e+08
A24: Licdo. Eugenio Rosario | E24: Licda. Milagros Martinez de la Rosa
A25: Encargado Administrativo y Financiero | E25: Contadora
B31: Dr. Armando Camejo
B32: Director General

Sheet Flujo de Efectivo
A1: Hospital Materno Infantil San Lorenzo de los Mina
A2: Estado de Flujo de Efectivo
A3: Del ejercicio terminado al 30 de abril 2025
A4: (Valores en RD$)
A5: Flujo de efectivo procedentes de actividades operativas
B7: 2025
A9: Cobros por venta de bienes y servicios y arrendamientos | B9: =+'NOTAS 7 AL19'!C67 -> 24062967
A10: Cobros de subvenciones, transferencias, y otras asignaciones | B10: =+'NOTAS 7 AL19'!C72 -> 5.0575311e+08
A11: Otros cobros | B11: =+'NOTAS 7 AL19'!C75 -> 1182489.4
A12: Pagos a los trabajadores o en beneficio de ellos | B12: -2.3692722e+08
A13: Pagos por contribuciones a la seguridad social | B13: =-'NOTAS 7 AL19'!C87-'NOTAS 7 AL19'!C88-'NOTAS 7 AL19'!C89 -> -33421226
A14: Pagos a proveedores | B14: -95147077
A15: Otros pagos | B15: =-'NOTAS 7 AL19'!C99 -> -912359.7
A16: Flujos de efectivo netos de las actividades de operación | B16: =SUM(B9:B15) -> 1.6459069e+08
A18: Flujos de efectivo de las actividades de inversión
A19: Pagos por adquisición de propiedad, planta y equipo | B19: =-'NOTA 10'!E7 -> -27598952
A20: Flujos de efectivo netos por las actividades de inversión | B20: =+B19 -> -27598952
A23: Incremento/(Disminución) neta en el efectivo y equivalentes al efectivo | B23: =+B16+B20 -> 1.3699173e+08
A24: Efectivo y equivalentes al efectivo al principio del periodo 01/01/2022 | B24: 1.6693513e+08
A25: Efectivo y equivalentes al efectivo al final del periodo | B25: =+B23+B24 -> 3.0392686e+08
A28: Las notas en las páginas 07 al 09 son parte integral de estos Estados Financieros.
A38: Licdo. Eugenio Rosario | B38: Licda. Milagros Martinez de la Rosa
A39: Encargado Administrativo y Financiero | B39: Contadora
A44: Dr. Armando Camejo
A45: Director General
A47: Dr. Leonardo Aquino
A48: Director General
A50: Dr. Armando Camejo
A51: Director General

Sheet  estado comp. presup.
A1: Hospital Materno Infantil San Lorenzo de los Mina
A2: Estado de Comparación de los Importes Presupuestados y Realizados
A3: Del ejercicio terminado al 30 de abril 2025
A4: Presupuesto sobre la Base de Efectivo
A5: (Clasificación de Ingresos y Gastos por Objeto)
A7: Concepto | C7: Presupuesto Reformado (A) | D7: Presupuesto Ejecutado (B) | E7: % de Variac Ejecución (C=B/A) | F7: Variación (D=A-B)
A8: 1 | B8: Ingresos totales | C8: =SUM(C9:C12) -> 1.504012e+09 | D8: =SUM(D9:D12) -> 5.3099857e+08 | E8: =+D8/C8 -> 0.35305474 | F8: =+C8-D8 -> 9.7301345e+08
A9: 1.4 | B9: Transferencias | C9: =1247948781 -> 1247948781 | D9: =+'NOTAS 7 AL19'!C71 -> 5.0575311e+08 | E9: =+D9/C9 -> 0.40526752 | F9: =+C9-D9 -> 7.4219567e+08
A10: 1.5 | B10: Ingresos por contraprestación | C10: 92836447 | D10: =+'NOTAS 7 AL19'!C67 -> 24062967 | E10: =+D10/C10 -> 0.25919741 | F10: =+C10-D10 -> 68773480
A11: 1.6 | B11: Otros ingresos | C11: 0 | D11: =+'NOTAS 7 AL19'!C75 -> 1182489.4 | E11: 0 | F11: =+C11-D11 -> -1182489.4
A12: 3.1 | B12: Disminucion de Activos Financieros | C12: 1.6322679e+08 | F12: =+C12-D12 -> 1.6322679e+08
A13: 2 | B13: Gastos totales | C13: =SUM(C14:C19) -> 1.504012e+09 | D13: =SUM(D14:D19) -> 3.9475226e+08 | E13: =+D13/C13 -> 0.26246616 | F13: =+C13-D13 -> 1.1092598e+09
A14: 2.1 | B14: Remuneraciones y contribuciones | C14: =844859288.58-5+10878647.92 -> 8.5573793e+08 | D14: =+'NOTAS 7 AL19'!C95-0.01 -> 2.7034844e+08 | E14: =+D14/C14 -> 0.31592434 | F14: =+C14-D14 -> 5.8538949e+08
A15: 2.2 | B15: Contratación de servicios | C15: =50217379.13+18830480.56+14501912.25 -> 83549772 | D15: =+'NOTAS 7 AL19'!C133+'NOTAS 7 AL19'!C139 -> 19082296 | E15: =+D15/C15 -> 0.22839435 | F15: =+C15-D15 -> 64467476
A16: 2.3 | B16: Materiales y suministros | C16: =399408759.41+14501912.25 -> 4.1391067e+08 | D16: =+'NOTAS 7 AL19'!C112 -> 76810203 | E16: =+D16/C16 -> 0.18557193 | F16: =+C16-D16 -> 3.3710047e+08
A17: 2.4 | B17: Transferencias corrientes | C17: 685000 | D17: =+'NOTAS 7 AL19'!C99 -> 912359.7 | E17: =+D17/C17 -> 1.331912 | F17: =+C17-D17 -> -227359.7
A18: 2.6 | B18: Bienes muebles, inmuebles e intangibles | C18: =135626733.94+14501912.26 -> 1.5012865e+08 | D18: =+'NOTA 10'!E7 -> 27598952 | E18: =+D18/C18 -> 0.18383535 | F18: =+C18-D18 -> 1.2252969e+08
A19: 2.9 | B19: Gastos financieros | C19: 0 | D19: 0 | E19: 0 | F19: =+C19-D19 -> 0
B20: Resultado financiero (1-2) | C20: =SUM(C8-C13) -> -2.3841858e-07 | D20: =+D8-D13 -> 1.3624631e+08 | F20: =+C20-D20 -> -1.3624631e+08
D21: =+D13-394752255.99 -> 0
A23: Nota: El Monto de RD$163,226,793.30, es un ingreso recibido mediante fondo financiador 121, que pertenece a disponibilidad de años anteriores
A49: Licdo. Eugenio Rosario | E49: Licda. Milagros Martinez de la Rosa
A50: Encargado Administrativo y Financiero | E50: Contadora
A55: Dr. Armando Camejo
A56: Director General
A58: Dr. Leonardo Aquino
A59: Director General
A61: Dr. Armando Camejo
A62: Director General

Sheet Estado Comparativo
A1: Hospital Materno Infantil San Lorenzo de los Mina
A2: Estado de Comparación de los Importes Presupuestados y Realizados
A3: Del ejercicio terminado al 31 de diciembre 2023
A4: Presupuesto sobre la Base de Efectivo
A5: (Clasificación de Ingresos y Gastos por Objeto)
A6: Concepto | C6: Presupuesto Reformado (A) | D6: Presupuesto Ejecutado (B) | E6: % de Variac Ejecución (C=B/A) | F6: Variación (D=A-B)
A7: 1 | B7: Ingresos totales | C7: =SUM(C8:C9) -> 3.8232418e+08 | D7: =SUM(D8:D9) -> 25245456 | E7: =+D7/C7 -> 0.066031545 | F7: =+C7-D7 -> 3.5707872e+08
A8: 1.5 | B8: Ingresos por contraprestación | C8: =130171600+3720000 -> 133891600 | D8: =+'NOTAS 7 AL19'!C67+'NOTAS 7 AL19'!C79 -> 24062967 | E8: =+D8/C8 -> 0.17971976 | F8: =+C8-D8 -> 1.0982863e+08
A9: 1.6 | B9: Otros ingresos | C9: 2.4843258e+08 | D9: =+'NOTAS 7 AL19'!C75 -> 1182489.4 | E9: =+D9/C9 -> 0.0047598002 | F9: =+C9-D9 -> 2.4725009e+08
A10: 2 | B10: Gastos totales | C10: =SUM(C11:C16) -> 3.2677766e+08 | D10: =SUM(D11:D16) -> #REF! | E10: =+D10/C10 -> #REF! | F10: =SUM(F11:F16) -> #REF!
A11: 2.1 | B11: Remuneraciones y contribuciones | C11: 13017160 | D11: =+'NOTAS 7 AL19'!C95 -> 2.7034844e+08 | E11: =+D11/C11 -> 20.76862 | F11: =+C11-D11 -> -2.5733128e+08
A12: 2.2 | B12: Contratación de servicios | C12: =199200+16959031.71 -> 17158232 | D12: =+'NOTAS 7 AL19'!C133-'NOTAS 7 AL19'!#REF! -> #REF! | E12: =+D12/C12 -> #REF! | F12: =+C12-D12 -> #REF!
A13: 2.3 | B13: Materiales y suministros | C13: =37000800+195705730 -> 232706530 | D13: =+'NOTAS 7 AL19'!C112 -> 76810203 | E13: =+D13/C13 -> 0.33007326 | F13: =+C13-D13 -> 1.5589633e+08
A14: 2.4 | B14: Transferencias corrientes | C14: 36000 | D14: =+'NOTAS 7 AL19'!#REF! -> #REF! | E14: =+D14/C14 -> #REF! | F14: =+C14-D14 -> #REF!
A15: 2.6 | B15: Bienes muebles, inmuebles e intangibles | C15: 63859742 | D15: =+'NOTA 10'!E7+'NOTA 10'!F7 -> 27598952 | E15: =+D15/C15 -> 0.43218076 | F15: =+C15-D15 -> 36260790
A16: 2.9 | B16: Gastos financieros | C16: 0 | D16: =+'NOTAS 7 AL19'!C139 -> 50054.14 | E16: 0 | F16: =+C16-D16 -> -50054.14
B17: Resultado financiero (1-2) | C17: =SUM(C7-C10) -> 55546515 | D17: =+D7-D10 -> #REF! | F17: =SUM(F7-F10) -> #REF!
A23: Las notas en las páginas 07 al 09 son parte integral de estos Estados Financieros.

Sheet dinámico de gastos al 30-06-24
A1: Cod.Capí­tulo | B1: Capí­tulo | C1: Cod.SubCapitulo | D1: SubCapitulo | E1: Cod.Unidad Ejecutora | F1: Unidad Ejecutora | G1: Cod.Fuentes Financiamiento | H1: Fuentes Financiamiento | I1: Cod.Actividad / Obra | J1: Actividad / Obra | K1: Cod.Función | L1: Función | M1: Cod.Programa | N1: Programa | O1: Cod.Organismos Financiadores | P1: Organismos Financiadores | Q1: Cod.Fuente Especifica | R1: Fuente Especifica | S1: Cod.Tp. Transacción | T1: Tp. Transacción | U1: Número Documento | V1: Cod.Inst. Rec. | W1: Inst. Rec. | X1: Concepto Formulario | Y1: Fch.Hist.Imputación | Z1: Fch.Hist.Registro | AA1: Cod.Ref CCP Cuenta | AB1: Ref CCP Cuenta | AC1: Cod.Ref CCP SubCuenta | AD1: Ref CCP SubCuenta | AE1: Cod.Ref CCP Aux | AF1: Ref CCP Aux | AG1: Devengado Aprobado | AH1: Pagado Aprobado
A2: 5180 | B2: DIRECCION CENTRAL DEL SERVICIO NACIONAL DE SALUD | C2: 01 | D2: DIRECCION CENTRAL DEL SERVICIO NACIONAL DE SALUD | E2: 0014 | F2: HOSPITAL MATERNO-INFANTIL SAN LORENZO DE LOS MINA | G2: 10 | H2: FONDO GENERAL | I2: 0001 | J2: Dirección y Coordinación | K2: 001 | L2: N/A | M2: 40 | N2: Salud materno neonatal | O2: 100 | P2: TESORO NACIONAL | Q2: 0100 | R2: FONDO GENERAL | S2: 000001 | T2: Pago | U2: 8 | V2: 0000 | W2: NO APLICA | X2: HOSANLORE. SUELDO ENERO 2024_x000D_ HOSPITAL SAN LORENZO DE LOS MINA_x000D_ FIJOS | Y2: 25/01/2024 | Z2: 25/01/2024 | AA2: 2.1.1 | AB2: REMUNERACIONES | AC2: 2.1.1.1 | AD2: Remuneraciones al personal fijo | AE2: 2.1.1.1.01 | AF2: Sueldos empleados fijos | AG2: 0 | AH2: 47719055
A3: 5180 | B3: DIRECCION CENTRAL DEL SERVICIO NACIONAL DE SALUD | C3: 01 | D3: DIRECCION CENTRAL DEL SERVICIO NACIONAL DE SALUD | E3: 0014 | F3: HOSPITAL MATERNO-INFANTIL SAN LORENZO DE LOS MINA | G3: 10 | H3: FONDO GENERAL | I3: 0001 | J3: Dirección y Coordinación | K3: 001 | L3: N/A | M3: 40 | N3: Salud materno neonatal | O3: 100 | P3: TESORO NACIONAL | Q3: 0100 | R3: FONDO GENERAL | S3: 000001 | T3: Pago | U3: 8 | V3: 0000 | W3: NO APLICA | X3: HOSANLORE. SUELDO ENERO 2024_x000D_ HOSPITAL SAN LORENZO DE LOS MINA_x000D_ FIJOS | Y3: 25/01/2024 | Z3: 25/01/2024 | AA3: 2.1.2 | AB3: SOBRESUELDOS | AC3: 2.1.2.1 | AD3: Primas por antigüedad | AE3: 2.1.2.1.01 | AF3: Primas por antigüedad | AG3: 0 | AH3: 2561925.4
A4: 5180 | B4: DIRECCION CENTRAL DEL SERVICIO NACIONAL DE SALUD | C4: 01 | D4: DIRECCION CENTRAL DEL SERVICIO NACIONAL DE SALUD | E4: 0014 | F4: HOSPITAL MATERNO-INFANTIL SAN LORENZO DE LOS MINA | G4: 10 | H4: FONDO GENERAL | I4: 0001 | J4: Dirección y Coordinación | K4: 001 | L4: N/A | M4: 40 | N4: Salud materno neonatal | O4: 100 | P4: TESORO NACIONAL | Q4: 0100 | R4: FONDO GENERAL | S4: 000001 | T4: Pago | U4: 8 | V4: 0000 | W4: NO APLICA | X4: HOSANLORE. SUELDO ENERO 2024_x000D_ HOSPITAL SAN LORENZO DE LOS MINA_x000D_ FIJOS | Y4: 25/01/2024 | Z4: 25/01/2024 | AA4: 2.1.2 | AB4: SOBRESUELDOS | AC4: 2.1.2.2 | AD4: Compensación | AE4: 2.1.2.2.08 | AF4: Compensaciones especiales | AG4: 0 | AH4: 396000
A5: 5180 | B5: DIRECCION CENTRAL DEL SERVICIO NACIONAL DE SALUD | C5: 01 | D5: DIRECCION CENTRAL DEL SERVICIO NACIONAL DE SALUD | E5: 0014 | F5: HOSPITAL MATERNO-INFANTIL SAN LORENZO DE LOS MINA | G5: 10 | H5: FONDO GENERAL | I5: 0001 | J5: Dirección y Coordinación | K5: 001 | L5: N/A | M5: 40 | N5: Salud materno neonatal | O5: 100 | P5: TESORO NACIONAL | Q5: 0100 | R5: FONDO GENERAL | S5: 000001 | T5: Pago | U5: 8 | V5: 0000 | W5: NO APLICA | X5: HOSANLORE. SUELDO ENERO 2024_x000D_ HOSPITAL SAN LORENZO DE LOS MINA_x000D_ FIJOS | Y5: 25/01/2024 | Z5: 25/01/2024 | AA5: 2.1.2 | AB5: SOBRESUELDOS | AC5: 2.1.2.2 | AD5: Compensación | AE5: 2.1.2.2.12 | AF5: Compensación por cargo al personal policial | AG5: 0 | AH5: 10717.4
A6: 5180 | B6: DIRECCION CENTRAL DEL SERVICIO NACIONAL DE SALUD | C6: 01 | D6: DIRECCION CENTRAL DEL SERVICIO NACIONAL DE SALUD | E6: 0014 | F6: HOSPITAL MATERNO-INFANTIL SAN LORENZO DE LOS MINA | G6: 10 | H6: FONDO GENERAL | I6: 0001 | J6: Dirección y Coordinación | K6: 001 | L6: N/A | M6: 40 | N6: Salud materno neonatal | O6: 100 | P6: TESORO NACIONAL | Q6: 0100 | R6: FONDO GENERAL | S6: 000001 | T6: Pago | U6: 8 | V6: 0000 | W6: NO APLICA | X6: HOSANLORE. SUELDO ENERO 2024_x000D_ HOSPITAL SAN LORENZO DE LOS MINA_x000D_ FIJOS | Y6: 25/01/2024 | Z6: 25/01/2024 | AA6: 2.1.2 | AB6: SOBRESUELDOS | AC6: 2.1.2.2 | AD6: Compensación | AE6: 2.1.2.2.13 | AF6: Incentivo por riesgo laboral al personal militar y policial | AG6: 0 | AH6: 64304.4
A7: 5180 | B7: DIRECCION CENTRAL DEL SERVICIO NACIONAL DE SALUD | C7: 01 | D7: DIRECCION CENTRAL DEL SERVICIO NACIONAL DE SALUD | E7: 0014 | F7: HOSPITAL MATERNO-INFANTIL SAN LORENZO DE LOS MINA | G7: 10 | H7: FONDO GENERAL | I7: 0001 | J7: Dirección y Coordinación | K7: 001 | L7: N/A | M7: 40 | N7: Salud materno neonatal | O7: 100 | P7: TESORO NACIONAL | Q7: 0100 | R7: FONDO GENERAL | S7: 000001 | T7: Pago | U7: 8 | V7: 0000 | W7: NO APLICA | X7: HOSANLORE. SUELDO ENERO 2024_x000D_ HOSPITAL SAN LORENZO DE LOS MINA_x000D_ FIJOS | Y7: 25/01/2024 | Z7: 25/01/2024 | AA7: 2.1.5 | AB7: CONTRIBUCIONES A LA SEGURIDAD SOCIAL | AC7: 2.1.5.1 | AD7: Contribuciones al seguro de salud | AE7: 2.1.5.1.01 | AF7: Contribuciones al seguro de salud | AG7: 0 | AH7: 3383280
A8: 5180 | B8: DIRECCION CENTRAL DEL SERVICIO NACIONAL DE SALUD | C8: 01 | D8: DIRECCION CENTRAL DEL SERVICIO NACIONAL DE SALUD | E8: 0014 | F8: HOSPITAL MATERNO-INFANTIL SAN LORENZO DE LOS MINA | G8: 10 | H8: FONDO GENERAL | I8: 0001 | J8: Dirección y Coordinación | K8: 001 | L8: N/A | M8: 40 | N8: Salud materno neonatal | O8: 100 | P8: TESORO NACIONAL | Q8: 0100 | R8: FONDO GENERAL | S8: 000001 | T8: Pago | U8: 8 | V8: 0000 | W8: NO APLICA | X8: HOSANLORE. SUELDO ENERO 2024_x000D_ HOSPITAL SAN LORENZO DE LOS MINA_x000D_ FIJOS | Y8: 25/01/2024 | Z8: 25/01/2024 | AA8: 2.1.5 | AB8: CONTRIBUCIONES A LA SEGURIDAD SOCIAL | AC8: 2.1.5.2 | AD8: Contribuciones al seguro de pensiones | AE8: 2.1.5.2.01 | AF8: Contribuciones al seguro de pensiones | AG8: 0 | AH8: 3388052.4
A9: 5180 | B9: DIRECCION CENTRAL DEL SERVICIO NACIONAL DE SALUD | C9: 01 | D9: DIRECCION CENTRAL DEL SERVICIO NACIONAL DE SALUD | E9: 0014 | F9: HOSPITAL MATERNO-INFANTIL SAN LORENZO DE LOS MINA | G9: 10 | H9: FONDO GENERAL | I9: 0001 | J9: Dirección y Coordinación | K9: 001 | L9: N/A | M9: 40 | N9: Salud materno neonatal | O9: 100 | P9: TESORO NACIONAL | Q9: 0100 | R9: FONDO GENERAL | S9: 000001 | T9: Pago | U9: 8 | V9: 0000 | W9: NO APLICA | X9: HOSANLORE. SUELDO ENERO 2024_x000D_ HOSPITAL SAN LORENZO DE LOS MINA_x000D_ FIJOS | Y9: 25/01/2024 | Z9: 25/01/2024 | AA9: 2.1.5 | AB9: CONTRIBUCIONES A LA SEGURIDAD SOCIAL | AC9: 2.1.5.3 | AD9: Contribuciones al seguro de riesgo laboral | AE9: 2.1.5.3.01 | AF9: Contribuciones al seguro de riesgo laboral | AG9: 0 | AH9: 571427.64
A10: 5180 | B10: DIRECCION CENTRAL DEL SERVICIO NACIONAL DE SALUD | C10: 01 | D10: DIRECCION CENTRAL DEL SERVICIO NACIONAL DE SALUD | E10: 0014 | F10: HOSPITAL MATERNO-INFANTIL SAN LORENZO DE LOS MINA | G10: 10 | H10: FONDO GENERAL | I10: 0001 | J10: Dirección y Coordinación | K10: 001 | L10: N/A | M10: 40 | N10: Salud materno neonatal | O10: 100 | P10: TESORO NACIONAL | Q10: 0100 | R10: FONDO GENERAL | S10: 000001 | T10: Pago | U10: 9 | V10: 0000 | W10: NO APLICA | X10: HOSANLORE. SUELDO ENERO 2024_x000D_ HOSPITAL SAN LORENZO DE LOS MINA_x000D_ TEMPORAL | Y10: 25/01/2024 | Z10: 25/01/2024 | AA10: 2.1.1 | AB10: REMUNERACIONES | AC10: 2.1.1.2 | AD10: Remuneraciones al personal de carácter temporal | AE10: 2.1.1.2.08 | AF10: Empleados temporales | AG10: 0 | AH10: 686003.26
A11: 5180 | B11: DIRECCION CENTRAL DEL SERVICIO NACIONAL DE SALUD | C11: 01 | D11: DIRECCION CENTRAL DEL SERVICIO NACIONAL DE SALUD | E11: 0014 | F11: HOSPITAL MATERNO-INFANTIL SAN LORENZO DE LOS MINA | G11: 10 | H11: FONDO GENERAL | I11: 0001 | J11: Dirección y Coordinación | K11: 001 | L11: N/A | M11: 40 | N11: Salud materno neonatal | O11: 100 | P11: TESORO NACIONAL | Q11: 0100 | R11: FONDO GENERAL | S11: 000001 | T11: Pago | U11: 9 | V11: 0000 | W11: NO APLICA | X11: HOSANLORE. SUELDO ENERO 2024_x000D_ HOSPITAL SAN LORENZO DE LOS MINA_x000D_ TEMPORAL | Y11: 25/01/2024 | Z11: 25/01/2024 | AA11: 2.1.5 | AB11: CONTRIBUCIONES A LA SEGURIDAD SOCIAL | AC11: 2.1.5.1 | AD11: Contribuciones al seguro de salud | AE11: 2.1.5.1.01 | AF11: Contribuciones al seguro de salud | AG11: 0 | AH11: 48637.63
A12: 5180 | B12: DIRECCION CENTRAL DEL SERVICIO NACIONAL DE SALUD | C12: 01 | D12: DIRECCION CENTRAL DEL SERVICIO NACIONAL DE SALUD | E12: 0014 | F12: HOSPITAL MATERNO-INFANTIL SAN LORENZO DE LOS MINA | G12: 10 | H12: FONDO GENERAL | I12: 0001 | J12: Dirección y Coordinación | K12: 001 | L12: N/A | M12: 40 | N12: Salud materno neonatal | O12: 100 | P12: TESORO NACIONAL | Q12: 0100 | R12: FONDO GENERAL | S12: 000001 | T12: Pago | U12: 9 | V12: 0000 | W12: NO APLICA | X12: HOSANLORE. SUELDO ENERO 2024_x000D_ HOSPITAL SAN LORENZO DE LOS MINA_x000D_ TEMPORAL | Y12: 25/01/2024 | Z12: 25/01/2024 | AA12: 2.1.5 | AB12: CONTRIBUCIONES A LA SEGURIDAD SOCIAL | AC12: 2.1.5.2 | AD12: Contribuciones al seguro de pensiones | AE12: 2.1.5.2.01 | AF12: Contribuciones al seguro de pensiones | AG12: 0 | AH12: 48706.23
A13: 5180 | B13: DIRECCION CENTRAL DEL SERVICIO NACIONAL DE SALUD | C13: 01 | D13: DIRECCION CENTRAL DEL SERVICIO NACIONAL DE SALUD | E13: 0014 | F13: HOSPITAL MATERNO-INFANTIL SAN LORENZO DE LOS MINA | G13: 10 | H13: FONDO GENERAL | I13: 0001 | J13: Dirección y Coordinación | K13: 001 | L13: N/A | M13: 40 | N13: Salud materno neonatal | O13: 100 | P13: TESORO NACIONAL | Q13: 0100 | R13: FONDO GENERAL | S13: 000001 | T13: Pago | U13: 9 | V13: 0000 | W13: NO APLICA | X13: HOSANLORE. SUELDO ENERO 2024_x000D_ HOSPITAL SAN LORENZO DE LOS MINA_x000D_ TEMPORAL | Y13: 25/01/2024 | Z13: 25/01/2024 | AA13: 2.1.5 | AB13: CONTRIBUCIONES A LA SEGURIDAD SOCIAL | AC13: 2.1.5.3 | AD13: Contribuciones al seguro de riesgo laboral | AE13: 2.1.5.3.01 | AF13: Contribuciones al seguro de riesgo laboral | AG13: 0 | AH13: 8109.74
... A1071: 5180 | B1071: DIRECCION CENTRAL DEL SERVICIO NACIONAL DE SALUD | C1071: 01 | D1071: DIRECCION CENTRAL DEL SERVICIO NACIONAL DE SALUD | E1071: 0014 | F1071: HOSPITAL MATERNO-INFANTIL SAN LORENZO DE LOS MINA | G1071: 10 | H1071: FONDO GENERAL | I1071: 0002 | J1071: Servicios de atención y control al neonato prematuro | K1071: 001 | L1071: N/A | M1071: 40 | N1071: Salud materno neonatal | O1071: 100 | P1071: TESORO NACIONAL | Q1071: 0100 | R1071: FONDO GENERAL | S1071: 000243 | T1071: DEVENGADO PROCESO DE COMPRAS PARA BIENES MUEBLES Y OBRAS | U1071: 1760 | V1071: 0000 | W1071: NO APLICA | X1071: PAGO DE FACT NCF B1500000033 POR ADQUISICION DE MOBILIARIOS DE OFICINA Y MONITOR SEGUN O/C HSLM-2024-00214. | Y1071: 19/06/2024 | Z1071: 19/06/2024 | AA1071: 2.6.1 | AB1071: MOBILIARIO Y EQUIPO | AC1071: 2.6.1.3 | AD1071: Equipos de tecnología de la información y comunicación | AE1071: 2.6.1.3.01 | AF1071: Equipos de tecnología de la información y comunicación | AG1071: 124872.68 | AH1071: 0
AG1073: =SUBTOTAL(9,AG2:AG1072) -> 4.5440444e+08 | AH1073: =SUBTOTAL(9,AH2:AH1072) -> 4.3675684e+08
AH1074: =+AH1073-AG1073 -> -17647601
AH1609: =SUBTOTAL(9,AH2:AH1608) -> 4.1910924e+08 | AI1609: 2.9258776e+08
AH1610: 4120195.3 | AI1610: 3469454.5
AH1611: =+AH1609+AH1610 -> 4.2322944e+08 | AI1611: 20570888
AI1612: 20541912
AI1613: =+AI1612+AI1611+AI1610+AI1609 -> 3.3717001e+08
AH1615: 20541912
AH1616: 20570888
AH1617: 3469454.5
AH1618: =+AH1615+AH1616+AH1617 -> 44582254
AH1620: 3.0662217e+08
AH1621: 614803.73
AH1622: =+AH1618+AH1620+AH1621 -> 3.5181923e+08

Sheet Hoja4
A1: Cod.Capí­tulo | B1: Capí­tulo | C1: Cod.SubCapitulo | D1: SubCapitulo | E1: Cod.Unidad Ejecutora | F1: Unidad Ejecutora | G1: Cod.Fuentes Financiamiento | H1: Fuentes Financiamiento | I1: Cod.Actividad / Obra | J1: Actividad / Obra | K1: Cod.Función | L1: Función | M1: Cod.Programa | N1: Programa | O1: Cod.Organismos Financiadores | P1: Organismos Financiadores | Q1: Cod.Fuente Especifica | R1: Fuente Especifica | S1: Cod.Tp. Transacción | T1: Tp. Transacción | U1: Número Documento | V1: Cod.Inst. Rec. | W1: Inst. Rec. | X1: Concepto Formulario | Y1: Fch.Hist.Imputación | Z1: Fch.Hist.Registro | AA1: Cod.Ref CCP Cuenta | AB1: Ref CCP Cuenta | AC1: Cod.Ref CCP SubCuenta | AD1: Ref CCP SubCuenta | AE1: Cod.Ref CCP Aux | AF1: Ref CCP Aux | AG1: Pagado Aprobado
A2: 5180 | B2: DIRECCION CENTRAL DEL SERVICIO NACIONAL DE SALUD | C2: 01 | D2: DIRECCION CENTRAL DEL SERVICIO NACIONAL DE SALUD | E2: 0014 | F2: HOSPITAL MATERNO-INFANTIL SAN LORENZO DE LOS MINA | G2: 10 | H2: FONDO GENERAL | I2: 0001 | J2: Dirección y Coordinación | K2: 001 | L2: N/A | M2: 40 | N2: Salud materno neonatal | O2: 100 | P2: TESORO NACIONAL | Q2: 0100 | R2: FONDO GENERAL | S2: 000001 | T2: Pago | U2: 2035 | V2: 0000 | W2: NO APLICA | X2: HOSANLORE. SUELDO NOMINA ADICIONAL TEMPORAL POR CREACION DE PLAZA CORRESPONDIENTE AL MES DE JUNIO 2024_x000D_ NOMINA ADICIONAL TEMPORAL POR CREACION DE PLAZA CORRESPONDIENTE AL MES DE JUNIO 2024 | Y2: 27/06/2024 | Z2: 27/06/2024 | AA2: 2.1.1 | AB2: REMUNERACIONES | AC2: 2.1.1.2 | AD2: Remuneraciones al personal de carácter temporal | AE2: 2.1.1.2.08 | AF2: Empleados temporales | AG2: 50000
A3: 5180 | B3: DIRECCION CENTRAL DEL SERVICIO NACIONAL DE SALUD | C3: 01 | D3: DIRECCION CENTRAL DEL SERVICIO NACIONAL DE SALUD | E3: 0014 | F3: HOSPITAL MATERNO-INFANTIL SAN LORENZO DE LOS MINA | G3: 10 | H3: FONDO GENERAL | I3: 0001 | J3: Dirección y Coordinación | K3: 001 | L3: N/A | M3: 40 | N3: Salud materno neonatal | O3: 100 | P3: TESORO NACIONAL | Q3: 0100 | R3: FONDO GENERAL | S3: 000001 | T3: Pago | U3: 1688 | V3: 0000 | W3: NO APLICA | X3: HOSANLORE. PAGO DE PRESTACIONES LABORALEX EX-EMPLEADOS | Y3: 11/06/2024 | Z3: 11/06/2024 | AA3: 2.1.1 | AB3: REMUNERACIONES | AC3: 2.1.1.5 | AD3: Prestaciones económicas | AE3: 2.1.1.5.03 | AF3: Prestación laboral por desvinculación | AG3: 55000
A4: 5180 | B4: DIRECCION CENTRAL DEL SERVICIO NACIONAL DE SALUD | C4: 01 | D4: DIRECCION CENTRAL DEL SERVICIO NACIONAL DE SALUD | E4: 0014 | F4: HOSPITAL MATERNO-INFANTIL SAN LORENZO DE LOS MINA | G4: 10 | H4: FONDO GENERAL | I4: 0001 | J4: Dirección y Coordinación | K4: 001 | L4: N/A | M4: 40 | N4: Salud materno neonatal | O4: 100 | P4: TESORO NACIONAL | Q4: 0100 | R4: FONDO GENERAL | S4: 000001 | T4: Pago | U4: 1690 | V4: 0000 | W4: NO APLICA | X4: HOSANLORE. PAGO DE VACACIONES NO DISFRUTADAS A EX-EMPLEADOS | Y4: 11/06/2024 | Z4: 11/06/2024 | AA4: 2.1.1 | AB4: REMUNERACIONES | AC4: 2.1.1.5 | AD4: Prestaciones económicas | AE4: 2.1.1.5.04 | AF4: Proporción de vacaciones no disfrutadas | AG4: 56650.2
A5: 5180 | B5: DIRECCION CENTRAL DEL SERVICIO NACIONAL DE SALUD | C5: 01 | D5: DIRECCION CENTRAL DEL SERVICIO NACIONAL DE SALUD | E5: 0014 | F5: HOSPITAL MATERNO-INFANTIL SAN LORENZO DE LOS MINA | G5: 10 | H5: FONDO GENERAL | I5: 0001 | J5: Dirección y Coordinación | K5: 001 | L5: N/A | M5: 40 | N5: Salud materno neonatal | O5: 100 | P5: TESORO NACIONAL | Q5: 0100 | R5: FONDO GENERAL | S5: 000001 | T5: Pago | U5: 1045 | V5: 0000 | W5: NO APLICA | X5: HOSANLORE. ADICIONAL FIJO ABRIL 2024 | Y5: 03/05/2024 | Z5: 03/05/2024 | AA5: 2.1.1 | AB5: REMUNERACIONES | AC5: 2.1.1.1 | AD5: Remuneraciones al personal fijo | AE5: 2.1.1.1.01 | AF5: Sueldos empleados fijos | AG5: 69663.1
A6: 5180 | B6: DIRECCION CENTRAL DEL SERVICIO NACIONAL DE SALUD | C6: 01 | D6: DIRECCION CENTRAL DEL SERVICIO NACIONAL DE SALUD | E6: 0014 | F6: HOSPITAL MATERNO-INFANTIL SAN LORENZO DE LOS MINA | G6: 10 | H6: FONDO GENERAL | I6: 0001 | J6: Dirección y Coordinación | K6: 001 | L6: N/A | M6: 40 | N6: Salud materno neonatal | O6: 100 | P6: TESORO NACIONAL | Q6: 0100 | R6: FONDO GENERAL | S6: 000001 | T6: Pago | U6: 25 | V6: 0000 | W6: NO APLICA | X6: HOSANLORE. PAGO DE VACACIONES NO DISFRUTADAS A EX- EMPLEADOS_x000D_ NOMINA FINAL FEBRERO 2024 | Y6: 04/03/2024 | Z6: 04/03/2024 | AA6: 2.1.1 | AB6: REMUNERACIONES | AC6: 2.1.1.5 | AD6: Prestaciones económicas | AE6: 2.1.1.5.04 | AF6: Proporción de vacaciones no disfrutadas | AG6: 156153.53
A7: 5180 | B7: DIRECCION CENTRAL DEL SERVICIO NACIONAL DE SALUD | C7: 01 | D7: DIRECCION CENTRAL DEL SERVICIO NACIONAL DE SALUD | E7: 0014 | F7: HOSPITAL MATERNO-INFANTIL SAN LORENZO DE LOS MINA | G7: 10 | H7: FONDO GENERAL | I7: 0001 | J7: Dirección y Coordinación | K7: 001 | L7: N/A | M7: 40 | N7: Salud materno neonatal | O7: 100 | P7: TESORO NACIONAL | Q7: 0100 | R7: FONDO GENERAL | S7: 000001 | T7: Pago | U7: 26 | V7: 0000 | W7: NO APLICA | X7: HOSANLORE. PAGO DE PRESTACIONES LABORALES EX-EMPLEADO._x000D_ NOMINA FINAL FEBRERO 2024 | Y7: 04/03/2024 | Z7: 04/03/2024 | AA7: 2.1.1 | AB7: REMUNERACIONES | AC7: 2.1.1.5 | AD7: Prestaciones económicas | AE7: 2.1.1.5.03 | AF7: Prestación laboral por desvinculación | AG7: 347000
A8: 5180 | B8: DIRECCION CENTRAL DEL SERVICIO NACIONAL DE SALUD | C8: 01 | D8: DIRECCION CENTRAL DEL SERVICIO NACIONAL DE SALUD | E8: 0014 | F8: HOSPITAL MATERNO-INFANTIL SAN LORENZO DE LOS MINA | G8: 10 | H8: FONDO GENERAL | I8: 0001 | J8: Dirección y Coordinación | K8: 001 | L8: N/A | M8: 40 | N8: Salud materno neonatal | O8: 100 | P8: TESORO NACIONAL | Q8: 0100 | R8: FONDO GENERAL | S8: 000001 | T8: Pago | U8: 9 | V8: 0000 | W8: NO APLICA | X8: HOSANLORE. SUELDO ENERO 2024_x000D_ HOSPITAL SAN LORENZO DE LOS MINA_x000D_ TEMPORAL | Y8: 25/01/2024 | Z8: 25/01/2024 | AA8: 2.1.1 | AB8: REMUNERACIONES | AC8: 2.1.1.2 | AD8: Remuneraciones al personal de carácter temporal | AE8: 2.1.1.2.08 | AF8: Empleados temporales | AG8: 686003.26
A9: 5180 | B9: DIRECCION CENTRAL DEL SERVICIO NACIONAL DE SALUD | C9: 01 | D9: DIRECCION CENTRAL DEL SERVICIO NACIONAL DE SALUD | E9: 0014 | F9: HOSPITAL MATERNO-INFANTIL SAN LORENZO DE LOS MINA | G9: 10 | H9: FONDO GENERAL | I9: 0001 | J9: Dirección y Coordinación | K9: 001 | L9: N/A | M9: 40 | N9: Salud materno neonatal | O9: 100 | P9: TESORO NACIONAL | Q9: 0100 | R9: FONDO GENERAL | S9: 000001 | T9: Pago | U9: 16 | V9: 0000 | W9: NO APLICA | X9: HOSANLORE. SUELDO FEBRERO 2024_x000D_ HOSPITAL SAN LORENZO DE LOS MINA_x000D_ TEMPORAL | Y9: 23/02/2024 | Z9: 23/02/2024 | AA9: 2.1.1 | AB9: REMUNERACIONES | AC9: 2.1.1.2 | AD9: Remuneraciones al personal de carácter temporal | AE9: 2.1.1.2.08 | AF9: Empleados temporales | AG9: 686003.26
A10: 5180 | B10: DIRECCION CENTRAL DEL SERVICIO NACIONAL DE SALUD | C10: 01 | D10: DIRECCION CENTRAL DEL SERVICIO NACIONAL DE SALUD | E10: 0014 | F10: HOSPITAL MATERNO-INFANTIL SAN LORENZO DE LOS MINA | G10: 10 | H10: FONDO GENERAL | I10: 0001 | J10: Dirección y Coordinación | K10: 001 | L10: N/A | M10: 40 | N10: Salud materno neonatal | O10: 100 | P10: TESORO NACIONAL | Q10: 0100 | R10: FONDO GENERAL | S10: 000001 | T10: Pago | U10: 166 | V10: 0000 | W10: NO APLICA | X10: HOSANLORE. SUELDO DE MARZO 2024_x000D_ NOMINA TEMPORAL | Y10: 21/03/2024 | Z10: 21/03/2024 | AA10: 2.1.1 | AB10: REMUNERACIONES | AC10: 2.1.1.2 | AD10: Remuneraciones al personal de carácter temporal | AE10: 2.1.1.2.08 | AF10: Empleados temporales | AG10: 732074.29
A11: 5180 | B11: DIRECCION CENTRAL DEL SERVICIO NACIONAL DE SALUD | C11: 01 | D11: DIRECCION CENTRAL DEL SERVICIO NACIONAL DE SALUD | E11: 0014 | F11: HOSPITAL MATERNO-INFANTIL SAN LORENZO DE LOS MINA | G11: 10 | H11: FONDO GENERAL | I11: 0001 | J11: Dirección y Coordinación | K11: 001 | L11: N/A | M11: 40 | N11: Salud materno neonatal | O11: 100 | P11: TESORO NACIONAL | Q11: 0100 | R11: FONDO GENERAL | S11: 000001 | T11: Pago | U11: 904 | V11: 0000 | W11: NO APLICA | X11: HOSANLORE. SUELDOS NOMINA TEMPORAL ABRIL 2024 | Y11: 22/04/2024 | Z11: 22/04/2024 | AA11: 2.1.1 | AB11: REMUNERACIONES | AC11: 2.1.1.2 | AD11: Remuneraciones al personal de carácter temporal | AE11: 2.1.1.2.08 | AF11: Empleados temporales | AG11: 732074.29
A12: 5180 | B12: DIRECCION CENTRAL DEL SERVICIO NACIONAL DE SALUD | C12: 01 | D12: DIRECCION CENTRAL DEL SERVICIO NACIONAL DE SALUD | E12: 0014 | F12: HOSPITAL MATERNO-INFANTIL SAN LORENZO DE LOS MINA | G12: 10 | H12: FONDO GENERAL | I12: 0001 | J12: Dirección y Coordinación | K12: 001 | L12: N/A | M12: 40 | N12: Salud materno neonatal | O12: 100 | P12: TESORO NACIONAL | Q12: 0100 | R12: FONDO GENERAL | S12: 000001 | T12: Pago | U12: 1295 | V12: 0000 | W12: NO APLICA | X12: HOSANLORE. SULEDO NOMINA TEMPORAL MAYO 2024 | Y12: 21/05/2024 | Z12: 21/05/2024 | AA12: 2.1.1 | AB12: REMUNERACIONES | AC12: 2.1.1.2 | AD12: Remuneraciones al personal de carácter temporal | AE12: 2.1.1.2.08 | AF12: Empleados temporales | AG12: 732074.29
A13: 5180 | B13: DIRECCION CENTRAL DEL SERVICIO NACIONAL DE SALUD | C13: 01 | D13: DIRECCION CENTRAL DEL SERVICIO NACIONAL DE SALUD | E13: 0014 | F13: HOSPITAL MATERNO-INFANTIL SAN LORENZO DE LOS MINA | G13: 10 | H13: FONDO GENERAL | I13: 0001 | J13: Dirección y Coordinación | K13: 001 | L13: N/A | M13: 40 | N13: Salud materno neonatal | O13: 100 | P13: TESORO NACIONAL | Q13: 0100 | R13: FONDO GENERAL | S13: 000001 | T13: Pago | U13: 1899 | V13: 0000 | W13: NO APLICA | X13: HOSANLORE. NOMINA SUELDO TEMPORAL JUNIO 2024_x000D_ SUELDO TEMPORAL JUNIO 2024 | Y13: 21/06/2024 | Z13: 21/06/2024 | AA13: 2.1.1 | AB13: REMUNERACIONES | AC13: 2.1.1.2 | AD13: Remuneraciones al personal de carácter temporal | AE13: 2.1.1.2.08 | AF13: Empleados temporales | AG13: 757074.29
... A446: 5180 | B446: DIRECCION CENTRAL DEL SERVICIO NACIONAL DE SALUD | C446: 01 | D446: DIRECCION CENTRAL DEL SERVICIO NACIONAL DE SALUD | E446: 0014 | F446: HOSPITAL MATERNO-INFANTIL SAN LORENZO DE LOS MINA | G446: 10 | H446: FONDO GENERAL | I446: 0001 | J446: Dirección y Coordinación | K446: 001 | L446: N/A | M446: 40 | N446: Salud materno neonatal | O446: 100 | P446: TESORO NACIONAL | Q446: 0100 | R446: FONDO GENERAL | S446: 000001 | T446: Pago | U446: 1044 | V446: 0000 | W446: NO APLICA | X446: Pago de Fact NCF No. B1500000008, por adquisicion de maquina industrial de costura, según orden de compra HSLM-2023-00755 | Y446: 03/05/2024 | Z446: 03/05/2024 | AA446: 2.6.5 | AB446: MAQUINARIA, OTROS EQUIPOS Y HERRAMIENTAS | AC446: 2.6.5.2 | AD446: Maquinaria y equipo industrial | AE446: 2.6.5.2.01 | AF446: Maquinaria y equipo industrial | AG446: 181720
AG448: =SUBTOTAL(9,AG2:AG447) -> 16311429
AG449: =+AG448-#REF! -> #REF!
AG984: =SUBTOTAL(9,AG2:AG983) -> #REF!
AG985: 4120195.3
AG986: =+AG984+AG985 -> #REF!

Sheet NOTAS 7 AL19
A1: Hospital Materno Infantil San Lorenzo de los Mina
A2: Nota a los Estados Financieros
A3: Del ejercicio terminado al 30 de abril 2025
A4: (Valores en RD$)
A6: Nota #7 Efectivo y equivalentes de efectivo.
A7: Detalle del efectivo y equivalente de efectivo al 30 de abril 2025 es como sigue:
A8: Descripción | C8: 2025
A9: Cuenta Bancaria Venta de Servicios No. 010-390450-6 | C9: =+'CONCILIACION '!G44 -> 1731116.6
A10: Cuenta Bancaria Fondo de Anticipo No. 960-454417-5 | C10: 0
A11: Cuenta Unica | C11: =+B14+B15 -> 3.0219372e+08
C12: =SUM(C8:C11) -> 3.0392686e+08
A14: Sub- Cuenta No. 0100269000 | B14: 3.0095074e+08
A15: Sub- Cuenta No. 995041000 | B15: 1242977.5
B16: =SUM(B14:B15) -> 3.0219372e+08
A17: TOTAL GENERAL
A19: Nota #8 Cuentas por cobrar a corto plazo
A20: Un detalle de las cuentas por cobrar 30 de abril 2025 es como sigue:
A21: Descripción | C21: 2024
A22: Cuentas por Cobrar por Ventas de Servicios | C22: =+CXC!B159 -> 18208482
A23: Cuentas por Cobrar Pacientes no Asegurados | C23: 63940334
A24: TOTAL GENERAL | C24: =SUM(C22:C23) -> 82148815
A25: Nota #9 Inventarios
A26: Un detalle de las partidas de inventario 30 de abril 2025 es como sigue:
A27: Descripción | C27: 2024
A28: Inventario De Utiles y Suministro de Oficina | C28: 7385934.8
A29: Inventario de Medicamentos | C29: =48965927.92+27706430.1 -> 76672358
A30: Inventario de Laboratorio | C30: 7545437.2
A31: Inventario de Perecederos | C31: 822695.3
A32: TOTAL GENERAL | C32: =SUM(C28:C31) -> 92426425
A34: Nota# 11 Cuentas por pagar a corto plazo
A35: Un detalle de las cuentas por pagar a corto plazo 30 de abril 2025 es como sigue:
A36: Descripción | C36: 2024
A37: Cuentas por Pagar a corto plazo proveedores (Sector Privado) | C37: =+'CUENTAS POR PAGAR'!N105 -> 21432969
A38: TOTAL GENERAL | C38: =SUM(C37:C37) -> 21432969
A40: Nota# 12 Retenciones y acumulaciones por pagar
A41: Un detalle de las retenciones y acumulaciones por pagar 30 de abril 2025 es como sigue:
A42: Descripción | C42: 2024
A43: Retenciones por pagar 5% | C43: =11389866.86+276884.63+183994.68 -> 11850746
A44: Retenciones por Pagar 10% | C44: =292785.08+2964.29 -> 295749.37
A45: Retencion de ITBIS | C45: =17550+26678.57 -> 44228.57
...

Sheet NOTA 10
A2: AÑO 2025
A4: Nota#10 Propiedad planta y equipo
B5: Terreno | C5: Infraestructura | D5: Edif. Y comp. | E5: Maq. Y Equipos | F5: Mob. Y equ. de ofic. | G5: Equipo,Transp y otros | H5: Const. En Proceso | I5: Total
A6: Costos de adquisición 2024 | B6: 0 | C6: 0 | D6: 0 | E6: 1.2590926e+08 | F6: 36903873 | G6: 0 | H6: 0 | I6: 1.6281313e+08
A7: Adiciones (AÑO 2025) | B7: 0 | C7: 0 | D7: 0 | E7: =22933910.83+4665041.39 -> 27598952 | G7: 0 | H7: 0 | I7: =+E7+F7 -> 27598952
A8: Saldo al final del periodo | B8: =SUM(B6:B7) -> 0 | C8: =SUM(C6:C7) -> 0 | D8: =SUM(D6:D7) -> 0 | E8: =SUM(E6:E7) -> 1.5350821e+08 | F8: =SUM(F6:F7) -> 36903873 | G8: =SUM(G6:G7) -> 0 | H8: =SUM(H6:H7) -> 0 | I8: =SUM(I6:I7) -> 1.9041208e+08
A10: Dep. Acum. al inicio del periodo | B10: 0 | D10: 0 | E10: 1926841.3 | F10: 9270238.7 | H10: 0 | I10: =SUM(B10:H10) -> 11197080
A11: Cargo del periodo | B11: 0 | C11: 0 | D11: 0 | E11: =+((E7*0.25)/12)+(((E6*0.25)/12)*4) -> 11067416 | F11: =+((F7*0.25)/12)+(((F6*0.25)/12)*4) -> 3075322.7 | H11: 0 | I11: =SUM(B11:H11) -> 14142739
A12: Saldo al final del periodo | B12: 0 | C12: 0 | D12: 0 | E12: =+E10+E11 -> 12994257 | F12: =+F10+F11 -> 12345561 | G12: =+G10+G11 -> 0 | H12: =+H10+H11 -> 0 | I12: =SUM(B12:H12) -> 25339819
A13: Prop. planta y equipos neto 2024 | B13: =SUM(B8-B12) -> 0 | C13: 0 | D13: =SUM(D8-D12) -> 0 | E13: =+E8-E12 -> 1.4051395e+08 | F13: =+F8-F12 -> 24558311 | G13: =+G8-G12 -> 0 | H13: =+H8-H12 -> 0 | I13: =SUM(I8-I12) -> 1.6507226e+08
A14: Nota: Nuestros Activos Fijos correspondiente a los años anteriores al 2021, estan siendo tasados, por lo que solo se reflejaran en este estado financiero los activos adquiridos durante el año 2021, 2022, 2023, 2024 y 2025, con su respectiva depreciacion.
A19: AÑO 2023
A21: Nota#10 Propiedad planta y equipo
B22: Terreno | C22: Infraestructura | D22: Edif. Y comp. | E22: Maq. Y Equipos | F22: Mob. Y equ. de ofic. | G22: Equipo,Transp y otros | H22: Const. En Proceso | I22: Total
A23: Costos de adquisición 2021 | B23: 1 | C23: 1 | D23: 1 | E23: 1674420 | F23: =2314111.33+10581957.22 -> 12896069 | G23: 1 | H23: 1 | I23: =+E23+F23 -> 14570489
A24: Adiciones (AÑO 2023) | B24: 0 | C24: 0 | D24: 0 | E24: =14051393.46+207414.5+48246.66+8339698.02 -> 22646753 | F24: =1893940.93+278000+280495.73+254362.5+286117.79+25804.24+394374.41+550970.21+970062.21+970224+175230+3152252+1444910+138549.7+58382.86+2382305.5+222902+129705.6+88500+170223.01+41300+186585.14+1753288.2+210134.4+172280+493068.19+103908.68+2039018.74+1113624.64+214052 -> 20194573 | G24: 0 | H24: 0 | I24: =+E24+F24 -> 42841325
A25: Saldo al final del periodo | B25: =SUM(B23+B24+#REF!-#REF!-#REF!-#REF!) -> #REF! | C25: =SUM(C23+C24+#REF!-#REF!-#REF!-#REF!) -> #REF! | D25: =SUM(D23+D24+#REF!-#REF!-#REF!-#REF!) -> #REF! | E25: =+E23+E24 -> 24321173 | F25: =+F23+F24 -> 33090641 | G25: =+G23+G24 -> 1 | H25: =+H23+H24 -> 1 | I25: =+I23+I24 -> 57411814
A27: Dep. Acum. al inicio del periodo | B27: 0 | D27: 0 | E27: 195349 | F27: 564252.85 | H27: 0 | I27: =SUM(B27:H27) -> 759601.85
A28: Cargo del periodo | B28: 0 | C28: 0 | D28: 0 | E28: =787877.58+471807.35+471807.35 -> 1731492.3 | F28: =6630044.48+393060.33+1682881.06 -> 8705985.9 | H28: 0 | I28: =SUM(B28:H28) -> 10437478
A29: Retiros | B29: 0 | C29: 0 | D29: 0 | F29: 0 | G29: 0 | H29: 0 | I29: =SUM(B29:H29) -> 0
A30: Saldo al final del periodo | B30: 0 | C30: 0 | D30: 0 | E30: =+E27+E28 -> 1926841.3 | F30: =+F27+F28 -> 9270238.7 | G30: 0 | H30: 0 | I30: =SUM(B30:H30) -> 11197080
A31: Prop. planta y equipos neto 2023 | B31: =SUM(B25-B30) -> #REF! | C31: =SUM(C25-C27-C28-C29) -> #REF! | D31: =SUM(D25-D30) -> #REF! | E31: =SUM(E25-E30) -> 22394331 | F31: =SUM(F25-F30) -> 23820403 | G31: =SUM(G25-G30) -> 1 | H31: =SUM(H25-H30) -> 1 | I31: =SUM(I25-I27-I28-I29) -> 46214734

Sheet Hoja6

Sheet obligaciones
B4: SERVICIO REGIONAL DE SALUD
B5: DIRECCIÓN DE FISCALIZACIÓN Y CONTROL
B6: DETALLE OBLIGACIONES CONTRAÍDAS PENDIENTES AL 30 DE ABRIL 2025
B7: HOSPITAL MATERNO INFANTIL SAN LORENZO DE LOS MINA
B8: A | C8: B | E8: C | F8: D | G8: E | H8: F
B9: TIPO | C9: PERÍODO | F9: STATUS PRESTAMO
C10: DESDE | D10: HASTA | E10: MONTO | F10: MONTO ORIGEN | G10: MONTO AMORTIZADO | H10: BALANCE PENDIENTE
B11: PROMESE CAL
B12: RETENCIONES DE IMPUESTOS (DGII) | C12: 44470 | D12: 45777 | E12: =6455721.37+191917.63+545919.42+146780.59+231604.06+289366.65+335354.64+387110.47+660164.03+254405.37+295100.71+268154.84+476725.77+301006.83+418780.67+471731.75+276884.63+183994.68 -> 12190724
B13: APROVISIONAMIENTOS DE INCENTIVOS | C13: 45505 | D13: 45777 | E13: =4432093.625+933892.46+332731.24+782528.07-5231553.59 -> 1249691.8
B14: SEGURIDAD SOCIAL
B15: APROVISIONAMIENTO DE REGALIA PASCUAL
B16: PRESTACIONES LABORALES
B17: VIATICOS
B18: PRÉSTAMOS Y/O ANTICIPOS FINANCIEROS OTORGADOS POR SENASA
B19: TOTAL | E19: =SUM(E12:E18)+E11 -> 13440416
B21: Nota. En el caso de las columnas D, E y F, solo aplican para llenado de los préstamos otogados por SENASA.
B25: Preparado por: | E25: Revisado por:

Sheet resumen compras
A1: REPUBLICA DOMINICANA
A2: SERVICIO NACIONAL DE SALUD
A3: LISTADO DE ORDENES DE COMPRAS DURANTE EL MES ABRIL 2024, VENTA DE SERVICIOS
A4: ESTABLECIMIENTO HOSPITAL MATERNO INFANTIL SAN LORENZO DE LOS MINA REGION SANTO DOMINGO ESTE
A5: Fecha | B5: No. Orden de Compra o Servicios | C5: No. De Factura Fiscal NCF | D5: Fuente. Financ FR-VS | E5: Beneficiario | F5: Rubro | G5: No. Cta. Objetal del Gasto | H5: Valor pesos dominicanos
A6: 45383 | B6: HSLM-2024-00285 | C6: HSLM-DAF-CM-2024-0086 | E6: CARLOS RAFAEL DE PAULA ROSSO | F6: 73152102 | G6: 2.2.7.2.08 | H6: 746173
A7: 45383 | B7: HSLM-2024-00286 | C7: HSLM-DAF-CD-2024-0050 | E7: LEFP CONSULTORES, SRL | F7: 81112501 | G7: 2.2.5.9.01 | H7: 195408
A8: 45384 | B8: HSLM-2024-00287 | C8: HSLM-DAF-CD-2024-0104 | E8: OFICLIN COMERCIAL, SRL | F8: 48101516 | G8: 2.6.1.4.01 | H8: 149956.3
A9: 45384 | B9: HSLM-2024-00288 | C9: HSLM-DAF-CD-2024-0105 | E9: G & M GELMAT COMERCIAL, SRL | F9: 52141501 | G9: 2.6.1.4.01 | H9: 211459.92
A10: 45384 | B10: HSLM-2024-00289 | C10: HSLM-DAF-CM-2024-0087 | E10: INSOCORP, SRL | F10: 42295123 | G10: 2.6.3.1.01 | H10: 1716900
A11: 45384 | B11: HSLM-2024-00290 | C11: HSLM-DAF-CM-2024-0085 | E11: BIO NOVA, SRL | F11: 41103001 | G11: 2.6.3.4.01 | H11: 326565
A12: 45384 | B12: HSLM-2024-00291 | C12: HSLM-DAF-CD-2024-0088 | E12: OSIRIS & CO, SA | F12: 42172101 | G12: 2.6.3.1.01 | H12: 609673.18
A13: 45385 | B13: HSLM-2024-00292 | C13: HSLM-DAF-CD-2024-0108 | E13: SAVEV SERVICIOS GENERALES, SRL | F13: 47121701 | G13: 2.3.9.3.01 | H13: 113280
A14: 45385 | B14: HSLM-2024-00293 | C14: HSLM-DAF-CD-2024-0106 | E14: GLOBAL MULTIPHARMA DOMINICANA RHM, SRL | F14: 42132201 | G14: 2.3.9.3.01 | H14: 204000
A15: 45385 | B15: HSLM-2024-00294 | C15: HSLM-DAF-CD-2024-0107 | E15: GLOBAL MULTIPHARMA DOMINICANA RHM, SRL | F15: 42312201 | G15: 2.3.9.3.01 | H15: 108000
A16: 45385 | B16: HSLM-2024-00295 | C16: HSLM-DAF-CD-2024-0103 | E16: ADLER AMICIS VALDEZ MARMOLEJOS | F16: 55121727 | G16: 2.3.9.9.05 | H16: 10620
A17: 45385 | B17: HSLM-2024-00296 | C17: HSLM-DAF-CM-2024-0089 | E17: Xavier Vargas, Ingeniería Electromecánica, EIRL | F17: 72101511 | G17: 2.2.7.2.08 | H17: 397424
... A72: 45401 | B72: HSLM-2024-00351 | C72: HSLM-DAF-CD-2024-0161 | E72: DISTRIBUIDORA RICEA E SANA DI M.C | F72: 42132205 | G72: 2.3.9.3.01 | H72: 177000
A73: 19/4/20224 | B73: HSLM-2024-00352 | C73: HSLM-DAF-CM-2024-0103 | E73: SERVIAMED DOMINICANA, SR. | F73: 42191807 | G73: 2.6.3.1.01 | H73: 254785.6
A74: 45401 | B74: HSLM-2024-00353 | C74: HSLM-DAF-CD-2024-0149 | E74: VENTAS DIVERSAS FARMACEUTICAS,SRL | F74: 51161812 | G74: 2.3.4.1.01 | H74: 6145
A75: 45401 | B75: HSLM-2024-00354 | C75: HSLM-DAF-CD-2024-0152 | E75: SMART SUPPLY MEDICAL DOMINICANA, SRL | F75: 42221503 | G75: 2.3.9.3.01 | H75: 141600
A76: 45401 | B76: HSLM-2024-00355 | C76: HSLM-DAF-CD-2024-0157 | E76: CRISTINA ROSARIO ROSARIO | F76: 48102107 | G76: 2.3.9.9.05 | H76: 60770
A77: 45401 | B77: HSLM-2024-00356 | C77: HSLM-DAF-CM-2024-0104 | E77: JM Distribución, SRL | F77: 14111704 | G77: 2.3.2.3.01 | H77: 416249.13
A78: 45404 | B78: HSLM-2024-00357 | C78: HSLM-DAF-CD-2024-0158 | E78: TENDAMED, SRL | F78: 42271903 | G78: 2.3.9.3.01 | H78: 78824
A79: 45404 | B79: HSLM-2024-00358 | C79: HSLM-DAF-CD-2024-0159 | E79: COMPRA-MED, SRL | F79: 42312202 | G79: 2.3.9.3.01 | H79: 159300
A80: 45404 | B80: HSLM-2024-00359 | C80: HSLM-DAF-CD-2024-0160 | E80: IMPRESOS C Y M, SRL | F80: 53101502 | G80: 2.3.2.3.01 | H80: 46728
A81: 45404 | B81: HSLM-2024-00360 | C81: HSLM-DAF-CD-2024-0156 | E81: ROPHARMA, SRL | F81: 51161703 | G81: 2.3.4.1.01 | H81: 254450
A82: 45404 | B82: HSLM-2024-00361 | C82: HSLM-DAF-CD-2024-0156 | E82: ROPHARMA, SRL | F82: 51161703 | G82: 2.3.4.1.01 | H82: 140850
A83: 45405 | B83: HSLM-2024-00362 | C83: HSLM-DAF-CD-2024-0163 | E83: SLYKING GROUP, SRL | F83: 80141607 | G83: 2.2.8.6.01 | H83: 174451.2
A84: 45405 | B84: HSLM-2024-00363 | C84: HSLM-DAF-CD-2024-0164 | E84: VENDIFAR, SRL | F84: 51161703 | G84: 2.3.4.1.01 | H84: 190000
A85: 45405 | B85: HSLM-2024-00364 | C85: HSLM-DAF-CD-2024-0166 | E85: MUEBLES OMAR | F85: 42221503 | G85: 2.3.9.3.01 | H85: 88087
... A101: 45407 | B101: HSLM-2024-00380 | C101: HSLM-DAF-CD-2024-0178 | E101: Q&Q Medical RD, SRL | F101: 41116003 | G101: 2.3.7.2.03 | H101: 80363.9
A102: 45407 | B102: HSLM-2024-00381 | C102: HSLM-DAF-CM-2024-0114 | E102: ARDAN, SRL | F102: 81112501 | G102: 2.2.5.9.01 | H102: 1726924.1
A103: 45408 | B103: HSLM-2024-00382 | C103: HMISLM-DAF-CD-2024-0179 | E103: BAUCOMER, SRL | F103: 51131801 | G103: 2.3.4.1.01 | H103: 226745
A104: 45412 | B104: HSLM-2024-00383 | C104: HMISLM-DAF-CD-2024-0181 | E104: COPEM HOSPICLINIC, SRL | F104: 42142503 | G104: 2.3.9.3.01 | H104: 149665.3
A105: 45412 | B105: HSLM-2024-00384 | C105: HMISLM-DAF-CD-2024-0180 | E105: IGBT SRL | F105: 73152102 | G105: 2.2.7.2.08 | H105: 233640
A106: 45412 | B106: HSLM-2024-00385 | C106: HSLM-DAF-CM-2024-0116 | E106: JM Distribución, SRL | F106: 52151503 | G106: 2.3.9.5.01 | H106: 771696.55
A107: 45412 | B107: HSLM-2024-00386 | C107: HSLM-DAF-CM-2024-0117 | E107: EXPRES SERVICE CONSERG EXSERCON, SRL | F107: 42295112 | G107: 2.3.9.6.01 | H107: 1156400
A108: 45412 | B108: HSLM-2024-00387 | C108: HSLM-DAF-CD-2024-0119 | E108: EXPRES SERVICE CONSERG EXSERCON, SRL | F108: 42295112 | G108: 2.3.9.6.01 | H108: 826000
A109: 45412 | B109: HSLM-2024-00388 | C109: HSLM-DAF-CM-2024-0120 | E109: MANTENERGIA ELECTRICA Y ABASTECIMIENTOS, SRL | F109: 73152102 | G109: 2.2.8.7.06 | H109: 1184600.7
...

Sheet CXC
A4: HOSPITAL MATERNO INFANTIL SAN LORENZO DE LOS MINA
A5: CUENTAS POR COBRAR ARS AÑO 2025
A7: Auxiliar Cuentas por Cobrar SeNaSa Subsidiado
J8: Balance Anterior | K8: 2710241.1
A9: ARS | B9: FECHA DE CORTE AUDITORIA | C9: CANTIDAD DE EXPEDIENTES | D9: MONTO GENERAL DE FACTURACION | E9: MONTO AUDITADO | F9: MONTO GLOSADO | G9: % | H9: Valor Facturado | I9: Referencia Documento de pago (CK-T) | J9: Monto pagado | K9: Balance CxC
A10: ARS SENASA SUBSIDIADO | B10: 45657 | D10: 4014536.9 | E10: 4014536.9 | F10: 85535 | G10: =+F10/E10 -> 0.021306318 | H10: 3929001.9 | K10: =+K8+H10 -> 6639243
A11: ARS SENASA SUBSIDIADO | I11: 02/01/2025 | J11: 4783111.5 | K11: =+K10+H11-J11 -> 1856131.5
A12: ARS SENASA SUBSIDIADO | I12: 09/01/2025 | J12: 50000 | K12: =+K11+H12-J12 -> 1806131.5
A13: ARS SENASA SUBSIDIADO | B13: 45688 | D13: 4840265.3 | E13: 4840265.3 | F13: 147829.22 | G13: =+F13/E13 -> 0.030541553 | H13: =+E13-F13 -> 4692436.1 | K13: =+K12+H13-J13 -> 6498567.6
A14: ARS SENASA SUBSIDIADO | B14: 45693 | J14: 5841673.2 | K14: =+K13+H14-J14 -> 656894.41
A15: ARS SENASA SUBSIDIADO | D15: 3228340.8 | E15: 3228340.8 | F15: 81431.03 | G15: =+F15/E15 -> 0.025223803 | H15: =+E15-F15 -> 3146909.7 | K15: =+K14+H15-J15 -> 3803804.1
A16: ARS SENASA SUBSIDIADO | B16: 45716 | J16: =4595181.39+50000 -> 4645181.4 | K16: =+K15+H16-J16 -> -841377.26
A17: ARS SENASA SUBSIDIADO | B17: 45747 | D17: 3267715.2 | E17: =+D17 -> 3267715.2 | F17: 68054 | G17: =+F17/E17 -> 0.020826172 | H17: =+E17-F17 -> 3199661.2 | I17: 1/4/2025 | J17: 2942930.3 | K17: =+H17-J17+K16 -> -584646.35
A18: ARS SENASA SUBSIDIADO | I18: 01/04/2025 | J18: 50000 | K18: =+H18-J18+K17 -> -634646.35
I19: 03/04/2025 | J19: 50000 | K19: =+H19-J19+K18 -> -684646.35
A20: TOTALES | D20: =SUM(D10:D19) -> 15350858 | E20: =SUM(E10:E19) -> 15350858 | F20: =SUM(F10:F19) -> 382849.25 | G20: =SUM(G10:G19) -> 0.097897846 | H20: =SUM(H10:H19) -> 14968009 | I20: =SUM(I10:I19) -> 0 | J20: =SUM(J10:J19) -> 18362896 | K20: =+K19 -> -684646.35
A23: Auxiliar Cuentas por Cobrar Ars Privadas
I24: BALANCE ANTERIOR | J24: 15638558
A25: ARS | B25: FECHA DE CORTE | C25: NCF | D25: CANTIDAD DE FACTURAS | E25: MONTO FACTURADO | F25: Referencia Documento de pago (CK-T) | G25: MONTO GLOSADO | H25: MONTO PAGADO | I25: DESMONTE POSTERIOR AL PAGO | J25: Balance CxC
A26: HUMANO | B26: 45667 | C26: B0100001070 | E26: 44770.98 | J26: =+J24+E26-H26 -> 15683329
A27: P. HUMANO | B27: 45667 | C27: B0100001071 | E27: 259154.57 | J27: =+J26+E27-G27-H27 -> 15942483
A28: MAPFRE AMB. | B28: 45667 | C28: B0100001072 | E28: 39434.4 | J28: =+J27+E28-G28-H28 -> 15981917
A29: MAPFRE EMERG. | B29: 45667 | C29: B0100001073 | E29: 16378.75 | J29: =+J28+E29-G29-H29 -> 15998296
A30: MAPFRE HOSP. | B30: 45667 | C30: B0100001074 | E30: 155901.42 | J30: =+J29+E30-G30-H30 -> 16154198
A31: RENACER | B31: 45667 | C31: B0100001075 | E31: 275352.44 | J31: =+J30+E31-G31-H31 -> 16429550
A32: YUNEN | B32: 45667 | C32: B0100001076 | E32: 7848.94 | J32: =+J31+E32-G32-H32 -> 16437399
A33: ASEMAP | B33: 45667 | C33: B0100001077 | E33: 4869.52 | J33: =+J32+E33-G33-H33 -> 16442269
A34: FUTURO | B34: 45667 | C34: B0100001078 | E34: 269639.73 | G34: 2300 | J34: =+J33+E34-G34-H34 -> 16709608
A35: MONUMENTAL | B35: 45667 | C35: B0100001079 | E35: 75131.09 | J35: =+J34+E35-G35-H35 -> 16784739
A36: RESERVAS | B36: 45667 | C36: B0100001080 | E36: 48081.02 | J36: =+J35+E36-G36-H36 -> 16832820
A37: CMD | B37: 45667 | C37: B0100001081 | E37: 273646.7 | J37: =+J36+E37-G37-H37 -> 17106467
A38: META SALUD | B38: 45667 | C38: B0100001082 | E38: 1396 | J38: =+J37+E38-G38-H38 -> 17107863
A39: SIMAG | B39: 45667 | C39: B0100001083 | E39: 28637.51 | J39: =+J38+E39-G39-H39 -> 17136501
A40: GMA | B40: 45667 | C40: B0100001084 | E40: 76159.34 | J40: =+J39+E40-G40-H40 -> 17212660
A41: APS | B41: 45667 | C41: B0100001085 | E41: 69588.33 | J41: =+J40+E41-G41-H41 -> 17282248
A42: RENACER | B42: 45674 | H42: 156983.55 | J42: =+J41+E42-G42-H42 -> 17125265
A43: MAPFRE AMB. | B43: 45677 | H43: 143189.49 | J43: =+J42+E43-G43-H43 -> 16982075
A44: MAPFRE EMERG. | B44: 45677 | H44: 55488.8 | J44: =+J43+E44-G44-H44 -> 16926586
A45: MAPFRE HOSP. | B45: 45677 | H45: 8230.16 | J45: =+J44+E45-G45-H45 -> 16918356
A46: ARS SEMMA | B46: 45677 | H46: 15993.02 | J46: =+J45+E46-G46-H46 -> 16902363
...

Sheet CUENTAS POR PAGAR
A1: Servicio Nacional de Salud
A2: DIRECCION DE FISCALIZACION
A3: RELACION DEUDA
A4: ESTABLECIMIENTO: | B4: HOSPITAL MATERNO INFANTIL SAN LORENZO DE LOS MINA | D4: CUENTAS POR PAGAR A: | E4: 45748
A6: NO | B6: NOMBRES PROVEEDOR | C6: CONCEPTO | D6: FUENTE FINANCIMIENTO | E6: Años anteriores 2020 | F6: AL 31 DICIEMBRE 2021 | G6: AL 31 DICIEMBRE 2022 | H6: AL 31 DICIEMBRE 2023 | I6: Al 31 DICIEMBRE 2024 | J6: AL 31 DE ENERO 2025 | K6: AL 28 DE FEBRERO 2025 | L6: 31 DE MARZO 2025 | M6: 30 DE ABRIL 2025 | N6: TOTAL ADEUDA
A7: 1 | B7: Hospifar, SRL | D7: VS/FG | H7: 94965 | N7: =SUM(E7:M7) -> 94965
A8: =+A7+1 -> 2 | B8: Hospifar, SRL | D8: VS/FG | H8: 11375 | N8: =SUM(E8:M8) -> 11375
A9: =+A8+1 -> 3 | B9: Ventas Diversas Farmaceuticas, SRL (VENDIFAR) | D9: VS/FG | H9: 224775 | N9: =SUM(E9:M9) -> 224775
A10: =+A9+1 -> 4 | B10: GA INTERPRISE IMPORT, SRL | D10: VS/FG | H10: 287920 | N10: =SUM(E10:M10) -> 287920
A11: =+A10+1 -> 5 | B11: D, CORA INDUSTRIAL, S.R.L | D11: VS/FG | H11: 220483.05 | N11: =SUM(E11:M11) -> 220483.05
A12: =+A11+1 -> 6 | B12: VARA, SRL. | D12: VS/FG | H12: 58382.86 | N12: =SUM(E12:M12) -> 58382.86
A13: =+A12+1 -> 7 | B13: Ventas Diversas Farmaceuticas, SRL (VENDIFAR) | D13: VS/FG | H13: 171690 | N13: =SUM(E13:M13) -> 171690
A14: =+A13+1 -> 8 | B14: Morami, SRL | D14: VS/FG | H14: 213260 | N14: =SUM(E14:M14) -> 213260
A15: =+A14+1 -> 9 | B15: Leromed Pharma, SRL | D15: VS/FG | H15: 167208 | N15: =SUM(E15:M15) -> 167208
A16: =+A15+1 -> 10 | B16: Caribbean Integrated Solutions, SRL | D16: VS/FG | H16: 400 | N16: =SUM(E16:M16) -> 400
A17: =+A16+1 -> 11 | B17: Insocorp, S.R.L. | D17: VS/FG | H17: 150096 | N17: =SUM(E17:M17) -> 150096
A18: =+A17+1 -> 12 | B18: SLYKING GROUP, SRL | D18: VS/FG | I18: 39361.26 | N18: =SUM(E18:M18) -> 39361.26
A19: =+A18+1 -> 13 | B19: FARMACIA RUTH | D19: VS/FG | I19: 88100 | N19: =SUM(E19:M19) -> 88100
A20: =+A19+1 -> 14 | B20: Macrotech Farmacéutica, SRL | D20: VS/FG | I20: 215000 | N20: =SUM(E20:M20) -> 215000
A21: =+A20+1 -> 15 | B21: LE.F.P CONSULTORES SRL | D21: VS/FG | I21: 48852 | N21: =SUM(E21:M21) -> 48852
A22: =+A21+1 -> 16 | B22: LE.F.P CONSULTORES SRL | D22: VS/FG | I22: 48852 | N22: =SUM(E22:M22) -> 48852
A23: =+A22+1 -> 17 | B23: Bio Nova, SRL | D23: VS/FG | I23: 14391 | N23: =SUM(E23:M23) -> 14391
A24: =+A23+1 -> 18 | B24: FARMACIA RUTH | D24: VS/FG | I24: 3450 | N24: =SUM(E24:M24) -> 3450
A25: =+A24+1 -> 19 | B25: Insocorp, S.R.L. | D25: VS/FG | I25: 162462.4 | N25: =SUM(E25:M25) -> 162462.4
A26: =+A25+1 -> 20 | B26: FARMACIA RUTH | D26: VS/FG | I26: 77150 | N26: =SUM(E26:M26) -> 77150
A27: =+A26+1 -> 21 | B27: Q&Q Medical RD, SRL | D27: VS/FG | I27: 80363.9 | N27: =SUM(E27:M27) -> 80363.9
A28: =+A27+1 -> 22 | B28: SLYKING GROUP, SRL | D28: VS/FG | I28: 240720 | N28: =SUM(E28:M28) -> 240720
A29: =+A28+1 -> 23 | B29: Ventas Diversas Farmaceuticas, SRL (VENDIFAR) | D29: VS/FG | I29: 190410 | N29: =SUM(E29:M29) -> 190410
... A41: =+A40+1 -> 35 | B41: Gestiones Sanitarias & Ambientales, SRL (GESA) | D41: VS/FG | I41: 39530 | N41: =SUM(E41:M41) -> 39530
A42: =+A41+1 -> 36 | B42: Insocorp, S.R.L. | D42: VS/FG | J42: 20060 | N42: =SUM(E42:M42) -> 20060
A43: =+A42+1 -> 37 | B43: SMART SUPPLY MEDICAL DOMINICANA, SRL | D43: VS/FG | K43: 54008.6 | N43: =SUM(E43:M43) -> 54008.6
A44: =+A43+1 -> 38 | B44: LEHAIM SUMINISTROS SRL | D44: VS/FG | K44: 271400 | N44: =SUM(E44:M44) -> 271400
A45: =+A44+1 -> 39 | B45: LEHAIM SUMINISTROS SRL | D45: VS/FG | K45: 227500 | N45: =SUM(E45:M45) -> 227500
A46: =+A45+1 -> 40 | B46: REGULATORY | D46: VS/FG | K46: 1692273.2 | N46: =SUM(E46:M46) -> 1692273.2
A47: =+A46+1 -> 41 | B47: Insocorp, S.R.L. | D47: VS/FG | K47: 137691.84 | N47: =SUM(E47:M47) -> 137691.84
A48: =+A47+1 -> 42 | B48: CEM CARIBBEAN EQUIPMENT MEDICAL | D48: VS/FG | K48: 846850 | N48: =SUM(E48:M48) -> 846850
A49: =+A48+1 -> 43 | B49: Gastables del Caribe (GADECA),SRL | D49: VS/FG | K49: 263328.8 | N49: =SUM(E49:M49) -> 263328.8
A50: =+A49+1 -> 44 | B50: Super Latop Browsing SRL | D50: VS/FG | L50: 413000 | N50: =SUM(E50:M50) -> 413000
A51: =+A50+1 -> 45 | B51: PATRIA RIVAS LABORATORIO CLINICO | D51: VS/FG | L51: 3500 | N51: =SUM(E51:M51) -> 3500
A52: =+A51+1 -> 46 | B52: Miguelina Vasquez Castillo | D52: VS/FG | L52: 229450 | N52: =SUM(E52:M52) -> 229450
...

Sheet Hoja5
A1: Form. No.6 SRS
A3: Servicio Nacional de Salud
A4: Dirección de Fizcalización
A5: Consolidado de Ingresos y Gastos por Fuente de Financiamiento
A6: HOSPITAL MATERNO INFANTIL SAN LORENZO DE LOS MINA
A7: ABRIL 2025
C8: Ingresos Generales:
E9: 1.- Balance Inicial / Fuente:
E10: Anticipo Financiero | H10: Otros Aportes
E11: Transferencias Corrientes
E12: Venta de Servicios | G12: 4614.79
E13: 2.- Ingresos por Fuente / Cuenta
E14: Anticipo Financiero | H14: Otros Aportes | I14: =+'[12]INGR SEGUN ORIGEN'!E39 -> 214750
E15: Transferencias Corrientes | G15: =+'[12]INGR SEGUN ORIGEN'!E12 -> 1.007793e+08 | H15: Aportes Nomina SNS | I15: 0
E16: Venta de Servicios | G16: =+'[12]INGR SEGUN ORIGEN'!E32 -> 6892064.8
H17: TOTAL INGRESOS RDS | I17: =+G10+G11+G12+I10+G14+G15+G16+I14+I15 -> 1.0789073e+08
A21: 1 | F21: 2 | G21: 3 | I21: 4 | J21: 5
A22: Código Presupuestario | F22: Descripción Gasto por Cuenta | G22: Distribución del Gasto por Fuente de Financiamiento | I22: TOTAL | J22: %
A23: Tipo | B23: Objeto | C23: Cuenta | D23: Sub-Cuenta | E23: Auxiliar | G23: Fondo 100 | H23: Venta de Servicios/ Otros Aportes
A25: 2 | F25: Gastos | G25: =+G26+G87+G212+G330+G336+G463 -> 91800340 | H25: =+H26+H87+H212+H330+H336+H463 -> 4881550.3 | I25: =SUM(G25:H25) -> 96681890 | J25: =+J26+J87+J212+J330+J336+J463 -> 1
A26: 2 | B26: 1 | F26: Servicios Personales | G26: =+G27+G51+G64+G71+G78 -> 66556156 | H26: =+H27+H51+H64+H71+H78 -> 0 | I26: =SUM(G26:H26) -> 66556156 | J26: =I26/$I$25 -> 0.68840355
A27: 2 | B27: 1 | C27: 1 | F27: Remuneraciones | G27: =+G28+G35+G42+G44+G46 -> 54771097 | H27: =+H28+H35+H42+H44+H46 -> 0 | I27: =SUM(G27:H27) -> 54771097 | J27: =I27/$I$25 -> 0.56650834
A28: 2 | B28: 1 | C28: 1 | D28: 1 | F28: Remuneraciones al personal fijo | G28: =SUM(G29:G34) -> 53482455 | H28: =SUM(H29:H34) -> 0 | I28: =SUM(G28:H28) -> 53482455 | J28: =I28/$I$25 -> 0.55317966
