Workbook

Sheet RELACION DE PAGOS EMITIDOS
A5: DIRECCION DE FISCALIZACION Y CONTROL
A6: RELACION DE PAGOS EMITIDOS DURANTE EL MES
A7: ESTABLECIMIENTO:HOSPITAL MATERNO INFANTIL SAN LORENZO DE LOS MINA
A9: PAGOS CORRESPONDIENTES AL MES : JULIO 2025
A10: FECHA | B10: LIBRAMIENTO | C10: TRANSFERENCIA | D10: CHEQUE | E10: BENEFICIARIO | F10: NO.FACTURAS | G10: VALOR DE FACTURA | H10: VALOR PAGADO
A11: 45842 | C11: 208 | E11: TROPIGAS DOMINICANA SRL | F11: PAGO NCF E450000005443 ADQUISICION DE GAS LICUADO DE PETROLEO SEGÚN ORDEN DE COMPRA HSLM-2025-00066. | G11: 22638 | H11: 22638
A12: 45842 | C12: 209 | E12: P&D RECYCLING SRL | F12: PAGO NCF B1500000313 SERVICIO DE RECOGIDA DE DESESCHOS SOLIDOS SEGÚN O/C HSLM-2025-00578. | G12: 760000 | H12: 722000
A13: 45842 | C13: 210 | E13: FILIDENNY RODRIGUEZ DE ACEVEDO | F13: PAGO DE REGALIA PASCUAL PERSONAL FIJOS INACTIVOS 2024, DEBIDO A QUE SU CUENTA FUE CERRADA. | G13: 19496.18 | H13: 19496.18
A14: 45842 | C14: 211 | E14: JULIO CESAR GONZALEZ | F14: PAGO DE PRESTACIONES LABORALES POR VACACIONES NO DISFRUTADAS MAYO 2025, DEBIDO A QUE SU CUENTA FUE CERRADA. | G14: 8860.18 | H14: 8860.18
A15: 45842 | C15: 212 | E15: NEGOCIOS SUHEIDY RODRIGUEZ, SRL | F15: PAGO DE FACTURA NCF NO B1500000110, POR ADQUISICION DE TARIMAS PLASTICAS, SEGÚN ORDEN DE COMPRA HSLM-2025-00626 | G15: 118075.52 | H15: 113072.32
A16: 45845 | C16: 213 | E16: LABORATORIO CLINICO LICDA PATRIA RIVAS, SRL | F16: PAGO DE FACT NCF NO E450000000049, POR SERVICIO DE ESTUDIOS ESPECIALIZADOS SEGÚN ORDEN DE COMPRA HSLM-2025-00312 | G16: 14160 | H16: 14160
A17: 45845 | C17: 214 | E17: CENTRO DE LA SANGRE Y ESPECIALIDADES Y ESPECIALIDADES SRL | F17: PAGO NCF B1500000403 SERVICIO DE SANGRE PARA PACIENTES INTERNOS SEGÚN O/C HSLM-2025-00428. | G17: 24000 | H17: 22800
A18: 45845 | C18: 215 | E18: NEGOCIOS SUHEIDY RODRIGUEZ, SRL | F18: PAGO DE FACT NCF B1500000108, POR ADQUISICION DE FUNDAS PLASTICAS, SEGÚN ORDEN DE COMPRA HSLM-2025-00614 | G18: 1230740 | H18: 1178590
A19: 45845 | C19: 216 | E19: SERVICIO DE BIOMEDICINA MEDICO SERBIOMED SRL | F19: PAGO DE FACT NCF NO. B1500000226, POR ADQUISICION DE KIT DE PRUEBA DE ESTERILIZADOR DE VACIO DE PULSO MARCA SHINVA DE 350, SEGÚN ORDEN DE COMPRA HSLM-2025-00526 | G19: 247800 | H19: 237300
A20: 45845 | C20: 217 | E20: SERVICIO DE BIOMEDICINA MEDICO SERBIOMED SRL | F20: PAGO DE FACT NCF NO. B1500000225, POR SERVICIO DE MANTENIMIENTO PREVENTIVO DE AUTOCLAVE SHINVA 350 LITRO, SEGÚN ORDEN DE SERVICIO HSLM-2025-00528 | G20: 212400 | H20: 203400
A21: 45845 | C21: 218 | E21: CABOD, SRL | F21: PAGO DE FACT NCF NO. B1500001808 Y B1500001802, POR ADQUISICION DE DETERGENTE PARA LAVANDERIA, SEGÚN ORDEN DE COMPRA HSLM-2025-00615 | G21: 409306.6 | H21: 391963.1
A22: 45845 | C22: 219 | E22: XAVIER VARGAS, INGENIERIA ELECROMECANICA, EIRL | F22: PAGO DE FACT NCF NO. B1500000249, POR SERVICIO DE MANTENIMIENTO DE AIRES ACONDICIONADOS, SEGÚN ORDEN DE SERVICIO NO. HSLM-2025-00570 | G22: 594720 | H22: 569520
... A49: 45869 | C49: 247 | E49: LILIAN YOMAYRA ENCARNACION | F49: pago de regencia en permiso de drogas y farmacia, perteneciente al mes de julio 2025 | G49: 10000 | H49: 10000
A50: 45839 | D50: 37252 | E50: FREDY OSCAR RODRIGUEZ RIVAS | F50: COLABORACION PARA CAVAR HOYO Y CERTIFICACION DE ACTAS DE DEFUNCION | G50: 3600 | H50: 3600
A51: 45841 | D51: =+D50+1 -> 37253 | E51: PAOLA VIRIGILIO JAVIER | F51: COLABORACION PARA LA PACIENTE R/N PAOLA JAVIER LA CUAL SE LE REALIZARA UN DOPPLER CEREBRAL PARA DESCARTAR MUERTE CEREBRAL | G51: 10000 | H51: 10000
A52: 45841 | D52: =+D51+1 -> 37254 | E52: ISMAEL TEJEDA SIGARAN | F52: PAGO POR SERVICIO DE TRASLADO DE INSUMO DEL AREA DE FARMACIA. | G52: 18061.23 | H52: 15000
A53: 45841 | D53: =+D52+1 -> 37255 | E53: DELMIRA GARCIA | F53: REPICION DE FONDO DE CAJA CHICA | G53: 55105.58 | H53: 55105.58
A54: 45848 | D54: =+D53+1 -> 37256 | E54: OLEGARIO GUERRERO | F54: PAGO DE FACT NCF B1100000054 POR SERVICIO DE JARDINERIA DEL AREA VERDE Y PODA DE ARBOLES EXTERIOR E INTERIOR DE ESTE HOSPITAL. | G54: 9632.66 | H54: 8000
A55: 45848 | D55: =+D54+1 -> 37257 | E55: ESTHERLING YUBANET LARA DE LOS SANTOS | F55: PAGO DE FACT NCF B1100000053 POR SERVICIO DE REPARACION DE REBANADORA DEL AREA DE COCINA DE ESTE HOSPITAL. | G55: 12402.05 | H55: 10300
A56: 45853 | D56: =+D55+1 -> 37258 | E56: CRISTIAN ERASMO VENTURA | F56: PAGO DE FACT NCF B1100000055 POR SERVICIO DE CONFECCION DE 2 TAPAS DE REGISTROS, CONFECCION DE VERJAS PROTECTORAS PERIMETRAL, REPARACION DE LA PUERTA DE ENTRADA A CUARTO DE BOMBA Y REPARACION DE 2 BANCADAS DEL HOSPITAL | G56: 36122.46 | H56: 30000.01
A57: 45856 | D57: =+D56+1 -> 37259 | E57: ABRAHAN JOSE MENDOZA | F57: PAGO DE FACT NCF B1100000056 POR SERVICIO DE MANTENIMIENTO DE REMIENDO DE PARQUEO EN LAS EMERGENCIAS Y OBSTETRICIA, RESANE DE PAREDES DE DISTINTAS AREAS DEL HOSPITAL | G57: 8428.57 | H57: 7000
A58: 45859 | D58: =+D57+1 -> 37260 | E58: ABRAHAN JOSE MENDOZA | F58: PAGO DE FACT NCF B1100000057 POR SERVICIO DE REPARACION DE HUECO Y PULIDO DE PARED DEL DEPTO DE LABORATORIO DEL HOSPITAL | G58: 22877.56 | H58: 19000
A59: 45860 | D59: =+D58+1 -> 37261 | E59: NULO | F59: NULO | G59: 0
A60: 45860 | D60: =+D59+1 -> 37262 | E60: SANDRA TOLENTINO MARTINEZ | F60: PAGO POR SERVICIO DE ECOCARDIOGRAMA Y EVALUACION CARDIOVASCULAR PARA 7 PACIENTES INGRESADOS EN EL HOSPITAL A UN COSTO DE RD$3,000.00 C/U | G60: 21000 | H60: 21000
A61: 45860 | D61: =+D60+1 -> 37263 | E61: ALEXANDER MENDEZ CONTRERAS | F61: PAGO POR EL SERVICIO DE JARDINERIA Y MANTENIMIENTO DE AREAS VERDES DE ESTE HOSPITAL | G61: 18061.22 | H61: 15000
A62: 45860 | D62: =+D61+1 -> 37264 | E62: RUDDY SEGURA | F62: PAGO POR EL SERVICIO DE LIMPIEZA Y CLORIFICACION DE LAS CISTERNAS DE ESTE HOSPITAL | G62: 21673.47 | H62: 18000.01
A63: 45860 | D63: =+D62+1 -> 37265 | E63: NELSON YNFANTE VELAZQUEZ | F63: PAGO DE FACT NCF B1100000060 POR SERVICIO DE PINTURA PARA DIFERENTES AREAS DEL HOSPITAL | G63: 18061.22 | H63: 15000
A64: 45860 | D64: =+D63+1 -> 37266 | E64: NULO | F64: NULO | G64: 0
A65: 45860 | D65: =+D64+1 -> 37267 | E65: FREDY OSCAR RODRIGUEZ RIVAS | F65: COLABORACION PARA CAVAR HOYO Y CERTIFICACION DE ACTAS DE DEFUNCION. | G65: 3600 | H65: 3600
A66: 45860 | D66: =+D65+1 -> 37268 | E66: Ovidio De Jesús Duran Clemente | F66: PAGO POR SERVICIO DE TRANSPORTE DE LA AMBULANCIA CORRESPONDIENTE AL MES DE JULIO 2025 | G66: 20000 | H66: 20000
A67: 45867 | D67: 37269 | E67: DELMIRA GARCIA | F67: REPICION DE FONDO DE CAJA CHICA | G67: 54251.88 | H67: 54251.88
A68: 45867 | D68: 37270 | E68: EMMANUEL JIMENEZ | F68: PAGO POR SERVICIO DE TERAPIA FISICA A PACIENTE INGRESADA | G68: 22500 | H68: 22500
A69: 45867 | D69: 37271 | E69: RAFAEL ELIGIO MORENO MARTINEZ | F69: PAGO POR SERVICIO DE ANALISIS PARA LA PACIENTE CARINE OLIVER INGRESADA EN LA INSTITUCION | G69: 7871 | H69: 7871
A70: 01/07/2025 | B70: 2719 | E70: Macrotech Farmacéutica, SRL | F70: PAGO DE FACT NCF E450000001047 POR ADQUISICION DE UTILES MEDICOS SEGUN O/C HSLM-2025-00593. | G70: 578891.48
A71: 01/07/2025 | B71: 2724 | E71: Khris Aus Pharmacy, S.R.L | F71: PAGO DE FACT NCF B1500000155 POR ADQUISICION DE MEDICAMENTOS SEGUN O/C HSLM-2025-00601. | G71: 180000
...

Sheet RELACION ORDENES DE COMPRAS
A4: SERVICIO NACIONAL DE SALUD
A5: DIRECCION DE FISCALIZACION
A6: RELACIÓN DE ORDENES DE COMPRAS DE BIENES Y SERVICIOS EFECTUADAS.
A7: ESTABLECIMIENTO: HOSPITAL MATERNO INFANTIL SAN LORENZO DE LOS MINA REGION OZAMA, MES DE JULIO 2025
A8: Fecha | B8: # Orden de Compra o Servicios | C8: # DE EXPEDIENTE(PROCESO CELEBRADO) | D8: No. De Factura Fiscal NCF | E8: Fuente. Financ (FR-VS) | F8: Beneficiario | G8: Rubro | H8: No. Cta. Objetal del Gasto | I8: Valor | J8: Status del proceso | K8: solo observar cuando se presentas esos procesos
A9: 45841.626 | B9: HSML-2025-00632 | C9: HSLM-DAF-CD-2025-0494 | E9: VS/FG | F9: Express Service Conserg Exsercon, SRL | G9: 42290000 | H9: Productos quirúrgicos | I9: 270820 | J9: Adjudicado
A10: 45841.626 | B10: HSML-2025-00631 | C10: HSLM-DAF-CD-2025-0495 | E10: VS/FG | F10: Express Service Conserg Exsercon, SRL | G10: 51160000 | H10: Medicamentos que afectan al sistema respiratorio | I10: 217120 | J10: Adjudicado
A11: 45842.668 | B11: HSML-2025-00677 | C11: HSLM-DAF-CM-2025-0165 | E11: VS/FG | F11: Actualidades VD, SRL | G11: 52140000 | H11: Aparatos electrodomésticos | I11: 177047 | J11: Adjudicado
A12: 45848.419 | B12: HSML-2025-00653 | C12: HSLM-DAF-CD-2025-0516 | E12: VS/FG | F12: Morami, SRL | G12: 42140000 | H12: Suministros, productos de tratamiento y cuidado del enfermo | I12: 206500 | J12: Adjudicado
A13: 45848.459 | B13: HSML-2025-00655 | C13: HSLM-DAF-CD-2025-0517 | E13: VS/FG | F13: Baucomer, SRL | G13: 51180000 | H13: Hormonas y antagonistas hormonales | I13: 245000 | J13: Adjudicado
A14: 45852.459 | B14: HSML-2025-00669 | C14: HSLM-DAF-CD-2025-0532 | E14: VS/FG | F14: Bio Win, SRL | G14: 41110000 | H14: Instrumentos de medida, observación y ensayo | I14: 30000 | J14: Adjudicado
A15: 45853.542 | B15: HSML-2025-00680 | C15: HSLM-DAF-CD-2025-0540 | E15: VS/FG | F15: AGROGLOBAL EXPORT E IMPORT, SRL | G15: 24110000 | H15: Recipientes y almacenamiento | I15: 63720 | J15: Adjudicado
A16: 45859.479 | B16: HSML-2025-00702 | C16: HSLM-DAF-CD-2025-0555 | E16: VS/FG | F16: Papelería E. Impresos Crishoan, SRL | G16: 47120000 | H16: Equipo de aseo | I16: 53336 | J16: Adjudicado
A17: 45859.585 | B17: HSML-2025-00727 | C17: HSLM-DAF-CD-2025-0557 | E17: VS/FG | F17: INSOCORP, SRL | G17: 42270000 | H17: Productos de resucitación, anestesia y respiratorio | I17: 47200 | J17: Adjudicado
A18: 45859.585 | B18: HSML-2025-00724 | C18: HSLM-DAF-CM-2025-0177 | E18: VS/FG | F18: INSOCORP, SRL | G18: 42290000 | H18: Productos quirúrgicos | I18: 1945820 | J18: Adjudicado
A19: 45861.376 | B19: HSML-2025-00710 | C19: HSLM-DAF-CD-2025-0563 | E19: VS/FG | F19: Morami, SRL | G19: 42140000 | H19: Suministros, productos de tratamiento y cuidado del enfermo | I19: 236000 | J19: Adjudicado
A20: 45861.444 | B20: HSML-2025-00712 | C20: HSLM-DAF-CD-2025-0566 | E20: VS/FG | F20: Ropharma, SRL | G20: 51190000 | H20: Agentes que afectan el agua y los electrolitos | I20: 136500 | J20: Adjudicado
... A27: 45866.459 | B27: HSML-2025-00754 | C27: HSLM-DAF-CM-2025-0182 | E27: VS/FG | F27: Farmaco Internacional, SRL | G27: 51100000 | H27: Medicamentos antiinfecciosos | I27: 294470 | J27: Adjudicado
A28: 45866.459 | B28: DECIERTO | C28: HSLM-DAF-CD-2025-0574 | E28: VS/FG | G28: 78180000 | H28: Servicios de mantenimiento o reparaciones de transportes | J28: Desierto
A29: 45866.502 | B29: HSML-2025-00733 | C29: HSLM-DAF-CD-2025-0577 | E29: VS/FG | F29: INSOCORP, SRL | G29: 42310000 | H29: Productos para el cuidado de heridas | I29: 247800 | J29: Adjudicado
A30: 45866.542 | B30: HSML-2025-00731 | C30: HSLM-DAF-CD-2025-0580 | E30: VS/FG | F30: INSOCORP, SRL | G30: 42290000 | H30: Productos quirúrgicos | I30: 59000 | J30: Adjudicado
A31: 45866.542 | B31: HSML-2025-00740 | C31: HSLM-DAF-CD-2025-0578 | E31: VS/FG | F31: Ofitop, S.R.L | G31: 56100000 | H31: Muebles de alojamiento | I31: 262509 | J31: Adjudicado
A32: 45866.542 | B32: HSML-2025-00732 | C32: HSLM-DAF-CD-2025-0579 | E32: VS/FG | F32: INSOCORP, SRL | G32: 42130000 | H32: Telas y vestidos médicos | I32: 271254 | J32: Adjudicado
A33: 45866.584 | B33: HSML-2025-00755 | C33: HSLM-DAF-CM-2025-0183 | E33: VS/FG | F33: INSOCORP, SRL | G33: 41110000 | H33: Instrumentos de medida, observación y ensayo | I33: 1456293.2 | J33: Evaluación
A34: 45866.584 | B34: HSML-2025-00739 | C34: HSLM-DAF-CD-2025-0582 | E34: VS/FG | F34: Khris Aus Pharmacy, S.R.L | G34: 42310000 | H34: Productos para el cuidado de heridas | I34: 160000 | J34: Adjudicado
A35: 45866.626 | B35: HSML-2025-00741 | C35: HSLM-DAF-CD-2025-0583 | E35: VS/FG | F35: Abrias Novo Group SRL | G35: 56110000 | H35: Muebles comerciales e industriales | I35: 80523 | J35: Adjudicado
A36: 45867.419 | B36: HSML-2025-00747 | C36: HSLM-DAF-CD-2025-0585 | E36: VS/FG | F36: Ofitop, S.R.L | G36: 56110000 | H36: Muebles comerciales e industriales | I36: 264511 | J36: Adjudicado
A37: 45867.459 | B37: HSML-2025-00738 | C37: HSLM-DAF-CD-2025-0588 | E37: VS/FG | F37: I.V. Biodesinfección, SRL | G37: 76100000 | H37: Servicios de descontaminación | I37: 9912 | J37: Adjudicado
A38: 45867.502 | B38: HSML-2025-00742 | C38: HSLM-DAF-CD-2025-0589 | E38: VS/FG | F38: Adler Amicis Valdez Marmolejos | G38: 82120000 | H38: Servicios de reproducción | I38: 167560 | J38: Adjudicado
A39: 45869.419 | B39: Analisis de oferta | C39: HSLM-DAF-CM-2025-0186 | E39: VS/FG | G39: 43210000 | H39: Equipo informático y accesorios | J39: Publicado
A40: 45869.427 | B40: HSML-2025-00751 | C40: HSLM-DAF-CD-2025-0596 | E40: VS/FG | F40: Asenp Quality Consulting,SRL | G40: 42290000 | H40: Productos quirúrgicos | I40: 70092 | J40: Adjudicado
A41: 45869.465 | B41: HSML-2025-00748 | C41: HSLM-DAF-CD-2025-0597 | E41: VS/FG | F41: Gestiones Sanitarias & Ambientales, SRL (GESA) | G41: 42260000 | H41: Equipo y suministros post mortem y funerarios | I41: 18290 | J41: Adjudicado
A42: 45869.502 | B42: HSML-2025-00749 | C42: HSLM-DAF-CD-2025-0599 | E42: VS/FG | F42: Morami, SRL | G42: 42290000 | H42: Productos quirúrgicos | I42: 106200 | J42: Adjudicado
A43: 45869.502 | B43: HSML-2025-00750 | C43: HSLM-DAF-CD-2025-0598 | E43: VS/FG | F43: Compra-Med, SRL | G43: 51160000 | H43: Medicamentos que afectan al sistema respiratorio | I43: 112995 | J43: Adjudicado
A44: 45869.376 | B44: Cancelado | C44: HSLM-DAF-CD-2025-0594 | E44: VS/FG | G44: 50130000 | H44: Productos lácteos y huevos | J44: Cancelado
A45: 45868.543 | B45: Analisis de oferta | C45: HSLM-DAF-CM-2025-0184 | E45: VS/FG | G45: 90100000 | H45: Restaurantes y catering (servicios de comidas y bebidas) | J45: Publicado
A46: 45867.502 | B46: Analisis de oferta | C46: HSLM-DAF-CD-2025-0590 | E46: VS/FG | G46: 82120000 | H46: Servicios de reproducción | J46: Evaluación
A47: 45867.459 | B47: Analisis de oferta | C47: HSLM-DAF-CD-2025-0586 | E47: VS/FG | G47: 39100000 | H47: Lámparas y bombillas y componentes para lámparas | J47: Evaluación
A48: 45867.418 | B48: HSML-2025-00736 | C48: HSLM-DAF-CD-2025-0584 | E48: VS/FG | F48: Suplimed, SRL | G48: 85120000 | H48: Práctica médica | I48: 195000 | J48: Adjudicado
A49: 45866.419 | B49: HSML-2025-00729 | C49: HSLM-DAF-CD-2025-0576 | E49: VS/FG | F49: Adler Amicis Valdez Marmolejos | G49: 82120000 | H49: Servicios de reproducción | I49: 88795 | J49: Adjudicado
...

Sheet CUENTA T VS
A1: D E S G L O S E D E L A S C U E N T A S
A2: 211101 | B2: 211102 | C2: 211103 | D2: 211104 | E2: 211105 | F2: 211106 | G2: 211203 | H2: 211205 | I2: 211206 | J2: 211208 | K2: 211209 | L2: 211211 | M2: 211301 | N2: 211401 | O2: 211501 | P2: 211502 | Q2: 211503 | R2: 211504 | S2: 212101 | T2: 212201 | U2: 212203 | V2: 212204 | W2: 212205 | X2: 212206 | Y2: 212207 | Z2: 212208 | AA2: 212209 | AB2: 212210 | AC2: 213101 | AD2: 213102 | AE2: 213201 | AF2: 213202 | AG2: 214101 | AH2: 214201 | AI2: 214202 | AJ2: 214203 | AK2: 215101 | AL2: 215201 | AM2: 215301 | AN2: 215401 | AO2: 221101 | AP2: 221201 | AQ2: 221301 | AR2: 221401 | AS2: 221501 | AT2: 221601 | AU2: 221602 | AV2: 221701 | AW2: 221801 | AX2: 222101 | AY2: 222201 | AZ2: 223101 | BA2: 223201 | BB2: 224101 | BC2: 224201 | BD2: 224301 | BE2: 224401 | BF2: 225101 | BG2: 225201 | BH2: 225301 | BI2: 225302 | BJ2: 225303 | BK2: 225304 | BL2: 225305 | BM2: 225401 | BN2: 225501 | BO2: 225601 | BP2: 225701 | BQ2: 225801 | BR2: 225901 | BS2: 226101 | BT2: 226201 | BU2: 226301 | BV2: 226401 | BW2: 227101 | BX2: 227102 | BY2: 227103 | BZ2: 227104 | CA2: 227105 | CB2: 227106 | CC2: 227107 | CD2: 227199 | CE2: 227201 | CF2: 227202 | CG2: 227203 | CH2: 227204 | CI2: 227205 | CJ2: 227206 | CK2: 227207 | CL2: 227208 | CM2: 227299 | CN2: 227301 | CO2: 228101 | CP2: 228201 | CQ2: 228301 | CR2: 228401 | CS2: 228501 | CT2: 228502 | CU2: 228503 | CV2: 228601 | CW2: 228602 | CX2: 228603 | CY2: 228604 | CZ2: 228701 | DA2: 228702 | DB2: 228703 | DC2: 228704 | DD2: 228705 | DE2: 228706 | DF2: 228801 | DG2: 228802 | DH2: 228803 | DI2: 229201 | DJ2: 229203 | DK2: 231101 | DL2: 231102 | DM2: 231201 | DN2: 231301 | DO2: 231302 | DP2: 231303 | DQ2: 231401 | DR2: 232101 | DS2: 232201 | DT2: 232301 | DU2: 233101 | DV2: 233201 | DW2: 233301 | DX2: 233401 | DY2: 233501 | DZ2: 233601 | EA2: 234101 | EB2: 234201 | EC2: 235101 | ED2: 235201 | EE2: 235301 | EF2: 235401 | EG2: 235501 | EH2: 236101 | EI2: 236102 | EJ2: 236103 | EK2: 236104 | EL2: 236105 | EM2: 236201 | EN2: 236202 | EO2: 236203 | EP2: 236304 | EQ2: 236305 | ER2: 236306 | ES2: 236401 | ET2: 236402 | EU2: 236403 | EV2: 236404 | EW2: 236405 | EX2: 236406 | EY2: 236407 | EZ2: 236901 | FA2: 237101 | FB2: 237102 | FC2: 237103 | FD2: 237104 | FE2: 237105 | FF2: 237106 | FG2: 237107 | FH2: 237201 | FI2: 237202 | FJ2: 237203 | FK2: 237204 | FL2: 237205 | FM2: 237206 | FN2: 237299 | FO2: 238101 | FP2: 238201 | FQ2: 239101 | FR2: 239102 | FS2: 239201 | FT2: 239301 | FU2: 239401 | FV2: 239501 | FW2: 239601 | FX2: 239701 | FY2: 239801 | FZ2: 239802 | GA2: 239901 | GB2: 239904 | GC2: 241201 | GD2: 241202 | GE2: 241203 | GF2: 241204 | GG2: 241205 | GH2: 261101 | GI2: 261201 | GJ2: 261301 | GK2: 261401 | GL2: 261901 | GM2: 262101 | GN2: 262201 | GO2: 262301 | GP2: 262401 | GQ2: 263101 | GR2: 263201 | GS2: 263301 | GT2: 263401 | GU2: 264101 | GV2: 264201 | GW2: 264301 | GX2: 264401 | GY2: 264501 | GZ2: 264601 | HA2: 264701 | HB2: 264801 | HC2: 265101 | HD2: 265201 | HE2: 265301 | HF2: 265401 | HG2: 265501 | HH2: 265601 | HI2: 265701 | HJ2: 265801 | HK2: 266101 | HL2: 266201 | HM2: 267101 | HN2: 267201 | HO2: 267301 | HP2: 267401 | HQ2: 267501 | HR2: 267601 | HS2: 267701 | HT2: 267801 | HU2: 267901 | HV2: 268101 | HW2: 268201 | HX2: 268301 | HY2: 268302 | HZ2: 268401 | IA2: 268501 | IB2: 268601 | IC2: 268701 | ID2: 268802 | IE2: 268803 | IF2: 268804 | IG2: 268901 | IH2: 269101 | II2: 269102 | IJ2: 269201 | IK2: 269202 | IL2: 269301 | IM2: 269401 | IN2: 269501 | IO2: 269502 | IP2: 269503 | IQ2: 2269901 | IR2: 271101 | IS2: 271201 | IT2: 271301 | IU2: 271401 | IV2: 272101 | IW2: 272201 | IX2: 272301 | IY2: 272401 | IZ2: 272501 | JA2: 272601 | JB2: 272701 | JC2: 272801 | JD2: 272901 | JE2: 273101 | JF2: 273201 | JG2: 274101 | JH2: 274201 | JI2: Totales | JJ2: TRANSF NO. | JK2: VALOR | JL2: RETENCION | JM2: AÑOS ANTERIORES | JN2: 2022 | JO2: Total | JP2: Proveedor Informal
FD3: 22638 | JI3: =SUM(A3:JH3) -> 22638 | JJ3: 208 | JK3: 22638 | JL3: =+JI3-JK3 -> 0
AW4: 760000 | JI4: =SUM(A4:JH4) -> 760000 | JJ4: =+JJ3+1 -> 209 | JK4: 722000 | JL4: =+JI4-JK4 -> 38000
DE5: 19496.18 | JI5: =SUM(A5:JH5) -> 19496.18 | JJ5: =+JJ4+1 -> 210 | JK5: 19496.18 | JL5: =+JI5-JK5 -> 0
DE6: 8860.18 | JI6: =SUM(A6:JH6) -> 8860.18 | JJ6: =+JJ5+1 -> 211 | JK6: 8860.18 | JL6: =+JI6-JK6 -> 0
DE7: 118075.52 | JI7: =SUM(A7:JH7) -> 118075.52 | JJ7: =+JJ6+1 -> 212 | JK7: 113072.32 | JL7: =+JI7-JK7 -> 5003.2
DE8: 14160 | JI8: =SUM(A8:JH8) -> 14160 | JJ8: =+JJ7+1 -> 213 | JK8: 14160 | JL8: =+JI8-JK8 -> 0
EA9: 24000 | JI9: =SUM(A9:JH9) -> 24000 | JJ9: =+JJ8+1 -> 214 | JK9: 22800 | JL9: =+JI9-JK9 -> 1200
FQ10: 1230740 | JI10: =SUM(A10:JH10) -> 1230740 | JJ10: =+JJ9+1 -> 215 | JK10: 1178590 | JL10: =+JI10-JK10 -> 52150
CH11: 247800 | JI11: =SUM(A11:JH11) -> 247800 | JJ11: =+JJ10+1 -> 216 | JK11: 237300 | JL11: =+JI11-JK11 -> 10500
CH12: 212400 | JI12: =SUM(A12:JH12) -> 212400 | JJ12: =+JJ11+1 -> 217 | JK12: 203400 | JL12: =+JI12-JK12 -> 9000
CM13: 409306.6 | JI13: =SUM(A13:JH13) -> 409306.6 | JJ13: =+JJ12+1 -> 218 | JK13: 391963.1 | JL13: =+JI13-JK13 -> 17343.5
CL14: 594720 | JI14: =SUM(A14:JH14) -> 594720 | JJ14: =+JJ13+1 -> 219 | JK14: 569520 | JL14: =+JI14-JK14 -> 25200
HL15: 58764 | JI15: =SUM(A15:JH15) -> 58764 | JJ15: =+JJ14+1 -> 220 | JK15: 56274 | JL15: =+JI15-JK15 -> 2490
CJ16: 3026.1 | JI16: =SUM(A16:JH16) -> 3026.1 | JJ16: =+JJ15+1 -> 221 | JK16: 3026.1 | JL16: =+JI16-JK16 -> 0
HD17: 272200 | JI17: =SUM(A17:JH17) -> 272200 | JJ17: =+JJ16+1 -> 222 | JK17: 260666.1 | JL17: =+JI17-JK17 -> 11533.9
CS18: 147500 | JI18: =SUM(A18:JH18) -> 147500 | JJ18: =+JJ17+1 -> 223 | JK18: 118750 | JL18: =+JI18-JK18 -> 28750
AY19: 212400 | DV19: 26550 | JI19: =SUM(A19:JH19) -> 238950 | JJ19: =+JJ18+1 -> 224 | JK19: 228825 | JL19: =+JI19-JK19 -> 10125
BI20: 298861.54 | JI20: =SUM(A20:JH20) -> 298861.54 | JJ20: =+JJ19+1 -> 225 | JK20: 298861.54 | JL20: =+JI20-JK20 -> 0
DE21: 165375 | JI21: =SUM(A21:JH21) -> 165375 | JJ21: =+JJ20+1 -> 226 | JK21: 165375 | JL21: =+JI21-JK21 -> 0
BC22: 8000 | JI22: =SUM(A22:JH22) -> 8000 | JJ22: =+JJ21+1 -> 227 | JK22: 7600 | JL22: =+JI22-JK22 -> 400
EG23: 77390.01 | ER23: 2100 | FY23: 31450 | GB23: 1000 | HI23: 10500.01 | JI23: =SUM(A23:JH23) -> 122440.02 | JJ23: =+JJ22+1 -> 228 | JK23: 117251.88 | JL23: =+JI23-JK23 -> 5188.14
DE24: 165375 | JI24: =SUM(A24:JH24) -> 165375 | JJ24: =+JJ23+1 -> 229 | JK24: 165375 | JL24: =+JI24-JK24 -> 0
FN25: 431408 | JI25: =SUM(A25:JH25) -> 431408 | JJ25: =+JJ24+1 -> 230 | JK25: 413128 | JL25: =+JI25-JK25 -> 18280
DK26: 275330 | JI26: =SUM(A26:JH26) -> 275330 | JJ26: =+JJ25+1 -> 231 | JK26: 261563.5 | JL26: =+JI26-JK26 -> 13766.5
GO27: 389046 | JI27: =SUM(A27:JH27) -> 389046 | JJ27: =+JJ26+1 -> 232 | JK27: 372561 | JL27: =+JI27-JK27 -> 16485
AW28: 50000 | JI28: =SUM(A28:JH28) -> 50000 | JJ28: =+JJ27+1 -> 233 | JK28: 50000 | JL28: =+JI28-JK28 -> 0
AQ29: 211904.05 | JI29: =SUM(A29:JH29) -> 211904.05 | JJ29: =+JJ28+1 -> 234 | JK29: 211904.05 | JL29: =+JI29-JK29 -> 0
FD30: 22638 | JI30: =SUM(A30:JH30) -> 22638 | JJ30: =+JJ29+1 -> 235 | JK30: 22638 | JL30: =+JI30-JK30 -> 0
DK31: 85400 | JI31: =SUM(A31:JH31) -> 85400 | JJ31: =+JJ30+1 -> 236 | JK31: 81130 | JL31: =+JI31-JK31 -> 4270
AY32: 236295 | JI32: =SUM(A32:JH32) -> 236295 | JJ32: =+JJ31+1 -> 237 | JK32: 226282.5 | JL32: =+JI32-JK32 -> 10012.5
AY33: 132750 | JI33: =SUM(A33:JH33) -> 132750 | JJ33: =+JJ32+1 -> 238 | JK33: 127125 | JL33: =+JI33-JK33 -> 5625
FN34: 395831 | JI34: =SUM(A34:JH34) -> 395831 | JJ34: =+JJ33+1 -> 239 | JK34: 379058.5 | JL34: =+JI34-JK34 -> 16772.5
EA35: 128800 | JI35: =SUM(A35:JH35) -> 128800 | JJ35: =+JJ34+1 -> 240 | JK35: 128800 | JL35: =+JI35-JK35 -> 0
FT36: 168800 | JI36: =SUM(A36:JH36) -> 168800 | JJ36: =+JJ35+1 -> 241 | JK36: 160360 | JL36: =+JI36-JK36 -> 8440
EH37: 1483.02 | EN37: 20574.93 | FW37: 62731.97 | FY37: 118290 | FZ37: 34881 | GB37: 1230.48 | JI37: =SUM(A37:JH37) -> 239191.4 | JJ37: =+JJ36+1 -> 242 | JK37: 227231.83 | JL37: =+JI37-JK37 -> 11959.57
CZ38: 39530 | JI38: =SUM(A38:JH38) -> 39530 | JJ38: =+JJ37+1 -> 243 | JK38: 37855 | JL38: =+JI38-JK38 -> 1675
AW39: 760000 | JI39: =SUM(A39:JH39) -> 760000 | JJ39: =+JJ38+1 -> 244 | JK39: 722000 | JL39: =+JI39-JK39 -> 38000
FA40: 172000 | JI40: =SUM(A40:JH40) -> 172000 | JJ40: 246 | JK40: 170573.26 | JL40: =+JI40-JK40 -> 1426.74
...

Sheet CUENTA T FONDO 100
A1: D E S G L O S E D E L A S C U E N T A S
A2: 211101 | B2: 211102 | C2: 211103 | D2: 211104 | E2: 211105 | F2: 211106 | G2: 211203 | H2: 211205 | I2: 211206 | J2: 211208 | K2: 211209 | L2: 211211 | M2: 211301 | N2: 211401 | O2: 211501 | P2: 211502 | Q2: 211503 | R2: 211504 | S2: 212101 | T2: 212201 | U2: 212203 | V2: 212204 | W2: 212205 | X2: 212206 | Y2: 212207 | Z2: 212208 | AA2: 212209 | AB2: 212210 | AC2: 213101 | AD2: 213102 | AE2: 213201 | AF2: 213202 | AG2: 214101 | AH2: 214201 | AI2: 214202 | AJ2: 214203 | AK2: 215101 | AL2: 215201 | AM2: 215301 | AN2: 215401 | AO2: 221101 | AP2: 221201 | AQ2: 221301 | AR2: 221401 | AS2: 221501 | AT2: 221601 | AU2: 221602 | AV2: 221701 | AW2: 221801 | AX2: 222101 | AY2: 222201 | AZ2: 223101 | BA2: 223201 | BB2: 224101 | BC2: 224201 | BD2: 224301 | BE2: 224401 | BF2: 225101 | BG2: 225201 | BH2: 225301 | BI2: 225302 | BJ2: 225303 | BK2: 225304 | BL2: 225305 | BM2: 225401 | BN2: 225501 | BO2: 225601 | BP2: 225701 | BQ2: 225801 | BR2: 225901 | BS2: 226101 | BT2: 226201 | BU2: 226301 | BV2: 226401 | BW2: 227101 | BX2: 227102 | BY2: 227103 | BZ2: 227104 | CA2: 227105 | CB2: 227106 | CC2: 227107 | CD2: 227199 | CE2: 227201 | CF2: 227202 | CG2: 227203 | CH2: 227204 | CI2: 227205 | CJ2: 227206 | CK2: 227207 | CL2: 227208 | CM2: 227299 | CN2: 227301 | CO2: 228101 | CP2: 228201 | CQ2: 228301 | CR2: 228401 | CS2: 228501 | CT2: 228502 | CU2: 228503 | CV2: 228601 | CW2: 228602 | CX2: 228603 | CY2: 228604 | CZ2: 228701 | DA2: 228702 | DB2: 228703 | DC2: 228704 | DD2: 228705 | DE2: 228706 | DF2: 228801 | DG2: 228802 | DH2: 228803 | DI2: 229201 | DJ2: 229203 | DK2: 231101 | DL2: 231102 | DM2: 231201 | DN2: 231301 | DO2: 231302 | DP2: 231303 | DQ2: 231401 | DR2: 232101 | DS2: 232201 | DT2: 232301 | DU2: 233101 | DV2: 233201 | DW2: 233301 | DX2: 233401 | DY2: 233501 | DZ2: 233601 | EA2: 234101 | EB2: 234201 | EC2: 235101 | ED2: 235201 | EE2: 235301 | EF2: 235401 | EG2: 235501 | EH2: 236101 | EI2: 236102 | EJ2: 236103 | EK2: 236104 | EL2: 236105 | EM2: 236201 | EN2: 236202 | EO2: 236203 | EP2: 236304 | EQ2: 236305 | ER2: 236306 | ES2: 236401 | ET2: 236402 | EU2: 236403 | EV2: 236404 | EW2: 236405 | EX2: 236406 | EY2: 236407 | EZ2: 236901 | FA2: 237101 | FB2: 237102 | FC2: 237103 | FD2: 237104 | FE2: 237105 | FF2: 237106 | FG2: 237107 | FH2: 237201 | FI2: 237202 | FJ2: 237203 | FK2: 237204 | FL2: 237205 | FM2: 237206 | FN2: 237299 | FO2: 238101 | FP2: 238201 | FQ2: 239101 | FR2: 239102 | FS2: 239201 | FT2: 239301 | FU2: 239401 | FV2: 239501 | FW2: 239601 | FX2: 239701 | FY2: 239801 | FZ2: 239802 | GA2: 239901 | GB2: 239904 | GC2: 241201 | GD2: 241202 | GE2: 241203 | GF2: 241204 | GG2: 241205 | GH2: 261101 | GI2: 261201 | GJ2: 261301 | GK2: 261401 | GL2: 261901 | GM2: 262101 | GN2: 262201 | GO2: 262301 | GP2: 262401 | GQ2: 263101 | GR2: 263201 | GS2: 263301 | GT2: 263401 | GU2: 264101 | GV2: 264201 | GW2: 264301 | GX2: 264401 | GY2: 264501 | GZ2: 264601 | HA2: 264701 | HB2: 264801 | HC2: 265101 | HD2: 265201 | HE2: 265301 | HF2: 265401 | HG2: 265501 | HH2: 265601 | HI2: 265701 | HJ2: 265801 | HK2: 266101 | HL2: 266201 | HM2: 267101 | HN2: 267201 | HO2: 267301 | HP2: 267401 | HQ2: 267501 | HR2: 267601 | HS2: 267701 | HT2: 267801 | HU2: 267901 | HV2: 268101 | HW2: 268201 | HX2: 268301 | HY2: 268302 | HZ2: 268401 | IA2: 268501 | IB2: 268601 | IC2: 268701 | ID2: 268802 | IE2: 268803 | IF2: 268804 | IG2: 268901 | IH2: 269101 | II2: 269102 | IJ2: 269201 | IK2: 269202 | IL2: 269301 | IM2: 269401 | IN2: 269501 | IO2: 269502 | IP2: 269503 | IQ2: 2269901 | IR2: 271101 | IS2: 271201 | IT2: 271301 | IU2: 271401 | IV2: 272101 | IW2: 272201 | IX2: 272301 | IY2: 272401 | IZ2: 272501 | JA2: 272601 | JB2: 272701 | JC2: 272801 | JD2: 272901 | JE2: 273101 | JF2: 273201 | JG2: 274101 | JH2: 274201 | JI2: Totales | JJ2: LIBRAMIENTO | JK2: VALOR | JL2: RETENCION | JM2: AÑOS ANTERIORES | JN2: 2024 | JO2: Total | JP2: Proveedor Informal
FT3: 578891.48 | JI3: =SUM(A3:JH3) -> 578891.48 | JJ3: 2719 | JO3: =+JM3+JN3 -> 0
EA4: 180000 | JI4: =SUM(A4:JH4) -> 180000 | JJ4: 2724
EG5: 387807.15 | JI5: =SUM(A5:JH5) -> 387807.15 | JJ5: 2725
GL6: 1361145 | JI6: =SUM(A6:JH6) -> 1361145 | JJ6: 2729
DV7: 265393.8 | JI7: =SUM(A7:JH7) -> 265393.8 | JJ7: 2735
FQ8: 342200 | JI8: =SUM(A8:JH8) -> 342200 | JJ8: 2739
EA9: 200010 | JI9: =SUM(A9:JH9) -> 200010 | JJ9: 2743
FT10: 59000 | JI10: =SUM(A10:JH10) -> 59000 | JJ10: 2747
GQ11: 70800 | JI11: =SUM(A11:JH11) -> 70800 | JJ11: 2751
EG12: 72900.1 | JI12: =SUM(A12:JH12) -> 72900.1 | JJ12: 2756
GQ13: 671774 | JI13: =SUM(A13:JH13) -> 671774 | JJ13: 2760
GQ14: 1999226.8 | JI14: =SUM(A14:JH14) -> 1999226.8 | JJ14: 2764
BW15: 74179.46 | FY15: 809192.93 | JI15: =SUM(A15:JH15) -> 883372.39 | JJ15: 2771
AV16: 60535 | JI16: =SUM(A16:JH16) -> 60535 | JJ16: 2775
FJ17: 161376 | JI17: =SUM(A17:JH17) -> 161376 | JJ17: 2794
FJ18: 16605 | JI18: =SUM(A18:JH18) -> 16605 | JJ18: 2800
FT19: 220312.32 | JI19: =SUM(A19:JH19) -> 220312.32 | JJ19: 2804
FJ20: 185670.37 | JI20: =SUM(A20:JH20) -> 185670.37 | JJ20: 2808
FT21: 270007.6 | JI21: =SUM(A21:JH21) -> 270007.6 | JJ21: 2812
GK22: 251876.14 | JI22: =SUM(A22:JH22) -> 251876.14 | JJ22: 2817
FN23: 168860.36 | FZ23: 15463.9 | JI23: =SUM(A23:JH23) -> 184324.26 | JJ23: 2821
EG24: 26432 | FQ24: 5074 | JI24: =SUM(A24:JH24) -> 31506 | JJ24: 2825
FJ25: 162040 | FT25: 85083.9 | JI25: =SUM(A25:JH25) -> 247123.9 | JJ25: 2830
FJ26: 43108 | JI26: =SUM(A26:JH26) -> 43108 | JJ26: 2834
DW27: 39530 | FS27: 45902 | GB27: 1699.2 | JI27: =SUM(A27:JH27) -> 87131.2 | JJ27: 2838
Q28: 12100 | JI28: =SUM(A28:JH28) -> 12100 | JJ28: 2840
GH29: 216333.29 | JI29: =SUM(A29:JH29) -> 216333.29 | JJ29: 2847
FT30: 175000 | JI30: =SUM(A30:JH30) -> 175000 | JJ30: 2851
EA31: 210000 | FJ31: 7120 | JI31: =SUM(A31:JH31) -> 217120 | JJ31: 2855
FT32: 270820 | JI32: =SUM(A32:JH32) -> 270820 | JJ32: 2859
GR33: 239687.5 | JI33: =SUM(A33:JH33) -> 239687.5 | JJ33: 2863
EA34: 200000 | JI34: =SUM(A34:JH34) -> 200000 | JJ34: 2872
DS35: 1365869.3 | JI35: =SUM(A35:JH35) -> 1365869.3 | JJ35: 2876
DK36: 521100 | JI36: =SUM(A36:JH36) -> 521100 | JJ36: 2880
GQ37: 1298000 | JI37: =SUM(A37:JH37) -> 1298000 | JJ37: 2884
FT38: 323615 | JI38: =SUM(A38:JH38) -> 323615 | JJ38: 2888
FT39: 401200 | JI39: =SUM(A39:JH39) -> 401200 | JJ39: 2892
EA40: 1105000 | JI40: =SUM(A40:JH40) -> 1105000 | JJ40: 2900
...

Sheet CONS. FUENTES FINAN
A1: Form. No.6 SRS
A3: Servicio Nacional de Salud
A4: Dirección de Fizcalización
A5: Consolidado de Ingresos y Gastos por Fuente de Financiamiento
A6: HOSPITAL MATERNO INFANTIL SAN LORENZO DE LOS MINA
A7: JULIO 2025
C8: Ingresos Generales:
E9: 1.- Balance Inicial / Fuente:
E10: Anticipo Financiero | H10: Otros Aportes | L10: Contraseña: 0001
E11: Transferencias Corrientes
E12: Venta de Servicios | G12: 1771845.5
E13: 2.- Ingresos por Fuente / Cuenta
E14: Anticipo Financiero | H14: Otros Aportes | I14: =+'INGR SEGUN ORIGEN'!E47 -> 834400 | L14: OBJETAL | M14: FR | N14: VS
E15: Transferencias Corrientes | G15: =12593841.17+3169632.08+84553321.83 -> 1.003168e+08 | H15: Aportes Nomina SNS | I15: 0 | L15: 2.1 | M15: =G26 -> 0 | N15: =H26 -> 0
E16: Venta de Servicios | G16: =+'INGR SEGUN ORIGEN'!E39 -> 10942139 | L16: 2.2 | M16: =G87 -> 0 | N16: =H87 -> 1213383.4
H17: TOTAL INGRESOS RDS | I17: =+G10+G11+G12+I10+G14+G15+G16+I14+I15 -> 1.1386518e+08 | L17: 2.3 | M17: ='[1]CONS. FUENTES FINAN'!G212 -> 14433131 | N17: ='[1]CONS. FUENTES FINAN'!H212 -> 2432378.3
L18: 2.4 | M18: =G330 -> 0 | N18: =H330 -> 23400
L19: 2.6 | M19: =G336 -> 0 | N19: =H336 -> 3887510
L20: 2.7 | M20: ='[1]CONS. FUENTES FINAN'!G463 -> 0 | N20: ='[1]CONS. FUENTES FINAN'!H463 -> 0
A21: 1 | F21: 2 | G21: 3 | I21: 4 | J21: 5
A22: Código Presupuestario | F22: Descripción Gasto por Cuenta | G22: Distribución del Gasto por Fuente de Financiamiento | I22: TOTAL | J22: %
A23: Tipo | B23: Objeto | C23: Cuenta | D23: Sub-Cuenta | E23: Auxiliar | G23: Fondo 100 | H23: Venta de Servicios/ Otros Aportes
A25: 2 | F25: Gastos | G25: =+G26+G87+G212+G330+G336+G463 -> 0 | H25: =+H26+H87+H212+H330+H336+H463 -> 7556671.6 | I25: =SUM(G25:H25) -> 7556671.6 | J25: =+J26+J87+J212+J330+J336+J463 -> 1
A26: 2 | B26: 1 | F26: Servicios Personales | G26: =+G27+G51+G64+G71+G78 -> 0 | H26: =+H27+H51+H64+H71+H78 -> 0 | I26: =SUM(G26:H26) -> 0 | J26: =I26/$I$25 -> 0
A27: 2 | B27: 1 | C27: 1 | F27: Remuneraciones | G27: =+G28+G35+G42+G44+G46 -> 0 | H27: =+H28+H35+H42+H44+H46 -> 0 | I27: =SUM(G27:H27) -> 0 | J27: =I27/$I$25 -> 0
A28: 2 | B28: 1 | C28: 1 | D28: 1 | F28: Remuneraciones al personal fijo | G28: =SUM(G29:G34) -> 0 | H28: =SUM(H29:H34) -> 0 | I28: =SUM(G28:H28) -> 0 | J28: =I28/$I$25 -> 0
A29: 2 | B29: 1 | C29: 1 | D29: 1 | E29: 01 | F29: Sueldos a empleados fijos | G29: ='[1]CUENTA T FONDO 100'!A145 -> 0 | H29: ='[1]CUENTA T VS'!A96 -> 0 | I29: =SUM(G29:H29) -> 0 | J29: =I29/$I$25 -> 0
A30: 2 | B30: 1 | C30: 1 | D30: 1 | E30: 02 | F30: Sueldos a médicos | G30: ='[1]CUENTA T FONDO 100'!B145 -> 0 | H30: ='[1]CUENTA T VS'!B96 -> 0 | I30: =SUM(G30:H30) -> 0 | J30: =I30/$I$25 -> 0
A31: 2 | B31: 1 | C31: 1 | D31: 1 | E31: 03 | F31: Ascensos a militares | G31: ='[1]CUENTA T FONDO 100'!C145 -> 0 | H31: ='[1]CUENTA T VS'!C96 -> 0 | I31: =SUM(G31:H31) -> 0 | J31: =I31/$I$25 -> 0
A32: 2 | B32: 1 | C32: 1 | D32: 1 | E32: 04 | F32: Nuevas plazas maestros | G32: ='[1]CUENTA T FONDO 100'!D145 -> 0 | H32: ='[1]CUENTA T VS'!D96 -> 0 | I32: =SUM(G32:H32) -> 0 | J32: =I32/$I$25 -> 0
A33: 2 | B33: 1 | C33: 1 | D33: 1 | E33: 05 | F33: Incentivos y escalafón | G33: ='[1]CUENTA T FONDO 100'!E145 -> 0 | H33: ='[1]CUENTA T VS'!E96 -> 0 | I33: =SUM(G33:H33) -> 0 | J33: =I33/$I$25 -> 0
A34: 2 | B34: 1 | C34: 1 | D34: 1 | E34: 06 | F34: Nuevas plazas a médicos | G34: ='[1]CUENTA T FONDO 100'!F145 -> 0 | H34: ='[1]CUENTA T VS'!F96 -> 0 | I34: =SUM(G34:H34) -> 0 | J34: =I34/$I$25 -> 0
A35: 2 | B35: 1 | C35: 1 | D35: 2 | F35: Remuneraciones al personal con carácter transitorio | G35: =SUM(G36:G41) -> 0 | H35: =SUM(H36:H41) -> 0 | I35: =SUM(G35:H35) -> 0
A36: 2 | B36: 1 | C36: 1 | D36: 2 | E36: 03 | F36: Suplencias | G36: ='[1]CUENTA T FONDO 100'!G145 -> 0 | H36: ='[1]CUENTA T VS'!G96 -> 0 | I36: =SUM(G36:H36) -> 0 | J36: =I36/$I$25 -> 0
A37: 2 | B37: 1 | C37: 1 | D37: 2 | E37: 05 | F37: Sueldo al personal nominal en período probatorio | G37: ='[1]CUENTA T FONDO 100'!H145 -> 0 | H37: ='[1]CUENTA T VS'!H96 -> 0 | I37: =SUM(G37:H37) -> 0 | J37: =I37/$I$25 -> 0
A38: 2 | B38: 1 | C38: 1 | D38: 2 | E38: 06 | F38: Jornales | G38: ='[1]CUENTA T FONDO 100'!I145 -> 0 | H38: ='[1]CUENTA T VS'!I96 -> 0 | I38: =SUM(G38:H38) -> 0 | J38: =I38/$I$25 -> 0
A39: 2 | B39: 1 | C39: 1 | D39: 2 | E39: 08 | F39: Empleados temporales | G39: ='[1]CUENTA T FONDO 100'!J145 -> 0 | H39: ='[1]CUENTA T VS'!J96 -> 0 | I39: =SUM(G39:H39) -> 0 | J39: =I39/$I$25 -> 0
A40: 2 | B40: 1 | C40: 1 | D40: 2 | E40: 09 | F40: Personal de carácter eventual | G40: ='[1]CUENTA T FONDO 100'!K145 -> 0 | H40: ='[1]CUENTA T VS'!K96 -> 0 | I40: =SUM(G40:H40) -> 0 | J40: =I40/$I$25 -> 0
A41: 2 | B41: 1 | C41: 1 | D41: 2 | E41: 11 | F41: Interinato | G41: ='[1]CUENTA T FONDO 100'!L145 -> 0 | H41: ='[1]CUENTA T VS'!L96 -> 0 | I41: =SUM(G41:H41) -> 0 | J41: =I41/$I$25 -> 0
A42: 2 | B42: 1 | C42: 1 | D42: 3 | F42: Sueldos al personal fijo en trámite de pensiones | G42: =SUM(G43) -> 0 | H42: =SUM(H43) -> 0 | I42: =SUM(G42:H42) -> 0
...

Sheet GASTOS X ATENCION
A1: SERVICIO NACIONAL DE SALUD
A2: ='CONS. FUENTES FINAN'!A6 -> HOSPITAL MATERNO INFANTIL SAN LORENZO DE LOS MINA
A3: RESUMEN COMPARATIVO DE GASTOS ESPECIFICOS FONDO 100 Y VENTA DE SERVICIOS
A6: DETALLE | B6: FONDO 100 | C6: VENTA SERVICIOS | D6: TOTAL | E6: %
A8: Atención Directa
A9: Medicamentos e Insumos Médicos | B9: ='CONS. FUENTES FINAN'!G245+'CONS. FUENTES FINAN'!G315 -> 0 | C9: ='CONS. FUENTES FINAN'!H245+'CONS. FUENTES FINAN'!H315 -> 419800 | D9: =SUM(B9:C9) -> 419800 | E9: =+D9/D12 -> 0.31362328
A10: Oxigeno | B10: ='CONS. FUENTES FINAN'!G302 -> 0 | C10: ='CONS. FUENTES FINAN'!H302 -> 899773.6 | D10: =SUM(B10:C10) -> 899773.6 | E10: =+D10/D12 -> 0.67220092
A11: Reactivos e Insumos de Laboratorio | B11: ='CONS. FUENTES FINAN'!G296+'CONS. FUENTES FINAN'!G297+'CONS. FUENTES FINAN'!G298 -> 0 | C11: ='CONS. FUENTES FINAN'!H296+'CONS. FUENTES FINAN'!H297+'CONS. FUENTES FINAN'!H298 -> 18975 | D11: =SUM(B11:C11) -> 18975 | E11: =+D11/D12 -> 0.014175802
A12: Total | B12: =SUM(B9:B11) -> 0 | C12: =SUM(C9:C11) -> 1338548.6 | D12: =SUM(D9:D11) -> 1338548.6 | E12: =+D12/D39 -> 0.17713468
A13: Mantenimiento de Equipos
A14: Reparación y Mantenimiento Maquinaria y Eq. | B14: ='CONS. FUENTES FINAN'!G157+'CONS. FUENTES FINAN'!G188+'CONS. FUENTES FINAN'!G223+'CONS. FUENTES FINAN'!G252+'CONS. FUENTES FINAN'!G254+'CONS. FUENTES FINAN'!G256+'CONS. FUENTES FINAN'!G258+'CONS. FUENTES FINAN'!G261+'CONS. FUENTES FINAN'!G292+'CONS. FUENTES FINAN'!G293+'CONS. FUENTES FINAN'!G299+'CONS. FUENTES FINAN'!G300+'CONS. FUENTES FINAN'!G301+'CONS. FUENTES FINAN'!G324 -> 0 | C14: ='CONS. FUENTES FINAN'!H157+'CONS. FUENTES FINAN'!H188+'CONS. FUENTES FINAN'!H223+'CONS. FUENTES FINAN'!H252+'CONS. FUENTES FINAN'!H254+'CONS. FUENTES FINAN'!H256+'CONS. FUENTES FINAN'!H258+'CONS. FUENTES FINAN'!H261+'CONS. FUENTES FINAN'!H292+'CONS. FUENTES FINAN'!H293+'CONS. FUENTES FINAN'!H299+'CONS. FUENTES FINAN'!H300+'CONS. FUENTES FINAN'!H301+'CONS. FUENTES FINAN'!H324 -> 656488.94 | D14: =SUM(B14:C14) -> 656488.94 | E14: =+D14/D16 -> 0.99386863
A15: Productos Eléctricos y Afines | B15: ='CONS. FUENTES FINAN'!G320 -> 0 | C15: ='CONS. FUENTES FINAN'!H320 -> 4050.01 | D15: =SUM(B15:C15) -> 4050.01 | E15: =+D15/D16 -> 0.006131372
A16: Total | B16: =SUM(B14:B15) -> 0 | C16: =SUM(C14:C15) -> 660538.95 | D16: =SUM(D14:D15) -> 660538.95 | E16: =+D16/D39 -> 0.087411361
A17: Gastos Administrativos
A18: Servicios Personales | B18: ='CONS. FUENTES FINAN'!G26 -> 0 | C18: ='CONS. FUENTES FINAN'!H26 -> 0 | D18: =SUM(B18:C18) -> 0 | E18: =+D18/D34 -> 0
A19: Servicio Telefónico | B19: ='CONS. FUENTES FINAN'!G91+'CONS. FUENTES FINAN'!G93+'CONS. FUENTES FINAN'!G95+'CONS. FUENTES FINAN'!G97 -> 0 | C19: ='CONS. FUENTES FINAN'!H91+'CONS. FUENTES FINAN'!H93+'CONS. FUENTES FINAN'!H95+'CONS. FUENTES FINAN'!H97 -> 259054.4 | D19: =SUM(B19:C19) -> 259054.4 | E19: =+D19/D34 -> 0.15511551
A20: Servicios Basicos (electricidad, agua y residuos solidos) | B20: ='CONS. FUENTES FINAN'!G99+'CONS. FUENTES FINAN'!G102+'CONS. FUENTES FINAN'!G104 -> 0 | C20: ='CONS. FUENTES FINAN'!H99+'CONS. FUENTES FINAN'!H102+'CONS. FUENTES FINAN'!H104 -> 0 | D20: =SUM(B20:C20) -> 0 | E20: =+D20/D34 -> 0
A21: Viáticos | B21: ='CONS. FUENTES FINAN'!G111 -> 0 | C21: ='CONS. FUENTES FINAN'!H111 -> 0 | D21: =SUM(B21:C21) -> 0 | E21: =+D21/D34 -> 0
A22: Transporte y almacenaje | B22: ='CONS. FUENTES FINAN'!G116 -> 0 | C22: ='CONS. FUENTES FINAN'!H116 -> 24000 | D22: =SUM(B22:C22) -> 24000 | E22: =+D22/D34 -> 0.01437062
A23: Alquileres | B23: ='CONS. FUENTES FINAN'!G125 -> 0 | C23: ='CONS. FUENTES FINAN'!H125 -> 252960.9 | D23: =SUM(B23:C23) -> 252960.9 | E23: =+D23/D34 -> 0.15146687
A24: Comisiones y Gastos Bancarios | B24: ='CONS. FUENTES FINAN'!G182 -> 0 | C24: ='CONS. FUENTES FINAN'!H182 -> 11179.44 | D24: =SUM(B24:C24) -> 11179.44 | E24: =+D24/D34 -> 0.0066939785
A25: Materiales de Oficina, Impresión y Encuadernación | B25: ='CONS. FUENTES FINAN'!G109+'CONS. FUENTES FINAN'!G312 -> 0 | C25: ='CONS. FUENTES FINAN'!H109+'CONS. FUENTES FINAN'!H312 -> 0 | D25: =SUM(B25:C25) -> 0 | E25: =+D25/D34 -> 0
A26: Alimentos y Bebidas para Personas | B26: ='CONS. FUENTES FINAN'!G208+'CONS. FUENTES FINAN'!G214+'CONS. FUENTES FINAN'!G217+'CONS. FUENTES FINAN'!G219 -> 0 | C26: ='CONS. FUENTES FINAN'!H208+'CONS. FUENTES FINAN'!H214+'CONS. FUENTES FINAN'!H217+'CONS. FUENTES FINAN'!H219 -> 300691.8 | D26: =SUM(B26:C26) -> 300691.8 | E26: =+D26/D34 -> 0.18004698
A27: Productos de papel, carton e impesos | B27: ='CONS. FUENTES FINAN'!G232 -> 0 | C27: ='CONS. FUENTES FINAN'!H232 -> 107616 | D27: =SUM(B27:C27) -> 107616 | E27: =+D27/D34 -> 0.06443786
A28: Articulos de Plasticos | B28: ='CONS. FUENTES FINAN'!G259 -> 0 | C28: ='CONS. FUENTES FINAN'!H259 -> 249831.2 | D28: =SUM(B28:C28) -> 249831.2 | E28: =+D28/D34 -> 0.14959288
A29: Gasolina | B29: ='CONS. FUENTES FINAN'!G288 -> 0 | C29: ='CONS. FUENTES FINAN'!H288 -> 172000 | D29: =SUM(B29:C29) -> 172000 | E29: =+D29/D34 -> 0.10298944
A30: Gasoil | B30: ='CONS. FUENTES FINAN'!G289+'CONS. FUENTES FINAN'!G290 -> 0 | C30: ='CONS. FUENTES FINAN'!H289+'CONS. FUENTES FINAN'!H290 -> 0 | D30: =SUM(B30:C30) -> 0 | E30: =+D30/D34 -> 0
A31: GLP | B31: ='CONS. FUENTES FINAN'!G291+'CONS. FUENTES FINAN'!G294 -> 0 | C31: ='CONS. FUENTES FINAN'!H291+'CONS. FUENTES FINAN'!H294 -> 23844.13 | D31: =SUM(B31:C31) -> 23844.13 | E31: =+D31/D34 -> 0.014277289
A32: Materiales de Limpieza e Higiene | B32: ='CONS. FUENTES FINAN'!G309 -> 0 | C32: ='CONS. FUENTES FINAN'!H309 -> 0 | D32: =SUM(B32:C32) -> 0 | E32: =+D32/D34 -> 0
A33: Otros Egresos y Gastos | B33: ='CONS. FUENTES FINAN'!G89+'CONS. FUENTES FINAN'!G107+'CONS. FUENTES FINAN'!G148+'CONS. FUENTES FINAN'!G180+'CONS. FUENTES FINAN'!G184+'CONS. FUENTES FINAN'!G186+'CONS. FUENTES FINAN'!G192+'CONS. FUENTES FINAN'!G197+'CONS. FUENTES FINAN'!G204+'CONS. FUENTES FINAN'!G225+'CONS. FUENTES FINAN'!G303+'CONS. FUENTES FINAN'!G316+'CONS. FUENTES FINAN'!G318+'CONS. FUENTES FINAN'!G322+'CONS. FUENTES FINAN'!G327+'CONS. FUENTES FINAN'!G330 -> 0 | C33: ='CONS. FUENTES FINAN'!H89+'CONS. FUENTES FINAN'!H107+'CONS. FUENTES FINAN'!H148+'CONS. FUENTES FINAN'!H180+'CONS. FUENTES FINAN'!H184+'CONS. FUENTES FINAN'!H186+'CONS. FUENTES FINAN'!H192+'CONS. FUENTES FINAN'!H197+'CONS. FUENTES FINAN'!H204+'CONS. FUENTES FINAN'!H225+'CONS. FUENTES FINAN'!H303+'CONS. FUENTES FINAN'!H316+'CONS. FUENTES FINAN'!H318+'CONS. FUENTES FINAN'!H322+'CONS. FUENTES FINAN'!H327+'CONS. FUENTES FINAN'!H330 -> 268896.22 | D33: =SUM(B33:C33) -> 268896.22 | E33: =+D33/D34 -> 0.16100856
A34: Total | B34: =SUM(B17:B33) -> 0 | C34: =SUM(C17:C33) -> 1670074.1 | D34: =SUM(D17:D33) -> 1670074.1 | E34: =+D34/D39 -> 0.22100657
A35: Gastos Inversion y Capital
A36: Bienes Muebles, Inmuebles e Intangibles | B36: ='CONS. FUENTES FINAN'!G336 -> 0 | C36: ='CONS. FUENTES FINAN'!H336 -> 3887510 | D36: =SUM(B36:C36) -> 3887510 | E36: =+D36/D38 -> 1
A37: Obras | B37: ='CONS. FUENTES FINAN'!G463 -> 0 | C37: ='CONS. FUENTES FINAN'!H463 -> 0 | D37: =SUM(B37:C37) -> 0 | E37: =+D37/D38 -> 0
A38: Total | B38: =SUM(B36:B37) -> 0 | C38: =SUM(C36:C37) -> 3887510 | D38: =SUM(D36:D37) -> 3887510 | E38: =+D38/D39 -> 0.51444739
A39: Total General | B39: =+B12+B16+B34+B38 -> 0 | C39: =+C12+C16+C34+C38 -> 7556671.6 | D39: =+D12+D16+D34+D38 -> 7556671.6 | E39: =+E12+E16+E34+E38 -> 1
A40: Porciento | B40: =+B39/D39 -> 0 | C40: =+C39/D39 -> 1 | D40: =+B40+C40 -> 1

Sheet PLANTILLA PRESUPUESTO
A1: SERVICIO NACIONAL DE SALUD
A2: HOSPITAL MATERNO INFANTIL SAN LORENZO DE LOS MINA
A3: CONSOLIDADO GASTOS EJECUCION FINANCIERA 2025
A4: En RD$
A6: Detalle | B6: FONDO REPONIBLE | G6: VENTA SEVICIOS/OTROS APORTES | L6: TOTAL
A7: 2 - GASTOS | B7: 1ro | C7: 2do | D7: 3ro | E7: 4to | G7: 1ro | H7: 2do | I7: 3ro | J7: 4to | L7: 1ro | M7: 2do | N7: 3ro | O7: 4to
A8: 2.1 - REMUNERACIONES Y CONTRIBUCIONES | B8: =SUM(B9:B13) -> 1.9856074e+08 | C8: =SUM(C9:C13) -> 1.9977032e+08 | D8: =SUM(D9:D13) -> 71335676 | E8: =SUM(E9:E13) -> 0 | G8: =SUM(G9:G13) -> 5231553.6 | H8: =SUM(H9:H13) -> 0 | I8: =SUM(I9:I13) -> 0 | J8: =SUM(J9:J13) -> 0 | L8: =SUM(B8+G8) -> 2.0379229e+08 | M8: =SUM(C8+H8) -> 1.9977032e+08 | N8: =SUM(D8+I8) -> 71335676 | O8: =SUM(E8+J8) -> 0
A9: 2.1.1 - REMUNERACIONES | B9: =SUM('TRANSFERENCIA CORRIENTE'!C10:E10) -> 1.639452e+08 | C9: =SUM('TRANSFERENCIA CORRIENTE'!F10:H10) -> 1.6408478e+08 | D9: =SUM('TRANSFERENCIA CORRIENTE'!I10:K10) -> 58925421 | E9: =SUM('TRANSFERENCIA CORRIENTE'!L10:N10) -> 0 | G9: =SUM(VS!C10:E10) -> 0 | H9: =SUM(VS!F10:H10) -> 0 | I9: =SUM(VS!I10:K10) -> 0 | J9: =SUM(VS!L10:N10) -> 0 | L9: =SUM(B9+G9) -> 1.639452e+08 | M9: =SUM(C9+H9) -> 1.6408478e+08 | N9: =SUM(D9+I9) -> 58925421 | O9: =SUM(E9+J9) -> 0
A10: 2.1.2 - SOBRESUELDOS | B10: =SUM('TRANSFERENCIA CORRIENTE'!C11:E11) -> 9594398.8 | C10: =SUM('TRANSFERENCIA CORRIENTE'!F11:H11) -> 10535799 | D10: =SUM('TRANSFERENCIA CORRIENTE'!I11:K11) -> 3344880.2 | E10: =SUM('TRANSFERENCIA CORRIENTE'!L11:N11) -> 0 | G10: =SUM(VS!C11:E11) -> 5231553.6 | H10: =SUM(VS!F11:H11) -> 0 | I10: =SUM(VS!I11:K11) -> 0 | J10: =SUM(VS!L11:N11) -> 0 | L10: =SUM(B10+G10) -> 14825952 | M10: =SUM(C10+H10) -> 10535799 | N10: =SUM(D10+I10) -> 3344880.2 | O10: =SUM(E10+J10) -> 0
A11: 2.1.3 - DIETAS Y GASTOS DE REPRESENTACIÓN | B11: =SUM('TRANSFERENCIA CORRIENTE'!C12:E12) -> 0 | C11: =SUM('TRANSFERENCIA CORRIENTE'!F12:H12) -> 0 | D11: =SUM('TRANSFERENCIA CORRIENTE'!I12:K12) -> 0 | E11: =SUM('TRANSFERENCIA CORRIENTE'!L12:N12) -> 0 | G11: =SUM(VS!C12:E12) -> 0 | H11: =SUM(VS!F12:H12) -> 0 | I11: =SUM(VS!I12:K12) -> 0 | J11: =SUM(VS!L12:N12) -> 0 | L11: =SUM(B11+G11) -> 0 | M11: =SUM(C11+H11) -> 0 | N11: =SUM(D11+I11) -> 0 | O11: =SUM(E11+J11) -> 0
A12: 2.1.4 - GRATIFICACIONES Y BONIFICACIONES | B12: =SUM('TRANSFERENCIA CORRIENTE'!C13:E13) -> 0 | C12: =SUM('TRANSFERENCIA CORRIENTE'!F13:H13) -> 0 | D12: =SUM('TRANSFERENCIA CORRIENTE'!I13:K13) -> 0 | E12: =SUM('TRANSFERENCIA CORRIENTE'!L13:N13) -> 0 | G12: =SUM(VS!C13:E13) -> 0 | H12: =SUM(VS!F13:H13) -> 0 | I12: =SUM(VS!I13:K13) -> 0 | J12: =SUM(VS!L13:N13) -> 0 | L12: =SUM(B12+G12) -> 0 | M12: =SUM(C12+H12) -> 0 | N12: =SUM(D12+I12) -> 0 | O12: =SUM(E12+J12) -> 0
A13: 2.1.5 - CONTRIBUCIONES A LA SEGURIDAD SOCIAL | B13: =SUM('TRANSFERENCIA CORRIENTE'!C14:E14) -> 25021132 | C13: =SUM('TRANSFERENCIA CORRIENTE'!F14:H14) -> 25149742 | D13: =SUM('TRANSFERENCIA CORRIENTE'!I14:K14) -> 9065374.6 | E13: =SUM('TRANSFERENCIA CORRIENTE'!L14:N14) -> 0 | G13: =SUM(VS!C14:E14) -> 0 | H13: =SUM(VS!F14:H14) -> 0 | I13: =SUM(VS!I14:K14) -> 0 | J13: =SUM(VS!L14:N14) -> 0 | L13: =SUM(B13+G13) -> 25021132 | M13: =SUM(C13+H13) -> 25149742 | N13: =SUM(D13+I13) -> 9065374.6 | O13: =SUM(E13+J13) -> 0
A14: 2.2 - CONTRATACIÓN DE SERVICIOS | B14: =SUM(B15:B23) -> 9308364.9 | C14: =SUM(C15:C23) -> 10131818 | D14: =SUM(D15:D23) -> 0 | E14: =SUM(E15:E23) -> 0 | G14: =SUM(G15:G23) -> 8306683.8 | H14: =SUM(H15:H23) -> 7239413.8 | I14: =SUM(I15:I23) -> 5012155.8 | J14: =SUM(J15:J23) -> 0 | L14: =SUM(B14+G14) -> 17615049 | M14: =SUM(C14+H14) -> 17371232 | N14: =SUM(D14+I14) -> 5012155.8 | O14: =SUM(E14+J14) -> 0
A15: 2.2.1 - SERVICIOS BÁSICOS | B15: =SUM('TRANSFERENCIA CORRIENTE'!C16:E16) -> 2020024.3 | C15: =SUM('TRANSFERENCIA CORRIENTE'!F16:H16) -> 181605 | D15: =SUM('TRANSFERENCIA CORRIENTE'!J16:L16) -> 0 | E15: =SUM('TRANSFERENCIA CORRIENTE'!L16:N16) -> 0 | G15: =SUM(VS!C16:E16) -> 2341561.9 | H15: =SUM(VS!F16:H16) -> 2348580.7 | I15: =SUM(VS!I16:K16) -> 1781904.1 | J15: =SUM(VS!L16:N16) -> 0 | L15: =SUM(B15+G15) -> 4361586.2 | M15: =SUM(C15+H15) -> 2530185.7 | N15: =SUM(D15+I15) -> 1781904.1 | O15: =SUM(E15+J15) -> 0
A16: 2.2.2 - PUBLICIDAD, IMPRESIÓN Y ENCUADERNACIÓN | B16: =SUM('TRANSFERENCIA CORRIENTE'!C17:E17) -> 324206.83 | C16: =SUM('TRANSFERENCIA CORRIENTE'!F17:H17) -> 351993.83 | D16: =SUM('TRANSFERENCIA CORRIENTE'!J17:L17) -> 0 | E16: =SUM('TRANSFERENCIA CORRIENTE'!L17:N17) -> 0 | G16: =SUM(VS!C17:E17) -> 0 | H16: =SUM(VS!F17:H17) -> 310139.4 | I16: =SUM(VS!I17:K17) -> 581445 | J16: =SUM(VS!L17:N17) -> 0 | L16: =SUM(B16+G16) -> 324206.83 | M16: =SUM(C16+H16) -> 662133.23 | N16: =SUM(D16+I16) -> 581445 | O16: =SUM(E16+J16) -> 0
A17: 2.2.3 - VIÁTICOS | B17: =SUM('TRANSFERENCIA CORRIENTE'!C18:E18) -> 0 | C17: =SUM('TRANSFERENCIA CORRIENTE'!F18:H18) -> 0 | D17: =SUM('TRANSFERENCIA CORRIENTE'!J18:L18) -> 0 | E17: =SUM('TRANSFERENCIA CORRIENTE'!L18:N18) -> 0 | G17: =SUM(VS!C18:E18) -> 0 | H17: =SUM(VS!F18:H18) -> 0 | I17: =SUM(VS!I18:K18) -> 0 | J17: =SUM(VS!L18:N18) -> 0 | L17: =SUM(B17+G17) -> 0 | M17: =SUM(C17+H17) -> 0 | N17: =SUM(D17+I17) -> 0 | O17: =SUM(E17+J17) -> 0
A18: 2.2.4 - TRANSPORTE Y ALMACENAJE | B18: =SUM('TRANSFERENCIA CORRIENTE'!C19:E19) -> 0 | C18: =SUM('TRANSFERENCIA CORRIENTE'!F19:H19) -> 0 | D18: =SUM('TRANSFERENCIA CORRIENTE'!J19:L19) -> 0 | E18: =SUM('TRANSFERENCIA CORRIENTE'!L19:N19) -> 0 | G18: =SUM(VS!C19:E19) -> 56000 | H18: =SUM(VS!F19:H19) -> 96000 | I18: =SUM(VS!I19:K19) -> 8000 | J18: =SUM(VS!L19:N19) -> 0 | L18: =SUM(B18+G18) -> 56000 | M18: =SUM(C18+H18) -> 96000 | N18: =SUM(D18+I18) -> 8000 | O18: =SUM(E18+J18) -> 0
A19: 2.2.5 - ALQUILERES Y RENTAS | B19: =SUM('TRANSFERENCIA CORRIENTE'!C20:E20) -> 0 | C19: =SUM('TRANSFERENCIA CORRIENTE'!F20:H20) -> 150000 | D19: =SUM('TRANSFERENCIA CORRIENTE'!J20:L20) -> 0 | E19: =SUM('TRANSFERENCIA CORRIENTE'!L20:N20) -> 0 | G19: =SUM(VS!C20:E20) -> 519625.15 | H19: =SUM(VS!F20:H20) -> 759170.42 | I19: =SUM(VS!I20:K20) -> 298861.54 | J19: =SUM(VS!L20:N20) -> 0 | L19: =SUM(B19+G19) -> 519625.15 | M19: =SUM(C19+H19) -> 909170.42 | N19: =SUM(D19+I19) -> 298861.54 | O19: =SUM(E19+J19) -> 0
A20: 2.2.6 - SEGUROS | B20: =SUM('TRANSFERENCIA CORRIENTE'!C21:E21) -> 0 | C20: =SUM('TRANSFERENCIA CORRIENTE'!F21:H21) -> 0 | D20: =SUM('TRANSFERENCIA CORRIENTE'!J21:L21) -> 0 | E20: =SUM('TRANSFERENCIA CORRIENTE'!L21:N21) -> 0 | G20: =SUM(VS!C21:E21) -> 0 | H20: =SUM(VS!F21:H21) -> 0 | I20: =SUM(VS!I21:K21) -> 0 | J20: =SUM(VS!L21:N21) -> 0 | L20: =SUM(B20+G20) -> 0 | M20: =SUM(C20+H20) -> 0 | N20: =SUM(D20+I20) -> 0 | O20: =SUM(E20+J20) -> 0
A21: 2.2.7 - SERVICIOS DE CONSERVACIÓN, REPARACIONES MENORES E INSTALACIONES TEMPORALES | B21: =SUM('TRANSFERENCIA CORRIENTE'!C22:E22) -> 6474433.8 | C21: =SUM('TRANSFERENCIA CORRIENTE'!F22:H22) -> 5611474.3 | D21: =SUM('TRANSFERENCIA CORRIENTE'!J22:L22) -> 0 | E21: =SUM('TRANSFERENCIA CORRIENTE'!L22:N22) -> 0 | G21: =SUM(VS!C22:E22) -> 4556850.1 | H21: =SUM(VS!F22:H22) -> 1040817.6 | I21: =SUM(VS!I22:K22) -> 1632573.3 | J21: =SUM(VS!L22:N22) -> 0 | L21: =SUM(B21+G21) -> 11031284 | M21: =SUM(C21+H21) -> 6652291.9 | N21: =SUM(D21+I21) -> 1632573.3 | O21: =SUM(E21+J21) -> 0
A22: 2.2.8 - OTROS SERVICIOS NO INCLUIDOS EN CONCEPTOS ANTERIORES | B22: =SUM('TRANSFERENCIA CORRIENTE'!C23:E23) -> 489700 | C22: =SUM('TRANSFERENCIA CORRIENTE'!F23:H23) -> 413000 | D22: =SUM('TRANSFERENCIA CORRIENTE'!J23:L23) -> 0 | E22: =SUM('TRANSFERENCIA CORRIENTE'!L23:N23) -> 0 | G22: =SUM(VS!C23:E23) -> 832646.66 | H22: =SUM(VS!F23:H23) -> 1774418.3 | I22: =SUM(VS!I23:K23) -> 709371.88 | J22: =SUM(VS!L23:N23) -> 0 | L22: =SUM(B22+G22) -> 1322346.7 | M22: =SUM(C22+H22) -> 2187418.3 | N22: =SUM(D22+I22) -> 709371.88 | O22: =SUM(E22+J22) -> 0
A23: 2.2.9 - OTRAS CONTRATACIONES DE SERVICIOS | B23: =SUM('TRANSFERENCIA CORRIENTE'!C24:E24) -> 0 | C23: =SUM('TRANSFERENCIA CORRIENTE'!F24:H24) -> 3423745 | D23: =SUM('TRANSFERENCIA CORRIENTE'!J24:L24) -> 0 | E23: =SUM('TRANSFERENCIA CORRIENTE'!L24:N24) -> 0 | G23: =SUM(VS!C24:E24) -> 0 | H23: =SUM(VS!F24:H24) -> 910287.4 | I23: =SUM(VS!I24:K24) -> 0 | J23: =SUM(VS!L24:N24) -> 0 | L23: =SUM(B23+G23) -> 0 | M23: =SUM(C23+H23) -> 4334032.4 | N23: =SUM(D23+I23) -> 0 | O23: =SUM(E23+J23) -> 0
A24: 2.3 - MATERIALES Y SUMINISTROS | B24: =SUM(B25:B33) -> 46153283 | C24: =SUM(C25:C33) -> 52385651 | D24: =SUM(D25:D33) -> 38552154 | E24: =SUM(E25:E33) -> 0 | G24: =SUM(G25:G33) -> 7292547.3 | H24: =SUM(H25:H33) -> 6552680.6 | I24: =SUM(I25:I33) -> 3444623.9 | J24: =SUM(J25:J33) -> 0 | L24: =SUM(B24+G24) -> 53445831 | M24: =SUM(C24+H24) -> 58938331 | N24: =SUM(D24+I24) -> 41996778 | O24: =SUM(E24+J24) -> 0
A25: 2.3.1 - ALIMENTOS Y PRODUCTOS AGROFORESTALES | B25: =SUM('TRANSFERENCIA CORRIENTE'!C26:E26) -> 3713897.2 | C25: =SUM('TRANSFERENCIA CORRIENTE'!F26:H26) -> 4866999.2 | D25: =SUM('TRANSFERENCIA CORRIENTE'!I23:K23) -> 0 | E25: =SUM('TRANSFERENCIA CORRIENTE'!L26:N26) -> 0 | G25: =SUM(VS!C26:E26) -> 1500755.8 | H25: =SUM(VS!F26:H26) -> 663230 | I25: =SUM(VS!I26:K26) -> 360730 | J25: =SUM(VS!L26:N26) -> 0 | L25: =SUM(B25+G25) -> 5214653 | M25: =SUM(C25+H25) -> 5530229.2 | N25: =SUM(D25+I25) -> 360730 | O25: =SUM(E25+J25) -> 0
A26: 2.3.2 - TEXTILES Y VESTUARIOS | B26: =SUM('TRANSFERENCIA CORRIENTE'!C27:E27) -> 61630.73 | C26: =SUM('TRANSFERENCIA CORRIENTE'!F27:H27) -> 2375399.4 | D26: =SUM('TRANSFERENCIA CORRIENTE'!I24:K24) -> 0 | E26: =SUM('TRANSFERENCIA CORRIENTE'!L27:N27) -> 0 | G26: =SUM(VS!C27:E27) -> 0 | H26: =SUM(VS!F27:H27) -> 346306.4 | I26: =SUM(VS!I27:K27) -> 0 | J26: =SUM(VS!L27:N27) -> 0 | L26: =SUM(B26+G26) -> 61630.73 | M26: =SUM(C26+H26) -> 2721705.8 | N26: =SUM(D26+I26) -> 0 | O26: =SUM(E26+J26) -> 0
A27: 2.3.3 - PRODUCTOS DE PAPEL, CARTÓN E IMPRESOS | B27: =SUM('TRANSFERENCIA CORRIENTE'!C28:E28) -> 1826911.8 | C27: =SUM('TRANSFERENCIA CORRIENTE'!F28:H28) -> 2991695.7 | D27: =SUM('TRANSFERENCIA CORRIENTE'!I25:K25) -> 26146220 | E27: =SUM('TRANSFERENCIA CORRIENTE'!L28:N28) -> 0 | G27: =SUM(VS!C28:E28) -> 251163 | H27: =SUM(VS!F28:H28) -> 803989 | I27: =SUM(VS!I28:K28) -> 26550 | J27: =SUM(VS!L28:N28) -> 0 | L27: =SUM(B27+G27) -> 2078074.8 | M27: =SUM(C27+H27) -> 3795684.7 | N27: =SUM(D27+I27) -> 26172770 | O27: =SUM(E27+J27) -> 0
A28: 2.3.4 - PRODUCTOS FARMACÉUTICOS | B28: =SUM('TRANSFERENCIA CORRIENTE'!C29:E29) -> 10797336 | C28: =SUM('TRANSFERENCIA CORRIENTE'!F29:H29) -> 12009357 | D28: =SUM('TRANSFERENCIA CORRIENTE'!I26:K26) -> 1787251.8 | E28: =SUM('TRANSFERENCIA CORRIENTE'!L29:N29) -> 0 | G28: =SUM(VS!C29:E29) -> 558000 | H28: =SUM(VS!F29:H29) -> 402220.76 | I28: =SUM(VS!I29:K29) -> 152800 | J28: =SUM(VS!L29:N29) -> 0 | L28: =SUM(B28+G28) -> 11355336 | M28: =SUM(C28+H28) -> 12411577 | N28: =SUM(D28+I28) -> 1940051.8 | O28: =SUM(E28+J28) -> 0
A29: 2.3.5 - PRODUCTOS DE CUERO, CAUCHO Y PLÁSTICO | B29: =SUM('TRANSFERENCIA CORRIENTE'!C30:E30) -> 334708.95 | C29: =SUM('TRANSFERENCIA CORRIENTE'!F30:H30) -> 1024240.4 | D29: =SUM('TRANSFERENCIA CORRIENTE'!I27:K27) -> 1577150.7 | E29: =SUM('TRANSFERENCIA CORRIENTE'!L30:N30) -> 0 | G29: =SUM(VS!C30:E30) -> 567494.87 | H29: =SUM(VS!F30:H30) -> 0 | I29: =SUM(VS!I30:K30) -> 77390.01 | J29: =SUM(VS!L30:N30) -> 0 | L29: =SUM(B29+G29) -> 902203.82 | M29: =SUM(C29+H29) -> 1024240.4 | N29: =SUM(D29+I29) -> 1654540.7 | O29: =SUM(E29+J29) -> 0
A30: 2.3.6 - PRODUCTOS DE MINERALES, METÁLICOS Y NO METÁLICOS | B30: =SUM('TRANSFERENCIA CORRIENTE'!C31:E31) -> 11630.98 | C30: =SUM('TRANSFERENCIA CORRIENTE'!F31:H31) -> 667620.59 | D30: =SUM('TRANSFERENCIA CORRIENTE'!I28:K28) -> 1579886.7 | E30: =SUM('TRANSFERENCIA CORRIENTE'!L31:N31) -> 0 | G30: =SUM(VS!C31:E31) -> 293957.3 | H30: =SUM(VS!F31:H31) -> 0 | I30: =SUM(VS!I31:K31) -> 24157.95 | J30: =SUM(VS!L31:N31) -> 0 | L30: =SUM(B30+G30) -> 305588.28 | M30: =SUM(C30+H30) -> 667620.59 | N30: =SUM(D30+I30) -> 1604044.6 | O30: =SUM(E30+J30) -> 0
A31: 2.3.7 - COMBUSTIBLES, LUBRICANTES, PRODUCTOS QUÍMICOS Y CONEXOS | B31: =SUM('TRANSFERENCIA CORRIENTE'!C32:E32) -> 8910102 | C31: =SUM('TRANSFERENCIA CORRIENTE'!F32:H32) -> 10068979 | D31: =SUM('TRANSFERENCIA CORRIENTE'!I29:K29) -> 6806505 | E31: =SUM('TRANSFERENCIA CORRIENTE'!L32:N32) -> 0 | G31: =SUM(VS!C32:E32) -> 1660334.6 | H31: =SUM(VS!F32:H32) -> 1500202 | I31: =SUM(VS!I32:K32) -> 1044515 | J31: =SUM(VS!L32:N32) -> 0 | L31: =SUM(B31+G31) -> 10570437 | M31: =SUM(C31+H31) -> 11569181 | N31: =SUM(D31+I31) -> 7851020 | O31: =SUM(E31+J31) -> 0
A32: 2.3.8 - GASTOS QUE SE ASIGNARÁN DURANTE EL EJERCICIO (ART. 32 Y 33 LEY 423-06) | B32: =SUM('TRANSFERENCIA CORRIENTE'!C33:E33) -> 0 | C32: =SUM('TRANSFERENCIA CORRIENTE'!F33:H33) -> 0 | D32: =SUM('TRANSFERENCIA CORRIENTE'!I30:K30) -> 655140.22 | E32: =SUM('TRANSFERENCIA CORRIENTE'!L33:N33) -> 0 | G32: =SUM(VS!C33:E33) -> 0 | H32: =SUM(VS!F33:H33) -> 0 | I32: =SUM(VS!I33:K33) -> 0 | J32: =SUM(VS!L33:N33) -> 0 | L32: =SUM(B32+G32) -> 0 | M32: =SUM(C32+H32) -> 0 | N32: =SUM(D32+I32) -> 655140.22 | O32: =SUM(E32+J32) -> 0
A33: 2.3.9 - PRODUCTOS Y ÚTILES VARIOS | B33: =SUM('TRANSFERENCIA CORRIENTE'!C34:E34) -> 20497066 | C33: =SUM('TRANSFERENCIA CORRIENTE'!F34:H34) -> 18381359 | D33: =SUM('TRANSFERENCIA CORRIENTE'!I31:K31) -> 0 | E33: =SUM('TRANSFERENCIA CORRIENTE'!L34:N34) -> 0 | G33: =SUM(VS!C34:E34) -> 2460841.8 | H33: =SUM(VS!F34:H34) -> 2836732.4 | I33: =SUM(VS!I34:K34) -> 1758480.9 | J33: =SUM(VS!L34:N34) -> 0 | L33: =SUM(B33+G33) -> 22957908 | M33: =SUM(C33+H33) -> 21218092 | N33: =SUM(D33+I33) -> 1758480.9 | O33: =SUM(E33+J33) -> 0
A34: 2.4 - TRANSFERENCIAS CORRIENTES | B34: =SUM(B35:B41) -> 0 | C34: =SUM(C35:C41) -> 0 | D34: =SUM(D35:D41) -> 0 | E34: =SUM(E35:E41) -> 0 | G34: =SUM(G35:G41) -> 287786.7 | H34: =SUM(H35:H41) -> 1223981 | I34: =SUM(I35:I41) -> 67571 | J34: =SUM(J35:J41) -> 0 | L34: =SUM(B34+G34) -> 287786.7 | M34: =SUM(C34+H34) -> 1223981 | N34: =SUM(D34+I34) -> 67571 | O34: =SUM(E34+J34) -> 0
A35: 2.4.1 - TRANSFERENCIAS CORRIENTES AL SECTOR PRIVADO | B35: =SUM('TRANSFERENCIA CORRIENTE'!C36:E36) -> 0 | C35: =SUM('TRANSFERENCIA CORRIENTE'!F36:H36) -> 0 | D35: =SUM('TRANSFERENCIA CORRIENTE'!I36:K36) -> 0 | E35: =SUM('TRANSFERENCIA CORRIENTE'!L36:N36) -> 0 | G35: =SUM(VS!C36:E36) -> 287786.7 | H35: =SUM(VS!F36:H36) -> 1163981 | I35: =SUM(VS!I36:K36) -> 67571 | J35: =SUM(VS!L36:N36) -> 0 | L35: =SUM(B35+G35) -> 287786.7 | M35: =SUM(C35+H35) -> 1163981 | N35: =SUM(D35+I35) -> 67571 | O35: =SUM(E35+J35) -> 0
A36: 2.4.2 - TRANSFERENCIAS CORRIENTES AL GOBIERNO GENERAL NACIONAL | B36: =SUM('TRANSFERENCIA CORRIENTE'!C37:E37) -> 0 | C36: =SUM('TRANSFERENCIA CORRIENTE'!F37:H37) -> 0 | D36: =SUM('TRANSFERENCIA CORRIENTE'!I37:K37) -> 0 | E36: =SUM('TRANSFERENCIA CORRIENTE'!L37:N37) -> 0 | G36: =SUM(VS!C37:E37) -> 0 | H36: =SUM(VS!F37:H37) -> 60000 | I36: =SUM(VS!I37:K37) -> 0 | J36: =SUM(VS!L37:N37) -> 0 | L36: =SUM(B36+G36) -> 0 | M36: =SUM(C36+H36) -> 60000 | N36: =SUM(D36+I36) -> 0 | O36: =SUM(E36+J36) -> 0
A37: 2.4.3 - TRANSFERENCIAS CORRIENTES A GOBIERNOS GENERALES LOCALES | B37: =SUM('TRANSFERENCIA CORRIENTE'!C38:E38) -> 0 | C37: =SUM('TRANSFERENCIA CORRIENTE'!F38:H38) -> 0 | D37: =SUM('TRANSFERENCIA CORRIENTE'!I38:K38) -> 0 | E37: =SUM('TRANSFERENCIA CORRIENTE'!L38:N38) -> 0 | G37: =SUM(VS!C38:E38) -> 0 | H37: =SUM(VS!F38:H38) -> 0 | I37: =SUM(VS!I38:K38) -> 0 | J37: =SUM(VS!L38:N38) -> 0 | L37: =SUM(B37+G37) -> 0 | M37: =SUM(C37+H37) -> 0 | N37: =SUM(D37+I37) -> 0 | O37: =SUM(E37+J37) -> 0
A38: 2.4.4 - TRANSFERENCIAS CORRIENTES A EMPRESAS PÚBLICAS NO FINANCIERAS | B38: =SUM('TRANSFERENCIA CORRIENTE'!C39:E39) -> 0 | C38: =SUM('TRANSFERENCIA CORRIENTE'!F39:H39) -> 0 | D38: =SUM('TRANSFERENCIA CORRIENTE'!I39:K39) -> 0 | E38: =SUM('TRANSFERENCIA CORRIENTE'!L39:N39) -> 0 | G38: =SUM(VS!C39:E39) -> 0 | H38: =SUM(VS!F39:H39) -> 0 | I38: =SUM(VS!I39:K39) -> 0 | J38: =SUM(VS!L39:N39) -> 0 | L38: =SUM(B38+G38) -> 0 | M38: =SUM(C38+H38) -> 0 | N38: =SUM(D38+I38) -> 0 | O38: =SUM(E38+J38) -> 0
A39: 2.4.5 - TRANSFERENCIAS CORRIENTES A INSTITUCIONES PÚBLICAS FINANCIERAS | B39: =SUM('TRANSFERENCIA CORRIENTE'!C40:E40) -> 0 | C39: =SUM('TRANSFERENCIA CORRIENTE'!F40:H40) -> 0 | D39: =SUM('TRANSFERENCIA CORRIENTE'!I40:K40) -> 0 | E39: =SUM('TRANSFERENCIA CORRIENTE'!L40:N40) -> 0 | G39: =SUM(VS!C40:E40) -> 0 | H39: =SUM(VS!F40:H40) -> 0 | I39: =SUM(VS!I40:K40) -> 0 | J39: =SUM(VS!L40:N40) -> 0 | L39: =SUM(B39+G39) -> 0 | M39: =SUM(C39+H39) -> 0 | N39: =SUM(D39+I39) -> 0 | O39: =SUM(E39+J39) -> 0
A40: 2.4.7 - TRANSFERENCIAS CORRIENTES AL SECTOR EXTERNO | B40: =SUM('TRANSFERENCIA CORRIENTE'!C41:E41) -> 0 | C40: =SUM('TRANSFERENCIA CORRIENTE'!F41:H41) -> 0 | D40: =SUM('TRANSFERENCIA CORRIENTE'!I41:K41) -> 0 | E40: =SUM('TRANSFERENCIA CORRIENTE'!L41:N41) -> 0 | G40: =SUM(VS!C41:E41) -> 0 | H40: =SUM(VS!F41:H41) -> 0 | I40: =SUM(VS!I41:K41) -> 0 | J40: =SUM(VS!L41:N41) -> 0 | L40: =SUM(B40+G40) -> 0 | M40: =SUM(C40+H40) -> 0 | N40: =SUM(D40+I40) -> 0 | O40: =SUM(E40+J40) -> 0
A41: 2.4.9 - TRANSFERENCIAS CORRIENTES A OTRAS INSTITUCIONES PÚBLICAS | B41: =SUM('TRANSFERENCIA CORRIENTE'!C42:E42) -> 0 | C41: =SUM('TRANSFERENCIA CORRIENTE'!F42:H42) -> 0 | D41: =SUM('TRANSFERENCIA CORRIENTE'!I42:K42) -> 0 | E41: =SUM('TRANSFERENCIA CORRIENTE'!L42:N42) -> 0 | G41: =SUM(VS!C42:E42) -> 0 | H41: =SUM(VS!F42:H42) -> 0 | I41: =SUM(VS!I42:K42) -> 0 | J41: =SUM(VS!L42:N42) -> 0 | L41: =SUM(B41+G41) -> 0 | M41: =SUM(C41+H41) -> 0 | N41: =SUM(D41+I41) -> 0 | O41: =SUM(E41+J41) -> 0
...

Sheet TRANSFERENCIA CORRIENTE
A1: SERVICIO NACIONAL DE SALUD
A2: HOSPITAL MATERNO INFANTIL SAN LORENZO DE LOS MINA
A3: REGION
A4: Ejecución de Gastos Fondo (100) 2025
A5: En RD$
A7: Detalle | B7: Total | C7: Enero | D7: Febrero | E7: Marzo | F7: Abril | G7: Mayo | H7: Junio | I7: Julio | J7: Agosto | K7: Septiembre | L7: Octubre | M7: Noviembre | N7: Diciembre
A8: 2 - GASTOS
A9: 2.1 - REMUNERACIONES Y CONTRIBUCIONES | B9: =SUM(C9:N9) -> 4.6966673e+08 | C9: =SUM(C10:C14) -> 65091180 | D9: =SUM(D10:D14) -> 67131936 | E9: =SUM(E10:E14) -> 66337620 | F9: =SUM(F10:F14) -> 66556156 | G9: =SUM(G10:G14) -> 66630551 | H9: =SUM(H10:H14) -> 66583615 | I9: =SUM(I10:I14) -> 71335676 | J9: =SUM(J10:J14) -> 0 | ... N9: =SUM(N10:N14) -> 0
A10: 2.1.1 - REMUNERACIONES | B10: =SUM(C10:N10) -> 3.8695541e+08 | C10: 53640339 | D10: 55586129 | E10: 54718737 | F10: 54771097 | G10: 54445140 | H10: 54868543 | I10: 58925421
A11: 2.1.2 - SOBRESUELDOS | B11: =SUM(C11:N11) -> 23475078 | C11: 3196999.6 | D11: 3197999.6 | E11: 3199399.6 | F11: 3384964.5 | G11: 3807608.3 | H11: 3343226.2 | I11: 3344880.2
A12: 2.1.3 - DIETAS Y GASTOS DE REPRESENTACIÓN | B12: =SUM(C12:N12) -> 0
