Workbook

Sheet RELACION DE PAGOS EMITIDOS
A5: DIRECCION DE FISCALIZACION Y CONTROL
A6: RELACION DE PAGOS EMITIDOS DURANTE EL MES
A7: ESTABLECIMIENTO:HOSPITAL MATERNO INFANTIL SAN LORENZO DE LOS MINA
A9: PAGOS CORRESPONDIENTES AL MES : MARZO 2025
A10: FECHA | B10: LIBRAMIENTO | C10: TRANSFERENCIA | D10: CHEQUE | E10: BENEFICIARIO | F10: NO.FACTURAS | G10: VALOR DE FACTURA | H10: VALOR PAGADO
A11: 45719 | C11: 58 | E11: P&D RECYCLING, SRL | F11: FACT B1500000304 | G11: 760000 | H11: 722000
A12: 45719 | C12: 59 | E12: REFRICLIMA HF, SRL | F12: FACT B1500000868 | G12: 192930 | H12: 184755
A13: 45721 | C13: 60 | E13: LEFP CONSULTORES, SRL | F13: FACT B1500000342 | G13: 48852 | H13: 46782
A14: 45721 | C14: 61 | E14: IV BIODESINFECCION, SRL | F14: FACT B1500000279 | G14: 188564 | H14: 180574
A15: 45721 | C15: 62 | E15: ORTRO CHEMICAL, SRL | F15: FACT B1500000367 | G15: 42000 | H15: 39900
A16: 45721 | C16: 63 | E16: INVERSIONES FH, SRL | F16: FACT B1500001471 | G16: 172000 | H16: 170573.26
A17: 45721 | C17: 64 | E17: TROPIGAS DOMINICANA, SRL | F17: E450000005356, E450000005368, E450000006369 | G17: 55029 | H17: 55029
A18: 45722 | C18: 65 | E18: LORA & ALMONTE REPARACIONES, SRL | F18: FACT B1500000194 | G18: 41305.02 | H18: 39555.02
A19: 45722 | C19: 66 | E19: HOSPAL MEDICAL, SRL | F19: FACT B1500017801 | G19: 34220 | H19: 32770
A20: 45722 | C20: 67 | E20: DIUCAM GROUP, SRL | F20: FACT B1500000007 | G20: 473584 | H20: 451814
A21: 45722 | C21: 68 | E21: DOCTORES MALLEN GUERRA | F21: COT. DM-COT009852-1 | G21: 61500 | H21: 58425
A22: 45723 | C22: 69 | E22: GTA ELEVATORS, SRL | F22: FACT B1500000019 | G22: 636067.2 | H22: 609115.2
... A31: 45730 | C31: 78 | E31: SOLUCIONES DE SERVICIOS Y TECNICAS ALTADIS, SRL | F31: PAGO DE FACT NCF NO. B1500000100 | G31: 107609.37 | H31: 103049.65
A32: 45730 | C32: 79 | E32: LILIAN YOMAIRA ENCARNACION | G32: 20000 | H32: 20000
A33: 45735 | C33: 80 | E33: ADLER AMICIS VALDEZ MARMOLEJOS | F33: FACT B1500000255 | G33: 26845 | H33: 25707.5
A34: 45735 | C34: 81 | E34: JESUS FERMIN MARTINEZ LOPEZ | F34: FACT B1500000423 | G34: 8000 | H34: 7600
A35: 45735 | C35: 82 | E35: SUPLIMED | F35: FACT B1500005690, B1500005703, B1500005706 | G35: 225000 | H35: 213750
A36: 45740 | C36: 83 | E36: CENTRO DE ESTUDIOS MEDICOS Y DIAGNOSTICOS POR IMÁGENES, SRL | F36: FACTS NCF B1500000364 Y B1500000370 | G36: 83800 | H36: 79610
A37: 45740 | C37: =+C36+1 -> 84 | E37: ADLER AMICIS VALDEZ MARMOLEJOS | F37: FACT NCF B1500000257 | G37: 31152 | H37: 29832
A38: 45740 | C38: =+C37+1 -> 85 | E38: TROPIGAS DOMINICANA, SRL | F38: FACT NCF E450000005393 | G38: 22542 | H38: 22542
A39: 45742 | C39: =+C38+1 -> 86 | E39: JESUS FERMIN MARTINEZ LOPEZ | F39: FACT B1500000426 | G39: 24000 | H39: 22800
A40: 45743 | C40: =+C39+1 -> 87 | E40: LORA & ALMONTE REPARACIONES, SRL | F40: FACT B1500000196 | G40: 105649.96 | H40: 101173.27
A41: 45743 | C41: =+C40+1 -> 88 | E41: COLEGIO DOMINICANO DE PROFESIONALES DE ENFERMERIA | F41: COLABORACION DE UN 50% PARA EL XVIII CONGRESO NACIONAL DE ENFERMERIA | G41: 40000 | H41: 40000
A42: 45743 | C42: =+C41+1 -> 89 | E42: PLANETA AZUL. SA | F42: FACT NCF E450000009903, E450000001760 | G42: 14000 | H42: 14000
A43: 45743 | C43: =+C42+1 -> 90 | E43: PLANETA AZUL. SA | F43: FACT NCF E450000009389, E450000009385 | G43: 11640 | H43: 11640
A44: 45743 | C44: =+C43+1 -> 91 | E44: PLANETA AZUL. SA | F44: FACT NCF E450000009396, E450000009390, E450000006400 | G44: 23580 | H44: 23580
A45: 45744 | C45: =+C44+1 -> 92 | E45: ELIGIUM, SRL | F45: PAGO DE FACT NCF NO. B1500000021 | G45: 272580 | H45: 261030
A46: 45744 | C46: =+C45+1 -> 93 | E46: MANTENERGIA ELECTRICA Y ABASTECIMIENTOS, SRL | F46: PAGO DE FACT B1500000162 | G46: 248711.41 | H46: 238172.79
A47: 45744 | C47: =+C46+1 -> 94 | E47: INGENIERIA Y CONSTRUCCIONES FASUMER, SRL | F47: PAGO DE FACT NCF NO B1500000151 | G47: 271800.26 | H47: 260283.3
A48: 45744 | C48: =+C47+1 -> 95 | E48: MANTENERGIA ELECTRICA Y ABASTECIMIENTOS, SRL | F48: PAGO FACT NCF NO. B1500000163 | G48: 230085.84 | H48: 220336.44
... A50: 45747 | C50: =+C49+1 -> 97 | E50: P&D RECYCLING, SRL | F50: PAGO DE FACT NCF NO. B1500000306 | G50: 760000 | H50: 722000
A51: 45747 | C51: 98 | E51: NOMINA POR PAGAR INCENTIVO | F51: NOMINA INCENTIVO | G51: 5231553.6 | H51: 5231553.6
A52: 45719 | D52: 37197 | E52: NULO | F52: NULO | G52: 0 | H52: 0
A53: 45719 | D53: 37198 | E53: BILLY DRAY GONZALEZ GONZALEZ | F53: COLABORACION PARA ESTUDIO ANGIOTOMOGRAFIA CEREBRAL, PARA EL PACIENTE JESUS GOZALEZ | G53: 26000 | H53: 26000
A54: 45719 | D54: 37199 | E54: HECTOR BIENVENIDO DIAZ BURGOS | F54: PAGO POR LA PLATAFORMA DATA INSTALADA EN LA INSTITUCION | G54: 14000 | H54: 14000
...

Sheet RELACION ORDENES DE COMPRAS
A3: Republica Dominicana
A6: RELACIÓN DE ORDENES DE COMPRAS O SERVICIOS EFECTUADAS DURANTE EL MES
A7: ESTABLECIMIENTO_______________________________________________________________REGION_____________________
A8: Fecha | B8: # De Orden de Compras | C8: Proceso Realizado | D8: No. De Factura Fiscal NCF | E8: Fuente. Financ (FR-VS) | F8: Beneficiario | G8: Rubro | H8: No. Cta. Objetal del Gasto | I8: Valor
A9: 45719.501 | B9: HSLM-DAF-CD-2025-0178 | C9: Compras por Debajo del Umbral | E9: FR/VS | F9: PROYEFIC INGENIERIA Y SERVICIOS, SRL | G9: 72100000 | I9: 272432.5
A10: 45719.501 | B10: HSLM-DAF-CD-2025-0180 | C10: Compras por Debajo del Umbral | E10: FR/VS | F10: INGENIERIA Y CONSTRUCCIONES FASUMER, SRL | G10: 72100000 | I10: 271800.26
A11: 45719.501 | B11: HSLM-DAF-CD-2025-0179 | C11: Compras por Debajo del Umbral | E11: FR/VS | F11: Eligium, EIRL | G11: 72100000 | I11: 272580
A12: 45720.501 | B12: HSLM-DAF-CD-2025-0181 | C12: Compras por Debajo del Umbral | E12: FR/VS | F12: Bio Win, SRL | G12: 41110000 | I12: 30000
A13: 45720.542 | B13: HSLM-DAF-CD-2025-0183 | C13: Compras por Debajo del Umbral | E13: FR/VS | F13: Express Service Conserg Exsercon, SRL | G13: 42180000 | I13: 230320
A14: 45720.542 | B14: HSLM-DAF-CM-2025-0050 | C14: Compras Menores | E14: FR/VS | F14: Corporacion Medica A.G., SRL | G14: 42310000 | I14: 525648
A15: 45720.542 | B15: HSLM-DAF-CD-2025-0184 | C15: Compras por Debajo del Umbral | E15: FR/VS | F15: INVERSIONES FH, SRL | G15: 15100000 | I15: 172000
A16: 45720.542 | B16: HSLM-DAF-CD-2025-0182 | C16: Compras por Debajo del Umbral | E16: FR/VS | F16: Corporacion Medica A.G., SRL | G16: 42130000 | I16: 201500
A17: 45720.584 | B17: HSLM-DAF-CM-2025-0051 | C17: Compras Menores | E17: FR/VS | F17: Farmaco Internacional, SRL | G17: 42310000 | I17: 1937560
A18: 45720.626 | B18: HSLM-DAF-CM-2025-0052 | C18: Compras Menores | E18: FR/VS | F18: Baucomer, SRL | G18: 51150000 | I18: 1518000
A19: 45720.626 | B19: HSLM-DAF-CM-2025-0053 | C19: Compras Menores | E19: FR/VS | F19: Baucomer, SRL | G19: 42310000 | I19: 1056640
A20: 45721.501 | B20: HSLM-DAF-CD-2025-0185 | C20: Compras por Debajo del Umbral | E20: FR/VS | F20: Cristina Rosario Rosario | G20: 42140000 | I20: 212284
... A67: 45735.424 | B67: HSLM-DAF-CD-2025-0223 | C67: Compras por Debajo del Umbral | E67: FR/VS | F67: Ropharma, SRL | G67: 51170000 | I67: 180000
A68: 45735.438 | B68: HSLM-DAF-CD-2025-0224 | C68: Compras por Debajo del Umbral | D68: CANCELADO | E68: FR/VS | F68: CANCELADO | G68: 51100000 | I68: 0
A69: 45735.459 | B69: HSLM-DAF-CD-2025-0221 | C69: Compras por Debajo del Umbral | E69: FR/VS | F69: Felipe Antonio Morey Paulino | G69: 82120000 | I69: 196824
A70: 45735.502 | B70: HSLM-DAF-CD-2025-0225 | C70: Compras por Debajo del Umbral | E70: FR/VS | F70: Empresa Rotricomercial, SRL | G70: 51150000 | I70: 210000
A71: 45735.618 | B71: HSLM-DAF-CD-2025-0226 | C71: Compras por Debajo del Umbral | E71: FR/VS | F71: Grupo Irmaceli Services, S.R.L. | G71: 46190000 | I71: 61950
A72: 45735.668 | B72: HSLM-DAF-CD-2025-0227 | C72: Compras por Debajo del Umbral | E72: FR/VS | F72: Lora & Almonte Reparaciones, SRL | G72: 27110000 | I72: 105650
A73: 45736.479 | B73: HSLM-DAF-CM-2025-0065 | C73: Compras Menores | D73: CANCELADO | E73: FR/VS | F73: CANCELADO | G73: 50110000 | I73: 0
A74: 45736.542 | B74: HSLM-DAF-CM-2025-0064 | C74: Compras Menores | E74: FR/VS | F74: BAAM & ASOCIADOS | G74: 44100000 | I74: 436278.18
A75: 45736.604 | B75: HSLM-DAF-CD-2025-0228 | C75: Compras por Debajo del Umbral | E75: FR/VS | F75: Ropharma, SRL | G75: 51190000 | I75: 272580
A76: 45736.626 | B76: HSLM-DAF-CD-2025-0229 | C76: Compras por Debajo del Umbral | E76: FR/VS | F76: Bello-Lab, SRL | G76: 41100000 | I76: 123885
A77: 45736.646 | B77: HSLM-DAF-CM-2025-0066 | C77: Compras Menores | E77: FR/VS | F77: Sandry Gomez Rodriguez | G77: 50100000 | I77: 436930
A78: 45737.418 | B78: HSLM-DAF-CD-2025-0230 | C78: Compras por Debajo del Umbral | E78: FR/VS | F78: Copem Hospiclinic, SRL | G78: 51140000 | I78: 219375
A79: 45737.502 | B79: HSLM-DAF-CM-2025-0067 | C79: Compras Menores | E79: FR/VS | F79: Tu Amigo, SRL | G79: 15100000 | I79: 664800
A80: 45737.521 | B80: HSLM-DAF-CD-2025-0231 | C80: Compras por Debajo del Umbral | E80: FR/VS | F80: Copem Hospiclinic, SRL | G80: 51180000 | I80: 272500
A81: 45737.549 | B81: HSLM-DAF-CD-2025-0232 | C81: Compras por Debajo del Umbral | E81: FR/VS | F81: Bio Desinfeccion, SRL | G81: 76100000 | I81: 188564
A82: 45737.709 | B82: HSLM-DAF-CD-2025-0233 | C82: Compras por Debajo del Umbral | E82: FR/VS | F82: Bio Nova, SRL | G82: 41110000 | I82: 103887
A83: 45740.459 | B83: HSLM-DAF-CD-2025-0235 | C83: Compras por Debajo del Umbral | E83: FR/VS | F83: Abrias Novo Group SRL | G83: 52130000 | I83: 129800
A84: 45740.459 | B84: HSLM-DAF-CD-2025-0234 | C84: Compras por Debajo del Umbral | E84: FR/VS | F84: Abrias Novo Group SRL | G84: 56100000 | I84: 252028
A85: 45740.459 | B85: HSLM-DAF-CM-2025-0068 | C85: Compras Menores | E85: FR/VS | F85: Food Caraballo & Nuñez | G85: 50130000 | I85: 269657.5
... A96: 45742.542 | B96: HSLM-DAF-CM-2025-0073 | C96: Compras Menores | E96: FR/VS | F96: Hospitronica | G96: 42190000 | I96: 621605.1
A97: 45742.585 | B97: HSLM-DAF-CM-2025-0072 | C97: Compras Menores | E97: FR/VS | G97: 50190000
A98: 45742.626 | B98: HSLM-DAF-CD-2025-0243 | C98: Compras por Debajo del Umbral | E98: FR/VS | F98: Sandry Gomez Rodriguez | G98: 50110000 | I98: 234200
A99: 45744.376 | B99: HSLM-DAF-CD-2025-0244 | C99: Compras por Debajo del Umbral | E99: FR/VS | F99: Grupo Xeron Medic SRL | G99: 51190000 | I99: 250000
A100: 45744.419 | B100: HSLM-DAF-CD-2025-0245 | C100: Compras por Debajo del Umbral | E100: FR/VS | F100: Papelería E. Impresos Crishoan, SRL | G100: 82120000 | I100: 261960
...

Sheet CONS. FUENTES FINAN
A1: Form. No.6 SRS
A3: Servicio Nacional de Salud
A4: Dirección de Fizcalización
A5: Consolidado de Ingresos y Gastos por Fuente de Financiamiento
A6: HOSPITAL MATERNO INFANTIL SAN LORENZO DE LOS MINA
A7: MARZO 2025
C8: Ingresos Generales:
E9: 1.- Balance Inicial / Fuente:
E10: Anticipo Financiero | H10: Otros Aportes | L10: Contraseña: 0001
E11: Transferencias Corrientes
E12: Venta de Servicios | G12: 2511952.5
E13: 2.- Ingresos por Fuente / Cuenta
E14: Anticipo Financiero | H14: Otros Aportes | I14: =+'INGR SEGUN ORIGEN'!E39 -> 223625 | L14: OBJETAL | M14: FR | N14: VS
E15: Transferencias Corrientes | G15: =+'INGR SEGUN ORIGEN'!E12 -> 1.003168e+08 | H15: Aportes Nomina SNS | I15: 0 | L15: 2.1 | M15: =G26 -> 66337620 | N15: =H26 -> 5231553.6
E16: Venta de Servicios | G16: =+'INGR SEGUN ORIGEN'!E37 -> 7825280.6 | L16: 2.2 | M16: =G87 -> 7971396.2 | N16: =H87 -> 4359456.2
H17: TOTAL INGRESOS RDS | I17: =+G10+G11+G12+I10+G14+G15+G16+I14+I15 -> 1.1087765e+08 | L17: 2.3 | M17: ='CONS. FUENTES FINAN'!G212 -> 26749552 | N17: ='CONS. FUENTES FINAN'!H212 -> 1797538.3
L18: 2.4 | M18: =G330 -> 0 | N18: =H330 -> 127420
L19: 2.6 | M19: =G336 -> 11396849 | N19: =H336 -> 300539.37
L20: 2.7 | M20: ='CONS. FUENTES FINAN'!G463 -> 0 | N20: ='CONS. FUENTES FINAN'!H463 -> 0
A21: 1 | F21: 2 | G21: 3 | I21: 4 | J21: 5
A22: Código Presupuestario | F22: Descripción Gasto por Cuenta | G22: Distribución del Gasto por Fuente de Financiamiento | I22: TOTAL | J22: %
A23: Tipo | B23: Objeto | C23: Cuenta | D23: Sub-Cuenta | E23: Auxiliar | G23: Fondo 100 | H23: Venta de Servicios/ Otros Aportes
A25: 2 | F25: Gastos | G25: =+G26+G87+G212+G330+G336+G463 -> 1.1245542e+08 | H25: =+H26+H87+H212+H330+H336+H463 -> 11816507 | I25: =SUM(G25:H25) -> 1.2427192e+08 | J25: =+J26+J87+J212+J330+J336+J463 -> 1
A26: 2 | B26: 1 | F26: Servicios Personales | G26: =+G27+G51+G64+G71+G78 -> 66337620 | H26: =+H27+H51+H64+H71+H78 -> 5231553.6 | I26: =SUM(G26:H26) -> 71569173 | J26: =I26/$I$25 -> 0.57590782
A27: 2 | B27: 1 | C27: 1 | F27: Remuneraciones | G27: =+G28+G35+G42+G44+G46 -> 54718737 | H27: =+H28+H35+H42+H44+H46 -> 0 | I27: =SUM(G27:H27) -> 54718737 | J27: =I27/$I$25 -> 0.44031455
A28: 2 | B28: 1 | C28: 1 | D28: 1 | F28: Remuneraciones al personal fijo | G28: =SUM(G29:G34) -> 53611206 | H28: =SUM(H29:H34) -> 0 | I28: =SUM(G28:H28) -> 53611206 | J28: =I28/$I$25 -> 0.4314024
A29: 2 | B29: 1 | C29: 1 | D29: 1 | E29: 01 | F29: Sueldos a empleados fijos | G29: ='CUENTA T FONDO 100'!A127 -> 53611206 | H29: ='CUENTA T VS'!A96 -> 0 | I29: =SUM(G29:H29) -> 53611206 | J29: =I29/$I$25 -> 0.4314024
A30: 2 | B30: 1 | C30: 1 | D30: 1 | E30: 02 | F30: Sueldos a médicos | G30: ='CUENTA T FONDO 100'!B127 -> 0 | H30: ='CUENTA T VS'!B96 -> 0 | I30: =SUM(G30:H30) -> 0 | J30: =I30/$I$25 -> 0
A31: 2 | B31: 1 | C31: 1 | D31: 1 | E31: 03 | F31: Ascensos a militares | G31: ='CUENTA T FONDO 100'!C127 -> 0 | H31: ='CUENTA T VS'!C96 -> 0 | I31: =SUM(G31:H31) -> 0 | J31: =I31/$I$25 -> 0
A32: 2 | B32: 1 | C32: 1 | D32: 1 | E32: 04 | F32: Nuevas plazas maestros | G32: ='CUENTA T FONDO 100'!D127 -> 0 | H32: ='CUENTA T VS'!D96 -> 0 | I32: =SUM(G32:H32) -> 0 | J32: =I32/$I$25 -> 0
A33: 2 | B33: 1 | C33: 1 | D33: 1 | E33: 05 | F33: Incentivos y escalafón | G33: ='CUENTA T FONDO 100'!E127 -> 0 | H33: ='CUENTA T VS'!E96 -> 0 | I33: =SUM(G33:H33) -> 0 | J33: =I33/$I$25 -> 0
A34: 2 | B34: 1 | C34: 1 | D34: 1 | E34: 06 | F34: Nuevas plazas a médicos | G34: ='CUENTA T FONDO 100'!F127 -> 0 | H34: ='CUENTA T VS'!F96 -> 0 | I34: =SUM(G34:H34) -> 0 | J34: =I34/$I$25 -> 0
A35: 2 | B35: 1 | C35: 1 | D35: 2 | F35: Remuneraciones al personal con carácter transitorio | G35: =SUM(G36:G41) -> 1107531 | H35: =SUM(H36:H41) -> 0 | I35: =SUM(G35:H35) -> 1107531
A36: 2 | B36: 1 | C36: 1 | D36: 2 | E36: 03 | F36: Suplencias | G36: ='CUENTA T FONDO 100'!G127 -> 0 | H36: ='CUENTA T VS'!G96 -> 0 | I36: =SUM(G36:H36) -> 0 | J36: =I36/$I$25 -> 0
A37: 2 | B37: 1 | C37: 1 | D37: 2 | E37: 05 | F37: Sueldo al personal nominal en período probatorio | G37: ='CUENTA T FONDO 100'!H127 -> 0 | H37: ='CUENTA T VS'!H96 -> 0 | I37: =SUM(G37:H37) -> 0 | J37: =I37/$I$25 -> 0
A38: 2 | B38: 1 | C38: 1 | D38: 2 | E38: 06 | F38: Jornales | G38: ='CUENTA T FONDO 100'!I127 -> 0 | H38: ='CUENTA T VS'!I96 -> 0 | I38: =SUM(G38:H38) -> 0 | J38: =I38/$I$25 -> 0
A39: 2 | B39: 1 | C39: 1 | D39: 2 | E39: 08 | F39: Empleados temporales | G39: ='CUENTA T FONDO 100'!J127 -> 1107531 | H39: ='CUENTA T VS'!J96 -> 0 | I39: =SUM(G39:H39) -> 1107531 | J39: =I39/$I$25 -> 0.008912158
A40: 2 | B40: 1 | C40: 1 | D40: 2 | E40: 09 | F40: Personal de carácter eventual | G40: ='CUENTA T FONDO 100'!K127 -> 0 | H40: ='CUENTA T VS'!K96 -> 0 | I40: =SUM(G40:H40) -> 0 | J40: =I40/$I$25 -> 0
A41: 2 | B41: 1 | C41: 1 | D41: 2 | E41: 11 | F41: Interinato | G41: ='CUENTA T FONDO 100'!L127 -> 0 | H41: ='CUENTA T VS'!L96 -> 0 | I41: =SUM(G41:H41) -> 0 | J41: =I41/$I$25 -> 0
A42: 2 | B42: 1 | C42: 1 | D42: 3 | F42: Sueldos al personal fijo en trámite de pensiones | G42: =SUM(G43) -> 0 | H42: =SUM(H43) -> 0 | I42: =SUM(G42:H42) -> 0
...

Sheet CUENTA T FONDO 100
A1: D E S G L O S E D E L A S C U E N T A S
A2: 211101 | B2: 211102 | C2: 211103 | D2: 211104 | E2: 211105 | F2: 211106 | G2: 211203 | H2: 211205 | I2: 211206 | J2: 211208 | K2: 211209 | L2: 211211 | M2: 211301 | N2: 211401 | O2: 211501 | P2: 211502 | Q2: 211503 | R2: 211504 | S2: 212101 | T2: 212201 | U2: 212203 | V2: 212204 | W2: 212205 | X2: 212206 | Y2: 212207 | Z2: 212208 | AA2: 212209 | AB2: 212210 | AC2: 213101 | AD2: 213102 | AE2: 213201 | AF2: 213202 | AG2: 214101 | AH2: 214201 | AI2: 214202 | AJ2: 214203 | AK2: 215101 | AL2: 215201 | AM2: 215301 | AN2: 215401 | AO2: 221101 | AP2: 221201 | AQ2: 221301 | AR2: 221401 | AS2: 221501 | AT2: 221601 | AU2: 221602 | AV2: 221701 | AW2: 221801 | AX2: 222101 | AY2: 222201 | AZ2: 223101 | BA2: 223201 | BB2: 224101 | BC2: 224201 | BD2: 224301 | BE2: 224401 | BF2: 225101 | BG2: 225201 | BH2: 225301 | BI2: 225302 | BJ2: 225303 | BK2: 225304 | BL2: 225305 | BM2: 225401 | BN2: 225501 | BO2: 225601 | BP2: 225701 | BQ2: 225801 | BR2: 225901 | BS2: 226101 | BT2: 226201 | BU2: 226301 | BV2: 226401 | BW2: 227101 | BX2: 227102 | BY2: 227103 | BZ2: 227104 | CA2: 227105 | CB2: 227106 | CC2: 227107 | CD2: 227199 | CE2: 227201 | CF2: 227202 | CG2: 227203 | CH2: 227204 | CI2: 227205 | CJ2: 227206 | CK2: 227207 | CL2: 227208 | CM2: 227299 | CN2: 227301 | CO2: 228101 | CP2: 228201 | CQ2: 228301 | CR2: 228401 | CS2: 228501 | CT2: 228502 | CU2: 228503 | CV2: 228601 | CW2: 228602 | CX2: 228603 | CY2: 228604 | CZ2: 228701 | DA2: 228702 | DB2: 228703 | DC2: 228704 | DD2: 228705 | DE2: 228706 | DF2: 228801 | DG2: 228802 | DH2: 228803 | DI2: 229201 | DJ2: 229203 | DK2: 231101 | DL2: 231102 | DM2: 231201 | DN2: 231301 | DO2: 231302 | DP2: 231303 | DQ2: 231401 | DR2: 232101 | DS2: 232201 | DT2: 232301 | DU2: 233101 | DV2: 233201 | DW2: 233301 | DX2: 233401 | DY2: 233501 | DZ2: 233601 | EA2: 234101 | EB2: 234201 | EC2: 235101 | ED2: 235201 | EE2: 235301 | EF2: 235401 | EG2: 235501 | EH2: 236101 | EI2: 236102 | EJ2: 236103 | EK2: 236104 | EL2: 236105 | EM2: 236201 | EN2: 236202 | EO2: 236203 | EP2: 236304 | EQ2: 236305 | ER2: 236306 | ES2: 236401 | ET2: 236402 | EU2: 236403 | EV2: 236404 | EW2: 236405 | EX2: 236406 | EY2: 236407 | EZ2: 236901 | FA2: 237101 | FB2: 237102 | FC2: 237103 | FD2: 237104 | FE2: 237105 | FF2: 237106 | FG2: 237107 | FH2: 237201 | FI2: 237202 | FJ2: 237203 | FK2: 237204 | FL2: 237205 | FM2: 237206 | FN2: 237299 | FO2: 238101 | FP2: 238201 | FQ2: 239101 | FR2: 239102 | FS2: 239201 | FT2: 239301 | FU2: 239401 | FV2: 239501 | FW2: 239601 | FX2: 239701 | FY2: 239801 | FZ2: 239802 | GA2: 239901 | GB2: 239904 | GC2: 241201 | GD2: 241202 | GE2: 241203 | GF2: 241204 | GG2: 241205 | GH2: 261101 | GI2: 261201 | GJ2: 261301 | GK2: 261401 | GL2: 261901 | GM2: 262101 | GN2: 262201 | GO2: 262301 | GP2: 262401 | GQ2: 263101 | GR2: 263201 | GS2: 263301 | GT2: 263401 | GU2: 264101 | GV2: 264201 | GW2: 264301 | GX2: 264401 | GY2: 264501 | GZ2: 264601 | HA2: 264701 | HB2: 264801 | HC2: 265101 | HD2: 265201 | HE2: 265301 | HF2: 265401 | HG2: 265501 | HH2: 265601 | HI2: 265701 | HJ2: 265801 | HK2: 266101 | HL2: 266201 | HM2: 267101 | HN2: 267201 | HO2: 267301 | HP2: 267401 | HQ2: 267501 | HR2: 267601 | HS2: 267701 | HT2: 267801 | HU2: 267901 | HV2: 268101 | HW2: 268201 | HX2: 268301 | HY2: 268302 | HZ2: 268401 | IA2: 268501 | IB2: 268601 | IC2: 268701 | ID2: 268802 | IE2: 268803 | IF2: 268804 | IG2: 268901 | IH2: 269101 | II2: 269102 | IJ2: 269201 | IK2: 269202 | IL2: 269301 | IM2: 269401 | IN2: 269501 | IO2: 269502 | IP2: 269503 | IQ2: 2269901 | IR2: 271101 | IS2: 271201 | IT2: 271301 | IU2: 271401 | IV2: 272101 | IW2: 272201 | IX2: 272301 | IY2: 272401 | IZ2: 272501 | JA2: 272601 | JB2: 272701 | JC2: 272801 | JD2: 272901 | JE2: 273101 | JF2: 273201 | JG2: 274101 | JH2: 274201 | JI2: Totales | JJ2: TRANSF NO. | JK2: VALOR | JL2: RETENCION | JM2: AÑOS ANTERIORES | JN2: 2024 | JO2: Total | JP2: Proveedor Informal
FW3: 90000.1 | FY3: 19599.99 | FZ3: 4000.01 | GB3: 22499.99 | JI3: =SUM(A3:JH3) -> 136100.09 | JJ3: 547 | JL3: =+JI3-JK3 -> 136100.09 | JO3: =+JM3+JN3 -> 0
HH4: 3199.97 | JI4: =SUM(A4:JH4) -> 3199.97 | JJ4: 551 | JL4: =+JI4-JK4 -> 3199.97
EA5: 86700 | JI5: =SUM(A5:JH5) -> 86700 | JJ5: 554 | JL5: =+JI5-JK5 -> 86700
GQ6: 999401 | JI6: =SUM(A6:JH6) -> 999401 | JJ6: 558 | JL6: =+JI6-JK6 -> 999401
FT7: 265051.6 | JI7: =SUM(A7:JH7) -> 265051.6 | JJ7: 562 | JL7: =+JI7-JK7 -> 265051.6
GQ8: 1968240 | JI8: =SUM(A8:JH8) -> 1968240 | JJ8: 566 | JL8: =+JI8-JK8 -> 1968240
GQ9: 873200 | JI9: =SUM(A9:JH9) -> 873200 | JJ9: 570 | JL9: =+JI9-JK9 -> 873200
EA10: 57000 | FT10: 207711.6 | JI10: =SUM(A10:JH10) -> 264711.6 | JJ10: 574 | JL10: =+JI10-JK10 -> 264711.6
EA11: 6875 | FT11: 233640 | JI11: =SUM(A11:JH11) -> 240515 | JJ11: 578 | JL11: =+JI11-JK11 -> 240515
EA12: 146000 | FT12: 121156.5 | JI12: =SUM(A12:JH12) -> 267156.5 | JJ12: 582 | JL12: =+JI12-JK12 -> 267156.5
EA13: 151000 | JI13: =SUM(A13:JH13) -> 151000 | JJ13: 586 | JL13: =+JI13-JK13 -> 151000
EA14: 37600 | FT14: 88500 | JI14: =SUM(A14:JH14) -> 126100 | JJ14: 591 | JL14: =+JI14-JK14 -> 126100
GJ15: 6490 | JI15: =SUM(A15:JH15) -> 6490 | JJ15: 595 | JL15: =+JI15-JK15 -> 6490
GJ16: 57230 | JI16: =SUM(A16:JH16) -> 57230 | JJ16: 599 | JL16: =+JI16-JK16 -> 57230
GJ17: 120360 | JI17: =SUM(A17:JH17) -> 120360 | JJ17: 603 | JL17: =+JI17-JK17 -> 120360
EA18: 90000 | JI18: =SUM(A18:JH18) -> 90000 | JJ18: 607 | JL18: =+JI18-JK18 -> 90000
EA19: 47400 | FT19: 224790 | JI19: =SUM(A19:JH19) -> 272190 | JJ19: 611 | JL19: =+JI19-JK19 -> 272190
FN20: 144969.28 | FT20: 90109.52 | JI20: =SUM(A20:JH20) -> 235078.8 | JJ20: 615 | JL20: =+JI20-JK20 -> 235078.8
GR21: 15930 | JI21: =SUM(A21:JH21) -> 15930 | JJ21: 619 | JL21: =+JI21-JK21 -> 15930
AV22: 1959489.3 | JI22: =SUM(A22:JH22) -> 1959489.3 | JJ22: 624 | JL22: =+JI22-JK22 -> 1959489.3
FQ23: 160215.06 | JI23: =SUM(A23:JH23) -> 160215.06 | JJ23: 626 | JL23: =+JI23-JK23 -> 160215.06
FT24: 186440 | JI24: =SUM(A24:JH24) -> 186440 | JJ24: 632 | JL24: =+JI24-JK24 -> 186440
FJ25: 268000 | JI25: =SUM(A25:JH25) -> 268000 | JJ25: 655 | JL25: =+JI25-JK25 -> 268000
FN26: 14300 | JI26: =SUM(A26:JH26) -> 14300 | JJ26: 661 | JL26: =+JI26-JK26 -> 14300
FT27: 235823 | JI27: =SUM(A27:JH27) -> 235823 | JJ27: 665 | JL27: =+JI27-JK27 -> 235823
FT28: 270000 | JI28: =SUM(A28:JH28) -> 270000 | JJ28: 669 | JL28: =+JI28-JK28 -> 270000
BW29: 1091212.1 | JI29: =SUM(A29:JH29) -> 1091212.1 | JJ29: 673 | JL29: =+JI29-JK29 -> 1091212.1
BW30: 1692916.7 | JI30: =SUM(A30:JH30) -> 1692916.7 | JJ30: 677 | JL30: =+JI30-JK30 -> 1692916.7
EA31: 33000 | FT31: 206647.5 | JI31: =SUM(A31:JH31) -> 239647.5 | JJ31: 681 | JL31: =+JI31-JK31 -> 239647.5
FT32: 129664 | JI32: =SUM(A32:JH32) -> 129664 | JJ32: 685 | JL32: =+JI32-JK32 -> 129664
GH33: 241546 | JI33: =SUM(A33:JH33) -> 241546 | JJ33: 689 | JL33: =+JI33-JK33 -> 241546
DK34: 222558.2 | DV34: 18408 | FA34: 1829 | JI34: =SUM(A34:JH34) -> 242795.2 | JJ34: 693 | JL34: =+JI34-JK34 -> 242795.2
FT35: 208010.4 | JI35: =SUM(A35:JH35) -> 208010.4 | JJ35: 697 | JL35: =+JI35-JK35 -> 208010.4
FT36: 203078 | JI36: =SUM(A36:JH36) -> 203078 | JJ36: 701 | JL36: =+JI36-JK36 -> 203078
DK37: 264630 | JI37: =SUM(A37:JH37) -> 264630 | JJ37: 705 | JL37: =+JI37-JK37 -> 264630
GH38: 241546 | JI38: =SUM(A38:JH38) -> 241546 | JJ38: 709 | JL38: =+JI38-JK38 -> 241546
FM39: 203654.83 | JI39: =SUM(A39:JH39) -> 203654.83 | JJ39: 717 | JL39: =+JI39-JK39 -> 203654.83
EA40: 198000 | FT40: 67496 | JI40: =SUM(A40:JH40) -> 265496 | JJ40: 721 | JL40: =+JI40-JK40 -> 265496
...

Sheet CUENTA T VS
A1: D E S G L O S E D E L A S C U E N T A S
A2: 211101 | B2: 211102 | C2: 211103 | D2: 211104 | E2: 211105 | F2: 211106 | G2: 211203 | H2: 211205 | I2: 211206 | J2: 211208 | K2: 211209 | L2: 211211 | M2: 211301 | N2: 211401 | O2: 211501 | P2: 211502 | Q2: 211503 | R2: 211504 | S2: 212101 | T2: 212201 | U2: 212203 | V2: 212204 | W2: 212205 | X2: 212206 | Y2: 212207 | Z2: 212208 | AA2: 212209 | AB2: 212210 | AC2: 213101 | AD2: 213102 | AE2: 213201 | AF2: 213202 | AG2: 214101 | AH2: 214201 | AI2: 214202 | AJ2: 214203 | AK2: 215101 | AL2: 215201 | AM2: 215301 | AN2: 215401 | AO2: 221101 | AP2: 221201 | AQ2: 221301 | AR2: 221401 | AS2: 221501 | AT2: 221601 | AU2: 221602 | AV2: 221701 | AW2: 221801 | AX2: 222101 | AY2: 222201 | AZ2: 223101 | BA2: 223201 | BB2: 224101 | BC2: 224201 | BD2: 224301 | BE2: 224401 | BF2: 225101 | BG2: 225201 | BH2: 225301 | BI2: 225302 | BJ2: 225303 | BK2: 225304 | BL2: 225305 | BM2: 225401 | BN2: 225501 | BO2: 225601 | BP2: 225701 | BQ2: 225801 | BR2: 225901 | BS2: 226101 | BT2: 226201 | BU2: 226301 | BV2: 226401 | BW2: 227101 | BX2: 227102 | BY2: 227103 | BZ2: 227104 | CA2: 227105 | CB2: 227106 | CC2: 227107 | CD2: 227199 | CE2: 227201 | CF2: 227202 | CG2: 227203 | CH2: 227204 | CI2: 227205 | CJ2: 227206 | CK2: 227207 | CL2: 227208 | CM2: 227299 | CN2: 227301 | CO2: 228101 | CP2: 228201 | CQ2: 228301 | CR2: 228401 | CS2: 228501 | CT2: 228502 | CU2: 228503 | CV2: 228601 | CW2: 228602 | CX2: 228603 | CY2: 228604 | CZ2: 228701 | DA2: 228702 | DB2: 228703 | DC2: 228704 | DD2: 228705 | DE2: 228706 | DF2: 228801 | DG2: 228802 | DH2: 228803 | DI2: 229201 | DJ2: 229203 | DK2: 231101 | DL2: 231102 | DM2: 231201 | DN2: 231301 | DO2: 231302 | DP2: 231303 | DQ2: 231401 | DR2: 232101 | DS2: 232201 | DT2: 232301 | DU2: 233101 | DV2: 233201 | DW2: 233301 | DX2: 233401 | DY2: 233501 | DZ2: 233601 | EA2: 234101 | EB2: 234201 | EC2: 235101 | ED2: 235201 | EE2: 235301 | EF2: 235401 | EG2: 235501 | EH2: 236101 | EI2: 236102 | EJ2: 236103 | EK2: 236104 | EL2: 236105 | EM2: 236201 | EN2: 236202 | EO2: 236203 | EP2: 236304 | EQ2: 236305 | ER2: 236306 | ES2: 236401 | ET2: 236402 | EU2: 236403 | EV2: 236404 | EW2: 236405 | EX2: 236406 | EY2: 236407 | EZ2: 236901 | FA2: 237101 | FB2: 237102 | FC2: 237103 | FD2: 237104 | FE2: 237105 | FF2: 237106 | FG2: 237107 | FH2: 237201 | FI2: 237202 | FJ2: 237203 | FK2: 237204 | FL2: 237205 | FM2: 237206 | FN2: 237299 | FO2: 238101 | FP2: 238201 | FQ2: 239101 | FR2: 239102 | FS2: 239201 | FT2: 239301 | FU2: 239401 | FV2: 239501 | FW2: 239601 | FX2: 239701 | FY2: 239801 | FZ2: 239802 | GA2: 239901 | GB2: 239904 | GC2: 241201 | GD2: 241202 | GE2: 241203 | GF2: 241204 | GG2: 241205 | GH2: 261101 | GI2: 261201 | GJ2: 261301 | GK2: 261401 | GL2: 261901 | GM2: 262101 | GN2: 262201 | GO2: 262301 | GP2: 262401 | GQ2: 263101 | GR2: 263201 | GS2: 263301 | GT2: 263401 | GU2: 264101 | GV2: 264201 | GW2: 264301 | GX2: 264401 | GY2: 264501 | GZ2: 264601 | HA2: 264701 | HB2: 264801 | HC2: 265101 | HD2: 265201 | HE2: 265301 | HF2: 265401 | HG2: 265501 | HH2: 265601 | HI2: 265701 | HJ2: 265801 | HK2: 266101 | HL2: 266201 | HM2: 267101 | HN2: 267201 | HO2: 267301 | HP2: 267401 | HQ2: 267501 | HR2: 267601 | HS2: 267701 | HT2: 267801 | HU2: 267901 | HV2: 268101 | HW2: 268201 | HX2: 268301 | HY2: 268302 | HZ2: 268401 | IA2: 268501 | IB2: 268601 | IC2: 268701 | ID2: 268802 | IE2: 268803 | IF2: 268804 | IG2: 268901 | IH2: 269101 | II2: 269102 | IJ2: 269201 | IK2: 269202 | IL2: 269301 | IM2: 269401 | IN2: 269501 | IO2: 269502 | IP2: 269503 | IQ2: 2269901 | IR2: 271101 | IS2: 271201 | IT2: 271301 | IU2: 271401 | IV2: 272101 | IW2: 272201 | IX2: 272301 | IY2: 272401 | IZ2: 272501 | JA2: 272601 | JB2: 272701 | JC2: 272801 | JD2: 272901 | JE2: 273101 | JF2: 273201 | JG2: 274101 | JH2: 274201 | JI2: Totales | JJ2: TRANSF NO. | JK2: VALOR | JL2: RETENCION | JM2: AÑOS ANTERIORES | JN2: 2022 | JO2: Total | JP2: Proveedor Informal
AW3: 760000 | JI3: =SUM(A3:JH3) -> 760000 | JJ3: 58 | JK3: 722000 | JL3: =+JI3-JK3 -> 38000
HF4: 192930 | JI4: =SUM(A4:JH4) -> 192930 | JJ4: 59 | JK4: 184755 | JL4: =+JI4-JK4 -> 8175
DD5: 48852 | JI5: =SUM(A5:JH5) -> 48852 | JJ5: 60 | JK5: 46782 | JL5: =+JI5-JK5 -> 2070
CU6: 188564 | JI6: =SUM(A6:JH6) -> 188564 | JJ6: 61 | JK6: 180574 | JL6: =+JI6-JK6 -> 7990
FN7: 42000 | JI7: =SUM(A7:JH7) -> 42000 | JJ7: 62 | JK7: 39900 | JL7: =+JI7-JK7 -> 2100
FA8: 172000 | JI8: =SUM(A8:JH8) -> 172000 | JJ8: 63 | JK8: 170573.26 | JL8: =+JI8-JK8 -> 1426.74
FD9: 55029 | JI9: =SUM(A9:JH9) -> 55029 | JJ9: 64 | JK9: 55029 | JL9: =+JI9-JK9 -> 0
EG10: 15340.03 | EP10: 16250 | ER10: 7825 | FN10: 1889.99 | JI10: =SUM(A10:JH10) -> 41305.02 | JJ10: 65 | JK10: 39555.02 | JL10: =+JI10-JK10 -> 1750
FT11: 34220 | JI11: =SUM(A11:JH11) -> 34220 | JJ11: 66 | JK11: 32770 | JL11: =+JI11-JK11 -> 1450
DK12: 473584 | JI12: =SUM(A12:JH12) -> 473584 | JJ12: 67 | JK12: 451814 | JL12: =+JI12-JK12 -> 21770
CJ13: 0 | EA13: 61500 | JI13: =SUM(A13:JH13) -> 61500 | JJ13: 68 | JK13: 58425 | JL13: =+JI13-JK13 -> 3075
CJ14: 636067.2 | JI14: =SUM(A14:JH14) -> 636067.2 | JJ14: 69 | JK14: 609115.2 | JL14: =+JI14-JK14 -> 26952
AQ15: 211191.19 | JI15: =SUM(A15:JH15) -> 211191.19 | JJ15: 70 | JK15: 211191.19 | JL15: =+JI15-JK15 -> 0
DK16: 36420 | JI16: =SUM(A16:JH16) -> 36420 | JJ16: 71 | JK16: 36420 | JL16: =+JI16-JK16 -> 0
EA17: 188500 | JI17: =SUM(A17:JH17) -> 188500 | JJ17: 72 | JK17: 179075 | JL17: =+JI17-JK17 -> 9425
DE18: 2150 | JI18: =SUM(A18:JH18) -> 2150 | JJ18: 73 | JK18: 2042.5 | JL18: =+JI18-JK18 -> 107.5
FD19: 23868 | JI19: =SUM(A19:JH19) -> 23868 | JJ19: 74 | JK19: 23868 | JL19: =+JI19-JK19 -> 0
DK20: 85575 | JI20: =SUM(A20:JH20) -> 85575 | JJ20: 75 | JK20: 81296.25 | JL20: =+JI20-JK20 -> 4278.75
EE21: 282823.65 | JI21: =SUM(A21:JH21) -> 282823.65 | JJ21: 76 | JK21: 270839.6 | JL21: =+JI21-JK21 -> 11984.05
DK22: 14000 | JI22: =SUM(A22:JH22) -> 14000 | JJ22: 77 | JK22: 14000 | JL22: =+JI22-JK22 -> 0
GZ23: 107609.37 | JI23: =SUM(A23:JH23) -> 107609.37 | JJ23: 78 | JK23: 103049.65 | JL23: =+JI23-JK23 -> 4559.72
DE24: 20000 | JI24: =SUM(A24:JH24) -> 20000 | JJ24: 79 | JK24: 20000 | JL24: =+JI24-JK24 -> 0
DW25: 26845 | JI25: =SUM(A25:JH25) -> 26845 | JJ25: 80 | JK25: 25707.5 | JL25: =+JI25-JK25 -> 1137.5
BC26: 8000 | JI26: =SUM(A26:JH26) -> 8000 | JJ26: 81 | JK26: 7600 | JL26: =+JI26-JK26 -> 400
DE27: 225000 | JI27: =SUM(A27:JH27) -> 225000 | JJ27: 82 | JK27: 213750 | JL27: =+JI27-JK27 -> 11250
DE28: 83800 | JI28: =SUM(A28:JH28) -> 83800 | JJ28: =+JJ27+1 -> 83 | JK28: 79610 | JL28: =+JI28-JK28 -> 4190
DW29: 31152 | JI29: =SUM(A29:JH29) -> 31152 | JJ29: =+JJ28+1 -> 84 | JK29: 29832 | JL29: =+JI29-JK29 -> 1320
FD30: 22542 | JI30: =SUM(A30:JH30) -> 22542 | JJ30: =+JJ29+1 -> 85 | JK30: 22542 | JL30: =+JI30-JK30 -> 0
BC31: 24000 | JI31: =SUM(A31:JH31) -> 24000 | JJ31: =+JJ30+1 -> 86 | JK31: 22800 | JL31: =+JI31-JK31 -> 1200
EG32: 19499.99 | EM32: 15149.94 | EP32: 71000.03 | JI32: =SUM(A32:JH32) -> 105649.96 | JJ32: =+JJ31+1 -> 87 | JK32: 101173.27 | JL32: =+JI32-JK32 -> 4476.69
GD33: 40000 | JI33: =SUM(A33:JH33) -> 40000 | JJ33: =+JJ32+1 -> 88 | JK33: 40000 | JL33: =+JI33-JK33 -> 0
DK34: 14000 | JI34: =SUM(A34:JH34) -> 14000 | JJ34: =+JJ33+1 -> 89 | JK34: 14000 | JL34: =+JI34-JK34 -> 0
DK35: 11640 | JI35: =SUM(A35:JH35) -> 11640 | JJ35: =+JJ34+1 -> 90 | JK35: 11640 | JL35: =+JI35-JK35 -> 0
DK36: 23580 | JI36: =SUM(A36:JH36) -> 23580 | JJ36: =+JJ35+1 -> 91 | JK36: 23580 | JL36: =+JI36-JK36 -> 0
BW37: 272580 | JI37: =SUM(A37:JH37) -> 272580 | JJ37: =+JJ36+1 -> 92 | JK37: 261030 | JL37: =+JI37-JK37 -> 11550
CL38: 248711.41 | JI38: =SUM(A38:JH38) -> 248711.41 | JJ38: =+JJ37+1 -> 93 | JK38: 238172.79 | JL38: =+JI38-JK38 -> 10538.62
BW39: 271800.26 | JI39: =SUM(A39:JH39) -> 271800.26 | JJ39: =+JJ38+1 -> 94 | JK39: 260283.3 | JL39: =+JI39-JK39 -> 11516.96
CL40: 230085.84 | JI40: =SUM(A40:JH40) -> 230085.84 | JJ40: =+JJ39+1 -> 95 | JK40: 220336.44 | JL40: =+JI40-JK40 -> 9749.4
...

Sheet GASTOS X ATENCION
A1: SERVICIO NACIONAL DE SALUD
A2: ='CONS. FUENTES FINAN'!A6 -> HOSPITAL MATERNO INFANTIL SAN LORENZO DE LOS MINA
A3: RESUMEN COMPARATIVO DE GASTOS ESPECIFICOS FONDO 100 Y VENTA DE SERVICIOS
A6: DETALLE | B6: FONDO 100 | C6: VENTA SERVICIOS | D6: TOTAL | E6: %
A8: Atención Directa
A9: Medicamentos e Insumos Médicos | B9: ='CONS. FUENTES FINAN'!G245+'CONS. FUENTES FINAN'!G315 -> 17715524 | C9: ='CONS. FUENTES FINAN'!H245+'CONS. FUENTES FINAN'!H315 -> 284220 | D9: =SUM(B9:C9) -> 17999744 | E9: =+D9/D12 -> 0.8803263
A10: Oxigeno | B10: ='CONS. FUENTES FINAN'!G302 -> 159269.28 | C10: ='CONS. FUENTES FINAN'!H302 -> 43889.99 | D10: =SUM(B10:C10) -> 203159.27 | E10: =+D10/D12 -> 0.0099360548
A11: Reactivos e Insumos de Laboratorio | B11: ='CONS. FUENTES FINAN'!G296+'CONS. FUENTES FINAN'!G297+'CONS. FUENTES FINAN'!G298 -> 2243769.9 | C11: ='CONS. FUENTES FINAN'!H296+'CONS. FUENTES FINAN'!H297+'CONS. FUENTES FINAN'!H298 -> 0 | D11: =SUM(B11:C11) -> 2243769.9 | E11: =+D11/D12 -> 0.10973765
A12: Total | B12: =SUM(B9:B11) -> 20118564 | C12: =SUM(C9:C11) -> 328109.99 | D12: =SUM(D9:D11) -> 20446674 | E12: =+D12/D39 -> 0.16453172
A13: Mantenimiento de Equipos
A14: Reparación y Mantenimiento Maquinaria y Eq. | B14: ='CONS. FUENTES FINAN'!G157+'CONS. FUENTES FINAN'!G188+'CONS. FUENTES FINAN'!G223+'CONS. FUENTES FINAN'!G252+'CONS. FUENTES FINAN'!G254+'CONS. FUENTES FINAN'!G256+'CONS. FUENTES FINAN'!G258+'CONS. FUENTES FINAN'!G261+'CONS. FUENTES FINAN'!G292+'CONS. FUENTES FINAN'!G293+'CONS. FUENTES FINAN'!G299+'CONS. FUENTES FINAN'!G300+'CONS. FUENTES FINAN'!G301+'CONS. FUENTES FINAN'!G324 -> 6178626.8 | C14: ='CONS. FUENTES FINAN'!H157+'CONS. FUENTES FINAN'!H188+'CONS. FUENTES FINAN'!H223+'CONS. FUENTES FINAN'!H252+'CONS. FUENTES FINAN'!H254+'CONS. FUENTES FINAN'!H256+'CONS. FUENTES FINAN'!H258+'CONS. FUENTES FINAN'!H261+'CONS. FUENTES FINAN'!H292+'CONS. FUENTES FINAN'!H293+'CONS. FUENTES FINAN'!H299+'CONS. FUENTES FINAN'!H300+'CONS. FUENTES FINAN'!H301+'CONS. FUENTES FINAN'!H324 -> 2601187.8 | D14: =SUM(B14:C14) -> 8779814.6 | E14: =+D14/D16 -> 0.95762161
A15: Productos Eléctricos y Afines | B15: ='CONS. FUENTES FINAN'!G320 -> 388540.1 | C15: ='CONS. FUENTES FINAN'!H320 -> 0 | D15: =SUM(B15:C15) -> 388540.1 | E15: =+D15/D16 -> 0.042378389
A16: Total | B16: =SUM(B14:B15) -> 6567166.9 | C16: =SUM(C14:C15) -> 2601187.8 | D16: =SUM(D14:D15) -> 9168354.7 | E16: =+D16/D39 -> 0.073776556
A17: Gastos Administrativos
A18: Servicios Personales | B18: ='CONS. FUENTES FINAN'!G26 -> 66337620 | C18: ='CONS. FUENTES FINAN'!H26 -> 5231553.6 | D18: =SUM(B18:C18) -> 71569173 | E18: =+D18/D34 -> 0.86270008
A19: Servicio Telefónico | B19: ='CONS. FUENTES FINAN'!G91+'CONS. FUENTES FINAN'!G93+'CONS. FUENTES FINAN'!G95+'CONS. FUENTES FINAN'!G97 -> 0 | C19: ='CONS. FUENTES FINAN'!H91+'CONS. FUENTES FINAN'!H93+'CONS. FUENTES FINAN'!H95+'CONS. FUENTES FINAN'!H97 -> 211191.19 | D19: =SUM(B19:C19) -> 211191.19 | E19: =+D19/D34 -> 0.0025457141
A20: Servicios Basicos (electricidad, agua y residuos solidos) | B20: ='CONS. FUENTES FINAN'!G99+'CONS. FUENTES FINAN'!G102+'CONS. FUENTES FINAN'!G104 -> 2020024.3 | C20: ='CONS. FUENTES FINAN'!H99+'CONS. FUENTES FINAN'!H102+'CONS. FUENTES FINAN'!H104 -> 1520000 | D20: =SUM(B20:C20) -> 3540024.3 | E20: =+D20/D34 -> 0.042671713
A21: Viáticos | B21: ='CONS. FUENTES FINAN'!G111 -> 0 | C21: ='CONS. FUENTES FINAN'!H111 -> 0 | D21: =SUM(B21:C21) -> 0 | E21: =+D21/D34 -> 0
A22: Transporte y almacenaje | B22: ='CONS. FUENTES FINAN'!G116 -> 0 | C22: ='CONS. FUENTES FINAN'!H116 -> 32000 | D22: =SUM(B22:C22) -> 32000 | E22: =+D22/D34 -> 0.00038573035
A23: Alquileres | B23: ='CONS. FUENTES FINAN'!G125 -> 0 | C23: ='CONS. FUENTES FINAN'!H125 -> 0 | D23: =SUM(B23:C23) -> 0 | E23: =+D23/D34 -> 0
A24: Comisiones y Gastos Bancarios | B24: ='CONS. FUENTES FINAN'!G182 -> 0 | C24: ='CONS. FUENTES FINAN'!H182 -> 8323.87 | D24: =SUM(B24:C24) -> 8323.87 | E24: =+D24/D34 -> 0.00010033654
A25: Materiales de Oficina, Impresión y Encuadernación | B25: ='CONS. FUENTES FINAN'!G109+'CONS. FUENTES FINAN'!G312 -> 132475.4 | C25: ='CONS. FUENTES FINAN'!H109+'CONS. FUENTES FINAN'!H312 -> 0 | D25: =SUM(B25:C25) -> 132475.4 | E25: =+D25/D34 -> 0.0015968682
A26: Alimentos y Bebidas para Personas | B26: ='CONS. FUENTES FINAN'!G208+'CONS. FUENTES FINAN'!G214+'CONS. FUENTES FINAN'!G217+'CONS. FUENTES FINAN'!G219 -> 3122436.8 | C26: ='CONS. FUENTES FINAN'!H208+'CONS. FUENTES FINAN'!H214+'CONS. FUENTES FINAN'!H217+'CONS. FUENTES FINAN'!H219 -> 658799 | D26: =SUM(B26:C26) -> 3781235.8 | E26: =+D26/D34 -> 0.045579295
A27: Productos de papel, carton e impesos | B27: ='CONS. FUENTES FINAN'!G232 -> 1474545.2 | C27: ='CONS. FUENTES FINAN'!H232 -> 57997 | D27: =SUM(B27:C27) -> 1532542.2 | E27: =+D27/D34 -> 0.018473376
A28: Articulos de Plasticos | B28: ='CONS. FUENTES FINAN'!G259 -> 334708.95 | C28: ='CONS. FUENTES FINAN'!H259 -> 34840.02 | D28: =SUM(B28:C28) -> 369548.97 | E28: =+D28/D34 -> 0.0044545704
A29: Gasolina | B29: ='CONS. FUENTES FINAN'!G288 -> 555829 | C29: ='CONS. FUENTES FINAN'!H288 -> 172000 | D29: =SUM(B29:C29) -> 727829 | E29: =+D29/D34 -> 0.0087733043
A30: Gasoil | B30: ='CONS. FUENTES FINAN'!G289+'CONS. FUENTES FINAN'!G290 -> 0 | C30: ='CONS. FUENTES FINAN'!H289+'CONS. FUENTES FINAN'!H290 -> 0 | D30: =SUM(B30:C30) -> 0 | E30: =+D30/D34 -> 0
A31: GLP | B31: ='CONS. FUENTES FINAN'!G291+'CONS. FUENTES FINAN'!G294 -> 0 | C31: ='CONS. FUENTES FINAN'!H291+'CONS. FUENTES FINAN'!H294 -> 101439 | D31: =SUM(B31:C31) -> 101439 | E31: =+D31/D34 -> 0.0012227532
A32: Materiales de Limpieza e Higiene | B32: ='CONS. FUENTES FINAN'!G309 -> 369511.66 | C32: ='CONS. FUENTES FINAN'!H309 -> 0 | D32: =SUM(B32:C32) -> 369511.66 | E32: =+D32/D34 -> 0.0044541207
A33: Otros Egresos y Gastos | B33: ='CONS. FUENTES FINAN'!G89+'CONS. FUENTES FINAN'!G107+'CONS. FUENTES FINAN'!G148+'CONS. FUENTES FINAN'!G180+'CONS. FUENTES FINAN'!G184+'CONS. FUENTES FINAN'!G186+'CONS. FUENTES FINAN'!G192+'CONS. FUENTES FINAN'!G197+'CONS. FUENTES FINAN'!G204+'CONS. FUENTES FINAN'!G225+'CONS. FUENTES FINAN'!G303+'CONS. FUENTES FINAN'!G316+'CONS. FUENTES FINAN'!G318+'CONS. FUENTES FINAN'!G322+'CONS. FUENTES FINAN'!G327+'CONS. FUENTES FINAN'!G330 -> 25685.99 | C33: ='CONS. FUENTES FINAN'!H89+'CONS. FUENTES FINAN'!H107+'CONS. FUENTES FINAN'!H148+'CONS. FUENTES FINAN'!H180+'CONS. FUENTES FINAN'!H184+'CONS. FUENTES FINAN'!H186+'CONS. FUENTES FINAN'!H192+'CONS. FUENTES FINAN'!H197+'CONS. FUENTES FINAN'!H204+'CONS. FUENTES FINAN'!H225+'CONS. FUENTES FINAN'!H303+'CONS. FUENTES FINAN'!H316+'CONS. FUENTES FINAN'!H318+'CONS. FUENTES FINAN'!H322+'CONS. FUENTES FINAN'!H327+'CONS. FUENTES FINAN'!H330 -> 558526.69 | D33: =SUM(B33:C33) -> 584212.68 | E33: =+D33/D34 -> 0.0070421426
A34: Total | B34: =SUM(B17:B33) -> 74372837 | C34: =SUM(C17:C33) -> 8586670.4 | D34: =SUM(D17:D33) -> 82959507 | E34: =+D34/D39 -> 0.66756436
A35: Gastos Inversion y Capital
A36: Bienes Muebles, Inmuebles e Intangibles | B36: ='CONS. FUENTES FINAN'!G336 -> 11396849 | C36: ='CONS. FUENTES FINAN'!H336 -> 300539.37 | D36: =SUM(B36:C36) -> 11697389 | E36: =+D36/D38 -> 1
A37: Obras | B37: ='CONS. FUENTES FINAN'!G463 -> 0 | C37: ='CONS. FUENTES FINAN'!H463 -> 0 | D37: =SUM(B37:C37) -> 0 | E37: =+D37/D38 -> 0
A38: Total | B38: =SUM(B36:B37) -> 11396849 | C38: =SUM(C36:C37) -> 300539.37 | D38: =SUM(D36:D37) -> 11697389 | E38: =+D38/D39 -> 0.094127365
A39: Total General | B39: =+B12+B16+B34+B38 -> 1.1245542e+08 | C39: =+C12+C16+C34+C38 -> 11816507 | D39: =+D12+D16+D34+D38 -> 1.2427192e+08 | E39: =+E12+E16+E34+E38 -> 1
A40: Porciento | B40: =+B39/D39 -> 0.9049141 | C40: =+C39/D39 -> 0.095085898 | D40: =+B40+C40 -> 1

Sheet PLANTILLA PRESUPUESTO
A1: SERVICIO NACIONAL DE SALUD
A2: HOSPITAL MATERNO INFANTIL SAN LORENZO DE LOS MINA
A3: CONSOLIDADO GASTOS EJECUCION FINANCIERA 2025
A4: En RD$
A6: Detalle | B6: FONDO REPONIBLE | G6: VENTA SEVICIOS/OTROS APORTES | L6: TOTAL
A7: 2 - GASTOS | B7: 1ro | C7: 2do | D7: 3ro | E7: 4to | G7: 1ro | H7: 2do | I7: 3ro | J7: 4to | L7: 1ro | M7: 2do | N7: 3ro | O7: 4to
A8: 2.1 - REMUNERACIONES Y CONTRIBUCIONES | B8: =SUM(B9:B13) -> 1.9856074e+08 | C8: =SUM(C9:C13) -> 0 | D8: =SUM(D9:D13) -> 0 | E8: =SUM(E9:E13) -> 0 | G8: =SUM(G9:G13) -> 5231553.6 | H8: =SUM(H9:H13) -> 0 | I8: =SUM(I9:I13) -> 0 | J8: =SUM(J9:J13) -> 0 | L8: =SUM(B8+G8) -> 2.0379229e+08 | M8: =SUM(C8+H8) -> 0 | N8: =SUM(D8+I8) -> 0 | O8: =SUM(E8+J8) -> 0
A9: 2.1.1 - REMUNERACIONES | B9: =SUM('TRANSFERENCIA CORRIENTE'!C10:E10) -> 1.639452e+08 | C9: =SUM('TRANSFERENCIA CORRIENTE'!F10:H10) -> 0 | D9: =SUM('TRANSFERENCIA CORRIENTE'!I10:K10) -> 0 | E9: =SUM('TRANSFERENCIA CORRIENTE'!L10:N10) -> 0 | G9: =SUM(VS!C10:E10) -> 0 | H9: =SUM(VS!F10:H10) -> 0 | I9: =SUM(VS!I10:K10) -> 0 | J9: =SUM(VS!L10:N10) -> 0 | L9: =SUM(B9+G9) -> 1.639452e+08 | M9: =SUM(C9+H9) -> 0 | N9: =SUM(D9+I9) -> 0 | O9: =SUM(E9+J9) -> 0
A10: 2.1.2 - SOBRESUELDOS | B10: =SUM('TRANSFERENCIA CORRIENTE'!C11:E11) -> 9594398.8 | C10: =SUM('TRANSFERENCIA CORRIENTE'!F11:H11) -> 0 | D10: =SUM('TRANSFERENCIA CORRIENTE'!I11:K11) -> 0 | E10: =SUM('TRANSFERENCIA CORRIENTE'!L11:N11) -> 0 | G10: =SUM(VS!C11:E11) -> 5231553.6 | H10: =SUM(VS!F11:H11) -> 0 | I10: =SUM(VS!I11:K11) -> 0 | J10: =SUM(VS!L11:N11) -> 0 | L10: =SUM(B10+G10) -> 14825952 | M10: =SUM(C10+H10) -> 0 | N10: =SUM(D10+I10) -> 0 | O10: =SUM(E10+J10) -> 0
A11: 2.1.3 - DIETAS Y GASTOS DE REPRESENTACIÓN | B11: =SUM('TRANSFERENCIA CORRIENTE'!C12:E12) -> 0 | C11: =SUM('TRANSFERENCIA CORRIENTE'!F12:H12) -> 0 | D11: =SUM('TRANSFERENCIA CORRIENTE'!I12:K12) -> 0 | E11: =SUM('TRANSFERENCIA CORRIENTE'!L12:N12) -> 0 | G11: =SUM(VS!C12:E12) -> 0 | H11: =SUM(VS!F12:H12) -> 0 | I11: =SUM(VS!I12:K12) -> 0 | J11: =SUM(VS!L12:N12) -> 0 | L11: =SUM(B11+G11) -> 0 | M11: =SUM(C11+H11) -> 0 | N11: =SUM(D11+I11) -> 0 | O11: =SUM(E11+J11) -> 0
A12: 2.1.4 - GRATIFICACIONES Y BONIFICACIONES | B12: =SUM('TRANSFERENCIA CORRIENTE'!C13:E13) -> 0 | C12: =SUM('TRANSFERENCIA CORRIENTE'!F13:H13) -> 0 | D12: =SUM('TRANSFERENCIA CORRIENTE'!I13:K13) -> 0 | E12: =SUM('TRANSFERENCIA CORRIENTE'!L13:N13) -> 0 | G12: =SUM(VS!C13:E13) -> 0 | H12: =SUM(VS!F13:H13) -> 0 | I12: =SUM(VS!I13:K13) -> 0 | J12: =SUM(VS!L13:N13) -> 0 | L12: =SUM(B12+G12) -> 0 | M12: =SUM(C12+H12) -> 0 | N12: =SUM(D12+I12) -> 0 | O12: =SUM(E12+J12) -> 0
A13: 2.1.5 - CONTRIBUCIONES A LA SEGURIDAD SOCIAL | B13: =SUM('TRANSFERENCIA CORRIENTE'!C14:E14) -> 25021132 | C13: =SUM('TRANSFERENCIA CORRIENTE'!F14:H14) -> 0 | D13: =SUM('TRANSFERENCIA CORRIENTE'!I14:K14) -> 0 | E13: =SUM('TRANSFERENCIA CORRIENTE'!L14:N14) -> 0 | G13: =SUM(VS!C14:E14) -> 0 | H13: =SUM(VS!F14:H14) -> 0 | I13: =SUM(VS!I14:K14) -> 0 | J13: =SUM(VS!L14:N14) -> 0 | L13: =SUM(B13+G13) -> 25021132 | M13: =SUM(C13+H13) -> 0 | N13: =SUM(D13+I13) -> 0 | O13: =SUM(E13+J13) -> 0
A14: 2.2 - CONTRATACIÓN DE SERVICIOS | B14: =SUM(B15:B23) -> 9308364.9 | C14: =SUM(C15:C23) -> 0 | D14: =SUM(D15:D23) -> 0 | E14: =SUM(E15:E23) -> 0 | G14: =SUM(G15:G23) -> 8306683.8 | H14: =SUM(H15:H23) -> 0 | I14: =SUM(I15:I23) -> 0 | J14: =SUM(J15:J23) -> 0 | L14: =SUM(B14+G14) -> 17615049 | M14: =SUM(C14+H14) -> 0 | N14: =SUM(D14+I14) -> 0 | O14: =SUM(E14+J14) -> 0
A15: 2.2.1 - SERVICIOS BÁSICOS | B15: =SUM('TRANSFERENCIA CORRIENTE'!C16:E16) -> 2020024.3 | C15: =SUM('TRANSFERENCIA CORRIENTE'!F16:H16) -> 0 | D15: =SUM('TRANSFERENCIA CORRIENTE'!J16:L16) -> 0 | E15: =SUM('TRANSFERENCIA CORRIENTE'!L16:N16) -> 0 | G15: =SUM(VS!C16:E16) -> 2341561.9 | H15: =SUM(VS!F16:H16) -> 0 | I15: =SUM(VS!I16:K16) -> 0 | J15: =SUM(VS!L16:N16) -> 0 | L15: =SUM(B15+G15) -> 4361586.2 | M15: =SUM(C15+H15) -> 0 | N15: =SUM(D15+I15) -> 0 | O15: =SUM(E15+J15) -> 0
A16: 2.2.2 - PUBLICIDAD, IMPRESIÓN Y ENCUADERNACIÓN | B16: =SUM('TRANSFERENCIA CORRIENTE'!C17:E17) -> 324206.83 | C16: =SUM('TRANSFERENCIA CORRIENTE'!F17:H17) -> 0 | D16: =SUM('TRANSFERENCIA CORRIENTE'!J17:L17) -> 0 | E16: =SUM('TRANSFERENCIA CORRIENTE'!L17:N17) -> 0 | G16: =SUM(VS!C17:E17) -> 0 | H16: =SUM(VS!F17:H17) -> 0 | I16: =SUM(VS!I17:K17) -> 0 | J16: =SUM(VS!L17:N17) -> 0 | L16: =SUM(B16+G16) -> 324206.83 | M16: =SUM(C16+H16) -> 0 | N16: =SUM(D16+I16) -> 0 | O16: =SUM(E16+J16) -> 0
A17: 2.2.3 - VIÁTICOS | B17: =SUM('TRANSFERENCIA CORRIENTE'!C18:E18) -> 0 | C17: =SUM('TRANSFERENCIA CORRIENTE'!F18:H18) -> 0 | D17: =SUM('TRANSFERENCIA CORRIENTE'!J18:L18) -> 0 | E17: =SUM('TRANSFERENCIA CORRIENTE'!L18:N18) -> 0 | G17: =SUM(VS!C18:E18) -> 0 | H17: =SUM(VS!F18:H18) -> 0 | I17: =SUM(VS!I18:K18) -> 0 | J17: =SUM(VS!L18:N18) -> 0 | L17: =SUM(B17+G17) -> 0 | M17: =SUM(C17+H17) -> 0 | N17: =SUM(D17+I17) -> 0 | O17: =SUM(E17+J17) -> 0
A18: 2.2.4 - TRANSPORTE Y ALMACENAJE | B18: =SUM('TRANSFERENCIA CORRIENTE'!C19:E19) -> 0 | C18: =SUM('TRANSFERENCIA CORRIENTE'!F19:H19) -> 0 | D18: =SUM('TRANSFERENCIA CORRIENTE'!J19:L19) -> 0 | E18: =SUM('TRANSFERENCIA CORRIENTE'!L19:N19) -> 0 | G18: =SUM(VS!C19:E19) -> 56000 | H18: =SUM(VS!F19:H19) -> 0 | I18: =SUM(VS!I19:K19) -> 0 | J18: =SUM(VS!L19:N19) -> 0 | L18: =SUM(B18+G18) -> 56000 | M18: =SUM(C18+H18) -> 0 | N18: =SUM(D18+I18) -> 0 | O18: =SUM(E18+J18) -> 0
A19: 2.2.5 - ALQUILERES Y RENTAS | B19: =SUM('TRANSFERENCIA CORRIENTE'!C20:E20) -> 0 | C19: =SUM('TRANSFERENCIA CORRIENTE'!F20:H20) -> 0 | D19: =SUM('TRANSFERENCIA CORRIENTE'!J20:L20) -> 0 | E19: =SUM('TRANSFERENCIA CORRIENTE'!L20:N20) -> 0 | G19: =SUM(VS!C20:E20) -> 519625.15 | H19: =SUM(VS!F20:H20) -> 0 | I19: =SUM(VS!I20:K20) -> 0 | J19: =SUM(VS!L20:N20) -> 0 | L19: =SUM(B19+G19) -> 519625.15 | M19: =SUM(C19+H19) -> 0 | N19: =SUM(D19+I19) -> 0 | O19: =SUM(E19+J19) -> 0
A20: 2.2.6 - SEGUROS | B20: =SUM('TRANSFERENCIA CORRIENTE'!C21:E21) -> 0 | C20: =SUM('TRANSFERENCIA CORRIENTE'!F21:H21) -> 0 | D20: =SUM('TRANSFERENCIA CORRIENTE'!J21:L21) -> 0 | E20: =SUM('TRANSFERENCIA CORRIENTE'!L21:N21) -> 0 | G20: =SUM(VS!C21:E21) -> 0 | H20: =SUM(VS!F21:H21) -> 0 | I20: =SUM(VS!I21:K21) -> 0 | J20: =SUM(VS!L21:N21) -> 0 | L20: =SUM(B20+G20) -> 0 | M20: =SUM(C20+H20) -> 0 | N20: =SUM(D20+I20) -> 0 | O20: =SUM(E20+J20) -> 0
A21: 2.2.7 - SERVICIOS DE CONSERVACIÓN, REPARACIONES MENORES E INSTALACIONES TEMPORALES | B21: =SUM('TRANSFERENCIA CORRIENTE'!C22:E22) -> 6474433.8 | C21: =SUM('TRANSFERENCIA CORRIENTE'!F22:H22) -> 0 | D21: =SUM('TRANSFERENCIA CORRIENTE'!J22:L22) -> 0 | E21: =SUM('TRANSFERENCIA CORRIENTE'!L22:N22) -> 0 | G21: =SUM(VS!C22:E22) -> 4556850.1 | H21: =SUM(VS!F22:H22) -> 0 | I21: =SUM(VS!I22:K22) -> 0 | J21: =SUM(VS!L22:N22) -> 0 | L21: =SUM(B21+G21) -> 11031284 | M21: =SUM(C21+H21) -> 0 | N21: =SUM(D21+I21) -> 0 | O21: =SUM(E21+J21) -> 0
A22: 2.2.8 - OTROS SERVICIOS NO INCLUIDOS EN CONCEPTOS ANTERIORES | B22: =SUM('TRANSFERENCIA CORRIENTE'!C23:E23) -> 489700 | C22: =SUM('TRANSFERENCIA CORRIENTE'!F23:H23) -> 0 | D22: =SUM('TRANSFERENCIA CORRIENTE'!J23:L23) -> 0 | E22: =SUM('TRANSFERENCIA CORRIENTE'!L23:N23) -> 0 | G22: =SUM(VS!C23:E23) -> 832646.66 | H22: =SUM(VS!F23:H23) -> 0 | I22: =SUM(VS!I23:K23) -> 0 | J22: =SUM(VS!L23:N23) -> 0 | L22: =SUM(B22+G22) -> 1322346.7 | M22: =SUM(C22+H22) -> 0 | N22: =SUM(D22+I22) -> 0 | O22: =SUM(E22+J22) -> 0
A23: 2.2.9 - OTRAS CONTRATACIONES DE SERVICIOS | B23: =SUM('TRANSFERENCIA CORRIENTE'!C24:E24) -> 0 | C23: =SUM('TRANSFERENCIA CORRIENTE'!F24:H24) -> 0 | D23: =SUM('TRANSFERENCIA CORRIENTE'!J24:L24) -> 0 | E23: =SUM('TRANSFERENCIA CORRIENTE'!L24:N24) -> 0 | G23: =SUM(VS!C24:E24) -> 0 | H23: =SUM(VS!F24:H24) -> 0 | I23: =SUM(VS!I24:K24) -> 0 | J23: =SUM(VS!L24:N24) -> 0 | L23: =SUM(B23+G23) -> 0 | M23: =SUM(C23+H23) -> 0 | N23: =SUM(D23+I23) -> 0 | O23: =SUM(E23+J23) -> 0
A24: 2.3 - MATERIALES Y SUMINISTROS | B24: =SUM(B25:B33) -> 46153283 | C24: =SUM(C25:C33) -> 0 | D24: =SUM(D25:D33) -> 0 | E24: =SUM(E25:E33) -> 0 | G24: =SUM(G25:G33) -> 7292547.3 | H24: =SUM(H25:H33) -> 0 | I24: =SUM(I25:I33) -> 0 | J24: =SUM(J25:J33) -> 0 | L24: =SUM(B24+G24) -> 53445831 | M24: =SUM(C24+H24) -> 0 | N24: =SUM(D24+I24) -> 0 | O24: =SUM(E24+J24) -> 0
A25: 2.3.1 - ALIMENTOS Y PRODUCTOS AGROFORESTALES | B25: =SUM('TRANSFERENCIA CORRIENTE'!C26:E26) -> 3713897.2 | C25: =SUM('TRANSFERENCIA CORRIENTE'!F26:H26) -> 0 | D25: =SUM('TRANSFERENCIA CORRIENTE'!I23:K23) -> 0 | E25: =SUM('TRANSFERENCIA CORRIENTE'!L26:N26) -> 0 | G25: =SUM(VS!C26:E26) -> 1500755.8 | H25: =SUM(VS!F26:H26) -> 0 | I25: =SUM(VS!I26:K26) -> 0 | J25: =SUM(VS!L26:N26) -> 0 | L25: =SUM(B25+G25) -> 5214653 | M25: =SUM(C25+H25) -> 0 | N25: =SUM(D25+I25) -> 0 | O25: =SUM(E25+J25) -> 0
A26: 2.3.2 - TEXTILES Y VESTUARIOS | B26: =SUM('TRANSFERENCIA CORRIENTE'!C27:E27) -> 61630.73 | C26: =SUM('TRANSFERENCIA CORRIENTE'!F27:H27) -> 0 | D26: =SUM('TRANSFERENCIA CORRIENTE'!I24:K24) -> 0 | E26: =SUM('TRANSFERENCIA CORRIENTE'!L27:N27) -> 0 | G26: =SUM(VS!C27:E27) -> 0 | H26: =SUM(VS!F27:H27) -> 0 | I26: =SUM(VS!I27:K27) -> 0 | J26: =SUM(VS!L27:N27) -> 0 | L26: =SUM(B26+G26) -> 61630.73 | M26: =SUM(C26+H26) -> 0 | N26: =SUM(D26+I26) -> 0 | O26: =SUM(E26+J26) -> 0
A27: 2.3.3 - PRODUCTOS DE PAPEL, CARTÓN E IMPRESOS | B27: =SUM('TRANSFERENCIA CORRIENTE'!C28:E28) -> 1826911.8 | C27: =SUM('TRANSFERENCIA CORRIENTE'!F28:H28) -> 0 | D27: =SUM('TRANSFERENCIA CORRIENTE'!I25:K25) -> 0 | E27: =SUM('TRANSFERENCIA CORRIENTE'!L28:N28) -> 0 | G27: =SUM(VS!C28:E28) -> 251163 | H27: =SUM(VS!F28:H28) -> 0 | I27: =SUM(VS!I28:K28) -> 0 | J27: =SUM(VS!L28:N28) -> 0 | L27: =SUM(B27+G27) -> 2078074.8 | M27: =SUM(C27+H27) -> 0 | N27: =SUM(D27+I27) -> 0 | O27: =SUM(E27+J27) -> 0
A28: 2.3.4 - PRODUCTOS FARMACÉUTICOS | B28: =SUM('TRANSFERENCIA CORRIENTE'!C29:E29) -> 10797336 | C28: =SUM('TRANSFERENCIA CORRIENTE'!F29:H29) -> 0 | D28: =SUM('TRANSFERENCIA CORRIENTE'!I26:K26) -> 0 | E28: =SUM('TRANSFERENCIA CORRIENTE'!L29:N29) -> 0 | G28: =SUM(VS!C29:E29) -> 558000 | H28: =SUM(VS!F29:H29) -> 0 | I28: =SUM(VS!I29:K29) -> 0 | J28: =SUM(VS!L29:N29) -> 0 | L28: =SUM(B28+G28) -> 11355336 | M28: =SUM(C28+H28) -> 0 | N28: =SUM(D28+I28) -> 0 | O28: =SUM(E28+J28) -> 0
A29: 2.3.5 - PRODUCTOS DE CUERO, CAUCHO Y PLÁSTICO | B29: =SUM('TRANSFERENCIA CORRIENTE'!C30:E30) -> 334708.95 | C29: =SUM('TRANSFERENCIA CORRIENTE'!F30:H30) -> 0 | D29: =SUM('TRANSFERENCIA CORRIENTE'!I27:K27) -> 0 | E29: =SUM('TRANSFERENCIA CORRIENTE'!L30:N30) -> 0 | G29: =SUM(VS!C30:E30) -> 567494.87 | H29: =SUM(VS!F30:H30) -> 0 | I29: =SUM(VS!I30:K30) -> 0 | J29: =SUM(VS!L30:N30) -> 0 | L29: =SUM(B29+G29) -> 902203.82 | M29: =SUM(C29+H29) -> 0 | N29: =SUM(D29+I29) -> 0 | O29: =SUM(E29+J29) -> 0
A30: 2.3.6 - PRODUCTOS DE MINERALES, METÁLICOS Y NO METÁLICOS | B30: =SUM('TRANSFERENCIA CORRIENTE'!C31:E31) -> 11630.98 | C30: =SUM('TRANSFERENCIA CORRIENTE'!F31:H31) -> 0 | D30: =SUM('TRANSFERENCIA CORRIENTE'!I28:K28) -> 0 | E30: =SUM('TRANSFERENCIA CORRIENTE'!L31:N31) -> 0 | G30: =SUM(VS!C31:E31) -> 293957.3 | H30: =SUM(VS!F31:H31) -> 0 | I30: =SUM(VS!I31:K31) -> 0 | J30: =SUM(VS!L31:N31) -> 0 | L30: =SUM(B30+G30) -> 305588.28 | M30: =SUM(C30+H30) -> 0 | N30: =SUM(D30+I30) -> 0 | O30: =SUM(E30+J30) -> 0
A31: 2.3.7 - COMBUSTIBLES, LUBRICANTES, PRODUCTOS QUÍMICOS Y CONEXOS | B31: =SUM('TRANSFERENCIA CORRIENTE'!C32:E32) -> 8910102 | C31: =SUM('TRANSFERENCIA CORRIENTE'!F32:H32) -> 0 | D31: =SUM('TRANSFERENCIA CORRIENTE'!I29:K29) -> 0 | E31: =SUM('TRANSFERENCIA CORRIENTE'!L32:N32) -> 0 | G31: =SUM(VS!C32:E32) -> 1660334.6 | H31: =SUM(VS!F32:H32) -> 0 | I31: =SUM(VS!I32:K32) -> 0 | J31: =SUM(VS!L32:N32) -> 0 | L31: =SUM(B31+G31) -> 10570437 | M31: =SUM(C31+H31) -> 0 | N31: =SUM(D31+I31) -> 0 | O31: =SUM(E31+J31) -> 0
A32: 2.3.8 - GASTOS QUE SE ASIGNARÁN DURANTE EL EJERCICIO (ART. 32 Y 33 LEY 423-06) | B32: =SUM('TRANSFERENCIA CORRIENTE'!C33:E33) -> 0 | C32: =SUM('TRANSFERENCIA CORRIENTE'!F33:H33) -> 0 | D32: =SUM('TRANSFERENCIA CORRIENTE'!I30:K30) -> 0 | E32: =SUM('TRANSFERENCIA CORRIENTE'!L33:N33) -> 0 | G32: =SUM(VS!C33:E33) -> 0 | H32: =SUM(VS!F33:H33) -> 0 | I32: =SUM(VS!I33:K33) -> 0 | J32: =SUM(VS!L33:N33) -> 0 | L32: =SUM(B32+G32) -> 0 | M32: =SUM(C32+H32) -> 0 | N32: =SUM(D32+I32) -> 0 | O32: =SUM(E32+J32) -> 0
A33: 2.3.9 - PRODUCTOS Y ÚTILES VARIOS | B33: =SUM('TRANSFERENCIA CORRIENTE'!C34:E34) -> 20497066 | C33: =SUM('TRANSFERENCIA CORRIENTE'!F34:H34) -> 0 | D33: =SUM('TRANSFERENCIA CORRIENTE'!I31:K31) -> 0 | E33: =SUM('TRANSFERENCIA CORRIENTE'!L34:N34) -> 0 | G33: =SUM(VS!C34:E34) -> 2460841.8 | H33: =SUM(VS!F34:H34) -> 0 | I33: =SUM(VS!I34:K34) -> 0 | J33: =SUM(VS!L34:N34) -> 0 | L33: =SUM(B33+G33) -> 22957908 | M33: =SUM(C33+H33) -> 0 | N33: =SUM(D33+I33) -> 0 | O33: =SUM(E33+J33) -> 0
A34: 2.4 - TRANSFERENCIAS CORRIENTES | B34: =SUM(B35:B41) -> 0 | C34: =SUM(C35:C41) -> 0 | D34: =SUM(D35:D41) -> 0 | E34: =SUM(E35:E41) -> 0 | G34: =SUM(G35:G41) -> 287786.7 | H34: =SUM(H35:H41) -> 0 | I34: =SUM(I35:I41) -> 0 | J34: =SUM(J35:J41) -> 0 | L34: =SUM(B34+G34) -> 287786.7 | M34: =SUM(C34+H34) -> 0 | N34: =SUM(D34+I34) -> 0 | O34: =SUM(E34+J34) -> 0
A35: 2.4.1 - TRANSFERENCIAS CORRIENTES AL SECTOR PRIVADO | B35: =SUM('TRANSFERENCIA CORRIENTE'!C36:E36) -> 0 | C35: =SUM('TRANSFERENCIA CORRIENTE'!F36:H36) -> 0 | D35: =SUM('TRANSFERENCIA CORRIENTE'!I36:K36) -> 0 | E35: =SUM('TRANSFERENCIA CORRIENTE'!L36:N36) -> 0 | G35: =SUM(VS!C36:E36) -> 287786.7 | H35: =SUM(VS!F36:H36) -> 0 | I35: =SUM(VS!I36:K36) -> 0 | J35: =SUM(VS!L36:N36) -> 0 | L35: =SUM(B35+G35) -> 287786.7 | M35: =SUM(C35+H35) -> 0 | N35: =SUM(D35+I35) -> 0 | O35: =SUM(E35+J35) -> 0
A36: 2.4.2 - TRANSFERENCIAS CORRIENTES AL GOBIERNO GENERAL NACIONAL | B36: =SUM('TRANSFERENCIA CORRIENTE'!C37:E37) -> 0 | C36: =SUM('TRANSFERENCIA CORRIENTE'!F37:H37) -> 0 | D36: =SUM('TRANSFERENCIA CORRIENTE'!I37:K37) -> 0 | E36: =SUM('TRANSFERENCIA CORRIENTE'!L37:N37) -> 0 | G36: =SUM(VS!C37:E37) -> 0 | H36: =SUM(VS!F37:H37) -> 0 | I36: =SUM(VS!I37:K37) -> 0 | J36: =SUM(VS!L37:N37) -> 0 | L36: =SUM(B36+G36) -> 0 | M36: =SUM(C36+H36) -> 0 | N36: =SUM(D36+I36) -> 0 | O36: =SUM(E36+J36) -> 0
A37: 2.4.3 - TRANSFERENCIAS CORRIENTES A GOBIERNOS GENERALES LOCALES | B37: =SUM('TRANSFERENCIA CORRIENTE'!C38:E38) -> 0 | C37: =SUM('TRANSFERENCIA CORRIENTE'!F38:H38) -> 0 | D37: =SUM('TRANSFERENCIA CORRIENTE'!I38:K38) -> 0 | E37: =SUM('TRANSFERENCIA CORRIENTE'!L38:N38) -> 0 | G37: =SUM(VS!C38:E38) -> 0 | H37: =SUM(VS!F38:H38) -> 0 | I37: =SUM(VS!I38:K38) -> 0 | J37: =SUM(VS!L38:N38) -> 0 | L37: =SUM(B37+G37) -> 0 | M37: =SUM(C37+H37) -> 0 | N37: =SUM(D37+I37) -> 0 | O37: =SUM(E37+J37) -> 0
A38: 2.4.4 - TRANSFERENCIAS CORRIENTES A EMPRESAS PÚBLICAS NO FINANCIERAS | B38: =SUM('TRANSFERENCIA CORRIENTE'!C39:E39) -> 0 | C38: =SUM('TRANSFERENCIA CORRIENTE'!F39:H39) -> 0 | D38: =SUM('TRANSFERENCIA CORRIENTE'!I39:K39) -> 0 | E38: =SUM('TRANSFERENCIA CORRIENTE'!L39:N39) -> 0 | G38: =SUM(VS!C39:E39) -> 0 | H38: =SUM(VS!F39:H39) -> 0 | I38: =SUM(VS!I39:K39) -> 0 | J38: =SUM(VS!L39:N39) -> 0 | L38: =SUM(B38+G38) -> 0 | M38: =SUM(C38+H38) -> 0 | N38: =SUM(D38+I38) -> 0 | O38: =SUM(E38+J38) -> 0
A39: 2.4.5 - TRANSFERENCIAS CORRIENTES A INSTITUCIONES PÚBLICAS FINANCIERAS | B39: =SUM('TRANSFERENCIA CORRIENTE'!C40:E40) -> 0 | C39: =SUM('TRANSFERENCIA CORRIENTE'!F40:H40) -> 0 | D39: =SUM('TRANSFERENCIA CORRIENTE'!I40:K40) -> 0 | E39: =SUM('TRANSFERENCIA CORRIENTE'!L40:N40) -> 0 | G39: =SUM(VS!C40:E40) -> 0 | H39: =SUM(VS!F40:H40) -> 0 | I39: =SUM(VS!I40:K40) -> 0 | J39: =SUM(VS!L40:N40) -> 0 | L39: =SUM(B39+G39) -> 0 | M39: =SUM(C39+H39) -> 0 | N39: =SUM(D39+I39) -> 0 | O39: =SUM(E39+J39) -> 0
A40: 2.4.7 - TRANSFERENCIAS CORRIENTES AL SECTOR EXTERNO | B40: =SUM('TRANSFERENCIA CORRIENTE'!C41:E41) -> 0 | C40: =SUM('TRANSFERENCIA CORRIENTE'!F41:H41) -> 0 | D40: =SUM('TRANSFERENCIA CORRIENTE'!I41:K41) -> 0 | E40: =SUM('TRANSFERENCIA CORRIENTE'!L41:N41) -> 0 | G40: =SUM(VS!C41:E41) -> 0 | H40: =SUM(VS!F41:H41) -> 0 | I40: =SUM(VS!I41:K41) -> 0 | J40: =SUM(VS!L41:N41) -> 0 | L40: =SUM(B40+G40) -> 0 | M40: =SUM(C40+H40) -> 0 | N40: =SUM(D40+I40) -> 0 | O40: =SUM(E40+J40) -> 0
A41: 2.4.9 - TRANSFERENCIAS CORRIENTES A OTRAS INSTITUCIONES PÚBLICAS | B41: =SUM('TRANSFERENCIA CORRIENTE'!C42:E42) -> 0 | C41: =SUM('TRANSFERENCIA CORRIENTE'!F42:H42) -> 0 | D41: =SUM('TRANSFERENCIA CORRIENTE'!I42:K42) -> 0 | E41: =SUM('TRANSFERENCIA CORRIENTE'!L42:N42) -> 0 | G41: =SUM(VS!C42:E42) -> 0 | H41: =SUM(VS!F42:H42) -> 0 | I41: =SUM(VS!I42:K42) -> 0 | J41: =SUM(VS!L42:N42) -> 0 | L41: =SUM(B41+G41) -> 0 | M41: =SUM(C41+H41) -> 0 | N41: =SUM(D41+I41) -> 0 | O41: =SUM(E41+J41) -> 0
...

Sheet TRANSFERENCIA CORRIENTE
A1: SERVICIO NACIONAL DE SALUD
A2: HOSPITAL MATERNO INFANTIL SAN LORENZO DE LOS MINA
A3: REGION
A4: Ejecución de Gastos Fondo (100) 2025
A5: En RD$
A7: Detalle | B7: Total | C7: Enero | D7: Febrero | E7: Marzo | F7: Abril | G7: Mayo | H7: Junio | I7: Julio | J7: Agosto | K7: Septiembre | L7: Octubre | M7: Noviembre | N7: Diciembre
A8: 2 - GASTOS
A9: 2.1 - REMUNERACIONES Y CONTRIBUCIONES | B9: =SUM(C9:N9) -> 1.9856074e+08 | C9: =SUM(C10:C14) -> 65091180 | D9: =SUM(D10:D14) -> 67131936 | E9: =SUM(E10:E14) -> 66337620 | F9: =SUM(F10:F14) -> 0 | G9: =SUM(G10:G14) -> 0 | H9: =SUM(H10:H14) -> 0 | I9: =SUM(I10:I14) -> 0 | J9: =SUM(J10:J14) -> 0 | ... N9: =SUM(N10:N14) -> 0
A10: 2.1.1 - REMUNERACIONES | B10: =SUM(C10:N10) -> 1.639452e+08 | C10: 53640339 | D10: 55586129 | E10: 54718737
A11: 2.1.2 - SOBRESUELDOS | B11: =SUM(C11:N11) -> 9594398.8 | C11: 3196999.6 | D11: 3197999.6 | E11: 3199399.6
A12: 2.1.3 - DIETAS Y GASTOS DE REPRESENTACIÓN | B12: =SUM(C12:N12) -> 0
A13: 2.1.4 - GRATIFICACIONES Y BONIFICACIONES | B13: =SUM(C13:N13) -> 0
A14: 2.1.5 - CONTRIBUCIONES A LA SEGURIDAD SOCIAL | B14: =SUM(C14:N14) -> 25021132 | C14: 8253841.6 | D14: 8347807.5 | E14: 8419483.2
A15: 2.2 - CONTRATACIÓN DE SERVICIOS | B15: =SUM(C15:N15) -> 9308364.9 | C15: =SUM(C16:C24) -> 0 | D15: =SUM(D16:D24) -> 1336968.6 | E15: =SUM(E16:E24) -> 7971396.2 | F15: =SUM(F16:F24) -> 0 | G15: =SUM(G16:G24) -> 0 | H15: =SUM(H16:H24) -> 0 | I15: =SUM(I16:I24) -> 0 | J15: =SUM(J16:J24) -> 0 | ... N15: =SUM(N16:N24) -> 0
A16: 2.2.1 - SERVICIOS BÁSICOS | B16: =SUM(C16:N16) -> 2020024.3 | E16: 2020024.3
A17: 2.2.2 - PUBLICIDAD, IMPRESIÓN Y ENCUADERNACIÓN | B17: =SUM(C17:N17) -> 324206.83 | D17: 324206.83
A18: 2.2.3 - VIÁTICOS | B18: =SUM(C18:N18) -> 0
A19: 2.2.4 - TRANSPORTE Y ALMACENAJE | B19: =SUM(C19:N19) -> 0
A20: 2.2.5 - ALQUILERES Y RENTAS | B20: =SUM(C20:N20) -> 0
A21: 2.2.6 - SEGUROS | B21: =SUM(C21:N21) -> 0
A22: 2.2.7 - SERVICIOS DE CONSERVACIÓN, REPARACIONES MENORES E INSTALACIONES TEMPORALES | B22: =SUM(C22:N22) -> 6474433.8 | D22: 523061.81 | E22: 5951371.9
A23: 2.2.8 - OTROS SERVICIOS NO INCLUIDOS EN CONCEPTOS ANTERIORES | B23: =SUM(C23:N23) -> 489700 | D23: 489700
A24: 2.2.9 - OTRAS CONTRATACIONES DE SERVICIOS | B24: =SUM(C24:N24) -> 0
A25: 2.3 - MATERIALES Y SUMINISTROS | B25: =SUM(C25:N25) -> 46153283 | C25: =SUM(C26:C34) -> 4970600.4 | D25: =SUM(D26:D34) -> 14433131 | E25: =SUM(E26:E34) -> 26749552 | F25: =SUM(F26:F34) -> 0 | G25: =SUM(G26:G34) -> 0 | H25: =SUM(H26:H34) -> 0 | I25: =SUM(I26:I34) -> 0 | J25: =SUM(J26:J34) -> 0 | ... N25: =SUM(N26:N34) -> 0
A26: 2.3.1 - ALIMENTOS Y PRODUCTOS AGROFORESTALES | D26: 591460.4 | E26: 3122436.8
A27: 2.3.2 - TEXTILES Y VESTUARIOS | D27: 61630.73
A28: 2.3.3 - PRODUCTOS DE PAPEL, CARTÓN E IMPRESOS | D28: 352366.67 | E28: 1474545.2
A29: 2.3.4 - PRODUCTOS FARMACÉUTICOS | C29: 1862880 | D29: 2014526.8 | E29: 6919929
A30: 2.3.5 - PRODUCTOS DE CUERO, CAUCHO Y PLÁSTICO | E30: 334708.95
A31: 2.3.6 - PRODUCTOS DE MINERALES, METÁLICOS Y NO METÁLICOS | D31: 11630.98
A32: 2.3.7 - COMBUSTIBLES, LUBRICANTES, PRODUCTOS QUÍMICOS Y CONEXOS | C32: 1844663.4 | D32: 3902915.5 | E32: 3162523
A33: 2.3.8 - GASTOS QUE SE ASIGNARÁN DURANTE EL EJERCICIO (ART. 32 Y 33 LEY 423-06)
A34: 2.3.9 - PRODUCTOS Y ÚTILES VARIOS | C34: 1263057 | D34: 7498600.4 | E34: 11735409
A35: 2.4 - TRANSFERENCIAS CORRIENTES | B35: =SUM(C35:N35) -> 0 | C35: =SUM(C36:C42) -> 0 | D35: =SUM(D36:D42) -> 0 | E35: =SUM(E36:E42) -> 0 | F35: =SUM(F36:F42) -> 0 | G35: =SUM(G36:G42) -> 0 | H35: =SUM(H36:H42) -> 0 | I35: =SUM(I36:I42) -> 0 | J35: =SUM(J36:J42) -> 0 | ... N35: =SUM(N36:N42) -> 0
A36: 2.4.1 - TRANSFERENCIAS CORRIENTES AL SECTOR PRIVADO | B36: =SUM(C36:N36) -> 0
A37: 2.4.2 - TRANSFERENCIAS CORRIENTES AL GOBIERNO GENERAL NACIONAL | B37: =SUM(C37:N37) -> 0
A38: 2.4.3 - TRANSFERENCIAS CORRIENTES A GOBIERNOS GENERALES LOCALES | B38: =SUM(C38:N38) -> 0
A39: 2.4.4 - TRANSFERENCIAS CORRIENTES A EMPRESAS PÚBLICAS NO FINANCIERAS | B39: =SUM(C39:N39) -> 0
A40: 2.4.5 - TRANSFERENCIAS CORRIENTES A INSTITUCIONES PÚBLICAS FINANCIERAS | B40: =SUM(C40:N40) -> 0
A41: 2.4.7 - TRANSFERENCIAS CORRIENTES AL SECTOR EXTERNO | B41: =SUM(C41:N41) -> 0
...

Sheet VS
A1: SERVICIO NACIONAL DE SALUD
A2: HOSPITAL MATERNO INFANTIL SAN LORENZO DE LOS MINA
A3: REGION
A4: Ejecución de Gastos VENTA SERVICIOS 2024
A5: En RD$
A7: Detalle | B7: Total | C7: Enero | D7: Febrero | E7: Marzo | F7: Abril | G7: Mayo | H7: Junio | I7: Julio | J7: Agosto | K7: Septiembre | L7: Octubre | M7: Noviembre | N7: Diciembre
A8: 2 - GASTOS
