Workbook

Sheet MARZO 2025
A1: Form. No.6 SRS
A3: Servicio Nacional de Salud
A4: Dirección de Fizcalización
A5: Consolidado de Ingresos y Gastos por Fuente de Financiamiento
A6: HOSPITAL MATERNO INFANTIL SAN LORENZO DE LOS MINA
A7: MARZO 2025
C8: Ingresos Generales:
E9: 1.- Balance Inicial / Fuente:
E10: Anticipo Financiero | H10: Otros Aportes | L10: Contraseña: 0001
E11: Transferencias Corrientes
E12: Venta de Servicios | G12: 2511952.5
E13: 2.- Ingresos por Fuente / Cuenta
E14: Anticipo Financiero | H14: Otros Aportes | I14: =+'[1]INGR SEGUN ORIGEN'!E39 -> 223625 | L14: OBJETAL | M14: FR | N14: VS
E15: Transferencias Corrientes | G15: =+'[1]INGR SEGUN ORIGEN'!E12 -> 1.003168e+08 | H15: Aportes Nomina SNS | I15: 0 | L15: 2.1 | M15: =G26 -> 66337620 | N15: =H26 -> 5231553.6
E16: Venta de Servicios | G16: =+'[1]INGR SEGUN ORIGEN'!E37 -> 7825280.6 | L16: 2.2 | M16: =G87 -> 7971396.2 | N16: =H87 -> 4359456.2
H17: TOTAL INGRESOS RDS | I17: =+G10+G11+G12+I10+G14+G15+G16+I14+I15 -> 1.1087765e+08 | L17: 2.3 | M17: ='[1]CONS. FUENTES FINAN'!G212 -> 26749552 | N17: ='[1]CONS. FUENTES FINAN'!H212 -> 1797538.3
L18: 2.4 | M18: =G330 -> 0 | N18: =H330 -> 127420
L19: 2.6 | M19: =G336 -> 11396849 | N19: =H336 -> 300539.37
L20: 2.7 | M20: ='[1]CONS. FUENTES FINAN'!G463 -> 0 | N20: ='[1]CONS. FUENTES FINAN'!H463 -> 0
A21: 1 | F21: 2 | G21: 3 | I21: 4 | J21: 5
A22: Código Presupuestario | F22: Descripción Gasto por Cuenta | G22: Distribución del Gasto por Fuente de Financiamiento | I22: TOTAL | J22: %
A23: Tipo | B23: Objeto | C23: Cuenta | D23: Sub-Cuenta | E23: Auxiliar | G23: Fondo 100 | H23: Venta de Servicios/ Otros Aportes
A25: 2 | F25: Gastos | G25: =+G26+G87+G212+G330+G336+G463 -> 1.1245542e+08 | H25: =+H26+H87+H212+H330+H336+H463 -> 11816507 | I25: =SUM(G25:H25) -> 1.2427192e+08 | J25: =+J26+J87+J212+J330+J336+J463 -> 1
A26: 2 | B26: 1 | F26: Servicios Personales | G26: =+G27+G51+G64+G71+G78 -> 66337620 | H26: =+H27+H51+H64+H71+H78 -> 5231553.6 | I26: =SUM(G26:H26) -> 71569173 | J26: =I26/$I$25 -> 0.57590782
A27: 2 | B27: 1 | C27: 1 | F27: Remuneraciones | G27: =+G28+G35+G42+G44+G46 -> 54718737 | H27: =+H28+H35+H42+H44+H46 -> 0 | I27: =SUM(G27:H27) -> 54718737 | J27: =I27/$I$25 -> 0.44031455
A28: 2 | B28: 1 | C28: 1 | D28: 1 | F28: Remuneraciones al personal fijo | G28: =SUM(G29:G34) -> 53611206 | H28: =SUM(H29:H34) -> 0 | I28: =SUM(G28:H28) -> 53611206 | J28: =I28/$I$25 -> 0.4314024
A29: 2 | B29: 1 | C29: 1 | D29: 1 | E29: 01 | F29: Sueldos a empleados fijos | G29: ='[1]CUENTA T FONDO 100'!A127 -> 53611206 | H29: ='[1]CUENTA T VS'!A96 -> 0 | I29: =SUM(G29:H29) -> 53611206 | J29: =I29/$I$25 -> 0.4314024
A30: 2 | B30: 1 | C30: 1 | D30: 1 | E30: 02 | F30: Sueldos a médicos | G30: ='[1]CUENTA T FONDO 100'!B127 -> 0 | H30: ='[1]CUENTA T VS'!B96 -> 0 | I30: =SUM(G30:H30) -> 0 | J30: =I30/$I$25 -> 0
A31: 2 | B31: 1 | C31: 1 | D31: 1 | E31: 03 | F31: Ascensos a militares | G31: ='[1]CUENTA T FONDO 100'!C127 -> 0 | H31: ='[1]CUENTA T VS'!C96 -> 0 | I31: =SUM(G31:H31) -> 0 | J31: =I31/$I$25 -> 0
A32: 2 | B32: 1 | C32: 1 | D32: 1 | E32: 04 | F32: Nuevas plazas maestros | G32: ='[1]CUENTA T FONDO 100'!D127 -> 0 | H32: ='[1]CUENTA T VS'!D96 -> 0 | I32: =SUM(G32:H32) -> 0 | J32: =I32/$I$25 -> 0
A33: 2 | B33: 1 | C33: 1 | D33: 1 | E33: 05 | F33: Incentivos y escalafón | G33: ='[1]CUENTA T FONDO 100'!E127 -> 0 | H33: ='[1]CUENTA T VS'!E96 -> 0 | I33: =SUM(G33:H33) -> 0 | J33: =I33/$I$25 -> 0
A34: 2 | B34: 1 | C34: 1 | D34: 1 | E34: 06 | F34: Nuevas plazas a médicos | G34: ='[1]CUENTA T FONDO 100'!F127 -> 0 | H34: ='[1]CUENTA T VS'!F96 -> 0 | I34: =SUM(G34:H34) -> 0 | J34: =I34/$I$25 -> 0
A35: 2 | B35: 1 | C35: 1 | D35: 2 | F35: Remuneraciones al personal con carácter transitorio | G35: =SUM(G36:G41) -> 1107531 | H35: =SUM(H36:H41) -> 0 | I35: =SUM(G35:H35) -> 1107531
A36: 2 | B36: 1 | C36: 1 | D36: 2 | E36: 03 | F36: Suplencias | G36: ='[1]CUENTA T FONDO 100'!G127 -> 0 | H36: ='[1]CUENTA T VS'!G96 -> 0 | I36: =SUM(G36:H36) -> 0 | J36: =I36/$I$25 -> 0
A37: 2 | B37: 1 | C37: 1 | D37: 2 | E37: 05 | F37: Sueldo al personal nominal en período probatorio | G37: ='[1]CUENTA T FONDO 100'!H127 -> 0 | H37: ='[1]CUENTA T VS'!H96 -> 0 | I37: =SUM(G37:H37) -> 0 | J37: =I37/$I$25 -> 0
A38: 2 | B38: 1 | C38: 1 | D38: 2 | E38: 06 | F38: Jornales | G38: ='[1]CUENTA T FONDO 100'!I127 -> 0 | H38: ='[1]CUENTA T VS'!I96 -> 0 | I38: =SUM(G38:H38) -> 0 | J38: =I38/$I$25 -> 0
A39: 2 | B39: 1 | C39: 1 | D39: 2 | E39: 08 | F39: Empleados temporales | G39: ='[1]CUENTA T FONDO 100'!J127 -> 1107531 | H39: ='[1]CUENTA T VS'!J96 -> 0 | I39: =SUM(G39:H39) -> 1107531 | J39: =I39/$I$25 -> 0.008912158
A40: 2 | B40: 1 | C40: 1 | D40: 2 | E40: 09 | F40: Personal de carácter eventual | G40: ='[1]CUENTA T FONDO 100'!K127 -> 0 | H40: ='[1]CUENTA T VS'!K96 -> 0 | I40: =SUM(G40:H40) -> 0 | J40: =I40/$I$25 -> 0
A41: 2 | B41: 1 | C41: 1 | D41: 2 | E41: 11 | F41: Interinato | G41: ='[1]CUENTA T FONDO 100'!L127 -> 0 | H41: ='[1]CUENTA T VS'!L96 -> 0 | I41: =SUM(G41:H41) -> 0 | J41: =I41/$I$25 -> 0
A42: 2 | B42: 1 | C42: 1 | D42: 3 | F42: Sueldos al personal fijo en trámite de pensiones | G42: =SUM(G43) -> 0 | H42: =SUM(H43) -> 0 | I42: =SUM(G42:H42) -> 0
...

Sheet FEBRERO 2025
A1: Form. No.6 SRS
A3: Servicio Nacional de Salud
A4: Dirección de Fizcalización
A5: Consolidado de Ingresos y Gastos por Fuente de Financiamiento
A6: HOSPITAL MATERNO INFANTIL SAN LORENZO DE LOS MINA
A7: FEBRERO 2025
C8: Ingresos Generales:
E9: 1.- Balance Inicial / Fuente:
E10: Anticipo Financiero | H10: Otros Aportes | L10: Contraseña: 0001
E11: Transferencias Corrientes
E12: Venta de Servicios | G12: 500388.24
E13: 2.- Ingresos por Fuente / Cuenta
E14: Anticipo Financiero | H14: Otros Aportes | L14: OBJETAL | M14: FR | N14: VS
E15: Transferencias Corrientes | G15: =12593841.17+3169632.08+84553321.83 -> 1.003168e+08 | H15: Aportes Nomina SNS | I15: 0 | L15: 2.1 | M15: =G26 -> 67131936 | N15: =H26 -> 0
E16: Venta de Servicios | G16: =+'[2]INGR SEGUN ORIGEN'!E31+'[2]INGR SEGUN ORIGEN'!E25 -> 9549024.6 | L16: 2.2 | M16: =G87 -> 1336968.6 | N16: =H87 -> 1213383.4
H17: TOTAL INGRESOS RDS | I17: =+G10+G11+G12+I10+G14+G15+G16+I14+I15 -> 1.1036621e+08 | L17: 2.3 | M17: ='[2]CONS. FUENTES FINAN'!G212 -> 14433131 | N17: ='[2]CONS. FUENTES FINAN'!H212 -> 2432378.3
L18: 2.4 | M18: =G330 -> 0 | N18: =H330 -> 23400
L19: 2.6 | M19: =G336 -> 6461017.3 | N19: =H336 -> 3887510
L20: 2.7 | M20: ='[2]CONS. FUENTES FINAN'!G463 -> 0 | N20: ='[2]CONS. FUENTES FINAN'!H463 -> 0
A21: 1 | F21: 2 | G21: 3 | I21: 4 | J21: 5
A22: Código Presupuestario | F22: Descripción Gasto por Cuenta | G22: Distribución del Gasto por Fuente de Financiamiento | I22: TOTAL | J22: %
A23: Tipo | B23: Objeto | C23: Cuenta | D23: Sub-Cuenta | E23: Auxiliar | G23: Fondo 100 | H23: Venta de Servicios/ Otros Aportes
A25: 2 | F25: Gastos | G25: =+G26+G87+G212+G330+G336+G463 -> 89363053 | H25: =+H26+H87+H212+H330+H336+H463 -> 7556671.6 | I25: =SUM(G25:H25) -> 96919725 | J25: =+J26+J87+J212+J330+J336+J463 -> 1
A26: 2 | B26: 1 | F26: Servicios Personales | G26: =+G27+G51+G64+G71+G78 -> 67131936 | H26: =+H27+H51+H64+H71+H78 -> 0 | I26: =SUM(G26:H26) -> 67131936 | J26: =I26/$I$25 -> 0.69265504
A27: 2 | B27: 1 | C27: 1 | F27: Remuneraciones | G27: =+G28+G35+G42+G44+G46 -> 55586129 | H27: =+H28+H35+H42+H44+H46 -> 0 | I27: =SUM(G27:H27) -> 55586129 | J27: =I27/$I$25 -> 0.57352751
A28: 2 | B28: 1 | C28: 1 | D28: 1 | F28: Remuneraciones al personal fijo | G28: =SUM(G29:G34) -> 53156478 | H28: =SUM(H29:H34) -> 0 | I28: =SUM(G28:H28) -> 53156478 | J28: =I28/$I$25 -> 0.54845882
A29: 2 | B29: 1 | C29: 1 | D29: 1 | E29: 01 | F29: Sueldos a empleados fijos | G29: ='[2]CUENTA T FONDO 100'!A116 -> 53156478 | H29: ='[2]CUENTA T VS'!A96 -> 0 | I29: =SUM(G29:H29) -> 53156478 | J29: =I29/$I$25 -> 0.54845882
A30: 2 | B30: 1 | C30: 1 | D30: 1 | E30: 02 | F30: Sueldos a médicos | G30: ='[2]CUENTA T FONDO 100'!B116 -> 0 | H30: ='[2]CUENTA T VS'!B96 -> 0 | I30: =SUM(G30:H30) -> 0 | J30: =I30/$I$25 -> 0
A31: 2 | B31: 1 | C31: 1 | D31: 1 | E31: 03 | F31: Ascensos a militares | G31: ='[2]CUENTA T FONDO 100'!C116 -> 0 | H31: ='[2]CUENTA T VS'!C96 -> 0 | I31: =SUM(G31:H31) -> 0 | J31: =I31/$I$25 -> 0
A32: 2 | B32: 1 | C32: 1 | D32: 1 | E32: 04 | F32: Nuevas plazas maestros | G32: ='[2]CUENTA T FONDO 100'!D116 -> 0 | H32: ='[2]CUENTA T VS'!D96 -> 0 | I32: =SUM(G32:H32) -> 0 | J32: =I32/$I$25 -> 0
A33: 2 | B33: 1 | C33: 1 | D33: 1 | E33: 05 | F33: Incentivos y escalafón | G33: ='[2]CUENTA T FONDO 100'!E116 -> 0 | H33: ='[2]CUENTA T VS'!E96 -> 0 | I33: =SUM(G33:H33) -> 0 | J33: =I33/$I$25 -> 0
A34: 2 | B34: 1 | C34: 1 | D34: 1 | E34: 06 | F34: Nuevas plazas a médicos | G34: ='[2]CUENTA T FONDO 100'!F116 -> 0 | H34: ='[2]CUENTA T VS'!F96 -> 0 | I34: =SUM(G34:H34) -> 0 | J34: =I34/$I$25 -> 0
A35: 2 | B35: 1 | C35: 1 | D35: 2 | F35: Remuneraciones al personal con carácter transitorio | G35: =SUM(G36:G41) -> 1096531 | H35: =SUM(H36:H41) -> 0 | I35: =SUM(G35:H35) -> 1096531
A36: 2 | B36: 1 | C36: 1 | D36: 2 | E36: 03 | F36: Suplencias | G36: ='[2]CUENTA T FONDO 100'!G116 -> 0 | H36: ='[2]CUENTA T VS'!G96 -> 0 | I36: =SUM(G36:H36) -> 0 | J36: =I36/$I$25 -> 0
A37: 2 | B37: 1 | C37: 1 | D37: 2 | E37: 05 | F37: Sueldo al personal nominal en período probatorio | G37: ='[2]CUENTA T FONDO 100'!H116 -> 0 | H37: ='[2]CUENTA T VS'!H96 -> 0 | I37: =SUM(G37:H37) -> 0 | J37: =I37/$I$25 -> 0
A38: 2 | B38: 1 | C38: 1 | D38: 2 | E38: 06 | F38: Jornales | G38: ='[2]CUENTA T FONDO 100'!I116 -> 0 | H38: ='[2]CUENTA T VS'!I96 -> 0 | I38: =SUM(G38:H38) -> 0 | J38: =I38/$I$25 -> 0
A39: 2 | B39: 1 | C39: 1 | D39: 2 | E39: 08 | F39: Empleados temporales | G39: ='[2]CUENTA T FONDO 100'!J116 -> 1096531 | H39: ='[2]CUENTA T VS'!J96 -> 0 | I39: =SUM(G39:H39) -> 1096531 | J39: =I39/$I$25 -> 0.011313807
A40: 2 | B40: 1 | C40: 1 | D40: 2 | E40: 09 | F40: Personal de carácter eventual | G40: ='[2]CUENTA T FONDO 100'!K116 -> 0 | H40: ='[2]CUENTA T VS'!K96 -> 0 | I40: =SUM(G40:H40) -> 0 | J40: =I40/$I$25 -> 0
A41: 2 | B41: 1 | C41: 1 | D41: 2 | E41: 11 | F41: Interinato | G41: ='[2]CUENTA T FONDO 100'!L116 -> 0 | H41: ='[2]CUENTA T VS'!L96 -> 0 | I41: =SUM(G41:H41) -> 0 | J41: =I41/$I$25 -> 0
A42: 2 | B42: 1 | C42: 1 | D42: 3 | F42: Sueldos al personal fijo en trámite de pensiones | G42: =SUM(G43) -> 0 | H42: =SUM(H43) -> 0 | I42: =SUM(G42:H42) -> 0
...

Sheet ENERO 2025
A1: Form. No.6 SRS
A3: Servicio Nacional de Salud
A4: Dirección de Fizcalización
A5: Consolidado de Ingresos y Gastos por Fuente de Financiamiento
A6: HOSPITAL MATERNO INFANTIL SAN LORENZO DE LOS MINA
A7: ENERO 2025
C8: Ingresos Generales:
E9: 1.- Balance Inicial / Fuente:
E10: Anticipo Financiero | G10: 0 | H10: Otros Aportes | M10: Contraseña: 0001
E11: Transferencias Corrientes | G11: 0
E12: Venta de Servicios | G12: 2244994.1
E13: 2.- Ingresos por Fuente / Cuenta
E14: Anticipo Financiero | H14: Otros Aportes | J14: =+'[3]INGRESOS SEGUN ORIGEN'!E8 -> 15763473 | M14: OBJETAL | N14: FR | O14: VS
E15: Transferencias Corrientes | H15: Aportes Nomina SNS | J15: =+'[3]INGRESOS SEGUN ORIGEN'!E7 -> 84553322 | M15: 2.1 | N15: =G26 -> 65091180 | O15: =H26 -> 0
E16: Venta de Servicios | G16: =+'[3]INGRESOS SEGUN ORIGEN'!E24+'[3]INGRESOS SEGUN ORIGEN'!E29 -> 6032481.2 | M16: 2.2 | N16: =G87 -> 0 | O16: =H87 -> 2733844.3
H17: TOTAL INGRESOS RDS | J17: =+G10+G11+G12+J10+G14+G15+G16+J14+J15 -> 1.0859427e+08 | M17: 2.3 | N17: ='[3]CONS. FUENTES FINAN'!G212 -> 4970601.2 | O17: ='[3]CONS. FUENTES FINAN'!H212 -> 3062630.7
M18: 2.4 | N18: =G330 -> 0 | O18: =H330 -> 136966.7
M19: 2.6 | N19: =G336 -> 0 | O19: =H336 -> 887994.84
M20: 2.7 | N20: ='[3]CONS. FUENTES FINAN'!G463 -> 0 | O20: ='[3]CONS. FUENTES FINAN'!H463 -> 0
A21: 1 | F21: 2 | G21: 3 | J21: 4 | K21: 5
A22: Código Presupuestario | F22: Descripción Gasto por Cuenta | G22: Distribución del Gasto por Fuente de Financiamiento | J22: TOTAL | K22: %
A23: Tipo | B23: Objeto | C23: Cuenta | D23: Sub-Cuenta | E23: Auxiliar | G23: Fondo 100 | H23: Venta de Servicios/ Otros Aportes | I23: Aportes Nomina SNS
A25: 2 | F25: Gastos | G25: =+G26+G87+G212+G330+G336+G463 -> 70061781 | H25: =+H26+H87+H212+H330+H336+H463 -> 6821436.5 | I25: =+I26+I87+I212+I330+I336+I463 -> 0 | J25: =SUM(G25:I25) -> 76883218 | K25: =+K26+K87+K212+K330+K336+K463 -> 1 | L25: =+G25+'FEBRERO 2025'!G25 -> 1.5942483e+08 | M25: =+H25+'FEBRERO 2025'!H25 -> 14378108
A26: 2 | B26: 1 | F26: Servicios Personales | G26: =+G27+G51+G64+G71+G78 -> 65091180 | H26: =+H27+H51+H64+H71+H78 -> 0 | I26: =+I27+I51+I64+I71+I78 -> 0 | J26: =SUM(G26:I26) -> 65091180 | K26: =J26/$J$25 -> 0.84662404
A27: 2 | B27: 1 | C27: 1 | F27: Remuneraciones | G27: =+G28+G35+G42+G44+G46 -> 53640339 | H27: =+H28+H35+H42+H44+H46 -> 0 | I27: =+I28+I35+I42+I44+I46 -> 0 | J27: =SUM(G27:I27) -> 53640339 | K27: =J27/$J$25 -> 0.69768592
A28: 2 | B28: 1 | C28: 1 | D28: 1 | F28: Remuneraciones al personal fijo | G28: =SUM(G29:G34) -> 52666808 | H28: =SUM(H29:H34) -> 0 | I28: =SUM(I29:I34) -> 0 | J28: =SUM(G28:I28) -> 52666808 | K28: =J28/$J$25 -> 0.68502346
A29: 2 | B29: 1 | C29: 1 | D29: 1 | E29: 01 | F29: Sueldos a empleados fijos | G29: ='[3]CUENTA T FONDO 100'!A288 -> 52666808 | H29: ='[3]CUENTA T VS'!A81 -> 0 | I29: ='[3]CUENTA T NOMINA SNS'!A58 -> 0 | J29: =SUM(G29:I29) -> 52666808 | K29: =J29/$J$25 -> 0.68502346
A30: 2 | B30: 1 | C30: 1 | D30: 1 | E30: 02 | F30: Sueldos a médicos | G30: ='[3]CUENTA T FONDO 100'!B288 -> 0 | H30: ='[3]CUENTA T VS'!B81 -> 0 | I30: ='[3]CUENTA T NOMINA SNS'!B58 -> 0 | J30: =SUM(G30:I30) -> 0 | K30: =J30/$J$25 -> 0
A31: 2 | B31: 1 | C31: 1 | D31: 1 | E31: 03 | F31: Ascensos a militares | G31: ='[3]CUENTA T FONDO 100'!C288 -> 0 | H31: ='[3]CUENTA T VS'!C81 -> 0 | I31: ='[3]CUENTA T NOMINA SNS'!C58 -> 0 | J31: =SUM(G31:I31) -> 0 | K31: =J31/$J$25 -> 0
A32: 2 | B32: 1 | C32: 1 | D32: 1 | E32: 04 | F32: Nuevas plazas maestros | G32: ='[3]CUENTA T FONDO 100'!D288 -> 0 | H32: ='[3]CUENTA T VS'!D81 -> 0 | I32: ='[3]CUENTA T NOMINA SNS'!D58 -> 0 | J32: =SUM(G32:I32) -> 0 | K32: =J32/$J$25 -> 0
A33: 2 | B33: 1 | C33: 1 | D33: 1 | E33: 05 | F33: Incentivos y escalafón | G33: ='[3]CUENTA T FONDO 100'!E288 -> 0 | H33: ='[3]CUENTA T VS'!E81 -> 0 | I33: ='[3]CUENTA T NOMINA SNS'!E58 -> 0 | J33: =SUM(G33:I33) -> 0 | K33: =J33/$J$25 -> 0
A34: 2 | B34: 1 | C34: 1 | D34: 1 | E34: 06 | F34: Nuevas plazas a médicos | G34: ='[3]CUENTA T FONDO 100'!F288 -> 0 | H34: ='[3]CUENTA T VS'!F81 -> 0 | I34: ='[3]CUENTA T NOMINA SNS'!F58 -> 0 | J34: =SUM(G34:I34) -> 0 | K34: =J34/$J$25 -> 0
A35: 2 | B35: 1 | C35: 1 | D35: 2 | F35: Remuneraciones al personal con carácter transitorio | G35: =SUM(G36:G41) -> 973531.03 | H35: =SUM(H36:H41) -> 0 | I35: =SUM(I36:I41) -> 0 | J35: =SUM(G35:I35) -> 973531.03
A36: 2 | B36: 1 | C36: 1 | D36: 2 | E36: 03 | F36: Suplencias | G36: ='[3]CUENTA T FONDO 100'!G288 -> 0 | H36: ='[3]CUENTA T VS'!G81 -> 0 | I36: ='[3]CUENTA T NOMINA SNS'!G58 -> 0 | J36: =SUM(G36:I36) -> 0 | K36: =J36/$J$25 -> 0
A37: 2 | B37: 1 | C37: 1 | D37: 2 | E37: 05 | F37: Sueldo al personal nominal en período probatorio | G37: ='[3]CUENTA T FONDO 100'!H288 -> 0 | H37: ='[3]CUENTA T VS'!H81 -> 0 | I37: ='[3]CUENTA T NOMINA SNS'!H58 -> 0 | J37: =SUM(G37:I37) -> 0 | K37: =J37/$J$25 -> 0
A38: 2 | B38: 1 | C38: 1 | D38: 2 | E38: 06 | F38: Jornales | G38: ='[3]CUENTA T FONDO 100'!I288 -> 0 | H38: ='[3]CUENTA T VS'!I81 -> 0 | I38: ='[3]CUENTA T NOMINA SNS'!I58 -> 0 | J38: =SUM(G38:I38) -> 0 | K38: =J38/$J$25 -> 0
A39: 2 | B39: 1 | C39: 1 | D39: 2 | E39: 08 | F39: Empleados temporales | G39: ='[3]CUENTA T FONDO 100'!J288 -> 973531.03 | H39: ='[3]CUENTA T VS'!J81 -> 0 | I39: ='[3]CUENTA T NOMINA SNS'!J58 -> 0 | J39: =SUM(G39:I39) -> 973531.03 | K39: =J39/$J$25 -> 0.012662465
A40: 2 | B40: 1 | C40: 1 | D40: 2 | E40: 09 | F40: Personal de carácter eventual | G40: ='[3]CUENTA T FONDO 100'!K288 -> 0 | H40: ='[3]CUENTA T VS'!K81 -> 0 | I40: ='[3]CUENTA T NOMINA SNS'!K58 -> 0 | J40: =SUM(G40:I40) -> 0 | K40: =J40/$J$25 -> 0
A41: 2 | B41: 1 | C41: 1 | D41: 2 | E41: 11 | F41: Interinato | G41: ='[3]CUENTA T FONDO 100'!L288 -> 0 | H41: ='[3]CUENTA T VS'!L81 -> 0 | I41: ='[3]CUENTA T NOMINA SNS'!L58 -> 0 | J41: =SUM(G41:I41) -> 0 | K41: =J41/$J$25 -> 0
A42: 2 | B42: 1 | C42: 1 | D42: 3 | F42: Sueldos al personal fijo en trámite de pensiones | G42: =SUM(G43) -> 0 | H42: =SUM(H43) -> 0 | I42: =SUM(I43) -> 0 | J42: =SUM(G42:I42) -> 0
...

Sheet TRIMESTRAL
A1: Form. No.6 SRS
A3: Servicio Nacional de Salud
A4: Dirección de Fizcalización
A5: Consolidado de Ingresos y Gastos por Fuente de Financiamiento
A6: HOSPITAL MATERNO INFANTIL SAN LORENZO DE LOS MINA
A7: TRIMESTRE ENERO-MARZO 2025
C8: Ingresos Generales:
E9: 1.- Balance Inicial / Fuente:
E10: Anticipo Financiero | G10: 0 | H10: Otros Aportes | M10: Contraseña: 0001
E11: Transferencias Corrientes | G11: 0
E12: Venta de Servicios | G12: =+'ENERO 2025'!G12 -> 2244994.1
E13: 2.- Ingresos por Fuente / Cuenta
E14: Anticipo Financiero | H14: Otros Aportes | M14: OBJETAL | N14: FR | O14: VS
E15: Transferencias Corrientes | G15: 3.0095039e+08 | H15: Aportes Nomina SNS | M15: 2.1 | N15: =G26 -> 1.9856074e+08 | O15: =H26 -> 5231553.6
E16: Venta de Servicios | G16: 23630411 | M16: 2.2 | N16: =G87 -> 9308364.9 | O16: =H87 -> 8306683.9
H17: TOTAL INGRESOS RDS | J17: =+G15+G16 -> 3.245808e+08 | M17: 2.3 | N17: ='[3]CONS. FUENTES FINAN'!G212 -> 4970601.2 | O17: ='[3]CONS. FUENTES FINAN'!H212 -> 3062630.7
M18: 2.4 | N18: =G330 -> 0 | O18: =H330 -> 287786.7
M19: 2.6 | N19: =G336 -> 17857867 | O19: =H336 -> 5076044.2
M20: 2.7 | N20: ='[3]CONS. FUENTES FINAN'!G463 -> 0 | O20: ='[3]CONS. FUENTES FINAN'!H463 -> 0
A21: 1 | F21: 2 | G21: 3 | J21: 4 | K21: 5
A22: Código Presupuestario | F22: Descripción Gasto por Cuenta | G22: Distribución del Gasto por Fuente de Financiamiento | J22: TOTAL | K22: %
A23: Tipo | B23: Objeto | C23: Cuenta | D23: Sub-Cuenta | E23: Auxiliar | G23: Fondo 100 | H23: Venta de Servicios/ Otros Aportes | I23: Aportes Nomina SNS
A25: 2 | F25: Gastos | G25: =+G26+G87+G212+G330+G336+G463 -> 2.7188025e+08 | H25: =+H26+H87+H212+H330+H336+H463 -> 26194616 | I25: =+I26+I87+I212+I330+I336+I463 -> 0 | J25: =SUM(G25:I25) -> 2.9807487e+08 | K25: =+K26+K87+K212+K330+K336+K463 -> 1
A26: 2 | B26: 1 | F26: Servicios Personales | G26: =+G27+G51+G64+G71+G78 -> 1.9856074e+08 | H26: =+H27+H51+H64+H71+H78 -> 5231553.6 | I26: =+I27+I51+I64+I71+I78 -> 0 | J26: =SUM(G26:I26) -> 2.0379229e+08 | K26: =J26/$J$25 -> 0.68369498
A27: 2 | B27: 1 | C27: 1 | F27: Remuneraciones | G27: =+G28+G35+G42+G44+G46 -> 1.639452e+08 | H27: =+H28+H35+H42+H44+H46 -> 0 | I27: =+I28+I35+I42+I44+I46 -> 0 | J27: =SUM(G27:I27) -> 1.639452e+08 | K27: =J27/$J$25 -> 0.55001351
A28: 2 | B28: 1 | C28: 1 | D28: 1 | F28: Remuneraciones al personal fijo | G28: =SUM(G29:G34) -> 1.5943449e+08 | H28: =SUM(H29:H34) -> 0 | I28: =SUM(I29:I34) -> 0 | J28: =SUM(G28:I28) -> 1.5943449e+08 | K28: =J28/$J$25 -> 0.53488069
A29: 2 | B29: 1 | C29: 1 | D29: 1 | E29: 01 | F29: Sueldos a empleados fijos | G29: =+'MARZO 2025'!G29+'FEBRERO 2025'!G29+'ENERO 2025'!G29 -> 1.5943449e+08 | H29: =+'MARZO 2025'!H29+'FEBRERO 2025'!H29+'ENERO 2025'!H29 -> 0 | I29: 0 | J29: =SUM(G29:I29) -> 1.5943449e+08 | K29: =J29/$J$25 -> 0.53488069
A30: 2 | B30: 1 | C30: 1 | D30: 1 | E30: 02 | F30: Sueldos a médicos | G30: =+'MARZO 2025'!G30+'FEBRERO 2025'!G30+'ENERO 2025'!G30 -> 0 | H30: =+'MARZO 2025'!H30+'FEBRERO 2025'!H30+'ENERO 2025'!H30 -> 0 | I30: 0 | J30: =SUM(G30:I30) -> 0 | K30: =J30/$J$25 -> 0
A31: 2 | B31: 1 | C31: 1 | D31: 1 | E31: 03 | F31: Ascensos a militares | G31: =+'MARZO 2025'!G31+'FEBRERO 2025'!G31+'ENERO 2025'!G31 -> 0 | H31: =+'MARZO 2025'!H31+'FEBRERO 2025'!H31+'ENERO 2025'!H31 -> 0 | I31: 0 | J31: =SUM(G31:I31) -> 0 | K31: =J31/$J$25 -> 0
A32: 2 | B32: 1 | C32: 1 | D32: 1 | E32: 04 | F32: Nuevas plazas maestros | G32: =+'MARZO 2025'!G32+'FEBRERO 2025'!G32+'ENERO 2025'!G32 -> 0 | H32: =+'MARZO 2025'!H32+'FEBRERO 2025'!H32+'ENERO 2025'!H32 -> 0 | I32: 0 | J32: =SUM(G32:I32) -> 0 | K32: =J32/$J$25 -> 0
A33: 2 | B33: 1 | C33: 1 | D33: 1 | E33: 05 | F33: Incentivos y escalafón | G33: =+'MARZO 2025'!G33+'FEBRERO 2025'!G33+'ENERO 2025'!G33 -> 0 | H33: =+'MARZO 2025'!H33+'FEBRERO 2025'!H33+'ENERO 2025'!H33 -> 0 | I33: 0 | J33: =SUM(G33:I33) -> 0 | K33: =J33/$J$25 -> 0
A34: 2 | B34: 1 | C34: 1 | D34: 1 | E34: 06 | F34: Nuevas plazas a médicos | G34: =+'MARZO 2025'!G34+'FEBRERO 2025'!G34+'ENERO 2025'!G34 -> 0 | H34: =+'MARZO 2025'!H34+'FEBRERO 2025'!H34+'ENERO 2025'!H34 -> 0 | I34: 0 | J34: =SUM(G34:I34) -> 0 | K34: =J34/$J$25 -> 0
A35: 2 | B35: 1 | C35: 1 | D35: 2 | F35: Remuneraciones al personal con carácter transitorio | G35: =+'MARZO 2025'!G35+'FEBRERO 2025'!G35+'ENERO 2025'!G35 -> 3177593.1 | H35: =+'MARZO 2025'!H35+'FEBRERO 2025'!H35+'ENERO 2025'!H35 -> 0 | I35: 0 | J35: =SUM(G35:I35) -> 3177593.1
A36: 2 | B36: 1 | C36: 1 | D36: 2 | E36: 03 | F36: Suplencias | G36: =+'MARZO 2025'!G36+'FEBRERO 2025'!G36+'ENERO 2025'!G36 -> 0 | H36: =+'MARZO 2025'!H36+'FEBRERO 2025'!H36+'ENERO 2025'!H36 -> 0 | I36: 0 | J36: =SUM(G36:I36) -> 0 | K36: =J36/$J$25 -> 0
A37: 2 | B37: 1 | C37: 1 | D37: 2 | E37: 05 | F37: Sueldo al personal nominal en período probatorio | G37: =+'MARZO 2025'!G37+'FEBRERO 2025'!G37+'ENERO 2025'!G37 -> 0 | H37: =+'MARZO 2025'!H37+'FEBRERO 2025'!H37+'ENERO 2025'!H37 -> 0 | I37: 0 | J37: =SUM(G37:I37) -> 0 | K37: =J37/$J$25 -> 0
A38: 2 | B38: 1 | C38: 1 | D38: 2 | E38: 06 | F38: Jornales | G38: =+'MARZO 2025'!G38+'FEBRERO 2025'!G38+'ENERO 2025'!G38 -> 0 | H38: =+'MARZO 2025'!H38+'FEBRERO 2025'!H38+'ENERO 2025'!H38 -> 0 | I38: 0 | J38: =SUM(G38:I38) -> 0 | K38: =J38/$J$25 -> 0
A39: 2 | B39: 1 | C39: 1 | D39: 2 | E39: 08 | F39: Empleados temporales | G39: =+'MARZO 2025'!G39+'FEBRERO 2025'!G39+'ENERO 2025'!G39 -> 3177593.1 | H39: =+'MARZO 2025'!H39+'FEBRERO 2025'!H39+'ENERO 2025'!H39 -> 0 | I39: 0 | J39: =SUM(G39:I39) -> 3177593.1 | K39: =J39/$J$25 -> 0.010660386
A40: 2 | B40: 1 | C40: 1 | D40: 2 | E40: 09 | F40: Personal de carácter eventual | G40: =+'MARZO 2025'!G40+'FEBRERO 2025'!G40+'ENERO 2025'!G40 -> 0 | H40: =+'MARZO 2025'!H40+'FEBRERO 2025'!H40+'ENERO 2025'!H40 -> 0 | I40: 0 | J40: =SUM(G40:I40) -> 0 | K40: =J40/$J$25 -> 0
A41: 2 | B41: 1 | C41: 1 | D41: 2 | E41: 11 | F41: Interinato | G41: =+'MARZO 2025'!G41+'FEBRERO 2025'!G41+'ENERO 2025'!G41 -> 0 | H41: =+'MARZO 2025'!H41+'FEBRERO 2025'!H41+'ENERO 2025'!H41 -> 0 | I41: 0 | J41: =SUM(G41:I41) -> 0 | K41: =J41/$J$25 -> 0
A42: 2 | B42: 1 | C42: 1 | D42: 3 | F42: Sueldos al personal fijo en trámite de pensiones | G42: =+'MARZO 2025'!G42+'FEBRERO 2025'!G42+'ENERO 2025'!G42 -> 0 | H42: =+'MARZO 2025'!H42+'FEBRERO 2025'!H42+'ENERO 2025'!H42 -> 0 | I42: 0 | J42: =SUM(G42:I42) -> 0
...

Sheet BIMENSUAL
A1: Form. No.6 SRS
A3: Servicio Nacional de Salud
A4: Dirección de Fizcalización
A5: Consolidado de Ingresos y Gastos por Fuente de Financiamiento
A6: HOSPITAL MATERNO INFANTIL SAN LORENZO DE LOS MINA
A7: TRIMESTRE ENERO-MARZO 2025
C8: Ingresos Generales:
E9: 1.- Balance Inicial / Fuente:
E10: Anticipo Financiero | G10: 0 | H10: Otros Aportes | M10: Contraseña: 0001
E11: Transferencias Corrientes | G11: 0
E12: Venta de Servicios | G12: =+'ENERO 2025'!G12 -> 2244994.1
E13: 2.- Ingresos por Fuente / Cuenta
E14: Anticipo Financiero | H14: Otros Aportes | J14: =+'MARZO 2025'!I14+'FEBRERO 2025'!I14+'ENERO 2025'!J14 -> 15987098 | M14: OBJETAL | N14: FR | O14: VS
E15: Transferencias Corrientes | G15: =+'MARZO 2025'!G15+'FEBRERO 2025'!G15 -> 2.0063359e+08 | H15: Aportes Nomina SNS | J15: =+'MARZO 2025'!I15+'FEBRERO 2025'!I15+'ENERO 2025'!J15 -> 84553322 | M15: 2.1 | N15: =G26 -> 1.3222312e+08 | O15: =H26 -> 0
E16: Venta de Servicios | G16: =+'MARZO 2025'!G16+'FEBRERO 2025'!G16+'ENERO 2025'!G16 -> 23406786 | M16: 2.2 | N16: =G87 -> 1336968.6 | O16: =H87 -> 3947227.6
H17: TOTAL INGRESOS RDS | J17: =+G10+G11+G12+J10+G14+G15+G16+J14+J15 -> 3.2682579e+08 | M17: 2.3 | N17: ='[3]CONS. FUENTES FINAN'!G212 -> 4970601.2 | O17: ='[3]CONS. FUENTES FINAN'!H212 -> 3062630.7
M18: 2.4 | N18: =G330 -> 0 | O18: =H330 -> 160366.7
M19: 2.6 | N19: =G336 -> 6461017.3 | O19: =H336 -> 4775504.8
M20: 2.7 | N20: ='[3]CONS. FUENTES FINAN'!G463 -> 0 | O20: ='[3]CONS. FUENTES FINAN'!H463 -> 0
A21: 1 | F21: 2 | G21: 3 | J21: 4 | K21: 5
A22: Código Presupuestario | F22: Descripción Gasto por Cuenta | G22: Distribución del Gasto por Fuente de Financiamiento | J22: TOTAL | K22: %
A23: Tipo | B23: Objeto | C23: Cuenta | D23: Sub-Cuenta | E23: Auxiliar | G23: Fondo 100 | H23: Venta de Servicios/ Otros Aportes | I23: Aportes Nomina SNS
A25: 2 | F25: Gastos | G25: =+G26+G87+G212+G330+G336+G463 -> 1.5942483e+08 | H25: =+H26+H87+H212+H330+H336+H463 -> 14378108 | I25: =+I26+I87+I212+I330+I336+I463 -> 0 | J25: =+G25+H25 -> 1.7380294e+08 | K25: =+K26+K87+K212+K330+K336+K463 -> 1
A26: 2 | B26: 1 | F26: Servicios Personales | G26: =+G27+G51+G64+G71+G78 -> 1.3222312e+08 | H26: =+H27+H51+H64+H71+H78 -> 0 | J26: =+G26+H26 -> 1.3222312e+08 | K26: =J26/$J$25 -> 0.76076454
A27: 2 | B27: 1 | C27: 1 | F27: Remuneraciones | G27: =+G28+G35+G42+G44+G46 -> 1.0922647e+08 | H27: =+H28+H35+H42+H44+H46 -> 0 | J27: =+G27+H27 -> 1.0922647e+08 | K27: =J27/$J$25 -> 0.62845005
A28: 2 | B28: 1 | C28: 1 | D28: 1 | F28: Remuneraciones al personal fijo | G28: =SUM(G29:G34) -> 1.0582329e+08 | H28: =SUM(H29:H34) -> 0 | J28: =+G28+H28 -> 1.0582329e+08 | K28: =J28/$J$25 -> 0.60886935
A29: 2 | B29: 1 | C29: 1 | D29: 1 | E29: 01 | F29: Sueldos a empleados fijos | G29: =+'ENERO 2025'!G29+'FEBRERO 2025'!G29 -> 1.0582329e+08 | H29: =+'ENERO 2025'!H29+'FEBRERO 2025'!H29 -> 0 | J29: =+G29+H29 -> 1.0582329e+08 | K29: =J29/$J$25 -> 0.60886935
A30: 2 | B30: 1 | C30: 1 | D30: 1 | E30: 02 | F30: Sueldos a médicos | G30: =+'ENERO 2025'!G30+'FEBRERO 2025'!G30 -> 0 | H30: =+'ENERO 2025'!H30+'FEBRERO 2025'!H30 -> 0 | J30: =+G30+H30 -> 0 | K30: =J30/$J$25 -> 0
A31: 2 | B31: 1 | C31: 1 | D31: 1 | E31: 03 | F31: Ascensos a militares | G31: =+'ENERO 2025'!G31+'FEBRERO 2025'!G31 -> 0 | H31: =+'ENERO 2025'!H31+'FEBRERO 2025'!H31 -> 0 | J31: =+G31+H31 -> 0 | K31: =J31/$J$25 -> 0
A32: 2 | B32: 1 | C32: 1 | D32: 1 | E32: 04 | F32: Nuevas plazas maestros | G32: =+'ENERO 2025'!G32+'FEBRERO 2025'!G32 -> 0 | H32: =+'ENERO 2025'!H32+'FEBRERO 2025'!H32 -> 0 | J32: =+G32+H32 -> 0 | K32: =J32/$J$25 -> 0
A33: 2 | B33: 1 | C33: 1 | D33: 1 | E33: 05 | F33: Incentivos y escalafón | G33: =+'ENERO 2025'!G33+'FEBRERO 2025'!G33 -> 0 | H33: =+'ENERO 2025'!H33+'FEBRERO 2025'!H33 -> 0 | J33: =+G33+H33 -> 0 | K33: =J33/$J$25 -> 0
A34: 2 | B34: 1 | C34: 1 | D34: 1 | E34: 06 | F34: Nuevas plazas a médicos | G34: =+'ENERO 2025'!G34+'FEBRERO 2025'!G34 -> 0 | H34: =+'ENERO 2025'!H34+'FEBRERO 2025'!H34 -> 0 | J34: =+G34+H34 -> 0 | K34: =J34/$J$25 -> 0
A35: 2 | B35: 1 | C35: 1 | D35: 2 | F35: Remuneraciones al personal con carácter transitorio | G35: =+'ENERO 2025'!G35+'FEBRERO 2025'!G35 -> 2070062.1 | H35: =+'ENERO 2025'!H35+'FEBRERO 2025'!H35 -> 0 | J35: =+G35+H35 -> 2070062.1
A36: 2 | B36: 1 | C36: 1 | D36: 2 | E36: 03 | F36: Suplencias | G36: =+'ENERO 2025'!G36+'FEBRERO 2025'!G36 -> 0 | H36: =+'ENERO 2025'!H36+'FEBRERO 2025'!H36 -> 0 | J36: =+G36+H36 -> 0 | K36: =J36/$J$25 -> 0
A37: 2 | B37: 1 | C37: 1 | D37: 2 | E37: 05 | F37: Sueldo al personal nominal en período probatorio | G37: =+'ENERO 2025'!G37+'FEBRERO 2025'!G37 -> 0 | H37: =+'ENERO 2025'!H37+'FEBRERO 2025'!H37 -> 0 | J37: =+G37+H37 -> 0 | K37: =J37/$J$25 -> 0
A38: 2 | B38: 1 | C38: 1 | D38: 2 | E38: 06 | F38: Jornales | G38: =+'ENERO 2025'!G38+'FEBRERO 2025'!G38 -> 0 | H38: =+'ENERO 2025'!H38+'FEBRERO 2025'!H38 -> 0 | J38: =+G38+H38 -> 0 | K38: =J38/$J$25 -> 0
A39: 2 | B39: 1 | C39: 1 | D39: 2 | E39: 08 | F39: Empleados temporales | G39: =+'ENERO 2025'!G39+'FEBRERO 2025'!G39 -> 2070062.1 | H39: =+'ENERO 2025'!H39+'FEBRERO 2025'!H39 -> 0 | J39: =+G39+H39 -> 2070062.1 | K39: =J39/$J$25 -> 0.011910397
A40: 2 | B40: 1 | C40: 1 | D40: 2 | E40: 09 | F40: Personal de carácter eventual | G40: =+'ENERO 2025'!G40+'FEBRERO 2025'!G40 -> 0 | H40: =+'ENERO 2025'!H40+'FEBRERO 2025'!H40 -> 0 | J40: =+G40+H40 -> 0 | K40: =J40/$J$25 -> 0
A41: 2 | B41: 1 | C41: 1 | D41: 2 | E41: 11 | F41: Interinato | G41: =+'ENERO 2025'!G41+'FEBRERO 2025'!G41 -> 0 | H41: =+'ENERO 2025'!H41+'FEBRERO 2025'!H41 -> 0 | J41: =+G41+H41 -> 0 | K41: =J41/$J$25 -> 0
A42: 2 | B42: 1 | C42: 1 | D42: 3 | F42: Sueldos al personal fijo en trámite de pensiones | G42: =+'ENERO 2025'!G42+'FEBRERO 2025'!G42 -> 0 | H42: =+'ENERO 2025'!H42+'FEBRERO 2025'!H42 -> 0 | J42: =+G42+H42 -> 0
...
