Workbook

Sheet RELACION CHEQUES EMITIDOS
A5: DIRECCION DE FISCALIZACION Y CONTROL
A6: RELACION DE LIBRAMIENTOS/CHEQUES/ TRANSFERENCIAS EMITIDOS DURANTE EL MES ENERO 2025
A7: ESTABLECIMIENTO: HOSPITAL MATERNO INFANTIL SAN LORENZO DE LOS MINA
A8: CORRESPONDIENTES AL MES : ENERO 2025
A9: FECHA | B9: LIBRAMIENTO | C9: TRANSFERENCIA | D9: CHEQUE | E9: BENEFICIARIO | F9: NO.FACTURAS | G9: VALOR DE FACTURA | H9: VALOR PAGADO
A10: 45667 | C10: TRANSF. 001 | E10: EQMAPHAR, SRL | F10: PAGO DE FACT NCF NO. B1500000006, POR ADQUISICION DE CALENTADORES PARA PACIENTES Y MANTAS TERMICAS NEONATALES, SEGÚN ORDEN DE COMPRA HSLM-2024-01349 | G10: 1129894.8 | H10: 1082017.9
A11: 45667 | C11: TRANSF. 002 | E11: LEHAIM SUMINISTROS, SRL | F11: PAGO DE FACT NCF NO. B1500000004, POR ADQUISICION DE MEDICAMENTOS, SEGÚN ORDEN DE COMPRA HSLM-2024-01377 | G11: 258000 | H11: 245100
A12: 45670 | C12: TRANSF. 003 | E12: GRAFISOL, SRL | F12: APORTE ECONOMICO PARA LA REVISTA MEDICA CIENTIFICA | G12: 100000 | H12: 100000
A13: 45670 | C13: TRANSF. 004 | E13: FARMACO QUIMICA NACIONAL S.A | F13: COMPRA DE VALVULA HIDROCEFALICA PARA RN INGRESADO EN EL HOSPITAL. | G13: 30166.7 | H13: 30166.7
A14: 45671 | C14: TRANSF. 005 | E14: CENTRO DE ESTUDIOS MEDICOS Y DIAGNOSTICOS POR IMÁGENES, SRL | F14: PAGO DE FACT NCF B1500000352, POR SERVICIOS DE ESTUDIOS ESPECIALIZADOS A PACIENTES INTERNOS SEGÚN O/C 2024-000116 | G14: 10100 | H14: 9595
A15: 45671 | C15: TRANSF. 006 | E15: TONER DEPOT MULTISERVICIOS EORG, SRL | F15: PAGO DE FACT NCF NO. B1500008206, POR PAGO DE SERVICIOS DE IMPRESIÓN O/C 2024-00767 | G15: 266664.26 | H15: 255364.93
A16: 45671 | C16: TRANSF. 007 | E16: AYUNTAMIENTO SANTO DOMINGO ESTE | F16: PAGO DE FACT B1500054922 Y B1500055023, POR SERVICIO DE RECOGIDA DE DESECHOS SOLIDOS | G16: 50000 | H16: 50000
A17: 45671 | C17: TRANSF. 008 | E17: LABORATORIO CLINICO LICDA PATRIA RIVAS, SRL | F17: PAGO DE FACT NCF NO. B1500002239, POR SERVICIO DE PRUEBAS ESPECIALES A PACIENTES INTERNOS, SEGÚN O/C 2024-00107 | G17: 17740 | H17: 16853
A18: 45671 | C18: TRANSF. 009 | E18: PLANETA AZUL | F18: PAGO DE FACT E4500006333, E4500006338, E4500006340, E4500007753, E4500006344, POR ADQUISICIONES DE BOTELLONES DE AGUA SEGÚN ORDEN DE COMPRA 2024-00796 | G18: 37740 | H18: 37740
A19: 45671 | C19: TRANSF. 010 | E19: TROPIGAS, SRL | F19: PAGO DE FACT NCF E4500005333 Y E450000005343, POR ADQUISICON DE GLP, SEGÚN ORDEN DE COMPRA 2024-00326 | G19: 49512.84 | H19: 49512.84
A20: 45672 | C20: TRANSF. 011 | E20: PRODUCTOS CANO SRL | F20: PAGO NCF B1500001242 ADQUISICION DE PAN SEGÚN O/C HSLM-2024-00631 | G20: 98115 | H20: 93209.25
A21: 45672 | C21: TRANSF. 012 | E21: BIO WIN SRL | F21: PAGO NCF B1500002379, B1500002382, B1500002083, B1500002090. ADQUISICION DE SANGRE DE CARNERO SEGÚN O/C HSLM-2024-00988. | G21: 6900 | H21: 6555
... A37: 45687 | C37: TRANSF. 028 | E37: SUED & FARGESA, SRL | F37: PAGO DE FACT NCF NO. E45000001159, POR ADQUISICION DE UNA GRAPADORA MAS 1 CARTUCHO DE GRAPAS AJUSTABLES DE 55MM | G37: 47176.05 | H37: 45177.07
A38: 22/01/2025 | B38: 4 | E38: HOSPITAL MATERNO INFANTIL SAN LORENZO DE LOS MINAS | F38: HOSANLORE. NOMINA SUELDO TEMPORAL ENERO 2025 | G38: 1123146.4 | H38: 1010139.8 | I38: =+G38-H38 -> 113006.56
A39: 22/01/2025 | B39: 6 | E39: HOSPITAL MATERNO INFANTIL SAN LORENZO DE LOS MINAS | F39: HOSANLORE. NOMINA SUELDO PERSONAL DE VIGILANCIA ENERO 2025 | G39: 45000 | H39: 43452.75 | I39: =+G39-H39 -> 1547.25
A40: 27/01/2025 | B40: 9 | E40: HOSPITAL MATERNO INFANTIL SAN LORENZO DE LOS MINAS | F40: HOSANLORE. NOMINA SUELDO FIJO ENERO 2025 | G40: 63923034 | H40: 42730628 | I40: =+G40-H40 -> 21192406
A41: 31/01/2025 | B41: 16 | E41: Grupo Xeron Medic SRL | F41: pago factura b1500000145 por medicamento orden compa HSLM-2024-01367 | G41: 55550 | H41: 52772.5 | I41: =+G41-H41 -> 2777.5
A42: 31/01/2025 | B42: 23 | E42: Grupo Xeron Medic SRL | F42: PAGO DE FACT NCF B1500000155 POR ADQUISICION DE MEDICAMENTOS SEGUN O/C HSLM-2025-00007. | G42: 252000 | H42: 239400 | I42: =+G42-H42 -> 12600
A43: 31/01/2025 | B43: 25 | E43: Bello-Lab, SRL | F43: Pago de Fact NCF No. B1500001014, por adquisicion de medicamentos, segun orden de compra, HSLM-2024-01400 | G43: 467802 | H43: 447957 | I43: =+G43-H43 -> 19845
A44: 31/01/2025 | B44: 31 | E44: Bello-Lab, SRL | F44: Pago de Fact NCF No. B1500001011, por adquisicion de reactivos, según orden de compra, HSLM-2024-01363 | G44: 332252 | H44: 316538.5 | I44: =+G44-H44 -> 15713.5
A45: 31/01/2025 | B45: 35 | E45: Oficclin Comercial, SRL | F45: Pago de Fact NCF No. B1500000557, por adquisicion de medicamentos, según orden de compra, HSLM-2025-00028 | G45: 271350 | H45: 257782.5 | I45: =+G45-H45 -> 13567.5
A46: 31/01/2025 | B46: 36 | E46: Farmaco Internacional, SRL | F46: PAGO FACTURA NCF B1500000996 POR ADQUISICION DE UTIL MEDICO SEGUN ORDEN DE COMPRA HSLM-2024-0139. | G46: 129664 | H46: 123180.8 | I46: =+G46-H46 -> 6483.2
A47: 31/01/2025 | B47: 43 | E47: CEM Caribbean Equipment Medical, SRL | F47: PAGO DE FACT NCF B1500001096 POR ADQUISICION DE UTILES MEDICOS SEGUN O/C HSLM-2024-01374. | G47: 235971.68 | H47: 225972.88 | I47: =+G47-H47 -> 9998.8
A48: 31/01/2025 | B48: 45 | E48: Socomedi Multisolutions, SRL | F48: PAGO FACTURA NCF B1500000368 POR ADQUISICION DE MEDICAMENTOS SEGUN O/C HSLM-2025-00042. | G48: 240000 | H48: 228000 | I48: =+G48-H48 -> 12000
A49: 31/01/2025 | B49: 49 | E49: Lambda Diagnósticos, SRL | F49: Pago de Fact NCF No. B1500002232, por adquisicion de reactivos, según orden de compra, HSLM-2024-01306 | G49: 703592.61 | H49: 668417.76 | I49: =+G49-H49 -> 35174.85
... A58: 31/01/2025 | B58: 84 | E58: Grupo Xeron Medic SRL | F58: PAGO FACT NCF B1500000157, POR ADQUISICION DE MEDICAMENTOS SEGUN ORDEN DE COMPRA HSLM-2025-00006. | G58: 236000 | H58: 224200 | I58: =+G58-H58 -> 11800
A59: 45660 | D59: 37174 | E59: FREDDY OSCAR RODRIGUEZ RIVAS | F59: COLABORACION PARA CAVACION DE HOYOS Y CERTIFICACION DE ACTAS | G59: 3400 | H59: 3400 | I59: =+G59-H59 -> 0
A60: 45671 | D60: =+D59+1 -> 37175 | E60: DELMIRA GARCIA | F60: REPOSICION DEL FONDO DE CAJA CHICA | G60: 49134.32 | H60: 49134.32 | I60: =+G60-H60 -> 0
A61: 45671 | D61: =+D60+1 -> 37176 | E61: JHONNY CASTILLO SORIANO | F61: PAGO POR SERVICIO DE MANTENIMIENTO MECANICO A LA AMBULANCIA DEL HOSPITAL, SEGÚN O/S 1915 | G61: 23600 | H61: 19600 | I61: =+G61-H61 -> 4000
A62: 45674 | D62: =+D61+1 -> 37177 | E62: OLEGARIO GUERRERO | F62: SERVICIO DE MANTENIMIENTO DE PINTURA AL DEPTO DE SEGURIDAD DEL HOSPITAL | G62: 21673.46 | H62: 18000 | I62: =+G62-H62 -> 3673.46
A63: 45679 | D63: =+D62+1 -> 37178 | E63: ALEXANDER MENDEZ CONTRERAS | F63: PAGO POR MANTENIMIENTO, LIMPIEZA Y CLORIFICACION DE LA CSTERNA DEL HOSPITAL | G63: 18061.22 | H63: 15000 | I63: =+G63-H63 -> 3061.22
A64: 45679 | D64: =+D63+1 -> 37179 | E64: NULO | F64: NULO | G64: 0 | H64: 0 | I64: =+G64-H64 -> 0
A65: 45679 | D65: =+D64+1 -> 37180 | E65: CARLOS ALEJANDRO SANCHEZ ORTEGA | F65: PAGO POR SERVICIO DE MANTENIMIENTO MECANICO A LA AMBULANCIA DEL HOSPITAL, SEGÚN O/S 1918 | G65: 42142.86 | H65: 35000 | I65: =+G65-H65 -> 7142.86
A66: 45679 | D66: =+D65+1 -> 37181 | E66: DELMIRA GARCIA | F66: REPOSICION DEL FONDO DE CAJA CHICA | G66: 50927.38 | H66: 50927.38 | I66: =+G66-H66 -> 0
A67: 45681 | D67: =+D66+1 -> 37182 | E67: NELSON YNFANTE VELAZQUEZ | F67: SERVICIO DE PINTURA PARA DIFERENTES AREA DEL HOSPITAL | G67: 18061.22 | H67: 15000 | I67: =+G67-H67 -> 3061.22
...

Sheet RELACION ORDENES DE COMPRAS
A1: HOSPITAL MATERNO INFANTIL SAN LORENZO DE LOS MINA
A2: ORDENES DE COMPRA MES DE ENERO 2025
A4: Capitulo | B4: Unidad de Compras | C4: Referencia del Proceso | D4: Proceso de Compra | E4: Proceso de Compra Mypyme | F4: Proceso de Compra Mypyme Mujer | G4: Modalidad | H4: Monto | I4: Estado del Procedimiento | J4: Rubro Del Proceso | K4: Descripción Rubro | L4: Empresa Adjudicada | M4: Estado Del Contrato | N4: Cantidad de Contratos | O4: Monto Por Contratos | P4: Tipo de Empresa Adjudicada | Q4: FECHA
A5: DIRECCION CENTRAL DEL SERVICIO NACIONAL DE SALUD | B5: Hospital Materno Infantil San Lorenzo de Los Minas | C5: HSLM-DAF-CD-2025-0001 | D5: ADQUISICION DE TIKETS DE COMBUSTIBLE | E5: No | F5: No | G5: Compras por Debajo del Umbral | H5: 172000 | I5: Adjudicado | J5: 15100000 | K5: Combustibles | L5: Inversiones FH, SRL | N5: 0 | O5: 172000 | P5: Grande | Q5: 45659.458
A6: DIRECCION CENTRAL DEL SERVICIO NACIONAL DE SALUD | B6: Hospital Materno Infantil San Lorenzo de Los Minas | C6: HSLM-DAF-CD-2025-0002 | D6: COMPRA DE EMBUTIDOS | E6: No | F6: No | G6: Compras por Debajo del Umbral | H6: 113000 | I6: Adjudicado | J6: 50130000 | K6: Productos lácteos y huevos | N6: 0 | P6: Grande | Q6: 45659.5
A7: DIRECCION CENTRAL DEL SERVICIO NACIONAL DE SALUD | B7: Hospital Materno Infantil San Lorenzo de Los Minas | C7: HSLM-DAF-CM-2025-0001 | D7: CARNES | E7: No | F7: No | G7: Compras Menores | H7: 573000 | I7: Adjudicado | J7: 50110000 | K7: Productos de carne y aves de corral | L7: Sandry Gomez Rodriguez | M7: Activo | N7: 1 | O7: 572250 | P7: Grande | Q7: 45659.5
A8: DIRECCION CENTRAL DEL SERVICIO NACIONAL DE SALUD | B8: Hospital Materno Infantil San Lorenzo de Los Minas | C8: HSLM-DAF-CM-2025-0002 | D8: ADQUISICION DE VEGETALES | E8: No | F8: No | G8: Compras Menores | H8: 434960 | I8: Adjudicado | J8: 50100000 | K8: Frutos secos | L8: Sandry Gomez Rodriguez | M8: Activo | N8: 1 | O8: 405410 | P8: Grande | Q8: 45659.563
A9: DIRECCION CENTRAL DEL SERVICIO NACIONAL DE SALUD | B9: Hospital Materno Infantil San Lorenzo de Los Minas | C9: HSLM-DAF-CM-2025-0003 | D9: DESPENSA | E9: No | F9: No | G9: Compras Menores | H9: 387750 | I9: Adjudicado | J9: 50190000 | K9: Alimentos preparados y conservados | L9: Distribuidora Latino, SRL | M9: Activo | N9: 2 | O9: 242795 | P9: Grande | Q9: 45659.668
A10: DIRECCION CENTRAL DEL SERVICIO NACIONAL DE SALUD | B10: Hospital Materno Infantil San Lorenzo de Los Minas | C10: HSLM-DAF-CM-2025-0003 | D10: DESPENSA | E10: No | F10: No | G10: Compras Menores | H10: 387750 | I10: Adjudicado | J10: 50190000 | K10: Alimentos preparados y conservados | L10: Diucam Group SRL | M10: Activo | N10: 2 | O10: 473584 | P10: Mipyme Mujer | Q10: 45659.667
A11: DIRECCION CENTRAL DEL SERVICIO NACIONAL DE SALUD | B11: Hospital Materno Infantil San Lorenzo de Los Minas | C11: HSLM-DAF-CD-2025-0003 | D11: SOLUCION SALINO AL 9% DE 1000 ML | E11: No | F11: No | G11: Compras por Debajo del Umbral | H11: 240000 | I11: Adjudicado | J11: 51190000 | K11: Agentes que afectan el agua y los electrolitos | N11: 0 | P11: Grande | Q11: 45660.418
A12: DIRECCION CENTRAL DEL SERVICIO NACIONAL DE SALUD | B12: Hospital Materno Infantil San Lorenzo de Los Minas | C12: HSLM-DAF-CD-2025-0004 | D12: ADQUISICION DE SOLUCION SALINO AL 9% DE 1000 ML Y ESPARADRAPO | E12: No | F12: No | G12: Compras por Debajo del Umbral | H12: 218656 | I12: Adjudicado | J12: 42310000 | K12: Productos para el cuidado de heridas | N12: 0 | P12: Grande | Q12: 45660.438
A13: DIRECCION CENTRAL DEL SERVICIO NACIONAL DE SALUD | B13: Hospital Materno Infantil San Lorenzo de Los Minas | C13: HSLM-DAF-CD-2025-0006 | D13: MISOPROSTOL 200MG | E13: No | F13: No | G13: Compras por Debajo del Umbral | H13: 180000 | I13: Adjudicado | J13: 51170000 | K13: Medicamentos que afectan al sistema gastrointestinal | N13: 0 | P13: Grande | Q13: 45660.542
A14: DIRECCION CENTRAL DEL SERVICIO NACIONAL DE SALUD | B14: Hospital Materno Infantil San Lorenzo de Los Minas | C14: HSLM-DAF-CD-2025-0005 | D14: HALOPERIDOL 5ML AMP | E14: No | F14: No | G14: Compras por Debajo del Umbral | H14: 236000 | I14: Adjudicado | J14: 51140000 | K14: Medicamentos para el sistema nervioso central | N14: 0 | P14: Grande | Q14: 45660.542
A15: DIRECCION CENTRAL DEL SERVICIO NACIONAL DE SALUD | B15: Hospital Materno Infantil San Lorenzo de Los Minas | C15: HSLM-DAF-CD-2025-0007 | D15: SOLUCION SALINO AL 9% DE 100 ML | E15: No | F15: No | G15: Compras por Debajo del Umbral | H15: 240000 | I15: Adjudicado | J15: 51190000 | K15: Agentes que afectan el agua y los electrolitos | N15: 0 | P15: Grande | Q15: 45660.552
A16: DIRECCION CENTRAL DEL SERVICIO NACIONAL DE SALUD | B16: Hospital Materno Infantil San Lorenzo de Los Minas | C16: HSLM-DAF-CD-2025-0008 | D16: ADQUISICION DE GERDEX | E16: No | F16: No | G16: Compras por Debajo del Umbral | H16: 218400 | I16: Adjudicado | J16: 42280000 | K16: Productos para la esterilización médica | N16: 0 | P16: Grande | Q16: 45664.382
A17: DIRECCION CENTRAL DEL SERVICIO NACIONAL DE SALUD | B17: Hospital Materno Infantil San Lorenzo de Los Minas | C17: HSLM-DAF-CM-2025-0004 | D17: ADQUISICION DE DETERGENTE PARA LAVANDERIA | E17: No | F17: No | G17: Compras Menores | H17: 1277300 | I17: Adjudicado | J17: 12160000 | K17: Aditivos | L17: Cabod, EIRL | M17: Activo | N17: 1 | O17: 1507214 | P17: MiPyme | Q17: 45664.417
A18: DIRECCION CENTRAL DEL SERVICIO NACIONAL DE SALUD | B18: Hospital Materno Infantil San Lorenzo de Los Minas | C18: HSLM-DAF-CD-2025-0009 | D18: ADQUISICION DE UTILES MEDICOS, PLACAS Y ELECTRODOS. | E18: No | F18: No | G18: Compras por Debajo del Umbral | H18: 232500 | I18: Adjudicado | J18: 42290000 | K18: Productos quirúrgicos | N18: 0 | P18: Grande | Q18: 45664.458
A19: DIRECCION CENTRAL DEL SERVICIO NACIONAL DE SALUD | B19: Hospital Materno Infantil San Lorenzo de Los Minas | C19: HSLM-DAF-CD-2025-0011 | D19: ADQUISICION DE UTILES MEDICOS, HILO,PAPEL DE SONOGRAFIA Y CINTA AUTOCLAVE. | E19: No | F19: No | G19: Compras por Debajo del Umbral | H19: 246580 | I19: Adjudicado | J19: 42310000 | K19: Productos para el cuidado de heridas | N19: 0 | P19: Grande | Q19: 45664.469
A20: DIRECCION CENTRAL DEL SERVICIO NACIONAL DE SALUD | B20: Hospital Materno Infantil San Lorenzo de Los Minas | C20: HSLM-DAF-CD-2025-0010 | D20: ADQUISICION DE ROLLOS DE PAPEL LABELS ZEBRA 2X1 | E20: No | F20: No | G20: Compras por Debajo del Umbral | H20: 191100 | I20: Adjudicado | J20: 14110000 | K20: Productos de papel | L20: Papelería E. Impresos Crishoan, SRL | M20: Activo | N20: 1 | O20: 226357 | P20: Grande | Q20: 45664.5
A21: DIRECCION CENTRAL DEL SERVICIO NACIONAL DE SALUD | B21: Hospital Materno Infantil San Lorenzo de Los Minas | C21: HSLM-DAF-CM-2025-0005 | D21: MATERIALES DE LIMPIEZA | E21: No | F21: No | G21: Compras Menores | H21: 396660 | I21: Cancelado | J21: 47130000 | K21: Suministros de aseo y limpieza | N21: 0 | P21: Grande | Q21: 45664.5
A22: DIRECCION CENTRAL DEL SERVICIO NACIONAL DE SALUD | B22: Hospital Materno Infantil San Lorenzo de Los Minas | C22: HSLM-DAF-CD-2025-0012 | D22: ADQUISICION DE UTILES MEDICOS, PERITAS NASALES Y ESPARADRAPOS. | E22: No | F22: No | G22: Compras por Debajo del Umbral | H22: 228100 | I22: Adjudicado | J22: 42310000 | K22: Productos para el cuidado de heridas | L22: Global Multi-Pharma Dominicana THM, SRL | M22: Activo | N22: 1 | O22: 269158 | P22: MiPyme | Q22: 45664.504
A23: DIRECCION CENTRAL DEL SERVICIO NACIONAL DE SALUD | B23: Hospital Materno Infantil San Lorenzo de Los Minas | C23: HSLM-DAF-CD-2025-0014 | D23: ADQUISICION DE UTILES MEDICOS, GORRO DE ENFERMERIA AZUL Y APOSITO PEDIATRICO. | E23: No | F23: No | G23: Compras por Debajo del Umbral | H23: 228000 | I23: Adjudicado | J23: 42130000 | K23: Telas y vestidos médicos | N23: 0 | P23: Grande | Q23: 45664.542
A24: DIRECCION CENTRAL DEL SERVICIO NACIONAL DE SALUD | B24: Hospital Materno Infantil San Lorenzo de Los Minas | C24: HSLM-DAF-CD-2025-0013 | D24: LECTOR DE CD | E24: No | F24: No | G24: Compras por Debajo del Umbral | H24: 5500 | I24: Adjudicado | J24: 43210000 | K24: Equipo informático y accesorios | N24: 0 | P24: Grande | Q24: 45664.542
A25: DIRECCION CENTRAL DEL SERVICIO NACIONAL DE SALUD | B25: Hospital Materno Infantil San Lorenzo de Los Minas | C25: HSLM-DAF-CD-2025-0015 | D25: ADQUISICION DE UTILES MEDICOS, TERMOMETRO ORAL Y CUBRE ZAPATOS. | E25: No | F25: No | G25: Compras por Debajo del Umbral | H25: 228300 | I25: Adjudicado | J25: 42180000 | K25: Productos de examen y control del paciente | L25: Global Multi-Pharma Dominicana THM, SRL | M25: Activo | N25: 1 | O25: 269394 | P25: MiPyme | Q25: 45664.552
A26: DIRECCION CENTRAL DEL SERVICIO NACIONAL DE SALUD | B26: Hospital Materno Infantil San Lorenzo de Los Minas | C26: HSLM-DAF-CD-2025-0017 | D26: CONTROL PARA MAQUINA MEDMAY | E26: No | F26: No | G26: Compras por Debajo del Umbral | H26: 15000 | I26: Adjudicado | J26: 41110000 | K26: Instrumentos de medida, observación y ensayo | L26: Bio Nova, SRL | M26: Activo | N26: 1 | O26: 16605 | P26: Grande | Q26: 45665.459
A27: DIRECCION CENTRAL DEL SERVICIO NACIONAL DE SALUD | B27: Hospital Materno Infantil San Lorenzo de Los Minas | C27: HSLM-DAF-CD-2025-0016 | D27: LLAVES | E27: No | F27: No | G27: Compras por Debajo del Umbral | H27: 78800 | I27: Adjudicado | J27: 40140000 | K27: Distribución de fluidos y gas | L27: Medina N Solutions, SRL | M27: Activo | N27: 1 | O27: 128507 | P27: MiPyme | Q27: 45665.501
A28: DIRECCION CENTRAL DEL SERVICIO NACIONAL DE SALUD | B28: Hospital Materno Infantil San Lorenzo de Los Minas | C28: HSLM-DAF-CM-2025-0006 | D28: REACTIVOS EQUIPO F200 | E28: No | F28: No | G28: Compras Menores | H28: 380000 | I28: Adjudicado | J28: 41110000 | K28: Instrumentos de medida, observación y ensayo | L28: Bello-Lab, SRL | M28: Activo | N28: 2 | O28: 9900 | P28: Mipyme Mujer | Q28: 45667.333
A29: DIRECCION CENTRAL DEL SERVICIO NACIONAL DE SALUD | B29: Hospital Materno Infantil San Lorenzo de Los Minas | C29: HSLM-DAF-CM-2025-0006 | D29: REACTIVOS EQUIPO F200 | E29: No | F29: No | G29: Compras Menores | H29: 380000 | I29: Adjudicado | J29: 41110000 | K29: Instrumentos de medida, observación y ensayo | L29: Lambda Diagnósticos, SRL | M29: Activo | N29: 2 | O29: 362162 | P29: Grande | Q29: 45667.333
A30: DIRECCION CENTRAL DEL SERVICIO NACIONAL DE SALUD | B30: Hospital Materno Infantil San Lorenzo de Los Minas | C30: HSLM-DAF-CD-2025-0018 | D30: ADQUISICION DE ACIDO TRANEXAMICO 500MG/5ML AMPOLLA | E30: No | F30: No | G30: Compras por Debajo del Umbral | H30: 240000 | I30: Adjudicado | J30: 51140000 | K30: Medicamentos para el sistema nervioso central | L30: Ronajus Farmaceutica, SRL | M30: Activo | N30: 1 | O30: 240000 | P30: MiPyme | Q30: 45667.438
A31: DIRECCION CENTRAL DEL SERVICIO NACIONAL DE SALUD | B31: Hospital Materno Infantil San Lorenzo de Los Minas | C31: HSLM-DAF-CD-2025-0019 | D31: ADQUISICION DE INSUMOS PARA SER UTILIZADOS POR EL ALMACEN DE FARMACIA | E31: No | F31: No | G31: Compras por Debajo del Umbral | H31: 160000 | I31: Adjudicado | J31: 51140000 | K31: Medicamentos para el sistema nervioso central | L31: Ronajus Farmaceutica, SRL | M31: Activo | N31: 1 | O31: 150005 | P31: MiPyme | Q31: 45667.458
A32: DIRECCION CENTRAL DEL SERVICIO NACIONAL DE SALUD | B32: Hospital Materno Infantil San Lorenzo de Los Minas | C32: HSLM-DAF-CD-2025-0020 | D32: ADQUISICION DE TIRILLAS DE GLUCOMETRO SMARTEST | E32: No | F32: No | G32: Compras por Debajo del Umbral | H32: 220400 | I32: Abierto | J32: 41110000 | K32: Instrumentos de medida, observación y ensayo | N32: 0 | P32: Grande | Q32: 45667.465
A33: DIRECCION CENTRAL DEL SERVICIO NACIONAL DE SALUD | B33: Hospital Materno Infantil San Lorenzo de Los Minas | C33: HSLM-DAF-CM-2025-0007 | D33: INSUMOS PARA LA MAQUINA BS-380 | E33: No | F33: No | G33: Compras Menores | H33: 927000 | I33: Adjudicado | J33: 41100000 | K33: Equipo de laboratorio y científico | L33: Ciencia Tecnología y Consultas, SRL | M33: Activo | N33: 1 | O33: 616702 | P33: Grande | Q33: 45667.5
A34: DIRECCION CENTRAL DEL SERVICIO NACIONAL DE SALUD | B34: Hospital Materno Infantil San Lorenzo de Los Minas | C34: HSLM-DAF-CD-2025-0022 | D34: ADQUISICION DE GUANTES LATEX DE EXAMEN M | E34: No | F34: No | G34: Compras por Debajo del Umbral | H34: 197500 | I34: Adjudicado | J34: 42130000 | K34: Telas y vestidos médicos | L34: Ventas Diversas Farmaceuticas, SRL | M34: Activo | N34: 1 | O34: 233050 | P34: MiPyme | Q34: 45667.51
A35: DIRECCION CENTRAL DEL SERVICIO NACIONAL DE SALUD | B35: Hospital Materno Infantil San Lorenzo de Los Minas | C35: HSLM-DAF-CD-2025-0023 | D35: ADQUISICION DE CEFTRIAXONA 1G | E35: No | F35: No | G35: Compras por Debajo del Umbral | H35: 180000 | I35: Adjudicado | J35: 51100000 | K35: Medicamentos antiinfecciosos | L35: Socomedi Multisolutions, SRL | M35: Activo | N35: 1 | O35: 180000 | P35: Grande | Q35: 45667.531
A36: DIRECCION CENTRAL DEL SERVICIO NACIONAL DE SALUD | B36: Hospital Materno Infantil San Lorenzo de Los Minas | C36: HSLM-DAF-CD-2025-0021 | D36: ADQUISICION DE AGUA OXIGENADA, CLAMP UMBILICAL, HEMOVAC BRAZALETES PEDIATRICOS CATETER JELCO #24 | E36: No | F36: No | G36: Compras por Debajo del Umbral | H36: 164000 | I36: Adjudicado | J36: 51100000 | K36: Medicamentos antiinfecciosos | L36: A&S Importadora Medicas, SRL | M36: Activo | N36: 1 | O36: 178260 | P36: Mipyme Mujer | Q36: 45667.535
A37: DIRECCION CENTRAL DEL SERVICIO NACIONAL DE SALUD | B37: Hospital Materno Infantil San Lorenzo de Los Minas | C37: HSLM-DAF-CM-2025-0008 | D37: REACTIVOS MIUREX | E37: No | F37: No | G37: Compras Menores | H37: 363500 | I37: Adjudicado | J37: 41110000 | K37: Instrumentos de medida, observación y ensayo | L37: Bio Nuclear, SA | M37: Activo | N37: 1 | O37: 91807 | P37: Grande | Q37: 45667.542
A38: DIRECCION CENTRAL DEL SERVICIO NACIONAL DE SALUD | B38: Hospital Materno Infantil San Lorenzo de Los Minas | C38: HSLM-DAF-CD-2025-0024 | D38: LEVETIRACETAM 500 MG | E38: No | F38: No | G38: Compras por Debajo del Umbral | H38: 185400 | I38: Adjudicado | J38: 51140000 | K38: Medicamentos para el sistema nervioso central | L38: Ameriline Pharmaceutical, SRL | M38: Activo | N38: 1 | O38: 185400 | P38: Grande | Q38: 45667.566
A39: DIRECCION CENTRAL DEL SERVICIO NACIONAL DE SALUD | B39: Hospital Materno Infantil San Lorenzo de Los Minas | C39: HSLM-DAF-CD-2025-0025 | D39: ADQUISICION DE CANULAS DE MAYO Y JERINGAS DE 10 CC | E39: No | F39: No | G39: Compras por Debajo del Umbral | H39: 165000 | I39: Adjudicado | J39: 42220000 | K39: Productos para administración intravenosa y arterial | L39: Lehaim Suministros , SRL | M39: Activo | N39: 1 | O39: 264792 | P39: Grande | Q39: 45667.583
A40: DIRECCION CENTRAL DEL SERVICIO NACIONAL DE SALUD | B40: Hospital Materno Infantil San Lorenzo de Los Minas | C40: HSLM-DAF-CD-2025-0026 | D40: ADQUISICION DE PARACETAMOL 1GR | E40: No | F40: No | G40: Compras por Debajo del Umbral | H40: 86700 | I40: Adjudicado | J40: 51140000 | K40: Medicamentos para el sistema nervioso central | L40: Ameriline Pharmaceutical, SRL | M40: Activo | N40: 1 | O40: 86700 | P40: Grande | Q40: 45667.604
A41: DIRECCION CENTRAL DEL SERVICIO NACIONAL DE SALUD | B41: Hospital Materno Infantil San Lorenzo de Los Minas | C41: HSLM-DAF-CD-2025-0027 | D41: CEFTRIAZONA | E41: No | F41: No | G41: Compras por Debajo del Umbral | H41: 234000 | I41: Cancelado | J41: 51100000 | K41: Medicamentos antiinfecciosos | N41: 0 | P41: Grande | Q41: 45667.604
...

Sheet Hoja1

Sheet CONS. FUENTES FINAN
A1: Form. No.6 SRS
A3: Servicio Nacional de Salud
A4: Dirección de Fizcalización
A5: Consolidado de Ingresos y Gastos por Fuente de Financiamiento
A6: HOSPITAL MATERNO INFANTIL SAN LORENZO DE LOS MINA
A7: ENERO 2025
C8: Ingresos Generales:
E9: 1.- Balance Inicial / Fuente:
E10: Anticipo Financiero | G10: 0 | H10: Otros Aportes | M10: Contraseña: 0001
E11: Transferencias Corrientes | G11: 0
E12: Venta de Servicios | G12: 2244994.1
E13: 2.- Ingresos por Fuente / Cuenta
E14: Anticipo Financiero | H14: Otros Aportes | J14: =+'INGRESOS SEGUN ORIGEN'!E8 -> 15763473 | M14: OBJETAL | N14: FR | O14: VS
E15: Transferencias Corrientes | H15: Aportes Nomina SNS | J15: =+'INGRESOS SEGUN ORIGEN'!E7 -> 84553322 | M15: 2.1 | N15: =G26 -> 65091180 | O15: =H26 -> 0
E16: Venta de Servicios | G16: =+'INGRESOS SEGUN ORIGEN'!E26+'INGRESOS SEGUN ORIGEN'!E31 -> 6032481.2 | M16: 2.2 | N16: =G87 -> 0 | O16: =H87 -> 2733844.3
H17: TOTAL INGRESOS RDS | J17: =+G10+G11+G12+J10+G14+G15+G16+J14+J15 -> 1.0859427e+08 | M17: 2.3 | N17: ='CONS. FUENTES FINAN'!G212 -> 4970601.2 | O17: ='CONS. FUENTES FINAN'!H212 -> 3062630.7
M18: 2.4 | N18: =G330 -> 0 | O18: =H330 -> 136966.7
M19: 2.6 | N19: =G336 -> 0 | O19: =H336 -> 887994.84
M20: 2.7 | N20: ='CONS. FUENTES FINAN'!G463 -> 0 | O20: ='CONS. FUENTES FINAN'!H463 -> 0
A21: 1 | F21: 2 | G21: 3 | J21: 4 | K21: 5
A22: Código Presupuestario | F22: Descripción Gasto por Cuenta | G22: Distribución del Gasto por Fuente de Financiamiento | J22: TOTAL | K22: %
A23: Tipo | B23: Objeto | C23: Cuenta | D23: Sub-Cuenta | E23: Auxiliar | G23: Fondo 100 | H23: Venta de Servicios/ Otros Aportes | I23: Aportes Nomina SNS
A25: 2 | F25: Gastos | G25: =+G26+G87+G212+G330+G336+G463 -> 70061781 | H25: =+H26+H87+H212+H330+H336+H463 -> 6821436.5 | I25: =+I26+I87+I212+I330+I336+I463 -> 0 | J25: =SUM(G25:I25) -> 76883218 | K25: =+K26+K87+K212+K330+K336+K463 -> 1
A26: 2 | B26: 1 | F26: Servicios Personales | G26: =+G27+G51+G64+G71+G78 -> 65091180 | H26: =+H27+H51+H64+H71+H78 -> 0 | I26: =+I27+I51+I64+I71+I78 -> 0 | J26: =SUM(G26:I26) -> 65091180 | K26: =J26/$J$25 -> 0.84662404
A27: 2 | B27: 1 | C27: 1 | F27: Remuneraciones | G27: =+G28+G35+G42+G44+G46 -> 53640339 | H27: =+H28+H35+H42+H44+H46 -> 0 | I27: =+I28+I35+I42+I44+I46 -> 0 | J27: =SUM(G27:I27) -> 53640339 | K27: =J27/$J$25 -> 0.69768592
A28: 2 | B28: 1 | C28: 1 | D28: 1 | F28: Remuneraciones al personal fijo | G28: =SUM(G29:G34) -> 52666808 | H28: =SUM(H29:H34) -> 0 | I28: =SUM(I29:I34) -> 0 | J28: =SUM(G28:I28) -> 52666808 | K28: =J28/$J$25 -> 0.68502346
A29: 2 | B29: 1 | C29: 1 | D29: 1 | E29: 01 | F29: Sueldos a empleados fijos | G29: ='CUENTA T FONDO 100'!A288 -> 52666808 | H29: ='CUENTA T VS'!A81 -> 0 | I29: ='CUENTA T NOMINA SNS'!A58 -> 0 | J29: =SUM(G29:I29) -> 52666808 | K29: =J29/$J$25 -> 0.68502346
A30: 2 | B30: 1 | C30: 1 | D30: 1 | E30: 02 | F30: Sueldos a médicos | G30: ='CUENTA T FONDO 100'!B288 -> 0 | H30: ='CUENTA T VS'!B81 -> 0 | I30: ='CUENTA T NOMINA SNS'!B58 -> 0 | J30: =SUM(G30:I30) -> 0 | K30: =J30/$J$25 -> 0
A31: 2 | B31: 1 | C31: 1 | D31: 1 | E31: 03 | F31: Ascensos a militares | G31: ='CUENTA T FONDO 100'!C288 -> 0 | H31: ='CUENTA T VS'!C81 -> 0 | I31: ='CUENTA T NOMINA SNS'!C58 -> 0 | J31: =SUM(G31:I31) -> 0 | K31: =J31/$J$25 -> 0
A32: 2 | B32: 1 | C32: 1 | D32: 1 | E32: 04 | F32: Nuevas plazas maestros | G32: ='CUENTA T FONDO 100'!D288 -> 0 | H32: ='CUENTA T VS'!D81 -> 0 | I32: ='CUENTA T NOMINA SNS'!D58 -> 0 | J32: =SUM(G32:I32) -> 0 | K32: =J32/$J$25 -> 0
A33: 2 | B33: 1 | C33: 1 | D33: 1 | E33: 05 | F33: Incentivos y escalafón | G33: ='CUENTA T FONDO 100'!E288 -> 0 | H33: ='CUENTA T VS'!E81 -> 0 | I33: ='CUENTA T NOMINA SNS'!E58 -> 0 | J33: =SUM(G33:I33) -> 0 | K33: =J33/$J$25 -> 0
A34: 2 | B34: 1 | C34: 1 | D34: 1 | E34: 06 | F34: Nuevas plazas a médicos | G34: ='CUENTA T FONDO 100'!F288 -> 0 | H34: ='CUENTA T VS'!F81 -> 0 | I34: ='CUENTA T NOMINA SNS'!F58 -> 0 | J34: =SUM(G34:I34) -> 0 | K34: =J34/$J$25 -> 0
A35: 2 | B35: 1 | C35: 1 | D35: 2 | F35: Remuneraciones al personal con carácter transitorio | G35: =SUM(G36:G41) -> 973531.03 | H35: =SUM(H36:H41) -> 0 | I35: =SUM(I36:I41) -> 0 | J35: =SUM(G35:I35) -> 973531.03
A36: 2 | B36: 1 | C36: 1 | D36: 2 | E36: 03 | F36: Suplencias | G36: ='CUENTA T FONDO 100'!G288 -> 0 | H36: ='CUENTA T VS'!G81 -> 0 | I36: ='CUENTA T NOMINA SNS'!G58 -> 0 | J36: =SUM(G36:I36) -> 0 | K36: =J36/$J$25 -> 0
A37: 2 | B37: 1 | C37: 1 | D37: 2 | E37: 05 | F37: Sueldo al personal nominal en período probatorio | G37: ='CUENTA T FONDO 100'!H288 -> 0 | H37: ='CUENTA T VS'!H81 -> 0 | I37: ='CUENTA T NOMINA SNS'!H58 -> 0 | J37: =SUM(G37:I37) -> 0 | K37: =J37/$J$25 -> 0
A38: 2 | B38: 1 | C38: 1 | D38: 2 | E38: 06 | F38: Jornales | G38: ='CUENTA T FONDO 100'!I288 -> 0 | H38: ='CUENTA T VS'!I81 -> 0 | I38: ='CUENTA T NOMINA SNS'!I58 -> 0 | J38: =SUM(G38:I38) -> 0 | K38: =J38/$J$25 -> 0
A39: 2 | B39: 1 | C39: 1 | D39: 2 | E39: 08 | F39: Empleados temporales | G39: ='CUENTA T FONDO 100'!J288 -> 973531.03 | H39: ='CUENTA T VS'!J81 -> 0 | I39: ='CUENTA T NOMINA SNS'!J58 -> 0 | J39: =SUM(G39:I39) -> 973531.03 | K39: =J39/$J$25 -> 0.012662465
A40: 2 | B40: 1 | C40: 1 | D40: 2 | E40: 09 | F40: Personal de carácter eventual | G40: ='CUENTA T FONDO 100'!K288 -> 0 | H40: ='CUENTA T VS'!K81 -> 0 | I40: ='CUENTA T NOMINA SNS'!K58 -> 0 | J40: =SUM(G40:I40) -> 0 | K40: =J40/$J$25 -> 0
A41: 2 | B41: 1 | C41: 1 | D41: 2 | E41: 11 | F41: Interinato | G41: ='CUENTA T FONDO 100'!L288 -> 0 | H41: ='CUENTA T VS'!L81 -> 0 | I41: ='CUENTA T NOMINA SNS'!L58 -> 0 | J41: =SUM(G41:I41) -> 0 | K41: =J41/$J$25 -> 0
A42: 2 | B42: 1 | C42: 1 | D42: 3 | F42: Sueldos al personal fijo en trámite de pensiones | G42: =SUM(G43) -> 0 | H42: =SUM(H43) -> 0 | I42: =SUM(I43) -> 0 | J42: =SUM(G42:I42) -> 0
...

Sheet CUENTA T FONDO 100
A1: D E S G L O S E D E L A S C U E N T A S
A2: 211101 | B2: 211102 | C2: 211103 | D2: 211104 | E2: 211105 | F2: 211106 | G2: 211203 | H2: 211205 | I2: 211206 | J2: 211208 | K2: 211209 | L2: 211211 | M2: 211301 | N2: 211401 | O2: 211501 | P2: 211502 | Q2: 211503 | R2: 211504 | S2: 212101 | T2: 212201 | U2: 212203 | V2: 212204 | W2: 212205 | X2: 212206 | Y2: 212207 | Z2: 212208 | AA2: 212209 | AB2: 212210 | AC2: 213101 | AD2: 213102 | AE2: 213201 | AF2: 213202 | AG2: 214101 | AH2: 214201 | AI2: 214202 | AJ2: 214203 | AK2: 215101 | AL2: 215201 | AM2: 215301 | AN2: 215401 | AO2: 221101 | AP2: 221201 | AQ2: 221301 | AR2: 221401 | AS2: 221501 | AT2: 221601 | AU2: 221602 | AV2: 221701 | AW2: 221801 | AX2: 222101 | AY2: 222201 | AZ2: 223101 | BA2: 223201 | BB2: 224101 | BC2: 224201 | BD2: 224301 | BE2: 224401 | BF2: 225101 | BG2: 225201 | BH2: 225301 | BI2: 225302 | BJ2: 225303 | BK2: 225304 | BL2: 225305 | BM2: 225401 | BN2: 225501 | BO2: 225601 | BP2: 225701 | BQ2: 225801 | BR2: 225901 | BS2: 226101 | BT2: 226201 | BU2: 226301 | BV2: 226401 | BW2: 227101 | BX2: 227102 | BY2: 227103 | BZ2: 227104 | CA2: 227105 | CB2: 227106 | CC2: 227107 | CD2: 227199 | CE2: 227201 | CF2: 227202 | CG2: 227203 | CH2: 227204 | CI2: 227205 | CJ2: 227206 | CK2: 227207 | CL2: 227208 | CM2: 227299 | CN2: 227301 | CO2: 228101 | CP2: 228201 | CQ2: 228301 | CR2: 228401 | CS2: 228501 | CT2: 228502 | CU2: 228503 | CV2: 228601 | CW2: 228602 | CX2: 228603 | CY2: 228604 | CZ2: 228701 | DA2: 228702 | DB2: 228703 | DC2: 228704 | DD2: 228705 | DE2: 228706 | DF2: 228801 | DG2: 228802 | DH2: 228803 | DI2: 229201 | DJ2: 229203 | DK2: 231101 | DL2: 231102 | DM2: 231201 | DN2: 231301 | DO2: 231302 | DP2: 231303 | DQ2: 231401 | DR2: 232101 | DS2: 232201 | DT2: 232301 | DU2: 233101 | DV2: 233201 | DW2: 233301 | DX2: 233401 | DY2: 233501 | DZ2: 233601 | EA2: 234101 | EB2: 234201 | EC2: 235101 | ED2: 235201 | EE2: 235301 | EF2: 235401 | EG2: 235501 | EH2: 236101 | EI2: 236102 | EJ2: 236103 | EK2: 236104 | EL2: 236105 | EM2: 236201 | EN2: 236202 | EO2: 236203 | EP2: 236304 | EQ2: 236305 | ER2: 236306 | ES2: 236401 | ET2: 236402 | EU2: 236403 | EV2: 236404 | EW2: 236405 | EX2: 236406 | EY2: 236407 | EZ2: 236901 | FA2: 237101 | FB2: 237102 | FC2: 237103 | FD2: 237104 | FE2: 237105 | FF2: 237106 | FG2: 237107 | FH2: 237201 | FI2: 237202 | FJ2: 237203 | FK2: 237204 | FL2: 237205 | FM2: 237206 | FN2: 237299 | FO2: 238101 | FP2: 238201 | FQ2: 239101 | FR2: 239102 | FS2: 239201 | FT2: 239301 | FU2: 239401 | FV2: 239501 | FW2: 239601 | FX2: 239701 | FY2: 239801 | FZ2: 239802 | GA2: 239901 | GB2: 239904 | GC2: 241201 | GD2: 241202 | GE2: 241203 | GF2: 241204 | GG2: 241205 | GH2: 261101 | GI2: 261201 | GJ2: 261301 | GK2: 261401 | GL2: 261901 | GM2: 262101 | GN2: 262201 | GO2: 262301 | GP2: 262401 | GQ2: 263101 | GR2: 263201 | GS2: 263301 | GT2: 263401 | GU2: 264101 | GV2: 264201 | GW2: 264301 | GX2: 264401 | GY2: 264501 | GZ2: 264601 | HA2: 264701 | HB2: 264801 | HC2: 265101 | HD2: 265201 | HE2: 265301 | HF2: 265401 | HG2: 265501 | HH2: 265601 | HI2: 265701 | HJ2: 265801 | HK2: 266101 | HL2: 266201 | HM2: 267101 | HN2: 267201 | HO2: 267301 | HP2: 267401 | HQ2: 267501 | HR2: 267601 | HS2: 267701 | HT2: 267801 | HU2: 267901 | HV2: 268101 | HW2: 268201 | HX2: 268301 | HY2: 268302 | HZ2: 268401 | IA2: 268501 | IB2: 268601 | IC2: 268701 | ID2: 268802 | IE2: 268803 | IF2: 268804 | IG2: 268901 | IH2: 269101 | II2: 269102 | IJ2: 269201 | IK2: 269202 | IL2: 269301 | IM2: 269401 | IN2: 269501 | IO2: 269502 | IP2: 269503 | IQ2: 2269901 | IR2: 271101 | IS2: 271201 | IT2: 271301 | IU2: 271401 | IV2: 272101 | IW2: 272201 | IX2: 272301 | IY2: 272401 | IZ2: 272501 | JA2: 272601 | JB2: 272701 | JC2: 272801 | JD2: 272901 | JE2: 273101 | JF2: 273201 | JG2: 274101 | JH2: 274201 | JI2: Totales | JJ2: LIBRAMIENTO | JK2: VALOR | JL2: RETENCION | JM2: AÑOS ANTERIORES | JN2: 2024 | JO2: Total | JP2: Proveedor Informal
JI3: =SUM(A3:JH3) -> 0 | JJ3: 5642 | JK3: =+JI3-JL3 -> 0
JI4: =SUM(A4:JH4) -> 0 | JJ4: 5646 | JK4: =+JI4-JL4 -> 0
JI5: =SUM(A5:JH5) -> 0 | JJ5: 5650 | JK5: =+JI5-JL5 -> 0
JI6: =SUM(A6:JH6) -> 0 | JJ6: 5654 | JK6: =+JI6-JL6 -> 0
JI7: =SUM(A7:JH7) -> 0 | JJ7: 5670 | JK7: =+JI7-JL7 -> 0
JI8: =SUM(A8:JH8) -> 0 | JJ8: 5671 | JK8: =+JI8-JL8 -> 0
JI9: =SUM(A9:JH9) -> 0 | JJ9: 5675 | JK9: =+JI9-JL9 -> 0
JI10: =SUM(A10:JH10) -> 0 | JJ10: 5680 | JK10: =+JI10-JL10 -> 0
JI11: =SUM(A11:JH11) -> 0 | JJ11: 5682 | JK11: =+JI11-JL11 -> 0
JI12: =SUM(A12:JH12) -> 0 | JJ12: 5683 | JK12: =+JI12-JL12 -> 0
JI13: =SUM(A13:JH13) -> 0 | JJ13: 5687 | JK13: =+JI13-JL13 -> 0
JI14: =SUM(A14:JH14) -> 0 | JJ14: 5691 | JK14: =+JI14-JL14 -> 0
... JI127: =SUM(A127:JH127) -> 0 | JJ127: 6312 | JK127: =+JI127-JL127 -> 0
JI128: =SUM(A128:JH128) -> 0 | JJ128: 6316 | JK128: =+JI128-JL128 -> 0 | JM128: =SUM(JM3:JM59) -> 0 | JN128: =SUM(JN3:JN59) -> 0 | JO128: =SUM(JO3:JO59) -> 0 | JP128: =SUM(JP3:JP59) -> 0
JI129: =SUM(A129:JH129) -> 0 | JJ129: 6322 | JK129: =+JI129-JL129 -> 0
JI130: =SUM(A130:JH130) -> 0 | JJ130: 6326 | JK130: =+JI130-JL130 -> 0
JI131: =SUM(A131:JH131) -> 0 | JJ131: 6330 | JK131: =+JI131-JL131 -> 0
JI132: =SUM(A132:JH132) -> 0 | JJ132: 6332 | JK132: =+JI132-JL132 -> 0
JI133: =SUM(A133:JH133) -> 0 | JJ133: 6344 | JK133: =+JI133-JL133 -> 0
JI134: =SUM(A134:JH134) -> 0 | JJ134: 6346 | JK134: =+JI134-JL134 -> 0
JI135: =SUM(A135:JH135) -> 0 | JJ135: 6355 | JK135: =+JI135-JL135 -> 0
JI136: =SUM(A136:JH136) -> 0 | JJ136: 6359 | JK136: =+JI136-JL136 -> 0
JI137: =SUM(A137:JH137) -> 0 | JJ137: 6361 | JK137: =+JI137-JL137 -> 0
JI138: =SUM(A138:JH138) -> 0 | JJ138: 6363 | JK138: =+JI138-JL138 -> 0
JI139: =SUM(A139:JH139) -> 0 | JJ139: 6369 | JK139: =+JI139-JL139 -> 0
JI140: =SUM(A140:JH140) -> 0 | JJ140: 6370 | JK140: =+JI140-JL140 -> 0
... JI165: =SUM(A165:JH165) -> 0 | JJ165: 6474 | JK165: =+JI165-JL165 -> 0
J166: 973531.03 | AK166: 69023.35 | AL166: 69120.7 | AM166: 11471.29 | JI166: =SUM(A166:JH166) -> 1123146.4 | JJ166: 6478 | JK166: =+JI166-JL166 -> 1123146.4
W167: 45000 | JI167: =SUM(A167:JH167) -> 45000 | JJ167: 6482 | JK167: =+JI167-JL167 -> 45000
A168: 52666808 | S168: 2752136.5 | W168: . | Z168: 330200 | AB168: =10717.4+58945.7 -> 69663.1 | AK168: 3734078.9 | AL168: 3739343.8 | AM168: 630803.53 | JI168: =SUM(A168:JH168) -> 63923034 | JJ168: 6486 | JK168: =+JI168-JL168 -> 63923034
EA169: 55550 | JI169: =SUM(A169:JH169) -> 55550 | JJ169: 6492 | JK169: =+JI169-JL169 -> 55550
EA170: 252000 | JI170: =SUM(A170:JH170) -> 252000 | JJ170: 6496 | JK170: =+JI170-JL170 -> 252000
FJ171: 467802 | JI171: =SUM(A171:JH171) -> 467802 | JJ171: 6500 | JK171: =+JI171-JL171 -> 467802
FJ172: 332252 | JI172: =SUM(A172:JH172) -> 332252 | JJ172: 6504 | JK172: =+JI172-JL172 -> 332252
EA173: 271350 | JI173: =SUM(A173:JH173) -> 271350 | JJ173: 6516 | JK173: =+JI173-JL173 -> 271350
FT174: 129664 | JI174: =SUM(A174:JH174) -> 129664 | JJ174: 6523 | JK174: =+JI174-JL174 -> 129664
FT175: 235971.68 | JI175: =SUM(A175:JH175) -> 235971.68 | JJ175: 6524 | JK175: =+JI175-JL175 -> 235971.68
EA176: 240000 | JI176: =SUM(A176:JH176) -> 240000 | JJ176: 6530 | JK176: =+JI176-JL176 -> 240000
...

Sheet CUENTA T VS
A1: D E S G L O S E D E L A S C U E N T A S
A2: 211101 | B2: 211102 | C2: 211103 | D2: 211104 | E2: 211105 | F2: 211106 | G2: 211203 | H2: 211205 | I2: 211206 | J2: 211208 | K2: 211209 | L2: 211211 | M2: 211301 | N2: 211401 | O2: 211501 | P2: 211502 | Q2: 211503 | R2: 211504 | S2: 212101 | T2: 212201 | U2: 212203 | V2: 212204 | W2: 212205 | X2: 212206 | Y2: 212207 | Z2: 212208 | AA2: 212209 | AB2: 212210 | AC2: 213101 | AD2: 213102 | AE2: 213201 | AF2: 213202 | AG2: 214101 | AH2: 214201 | AI2: 214202 | AJ2: 214203 | AK2: 215101 | AL2: 215201 | AM2: 215301 | AN2: 215401 | AO2: 221101 | AP2: 221201 | AQ2: 221301 | AR2: 221401 | AS2: 221501 | AT2: 221601 | AU2: 221602 | AV2: 221701 | AW2: 221801 | AX2: 222101 | AY2: 222201 | AZ2: 223101 | BA2: 223201 | BB2: 224101 | BC2: 224201 | BD2: 224301 | BE2: 224401 | BF2: 225101 | BG2: 225201 | BH2: 225301 | BI2: 225302 | BJ2: 225303 | BK2: 225304 | BL2: 225305 | BM2: 225401 | BN2: 225501 | BO2: 225601 | BP2: 225701 | BQ2: 225801 | BR2: 225901 | BS2: 226101 | BT2: 226201 | BU2: 226301 | BV2: 226401 | BW2: 227101 | BX2: 227102 | BY2: 227103 | BZ2: 227104 | CA2: 227105 | CB2: 227106 | CC2: 227107 | CD2: 227199 | CE2: 227201 | CF2: 227202 | CG2: 227203 | CH2: 227204 | CI2: 227205 | CJ2: 227206 | CK2: 227207 | CL2: 227208 | CM2: 227299 | CN2: 227301 | CO2: 228101 | CP2: 228201 | CQ2: 228301 | CR2: 228401 | CS2: 228501 | CT2: 228502 | CU2: 228503 | CV2: 228601 | CW2: 228602 | CX2: 228603 | CY2: 228604 | CZ2: 228701 | DA2: 228702 | DB2: 228703 | DC2: 228704 | DD2: 228705 | DE2: 228706 | DF2: 228801 | DG2: 228802 | DH2: 228803 | DI2: 229201 | DJ2: 229203 | DK2: 231101 | DL2: 231102 | DM2: 231201 | DN2: 231301 | DO2: 231302 | DP2: 231303 | DQ2: 231401 | DR2: 232101 | DS2: 232201 | DT2: 232301 | DU2: 233101 | DV2: 233201 | DW2: 233301 | DX2: 233401 | DY2: 233501 | DZ2: 233601 | EA2: 234101 | EB2: 234201 | EC2: 235101 | ED2: 235201 | EE2: 235301 | EF2: 235401 | EG2: 235501 | EH2: 236101 | EI2: 236102 | EJ2: 236103 | EK2: 236104 | EL2: 236105 | EM2: 236201 | EN2: 236202 | EO2: 236203 | EP2: 236304 | EQ2: 236305 | ER2: 236306 | ES2: 236401 | ET2: 236402 | EU2: 236403 | EV2: 236404 | EW2: 236405 | EX2: 236406 | EY2: 236407 | EZ2: 236901 | FA2: 237101 | FB2: 237102 | FC2: 237103 | FD2: 237104 | FE2: 237105 | FF2: 237106 | FG2: 237107 | FH2: 237201 | FI2: 237202 | FJ2: 237203 | FK2: 237204 | FL2: 237205 | FM2: 237206 | FN2: 237299 | FO2: 238101 | FP2: 238201 | FQ2: 239101 | FR2: 239102 | FS2: 239201 | FT2: 239301 | FU2: 239401 | FV2: 239501 | FW2: 239601 | FX2: 239701 | FY2: 239801 | FZ2: 239802 | GA2: 239901 | GB2: 239904 | GC2: 241201 | GD2: 241202 | GE2: 241203 | GF2: 241204 | GG2: 241205 | GH2: 261101 | GI2: 261201 | GJ2: 261301 | GK2: 261401 | GL2: 261901 | GM2: 262101 | GN2: 262201 | GO2: 262301 | GP2: 262401 | GQ2: 263101 | GR2: 263201 | GS2: 263301 | GT2: 263401 | GU2: 264101 | GV2: 264201 | GW2: 264301 | GX2: 264401 | GY2: 264501 | GZ2: 264601 | HA2: 264701 | HB2: 264801 | HC2: 265101 | HD2: 265201 | HE2: 265301 | HF2: 265401 | HG2: 265501 | HH2: 265601 | HI2: 265701 | HJ2: 265801 | HK2: 266101 | HL2: 266201 | HM2: 267101 | HN2: 267201 | HO2: 267301 | HP2: 267401 | HQ2: 267501 | HR2: 267601 | HS2: 267701 | HT2: 267801 | HU2: 267901 | HV2: 268101 | HW2: 268201 | HX2: 268301 | HY2: 268302 | HZ2: 268401 | IA2: 268501 | IB2: 268601 | IC2: 268701 | ID2: 268802 | IE2: 268803 | IF2: 268804 | IG2: 268901 | IH2: 269101 | II2: 269102 | IJ2: 269201 | IK2: 269202 | IL2: 269301 | IM2: 269401 | IN2: 269501 | IO2: 269502 | IP2: 269503 | IQ2: 2269901 | IR2: 271101 | IS2: 271201 | IT2: 271301 | IU2: 271401 | IV2: 272101 | IW2: 272201 | IX2: 272301 | IY2: 272401 | IZ2: 272501 | JA2: 272601 | JB2: 272701 | JC2: 272801 | JD2: 272901 | JE2: 273101 | JF2: 273201 | JG2: 274101 | JH2: 274201 | JI2: Totales | JJ2: TRANSF NO. | JK2: VALOR | JL2: RETENCION | JM2: AÑOS ANTERIORES | JN2: 2024 | JO2: Total | JP2: Proveedor Informal
FT3: 241900 | GQ3: 887994.84 | JI3: =SUM(A3:JH3) -> 1129894.8 | JJ3: TRANSF. 001 | JK3: 1082017.9 | JL3: =+JI3-JK3 -> 47876.9
EA4: 258000 | JI4: =SUM(A4:JH4) -> 258000 | JJ4: TRANSF. 002 | JK4: 245100 | JL4: =+JI4-JK4 -> 12900
GD5: 100000 | JI5: =SUM(A5:JH5) -> 100000 | JJ5: TRANSF. 003 | JK5: 100000 | JL5: =+JI5-JK5 -> 0
GD6: 30166.7 | JI6: =SUM(A6:JH6) -> 30166.7 | JJ6: TRANSF. 004 | JK6: 30166.7 | JL6: =+JI6-JK6 -> 0
DE7: 10100 | JI7: =SUM(A7:JH7) -> 10100 | JJ7: TRANSF. 005 | JK7: 9595 | JL7: =+JI7-JK7 -> 505
BI8: 266664.26 | JI8: =SUM(A8:JH8) -> 266664.26 | JJ8: TRANSF. 006 | JK8: 255364.93 | JL8: =+JI8-JK8 -> 11299.33
AW9: 50000 | JI9: =SUM(A9:JH9) -> 50000 | JJ9: TRANSF. 007 | JK9: 50000 | JL9: =+JI9-JK9 -> 0
DE10: 17740 | JI10: =SUM(A10:JH10) -> 17740 | JJ10: TRANSF. 008 | JK10: 16853 | JL10: =+JI10-JK10 -> 887
DK11: 37740 | JI11: =SUM(A11:JH11) -> 37740 | JJ11: TRANSF. 009 | JK11: 37740 | JL11: =+JI11-JK11 -> 0
FD12: 49512.84 | JI12: =SUM(A12:JH12) -> 49512.84 | JJ12: TRANSF. 010 | JK12: 49512.84 | JL12: =+JI12-JK12 -> 0
DK13: 98115 | JI13: =SUM(A13:JH13) -> 98115 | JJ13: TRANSF. 011 | JK13: 93209.25 | JL13: =+JI13-JK13 -> 4905.75
FJ14: 6900 | JI14: =SUM(A14:JH14) -> 6900 | JJ14: TRANSF. 012 | JK14: 6555 | JL14: =+JI14-JK14 -> 345
EA15: 50000 | JI15: =SUM(A15:JH15) -> 50000 | JJ15: TRANSF. 013 | JK15: 47500 | JL15: =+JI15-JK15 -> 2500
AQ16: 91518.64 | JI16: =SUM(A16:JH16) -> 91518.64 | JJ16: TRANSF. 014 | JK16: 91518.64 | JL16: =+JI16-JK16 -> 0
AQ17: 209797.69 | JI17: =SUM(A17:JH17) -> 209797.69 | JJ17: TRANSF. 015 | JK17: 209797.69 | JL17: =+JI17-JK17 -> 0
DW18: 29500 | JI18: =SUM(A18:JH18) -> 29500 | JJ18: TRANSF. 016 | JK18: 28250 | JL18: =+JI18-JK18 -> 1250
DW19: 56050 | JI19: =SUM(A19:JH19) -> 56050 | JJ19: TRANSF. 017 | JK19: 53675 | JL19: =+JI19-JK19 -> 2375
FT20: 684400 | JI20: =SUM(A20:JH20) -> 684400 | JJ20: TRANSF. 018 | JK20: 655400 | JL20: =+JI20-JK20 -> 29000
CU21: 10148 | JI21: =SUM(A21:JH21) -> 10148 | JJ21: TRANSF. 019 | JK21: 9718 | JL21: =+JI21-JK21 -> 430
FA22: 172000 | JI22: =SUM(A22:JH22) -> 172000 | JJ22: TRANSF. 020 | JK22: 170573.26 | JL22: =+JI22-JK22 -> 1426.74
CH23: 1888000 | JI23: =SUM(A23:JH23) -> 1888000 | JJ23: TRANSF. 021 | JK23: 1808000 | JL23: =+JI23-JK23 -> 80000
FT24: 192288.08 | JI24: =SUM(A24:JH24) -> 192288.08 | JJ24: TRANSF. 022 | JK24: 184140.28 | JL24: =+JI24-JK24 -> 8147.8
FT25: 69915 | JI25: =SUM(A25:JH25) -> 69915 | JJ25: TRANSF. 023 | JK25: 66952.5 | JL25: =+JI25-JK25 -> 2962.5
FT26: 269394 | JI26: =SUM(A26:JH26) -> 269394 | JJ26: TRANSF. 024 | JK26: 257979 | JL26: =+JI26-JK26 -> 11415
FT27: 269158 | JI27: =SUM(A27:JH27) -> 269158 | JJ27: TRANSF. 025 | JK27: 257753 | JL27: =+JI27-JK27 -> 11405
FT28: 25110 | JI28: =SUM(A28:JH28) -> 25110 | JJ28: TRANSF. 026 | JK28: 25110 | JL28: =+JI28-JK28 -> 0
DK29: 405410 | JI29: =SUM(A29:JH29) -> 405410 | JJ29: TRANSF. 027 | JK29: 385139.5 | JL29: =+JI29-JK29 -> 20270.5
FT30: 47176.05 | JI30: =SUM(A30:JH30) -> 47176.05 | JJ30: TRANSF. 028 | JK30: 45177.07 | JL30: =+JI30-JK30 -> 1998.98
GC31: 3400 | JI31: =SUM(A31:JH31) -> 3400 | JJ31: 37174 | JK31: 3400 | JL31: =+JI31-JK31 -> 0
GA32: 49134.32 | JI32: =SUM(A32:JH32) -> 49134.32 | JJ32: 37175 | JK32: 49134.32 | JL32: =+JI32-JK32 -> 0
CJ33: 23600 | JI33: =SUM(A33:JH33) -> 23600 | JJ33: 37176 | JK33: 19600 | JL33: =+JI33-JK33 -> 4000
BW34: 21673.46 | JI34: =SUM(A34:JH34) -> 21673.46 | JJ34: 37177 | JK34: 18000 | JL34: =+JI34-JK34 -> 3673.46
BX35: 18061.22 | JI35: =SUM(A35:JH35) -> 18061.22 | JJ35: 37178 | JK35: 15000 | JL35: =+JI35-JK35 -> 3061.22
JI36: =SUM(A36:JH36) -> 0 | JJ36: 37179 | JK36: 0 | JL36: =+JI36-JK36 -> 0
BX37: 42142.86 | JI37: =SUM(A37:JH37) -> 42142.86 | JJ37: 37180 | JK37: 35000 | JL37: =+JI37-JK37 -> 7142.86
GA38: 50927.38 | JI38: =SUM(A38:JH38) -> 50927.38 | JJ38: 37181 | JK38: 50927.38 | JL38: =+JI38-JK38 -> 0
BX39: 18061.22 | JI39: =SUM(A39:JH39) -> 18061.22 | JJ39: 37182 | JK39: 15000 | JL39: =+JI39-JK39 -> 3061.22
BX40: 21673.47 | JI40: =SUM(A40:JH40) -> 21673.47 | JJ40: 37183 | JK40: 18000 | JL40: =+JI40-JK40 -> 3673.47
...

Sheet CUENTA T NOMINA SNS
A1: D E S G L O S E D E L A S C U E N T A S
A2: 211101 | B2: 211102 | C2: 211103 | D2: 211104 | E2: 211105 | F2: 211106 | G2: 211203 | H2: 211205 | I2: 211206 | J2: 211208 | K2: 211209 | L2: 211211 | M2: 211301 | N2: 211401 | O2: 211501 | P2: 211502 | Q2: 211503 | R2: 211504 | S2: 212101 | T2: 212201 | U2: 212203 | V2: 212204 | W2: 212205 | X2: 212206 | Y2: 212207 | Z2: 212208 | AA2: 212209 | AB2: 212210 | AC2: 213101 | AD2: 213102 | AE2: 213201 | AF2: 213202 | AG2: 214101 | AH2: 214201 | AI2: 214202 | AJ2: 214203 | AK2: 215101 | AL2: 215201 | AM2: 215301 | AN2: 215401 | AO2: Totales
AO3: =SUM(A3:AN3) -> 0
AO4: =SUM(A4:AN4) -> 0
AO5: =SUM(A5:AN5) -> 0
AO6: =SUM(A6:AN6) -> 0
AO7: =SUM(A7:AN7) -> 0
AO8: =SUM(A8:AN8) -> 0
AO9: =SUM(A9:AN9) -> 0
AO10: =SUM(A10:AN10) -> 0
AO11: =SUM(A11:AN11) -> 0
AO12: =SUM(A12:AN12) -> 0
AO13: =SUM(A13:AN13) -> 0
AO14: =SUM(A14:AN14) -> 0
... AO57: =SUM(A57:AN57) -> 0
A58: =SUM(A3:A57) -> 0 | B58: =SUM(B3:B57) -> 0 | C58: =SUM(C3:C57) -> 0 | D58: =SUM(D3:D57) -> 0 | E58: =SUM(E3:E57) -> 0 | F58: =SUM(F3:F57) -> 0 | G58: =SUM(G3:G57) -> 0 | H58: =SUM(H3:H57) -> 0 | ... AO58: =SUM(AO3:AO57) -> 0 | AQ58: 0

Sheet GASTOS X ATENCION
A1: SERVICIO NACIONAL DE SALUD
A2: ='CONS. FUENTES FINAN'!A6 -> HOSPITAL MATERNO INFANTIL SAN LORENZO DE LOS MINA
A3: RESUMEN COMPARATIVO DE GASTOS ESPECIFICOS FONDO 100 Y VENTA DE SERVICIOS
A6: DETALLE | B6: REPONIBLE | C6: VENTA SERVICIOS | D6: TOTAL | E6: %
A8: Atención Directa
A9: Medicamentos e Insumos Médicos | B9: ='CONS. FUENTES FINAN'!G245+'CONS. FUENTES FINAN'!G315 -> 3125937.8 | C9: ='CONS. FUENTES FINAN'!H245+'CONS. FUENTES FINAN'!H315 -> 2107341.1 | D9: =SUM(B9:C9) -> 5233278.9 | E9: =+D9/D12 -> 0.73865849
A10: Oxigeno | B10: ='CONS. FUENTES FINAN'!G302 -> 0 | C10: ='CONS. FUENTES FINAN'!H302 -> 0 | D10: =SUM(B10:C10) -> 0 | E10: =+D10/D12 -> 0
A11: Reactivos e Insumos de Laboratorio | B11: ='CONS. FUENTES FINAN'!G296+'CONS. FUENTES FINAN'!G297+'CONS. FUENTES FINAN'!G298 -> 1844663.4 | C11: ='CONS. FUENTES FINAN'!H296+'CONS. FUENTES FINAN'!H297+'CONS. FUENTES FINAN'!H298 -> 6900 | D11: =SUM(B11:C11) -> 1851563.4 | E11: =+D11/D12 -> 0.26134151
A12: Total | B12: =SUM(B9:B11) -> 4970601.2 | C12: =SUM(C9:C11) -> 2114241.1 | D12: =SUM(D9:D11) -> 7084842.3 | E12: =+D12/D39 -> 0.0921507
A13: Mantenimiento de Equipos
A14: Reparación y Mantenimiento Maquinaria y Eq. | B14: ='CONS. FUENTES FINAN'!G157+'CONS. FUENTES FINAN'!G188+'CONS. FUENTES FINAN'!G223+'CONS. FUENTES FINAN'!G252+'CONS. FUENTES FINAN'!G254+'CONS. FUENTES FINAN'!G256+'CONS. FUENTES FINAN'!G258+'CONS. FUENTES FINAN'!G261+'CONS. FUENTES FINAN'!G292+'CONS. FUENTES FINAN'!G293+'CONS. FUENTES FINAN'!G299+'CONS. FUENTES FINAN'!G300+'CONS. FUENTES FINAN'!G301+'CONS. FUENTES FINAN'!G324 -> 0 | C14: ='CONS. FUENTES FINAN'!H157+'CONS. FUENTES FINAN'!H188+'CONS. FUENTES FINAN'!H223+'CONS. FUENTES FINAN'!H252+'CONS. FUENTES FINAN'!H254+'CONS. FUENTES FINAN'!H256+'CONS. FUENTES FINAN'!H258+'CONS. FUENTES FINAN'!H261+'CONS. FUENTES FINAN'!H292+'CONS. FUENTES FINAN'!H293+'CONS. FUENTES FINAN'!H299+'CONS. FUENTES FINAN'!H300+'CONS. FUENTES FINAN'!H301+'CONS. FUENTES FINAN'!H324 -> 2074666.4 | D14: =SUM(B14:C14) -> 2074666.4 | E14: =+D14/D16 -> 1
A15: Productos Eléctricos y Afines | B15: ='CONS. FUENTES FINAN'!G320 -> 0 | C15: ='CONS. FUENTES FINAN'!H320 -> 0 | D15: =SUM(B15:C15) -> 0 | E15: =+D15/D16 -> 0
A16: Total | B16: =SUM(B14:B15) -> 0 | C16: =SUM(C14:C15) -> 2074666.4 | D16: =SUM(D14:D15) -> 2074666.4 | E16: =+D16/D39 -> 0.026984645
A17: Gastos Administrativos
A18: Servicios Personales | B18: ='CONS. FUENTES FINAN'!G26 -> 65091180 | C18: ='CONS. FUENTES FINAN'!H26 -> 0 | D18: =SUM(B18:C18) -> 65091180 | E18: =+D18/D34 -> 0.97389817
A19: Servicio Telefónico | B19: ='CONS. FUENTES FINAN'!G91+'CONS. FUENTES FINAN'!G93+'CONS. FUENTES FINAN'!G95+'CONS. FUENTES FINAN'!G97 -> 0 | C19: ='CONS. FUENTES FINAN'!H91+'CONS. FUENTES FINAN'!H93+'CONS. FUENTES FINAN'!H95+'CONS. FUENTES FINAN'!H97 -> 301316.33 | D19: =SUM(B19:C19) -> 301316.33 | E19: =+D19/D34 -> 0.0045083132
A20: Servicios Basicos (electricidad, agua y residuos solidos) | B20: ='CONS. FUENTES FINAN'!G99+'CONS. FUENTES FINAN'!G102+'CONS. FUENTES FINAN'!G104 -> 0 | C20: ='CONS. FUENTES FINAN'!H99+'CONS. FUENTES FINAN'!H102+'CONS. FUENTES FINAN'!H104 -> 50000 | D20: =SUM(B20:C20) -> 50000 | E20: =+D20/D34 -> 0.00074810303
A21: Viáticos | B21: ='CONS. FUENTES FINAN'!G111 -> 0 | C21: ='CONS. FUENTES FINAN'!H111 -> 0 | D21: =SUM(B21:C21) -> 0 | E21: =+D21/D34 -> 0
A22: Transporte y almacenaje | B22: ='CONS. FUENTES FINAN'!G116 -> 0 | C22: ='CONS. FUENTES FINAN'!H116 -> 0 | D22: =SUM(B22:C22) -> 0 | E22: =+D22/D34 -> 0
A23: Alquileres | B23: ='CONS. FUENTES FINAN'!G125 -> 0 | C23: ='CONS. FUENTES FINAN'!H125 -> 266664.26 | D23: =SUM(B23:C23) -> 266664.26 | E23: =+D23/D34 -> 0.0039898468
A24: Comisiones y Gastos Bancarios | B24: ='CONS. FUENTES FINAN'!G182 -> 0 | C24: ='CONS. FUENTES FINAN'!H182 -> 13357.35 | D24: =SUM(B24:C24) -> 13357.35 | E24: =+D24/D34 -> 0.00019985348
A25: Materiales de Oficina, Impresión y Encuadernación | B25: ='CONS. FUENTES FINAN'!G109+'CONS. FUENTES FINAN'!G312 -> 0 | C25: ='CONS. FUENTES FINAN'!H109+'CONS. FUENTES FINAN'!H312 -> 0 | D25: =SUM(B25:C25) -> 0 | E25: =+D25/D34 -> 0
A26: Alimentos y Bebidas para Personas | B26: ='CONS. FUENTES FINAN'!G208+'CONS. FUENTES FINAN'!G214+'CONS. FUENTES FINAN'!G217+'CONS. FUENTES FINAN'!G219 -> 0 | C26: ='CONS. FUENTES FINAN'!H208+'CONS. FUENTES FINAN'!H214+'CONS. FUENTES FINAN'!H217+'CONS. FUENTES FINAN'!H219 -> 541265 | D26: =SUM(B26:C26) -> 541265 | E26: =+D26/D34 -> 0.0080984397
A27: Productos de papel, carton e impesos | B27: ='CONS. FUENTES FINAN'!G232 -> 0 | C27: ='CONS. FUENTES FINAN'!H232 -> 85550 | D27: =SUM(B27:C27) -> 85550 | E27: =+D27/D34 -> 0.0012800043
A28: Articulos de Plasticos | B28: ='CONS. FUENTES FINAN'!G259 -> 0 | C28: ='CONS. FUENTES FINAN'!H259 -> 0 | D28: =SUM(B28:C28) -> 0 | E28: =+D28/D34 -> 0
A29: Gasolina | B29: ='CONS. FUENTES FINAN'!G288 -> 0 | C29: ='CONS. FUENTES FINAN'!H288 -> 172000 | D29: =SUM(B29:C29) -> 172000 | E29: =+D29/D34 -> 0.0025734744
A30: Gasoil | B30: ='CONS. FUENTES FINAN'!G289+'CONS. FUENTES FINAN'!G290 -> 0 | C30: ='CONS. FUENTES FINAN'!H289+'CONS. FUENTES FINAN'!H290 -> 0 | D30: =SUM(B30:C30) -> 0 | E30: =+D30/D34 -> 0
A31: GLP | B31: ='CONS. FUENTES FINAN'!G291+'CONS. FUENTES FINAN'!G294 -> 0 | C31: ='CONS. FUENTES FINAN'!H291+'CONS. FUENTES FINAN'!H294 -> 49512.84 | D31: =SUM(B31:C31) -> 49512.84 | E31: =+D31/D34 -> 0.00074081411
A32: Materiales de Limpieza e Higiene | B32: ='CONS. FUENTES FINAN'!G309 -> 0 | C32: ='CONS. FUENTES FINAN'!H309 -> 0 | D32: =SUM(B32:C32) -> 0 | E32: =+D32/D34 -> 0
A33: Otros Egresos y Gastos | B33: ='CONS. FUENTES FINAN'!G89+'CONS. FUENTES FINAN'!G107+'CONS. FUENTES FINAN'!G148+'CONS. FUENTES FINAN'!G180+'CONS. FUENTES FINAN'!G184+'CONS. FUENTES FINAN'!G186+'CONS. FUENTES FINAN'!G192+'CONS. FUENTES FINAN'!G197+'CONS. FUENTES FINAN'!G204+'CONS. FUENTES FINAN'!G225+'CONS. FUENTES FINAN'!G303+'CONS. FUENTES FINAN'!G316+'CONS. FUENTES FINAN'!G318+'CONS. FUENTES FINAN'!G322+'CONS. FUENTES FINAN'!G327+'CONS. FUENTES FINAN'!G330 -> 0 | C33: ='CONS. FUENTES FINAN'!H89+'CONS. FUENTES FINAN'!H107+'CONS. FUENTES FINAN'!H148+'CONS. FUENTES FINAN'!H180+'CONS. FUENTES FINAN'!H184+'CONS. FUENTES FINAN'!H186+'CONS. FUENTES FINAN'!H192+'CONS. FUENTES FINAN'!H197+'CONS. FUENTES FINAN'!H204+'CONS. FUENTES FINAN'!H225+'CONS. FUENTES FINAN'!H303+'CONS. FUENTES FINAN'!H316+'CONS. FUENTES FINAN'!H318+'CONS. FUENTES FINAN'!H322+'CONS. FUENTES FINAN'!H327+'CONS. FUENTES FINAN'!H330 -> 264868.4 | D33: =SUM(B33:C33) -> 264868.4 | E33: =+D33/D34 -> 0.003962977
A34: Total | B34: =SUM(B17:B33) -> 65091180 | C34: =SUM(C17:C33) -> 1744534.2 | D34: =SUM(D17:D33) -> 66835714 | E34: =+D34/D39 -> 0.86931474
A35: Gastos Inversion y Capital
A36: Bienes Muebles, Inmuebles e Intangibles | B36: ='CONS. FUENTES FINAN'!G336 -> 0 | C36: ='CONS. FUENTES FINAN'!H336 -> 887994.84 | D36: =SUM(B36:C36) -> 887994.84 | E36: =+D36/D38 -> 1
A37: Obras | B37: ='CONS. FUENTES FINAN'!G463 -> 0 | C37: ='CONS. FUENTES FINAN'!H463 -> 0 | D37: =SUM(B37:C37) -> 0 | E37: =+D37/D38 -> 0
A38: Total | B38: =SUM(B36:B37) -> 0 | C38: =SUM(C36:C37) -> 887994.84 | D38: =SUM(D36:D37) -> 887994.84 | E38: =+D38/D39 -> 0.011549918
A39: Total General | B39: =+B12+B16+B34+B38 -> 70061781 | C39: =+C12+C16+C34+C38 -> 6821436.5 | D39: =+D12+D16+D34+D38 -> 76883218 | E39: =+E12+E16+E34+E38 -> 1
A40: Porciento | B40: =+B39/D39 -> 0.91127535 | C40: =+C39/D39 -> 0.088724649 | D40: =+B40+C40 -> 1

Sheet PLANTILLA PRESUPUESTO
A1: SERVICIO NACIONAL DE SALUD
A2: NOMBRE DEL ESTABLECIMIENTO
A3: CONSOLIDADO GASTOS EJECUCION FINANCIERA 2024
A4: En RD$
A6: Detalle | B6: FONDO GENERAL 100 | G6: VENTA SEVICIOS/OTROS APORTES | L6: TOTAL
A7: 2 - GASTOS | B7: 1ro | C7: 2do | D7: 3ro | E7: 4to | G7: 1ro | H7: 2do | I7: 3ro | J7: 4to | L7: 1ro | M7: 2do | N7: 3ro | O7: 4to
A8: 2.1 - REMUNERACIONES Y CONTRIBUCIONES | B8: =SUM(B9:B13) -> 65091180 | C8: =SUM(C9:C13) -> 0 | D8: =SUM(D9:D13) -> 0 | E8: =SUM(E9:E13) -> 0 | G8: =SUM(G9:G13) -> 0 | H8: =SUM(H9:H13) -> 0 | I8: =SUM(I9:I13) -> 0 | J8: =SUM(J9:J13) -> 0 | L8: =SUM(B8+G8) -> 65091180 | M8: =SUM(C8+H8) -> 0 | N8: =SUM(D8+I8) -> 0 | O8: =SUM(E8+J8) -> 0
A9: 2.1.1 - REMUNERACIONES | B9: =SUM('TRANSFERENCIA CORRIENTE'!C10:E10) -> 53640339 | C9: =SUM('TRANSFERENCIA CORRIENTE'!F10:H10) -> 0 | D9: =SUM('TRANSFERENCIA CORRIENTE'!I10:K10) -> 0 | E9: =SUM('TRANSFERENCIA CORRIENTE'!L10:N10) -> 0 | G9: =SUM(VS!C10:E10) -> 0 | H9: =SUM(VS!F10:H10) -> 0 | I9: =SUM(VS!I10:K10) -> 0 | J9: =SUM(VS!L10:N10) -> 0 | L9: =SUM(B9+G9) -> 53640339 | M9: =SUM(C9+H9) -> 0 | N9: =SUM(D9+I9) -> 0 | O9: =SUM(E9+J9) -> 0
A10: 2.1.2 - SOBRESUELDOS | B10: =SUM('TRANSFERENCIA CORRIENTE'!C11:E11) -> 3196999.6 | C10: =SUM('TRANSFERENCIA CORRIENTE'!F11:H11) -> 0 | D10: =SUM('TRANSFERENCIA CORRIENTE'!I11:K11) -> 0 | E10: =SUM('TRANSFERENCIA CORRIENTE'!L11:N11) -> 0 | G10: =SUM(VS!C11:E11) -> 0 | H10: =SUM(VS!F11:H11) -> 0 | I10: =SUM(VS!I11:K11) -> 0 | J10: =SUM(VS!L11:N11) -> 0 | L10: =SUM(B10+G10) -> 3196999.6 | M10: =SUM(C10+H10) -> 0 | N10: =SUM(D10+I10) -> 0 | O10: =SUM(E10+J10) -> 0
A11: 2.1.3 - DIETAS Y GASTOS DE REPRESENTACIÓN | B11: =SUM('TRANSFERENCIA CORRIENTE'!C12:E12) -> 0 | C11: =SUM('TRANSFERENCIA CORRIENTE'!F12:H12) -> 0 | D11: =SUM('TRANSFERENCIA CORRIENTE'!I12:K12) -> 0 | E11: =SUM('TRANSFERENCIA CORRIENTE'!L12:N12) -> 0 | G11: =SUM(VS!C12:E12) -> 0 | H11: =SUM(VS!F12:H12) -> 0 | I11: =SUM(VS!I12:K12) -> 0 | J11: =SUM(VS!L12:N12) -> 0 | L11: =SUM(B11+G11) -> 0 | M11: =SUM(C11+H11) -> 0 | N11: =SUM(D11+I11) -> 0 | O11: =SUM(E11+J11) -> 0
A12: 2.1.4 - GRATIFICACIONES Y BONIFICACIONES | B12: =SUM('TRANSFERENCIA CORRIENTE'!C13:E13) -> 0 | C12: =SUM('TRANSFERENCIA CORRIENTE'!F13:H13) -> 0 | D12: =SUM('TRANSFERENCIA CORRIENTE'!I13:K13) -> 0 | E12: =SUM('TRANSFERENCIA CORRIENTE'!L13:N13) -> 0 | G12: =SUM(VS!C13:E13) -> 0 | H12: =SUM(VS!F13:H13) -> 0 | I12: =SUM(VS!I13:K13) -> 0 | J12: =SUM(VS!L13:N13) -> 0 | L12: =SUM(B12+G12) -> 0 | M12: =SUM(C12+H12) -> 0 | N12: =SUM(D12+I12) -> 0 | O12: =SUM(E12+J12) -> 0
A13: 2.1.5 - CONTRIBUCIONES A LA SEGURIDAD SOCIAL | B13: =SUM('TRANSFERENCIA CORRIENTE'!C14:E14) -> 8253841.6 | C13: =SUM('TRANSFERENCIA CORRIENTE'!F14:H14) -> 0 | D13: =SUM('TRANSFERENCIA CORRIENTE'!I14:K14) -> 0 | E13: =SUM('TRANSFERENCIA CORRIENTE'!L14:N14) -> 0 | G13: =SUM(VS!C14:E14) -> 0 | H13: =SUM(VS!F14:H14) -> 0 | I13: =SUM(VS!I14:K14) -> 0 | J13: =SUM(VS!L14:N14) -> 0 | L13: =SUM(B13+G13) -> 8253841.6 | M13: =SUM(C13+H13) -> 0 | N13: =SUM(D13+I13) -> 0 | O13: =SUM(E13+J13) -> 0
A14: 2.2 - CONTRATACIÓN DE SERVICIOS | B14: =SUM(B15:B23) -> 0 | C14: =SUM(C15:C23) -> 0 | D14: =SUM(D15:D23) -> 0 | E14: =SUM(E15:E23) -> 0 | G14: =SUM(G15:G23) -> 2733844.3 | H14: =SUM(H15:H23) -> 0 | I14: =SUM(I15:I23) -> 0 | J14: =SUM(J15:J23) -> 0 | L14: =SUM(B14+G14) -> 2733844.3 | M14: =SUM(C14+H14) -> 0 | N14: =SUM(D14+I14) -> 0 | O14: =SUM(E14+J14) -> 0
A15: 2.2.1 - SERVICIOS BÁSICOS | B15: =SUM('TRANSFERENCIA CORRIENTE'!C16:E16) -> 0 | C15: =SUM('TRANSFERENCIA CORRIENTE'!F16:H16) -> 0 | D15: =SUM('TRANSFERENCIA CORRIENTE'!J16:L16) -> 0 | E15: =SUM('TRANSFERENCIA CORRIENTE'!L16:N16) -> 0 | G15: =SUM(VS!C16:E16) -> 351316.33 | H15: =SUM(VS!F16:H16) -> 0 | I15: =SUM(VS!I16:K16) -> 0 | J15: =SUM(VS!L16:N16) -> 0 | L15: =SUM(B15+G15) -> 351316.33 | M15: =SUM(C15+H15) -> 0 | N15: =SUM(D15+I15) -> 0 | O15: =SUM(E15+J15) -> 0
A16: 2.2.2 - PUBLICIDAD, IMPRESIÓN Y ENCUADERNACIÓN | B16: =SUM('TRANSFERENCIA CORRIENTE'!C17:E17) -> 0 | C16: =SUM('TRANSFERENCIA CORRIENTE'!F17:H17) -> 0 | D16: =SUM('TRANSFERENCIA CORRIENTE'!J17:L17) -> 0 | E16: =SUM('TRANSFERENCIA CORRIENTE'!L17:N17) -> 0 | G16: =SUM(VS!C17:E17) -> 0 | H16: =SUM(VS!F17:H17) -> 0 | I16: =SUM(VS!I17:K17) -> 0 | J16: =SUM(VS!L17:N17) -> 0 | L16: =SUM(B16+G16) -> 0 | M16: =SUM(C16+H16) -> 0 | N16: =SUM(D16+I16) -> 0 | O16: =SUM(E16+J16) -> 0
A17: 2.2.3 - VIÁTICOS | B17: =SUM('TRANSFERENCIA CORRIENTE'!C18:E18) -> 0 | C17: =SUM('TRANSFERENCIA CORRIENTE'!F18:H18) -> 0 | D17: =SUM('TRANSFERENCIA CORRIENTE'!J18:L18) -> 0 | E17: =SUM('TRANSFERENCIA CORRIENTE'!L18:N18) -> 0 | G17: =SUM(VS!C18:E18) -> 0 | H17: =SUM(VS!F18:H18) -> 0 | I17: =SUM(VS!I18:K18) -> 0 | J17: =SUM(VS!L18:N18) -> 0 | L17: =SUM(B17+G17) -> 0 | M17: =SUM(C17+H17) -> 0 | N17: =SUM(D17+I17) -> 0 | O17: =SUM(E17+J17) -> 0
A18: 2.2.4 - TRANSPORTE Y ALMACENAJE | B18: =SUM('TRANSFERENCIA CORRIENTE'!C19:E19) -> 0 | C18: =SUM('TRANSFERENCIA CORRIENTE'!F19:H19) -> 0 | D18: =SUM('TRANSFERENCIA CORRIENTE'!J19:L19) -> 0 | E18: =SUM('TRANSFERENCIA CORRIENTE'!L19:N19) -> 0 | G18: =SUM(VS!C19:E19) -> 0 | H18: =SUM(VS!F19:H19) -> 0 | I18: =SUM(VS!I19:K19) -> 0 | J18: =SUM(VS!L19:N19) -> 0 | L18: =SUM(B18+G18) -> 0 | M18: =SUM(C18+H18) -> 0 | N18: =SUM(D18+I18) -> 0 | O18: =SUM(E18+J18) -> 0
A19: 2.2.5 - ALQUILERES Y RENTAS | B19: =SUM('TRANSFERENCIA CORRIENTE'!C20:E20) -> 0 | C19: =SUM('TRANSFERENCIA CORRIENTE'!F20:H20) -> 0 | D19: =SUM('TRANSFERENCIA CORRIENTE'!J20:L20) -> 0 | E19: =SUM('TRANSFERENCIA CORRIENTE'!L20:N20) -> 0 | G19: =SUM(VS!C20:E20) -> 266664.26 | H19: =SUM(VS!F20:H20) -> 0 | I19: =SUM(VS!I20:K20) -> 0 | J19: =SUM(VS!L20:N20) -> 0 | L19: =SUM(B19+G19) -> 266664.26 | M19: =SUM(C19+H19) -> 0 | N19: =SUM(D19+I19) -> 0 | O19: =SUM(E19+J19) -> 0
A20: 2.2.6 - SEGUROS | B20: =SUM('TRANSFERENCIA CORRIENTE'!C21:E21) -> 0 | C20: =SUM('TRANSFERENCIA CORRIENTE'!F21:H21) -> 0 | D20: =SUM('TRANSFERENCIA CORRIENTE'!J21:L21) -> 0 | E20: =SUM('TRANSFERENCIA CORRIENTE'!L21:N21) -> 0 | G20: =SUM(VS!C21:E21) -> 0 | H20: =SUM(VS!F21:H21) -> 0 | I20: =SUM(VS!I21:K21) -> 0 | J20: =SUM(VS!L21:N21) -> 0 | L20: =SUM(B20+G20) -> 0 | M20: =SUM(C20+H20) -> 0 | N20: =SUM(D20+I20) -> 0 | O20: =SUM(E20+J20) -> 0
A21: 2.2.7 - SERVICIOS DE CONSERVACIÓN, REPARACIONES MENORES E INSTALACIONES TEMPORALES | B21: =SUM('TRANSFERENCIA CORRIENTE'!C22:E22) -> 0 | C21: =SUM('TRANSFERENCIA CORRIENTE'!F22:H22) -> 0 | D21: =SUM('TRANSFERENCIA CORRIENTE'!J22:L22) -> 0 | E21: =SUM('TRANSFERENCIA CORRIENTE'!L22:N22) -> 0 | G21: =SUM(VS!C22:E22) -> 2064518.4 | H21: =SUM(VS!F22:H22) -> 0 | I21: =SUM(VS!I22:K22) -> 0 | J21: =SUM(VS!L22:N22) -> 0 | L21: =SUM(B21+G21) -> 2064518.4 | M21: =SUM(C21+H21) -> 0 | N21: =SUM(D21+I21) -> 0 | O21: =SUM(E21+J21) -> 0
A22: 2.2.8 - OTROS SERVICIOS NO INCLUIDOS EN CONCEPTOS ANTERIORES | B22: =SUM('TRANSFERENCIA CORRIENTE'!C23:E23) -> 0 | C22: =SUM('TRANSFERENCIA CORRIENTE'!F23:H23) -> 0 | D22: =SUM('TRANSFERENCIA CORRIENTE'!J23:L23) -> 0 | E22: =SUM('TRANSFERENCIA CORRIENTE'!L23:N23) -> 0 | G22: =SUM(VS!C23:E23) -> 51345.35 | H22: =SUM(VS!F23:H23) -> 0 | I22: =SUM(VS!I23:K23) -> 0 | J22: =SUM(VS!L23:N23) -> 0 | L22: =SUM(B22+G22) -> 51345.35 | M22: =SUM(C22+H22) -> 0 | N22: =SUM(D22+I22) -> 0 | O22: =SUM(E22+J22) -> 0
