Workbook
Name CodigoActividad: #REF!
Name Insumos: #REF!
Name Insumos: Insumos!$A$540:$A$583
Name Ls_DepartamentosSRS: #REF!
Name Ls_LinesEstategica: #REF!
Name Ls_Medio_Verificacion: #REF!
Name ls_Regiones: #REF!
Name ls_TiposAcciones: #REF!
Name lsAcabadosTextiles: Insumos!$C$2:$C$3
Name lsAireAcondicionado: Insumos!$C$333:$C$334
Name lsAlimentosyBebidas: Insumos!$C$4:$C$23
Name lsArticulosdePlastico: Insumos!$C$24:$C$30
Name lsElectrodomesticos: Insumos!$C$31:$C$35
Name lsEquiposComputos: Insumos!$C$132:$C$136
Name lsEquiposMedicos: Insumos!$C$44:$C$131
Name lsEquiposSeguridad: Insumos!$C$137:$C$138
Name lsEquiposTransporte: Insumos!$C$518:$C$520
Name lsEventosGenerales: Insumos!$C$139:$C$141
Name lsFuentesFinanciamiento: #REF!
Name lsGasoil: Insumos!$C$142:$C$149
Name lsHerramientasMenores: Insumos!$C$150:$C$179
Name lsImpresionyEncuadernacion: Insumos!$C$180
Name lsInsumos: #REF!
Name lsInsumosEquipos: #REF!
Name lsLlantasyNeumaticos: Insumos!$C$181:$C$188
Name lsMantenimiento: Insumos!$C$189:$C$202
Name lsMaterialesdeLimpieza: Insumos!$C$203:$C$217
Name lsMueblesdeAlojamiento: Insumos!$C$218:$C$219
Name lsMueblesdeOficina: Insumos!$C$220:$C$243
Name lsObrasMenoresEdificaciones: Insumos!$C$244
Name lsOtrosEquipos: Insumos!$C$245:$C$248
Name lsPeaje: Insumos!$C$249
Name lsPinturas: Insumos!$C$250:$C$251
Name lsProductosArtesGraficas: Insumos!$C$252:$C$253
Name lsProductosdeCemento: Insumos!$C$254
Name lsProductosdeLoza: Insumos!$C$255:$C$257
Name lsProductosdePapel: Insumos!$C$258:$C$282
Name lsProductosdeVidrio: Insumos!$C$283:$C$287
Name lsProductosElectricos: Insumos!$C$288:$C$309
Name lsProductosMedicinalesH: Insumos!$C$310:$C$328
Name lsProductosMetalicos: Insumos!$C$329
Name lsProductosQuimicos: Insumos!$C$330
Name lsPublicidadyPropaganda: Insumos!$C$331
Name lsServiciosTecnicosProfesionales: Insumos!$C$332
Name lsTelecomunicaciones: Insumos!$C$36:$C$43
Name LsTipoEESS: #REF!
Name lsTipoIntervencion: #REF!
Name lsUtilesdeCocina: Insumos!$C$335:$C$346
Name lsUtilesdeOficina: Insumos!$C$347:$C$475
Name lsUtilesMenoresMQ: Insumos!$C$476:$C$513
Name lsViaticosDP: Insumos!$C$514:$C$517
Name Periodo_POA: #REF!
Name Productos: #REF!
Name Provincias: #REF!

Sheet PPNE1
B1: Plan Operativo Anual
B2: Servicio Nacional de Salud
B3: Dirección de Planificación y Desarrollo | K3: 2025 | L3: 2026 | M3: 2027 | N3: 2028
B4: Programación Insumos por Producto Nivel Especializado | K4: Cibao Norte | L4: Cibao Sur | M4: Cibao Nordeste | N4: Cibao Noroeste | O4: Valdesia | P4: El Valle | Q4: Enriquillo | R4: Yuma | S4: Higüamo | T4: Ozama
B5: Año | C5: 2026
A6: Servicio Regional de Salud: | B6: Cibao Norte
A7: CEAS
A8: Productos Terminales | B8: Unidad de Medida | C8: Meta Lograda Año 2024 | D8: Meta Proyectada a Lograr Año 2025 | E8: Meta Proyectada Año 2026 | F8: Programación Trimestral | K8: Meta Lograda actual periodo Año 2025
F9: 1er. Trimestre | G9: 2do. Trimestre | H9: 3er. Trimestre | I9: 4to. Trimestre
A10: Servicio de Consulta Externa | B10: Consultas | C10: =SUM(C11:C12) -> 184374 | D10: =SUM(D11:D12) -> 192150.86 | E10: =SUM(E11:E12) -> 201555.61 | F10: =SUM(F11:F12) -> 28217.785 | G10: =SUM(G11:G12) -> 46357.789 | H10: =SUM(H11:H12) -> 76591.13 | I10: =SUM(I11:I12) -> 50388.901 | K10: =SUM(K11:K12) -> 112088
A11: Primera Vez | C11: 61980 | D11: =(K11/7)*12 -> 57281.143 | E11: =IF(C11="",0,(D11/C11)*D11) -> 52938.518 | F11: =E11*14% -> 7411.3925 | G11: =E11*0.23 -> 12175.859 | H11: =E11*0.38 -> 20116.637 | I11: =E11*0.25 -> 13234.629 | K11: 33414
A12: Subsecuente | C12: 122394 | D12: =(K12/7)*12 -> 134869.71 | E12: =IF(C12="",0,(D12/C12)*D12) -> 148617.09 | F12: =E12*14% -> 20806.392 | G12: =E12*0.23 -> 34181.93 | H12: =E12*0.38 -> 56474.493 | I12: =E12*0.25 -> 37154.272 | K12: 78674
A13: Servicio de Emergencia | B13: Consultas | C13: =SUM(C14) -> 62767 | D13: =D14 -> 69276 | E13: =E14 -> 76459.99 | F13: =F14 -> 10704.399 | G13: =G14 -> 17585.798 | H13: =H14 -> 29054.796 | I13: =I14 -> 19114.997 | K13: =K14 -> 40411
A14: Emergencias | C14: 62767 | D14: =(K14/7)*12 -> 69276 | E14: =IF(C14="",0,(D14/C14)*D14) -> 76459.99 | F14: =E14*0.14 -> 10704.399 | G14: =E14*0.23 -> 17585.798 | H14: =E14*0.38 -> 29054.796 | I14: =E14*0.25 -> 19114.997 | K14: 40411
A15: Servicio Hospitalización | B15: Egresos | C15: =SUM(C16:C29) -> 13245 | D15: =SUM(D16:D29) -> 11885.143 | E15: =SUM(E16:E29) -> 11027.639 | F15: =SUM(F16:F29) -> 1543.8695 | G15: =SUM(G16:G29) -> 2536.3571 | H15: =SUM(H16:H29) -> 58638.069 | I15: =SUM(I16:I29) -> 7525.7261 | K15: =SUM(K16:K29) -> 6933
A16: Medicina General | C16: 50 | D16: =(K16/7)*12 -> 44.571429 | E16: =IF(C16="",0,(D16/C16)*D16) -> 39.732245 | F16: =E16*0.14 -> 5.5625143 | G16: =E16*0.23 -> 9.1384163 | H16: =E16*0.38 -> 15.098253 | I16: =I14*0.25 -> 4778.7494 | K16: 26
A17: Cirugia General | C17: 2 | D17: =(K17/7)*12 -> 0 | E17: =IF(C17="",0,(D17/C17)*D17) -> 0 | F17: =E17*0.14 -> 0 | G17: =E17*0.23 -> 0 | H17: =E17*0.38 -> 0 | I17: =E17*0.25 -> 0
A18: Ginecología | C18: 1544 | D18: =(K18/7)*12 -> 1719.4286 | E18: =IF(C18="",0,(D18/C18)*D18) -> 1914.7893 | F18: =E18*0.14 -> 268.0705 | G18: =E18*0.23 -> 440.40153 | H18: =E18*0.38 -> 727.61992 | I18: =E18*0.25 -> 478.69731 | K18: 1003
A19: Obstetricia | C19: 6944 | D19: =(K19/7)*12 -> 6078.8571 | E19: =IF(C19="",0,(D19/C19)*D19) -> 5321.5012 | F19: =E19*0.14 -> 745.01016 | G19: =E19*0.23 -> 1223.9453 | H19: =E19*0.38 -> 2022.1704 | I19: =E19*0.25 -> 1330.3753 | K19: 3546
A20: Pediatria | C20: 2761 | D20: =(K20/7)*12 -> 2218.2857 | E20: =IF(C20="",0,(D20/C20)*D20) -> 1782.2497 | F20: =E20*0.14 -> 249.51496 | G20: =E20*0.23 -> 409.91744 | H20: =E20*0.38 -> 677.2549 | I20: =E20*0.25 -> 445.56243 | K20: 1294
A21: Cardiologia | D21: =(K21/7)*12 -> 0 | E21: =IF(C21="",0,(D21/C21)*D21) -> 0 | F21: =E21*0.14 -> 0 | G21: =E21*0.23 -> 0 | H21: =E21*0.38 -> 0 | I21: =E21*0.25 -> 0
A22: Gastroenterologia | D22: =(K22/7)*12 -> 0 | E22: =IF(C22="",0,(D22/C22)*D22) -> 0 | F22: =E22*0.14 -> 0 | G22: =E22*0.23 -> 0 | H22: =E22*0.38 -> 0 | I22: =E22*0.25 -> 0
A23: Endocrinologia | D23: =(K23/7)*12 -> 252 | E23: =IF(C23="",0,(D23/C23)*D23) -> 0 | F23: =E23*0.14 -> 0 | G23: =E23*0.23 -> 0 | H23: =E23*0.38 -> 0 | I23: =E23*0.25 -> 0 | K23: 147
A24: Medicina Interna | D24: =(K24/7)*12 -> 0 | E24: =IF(C24="",0,(D24/C24)*D24) -> 0 | F24: =E24*0.14 -> 0 | G24: =E24*0.23 -> 0 | H24: =E24*0.38 -> 0 | I24: =E24*0.25 -> 0
A25: Ortopedia | D25: =(K25/7)*12 -> 0 | E25: =IF(C25="",0,(D25/C25)*D25) -> 0 | F25: =E25*0.14 -> 0 | G25: =E25*0.23 -> 0 | H25: =E25*0.38 -> 0 | I25: =E25*0.25 -> 0
A26: Neumología | D26: =(K26/7)*12 -> 10.285714 | E26: =IF(C26="",0,(D26/C26)*D26) -> 0 | F26: =E26*0.14 -> 0 | G26: =E26*0.23 -> 0 | H26: =E26*0.38 -> 0 | I26: =E26*0.25 -> 0 | K26: 6
A27: Cardiología | D27: =(K27/7)*12 -> 0 | E27: =IF(C27="",0,(D27/C27)*D27) -> 0 | F27: =E27*0.14 -> 0 | G27: =E27*0.23 -> 0 | H27: =E27*0.38 -> 0 | I27: =E27*0.25 -> 0
A28: Cuidados Intensivos | C28: 1672 | D28: =(K28/7)*12 -> 934.28571 | E28: =IF(C28="",0,(D28/C28)*D28) -> 522.06328 | F28: =E28*0.14 -> 73.088859 | G28: =E28*0.23 -> 120.07455 | H28: =E28*0.38 -> 198.38404 | I28: =E28*0.25 -> 130.51582 | K28: 545
A29: Otros | C29: 272 | D29: =(K29/7)*12 -> 627.42857 | E29: =IF(C29="",0,(D29/C29)*D29) -> 1447.3037 | F29: =E29*0.14 -> 202.62252 | G29: =E29*0.23 -> 332.87986 | H29: =E29*38 -> 54997.541 | I29: =E29*0.25 -> 361.82593 | K29: 366
A30: Servicios de Apoyo Diagnóstico | C30: =SUM(C31:C32) -> 535836 | D30: =SUM(D31:D32) -> 598673.14 | E30: =SUM(E31:E32) -> 669547.29 | F30: =SUM(F31:F32) -> 93736.62 | G30: =SUM(G31:G32) -> 153995.88 | H30: =SUM(H31:H32) -> 254427.97 | I30: =SUM(I31:I32) -> 167386.82 | K30: =SUM(K31:K32) -> 349226
A31: Análisis de Laboratorio | B31: Pruebas | C31: 506262 | D31: =(K31/7)*12 -> 561310.29 | E31: =IF(C31="",0,(D31/C31)*D31) -> 622344.23 | F31: =E31*0.14 -> 87128.193 | G31: =E31*0.23 -> 143139.17 | H31: =E31*0.38 -> 236490.81 | I31: =E31*0.25 -> 155586.06 | K31: 327431
A32: Servicio de Imágenes | B32: Imágenes | C32: 29574 | D32: =(K32/7)*12 -> 37362.857 | E32: =IF(C32="",0,(D32/C32)*D32) -> 47203.053 | F32: =E32*0.14 -> 6608.4274 | G32: =E32*0.23 -> 10856.702 | H32: =E32*0.38 -> 17937.16 | I32: =E32*0.25 -> 11800.763 | K32: 21795
A33: Indicadores de Producción
A34: Años | B34: Camas Disponibles | C34: Egresos Hospitalarios | D34: Día Cama Disponibles | E34: Dias Pacientes | F34: Promedio Días Estada | G34: Porcentaje Ocupacional | H34: Porcentaje nacimientos prematuros | I34: Porcentaje de cesárea
A35: 2022 | B35: 229 | C35: 17180 | D35: =+B35*365 -> 83585 | E35: 41979 | F35: =+E35/C35 -> 2.4434808 | G35: =+E35/D35*100 -> 50.223126
A36: 2023 | B36: 231 | C36: 12957 | D36: =+B36*365 -> 84315 | E36: 32659 | F36: =+E36/C36 -> 2.520568 | G36: =+E36/D36*100 -> 38.734508
A37: 2024 | B37: 259 | C37: 13245 | D37: =+B37*365 -> 94535 | F37: =+E37/C37 -> 0 | G37: =+E37/D37*100 -> 0

Sheet PPNE2
A1: =+PPNE1!$B$1 -> Plan Operativo Anual
A2: Servicio Nacional de Salud
A3: Dirección de Planificación y Desarrollo | K3: Anticipo Financiero
A4: Programación de actividades | K4: Nómina
A5: =PPNE1!$C$5 -> 2026 | K5: Venta Servicios
A6: Servicio Regional de Salud: | K6: Recursos Externos
A7: CEAS:
A8: Resultados Esperados | B8: Productos | C8: Código | D8: Actividades Programables Presupuestables | E8: Ene | F8: Feb | G8: Mar | H8: Abr | I8: May | J8: Jun | K8: Jul | L8: Ago | M8: Sep | N8: Oct | O8: Nov | P8: Dic | Q8: Total de Acciones | R8: Medio de Verificación 1 | S8: Medio de Verificación 2 | T8: Medio de Verificación 3 | U8: Observaciones/ Comentarios | V8: Área Responsable
A9: 1.1 Reducidos los niveles de morbilidad y mortalidad materna e infantil por causas prevenibles en la población materno-infantil del país, disminuyendo la mortalidad materna de 127.33 y la mortalidad infantil de 18.44 en 2023 a 89.13 y 16.56 en 2028 en todas las regiones del territorio nacional. | B9: 1.1.1 Niños, niñas y Adolescentes reciben atención médica y servicios de salud basado en protocolos nacionales e internacionales. | C9: 1.1.1.01 | D9: Fortalecimiento de los Programas Madre Canguro . | E9: 2 | F9: 2 | G9: 1 | H9: 1 | I9: 1 | J9: 2 | K9: 1 | L9: 1 | M9: 2 | N9: 1 | O9: 1 | P9: 2 | Q9: =SUM(E9:P9) -> 17 | T9: Autoevaluación (enero)/ Plan de mejora (febrero)/ Registro Módulo PMC (mensual)/ Avances Plan de mejora (junio, septiembre,diciembre) | U9: Maternidad Nuestra Señora de la Altagracia, Infantil Dr. Robert Reid Cabral, Materno Infantil San Lorenzo de Los Mina, Materno Dr.Reynaldo Almanzar, Materno Dra. Evangelina Rodríguez, Materno Infantil Dr. Marcelino Velez, Hospital Pediátrico Dr. José Manuel Rodriguez Jimenes, Juan Pablo Pina, Infantil Dr. Arturo Grullón, Maternidad Presidente Estrella Ureña, San Vicente de Paul, Jaime Mota, Dr. Antonio Musa, Materno Infantil Nuestra Señora de la Altagracia, Materno Infantil Dr. Francisco A. Gonzalvo, Taiwan 19 de marzo, Dr.Alejandro Cabral, Materno Infantil Dr. José Fco. Peña Gómez, Dr. Luis M. Morillo King | V9: Materno Infantil y Adolescentes
A10: 1.1 Reducidos los niveles de morbilidad y mortalidad materna e infantil por causas prevenibles en la población materno-infantil del país, disminuyendo la mortalidad materna de 127.33 y la mortalidad infantil de 18.44 en 2023 a 89.13 y 16.56 en 2028 en todas las regiones del territorio nacional. | B10: 1.1.1 Niños, niñas y Adolescentes reciben atención médica y servicios de salud basado en protocolos nacionales e internacionales. | C10: 1.1.1.02 | D10: Seguimiento a la Sala Situacional IA | E10: 1 | F10: 1 | G10: 1 | H10: 1 | I10: 1 | J10: 1 | K10: 1 | L10: 1 | M10: 1 | N10: 1 | O10: 1 | P10: 1 | Q10: =SUM(E10:P10) -> 12 | T10: Reporte digital Módulo Sala Situacional IA | U10: Infantil Dr. Arturo Grullón, Dr. Luis Morillo King, San Vicente de Paul, Materno Infantil Dr. José Francisco Peña Gómez, Juan Pablo Pina, Jaime Mota, Regional Dr. Alejandro Cabral, Taiwan 19 de marzo, Regional Dr. Antonio Musa, Materno Infantil Nuestra Señora de la Altagracia, Materno Infantil Dr. Francisco A. Gonzalvo, Infantil Dr. Robert Reid Cabral, Materno Infantil San Lorenzo de Los Mina, Materno Infantil Dr. Marcelino Vélez Santana, Pediátrico Dr. Hugo Mendoza, Infantil Dr. José Rodriguez Jimenes, Materno Infantil Dr. Julio Rodriguez Grullón, Materno Infantil de Villa Mella | V10: Materno Infantil y Adolescentes
A11: 1.1 Reducidos los niveles de morbilidad y mortalidad materna e infantil por causas prevenibles en la población materno-infantil del país, disminuyendo la mortalidad materna de 127.33 y la mortalidad infantil de 18.44 en 2023 a 89.13 y 16.56 en 2028 en todas las regiones del territorio nacional. | B11: 1.1.1 Niños, niñas y Adolescentes reciben atención médica y servicios de salud basado en protocolos nacionales e internacionales. | C11: 1.1.1.03 | D11: Reporte casos niños asistidos por violencia. | E11: 1 | F11: 1 | G11: 1 | H11: 1 | I11: 1 | J11: 1 | K11: 1 | L11: 1 | M11: 1 | N11: 1 | O11: 1 | P11: 1 | Q11: =SUM(E11:P11) -> 12 | T11: Registro Sala Situacional/ Formulario de reporte | U11: Infantil Dr. Arturo Grullón, Dr. Luis Morillo King, San Vicente de Paul, Materno Infantil Dr. José Francisco Peña Gómez, Juan Pablo Pina, Jaime Mota, Regional Dr. Alejandro Cabral, Taiwan 19 de marzo, Regional Dr. Antonio Musa, Materno Infantil Nuestra Señora de la Altagracia, Materno Infantil Dr. Francisco A. Gonzalvo, Infantil Dr. Robert Reid Cabral, Materno Infantil San Lorenzo de Los Mina, Materno Infantil Dr. Marcelino Vélez Santana, Pediátrico Dr. Hugo Mendoza, Infantil Dr. José Rodriguez Jimenes, Materno Infantil Dr. Julio Rodriguez Grullón, Materno Infantil de Villa Mella | V11: Materno Infantil y Adolescentes
A12: 1.1 Reducidos los niveles de morbilidad y mortalidad materna e infantil por causas prevenibles en la población materno-infantil del país, disminuyendo la mortalidad materna de 127.33 y la mortalidad infantil de 18.44 en 2023 a 89.13 y 16.56 en 2028 en todas las regiones del territorio nacional. | B12: 1.1.1 Niños, niñas y Adolescentes reciben atención médica y servicios de salud basado en protocolos nacionales e internacionales. | C12: 1.1.1.04 | D12: Elaboración e implementación del plan de mejora para fortalecimiento de las Unidades de Atención Integrales en Salud para personas Adolescentes | E12: 1 | H12: 1 | K12: 1 | N12: 1 | Q12: =SUM(E12:P12) -> 4 | T12: Plan (elaboración enero) Seguimiento (abril, julio, octubre) | U12: Pediátrico Dr. Hugo Mendoza, Pediátrico Dr. Robert Reid Cabral, Materno Infantil San Lorenzo de Los Mina, Municipal Materno Infantil Villa Mella, Infantil Dr. Arturo Grullón, Dr. Ricardo Limardo, Maternidad Infantil Nuestra Señora de la Altagracia (Higuey), Dr. Luis Manuel Morillo King, Juan Pablo Pina, Materno Infantil Dr.Francisco Gonzalvo, San Vicente de Paúl, Dr.Antonio Musa, Jaime Mota, Materno Infantil Dr. Marcelino Vélez, Centro Dr. Nelson Astacio | V12: Materno Infantil y Adolescentes
A13: 1.1 Reducidos los niveles de morbilidad y mortalidad materna e infantil por causas prevenibles en la población materno-infantil del país, disminuyendo la mortalidad materna de 127.33 y la mortalidad infantil de 18.44 en 2023 a 89.13 y 16.56 en 2028 en todas las regiones del territorio nacional. | B13: 1.1.1 Niños, niñas y Adolescentes reciben atención médica y servicios de salud basado en protocolos nacionales e internacionales. | C13: 1.1.1.05 | D13: Reporte de la Planificación familiar en Adolescentes | E13: 1 | F13: 1 | G13: 1 | H13: 1 | I13: 1 | J13: 1 | K13: 1 | L13: 1 | M13: 1 | N13: 1 | O13: 1 | P13: 1 | Q13: =SUM(E13:P13) -> 12 | T13: Reporte | U13: Hospitales que asisten Adolecentes | V13: Materno Infantil y Adolescentes
A14: 1.1 Reducidos los niveles de morbilidad y mortalidad materna e infantil por causas prevenibles en la población materno-infantil del país, disminuyendo la mortalidad materna de 127.33 y la mortalidad infantil de 18.44 en 2023 a 89.13 y 16.56 en 2028 en todas las regiones del territorio nacional. | B14: 1.1.2 Recién nacidos reciben atención medica y servicios de salud neonatal basados en protocolos y normas nacionales e internacionales | C14: 1.2.2.01 | D14: Vigilanica sanitaria del agua en las UCIN del SNS | J14: 1 | P14: 1 | Q14: =SUM(E14:P14) -> 2 | R14: Reporte | U14: Maternidad Nuestra Señora de la Altagracia , Materno Infantil San Lorenzo de los Mina, Materno Dr. Reynaldo Almánzar, Materno Infantil Dr. Marcelino Vélez, Maternidad Presidente Estrella Ureña, Materno Infantil Nuestra Señora de la Altagracia (Higuey), Juan Pablo Pina, San Vicente de Paul, Dr. Luis M. Morillo King, Infantil Dr.Robert Reid Cabral, Maternidad Dra.Evangelina Rodriguez, Materno Infantil Dr. José Fco.Peña Gomez, Jaime Mota, Dr. Antonio Musa, Infantil Dr. Arturo Grullon, Materno Infantil Dr. José Rodriguez Grullón (Ciudad Sanitaria), Pediatrico Dr.Hugo Mendoza, Taiwan 19 de marzo, Dr. Alejandro Cabral | V14: Materno Infantil y Adolescentes
A15: 1.1 Reducidos los niveles de morbilidad y mortalidad materna e infantil por causas prevenibles en la población materno-infantil del país, disminuyendo la mortalidad materna de 127.33 y la mortalidad infantil de 18.44 en 2023 a 89.13 y 16.56 en 2028 en todas las regiones del territorio nacional. | B15: 1.1.2 Recién nacidos reciben atención medica y servicios de salud neonatal basados en protocolos y normas nacionales e internacionales | C15: 1.2.2.02 | D15: Monitoreo del registro en línea del Certificado de Nacido Vivo | E15: 1 | F15: 1 | G15: 1 | H15: 1 | I15: 1 | J15: 1 | K15: 1 | L15: 1 | M15: 1 | N15: 1 | O15: 1 | P15: 1 | Q15: =SUM(E15:P15) -> 12 | R15: Reporte | U15: Todos los CEAS donde se producen nacimientos | V15: Materno Infantil y Adolescentes
A16: 1.2 Aumentado el cumplimiento normativo para reducir la incidencia de complicaciones neonatales y maternas, pasando de un promedio del 75.5% en el año 2023 al 88% en el año 2028 en todas las regiones de la Red Pública de Servicios de Salud. | B16: 1.2.1 Gestantes reciben atención médica y servicios de salud materna basados en protocolos y normas nacionales e internacionales. | C16: 1.2.1.01 | D16: Seguimiento de la Morbilidad Materna Extrema | F16: 1 | G16: 1 | H16: 1 | I16: 1 | J16: 1 | K16: 1 | L16: 1 | M16: 1 | N16: 1 | O16: 1 | Q16: =SUM(E16:P16) -> 10 | R16: Informe | U16: Todos los hospitales regionales, maternos, materno infantil, que ofrecen servicios maternos | V16: Materno Infantil y Adolescentes
A17: 1.2 Aumentado el cumplimiento normativo para reducir la incidencia de complicaciones neonatales y maternas, pasando de un promedio del 75.5% en el año 2023 al 88% en el año 2028 en todas las regiones de la Red Pública de Servicios de Salud. | B17: 1.2.1 Gestantes reciben atención médica y servicios de salud materna basados en protocolos y normas nacionales e internacionales. | C17: 1.2.1.02 | D17: Análisis de los indicadores Maternos Neonatales de la Sala Situacional | G17: 1 | J17: 1 | M17: 1 | P17: 1 | Q17: =SUM(E17:P17) -> 4 | R17: Informe | T17: Plantilla estandarizada | U17: Todos los CEAS regionales, especializados y de referencia que ofrezcan servicios maternos | V17: Materno Infantil y Adolescentes
A18: 1.2 Aumentado el cumplimiento normativo para reducir la incidencia de complicaciones neonatales y maternas, pasando de un promedio del 75.5% en el año 2023 al 88% en el año 2028 en todas las regiones de la Red Pública de Servicios de Salud. | B18: 1.2.1 Gestantes reciben atención médica y servicios de salud materna basados en protocolos y normas nacionales e internacionales. | C18: 1.2.1.03 | D18: Seguimiento a la implementacion de la Estrategia Código Rojo. | G18: 1 | J18: 1 | M18: 1 | P18: 1 | Q18: =SUM(E18:P18) -> 4 | R18: Informe | S18: Listado de participación | U18: Todos los hospitales regionales, maternos y materno infantil que ofrecen servicios maternos | V18: Materno Infantil y Adolescentes
A19: 1.2 Aumentado el cumplimiento normativo para reducir la incidencia de complicaciones neonatales y maternas, pasando de un promedio del 75.5% en el año 2023 al 88% en el año 2028 en todas las regiones de la Red Pública de Servicios de Salud. | B19: 1.2.1 Gestantes reciben atención médica y servicios de salud materna basados en protocolos y normas nacionales e internacionales. | C19: 1.2.1.04 | D19: Seguimiento al tamizaje de infecciones vaginales y urinarias en la embarazada | G19: 1 | J19: 1 | N19: 1 | Q19: =SUM(E19:P19) -> 3 | R19: Informe | U19: Materno Dr. Reynaldo Almanzar, Maternidad Nuestra Señora de la Altagracia, Materno Infantil San Lorenzo de los Mina, Maternidad Presidente Estrella Ureña | V19: Materno Infantil y Adolescentes
A20: 1.2 Aumentado el cumplimiento normativo para reducir la incidencia de complicaciones neonatales y maternas, pasando de un promedio del 75.5% en el año 2023 al 88% en el año 2028 en todas las regiones de la Red Pública de Servicios de Salud. | B20: 1.2.1 Gestantes reciben atención médica y servicios de salud materna basados en protocolos y normas nacionales e internacionales. | C20: 1.2.1.05 | D20: Elaboracion de los planes de mejora de la metodología de Observación de la Práctica Clínica (OPC) según los resultados del monitoreo de calidad de los servicios en los CEAS priorizados | I20: 1 | N20: 1 | Q20: =SUM(E20:P20) -> 2 | R20: Plan | S20: Listado de participación | U20: CEAS PRIORIZADOS SRS Ozama 1. Hospital Materno Dr. Reynaldo Almánzar 2. Hospital Maternidad Nuestra Señora de la Altagracia 3. Hospital Materno Infantil San Lorenzo de los Mina 4. Hospital Materno Dra. Evangelina Rodríguez 5. ⁠Hospital Materno Infantil Dr. Marcelino Vélez Santana 6. Hospital Materno Infantil Dr. Julio Rodriguez Grullón SRS Valdesia 7.Hospital Regional Juan Pablo Pina SRS Cibao Norte 8. Hospital Maternidad Presidente Estrella Ureña SRS Cibao Nordeste 9. Hospital Regional San Vicente de Paul SRS Enriquillo 10. Hospital Regional Jaime Mota SRS Higuamo 11. Hospital Materno Infantil Nuestra Señora de la Altagracia 12. Hospital Materno Infantil Dr. Francisco Gonzalvo. SRS Yuma 13. Hospital Regional Dr. Antonio Musa SRS El Valle 14. Hospital Regional Dr. Alejandro Cabral 15. Hospital Regional Taiwán 19 de marzo SRS Cibao Noroeste 16. Hospital Materno Infantil Dr.José Francisco Peña Gómez SRS Cibao Sur 17. Hospital Regional Dr. Luis Morillo King | V20: Materno Infantil y Adolescentes
A21: 1.2 Aumentado el cumplimiento normativo para reducir la incidencia de complicaciones neonatales y maternas, pasando de un promedio del 75.5% en el año 2023 al 88% en el año 2028 en todas las regiones de la Red Pública de Servicios de Salud. | B21: 1.2.1 Gestantes reciben atención médica y servicios de salud materna basados en protocolos y normas nacionales e internacionales. | C21: 1.2.1.06 | D21: Seguimiento a la Planificación Post Evento Obstétrico | H21: 1 | L21: 1 | O21: 1 | Q21: =SUM(E21:P21) -> 3 | R21: Informe | U21: CEAS PRIORIZADOS SRS Ozama 1. Hospital Materno Dr. Reynaldo Almánzar 2. Hospital Maternidad Nuestra Señora de la Altagracia 3. Hospital Materno Infantil San Lorenzo de los Mina 4. Hospital Materno Dra. Evangelina Rodríguez 5. ⁠Hospital Materno Infantil Dr. Marcelino Vélez Santana 6. Hospital Materno Infantil Dr. Julio Rodriguez Grullón SRS Valdesia 7.Hospital Regional Juan Pablo Pina SRS Cibao Norte 8. Hospital Maternidad Presidente Estrella Ureña SRS Cibao Nordeste 9. Hospital Regional San Vicente de Paul SRS Enriquillo 10. Hospital Regional Jaime Mota SRS Higuamo 11. Hospital Materno Infantil Nuestra Señora de la Altagracia 12. Hospital Materno Infantil Dr. Francisco Gonzalvo. SRS Yuma 13. Hospital Regional Dr. Antonio Musa SRS El Valle 14. Hospital Regional Dr. Alejandro Cabral 15. Hospital Regional Taiwán 19 de marzo SRS Cibao Noroeste 16. Hospital Materno Infantil Dr.José Francisco Peña Gómez SRS Cibao Sur 17. Hospital Regional Dr. Luis Morillo King | V21: Materno Infantil y Adolescentes
A22: 1.2 Aumentado el cumplimiento normativo para reducir la incidencia de complicaciones neonatales y maternas, pasando de un promedio del 75.5% en el año 2023 al 88% en el año 2028 en todas las regiones de la Red Pública de Servicios de Salud. | B22: 1.2.1 Gestantes reciben atención médica y servicios de salud materna basados en protocolos y normas nacionales e internacionales. | C22: 1.2.1.07 | D22: Monitoreo al apego a protocolo de atencion en consulta prenatal. | I22: 1 | N22: 1 | Q22: =SUM(E22:P22) -> 2 | R22: Informe | U22: CEAS PRIORIZADOS SRS Ozama 1. Hospital Materno Dr. Reynaldo Almánzar 2. Hospital Maternidad Nuestra Señora de la Altagracia 3. Hospital Materno Infantil San Lorenzo de los Mina 4. Hospital Materno Dra. Evangelina Rodríguez 5. ⁠Hospital Materno Infantil Dr. Marcelino Vélez Santana 6. Hospital Materno Infantil Dr. Julio Rodriguez Grullón SRS Valdesia 7.Hospital Regional Juan Pablo Pina SRS Cibao Norte 8. Hospital Maternidad Presidente Estrella Ureña SRS Cibao Nordeste 9. Hospital Regional San Vicente de Paul SRS Enriquillo 10. Hospital Regional Jaime Mota SRS Higuamo 11. Hospital Materno Infantil Nuestra Señora de la Altagracia 12. Hospital Materno Infantil Dr. Francisco Gonzalvo. SRS Yuma 13. Hospital Regional Dr. Antonio Musa SRS El Valle 14. Hospital Regional Dr. Alejandro Cabral 15. Hospital Regional Taiwán 19 de marzo SRS Cibao Noroeste 16. Hospital Materno Infantil Dr.José Francisco Peña Gómez SRS Cibao Sur 17. Hospital Regional Dr. Luis Morillo King | V22: Materno Infantil y Adolescentes
A23: 1.5 Reducida la morbilidad y mortalidad prematura por enfermedades no transmisibles en personas de 30 a 69 años, en un 20% al año 2028, mediante la implementación de intervenciones integrales de prevención, diagnóstico temprano y tratamiento oportuno en los establecimientos de la Red Pública. | B23: 1.5.1 La población con riesgo o diagnóstico de hipertensión y diabetes recibe servicios integrales de prevención, diagnóstico, manejo y seguimiento de enfermedades crónicas no transmisibles, fortalecidos mediante la implementación del enfoque HEARTS. | C23: 1.5.1.01 | Q23: =SUM(E23:P23) -> 0
A24: 1.5 Reducida la morbilidad y mortalidad prematura por enfermedades no transmisibles en personas de 30 a 69 años, en un 20% al año 2028, mediante la implementación de intervenciones integrales de prevención, diagnóstico temprano y tratamiento oportuno en los establecimientos de la Red Pública. | B24: 1.5.2 Las víctimas de violencia de género e intrafamiliar reciben atención integral, oportuna y segura en los servicios de salud. | C24: 1.5.2.01 | D24: Reporte de estadísticas de los casos de violencia de género e intrafamiliar. | E24: 1 | F24: 1 | G24: 1 | H24: 1 | I24: 1 | J24: 1 | K24: 1 | L24: 1 | M24: 1 | N24: 1 | O24: 1 | P24: 1 | Q24: =SUM(E24:P24) -> 12 | R24: Reporte | V24: Género
A25: 1.6 Incrementado el acceso oportuno a servicios de salud de calidad, aumentando el acceso a servicios preventivos de 2.23% de la población prioritaria en 2023 al 5.24% en 2028 en todas las regiones del país. | B25: 1.6.5 La población usuaria recibe servicios odontológicos fortalecidos y de calidad mediante la ejecución de planes de mejora de la atención dental. | C25: 1.6.5.01 | D25: Capacitaciones a RRHH de las areas de odontología de acuerdo a las necesidades. | G25: 1 | J25: 1 | M25: 1 | Q25: =SUM(E25:P25) -> 3 | R25: Listado de participación | S25: Plan | V25: Odontología
A26: 1.6 Incrementado el acceso oportuno a servicios de salud de calidad, aumentando el acceso a servicios preventivos de 2.23% de la población prioritaria en 2023 al 5.24% en 2028 en todas las regiones del país. | B26: 1.6.5 La población usuaria recibe servicios odontológicos fortalecidos y de calidad mediante la ejecución de planes de mejora de la atención dental. | C26: 1.6.5.02 | D26: Desarrollo de plan de acciones para el acondicionamiento de infraestructura, mantenimiento de equipos y equipamiento de las áreas de odontología EES | G26: 1 | J26: 1 | M26: 1 | O26: 1 | Q26: =SUM(E26:P26) -> 4 | R26: Informe | S26: Plan | V26: Odontología
A27: 1.6 Incrementado el acceso oportuno a servicios de salud de calidad, aumentando el acceso a servicios preventivos de 2.23% de la población prioritaria en 2023 al 5.24% en 2028 en todas las regiones del país. | B27: 1.6.5 La población usuaria recibe servicios odontológicos fortalecidos y de calidad mediante la ejecución de planes de mejora de la atención dental. | C27: 1.6.5.03 | D27: Desarrollo del Programa Fomento de la Salud bucal. | H27: 1 | L27: 1 | N27: 1 | Q27: =SUM(E27:P27) -> 3 | R27: Informe | V27: Odontología
A28: 1.6 Incrementado el acceso oportuno a servicios de salud de calidad, aumentando el acceso a servicios preventivos de 2.23% de la población prioritaria en 2023 al 5.24% en 2028 en todas las regiones del país. | B28: 1.6.5 La población usuaria recibe servicios odontológicos fortalecidos y de calidad mediante la ejecución de planes de mejora de la atención dental. | C28: 1.6.5.04 | D28: Desarrollo del Programa Hospitales libre de caries | H28: 1 | M28: 1 | Q28: =SUM(E28:P28) -> 2 | R28: Informe | V28: Odontología
A29: 1.7 Aumentada la disponibilidad de medicamentos esenciales en los establecimientos de la Red Pública de Servicios de Salud, incrementando el cumplimiento promedio de abastecimiento del 88% en 2023 al 93% en 2028 en todas las regiones del país. | B29: 1.7.1 Pacientes reciben medicamentos esenciales para el tratamiento adecuado y oportuno de sus condiciones de salud. | C29: 1.7.1.01 | D29: Reunión Comité Farmaco Terapeutico (CFT) Hospitalario y promoción del uso racional de los medicamentos. | E29: 1 | H29: 1 | K29: 1 | N29: 1 | Q29: =SUM(E29:P29) -> 4 | R29: Listado de participación | S29: Minuta | V29: Medicamentos
A30: 1.8 Superadas las deficiencias en la organización e implementación de las Redes Integradas de Servicios de Salud (RISS) beneficiando a toda la población que utiliza los servicios de salud de la Red Pública, aumentando del 38% en 2023 al 50% en 2028 en todo el territorio nacional. | B30: 1.8.2 La población recibe acceso equitativo a servicios de salud, incluidos los de emergencia, de calidad, seguros, integrales, continuos e inclusivos, mediante redes integradas que incorporan mejora continua de procesos y avances tecnológicos. | C30: 1.8.2.01 | D30: Implementación del Modelo hospitalario y flujos de Asistencia Emergencias y Urgencias | J30: 1 | Q30: =SUM(E30:P30) -> 1 | R30: Reporte | V30: Emergencia
A31: 1.8 Superadas las deficiencias en la organización e implementación de las Redes Integradas de Servicios de Salud (RISS) beneficiando a toda la población que utiliza los servicios de salud de la Red Pública, aumentando del 38% en 2023 al 50% en 2028 en todo el territorio nacional. | B31: 1.8.2 La población recibe acceso equitativo a servicios de salud, incluidos los de emergencia, de calidad, seguros, integrales, continuos e inclusivos, mediante redes integradas que incorporan mejora continua de procesos y avances tecnológicos. | C31: 1.8.2.02 | D31: Socializacion e implementación del RAC-Triaje en las Salas de Emergencias Centros Hospitalarios | J31: 1 | O31: 1 | Q31: =SUM(E31:P31) -> 2 | R31: Listado de participación | S31: Reporte | V31: Emergencia
A32: 1.8 Superadas las deficiencias en la organización e implementación de las Redes Integradas de Servicios de Salud (RISS) beneficiando a toda la población que utiliza los servicios de salud de la Red Pública, aumentando del 38% en 2023 al 50% en 2028 en todo el territorio nacional. | B32: 1.8.2 La población recibe acceso equitativo a servicios de salud, incluidos los de emergencia, de calidad, seguros, integrales, continuos e inclusivos, mediante redes integradas que incorporan mejora continua de procesos y avances tecnológicos. | C32: 1.8.2.03 | D32: Llenado de historia clinica de emergencias y registro de todos los pacientes del libro de emergencias | M32: 1 | Q32: =SUM(E32:P32) -> 1 | R32: Reporte | V32: Emergencia
A33: 1.8 Superadas las deficiencias en la organización e implementación de las Redes Integradas de Servicios de Salud (RISS) beneficiando a toda la población que utiliza los servicios de salud de la Red Pública, aumentando del 38% en 2023 al 50% en 2028 en todo el territorio nacional. | B33: 1.8.2 La población recibe acceso equitativo a servicios de salud, incluidos los de emergencia, de calidad, seguros, integrales, continuos e inclusivos, mediante redes integradas que incorporan mejora continua de procesos y avances tecnológicos. | C33: 1.8.2.04 | D33: Implementación del procedimiento para la entrega, recibo y reposicion de carro de paro | F33: 1 | I33: 1 | L33: 1 | O33: 1 | Q33: =SUM(E33:P33) -> 4 | T33: Formularios de verificacion de Carro de paro (Apertura, Stock y Verificacion de desfibrilador) | V33: Emergencia
A34: 1.8 Superadas las deficiencias en la organización e implementación de las Redes Integradas de Servicios de Salud (RISS) beneficiando a toda la población que utiliza los servicios de salud de la Red Pública, aumentando del 38% en 2023 al 50% en 2028 en todo el territorio nacional. | B34: 1.8.2 La población recibe acceso equitativo a servicios de salud, incluidos los de emergencia, de calidad, seguros, integrales, continuos e inclusivos, mediante redes integradas que incorporan mejora continua de procesos y avances tecnológicos. | C34: 1.8.2.05 | D34: Registros en el tablero de Indicadores de Gestión de las Salas de Emergencias de los Centros de Salud. | G34: 1 | J34: 1 | M34: 1 | P34: 1 | Q34: =SUM(E34:P34) -> 4 | R34: Reporte | V34: Emergencia
A35: 1.8 Superadas las deficiencias en la organización e implementación de las Redes Integradas de Servicios de Salud (RISS) beneficiando a toda la población que utiliza los servicios de salud de la Red Pública, aumentando del 38% en 2023 al 50% en 2028 en todo el territorio nacional. | B35: 1.8.2 La población recibe acceso equitativo a servicios de salud, incluidos los de emergencia, de calidad, seguros, integrales, continuos e inclusivos, mediante redes integradas que incorporan mejora continua de procesos y avances tecnológicos. | C35: 1.8.2.06 | D35: Socialización de los procedimientos de traslado de pacientes | I35: 1 | Q35: =SUM(E35:P35) -> 1 | R35: Listado de participación | S35: Agenda | V35: Emergencia
A36: 1.8 Superadas las deficiencias en la organización e implementación de las Redes Integradas de Servicios de Salud (RISS) beneficiando a toda la población que utiliza los servicios de salud de la Red Pública, aumentando del 38% en 2023 al 50% en 2028 en todo el territorio nacional. | B36: 1.8.2 La población recibe acceso equitativo a servicios de salud, incluidos los de emergencia, de calidad, seguros, integrales, continuos e inclusivos, mediante redes integradas que incorporan mejora continua de procesos y avances tecnológicos. | C36: 1.8.2.07 | D36: Elaboración y/o actualización de los Planes de Emergencias y Desastres Hospitalarios | G36: 1 | Q36: =SUM(E36:P36) -> 1 | R36: Plan | V36: Emergencia
A37: 1.8 Superadas las deficiencias en la organización e implementación de las Redes Integradas de Servicios de Salud (RISS) beneficiando a toda la población que utiliza los servicios de salud de la Red Pública, aumentando del 38% en 2023 al 50% en 2028 en todo el territorio nacional. | B37: 1.8.2 La población recibe acceso equitativo a servicios de salud, incluidos los de emergencia, de calidad, seguros, integrales, continuos e inclusivos, mediante redes integradas que incorporan mejora continua de procesos y avances tecnológicos. | C37: 1.8.2.08 | D37: Reunion del comité de emergencias para socializacion del plan Hospitalarios Emergencias de salud publica y desastres naturales con el personal del hospital. | G37: 1 | J37: 1 | M37: 1 | Q37: =SUM(E37:P37) -> 3 | R37: Listado de participación | S37: Minuta | V37: Emergencia
A38: 1.8 Superadas las deficiencias en la organización e implementación de las Redes Integradas de Servicios de Salud (RISS) beneficiando a toda la población que utiliza los servicios de salud de la Red Pública, aumentando del 38% en 2023 al 50% en 2028 en todo el territorio nacional. | B38: 1.8.2 La población recibe acceso equitativo a servicios de salud, incluidos los de emergencia, de calidad, seguros, integrales, continuos e inclusivos, mediante redes integradas que incorporan mejora continua de procesos y avances tecnológicos. | C38: 1.8.2.09 | D38: Simulacro para probar la funcionabilidad de los Planes de Emergencias y Desastres Hospitalarios. | N38: 1 | Q38: =SUM(E38:P38) -> 1 | R38: Listado de participación | S38: Reporte | V38: Emergencia
A39: 1.8 Superadas las deficiencias en la organización e implementación de las Redes Integradas de Servicios de Salud (RISS) beneficiando a toda la población que utiliza los servicios de salud de la Red Pública, aumentando del 38% en 2023 al 50% en 2028 en todo el territorio nacional. | B39: 1.8.2 La población recibe acceso equitativo a servicios de salud, incluidos los de emergencia, de calidad, seguros, integrales, continuos e inclusivos, mediante redes integradas que incorporan mejora continua de procesos y avances tecnológicos. | C39: 1.8.2.10 | D39: Reunión con el Comite Hospitalario de Emergencias y Desastres para preparar el Operativo de Navidad y Año Nuevo comité de emergencias | P39: 1 | Q39: =SUM(E39:P39) -> 1 | R39: Listado de participación | S39: Minuta | V39: Emergencia
A40: 1.8 Superadas las deficiencias en la organización e implementación de las Redes Integradas de Servicios de Salud (RISS) beneficiando a toda la población que utiliza los servicios de salud de la Red Pública, aumentando del 38% en 2023 al 50% en 2028 en todo el territorio nacional. | B40: 1.8.2 La población recibe acceso equitativo a servicios de salud, incluidos los de emergencia, de calidad, seguros, integrales, continuos e inclusivos, mediante redes integradas que incorporan mejora continua de procesos y avances tecnológicos. | C40: 1.8.2.11 | D40: Reunión con el Comite Hospitalario de Emergencias y Desastres para preparar el Operativo de Semana Santa comité de emergencias | G40: 1 | Q40: =SUM(E40:P40) -> 1 | R40: Listado de participación | S40: Minuta | V40: Emergencia
...

Sheet Sheet1
E2: Informe | F2: 1.1 Reducidos los niveles de morbilidad y mortalidad materna e infantil por causas prevenibles en la población materno-infantil del país, disminuyendo la mortalidad materna de 127.33 y la mortalidad infantil de 18.44 en 2023 a 89.13 y 16.56 en 2028 en todas las regiones del territorio nacional.
E3: Listado de participación | F3: 1.2 Aumentado el cumplimiento normativo para reducir la incidencia de complicaciones neonatales y maternas, pasando de un promedio del 75.5% en el año 2023 al 88% en el año 2028 en todas las regiones de la Red Pública de Servicios de Salud.
E4: Fotos | F4: 1.3 Reducido el embarazo en adolescentes atendidas en los establecimientos de la Red Pública en un 20% al año 2028, mediante el fortalecimiento del acceso a servicios integrales de salud sexual y reproductiva.
E5: Agenda | F5: 1.4 Disminuida la proporción de partos por cesárea en hospitales del sector público pasando de 48.83 en el 2023 a 34 en el 2028.
E6: Plan | F6: 1.5 Reducida la morbilidad y mortalidad prematura por enfermedades no transmisibles en personas de 30 a 69 años, en un 20% al año 2028, mediante la implementación de intervenciones integrales de prevención, diagnóstico temprano y tratamiento oportuno en los establecimientos de la Red Pública.
E7: Protocolo | F7: 1.6 Incrementado el acceso oportuno a servicios de salud de calidad, aumentando el acceso a servicios preventivos de 2.23% de la población prioritaria en 2023 al 5.24% en 2028 en todas las regiones del país.
E8: Manual | F8: 1.7 Aumentada la disponibilidad de medicamentos esenciales en los establecimientos de la Red Pública de Servicios de Salud, incrementando el cumplimiento promedio de abastecimiento del 88% en 2023 al 93% en 2028 en todas las regiones del país.
E9: Resolución | F9: 1.8 Superadas las deficiencias en la organización e implementación de las Redes Integradas de Servicios de Salud (RISS) beneficiando a toda la población que utiliza los servicios de salud de la Red Pública, aumentando del 38% en 2023 al 50% en 2028 en todo el territorio nacional.
E10: Boletin | F10: 1.9 Fortalecida la implementación del Modelo de Atención en Salud beneficiando a la población usuaria del primer nivel de atención, incrementando la adscripción del 7% en 2023 al 80% en 2028, en todas las regiones del país.
E11: Reporte | F11: 1.10 Mejorada la distribución y presencia del Primer Nivel de Atención respecto a la sectorización, incrementando la presencia del Primer Nivel del 70% en 2023 al 71% en 2028 en todas las regiones del territorio nacional.
E12: Minuta | F12: 1.11 Fortalecida la continuidad en la atención de las puérperas y recién nacidos, aumentando la captación oportuna del 30% en 2023 al 50% en 2028 en el Primer Nivel de Atención.
E13: Hoja de supervisión | F13: 1.12 Superadas las deficiencias en la organización e implementación de las Redes Integradas de Servicios de Salud (RISS) beneficiando a toda la población que utiliza los servicios de salud de la Red Pública, aumentando del 38% en 2023 al 50% en 2028 en todo el territorio nacional.
... E20: Otros | F20: 3.4 Alcanzado un cumplimiento mínimo del 90% de las metas de planificación y ejecución presupuestaria, optimizando la asignación y uso de recursos.
F21: 3.5 Atendidas las solicitudes de información recibidas en los plazos establecidos, con reportes de cumplimiento mensual y mecanismos de retroalimentación al usuario.
F22: 3.6 Registradas y procesadas en el Sistema Electrónico de Compras Públicas las adquisiciones y contrataciones institucionales y de la Red Pública.
F23: 3.7 Incrementando progresivamente el índice de uso de las TIC y Gobierno Digital en la Red Pública de Servicios de Salud.
F24: 3.8 Implementados y operativos los controles internos definidos por las NOBACI, con revisiones de cumplimiento semestrales y planes de mejora continua.
F25: 3.9 Instalaciones físicas remodeladas y equipadas conforme a estándares de centros de salud incrementando su capacidad resolutiva.
F26: 3.10 Implementado un sistema integral de medición y gestión de la satisfacción de usuarios, con reportes trimestrales y planes de mejora continua para elevar la calidad percibida de los servicios públicos.

Sheet PPNE2.1
O1: Venta Servicios
G2: Servicio Nacional de Salud | S2: Anticipo Financiero
G3: Dirección de Planificación y Desarrollo | S3: Venta de Servicios
G4: Programación de Insumos | S4: Donaciones
J5: =+PPNE1!C5 -> 2026
G6: CEAS | H6: =+PPNE1!B7 -> 0
B7: ID_Dependendencia | C7: POA | D7: SRS | E7: AREA | F7: TIPO | G7: Código_Actividad | H7: Insumos | I7: Unidad de Medida | J7: Cantidad de Insumos | K7: Precio Unitario | L7: Valor Total | M7: Código Presupuestario | N7: Fuente de Financiamiento
B8: =IF(Tabla1[[#This Row],[Código_Actividad]]="","",CONCATENATE(Tabla1[[#This Row],[POA]],".",Tabla1[[#This Row],[SRS]],".",Tabla1[[#This Row],[AREA]],".",Tabla1[[#This Row],[TIPO]])) -> ... | G8: 1.2.1.01 | H8: leche | I8: und | L8: =+Tabla1[[#This Row],[Precio Unitario]]*Tabla1[[#This Row],[Cantidad de Insumos]] -> 0
B9: =IF(Tabla1[[#This Row],[Código_Actividad]]="","",CONCATENATE(Tabla1[[#This Row],[POA]],".",Tabla1[[#This Row],[SRS]],".",Tabla1[[#This Row],[AREA]],".",Tabla1[[#This Row],[TIPO]])) | L9: =+Tabla1[[#This Row],[Precio Unitario]]*Tabla1[[#This Row],[Cantidad de Insumos]] -> 0
B10: =IF(Tabla1[[#This Row],[Código_Actividad]]="","",CONCATENATE(Tabla1[[#This Row],[POA]],".",Tabla1[[#This Row],[SRS]],".",Tabla1[[#This Row],[AREA]],".",Tabla1[[#This Row],[TIPO]])) | L10: =+Tabla1[[#This Row],[Precio Unitario]]*Tabla1[[#This Row],[Cantidad de Insumos]] -> 0
B11: =IF(Tabla1[[#This Row],[Código_Actividad]]="","",CONCATENATE(Tabla1[[#This Row],[POA]],".",Tabla1[[#This Row],[SRS]],".",Tabla1[[#This Row],[AREA]],".",Tabla1[[#This Row],[TIPO]])) | L11: =+Tabla1[[#This Row],[Precio Unitario]]*Tabla1[[#This Row],[Cantidad de Insumos]] -> 0
B12: =IF(Tabla1[[#This Row],[Código_Actividad]]="","",CONCATENATE(Tabla1[[#This Row],[POA]],".",Tabla1[[#This Row],[SRS]],".",Tabla1[[#This Row],[AREA]],".",Tabla1[[#This Row],[TIPO]])) | L12: =+Tabla1[[#This Row],[Precio Unitario]]*Tabla1[[#This Row],[Cantidad de Insumos]] -> 0
B13: =IF(Tabla1[[#This Row],[Código_Actividad]]="","",CONCATENATE(Tabla1[[#This Row],[POA]],".",Tabla1[[#This Row],[SRS]],".",Tabla1[[#This Row],[AREA]],".",Tabla1[[#This Row],[TIPO]])) | L13: =+Tabla1[[#This Row],[Precio Unitario]]*Tabla1[[#This Row],[Cantidad de Insumos]] -> 0
B14: =IF(Tabla1[[#This Row],[Código_Actividad]]="","",CONCATENATE(Tabla1[[#This Row],[POA]],".",Tabla1[[#This Row],[SRS]],".",Tabla1[[#This Row],[AREA]],".",Tabla1[[#This Row],[TIPO]])) | L14: =+Tabla1[[#This Row],[Precio Unitario]]*Tabla1[[#This Row],[Cantidad de Insumos]] -> 0
B15: =IF(Tabla1[[#This Row],[Código_Actividad]]="","",CONCATENATE(Tabla1[[#This Row],[POA]],".",Tabla1[[#This Row],[SRS]],".",Tabla1[[#This Row],[AREA]],".",Tabla1[[#This Row],[TIPO]])) | L15: =+Tabla1[[#This Row],[Precio Unitario]]*Tabla1[[#This Row],[Cantidad de Insumos]] -> 0
B16: =IF(Tabla1[[#This Row],[Código_Actividad]]="","",CONCATENATE(Tabla1[[#This Row],[POA]],".",Tabla1[[#This Row],[SRS]],".",Tabla1[[#This Row],[AREA]],".",Tabla1[[#This Row],[TIPO]])) | L16: =+Tabla1[[#This Row],[Precio Unitario]]*Tabla1[[#This Row],[Cantidad de Insumos]] -> 0
B17: =IF(Tabla1[[#This Row],[Código_Actividad]]="","",CONCATENATE(Tabla1[[#This Row],[POA]],".",Tabla1[[#This Row],[SRS]],".",Tabla1[[#This Row],[AREA]],".",Tabla1[[#This Row],[TIPO]])) | L17: =+Tabla1[[#This Row],[Precio Unitario]]*Tabla1[[#This Row],[Cantidad de Insumos]] -> 0
B18: =IF(Tabla1[[#This Row],[Código_Actividad]]="","",CONCATENATE(Tabla1[[#This Row],[POA]],".",Tabla1[[#This Row],[SRS]],".",Tabla1[[#This Row],[AREA]],".",Tabla1[[#This Row],[TIPO]])) | L18: =+Tabla1[[#This Row],[Precio Unitario]]*Tabla1[[#This Row],[Cantidad de Insumos]] -> 0
B19: =IF(Tabla1[[#This Row],[Código_Actividad]]="","",CONCATENATE(Tabla1[[#This Row],[POA]],".",Tabla1[[#This Row],[SRS]],".",Tabla1[[#This Row],[AREA]],".",Tabla1[[#This Row],[TIPO]])) | L19: =+Tabla1[[#This Row],[Precio Unitario]]*Tabla1[[#This Row],[Cantidad de Insumos]] -> 0
B20: =IF(Tabla1[[#This Row],[Código_Actividad]]="","",CONCATENATE(Tabla1[[#This Row],[POA]],".",Tabla1[[#This Row],[SRS]],".",Tabla1[[#This Row],[AREA]],".",Tabla1[[#This Row],[TIPO]])) | L20: =+Tabla1[[#This Row],[Precio Unitario]]*Tabla1[[#This Row],[Cantidad de Insumos]] -> 0
... B214: =IF(Tabla1[[#This Row],[Código_Actividad]]="","",CONCATENATE(Tabla1[[#This Row],[POA]],".",Tabla1[[#This Row],[SRS]],".",Tabla1[[#This Row],[AREA]],".",Tabla1[[#This Row],[TIPO]])) | L214: =+Tabla1[[#This Row],[Precio Unitario]]*Tabla1[[#This Row],[Cantidad de Insumos]] -> 0

Sheet PPNE3
A1: =+PPNE1!B1 -> Plan Operativo Anual
A2: =+PPNE1!B2 -> Servicio Nacional de Salud
A3: =+PPNE1!B3 -> Dirección de Planificación y Desarrollo
A4: Estimación de Ingresos
A5: =+PPNE1!C5 -> 2026
A6: Servicio Regional de Salud: | E6: =+PPNE1!B6 -> Cibao Norte
A7: CEAS: | E7: =+PPNE1!B7 -> 0
A8: Grupo | B8: Subgrupo | C8: Cuenta | D8: Auxiliar | E8: Descripción Ingresos por Cuenta | F8: Valor RD$ | G8: %
A9: 3 | E9: Donaciones | F9: =+F10 -> 0 | G9: =G10 -> 0
B10: 31 | E10: Donaciones Corrientes | F10: =SUM(F11:F11) -> 0 | G10: =G11 -> 0
C11: 312 | E11: Donaciones corrientes de organismos internacionales | F11: 0 | G11: =IFERROR(F11/$F$31*100,"0.00") -> 0
A12: 4 | E12: Transferencias | F12: =+F13+F19 -> 1650000000 | G12: =G13+G19 -> 94.657767
B13: 41 | E13: Transferencias Corrientes | F13: =SUM(F15:F18) -> 1650000000 | G13: =SUM(G15:G18) -> 94.657767
C14: 413 | E14: Transferencias Corrientes Recibidas de Instituciones Públicas Descentralizas y Autonomas No Financieras | F14: =SUM(F16:F19) -> 1650000000 | G14: =SUM(G16:G19) -> 94.657767
C15: 413 | D15: ´01 | E15: Aportes SNS Nomina | F15: 0 | G15: =IFERROR(F15/$F$31*100,"0.00") -> 0
C16: 413 | D16: ´02 | E16: Anticipos Financieros | F16: 0 | G16: =IFERROR(F16/$F$31*100,"0.00") -> 0
C17: 413 | D17: ´03 | E17: Aportes SNS Medicamentos | F17: 0 | G17: =IFERROR(F17/$F$31*100,"0.00") -> 0
C18: 414 | E18: Transferencias Corrientes Recibidas de Instituciones Públicas de la Seguridad Social | F18: 1650000000 | G18: =IFERROR(F18/$F$31*100,"0.00") -> 94.657767
B19: 42 | E19: Transferencia de Capital | F19: =SUM(F21:F22) -> 0 | G19: =G21+G22 -> 0
C20: 423 | E20: Tranferencia de Capital Recibidas de Instituciones Públicas Descentralizas y Autonomas No Financieras | F20: =+F21+F22 -> 0 | G20: =+G21+G22 -> 0
C21: 423 | D21: ´01 | E21: Aportes SNS Equipamiento | F21: 0 | G21: =IFERROR(F21/$F$31*100,"0.00") -> 0
C22: 423 | D22: ´02 | E22: Aportes para otros gastos de inversión del SNS | F22: 0 | G22: =IFERROR(F22/$F$31*100,"0.00") -> 0
A23: 5 | E23: Ingresos por Contraprestación | F23: =+F24 -> 93121627 | G23: =G24 -> 5.3422335
B24: 51 | E24: Venta de Bienes y Servicios | F24: =F25 -> 93121627 | G24: =G25 -> 5.3422335
C25: 512 | E25: Venta de Servicios del Estado | F25: =F26 -> 93121627 | G25: =G26 -> 5.3422335
C26: 512 | D26: ´99 | E26: Otras ventas de servicios | F26: =+F27+F28+F29+F30 -> 93121627 | G26: =+G27+G28+G29+G30 -> 5.3422335
C27: 513 | E27: Venta de Servicios a SENASA por afiliados regimen subsidiado | F27: 44698381 | G27: =IFERROR(F27/$F$31*100,"0.00") -> 2.5642721
C28: 512 | E28: Venta de Servicios a SENASA por afiliados regimen contributivo | F28: 20486758 | G28: =IFERROR(F28/$F$31*100,"0.00") -> 1.1752914
C29: 512 | E29: Venta de Servicios a otras ARS por atencion a Regimen contributivo | F29: 27936488 | G29: =IFERROR(F29/$F$31*100,"0.00") -> 1.60267
C30: 512 | E30: Venta de Servicios a ARL | F30: 0 | G30: =IFERROR(F30/$F$31*100,"0.00") -> 0
E31: Total Ingresos | F31: =+F23+F12+F9 -> 1.7431216e+09 | G31: =+G23+G12+G9 -> 100

Sheet PPNE4
A1: =+PPNE1!B1 -> Plan Operativo Anual
A2: Servicio Nacional de Salud
A3: Dirección de Planificación y Desarrollo
A4: Consolidado Presupuesto Estimado de Ingresos y Gastos Nivel Especializado por Actividad Especifica
A5: =+PPNE1!C5 -> 2026
A6: Servicio Regional de Salud: | F6: =+PPNE1!B6 -> Cibao Norte
A7: Establecimiento: | F7: =+PPNE1!B7 -> 0
A8: Estimación de Ingresos
A9: Anticipos Financieros | G9: =+PPNE3!F16 -> 0
A10: Venta de Servicios y Otros Ingresos | G10: =+PPNE3!F25 -> 93121627
A11: Aportes SNS Nómina | G11: =+PPNE3!F15 -> 0
A12: Otros Aportes | G12: =+PPNE3!F9+PPNE3!F17+PPNE3!F21+PPNE3!F22 -> 0
A13: Transferencias Corrientes | G13: =+PPNE3!F18 -> 1650000000
A14: Total Ingresos RD$ | G14: =SUM(G9:G13) -> 1.7431216e+09
A15: Estimación de Gastos
A16: Tipo | B16: Objeto | C16: Cuenta | D16: Sub-Cuenta | E16: Auxiliar | F16: Descripción Gasto por Cuenta | G16: Consultas Externa | H16: Emergencias | I16: Hospitalización | J16: Apoyo Diagnóstico | L16: Servicios de Apoyo | N16: Total RD$ | O16: %
J17: Servicios de Laboratorios y Banco de Sangre | K17: Servicios de Imágenes RX | L17: Gestión de Usuario y Educación para la Salud | M17: Gestión Técnica y Administrativa
A18: 2 | F18: Egresos | G18: =+G19+G67+G171+G255+G272+G325 -> 1.7043851e+08 | H18: =+H19+H67+H171+H255+H272+H325 -> 1.653273e+08 | I18: =+I19+I67+I171+I255+I272+I325 -> 6.316076e+08 | J18: =+J19+J67+J171+J255+J272+J325 -> 1.3001682e+08 | K18: =+K19+K67+K171+K255+K272+K325 -> 1.3697676e+08 | L18: =+L19+L67+L171+L255+L272+L325 -> 1.2368163e+08 | M18: =+M19+M67+M171+M255+M272+M325 -> 3.85073e+08 | N18: =+N19+N67+N171+N255+N272+N325 -> 1.7431216e+09 | O18: =IFERROR(N18/$N$18*100,"0.00")/100 -> 1
A19: 2 | B19: 1 | F19: Servicios Personales | G19: =+G20+G42+G54+G58 -> 1.6622686e+08 | H19: =+H20+H42+H54+H58 -> 1.3908833e+08 | I19: =+I20+I42+I54+I58 -> 3.9523521e+08 | J19: =+J20+J42+J54+J58 -> 96211128 | K19: =+K20+K42+K54+K58 -> 1.282815e+08 | L19: =+L20+L42+L54+L58 -> 1.2164178e+08 | M19: =+M20+M42+M54+M58 -> 2.0352553e+08 | N19: =+G19+H19+I19+J19+K19+L19+M19 -> 1.2502103e+09 | O19: =IFERROR(N19/$N$18*100,"0.00")/100 -> 0.71722496
A20: 2 | B20: 1 | C20: 1 | F20: Remuneraciones | G20: =+G21+G26+G33+G35+G37 -> 1.3150267e+08 | H20: =+H21+H26+H33+H35+H37 -> 1.0648276e+08 | I20: =+I21+I26+I33+I35+I37 -> 3.0683956e+08 | J20: =+J21+J26+J33+J35+J37 -> 78901601 | K20: =+K21+K26+K33+K35+K37 -> 1.0520213e+08 | L20: =+L21+L26+L33+L35+L37 -> 96435290 | M20: =+M21+M26+M33+M35+M37 -> 1.9290661e+08 | N20: =+G20+H20+I20+J20+K20+L20+M20 -> 1.0182706e+09 | O20: =IFERROR(N20/$N$18*100,"0.00")/100 -> 0.58416499
A21: 2 | B21: 1 | C21: 1 | D21: 1 | F21: Remuneraciones al personal fijo | G21: =SUM(G22:G25) -> 1.2190495e+08 | H21: =SUM(H22:H25) -> 1.0565095e+08 | I21: =SUM(I22:I25) -> 2.8444487e+08 | J21: =SUM(J22:J25) -> 73142968 | K21: =SUM(K22:K25) -> 97523957 | L21: =SUM(L22:L25) -> 89396960 | M21: =SUM(M22:M25) -> 40634982 | N21: =+G21+H21+I21+J21+K21+L21+M21 -> 8.1269964e+08 | O21: =IFERROR(N21/$N$18*100,"0.00")/100 -> 0.46623232
A22: 2 | B22: 1 | C22: 1 | D22: 1 | E22: `01 | F22: Sueldos fijos | G22: =812699639.34*0.15 -> 1.2190495e+08 | H22: =812699639.34*0.13 -> 1.0565095e+08 | I22: =812699639.34*0.35 -> 2.8444487e+08 | J22: =812699639.34*0.09 -> 73142968 | K22: =812699639.34*0.12 -> 97523957 | L22: =812699639.34*0.11 -> 89396960 | M22: 40634982 | N22: =+G22+H22+I22+J22+K22+L22+M22 -> 8.1269964e+08 | O22: =IFERROR(N22/$N$18*100,"0.00")/100 -> 0.46623232
A23: 2 | B23: 1 | C23: 1 | D23: 1 | E23: `02 | F23: Sueldos a medicos | N23: =+G23+H23+I23+J23+K23+L23+M23 -> 0 | O23: =IFERROR(N23/$N$18*100,"0.00")/100 -> 0
A24: 2 | B24: 1 | C24: 1 | D24: 1 | E24: `05 | F24: Incentivos y escalafón | N24: =+G24+H24+I24+J24+K24+L24+M24 -> 0 | O24: =IFERROR(N24/$N$18*100,"0.00")/100 -> 0
A25: 2 | B25: 1 | C25: 1 | D25: 1 | E25: `06 | F25: Nuevas plazas a medicos | N25: =+G25+H25+I25+J25+K25+L25+M25 -> 0 | O25: =IFERROR(N25/$N$18*100,"0.00")/100 -> 0
A26: 2 | B26: 1 | C26: 1 | D26: 2 | F26: Remuneraciones al personal con carácter transitorio | G26: =SUM(G27:G32) -> 0 | H26: =SUM(H27:H32) -> 0 | I26: =SUM(I27:I32) -> 0 | J26: =SUM(J27:J32) -> 0 | K26: =SUM(K27:K32) -> 0 | L26: =SUM(L27:L32) -> 0 | M26: =SUM(M27:M32) -> 1.4007194e+08 | N26: =+G26+H26+I26+J26+K26+L26+M26 -> 1.4007194e+08 | O26: =IFERROR(N26/$N$18*100,"0.00")/100 -> 0.08035695
A27: 2 | B27: 1 | C27: 1 | D27: 2 | E27: `03 | F27: Suplencias | N27: =+G27+H27+I27+J27+K27+L27+M27 -> 0 | O27: =IFERROR(N27/$N$18*100,"0.00")/100 -> 0
A28: 2 | B28: 1 | C28: 1 | D28: 2 | E28: `05 | F28: Sueldo al personal nominal en período probatorio | N28: =+G28+H28+I28+J28+K28+L28+M28 -> 0 | O28: =IFERROR(N28/$N$18*100,"0.00")/100 -> 0
A29: 2 | B29: 1 | C29: 1 | D29: 2 | E29: `06 | F29: Jornales | N29: =+G29+H29+I29+J29+K29+L29+M29 -> 0 | O29: =IFERROR(N29/$N$18*100,"0.00")/100 -> 0
A30: 2 | B30: 1 | C30: 1 | D30: 2 | E30: `08 | F30: Empleados temporales | M30: 1.4007194e+08 | N30: =+G30+H30+I30+J30+K30+L30+M30 -> 1.4007194e+08 | O30: =IFERROR(N30/$N$18*100,"0.00")/100 -> 0.08035695
A31: 2 | B31: 1 | C31: 1 | D31: 2 | E31: `09 | F31: Personal de carácter eventual | N31: =+G31+H31+I31+J31+K31+L31+M31 -> 0 | O31: =IFERROR(N31/$N$18*100,"0.00")/100 -> 0
A32: 2 | B32: 1 | C32: 1 | D32: 2 | E32: `11 | F32: Interinato | N32: =+G32+H32+I32+J32+K32+L32+M32 -> 0 | O32: =IFERROR(N32/$N$18*100,"0.00")/100 -> 0
A33: 2 | B33: 1 | C33: 1 | D33: 3 | F33: Sueldos al personal fijo en trámite de pensiones | G33: =G34 -> 0 | H33: =H34 -> 0 | I33: =I34 -> 0 | J33: =J34 -> 0 | K33: =K34 -> 0 | L33: =L34 -> 0 | M33: =M34 -> 0 | N33: =+G33+H33+I33+J33+K33+L33+M33 -> 0 | O33: =IFERROR(N33/$N$18*100,"0.00")/100 -> 0
A34: 2 | B34: 1 | C34: 1 | D34: 3 | E34: `01 | F34: Sueldos al personal fijo en trámite de pensiones | N34: =+G34+H34+I34+J34+K34+L34+M34 -> 0 | O34: =IFERROR(N34/$N$18*100,"0.00")/100 -> 0
A35: 2 | B35: 1 | C35: 1 | D35: 4 | F35: Sueldo anual No. 13 | G35: =G36 -> 9597721.9 | H35: =H36 -> 831802.62 | I35: =I36 -> 22394684 | J35: =J36 -> 5758633.1 | K35: =K36 -> 7678177.5 | L35: =L36 -> 7038329.4 | M35: =M36 -> 10685464 | N35: =+G35+H35+I35+J35+K35+L35+M35 -> 63984813 | O35: =IFERROR(N35/$N$18*100,"0.00")/100 -> 0.036707027
A36: 2 | B36: 1 | C36: 1 | D36: 4 | E36: `01 | F36: Sueldo anual No. 13 | G36: =63984812.73*0.15 -> 9597721.9 | H36: =6398481.73*0.13 -> 831802.62 | I36: =63984812.73*0.35 -> 22394684 | J36: =63984812.73*0.09 -> 5758633.1 | K36: =63984812.73*0.12 -> 7678177.5 | L36: =63984812.73*0.11 -> 7038329.4 | M36: 10685464 | N36: =+G36+H36+I36+J36+K36+L36+M36 -> 63984813 | O36: =IFERROR(N36/$N$18*100,"0.00")/100 -> 0.036707027
A37: 2 | B37: 1 | C37: 1 | D37: 5 | F37: Prestacianes economicas | G37: =SUM(G38:G41) -> 0 | H37: =SUM(H38:H41) -> 0 | I37: =SUM(I38:I41) -> 0 | J37: =SUM(J38:J41) -> 0 | K37: =SUM(K38:K41) -> 0 | L37: =SUM(L38:L41) -> 0 | M37: =SUM(M38:M41) -> 1514231.2 | N37: =+G37+H37+I37+J37+K37+L37+M37 -> 1514231.2 | O37: =IFERROR(N37/$N$18*100,"0.00")/100 -> 0.00086868937
A38: 2 | B38: 1 | C38: 1 | D38: 5 | E38: `01 | F38: Prestacianes economicas | N38: =+G38+H38+I38+J38+K38+L38+M38 -> 0 | O38: =IFERROR(N38/$N$18*100,"0.00")/100 -> 0
A39: 2 | B39: 1 | C39: 1 | D39: 5 | E39: `02 | F39: Pago de porcentaje por desvinculación de cargo | N39: =+G39+H39+I39+J39+K39+L39+M39 -> 0 | O39: =IFERROR(N39/$N$18*100,"0.00")/100 -> 0
A40: 2 | B40: 1 | C40: 1 | D40: 5 | E40: `03 | F40: Prestacion laboral por desvinculación | M40: 907400 | N40: =+G40+H40+I40+J40+K40+L40+M40 -> 907400 | O40: =IFERROR(N40/$N$18*100,"0.00")/100 -> 0.00052056035
...

Sheet PPNE5
A1: =+PPNE1!B1 -> Plan Operativo Anual
A2: Servicio Nacional de Salud
A3: Dirección de Planificación y Desarrollo
A4: Consolidado Presupuesto Estimado de Ingresos y Gastos Nivel Especializado por Fuente de Financiamiento
A5: =+PPNE1!C5 -> 2026
A6: Servicio Regional de Salud: | F6: =+PPNE1!B6 -> Cibao Norte
A7: Establecimiento: | F7: =+PPNE1!B7 -> 0
A8: Estimación de Ingresos
A9: Anticipos Financieros | G9: =+PPNE3!F16 -> 0
A10: Venta de Servicios y Otros Ingresos | G10: =+PPNE3!F25 -> 93121627
A11: Aportes SNS Nómina | G11: =+PPNE3!F15 -> 0
A12: Otros Aportes | G12: =+PPNE3!F9+PPNE3!F17+PPNE3!F21+PPNE3!F22 -> 0
A13: Transferencias Corrientes | G13: =+PPNE3!F18 -> 1650000000
A14: Total Ingresos RD$ | G14: =SUM(G9:G13) -> 1.7431216e+09
A15: Estimación de Gastos
A16: Tipo | B16: Objeto | C16: Cuenta | D16: Sub-Cuenta | E16: Auxiliar | F16: Descripción Gasto por Cuenta | G16: Anticipos Financieros / Transferencias | H16: Venta de Servicios | I16: Nómina | J16: Total RD$ | K16: %
A18: 2 | F18: Egresos | G18: =+G19+G67+G170+G254+G270 -> 1.65e+09 | H18: =+H19+H67+H170+H254+H270+H323 -> 93121627 | I18: =+I19+I67+I170+I254+I270+I323 -> 0 | J18: =+J19+J67+J170+J254+J270 -> 1.7431216e+09 | K18: =IFERROR(J18/$J$18*100,"0.00")/100 -> 1
A19: 2 | B19: 1 | F19: Servicios Personales | G19: =+G20+G42+G54+G58 -> 1.2502103e+09 | H19: =+H20+H42+H54+H58 -> 0 | I19: =+I20+I47+I63+I70+I78 -> 0 | J19: =+G19+H19 -> 1.2502103e+09 | K19: =IFERROR(J19/$J$18*100,"0.00")/100 -> 0.71722496
A20: 2 | B20: 1 | C20: 1 | F20: Remuneraciones | G20: =+G21+G26+G33+G35+G37 -> 1.0182706e+09 | H20: =+H21+H28+H36+H38+H40+H45 -> 0 | I20: =+I21+I28+I36+I38+I40+I45 -> 0 | J20: =+G20+H20 -> 1.0182706e+09 | K20: =IFERROR(J20/$J$18*100,"0.00")/100 -> 0.58416499
A21: 2 | B21: 1 | C21: 1 | D21: 1 | F21: Remuneraciones al personal fijo | G21: =SUM(G22:G25) -> 8.1269964e+08 | H21: =SUM(H22:H27) -> 0 | I21: =SUM(I22:I27) -> 0 | J21: =+G21+H21 -> 8.1269964e+08 | K21: =IFERROR(J21/$J$18*100,"0.00")/100 -> 0.46623232
A22: 2 | B22: 1 | C22: 1 | D22: 1 | E22: `01 | F22: Sueldos fijos | G22: 8.1269964e+08 | J22: =+G22+H22 -> 8.1269964e+08 | K22: =IFERROR(J22/$J$18*100,"0.00")/100 -> 0.46623232
A23: 2 | B23: 1 | C23: 1 | D23: 1 | E23: `02 | F23: Sueldos a medicos | J23: =+G23+H23 -> 0 | K23: =IFERROR(J23/$J$18*100,"0.00")/100 -> 0
A24: 2 | B24: 1 | C24: 1 | D24: 1 | E24: `05 | F24: Incentivos y escalafón | J24: =+G24+H24 -> 0 | K24: =IFERROR(J24/$J$18*100,"0.00")/100 -> 0
A25: 2 | B25: 1 | C25: 1 | D25: 1 | E25: `06 | F25: Nuevas plazas a medicos | J25: =+G25+H25 -> 0 | K25: =IFERROR(J25/$J$18*100,"0.00")/100 -> 0
