Workbook

Sheet ABRIL 
A1: Form. No.6 SRS
A3: Servicio Nacional de Salud
A4: Dirección de Fizcalización
A5: Consolidado de Ingresos y Gastos por Fuente de Financiamiento
A6: HOSPITAL MATERNO INFANTIL SAN LORENZO DE LOS MINA
A7: ABRIL 2025
C8: Ingresos Generales:
E9: 1.- Balance Inicial / Fuente:
E10: Anticipo Financiero | H10: Otros Aportes
E11: Transferencias Corrientes
E12: Venta de Servicios | G12: 4614.79
E13: 2.- Ingresos por Fuente / Cuenta
E14: Anticipo Financiero | H14: Otros Aportes | I14: =+'[1]INGR SEGUN ORIGEN'!E39 -> 214750
E15: Transferencias Corrientes | G15: =+'[1]INGR SEGUN ORIGEN'!E12 -> 1.007793e+08 | H15: Aportes Nomina SNS | I15: 0
E16: Venta de Servicios | G16: =+'[1]INGR SEGUN ORIGEN'!E32 -> 6892064.8
H17: TOTAL INGRESOS RDS | I17: =+G10+G11+G12+I10+G14+G15+G16+I14+I15 -> 1.0789073e+08
A21: 1 | F21: 2 | G21: 3 | I21: 4 | J21: 5
A22: Código Presupuestario | F22: Descripción Gasto por Cuenta | G22: Distribución del Gasto por Fuente de Financiamiento | I22: TOTAL | J22: %
A23: Tipo | B23: Objeto | C23: Cuenta | D23: Sub-Cuenta | E23: Auxiliar | G23: Fondo 100 | H23: Venta de Servicios/ Otros Aportes
A25: 2 | F25: Gastos | G25: =+G26+G87+G212+G330+G336+G463 -> 91800340 | H25: =+H26+H87+H212+H330+H336+H463 -> 4881550.3 | I25: =SUM(G25:H25) -> 96681890 | J25: =+J26+J87+J212+J330+J336+J463 -> 1
A26: 2 | B26: 1 | F26: Servicios Personales | G26: =+G27+G51+G64+G71+G78 -> 66556156 | H26: =+H27+H51+H64+H71+H78 -> 0 | I26: =SUM(G26:H26) -> 66556156 | J26: =I26/$I$25 -> 0.68840355
A27: 2 | B27: 1 | C27: 1 | F27: Remuneraciones | G27: =+G28+G35+G42+G44+G46 -> 54771097 | H27: =+H28+H35+H42+H44+H46 -> 0 | I27: =SUM(G27:H27) -> 54771097 | J27: =I27/$I$25 -> 0.56650834
A28: 2 | B28: 1 | C28: 1 | D28: 1 | F28: Remuneraciones al personal fijo | G28: =SUM(G29:G34) -> 53482455 | H28: =SUM(H29:H34) -> 0 | I28: =SUM(G28:H28) -> 53482455 | J28: =I28/$I$25 -> 0.55317966
A29: 2 | B29: 1 | C29: 1 | D29: 1 | E29: 01 | F29: Sueldos a empleados fijos | G29: ='[1]CUENTA T FONDO 100'!A127 -> 53482455 | H29: ='[1]CUENTA T VS'!A89 -> 0 | I29: =SUM(G29:H29) -> 53482455 | J29: =I29/$I$25 -> 0.55317966
A30: 2 | B30: 1 | C30: 1 | D30: 1 | E30: 02 | F30: Sueldos a médicos | G30: ='[1]CUENTA T FONDO 100'!B127 -> 0 | H30: ='[1]CUENTA T VS'!B89 -> 0 | I30: =SUM(G30:H30) -> 0 | J30: =I30/$I$25 -> 0
A31: 2 | B31: 1 | C31: 1 | D31: 1 | E31: 03 | F31: Ascensos a militares | G31: ='[1]CUENTA T FONDO 100'!C127 -> 0 | H31: ='[1]CUENTA T VS'!C89 -> 0 | I31: =SUM(G31:H31) -> 0 | J31: =I31/$I$25 -> 0
A32: 2 | B32: 1 | C32: 1 | D32: 1 | E32: 04 | F32: Nuevas plazas maestros | G32: ='[1]CUENTA T FONDO 100'!D127 -> 0 | H32: ='[1]CUENTA T VS'!D89 -> 0 | I32: =SUM(G32:H32) -> 0 | J32: =I32/$I$25 -> 0
A33: 2 | B33: 1 | C33: 1 | D33: 1 | E33: 05 | F33: Incentivos y escalafón | G33: ='[1]CUENTA T FONDO 100'!E127 -> 0 | H33: ='[1]CUENTA T VS'!E89 -> 0 | I33: =SUM(G33:H33) -> 0 | J33: =I33/$I$25 -> 0
A34: 2 | B34: 1 | C34: 1 | D34: 1 | E34: 06 | F34: Nuevas plazas a médicos | G34: ='[1]CUENTA T FONDO 100'!F127 -> 0 | H34: ='[1]CUENTA T VS'!F89 -> 0 | I34: =SUM(G34:H34) -> 0 | J34: =I34/$I$25 -> 0
A35: 2 | B35: 1 | C35: 1 | D35: 2 | F35: Remuneraciones al personal con carácter transitorio | G35: =SUM(G36:G41) -> 1107531 | H35: =SUM(H36:H41) -> 0 | I35: =SUM(G35:H35) -> 1107531
A36: 2 | B36: 1 | C36: 1 | D36: 2 | E36: 03 | F36: Suplencias | G36: ='[1]CUENTA T FONDO 100'!G127 -> 0 | H36: ='[1]CUENTA T VS'!G89 -> 0 | I36: =SUM(G36:H36) -> 0 | J36: =I36/$I$25 -> 0
A37: 2 | B37: 1 | C37: 1 | D37: 2 | E37: 05 | F37: Sueldo al personal nominal en período probatorio | G37: ='[1]CUENTA T FONDO 100'!H127 -> 0 | H37: ='[1]CUENTA T VS'!H89 -> 0 | I37: =SUM(G37:H37) -> 0 | J37: =I37/$I$25 -> 0
A38: 2 | B38: 1 | C38: 1 | D38: 2 | E38: 06 | F38: Jornales | G38: ='[1]CUENTA T FONDO 100'!I127 -> 0 | H38: ='[1]CUENTA T VS'!I89 -> 0 | I38: =SUM(G38:H38) -> 0 | J38: =I38/$I$25 -> 0
A39: 2 | B39: 1 | C39: 1 | D39: 2 | E39: 08 | F39: Empleados temporales | G39: ='[1]CUENTA T FONDO 100'!J127 -> 1107531 | H39: ='[1]CUENTA T VS'!J89 -> 0 | I39: =SUM(G39:H39) -> 1107531 | J39: =I39/$I$25 -> 0.011455414
A40: 2 | B40: 1 | C40: 1 | D40: 2 | E40: 09 | F40: Personal de carácter eventual | G40: ='[1]CUENTA T FONDO 100'!K127 -> 0 | H40: ='[1]CUENTA T VS'!K89 -> 0 | I40: =SUM(G40:H40) -> 0 | J40: =I40/$I$25 -> 0
A41: 2 | B41: 1 | C41: 1 | D41: 2 | E41: 11 | F41: Interinato | G41: ='[1]CUENTA T FONDO 100'!L127 -> 0 | H41: ='[1]CUENTA T VS'!L89 -> 0 | I41: =SUM(G41:H41) -> 0 | J41: =I41/$I$25 -> 0
A42: 2 | B42: 1 | C42: 1 | D42: 3 | F42: Sueldos al personal fijo en trámite de pensiones | G42: =SUM(G43) -> 0 | H42: =SUM(H43) -> 0 | I42: =SUM(G42:H42) -> 0
A43: 2 | B43: 1 | C43: 1 | D43: 3 | E43: 01 | F43: Sueldos al personal fijo en trámite de pensiones | G43: ='[1]CUENTA T FONDO 100'!M127 -> 0 | H43: ='[1]CUENTA T VS'!M89 -> 0 | I43: =SUM(G43:H43) -> 0 | J43: =I43/$I$25 -> 0
A44: 2 | B44: 1 | C44: 1 | D44: 4 | F44: Sueldo anual no. 13 | G44: =SUM(G45) -> 0 | H44: =SUM(H45) -> 0 | I44: =SUM(G44:H44) -> 0
A45: 2 | B45: 1 | C45: 1 | D45: 4 | E45: 01 | F45: Sueldo anual no. 13 | G45: ='[1]CUENTA T FONDO 100'!N127 -> 0 | H45: ='[1]CUENTA T VS'!N89 -> 0 | I45: =SUM(G45:H45) -> 0 | J45: =I45/$I$25 -> 0
...

Sheet mayo 2025
A1: Form. No.6 SRS
A3: Servicio Nacional de Salud
A4: Dirección de Fizcalización
A5: Consolidado de Ingresos y Gastos por Fuente de Financiamiento
A6: HOSPITAL MATERNO INFANTIL SAN LORENZO DE LOS MINA
A7: MAYO 2025
C8: Ingresos Generales:
E9: 1.- Balance Inicial / Fuente:
E10: Anticipo Financiero | H10: Otros Aportes
E11: Transferencias Corrientes
E12: Venta de Servicios | G12: 1731116.6
E13: 2.- Ingresos por Fuente / Cuenta
E14: Anticipo Financiero | G14: 0 | H14: Otros Aportes | I14: =+'[2]INGR SEGUN ORIGEN'!E37 -> 574300
E15: Transferencias Corrientes | G15: =+'[2]INGR SEGUN ORIGEN'!E12 -> 1.003168e+08 | H15: Aportes Nomina SNS | I15: 0
E16: Venta de Servicios | G16: =+'[2]INGR SEGUN ORIGEN'!E29 -> 7518709.1
H17: TOTAL INGRESOS RDS | I17: =+G10+G11+G12+I10+G14+G15+G16+I14+I15 -> 1.1014092e+08
A21: 1 | F21: 2 | G21: 3 | I21: 4 | J21: 5
A22: Código Presupuestario | F22: Descripción Gasto por Cuenta | G22: Distribución del Gasto por Fuente de Financiamiento | I22: TOTAL | J22: %
A23: Tipo | B23: Objeto | C23: Cuenta | D23: Sub-Cuenta | E23: Auxiliar | G23: Fondo 100 | H23: Venta de Servicios/ Otros Aportes
A25: 2 | F25: Gastos | G25: =+G26+G87+G212+G330+G336+G463 -> 91500562 | H25: =+H26+H87+H212+H330+H336+H463 -> 9009314.4 | I25: =SUM(G25:H25) -> 1.0050988e+08 | J25: =+J26+J87+J212+J330+J336+J463 -> 1
A26: 2 | B26: 1 | F26: Servicios Personales | G26: =+G27+G51+G64+G71+G78 -> 66630551 | H26: =+H27+H51+H64+H71+H78 -> 0 | I26: =SUM(G26:H26) -> 66630551 | J26: =I26/$I$25 -> 0.66292541
A27: 2 | B27: 1 | C27: 1 | F27: Remuneraciones | G27: =+G28+G35+G42+G44+G46 -> 54445140 | H27: =+H28+H35+H42+H44+H46 -> 0 | I27: =SUM(G27:H27) -> 54445140 | J27: =I27/$I$25 -> 0.54168946
A28: 2 | B28: 1 | C28: 1 | D28: 1 | F28: Remuneraciones al personal fijo | G28: =SUM(G29:G34) -> 53314609 | H28: =SUM(H29:H34) -> 0 | I28: =SUM(G28:H28) -> 53314609 | J28: =I28/$I$25 -> 0.5304415
A29: 2 | B29: 1 | C29: 1 | D29: 1 | E29: 01 | F29: Sueldos a empleados fijos | G29: ='[2]CUENTA T FONDO 100'!A126 -> 53314609 | H29: ='[2]CUENTA T VS'!A106 -> 0 | I29: =SUM(G29:H29) -> 53314609 | J29: =I29/$I$25 -> 0.5304415
A30: 2 | B30: 1 | C30: 1 | D30: 1 | E30: 02 | F30: Sueldos a médicos | G30: ='[2]CUENTA T FONDO 100'!B126 -> 0 | H30: ='[2]CUENTA T VS'!B106 -> 0 | I30: =SUM(G30:H30) -> 0 | J30: =I30/$I$25 -> 0
A31: 2 | B31: 1 | C31: 1 | D31: 1 | E31: 03 | F31: Ascensos a militares | G31: ='[2]CUENTA T FONDO 100'!C126 -> 0 | H31: ='[2]CUENTA T VS'!C106 -> 0 | I31: =SUM(G31:H31) -> 0 | J31: =I31/$I$25 -> 0
A32: 2 | B32: 1 | C32: 1 | D32: 1 | E32: 04 | F32: Nuevas plazas maestros | G32: ='[2]CUENTA T FONDO 100'!D126 -> 0 | H32: ='[2]CUENTA T VS'!D106 -> 0 | I32: =SUM(G32:H32) -> 0 | J32: =I32/$I$25 -> 0
A33: 2 | B33: 1 | C33: 1 | D33: 1 | E33: 05 | F33: Incentivos y escalafón | G33: ='[2]CUENTA T FONDO 100'!E126 -> 0 | H33: ='[2]CUENTA T VS'!E106 -> 0 | I33: =SUM(G33:H33) -> 0 | J33: =I33/$I$25 -> 0
A34: 2 | B34: 1 | C34: 1 | D34: 1 | E34: 06 | F34: Nuevas plazas a médicos | G34: ='[2]CUENTA T FONDO 100'!F126 -> 0 | H34: ='[2]CUENTA T VS'!F106 -> 0 | I34: =SUM(G34:H34) -> 0 | J34: =I34/$I$25 -> 0
A35: 2 | B35: 1 | C35: 1 | D35: 2 | F35: Remuneraciones al personal con carácter transitorio | G35: =SUM(G36:G41) -> 1130531 | H35: =SUM(H36:H41) -> 0 | I35: =SUM(G35:H35) -> 1130531
A36: 2 | B36: 1 | C36: 1 | D36: 2 | E36: 03 | F36: Suplencias | G36: ='[2]CUENTA T FONDO 100'!G126 -> 0 | H36: ='[2]CUENTA T VS'!G106 -> 0 | I36: =SUM(G36:H36) -> 0 | J36: =I36/$I$25 -> 0
A37: 2 | B37: 1 | C37: 1 | D37: 2 | E37: 05 | F37: Sueldo al personal nominal en período probatorio | G37: ='[2]CUENTA T FONDO 100'!H126 -> 0 | H37: ='[2]CUENTA T VS'!H106 -> 0 | I37: =SUM(G37:H37) -> 0 | J37: =I37/$I$25 -> 0
A38: 2 | B38: 1 | C38: 1 | D38: 2 | E38: 06 | F38: Jornales | G38: ='[2]CUENTA T FONDO 100'!I126 -> 0 | H38: ='[2]CUENTA T VS'!I106 -> 0 | I38: =SUM(G38:H38) -> 0 | J38: =I38/$I$25 -> 0
A39: 2 | B39: 1 | C39: 1 | D39: 2 | E39: 08 | F39: Empleados temporales | G39: ='[2]CUENTA T FONDO 100'!J126 -> 1130531 | H39: ='[2]CUENTA T VS'!J106 -> 0 | I39: =SUM(G39:H39) -> 1130531 | J39: =I39/$I$25 -> 0.01124796
A40: 2 | B40: 1 | C40: 1 | D40: 2 | E40: 09 | F40: Personal de carácter eventual | G40: ='[2]CUENTA T FONDO 100'!K126 -> 0 | H40: ='[2]CUENTA T VS'!K106 -> 0 | I40: =SUM(G40:H40) -> 0 | J40: =I40/$I$25 -> 0
A41: 2 | B41: 1 | C41: 1 | D41: 2 | E41: 11 | F41: Interinato | G41: ='[2]CUENTA T FONDO 100'!L126 -> 0 | H41: ='[2]CUENTA T VS'!L106 -> 0 | I41: =SUM(G41:H41) -> 0 | J41: =I41/$I$25 -> 0
A42: 2 | B42: 1 | C42: 1 | D42: 3 | F42: Sueldos al personal fijo en trámite de pensiones | G42: =SUM(G43) -> 0 | H42: =SUM(H43) -> 0 | I42: =SUM(G42:H42) -> 0
A43: 2 | B43: 1 | C43: 1 | D43: 3 | E43: 01 | F43: Sueldos al personal fijo en trámite de pensiones | G43: ='[2]CUENTA T FONDO 100'!M126 -> 0 | H43: ='[2]CUENTA T VS'!M106 -> 0 | I43: =SUM(G43:H43) -> 0 | J43: =I43/$I$25 -> 0
A44: 2 | B44: 1 | C44: 1 | D44: 4 | F44: Sueldo anual no. 13 | G44: =SUM(G45) -> 0 | H44: =SUM(H45) -> 0 | I44: =SUM(G44:H44) -> 0
A45: 2 | B45: 1 | C45: 1 | D45: 4 | E45: 01 | F45: Sueldo anual no. 13 | G45: ='[2]CUENTA T FONDO 100'!N126 -> 0 | H45: ='[2]CUENTA T VS'!N106 -> 0 | I45: =SUM(G45:H45) -> 0 | J45: =I45/$I$25 -> 0
...

Sheet junioo 
A1: Form. No.6 SRS
A3: Servicio Nacional de Salud
A4: Dirección de Fizcalización
A5: Consolidado de Ingresos y Gastos por Fuente de Financiamiento
A6: HOSPITAL MATERNO INFANTIL SAN LORENZO DE LOS MINA
A7: JUNIO 2025
C8: Ingresos Generales:
E9: 1.- Balance Inicial / Fuente:
E10: Anticipo Financiero | H10: Otros Aportes
E11: Transferencias Corrientes
E12: Venta de Servicios | G12: 1377881.2
E13: 2.- Ingresos por Fuente / Cuenta
E14: Anticipo Financiero | G14: 0 | H14: Otros Aportes | I14: =+'[3]INGR SEGUN ORIGEN'!E31 -> 1026168.7
E15: Transferencias Corrientes | G15: =+'[3]INGR SEGUN ORIGEN'!E12 -> 1.003168e+08 | H15: Aportes Nomina SNS | I15: 0
E16: Venta de Servicios | G16: =+'[3]INGR SEGUN ORIGEN'!E23 -> 3631511.4
H17: TOTAL INGRESOS RDS | I17: =+G10+G11+G12+I10+G14+G15+G16+I14+I15 -> 1.0635236e+08
A21: 1 | F21: 2 | G21: 3 | I21: 4 | J21: 5
A22: Código Presupuestario | F22: Descripción Gasto por Cuenta | G22: Distribución del Gasto por Fuente de Financiamiento | I22: TOTAL | J22: %
A23: Tipo | B23: Objeto | C23: Cuenta | D23: Sub-Cuenta | E23: Auxiliar | G23: Fondo 100 | H23: Venta de Servicios/ Otros Aportes
A25: 2 | F25: Gastos | G25: =+G26+G87+G212+G330+G336+G463 -> 93930744 | H25: =+H26+H87+H212+H330+H336+H463 -> 6513141.9 | I25: =SUM(G25:H25) -> 1.0044389e+08 | J25: =+J26+J87+J212+J330+J336+J463 -> 1
A26: 2 | B26: 1 | F26: Servicios Personales | G26: =+G27+G51+G64+G71+G78 -> 66583615 | H26: =+H27+H51+H64+H71+H78 -> 0 | I26: =SUM(G26:H26) -> 66583615 | J26: =I26/$I$25 -> 0.66289366
A27: 2 | B27: 1 | C27: 1 | F27: Remuneraciones | G27: =+G28+G35+G42+G44+G46 -> 54868543 | H27: =+H28+H35+H42+H44+H46 -> 0 | I27: =SUM(G27:H27) -> 54868543 | J27: =I27/$I$25 -> 0.54626065
A28: 2 | B28: 1 | C28: 1 | D28: 1 | F28: Remuneraciones al personal fijo | G28: =SUM(G29:G34) -> 53275909 | H28: =SUM(H29:H34) -> 0 | I28: =SUM(G28:H28) -> 53275909 | J28: =I28/$I$25 -> 0.5304047
A29: 2 | B29: 1 | C29: 1 | D29: 1 | E29: 01 | F29: Sueldos a empleados fijos | G29: ='[3]CUENTA T FONDO 100'!A126 -> 53275909 | H29: ='[3]CUENTA T VS'!A106 -> 0 | I29: =SUM(G29:H29) -> 53275909 | J29: =I29/$I$25 -> 0.5304047
A30: 2 | B30: 1 | C30: 1 | D30: 1 | E30: 02 | F30: Sueldos a médicos | G30: ='[3]CUENTA T FONDO 100'!B126 -> 0 | H30: ='[3]CUENTA T VS'!B106 -> 0 | I30: =SUM(G30:H30) -> 0 | J30: =I30/$I$25 -> 0
A31: 2 | B31: 1 | C31: 1 | D31: 1 | E31: 03 | F31: Ascensos a militares | G31: ='[3]CUENTA T FONDO 100'!C126 -> 0 | H31: ='[3]CUENTA T VS'!C106 -> 0 | I31: =SUM(G31:H31) -> 0 | J31: =I31/$I$25 -> 0
A32: 2 | B32: 1 | C32: 1 | D32: 1 | E32: 04 | F32: Nuevas plazas maestros | G32: ='[3]CUENTA T FONDO 100'!D126 -> 0 | H32: ='[3]CUENTA T VS'!D106 -> 0 | I32: =SUM(G32:H32) -> 0 | J32: =I32/$I$25 -> 0
A33: 2 | B33: 1 | C33: 1 | D33: 1 | E33: 05 | F33: Incentivos y escalafón | G33: ='[3]CUENTA T FONDO 100'!E126 -> 0 | H33: ='[3]CUENTA T VS'!E106 -> 0 | I33: =SUM(G33:H33) -> 0 | J33: =I33/$I$25 -> 0
A34: 2 | B34: 1 | C34: 1 | D34: 1 | E34: 06 | F34: Nuevas plazas a médicos | G34: ='[3]CUENTA T FONDO 100'!F126 -> 0 | H34: ='[3]CUENTA T VS'!F106 -> 0 | I34: =SUM(G34:H34) -> 0 | J34: =I34/$I$25 -> 0
A35: 2 | B35: 1 | C35: 1 | D35: 2 | F35: Remuneraciones al personal con carácter transitorio | G35: =SUM(G36:G41) -> 1130531 | H35: =SUM(H36:H41) -> 0 | I35: =SUM(G35:H35) -> 1130531
A36: 2 | B36: 1 | C36: 1 | D36: 2 | E36: 03 | F36: Suplencias | G36: ='[3]CUENTA T FONDO 100'!G126 -> 0 | H36: ='[3]CUENTA T VS'!G106 -> 0 | I36: =SUM(G36:H36) -> 0 | J36: =I36/$I$25 -> 0
A37: 2 | B37: 1 | C37: 1 | D37: 2 | E37: 05 | F37: Sueldo al personal nominal en período probatorio | G37: ='[3]CUENTA T FONDO 100'!H126 -> 0 | H37: ='[3]CUENTA T VS'!H106 -> 0 | I37: =SUM(G37:H37) -> 0 | J37: =I37/$I$25 -> 0
A38: 2 | B38: 1 | C38: 1 | D38: 2 | E38: 06 | F38: Jornales | G38: ='[3]CUENTA T FONDO 100'!I126 -> 0 | H38: ='[3]CUENTA T VS'!I106 -> 0 | I38: =SUM(G38:H38) -> 0 | J38: =I38/$I$25 -> 0
A39: 2 | B39: 1 | C39: 1 | D39: 2 | E39: 08 | F39: Empleados temporales | G39: ='[3]CUENTA T FONDO 100'!J126 -> 1130531 | H39: ='[3]CUENTA T VS'!J106 -> 0 | I39: =SUM(G39:H39) -> 1130531 | J39: =I39/$I$25 -> 0.011255349
A40: 2 | B40: 1 | C40: 1 | D40: 2 | E40: 09 | F40: Personal de carácter eventual | G40: ='[3]CUENTA T FONDO 100'!K126 -> 0 | H40: ='[3]CUENTA T VS'!K106 -> 0 | I40: =SUM(G40:H40) -> 0 | J40: =I40/$I$25 -> 0
A41: 2 | B41: 1 | C41: 1 | D41: 2 | E41: 11 | F41: Interinato | G41: ='[3]CUENTA T FONDO 100'!L126 -> 0 | H41: ='[3]CUENTA T VS'!L106 -> 0 | I41: =SUM(G41:H41) -> 0 | J41: =I41/$I$25 -> 0
A42: 2 | B42: 1 | C42: 1 | D42: 3 | F42: Sueldos al personal fijo en trámite de pensiones | G42: =SUM(G43) -> 0 | H42: =SUM(H43) -> 0 | I42: =SUM(G42:H42) -> 0
A43: 2 | B43: 1 | C43: 1 | D43: 3 | E43: 01 | F43: Sueldos al personal fijo en trámite de pensiones | G43: ='[3]CUENTA T FONDO 100'!M126 -> 0 | H43: ='[3]CUENTA T VS'!M106 -> 0 | I43: =SUM(G43:H43) -> 0 | J43: =I43/$I$25 -> 0
A44: 2 | B44: 1 | C44: 1 | D44: 4 | F44: Sueldo anual no. 13 | G44: =SUM(G45) -> 0 | H44: =SUM(H45) -> 0 | I44: =SUM(G44:H44) -> 0
A45: 2 | B45: 1 | C45: 1 | D45: 4 | E45: 01 | F45: Sueldo anual no. 13 | G45: ='[3]CUENTA T FONDO 100'!N126 -> 0 | H45: ='[3]CUENTA T VS'!N106 -> 0 | I45: =SUM(G45:H45) -> 0 | J45: =I45/$I$25 -> 0
...

Sheet abril-junio 2025
A1: Form. No.6 SRS
A3: Servicio Nacional de Salud
A4: Dirección de Fizcalización
A5: Consolidado de Ingresos y Gastos por Fuente de Financiamiento
A6: HOSPITAL MATERNO INFANTIL SAN LORENZO DE LOS MINA
A7: EJECUCION DE INGRESOS E INGRESOS ABRIL- JUNIO 2025 3.1.1.2.05
C8: Ingresos Generales:
E9: 1.- Balance Inicial / Fuente:
E10: Anticipo Financiero | H10: Otros Aportes
E11: Transferencias Corrientes
E12: Venta de Servicios | G12: 0
E13: 2.- Ingresos por Fuente / Cuenta
E14: Anticipo Financiero | G14: 0 | H14: Otros Aportes | I14: =+'ABRIL '!I14+'mayo 2025'!I14+'junioo '!I14 -> 1815218.7
E15: Transferencias Corrientes | G15: =+'ABRIL '!G15+'mayo 2025'!G15+'junioo '!G15 -> 3.0141289e+08 | H15: Aportes Nomina SNS | I15: 0
E16: Venta de Servicios | G16: =+'ABRIL '!G16+'mayo 2025'!G16+'junioo '!G16 -> 18042285
H17: TOTAL INGRESOS RDS | I17: =+G10+G11+G12+I10+G14+G15+G16+I14+I15 -> 3.212704e+08
A21: 1 | F21: 2 | G21: 3 | I21: 4 | J21: 5
A22: Código Presupuestario | F22: Descripción Gasto por Cuenta | G22: Distribución del Gasto por Fuente de Financiamiento | I22: TOTAL | J22: %
A23: Tipo | B23: Objeto | C23: Cuenta | D23: Sub-Cuenta | E23: Auxiliar | G23: Fondo 100 | H23: Venta de Servicios/ Otros Aportes
A25: 2 | F25: Gastos | G25: =+'ABRIL '!G25+'mayo 2025'!G25+'junioo '!G25 -> 2.7723165e+08 | H25: =+'ABRIL '!H25+'mayo 2025'!H25+'junioo '!H25 -> 20404007 | I25: =SUM(G25:H25) -> 2.9763565e+08 | J25: =+J26+J87+J212+J330+J336+J463 -> 1
A26: 2 | B26: 1 | F26: Servicios Personales | G26: =+'ABRIL '!G26+'mayo 2025'!G26+'junioo '!G26 -> 1.9977032e+08 | H26: =+'ABRIL '!H26+'mayo 2025'!H26+'junioo '!H26 -> 0 | I26: =SUM(G26:H26) -> 1.9977032e+08 | J26: =I26/$I$25 -> 0.67119083
A27: 2 | B27: 1 | C27: 1 | F27: Remuneraciones | G27: =+'ABRIL '!G27+'mayo 2025'!G27+'junioo '!G27 -> 1.6408478e+08 | H27: =+'ABRIL '!H27+'mayo 2025'!H27+'junioo '!H27 -> 0 | I27: =SUM(G27:H27) -> 1.6408478e+08 | J27: =I27/$I$25 -> 0.5512941
A28: 2 | B28: 1 | C28: 1 | D28: 1 | F28: Remuneraciones al personal fijo | G28: =+'ABRIL '!G28+'mayo 2025'!G28+'junioo '!G28 -> 1.6007297e+08 | H28: =+'ABRIL '!H28+'mayo 2025'!H28+'junioo '!H28 -> 0 | I28: =SUM(G28:H28) -> 1.6007297e+08 | J28: =I28/$I$25 -> 0.53781519
A29: 2 | B29: 1 | C29: 1 | D29: 1 | E29: 01 | F29: Sueldos a empleados fijos | G29: =+'ABRIL '!G29+'mayo 2025'!G29+'junioo '!G29 -> 1.6007297e+08 | H29: =+'ABRIL '!H29+'mayo 2025'!H29+'junioo '!H29 -> 0 | I29: =SUM(G29:H29) -> 1.6007297e+08 | J29: =I29/$I$25 -> 0.53781519
A30: 2 | B30: 1 | C30: 1 | D30: 1 | E30: 02 | F30: Sueldos a médicos | G30: =+'ABRIL '!G30+'mayo 2025'!G30+'junioo '!G30 -> 0 | H30: =+'ABRIL '!H30+'mayo 2025'!H30+'junioo '!H30 -> 0 | I30: =SUM(G30:H30) -> 0 | J30: =I30/$I$25 -> 0
A31: 2 | B31: 1 | C31: 1 | D31: 1 | E31: 03 | F31: Ascensos a militares | G31: =+'ABRIL '!G31+'mayo 2025'!G31+'junioo '!G31 -> 0 | H31: =+'ABRIL '!H31+'mayo 2025'!H31+'junioo '!H31 -> 0 | I31: =SUM(G31:H31) -> 0 | J31: =I31/$I$25 -> 0
A32: 2 | B32: 1 | C32: 1 | D32: 1 | E32: 04 | F32: Nuevas plazas maestros | G32: =+'ABRIL '!G32+'mayo 2025'!G32+'junioo '!G32 -> 0 | H32: =+'ABRIL '!H32+'mayo 2025'!H32+'junioo '!H32 -> 0 | I32: =SUM(G32:H32) -> 0 | J32: =I32/$I$25 -> 0
A33: 2 | B33: 1 | C33: 1 | D33: 1 | E33: 05 | F33: Incentivos y escalafón | G33: =+'ABRIL '!G33+'mayo 2025'!G33+'junioo '!G33 -> 0 | H33: =+'ABRIL '!H33+'mayo 2025'!H33+'junioo '!H33 -> 0 | I33: =SUM(G33:H33) -> 0 | J33: =I33/$I$25 -> 0
A34: 2 | B34: 1 | C34: 1 | D34: 1 | E34: 06 | F34: Nuevas plazas a médicos | G34: =+'ABRIL '!G34+'mayo 2025'!G34+'junioo '!G34 -> 0 | H34: =+'ABRIL '!H34+'mayo 2025'!H34+'junioo '!H34 -> 0 | I34: =SUM(G34:H34) -> 0 | J34: =I34/$I$25 -> 0
A35: 2 | B35: 1 | C35: 1 | D35: 2 | F35: Remuneraciones al personal con carácter transitorio | G35: =+'ABRIL '!G35+'mayo 2025'!G35+'junioo '!G35 -> 3368593.1 | H35: =+'ABRIL '!H35+'mayo 2025'!H35+'junioo '!H35 -> 0 | I35: =SUM(G35:H35) -> 3368593.1
A36: 2 | B36: 1 | C36: 1 | D36: 2 | E36: 03 | F36: Suplencias | G36: =+'ABRIL '!G36+'mayo 2025'!G36+'junioo '!G36 -> 0 | H36: =+'ABRIL '!H36+'mayo 2025'!H36+'junioo '!H36 -> 0 | I36: =SUM(G36:H36) -> 0 | J36: =I36/$I$25 -> 0
A37: 2 | B37: 1 | C37: 1 | D37: 2 | E37: 05 | F37: Sueldo al personal nominal en período probatorio | G37: =+'ABRIL '!G37+'mayo 2025'!G37+'junioo '!G37 -> 0 | H37: =+'ABRIL '!H37+'mayo 2025'!H37+'junioo '!H37 -> 0 | I37: =SUM(G37:H37) -> 0 | J37: =I37/$I$25 -> 0
A38: 2 | B38: 1 | C38: 1 | D38: 2 | E38: 06 | F38: Jornales | G38: =+'ABRIL '!G38+'mayo 2025'!G38+'junioo '!G38 -> 0 | H38: =+'ABRIL '!H38+'mayo 2025'!H38+'junioo '!H38 -> 0 | I38: =SUM(G38:H38) -> 0 | J38: =I38/$I$25 -> 0
A39: 2 | B39: 1 | C39: 1 | D39: 2 | E39: 08 | F39: Empleados temporales | G39: =+'ABRIL '!G39+'mayo 2025'!G39+'junioo '!G39 -> 3368593.1 | H39: =+'ABRIL '!H39+'mayo 2025'!H39+'junioo '!H39 -> 0 | I39: =SUM(G39:H39) -> 3368593.1 | J39: =I39/$I$25 -> 0.011317841
A40: 2 | B40: 1 | C40: 1 | D40: 2 | E40: 09 | F40: Personal de carácter eventual | G40: =+'ABRIL '!G40+'mayo 2025'!G40+'junioo '!G40 -> 0 | H40: =+'ABRIL '!H40+'mayo 2025'!H40+'junioo '!H40 -> 0 | I40: =SUM(G40:H40) -> 0 | J40: =I40/$I$25 -> 0
A41: 2 | B41: 1 | C41: 1 | D41: 2 | E41: 11 | F41: Interinato | G41: =+'ABRIL '!G41+'mayo 2025'!G41+'junioo '!G41 -> 0 | H41: =+'ABRIL '!H41+'mayo 2025'!H41+'junioo '!H41 -> 0 | I41: =SUM(G41:H41) -> 0 | J41: =I41/$I$25 -> 0
A42: 2 | B42: 1 | C42: 1 | D42: 3 | F42: Sueldos al personal fijo en trámite de pensiones | G42: =+'ABRIL '!G42+'mayo 2025'!G42+'junioo '!G42 -> 0 | H42: =+'ABRIL '!H42+'mayo 2025'!H42+'junioo '!H42 -> 0 | I42: =SUM(G42:H42) -> 0
A43: 2 | B43: 1 | C43: 1 | D43: 3 | E43: 01 | F43: Sueldos al personal fijo en trámite de pensiones | G43: =+'ABRIL '!G43+'mayo 2025'!G43+'junioo '!G43 -> 0 | H43: =+'ABRIL '!H43+'mayo 2025'!H43+'junioo '!H43 -> 0 | I43: =SUM(G43:H43) -> 0 | J43: =I43/$I$25 -> 0
A44: 2 | B44: 1 | C44: 1 | D44: 4 | F44: Sueldo anual no. 13 | G44: =+'ABRIL '!G44+'mayo 2025'!G44+'junioo '!G44 -> 0 | H44: =+'ABRIL '!H44+'mayo 2025'!H44+'junioo '!H44 -> 0 | I44: =SUM(G44:H44) -> 0
A45: 2 | B45: 1 | C45: 1 | D45: 4 | E45: 01 | F45: Sueldo anual no. 13 | G45: =+'ABRIL '!G45+'mayo 2025'!G45+'junioo '!G45 -> 0 | H45: =+'ABRIL '!H45+'mayo 2025'!H45+'junioo '!H45 -> 0 | I45: =SUM(G45:H45) -> 0 | J45: =I45/$I$25 -> 0
...
